Workbook

Sheet חאזם
G1: =10/22 -> 0.45454545 | H1: 12
A2: סוכן | B2: סוכן | C2: יעד | D2: מכירות | E2: פתוחות | F2: אחוז ביצוע | G2: אומדן | H2: אחוז אומדן | I2: יעד יומי | J2: הפרש יעד יומי
A3: חאזם | B3: בתי מרקחת פרטיים | C3: 109000 | D3: =מכירות!C2+מכירות!C11 -> 20013.1 | E3: =פתוחות!D2 -> 4595 | F3: =(E3+D3)/C3 -> 0.22576239 | G3: =(E3+D3)/$G$1 -> 54137.82 | H3: =G3/C3 -> 0.49667725 | I3: =C3/22 -> 4954.5455 | J3: =(D3-E3)/$H$1 -> 1284.8417
B4: BE | C4: 25070 | D4: =מכירות!C3 -> 9809.2 | E4: =פתוחות!D3 -> 646 | F4: =(E4+D4)/C4 -> 0.41704029 | G4: =(E4+D4)/$G$1 -> 23001.44 | H4: =G4/C4 -> 0.91748863 | I4: =C4/22 -> 1139.5455 | J4: =(D4-E4)/$H$1 -> 763.6
B5: סופרפארם | C5: 119900 | D5: =מכירות!C4 -> 50294 | F5: =(E5+D5)/C5 -> 0.41946622 | G5: =(E5+D5)/$G$1 -> 110646.8 | H5: =G5/C5 -> 0.92282569 | I5: =C5/22 -> 5450 | J5: =(D5-E5)/$H$1 -> 4191.1667
B6: סה"כ | C6: =SUM(C3:C5) -> 253970 | D6: =SUM(D3:D5) -> 80116.3 | E6: =SUM(E3:E5) -> 5241 | F6: =(E6+D6)/C6 -> 0.33609206 | G6: =SUM(G3:G5) -> 187786.06 | H6: =G6/C6 -> 0.73940253 | I6: =SUM(I3:I5) -> 11544.091 | J6: =SUM(J3:J5) -> 6239.6083
B7: מכוני אורטופדיה | C7: 47457 | D7: =מכירות!C7 -> 19629 | F7: =(E7+D7)/C7 -> 0.41361654 | G7: =(E7+D7)/$G$1 -> 43183.8 | H7: =G7/C7 -> 0.90995638 | I7: =C7/22 -> 2157.1364 | J7: =(D7-E7)/$H$1 -> 1635.75
B8: מכוני פיזוטרפיה | C8: =16734+302 -> 17036 | D8: =מכירות!C8 -> 5352 | F8: =(E8+D8)/C8 -> 0.31415825 | G8: =(E8+D8)/$G$1 -> 11774.4 | H8: =G8/C8 -> 0.69114816 | I8: =C8/22 -> 774.36364 | J8: =(D8-E8)/$H$1 -> 446
B9: מאוחדת | C9: 21800 | D9: =מכירות!C5 -> 6626.4 | E9: =פתוחות!D4 -> 302 | F9: =(E9+D9)/C9 -> 0.31781651 | G9: =(E9+D9)/$G$1 -> 15242.48 | H9: =G9/C9 -> 0.69919633 | I9: =C9/22 -> 990.90909 | J9: =(D9-E9)/$H$1 -> 527.03333
B10: חנויות פרטיות | C10: 6250 | D10: =מכירות!C9 -> 0 | F10: =(E10+D10)/C10 -> 0 | G10: =(E10+D10)/$G$1 -> 0 | H10: =G10/C10 -> 0 | I10: =C10/22 -> 284.09091 | J10: =(D10-E10)/$H$1 -> 0
B11: חנויות ספורט | D11: =מכירות!C11 -> 1276 | F11: =(E11+D11)/C11 -> #DIV/0! | G11: =(E11+D11)/$G$1 -> 2807.2 | H11: =G11/C11 -> #DIV/0! | I11: =C11/20 -> 0 | J11: =(D11-E11)/$H$1 -> 106.33333
B12: סה"כ | C12: =SUM(C7:C11) -> 92543 | D12: =SUM(D7:D11) -> 32883.4 | E12: =SUM(E7:E11) -> 302 | F12: =(E12+D12)/C12 -> 0.35859438 | G12: =SUM(G7:G11) -> 73007.88 | H12: =G12/C12 -> 0.78890764 | I12: =SUM(I7:I11) -> 4206.5 | J12: =SUM(J7:J11) -> 2715.1167
B13: סה"כ כללי | C13: =C6+C12 -> 346513 | D13: =D6+D12 -> 112999.7 | E13: =E6+E12 -> 5543 | F13: =(E13+D13)/C13 -> 0.34210174 | G13: =G6+G12 -> 260793.94 | H13: =G13/C13 -> 0.75262383 | I13: =I6+I12 -> 15750.591 | J13: =J6+J12 -> 8954.725

Sheet דודו
G1: =חאזם!G1 -> 0.45454545 | H1: 12
A2: סוכן | B2: סוכן | C2: יעד | D2: מכירות | E2: פתוחות | F2: אחוז ביצוע | G2: אומדן | H2: אחוז אומדן | I2: יעד יומי | J2: הפרש יעד יומי
A3: דודו | B3: בתי מרקחת פרטיים | C3: 45780 | D3: =מכירות!B2+מכירות!B11 -> 28518.9 | E3: =פתוחות!D5 -> 885 | F3: =(E3+D3)/C3 -> 0.64228702 | G3: =(E3+D3)/$G$1 -> 64688.58 | H3: =G3/C3 -> 1.4130315 | I3: =C3/22 -> 2080.9091 | J3: =(C3-D3)/$H$1 -> 1438.425
B4: BE | C4: 25070 | D4: =מכירות!B3 -> 5330.1 | E4: =פתוחות!D6 -> 320 | F4: =(E4+D4)/C4 -> 0.22537296 | G4: =(E4+D4)/$G$1 -> 12430.22 | H4: =G4/C4 -> 0.4958205 | I4: =C4/22 -> 1139.5455 | J4: =(C4-D4)/$H$1 -> 1644.9917
B5: סופרפארם | C5: 167860 | D5: =מכירות!B4 -> 78350.3 | F5: =(E5+D5)/C5 -> 0.4667598 | G5: =(E5+D5)/$G$1 -> 172370.66 | H5: =G5/C5 -> 1.0268716 | I5: =C5/22 -> 7630 | J5: =(C5-D5)/$H$1 -> 7459.1417
B6: סה"כ | C6: =SUM(C3:C5) -> 238710 | D6: =SUM(D3:D5) -> 112199.3 | E6: =SUM(E3:E5) -> 1205 | F6: =(E6+D6)/C6 -> 0.47507143 | G6: =SUM(G3:G5) -> 249489.46 | H6: =G6/C6 -> 1.0451571 | I6: =SUM(I3:I5) -> 10850.455 | J6: =SUM(J3:J5) -> 10542.558
B7: מכוני אורטופדיה | C7: 28992 | D7: =מכירות!B7 -> 8622 | F7: =(E7+D7)/C7 -> 0.29739238 | G7: =(E7+D7)/$G$1 -> 18968.4 | H7: =G7/C7 -> 0.65426325 | I7: =C7/22 -> 1317.8182 | J7: =(C7-D7)/$H$1 -> 1697.5
B8: מכוני פיזוטרפיה | D8: =מכירות!B8 -> 0 | F8: =(E8+D8)/C8 -> #DIV/0! | G8: =(E8+D8)/$G$1 -> 0 | H8: =G8/C8 -> #DIV/0! | I8: =C8/22 -> 0 | J8: =(C8-D8)/$H$1 -> 0
B9: מאוחדת | C9: 43600 | D9: =מכירות!B5 -> 27849.1 | E9: =פתוחות!D7 -> 2240 | F9: =(E9+D9)/C9 -> 0.69011697 | G9: =(E9+D9)/$G$1 -> 66196.02 | H9: =G9/C9 -> 1.5182573 | I9: =C9/22 -> 1981.8182 | J9: =(C9-D9)/$H$1 -> 1312.575
B10: חנויות פרטיות | C10: 6250 | D10: =מכירות!B9 -> 0 | F10: =(E10+D10)/C10 -> 0 | G10: =(E10+D10)/$G$1 -> 0 | H10: =G10/C10 -> 0 | I10: =C10/22 -> 284.09091 | J10: =(C10-D10)/$H$1 -> 520.83333
B11: חנויות ספורט | D11: =מכירות!B11 -> 457 | F11: =(E11+D11)/C11 -> #DIV/0! | G11: =(E11+D11)/$G$1 -> 1005.4 | H11: =G11/C11 -> #DIV/0! | I11: =C11-D11-E11 -> -457 | J11: =I11/$H$1 -> -38.083333
B12: סה"כ | C12: =SUM(C7:C11) -> 78842 | D12: =SUM(D7:D11) -> 36928.1 | E12: =SUM(E7:E11) -> 2240 | F12: =(E12+D12)/C12 -> 0.49679232 | G12: =SUM(G7:G11) -> 86169.82 | H12: =G12/C12 -> 1.0929431 | I12: =SUM(I7:I11) -> 3126.7273 | J12: =SUM(J7:J11) -> 3492.825
B13: סה"כ כללי | C13: =C6+C12 -> 317552 | D13: =D6+D12 -> 149127.4 | E13: =E6+E12 -> 3445 | F13: =(E13+D13)/C13 -> 0.4804643 | G13: =G6+G12 -> 335659.28 | H13: =G13/C13 -> 1.0570215 | I13: =I6+I12 -> 13977.182 | J13: =J6+J12 -> 14035.383

Sheet חיים
G1: =חאזם!G1 -> 0.45454545 | H1: 12
A2: סוכן | B2: סוכן | C2: יעד | D2: מכירות | E2: פתוחות | F2: אחוז ביצוע | G2: אומדן | H2: אחוז אומדן | I2: יעד יומי | J2: הפרש יעד יומי
A3: חיים | B3: בתי מרקחת פרטיים | C3: 30520 | D3: =מכירות!D2 -> 13592.7 | E3: =פתוחות!D8 -> 75 | F3: =(E3+D3)/C3 -> 0.44782765 | G3: =(E3+D3)/$G$1 -> 30068.94 | H3: =G3/C3 -> 0.98522084 | I3: =C3/22 -> 1387.2727 | J3: =(D3-E3)/$H$1 -> 1126.475
B4: BE | C4: 30520 | D4: =מכירות!D3 -> 9861.2 | E4: =פתוחות!D9 -> 408 | F4: =(E4+D4)/C4 -> 0.33647444 | G4: =(E4+D4)/$G$1 -> 22592.24 | H4: =G4/C4 -> 0.74024377 | I4: =C4/22 -> 1387.2727 | J4: =(D4-E4)/$H$1 -> 787.76667
B5: סופרפארם | C5: 161865 | D5: =מכירות!D4 -> 64049.2 | F5: =(E5+D5)/C5 -> 0.39569518 | G5: =(E5+D5)/$G$1 -> 140908.24 | H5: =G5/C5 -> 0.87052939 | I5: =C5/22 -> 7357.5 | J5: =(D5-E5)/$H$1 -> 5337.4333
B6: סה"כ | C6: =SUM(C3:C5) -> 222905 | D6: =SUM(D3:D5) -> 87503.1 | E6: =SUM(E3:E5) -> 483 | F6: =(E6+D6)/C6 -> 0.39472466 | G6: =SUM(G3:G5) -> 193569.42 | H6: =G6/C6 -> 0.86839425 | I6: =SUM(I3:I5) -> 10132.045 | J6: =SUM(J3:J5) -> 7251.675
B7: מכוני אורטופדיה | C7: 12794 | D7: =מכירות!D7 -> 4269 | F7: =(E7+D7)/C7 -> 0.33367203 | G7: =(E7+D7)/$G$1 -> 9391.8 | H7: =G7/C7 -> 0.73407847 | I7: =C7/22 -> 581.54545 | J7: =(D7-E7)/$H$1 -> 355.75
B8: מכוני פיזוטרפיה | C8: 0 | D8: =מכירות!D8 -> 0 | F8: =(E8+D8)/C8 -> #DIV/0! | G8: =(E8+D8)/$G$1 -> 0 | H8: =G8/C8 -> #DIV/0! | I8: =C8/22 -> 0 | J8: =(D8-E8)/$H$1 -> 0
B9: מאוחדת | C9: 6625 | D9: =מכירות!D5 -> 4045 | E9: =פתוחות!D10 -> 537 | F9: =(E9+D9)/C9 -> 0.69162264 | G9: =(E9+D9)/$G$1 -> 10080.4 | H9: =G9/C9 -> 1.5215698 | I9: =C9/22 -> 301.13636 | J9: =(D9-E9)/$H$1 -> 292.33333
B10: חנויות פרטיות | C10: 22036 | D10: =מכירות!D9 -> 1212 | F10: =(E10+D10)/C10 -> 0.055000908 | G10: =(E10+D10)/$G$1 -> 2666.4 | H10: =G10/C10 -> 0.121002 | I10: =C10/22 -> 1001.6364 | J10: =(D10-E10)/$H$1 -> 101
B11: חנויות ספורט | F11: =(E11+D11)/C11 -> #DIV/0! | G11: =(E11+D11)/$G$1 -> 0 | H11: =G11/C11 -> #DIV/0! | I11: =C11/22 -> 0 | J11: =(D11-E11)/$H$1 -> 0
B12: סה"כ | C12: =SUM(C7:C11) -> 41455 | D12: =SUM(D7:D11) -> 9526 | E12: =SUM(E7:E11) -> 537 | F12: =(E12+D12)/C12 -> 0.24274515 | G12: =SUM(G7:G11) -> 22138.6 | H12: =G12/C12 -> 0.53403932 | I12: =SUM(I7:I11) -> 1884.3182 | J12: =SUM(J7:J11) -> 749.08333
B13: סה"כ כללי | C13: =C6+C12 -> 264360 | D13: =D6+D12 -> 97029.1 | E13: =E6+E12 -> 1020 | F13: =(E13+D13)/C13 -> 0.37089234 | G13: =G6+G12 -> 215708.02 | H13: =G13/C13 -> 0.81596316 | I13: =I6+I12 -> 12016.364 | J13: =J6+J12 -> 8000.7583

Sheet סטאס
G1: =חאזם!G1 -> 0.45454545 | H1: 12
A2: סוכן | B2: סוכן | C2: יעד | D2: מכירות | E2: פתוחות | F2: אחוז ביצוע | G2: אומדן | H2: אחוז אומדן | I2: יעד יומי | J2: הפרש ליעד יומי
A3: סטאס | B3: בתי מרקחת פרטיים | C3: 32700 | D3: =מכירות!E2+מכירות!E11 -> 10036.8 | E3: =פתוחות!D11 -> 0 | F3: =(E3+D3)/C3 -> 0.30693578 | G3: =(E3+D3)/$G$1 -> 22080.96 | H3: =G3/C3 -> 0.67525872 | I3: =C3/22 -> 1486.3636 | J3: =(D3-E3)/$H$1 -> 836.4
B4: BE | C4: 28340 | D4: =מכירות!E3 -> 11639.9 | E4: =פתוחות!D12 -> 481 | F4: =(E4+D4)/C4 -> 0.42769584 | G4: =(E4+D4)/$G$1 -> 26665.98 | H4: =G4/C4 -> 0.94093084 | I4: =C4/22 -> 1288.1818 | J4: =(D4-E4)/$H$1 -> 929.90833
B5: סופרפארם | C5: 149875 | D5: =מכירות!E4 -> 56289.2 | F5: =(E5+D5)/C5 -> 0.37557431 | G5: =(E5+D5)/$G$1 -> 123836.24 | H5: =G5/C5 -> 0.82626349 | I5: =C5/22 -> 6812.5 | J5: =(D5-E5)/$H$1 -> 4690.7667
B6: סה"כ | C6: =SUM(C3:C5) -> 210915 | D6: =SUM(D3:D5) -> 77965.9 | E6: =SUM(E3:E5) -> 481 | F6: =(E6+D6)/C6 -> 0.37193609 | G6: =SUM(G3:G5) -> 172583.18 | H6: =G6/C6 -> 0.81825939 | I6: =SUM(I3:I5) -> 9587.0455 | J6: =SUM(J3:J5) -> 6457.075
B7: מכוני אורטופדיה | C7: 10756 | D7: =מכירות!E7 -> 1222 | F7: =(E7+D7)/C7 -> 0.11361101 | G7: =(E7+D7)/$G$1 -> 2688.4 | H7: =G7/C7 -> 0.24994422 | I7: =C7/22 -> 488.90909 | J7: =(D7-E7)/$H$1 -> 101.83333
B8: מכוני פיזוטרפיה | C8: 7964 | D8: =מכירות!E8 -> 899 | F8: =(E8+D8)/C8 -> 0.11288297 | G8: =(E8+D8)/$G$1 -> 1977.8 | H8: =G8/C8 -> 0.24834254 | I8: =C8/22 -> 362 | J8: =(D8-E8)/$H$1 -> 74.916667
B9: מאוחדת | C9: 21564 | D9: =מכירות!E5 -> 7584.6 | E9: =פתוחות!D13 -> 132 | F9: =(E9+D9)/C9 -> 0.35784641 | G9: =(E9+D9)/$G$1 -> 16976.52 | H9: =G9/C9 -> 0.7872621 | I9: =C9/22 -> 980.18182 | J9: =(D9-E9)/$H$1 -> 621.05
B10: חנויות פרטיות | C10: 5875 | D10: =מכירות!E9 -> 157 | F10: =(E10+D10)/C10 -> 0.026723404 | G10: =(E10+D10)/$G$1 -> 345.4 | H10: =G10/C10 -> 0.058791489 | I10: =C10/22 -> 267.04545 | J10: =(D10-E10)/$H$1 -> 13.083333
B11: חנויות ספורט | F11: =(E11+D11)/C11 -> #DIV/0! | G11: =(E11+D11)/$G$1 -> 0 | H11: =G11/C11 -> #DIV/0! | I11: =C11/20 -> 0 | J11: =(D11-E11)/$H$1 -> 0
B12: סה"כ | C12: =SUM(C7:C11) -> 46159 | D12: =SUM(D7:D11) -> 9862.6 | E12: =SUM(E7:E11) -> 132 | F12: =(E12+D12)/C12 -> 0.21652549 | G12: =SUM(G7:G11) -> 21988.12 | H12: =G12/C12 -> 0.47635607 | I12: =SUM(I7:I11) -> 2098.1364 | J12: =SUM(J7:J11) -> 810.88333
B13: סה"כ כללי | C13: =C6+C12 -> 257074 | D13: =D6+D12 -> 87828.5 | E13: =E6+E12 -> 613 | F13: =(E13+D13)/C13 -> 0.34403129 | G13: =G6+G12 -> 194571.3 | H13: =G13/C13 -> 0.75686884 | I13: =I6+I12 -> 11685.182 | J13: =J6+J12 -> 7267.9583

Sheet סה"כ
G1: =חאזם!G1 -> 0.45454545
A2: סוכן | B2: סוכן | C2: יעד | D2: מכירות | E2: פתוחות | F2: אחוז ביצוע | G2: אומדן
A3: צפון | B3: בתי מרקחת פרטיים | C3: =חאזם!C3 -> 109000 | D3: =חאזם!D3 -> 20013.1 | E3: =חאזם!E3 -> 4595 | F3: =(E3+D3)/C3 -> 0.22576239 | G3: =(D3+E3)/$G$1 -> 54137.82
B4: BE | C4: =חאזם!C4 -> 25070 | D4: =חאזם!D4 -> 9809.2 | E4: =חאזם!E4 -> 646 | F4: =(E4+D4)/C4 -> 0.41704029 | G4: =(D4+E4)/$G$1 -> 23001.44
B5: סופרפארם | C5: =חאזם!C5 -> 119900 | D5: =חאזם!D5 -> 50294 | F5: =(E5+D5)/C5 -> 0.41946622 | G5: =(D5+E5)/$G$1 -> 110646.8
B6: מכוני אורטופדיה | C6: =חאזם!C7 -> 47457 | D6: =חאזם!D7 -> 19629 | F6: =(E6+D6)/C6 -> 0.41361654 | G6: =(D6+E6)/$G$1 -> 43183.8
B7: מכוני פיזוטרפיה | C7: =חאזם!C8 -> 17036 | D7: =חאזם!D8 -> 5352 | F7: =(E7+D7)/C7 -> 0.31415825 | G7: =(D7+E7)/$G$1 -> 11774.4
B8: מאוחדת | C8: =חאזם!C9 -> 21800 | D8: =חאזם!D9 -> 6626.4 | F8: =(E8+D8)/C8 -> 0.3039633 | G8: =(D8+E8)/$G$1 -> 14578.08
B9: חנויות פרטיות | C9: =חאזם!C10 -> 6250 | D9: =חאזם!D10 -> 0 | F9: =(E9+D9)/C9 -> 0 | G9: =(D9+E9)/$G$1 -> 0
A10: אילן | B10: סה"כ | C10: =SUM(C3:C9) -> 346513 | D10: =SUM(D3:D9) -> 111723.7 | E10: =SUM(E3:E9) -> 5241 | F10: =(E10+D10)/C10 -> 0.3375478 | G10: =SUM(G3:G9) -> 257322.34
A11: דודו | B11: בתי מרקחת פרטיים | C11: =דודו!C3 -> 45780 | D11: =דודו!D3 -> 28518.9 | E11: =דודו!E3 -> 885 | F11: =(E11+D11)/C11 -> 0.64228702 | G11: =(D11+E11)/$G$1 -> 64688.58
B12: BE | C12: =דודו!C4 -> 25070 | D12: =דודו!D4 -> 5330.1 | E12: =דודו!E4 -> 320 | F12: =(E12+D12)/C12 -> 0.22537296 | G12: =(D12+E12)/$G$1 -> 12430.22
B13: סופרפארם | C13: =דודו!C5 -> 167860 | D13: =דודו!D5 -> 78350.3 | F13: =(E13+D13)/C13 -> 0.4667598 | G13: =(D13+E13)/$G$1 -> 172370.66
B14: מכוני אורטופדיה | C14: =דודו!C7 -> 28992 | D14: =דודו!D7 -> 8622 | F14: =(E14+D14)/C14 -> 0.29739238 | G14: =(D14+E14)/$G$1 -> 18968.4
B15: מכוני פיזוטרפיה | C15: =דודו!C8 -> 0 | D15: =דודו!D8 -> 0 | F15: =(E15+D15)/C15 -> #DIV/0! | G15: =(D15+E15)/$G$1 -> 0
B16: מאוחדת | C16: =דודו!C9 -> 43600 | D16: =דודו!D9 -> 27849.1 | F16: =(E16+D16)/C16 -> 0.63874083 | G16: =(D16+E16)/$G$1 -> 61268.02
B17: חנויות פרטיות | C17: =דודו!C10 -> 6250 | D17: =דודו!D10 -> 0 | F17: =(E17+D17)/C17 -> 0 | G17: =(D17+E17)/$G$1 -> 0
A18: דודו | B18: סה"כ | C18: =SUM(C11:C17) -> 317552 | D18: =SUM(D11:D17) -> 148670.4 | E18: =SUM(E11:E17) -> 1205 | F18: =(E18+D18)/C18 -> 0.4719712 | G18: =SUM(G11:G17) -> 329725.88
A19: חיים | B19: בתי מרקחת פרטיים | C19: =חיים!C3 -> 30520 | D19: =חיים!D3 -> 13592.7 | E19: =חיים!E3 -> 75 | F19: =(E19+D19)/C19 -> 0.44782765 | G19: =(D19+E19)/$G$1 -> 30068.94
B20: BE | C20: =חיים!C4 -> 30520 | D20: =חיים!D4 -> 9861.2 | E20: =חיים!E4 -> 408 | F20: =(E20+D20)/C20 -> 0.33647444 | G20: =(D20+E20)/$G$1 -> 22592.24
B21: סופרפארם | C21: =חיים!C5 -> 161865 | D21: =חיים!D5 -> 64049.2 | F21: =(E21+D21)/C21 -> 0.39569518 | G21: =(D21+E21)/$G$1 -> 140908.24
B22: מכוני אורטופדיה | C22: =חיים!C7 -> 12794 | D22: =חיים!D7 -> 4269 | F22: =(E22+D22)/C22 -> 0.33367203 | G22: =(D22+E22)/$G$1 -> 9391.8
B23: מכוני פיזוטרפיה | C23: =חיים!C8 -> 0 | D23: =חיים!D8 -> 0 | F23: =(E23+D23)/C23 -> #DIV/0! | G23: =(D23+E23)/$G$1 -> 0
B24: מאוחדת | C24: =חיים!C9 -> 6625 | D24: =חיים!D9 -> 4045 | F24: =(E24+D24)/C24 -> 0.61056604 | G24: =(D24+E24)/$G$1 -> 8899
B25: חנויות פרטיות | C25: =חיים!C10 -> 22036 | D25: =חיים!D10 -> 1212 | F25: =(E25+D25)/C25 -> 0.055000908 | G25: =(D25+E25)/$G$1 -> 2666.4
A26: חיים | B26: סה"כ | C26: =SUM(C19:C25) -> 264360 | D26: =SUM(D19:D25) -> 97029.1 | E26: =SUM(E19:E25) -> 483 | F26: =(E26+D26)/C26 -> 0.36886102 | G26: =SUM(G19:G25) -> 214526.62
A27: סטאס | B27: בתי מרקחת פרטיים | C27: =סטאס!C3 -> 32700 | D27: =סטאס!D3 -> 10036.8 | E27: =סטאס!E3 -> 0 | F27: =(E27+D27)/C27 -> 0.30693578 | G27: =(D27+E27)/$G$1 -> 22080.96
B28: BE | C28: =סטאס!C4 -> 28340 | D28: =סטאס!D4 -> 11639.9 | E28: =סטאס!E4 -> 481 | F28: =(E28+D28)/C28 -> 0.42769584 | G28: =(D28+E28)/$G$1 -> 26665.98
B29: סופרפארם | C29: =סטאס!C5 -> 149875 | D29: =סטאס!D5 -> 56289.2 | F29: =(E29+D29)/C29 -> 0.37557431 | G29: =(D29+E29)/$G$1 -> 123836.24
B30: מכוני אורטופדיה | C30: =סטאס!C7 -> 10756 | D30: =סטאס!D7 -> 1222 | F30: =(E30+D30)/C30 -> 0.11361101 | G30: =(D30+E30)/$G$1 -> 2688.4
B31: מכוני פיזוטרפיה | C31: =סטאס!C8 -> 7964 | D31: =סטאס!D8 -> 899 | F31: =(E31+D31)/C31 -> 0.11288297 | G31: =(D31+E31)/$G$1 -> 1977.8
B32: מאוחדת | C32: =סטאס!C9 -> 21564 | D32: =סטאס!D9 -> 7584.6 | F32: =(E32+D32)/C32 -> 0.3517251 | G32: =(D32+E32)/$G$1 -> 16686.12
B33: חנויות פרטיות | C33: =סטאס!C10 -> 5875 | D33: =סטאס!D10 -> 157 | F33: =(E33+D33)/C33 -> 0.026723404 | G33: =(D33+E33)/$G$1 -> 345.4
A34: סטאס | B34: סה"כ | C34: =SUM(C27:C33) -> 257074 | D34: =SUM(D27:D33) -> 87828.5 | E34: =SUM(E27:E33) -> 481 | F34: =(E34+D34)/C34 -> 0.34351782 | G34: =SUM(G27:G33) -> 194280.9 | H34: יעד בניכוי עמלת כמיפל | I34: מכירות בניכוי עמלת כמיפל
A35: סה"כ | B35: בתי מרקחת פרטיים | C35: =C3+C11+C19+C27 -> 218000 | D35: =D3+D11+D19+D27 -> 72161.5 | E35: =E3+E11+E27+E19 -> 5555 | F35: =(E35+D35)/C35 -> 0.35649771 | G35: =G3+G11+G27 -> 140907.36 | H35: =C35*0.91 -> 198380 | I35: =D35*0.91 -> 65666.965
B36: BE | C36: =C4+C12+C20+C28 -> 109000 | D36: =D4+D12+D20+D28 -> 36640.4 | E36: =E4+E12+E28+E20 -> 1855 | F36: =(E36+D36)/C36 -> 0.35316881 | G36: =G4+G12+G28 -> 62097.64 | H36: =C36*0.91 -> 99190 | I36: =D36*0.91 -> 33342.764
B37: סופרפארם | C37: =C5+C13+C21+C29 -> 599500 | D37: =D5+D13+D21+D29 -> 248982.7 | E37: =E5+E13+E29 -> 0 | F37: =(E37+D37)/C37 -> 0.41531726 | G37: =G5+G13+G29 -> 406853.7 | H37: =C37*0.91 -> 545545 | I37: =D37*0.91 -> 226574.26
B38: מכוני אורטופדיה | C38: =C6+C14+C22+C30 -> 99999 | D38: =D6+D14+D22+D30 -> 33742 | E38: =E6+E14+E30 -> 0 | F38: =(E38+D38)/C38 -> 0.33742337 | G38: =G6+G14+G30 -> 64840.6 | H38: =C38 -> 99999 | I38: =D38 -> 33742
B39: מכוני פיזוטרפיה | C39: =C7+C15+C23+C31 -> 25000 | D39: =D7+D15+D23+D31 -> 6251 | E39: =E7+E15+E31 -> 0 | F39: =(E39+D39)/C39 -> 0.25004 | G39: =G7+G15+G31 -> 13752.2 | H39: =C39 -> 25000 | I39: =D39 -> 6251
B40: מאוחדת | C40: =C8+C16+C24+C32 -> 93589 | D40: =D8+D16+D24+D32 -> 46105.1 | E40: =E8+E16+E32 -> 0 | F40: =(E40+D40)/C40 -> 0.49263375 | G40: =G8+G16+G32 -> 92532.22 | H40: =C40 -> 93589 | I40: =D40*0.91 -> 41955.641
...

Sheet מכירות
B1: דודו | C1: חאזם | D1: חיים | E1: סטאס
A2: בתי מרקחת | B2: =24940.9+3121 -> 28061.9 | C2: =19176.1-439 -> 18737.1 | D2: =12979.7+613 -> 13592.7 | E2: 7414.8
A3: BE | B3: 5330.1 | C3: 9809.2 | D3: 9861.2 | E3: 11639.9
A4: סופרפארם | B4: =77984.3+366 -> 78350.3 | C4: =44573+5721 -> 50294 | D4: =63318.2+731 -> 64049.2 | E4: 56289.2
A5: מאוחדת | B5: =24724.1+3125 -> 27849.1 | C5: =6500.4+126 -> 6626.4 | D5: 4045 | E5: =6570.6+1014 -> 7584.6
A7: מכונים אורטופדיה | B7: 8622 | C7: 19629 | D7: 4269 | E7: 1222
A8: מכוני פיזוטרפיה | C8: 5352 | E8: 899
A9: חנויות פרטיות | D9: 1212 | E9: 157
A10: חנויות ספורט
A11: בימ"ק פיננסית | B11: 457 | C11: 1276 | D11: 1303 | E11: 2622

Sheet פתוחות
A1: סקטור | B1: סוכן | C1: לקוח | D1: Chemipal
A2: בתי מרקחת סה"כ | B2: אורלי | D2: 4595
A3: BE סה"כ | B3: אורלי | D3: 646
A4: מאוחדת סה"כ | B4: אורלי | D4: 302
A5: בתי מרקחת סה"כ | B5: דוד | D5: 885
A6: BE סה"כ | B6: דוד | D6: 320
A7: מאוחדת סה"כ | B7: דוד | D7: 2240
A8: בתי מרקחת סה"כ | B8: חיים | D8: 75
A9: BE סה"כ | B9: חיים | D9: 408
A10: מאוחדת סה"כ | B10: חיים | D10: 537
A11: בתי מרקחת סה"כ | B11: סטאס
A12: BE סה"כ | B12: סטאס | D12: 481
A13: מאוחדת סה"כ | B13: סטאס | D13: 132
A14: סכום כולל | D14: 10621

Sheet גיליון2
A1: סקטור | B1: סוכן | C1: לקוח | D1: Chemipal
A2: בתי מרקחת | B2: דודו | C2: ארתור טבעי בע""מ ר.בית שמש ב.מ | D2: 117
A3: בתי מרקחת | B3: דודו | C3: מזור י-ם ב.מ | D3: 679
A4: בתי מרקחת | B4: דודו | C4: עוזיאל י-ם ב.מ | D4: 74
A5: בתי מרקחת | B5: דודו | C5: הר נוף י-ם ב.מ שרמפארם | D5: 15
A6: בתי מרקחת סה"כ | B6: דודו | D6: =SUBTOTAL(9,D2:D5) -> 885
A7: BE | B7: דודו | C7: שבעת הכוכבים אילת BE | D7: 31
A8: BE | B8: דודו | C8: 145 נתיבות BE | D8: 289
A9: BE סה"כ | B9: דודו | D9: =SUBTOTAL(9,D7:D8) -> 320
A10: מאוחדת | B10: דודו | C10: 7311 קופ""ח מאוחדת הר חומה | D10: 54
A11: מאוחדת | B11: דודו | C11: 7319 מאוחדת פ.זאב | D11: 46
A12: מאוחדת | B12: דודו | C12: 7114 מאוחדת קרית ספר מודיעין | D12: 94
A13: מאוחדת | B13: דודו | C13: 5310 מאוחדת רחובות | D13: 857
A14: מאוחדת | B14: דודו | C14: מאוחדת בית""ר עילית 5102 מחסן | D14: 113
A15: מאוחדת | B15: דודו | C15: מאוחדת אגן האיילות 7302גבעת זא | D15: 32
A16: מאוחדת | B16: דודו | C16: 54 (מאוחדת פסגת זאב 2 )נדבה | D16: 89
A17: מאוחדת | B17: דודו | C17: מאוחדת גבעת מרדכי 7334 ירושלים | D17: 13
A18: מאוחדת | B18: דודו | C18: 59 מאוחדת רחובות הרצל | D18: 296
A19: מאוחדת | B19: דודו | C19: 7339 מאוחדת נופי סלע | D19: 500
A20: מאוחדת | B20: דודו | C20: 7351 מאוחדת פארם רוממה תובל | D20: 49
A21: מאוחדת | B21: דודו | C21: 7536 מאוחדת פארם רא""ם רחובות | D21: 97
A22: מאוחדת סה"כ | B22: דודו | D22: =SUBTOTAL(9,D10:D21) -> 2240
A23: בתי מרקחת | B23: חאזם | C23: חידאר פארם ב.מ | D23: 473
A24: בתי מרקחת | B24: חאזם | C24: המרכז אעבלין ב.מ | D24: 292
A25: בתי מרקחת | B25: חאזם | C25: בלסם פארם טמרה ב.מ | D25: 525
A26: בתי מרקחת | B26: חאזם | C26: סופר מדיקה ב.מ קרית ים | D26: 316
A27: בתי מרקחת | B27: חאזם | C27: שרה ב.מ נושק לבקה אל גרביה | D27: 94
A28: בתי מרקחת | B28: חאזם | C28: נרקיס פארם חדרה | D28: 2135
A29: בתי מרקחת | B29: חאזם | C29: אלבלד פארם ב.מ טמרה | D29: 729
A30: בתי מרקחת | B30: חאזם | C30: ד""ר קיי פארם חדרה | D30: 31
A31: בתי מרקחת סה"כ | B31: חאזם | D31: =SUBTOTAL(9,D23:D30) -> 4595
A32: BE | B32: חאזם | C32: 071 שופרסל ד.נשר תל חנן | D32: 66
A33: BE | B33: חאזם | C33: 697 ירכא BE | D33: 41
A34: BE | B34: חאזם | C34: 650 חיפה BE | D34: 105
A35: BE | B35: חאזם | C35: 676 יקנעם BE | D35: 102
A36: BE | B36: חאזם | C36: 679 כרכור מדיקל BE | D36: 82
A37: BE | B37: חאזם | C37: 712 עין הים חדרה BE | D37: 169
A38: BE | B38: חאזם | C38: 518 כפר קרע BE | D38: 81
A39: BE סה"כ | B39: חאזם | D39: =SUBTOTAL(9,D32:D38) -> 646
A40: מאוחדת | B40: חאזם | C40: 7401 מאוחדת אום אל פחם | D40: 273
...
