Workbook

Sheet תקציב  
E1: 2 | F1: =+E1+1 -> 3 | G1: =+F1+1 -> 4 | H1: =+G1+1 -> 5 | I1: =+H1+1 -> 6 | J1: =+I1+1 -> 7 | K1: =+J1+1 -> 8 | L1: =+K1+1 -> 9 | M1: =+L1+1 -> 10 | ... P1: =+O1+1 -> 13
E2: 3 | F2: =E2+3 -> 6 | G2: =F2+3 -> 9 | H2: =G2+3 -> 12 | I2: =H2+3 -> 15 | J2: =I2+3 -> 18 | K2: =J2+3 -> 21 | L2: =K2+3 -> 24 | M2: =L2+3 -> 27 | ... P2: =O2+3 -> 36
AG3: Actual | AI3: מטרה
A4: # | D4: ארץ | E4: ינואר | F4: פברואר | G4: מרץ | H4: אפריל | I4: מאי | J4: יוני | K4: יולי | L4: אוגוסט | M4: ספטמבר | N4: אוקטובר | O4: נובמבר | P4: דצמבר | Q4: שנתי | S4: מצטבר ינואר | U4: מצטבר פברואר | V4: מצטבר מרץ | W4: מצטבר אפריל | X4: מצטבר מאי | Y4: מצטבר יוני | Z4: מצטבר יולי | AA4: מצטבר אוגוסט | AB4: מצטבר ספטמבר | AC4: מצטבר אוקטובר | AD4: מצטבר נובמבר | AE4: מצטבר דצמבר | AG4: H1 | AI4: יולי | AJ4: אוגוסט | AK4: ספטמבר | AL4: אוקטובר | AM4: נובמבר | AN4: דצמבר | AO4: H2 | AP4: שנתי | AR4: מצטבר יולי | AS4: מצטבר אוגוסט | AT4: מצטבר ספטמבר | AU4: מצטבר אוקטובר | AV4: מצטבר נובמבר | AW4: מצטבר דצמבר
A5: 5 | B5: סופר פארם לייף | C5: סופר פארם לייף | D5: ISRAEL | E5: 176666.67 | F5: 168253.97 | G5: 193492.06 | H5: 173015.87 | I5: 188253.97 | J5: 235079.37 | K5: 235079.37 | L5: 235079.37 | M5: 209841.27 | N5: 226666.67 | O5: 235079.37 | P5: 243492.06 | Q5: =SUM(E5:P5) -> 2520000 | S5: =SUM(E5:E5) -> 176666.67 | U5: =SUM($E5:F5) -> 344920.63 | V5: =SUM($E5:G5) -> 538412.7 | W5: =SUM($E5:H5) -> 711428.57 | X5: =SUM($E5:I5) -> 899682.54 | Y5: =SUM($E5:J5) -> 1134761.9 | Z5: =SUM($E5:K5) -> 1369841.3 | AA5: =SUM($E5:L5) -> 1604920.6 | AB5: =SUM($E5:M5) -> 1814761.9 | ... AE5: =SUM($E5:P5) -> 2520000 | AG5: =_xlfn.XLOOKUP(A5,'מצטבר יוני'!A:A,'מצטבר יוני'!H:H) -> 740443.3 | AI5: =AJ5 -> 200000 | AJ5: =_xlfn.XLOOKUP($A5,'[1]ישראל חציון שני הערכה '!$B:$B,'[1]ישראל חציון שני הערכה '!L:L) -> 200000 | AK5: =_xlfn.XLOOKUP($A5,'[1]ישראל חציון שני הערכה '!$B:$B,'[1]ישראל חציון שני הערכה '!M:M) -> 200000 | AL5: =_xlfn.XLOOKUP($A5,'[1]ישראל חציון שני הערכה '!$B:$B,'[1]ישראל חציון שני הערכה '!N:N) -> 200000 | AM5: =_xlfn.XLOOKUP($A5,'[1]ישראל חציון שני הערכה '!$B:$B,'[1]ישראל חציון שני הערכה '!O:O) -> 200000 | AN5: =_xlfn.XLOOKUP($A5,'[1]ישראל חציון שני הערכה '!$B:$B,'[1]ישראל חציון שני הערכה '!P:P) -> 200000 | AO5: =SUM(AI5:AN5) -> 1200000 | AP5: =SUM(AI5:AN5)+Y5 -> 2334761.9 | AR5: =AI5+AG5 -> 940443.3 | AS5: =AR5+AJ5 -> 1140443.3 | AT5: =AS5+AK5 -> 1340443.3 | AU5: =AT5+AL5 -> 1540443.3 | AV5: =AU5+AM5 -> 1740443.3 | AW5: =AV5+AN5 -> 1940443.3
A6: 1 | B6: סופרפארם | C6: סופרפארם | D6: ISRAEL | E6: 536666.67 | F6: 532634.92 | G6: 610730.16 | H6: 475539.68 | I6: 558634.92 | J6: 605698.41 | K6: 605698.41 | L6: 605698.41 | M6: 527603.17 | N6: 546666.67 | O6: 574698.41 | P6: 598730.16 | Q6: =SUM(E6:P6) -> 6779000 | S6: =SUM(E6:E6) -> 536666.67 | U6: =SUM($E6:F6) -> 1069301.6 | V6: =SUM($E6:G6) -> 1680031.7 | W6: =SUM($E6:H6) -> 2155571.4 | X6: =SUM($E6:I6) -> 2714206.3 | Y6: =SUM($E6:J6) -> 3319904.8 | Z6: =SUM($E6:K6) -> 3925603.2 | AA6: =SUM($E6:L6) -> 4531301.6 | AB6: =SUM($E6:M6) -> 5058904.8 | ... AE6: =SUM($E6:P6) -> 6779000 | AG6: =_xlfn.XLOOKUP(A6,'מצטבר יוני'!A:A,'מצטבר יוני'!H:H) -> 2774937.9 | AI6: =AJ6 -> 550000 | AJ6: =_xlfn.XLOOKUP($A6,'[1]ישראל חציון שני הערכה '!$B:$B,'[1]ישראל חציון שני הערכה '!L:L) -> 550000 | AK6: =_xlfn.XLOOKUP($A6,'[1]ישראל חציון שני הערכה '!$B:$B,'[1]ישראל חציון שני הערכה '!M:M) -> 550000 | AL6: =_xlfn.XLOOKUP($A6,'[1]ישראל חציון שני הערכה '!$B:$B,'[1]ישראל חציון שני הערכה '!N:N) -> 550000 | AM6: =_xlfn.XLOOKUP($A6,'[1]ישראל חציון שני הערכה '!$B:$B,'[1]ישראל חציון שני הערכה '!O:O) -> 550000 | AN6: =_xlfn.XLOOKUP($A6,'[1]ישראל חציון שני הערכה '!$B:$B,'[1]ישראל חציון שני הערכה '!P:P) -> 550000 | AO6: =SUM(AI6:AN6) -> 3300000 | AP6: =SUM(AI6:AN6)+Y6 -> 6619904.8 | AR6: =AI6+AG6 -> 3324937.9 | AS6: =AR6+AJ6 -> 3874937.9 | AT6: =AS6+AK6 -> 4424937.9 | AU6: =AT6+AL6 -> 4974937.9 | AV6: =AU6+AM6 -> 5524937.9 | AW6: =AV6+AN6 -> 6074937.9
A7: 7 | B7: BE | C7: BE | D7: ISRAEL | E7: 73000 | F7: 73428.571 | G7: 82142.857 | H7: 60714.286 | I7: 71428.571 | J7: 78571.429 | K7: 78571.429 | L7: 78571.429 | M7: 67857.143 | N7: 75000 | O7: 78571.429 | P7: 82142.857 | Q7: =SUM(E7:P7) -> 900000 | S7: =SUM(E7:E7) -> 73000 | U7: =SUM($E7:F7) -> 146428.57 | V7: =SUM($E7:G7) -> 228571.43 | W7: =SUM($E7:H7) -> 289285.71 | X7: =SUM($E7:I7) -> 360714.29 | Y7: =SUM($E7:J7) -> 439285.71 | Z7: =SUM($E7:K7) -> 517857.14 | AA7: =SUM($E7:L7) -> 596428.57 | AB7: =SUM($E7:M7) -> 664285.71 | ... AE7: =SUM($E7:P7) -> 900000 | AG7: =_xlfn.XLOOKUP(A7,'מצטבר יוני'!A:A,'מצטבר יוני'!H:H) -> 437274.57 | AI7: =AJ7 -> 100000 | AJ7: =_xlfn.XLOOKUP($A7,'[1]ישראל חציון שני הערכה '!$B:$B,'[1]ישראל חציון שני הערכה '!L:L) -> 100000 | AK7: =_xlfn.XLOOKUP($A7,'[1]ישראל חציון שני הערכה '!$B:$B,'[1]ישראל חציון שני הערכה '!M:M) -> 100000 | AL7: =_xlfn.XLOOKUP($A7,'[1]ישראל חציון שני הערכה '!$B:$B,'[1]ישראל חציון שני הערכה '!N:N) -> 100000 | AM7: =_xlfn.XLOOKUP($A7,'[1]ישראל חציון שני הערכה '!$B:$B,'[1]ישראל חציון שני הערכה '!O:O) -> 100000 | AN7: =_xlfn.XLOOKUP($A7,'[1]ישראל חציון שני הערכה '!$B:$B,'[1]ישראל חציון שני הערכה '!P:P) -> 100000 | AO7: =SUM(AI7:AN7) -> 600000 | AP7: =SUM(AI7:AN7)+Y7 -> 1039285.7 | AR7: =AI7+AG7 -> 537274.56 | AS7: =AR7+AJ7 -> 637274.56 | AT7: =AS7+AK7 -> 737274.56 | AU7: =AT7+AL7 -> 837274.56 | AV7: =AU7+AM7 -> 937274.56 | AW7: =AV7+AN7 -> 1037274.6
A8: 4 | B8: בתי מרקחת | C8: בתי מרקחת | D8: ISRAEL | E8: 152333.33 | F8: 156793.65 | G8: 173412.7 | H8: 134174.6 | I8: 160793.65 | J8: 170873.02 | K8: 170873.02 | L8: 170873.02 | M8: 150253.97 | N8: 162333.33 | O8: 170873.02 | P8: 173412.7 | Q8: =SUM(E8:P8) -> 1947000 | S8: =SUM(E8:E8) -> 152333.33 | U8: =SUM($E8:F8) -> 309126.98 | V8: =SUM($E8:G8) -> 482539.68 | W8: =SUM($E8:H8) -> 616714.29 | X8: =SUM($E8:I8) -> 777507.94 | Y8: =SUM($E8:J8) -> 948380.95 | Z8: =SUM($E8:K8) -> 1119254 | AA8: =SUM($E8:L8) -> 1290127 | AB8: =SUM($E8:M8) -> 1440381 | ... AE8: =SUM($E8:P8) -> 1947000 | AG8: =_xlfn.XLOOKUP(A8,'מצטבר יוני'!A:A,'מצטבר יוני'!H:H) -> 918523.98 | AI8: =AJ8 -> 200000 | AJ8: =_xlfn.XLOOKUP($A8,'[1]ישראל חציון שני הערכה '!$B:$B,'[1]ישראל חציון שני הערכה '!L:L) -> 200000 | AK8: =_xlfn.XLOOKUP($A8,'[1]ישראל חציון שני הערכה '!$B:$B,'[1]ישראל חציון שני הערכה '!M:M) -> 200000 | AL8: =_xlfn.XLOOKUP($A8,'[1]ישראל חציון שני הערכה '!$B:$B,'[1]ישראל חציון שני הערכה '!N:N) -> 200000 | AM8: =_xlfn.XLOOKUP($A8,'[1]ישראל חציון שני הערכה '!$B:$B,'[1]ישראל חציון שני הערכה '!O:O) -> 200000 | AN8: =_xlfn.XLOOKUP($A8,'[1]ישראל חציון שני הערכה '!$B:$B,'[1]ישראל חציון שני הערכה '!P:P) -> 200000 | AO8: =SUM(AI8:AN8) -> 1200000 | AP8: =SUM(AI8:AN8)+Y8 -> 2148381 | AR8: =AI8+AG8 -> 1118524 | AS8: =AR8+AJ8 -> 1318524 | AT8: =AS8+AK8 -> 1518524 | AU8: =AT8+AL8 -> 1718524 | AV8: =AU8+AM8 -> 1918524 | AW8: =AV8+AN8 -> 2118524
A9: 3 | B9: כללית | C9: כללית | D9: ISRAEL | E9: 365000 | F9: 365000 | G9: 365000 | H9: 365000 | I9: 365000 | J9: 365000 | K9: 365000 | L9: 365000 | M9: 365000 | N9: 365000 | O9: 365000 | P9: 366000 | Q9: =SUM(E9:P9) -> 4381000 | S9: =SUM(E9:E9) -> 365000 | U9: =SUM($E9:F9) -> 730000 | V9: =SUM($E9:G9) -> 1095000 | W9: =SUM($E9:H9) -> 1460000 | X9: =SUM($E9:I9) -> 1825000 | Y9: =SUM($E9:J9) -> 2190000 | Z9: =SUM($E9:K9) -> 2555000 | AA9: =SUM($E9:L9) -> 2920000 | AB9: =SUM($E9:M9) -> 3285000 | ... AE9: =SUM($E9:P9) -> 4381000 | AG9: =_xlfn.XLOOKUP(A9,'מצטבר יוני'!A:A,'מצטבר יוני'!H:H) -> 1742410.9 | AI9: =AJ9 -> 330000 | AJ9: =_xlfn.XLOOKUP($A9,'[1]ישראל חציון שני הערכה '!$B:$B,'[1]ישראל חציון שני הערכה '!L:L) -> 330000 | AK9: =_xlfn.XLOOKUP($A9,'[1]ישראל חציון שני הערכה '!$B:$B,'[1]ישראל חציון שני הערכה '!M:M) -> 330000 | AL9: =_xlfn.XLOOKUP($A9,'[1]ישראל חציון שני הערכה '!$B:$B,'[1]ישראל חציון שני הערכה '!N:N) -> 330000 | AM9: =_xlfn.XLOOKUP($A9,'[1]ישראל חציון שני הערכה '!$B:$B,'[1]ישראל חציון שני הערכה '!O:O) -> 330000 | AN9: =_xlfn.XLOOKUP($A9,'[1]ישראל חציון שני הערכה '!$B:$B,'[1]ישראל חציון שני הערכה '!P:P) -> 330000 | AO9: =SUM(AI9:AN9) -> 1980000 | AP9: =SUM(AI9:AN9)+Y9 -> 4170000 | AR9: =AI9+AG9 -> 2072410.9 | AS9: =AR9+AJ9 -> 2402410.9 | AT9: =AS9+AK9 -> 2732410.9 | AU9: =AT9+AL9 -> 3062410.9 | AV9: =AU9+AM9 -> 3392410.9 | AW9: =AV9+AN9 -> 3722410.9
A10: 8 | B10: מאוחדת | C10: מאוחדת | D10: ISRAEL | E10: 83333.333 | F10: 109365.08 | G10: 111269.84 | H10: 97460.317 | I10: 99365.079 | J10: 107301.59 | K10: 107301.59 | L10: 107301.59 | M10: 95396.825 | N10: 103333.33 | O10: 107301.59 | P10: 91269.841 | Q10: =SUM(E10:P10) -> 1220000 | S10: =SUM(E10:E10) -> 83333.333 | U10: =SUM($E10:F10) -> 192698.41 | V10: =SUM($E10:G10) -> 303968.25 | W10: =SUM($E10:H10) -> 401428.57 | X10: =SUM($E10:I10) -> 500793.65 | Y10: =SUM($E10:J10) -> 608095.24 | Z10: =SUM($E10:K10) -> 715396.83 | AA10: =SUM($E10:L10) -> 822698.41 | AB10: =SUM($E10:M10) -> 918095.24 | ... AE10: =SUM($E10:P10) -> 1220000 | AG10: =_xlfn.XLOOKUP(A10,'מצטבר יוני'!A:A,'מצטבר יוני'!H:H) -> 343097.61 | AI10: =AJ10 -> 100000 | AJ10: =_xlfn.XLOOKUP($A10,'[1]ישראל חציון שני הערכה '!$B:$B,'[1]ישראל חציון שני הערכה '!L:L) -> 100000 | AK10: =_xlfn.XLOOKUP($A10,'[1]ישראל חציון שני הערכה '!$B:$B,'[1]ישראל חציון שני הערכה '!M:M) -> 100000 | AL10: =_xlfn.XLOOKUP($A10,'[1]ישראל חציון שני הערכה '!$B:$B,'[1]ישראל חציון שני הערכה '!N:N) -> 100000 | AM10: =_xlfn.XLOOKUP($A10,'[1]ישראל חציון שני הערכה '!$B:$B,'[1]ישראל חציון שני הערכה '!O:O) -> 100000 | AN10: =_xlfn.XLOOKUP($A10,'[1]ישראל חציון שני הערכה '!$B:$B,'[1]ישראל חציון שני הערכה '!P:P) -> 100000 | AO10: =SUM(AI10:AN10) -> 600000 | AP10: =SUM(AI10:AN10)+Y10 -> 1208095.2 | AR10: =AI10+AG10 -> 443097.61 | AS10: =AR10+AJ10 -> 543097.61 | AT10: =AS10+AK10 -> 643097.61 | AU10: =AT10+AL10 -> 743097.61 | AV10: =AU10+AM10 -> 843097.61 | AW10: =AV10+AN10 -> 943097.61
A11: 6 | B11: מכוני אורטופדיה | C11: מכוני אורטופדיה | D11: ISRAEL | E11: 127583.33 | F11: 155079.37 | G11: 160591.27 | H11: 139567.46 | I11: 170079.37 | J11: 177087.3 | K11: 177087.3 | L11: 177087.3 | M11: 166575.4 | N11: 173583.33 | O11: 177087.3 | P11: 177591.27 | Q11: =SUM(E11:P11) -> 1979000 | S11: =SUM(E11:E11) -> 127583.33 | U11: =SUM($E11:F11) -> 282662.7 | V11: =SUM($E11:G11) -> 443253.97 | W11: =SUM($E11:H11) -> 582821.43 | X11: =SUM($E11:I11) -> 752900.79 | Y11: =SUM($E11:J11) -> 929988.1 | Z11: =SUM($E11:K11) -> 1107075.4 | AA11: =SUM($E11:L11) -> 1284162.7 | AB11: =SUM($E11:M11) -> 1450738.1 | ... AE11: =SUM($E11:P11) -> 1979000 | AG11: =_xlfn.XLOOKUP(A11,'מצטבר יוני'!A:A,'מצטבר יוני'!H:H) -> 475277.57 | AI11: =AJ11 -> 100000 | AJ11: =_xlfn.XLOOKUP($A11,'[1]ישראל חציון שני הערכה '!$B:$B,'[1]ישראל חציון שני הערכה '!L:L) -> 100000 | AK11: =_xlfn.XLOOKUP($A11,'[1]ישראל חציון שני הערכה '!$B:$B,'[1]ישראל חציון שני הערכה '!M:M) -> 100000 | AL11: =_xlfn.XLOOKUP($A11,'[1]ישראל חציון שני הערכה '!$B:$B,'[1]ישראל חציון שני הערכה '!N:N) -> 100000 | AM11: =_xlfn.XLOOKUP($A11,'[1]ישראל חציון שני הערכה '!$B:$B,'[1]ישראל חציון שני הערכה '!O:O) -> 100000 | AN11: =_xlfn.XLOOKUP($A11,'[1]ישראל חציון שני הערכה '!$B:$B,'[1]ישראל חציון שני הערכה '!P:P) -> 100000 | AO11: =SUM(AI11:AN11) -> 600000 | AP11: =SUM(AI11:AN11)+Y11 -> 1529988.1 | AR11: =AI11+AG11 -> 575277.57 | AS11: =AR11+AJ11 -> 675277.57 | AT11: =AS11+AK11 -> 775277.57 | AU11: =AT11+AL11 -> 875277.57 | AV11: =AU11+AM11 -> 975277.57 | AW11: =AV11+AN11 -> 1075277.6
A12: 10 | B12: לקוחות מפעל | C12: לקוחות מפעל | D12: ISRAEL | E12: 15833.333 | F12: 15079.365 | G12: 17341.27 | H12: 12817.46 | I12: 15079.365 | J12: 16587.302 | K12: 16587.302 | L12: 16587.302 | M12: 14325.397 | N12: 15833.333 | O12: 16587.302 | P12: 17341.27 | Q12: =SUM(E12:P12) -> 190000 | S12: =SUM(E12:E12) -> 15833.333 | U12: =SUM($E12:F12) -> 30912.698 | V12: =SUM($E12:G12) -> 48253.968 | W12: =SUM($E12:H12) -> 61071.429 | X12: =SUM($E12:I12) -> 76150.794 | Y12: =SUM($E12:J12) -> 92738.095 | Z12: =SUM($E12:K12) -> 109325.4 | AA12: =SUM($E12:L12) -> 125912.7 | AB12: =SUM($E12:M12) -> 140238.1 | ... AE12: =SUM($E12:P12) -> 190000 | AG12: =_xlfn.XLOOKUP(A12,'מצטבר יוני'!A:A,'מצטבר יוני'!H:H) -> 61235.08 | AI12: =AJ12 -> 15000 | AJ12: =_xlfn.XLOOKUP($A12,'[1]ישראל חציון שני הערכה '!$B:$B,'[1]ישראל חציון שני הערכה '!L:L) -> 15000 | AK12: =_xlfn.XLOOKUP($A12,'[1]ישראל חציון שני הערכה '!$B:$B,'[1]ישראל חציון שני הערכה '!M:M) -> 15000 | AL12: =_xlfn.XLOOKUP($A12,'[1]ישראל חציון שני הערכה '!$B:$B,'[1]ישראל חציון שני הערכה '!N:N) -> 15000 | AM12: =_xlfn.XLOOKUP($A12,'[1]ישראל חציון שני הערכה '!$B:$B,'[1]ישראל חציון שני הערכה '!O:O) -> 15000 | AN12: =_xlfn.XLOOKUP($A12,'[1]ישראל חציון שני הערכה '!$B:$B,'[1]ישראל חציון שני הערכה '!P:P) -> 15000 | AO12: =SUM(AI12:AN12) -> 90000 | AP12: =SUM(AI12:AN12)+Y12 -> 182738.1 | AR12: =AI12+AG12 -> 76235.08 | AS12: =AR12+AJ12 -> 91235.08 | AT12: =AS12+AK12 -> 106235.08 | AU12: =AT12+AL12 -> 121235.08 | AV12: =AU12+AM12 -> 136235.08 | AW12: =AV12+AN12 -> 151235.08
A13: 11 | B13: חנויות פרטיות | C13: חנויות פרטיות | D13: ISRAEL | E13: 6333.3333 | F13: 7936.5079 | G13: 9126.9841 | H13: 6746.0317 | I13: 7936.5079 | J13: 8730.1587 | K13: 8730.1587 | L13: 8730.1587 | M13: 8539.6825 | N13: 9333.3333 | O13: 8730.1587 | P13: 9126.9841 | Q13: =SUM(E13:P13) -> 100000 | S13: =SUM(E13:E13) -> 6333.3333 | U13: =SUM($E13:F13) -> 14269.841 | V13: =SUM($E13:G13) -> 23396.825 | W13: =SUM($E13:H13) -> 30142.857 | X13: =SUM($E13:I13) -> 38079.365 | Y13: =SUM($E13:J13) -> 46809.524 | Z13: =SUM($E13:K13) -> 55539.683 | AA13: =SUM($E13:L13) -> 64269.841 | AB13: =SUM($E13:M13) -> 72809.524 | ... AE13: =SUM($E13:P13) -> 100000 | AG13: =_xlfn.XLOOKUP(A13,'מצטבר יוני'!A:A,'מצטבר יוני'!H:H) -> 34015.41 | AI13: =AJ13 -> 10000 | AJ13: =_xlfn.XLOOKUP($A13,'[1]ישראל חציון שני הערכה '!$B:$B,'[1]ישראל חציון שני הערכה '!L:L) -> 10000 | AK13: =_xlfn.XLOOKUP($A13,'[1]ישראל חציון שני הערכה '!$B:$B,'[1]ישראל חציון שני הערכה '!M:M) -> 10000 | AL13: =_xlfn.XLOOKUP($A13,'[1]ישראל חציון שני הערכה '!$B:$B,'[1]ישראל חציון שני הערכה '!N:N) -> 10000 | AM13: =_xlfn.XLOOKUP($A13,'[1]ישראל חציון שני הערכה '!$B:$B,'[1]ישראל חציון שני הערכה '!O:O) -> 10000 | AN13: =_xlfn.XLOOKUP($A13,'[1]ישראל חציון שני הערכה '!$B:$B,'[1]ישראל חציון שני הערכה '!P:P) -> 10000 | AO13: =SUM(AI13:AN13) -> 60000 | AP13: =SUM(AI13:AN13)+Y13 -> 106809.52 | AR13: =AI13+AG13 -> 44015.41 | AS13: =AR13+AJ13 -> 54015.41 | AT13: =AS13+AK13 -> 64015.41 | AU13: =AT13+AL13 -> 74015.41 | AV13: =AU13+AM13 -> 84015.41 | AW13: =AV13+AN13 -> 94015.41
A14: 14 | B14: מכוני פדיקור | C14: מכוני פדיקור | D14: ISRAEL | E14: 0 | F14: 0 | G14: 0 | H14: 0 | I14: 0 | J14: 0 | K14: 0 | L14: 0 | M14: 0 | N14: 0 | O14: 0 | P14: 0 | Q14: =SUM(E14:P14) -> 0 | S14: =SUM(E14:E14) -> 0 | U14: =SUM($E14:F14) -> 0 | V14: =SUM($E14:G14) -> 0 | W14: =SUM($E14:H14) -> 0 | X14: =SUM($E14:I14) -> 0 | Y14: =SUM($E14:J14) -> 0 | Z14: =SUM($E14:K14) -> 0 | AA14: =SUM($E14:L14) -> 0 | AB14: =SUM($E14:M14) -> 0 | ... AE14: =SUM($E14:P14) -> 0 | AG14: =_xlfn.XLOOKUP(A14,'מצטבר יוני'!A:A,'מצטבר יוני'!H:H) -> 3576.15 | AI14: =AJ14 -> 5000 | AJ14: =_xlfn.XLOOKUP($A14,'[1]ישראל חציון שני הערכה '!$B:$B,'[1]ישראל חציון שני הערכה '!L:L) -> 5000 | AK14: =_xlfn.XLOOKUP($A14,'[1]ישראל חציון שני הערכה '!$B:$B,'[1]ישראל חציון שני הערכה '!M:M) -> 5000 | AL14: =_xlfn.XLOOKUP($A14,'[1]ישראל חציון שני הערכה '!$B:$B,'[1]ישראל חציון שני הערכה '!N:N) -> 5000 | AM14: =_xlfn.XLOOKUP($A14,'[1]ישראל חציון שני הערכה '!$B:$B,'[1]ישראל חציון שני הערכה '!O:O) -> 5000 | AN14: =_xlfn.XLOOKUP($A14,'[1]ישראל חציון שני הערכה '!$B:$B,'[1]ישראל חציון שני הערכה '!P:P) -> 5000 | AO14: =SUM(AI14:AN14) -> 30000 | AP14: =SUM(AI14:AN14)+Y14 -> 30000 | AR14: =AI14+AG14 -> 8576.15 | AS14: =AR14+AJ14 -> 13576.15 | AT14: =AS14+AK14 -> 18576.15 | AU14: =AT14+AL14 -> 23576.15 | AV14: =AU14+AM14 -> 28576.15 | AW14: =AV14+AN14 -> 33576.15
A15: 16 | B15: חנויות ספורט | C15: חנויות ספורט | D15: ISRAEL | E15: 0 | F15: 0 | G15: 0 | H15: 0 | I15: 0 | J15: 0 | K15: 0 | L15: 0 | M15: 0 | N15: 0 | O15: 0 | P15: 0 | Q15: =SUM(E15:P15) -> 0 | S15: =SUM(E15:E15) -> 0 | U15: =SUM($E15:F15) -> 0 | V15: =SUM($E15:G15) -> 0 | W15: =SUM($E15:H15) -> 0 | X15: =SUM($E15:I15) -> 0 | Y15: =SUM($E15:J15) -> 0 | Z15: =SUM($E15:K15) -> 0 | AA15: =SUM($E15:L15) -> 0 | AB15: =SUM($E15:M15) -> 0 | ... AE15: =SUM($E15:P15) -> 0 | AI15: =AJ15 -> 0 | AO15: =SUM(AI15:AN15) -> 0 | AP15: =SUM(AI15:AN15)+Y15 -> 0 | AR15: =AI15+AG15 -> 0 | AS15: =AR15+AJ15 -> 0 | AT15: =AS15+AK15 -> 0 | AU15: =AT15+AL15 -> 0 | AV15: =AU15+AM15 -> 0 | AW15: =AV15+AN15 -> 0
A16: 13 | B16: בתי חולים ושרות | C16: בתי חולים ושרות | D16: ISRAEL | E16: 0 | F16: 0 | G16: 0 | H16: 50000 | I16: 50000 | J16: 50000 | K16: 50000 | L16: 50000 | M16: 50000 | N16: 50000 | O16: 50000 | P16: 0 | Q16: =SUM(E16:P16) -> 400000 | S16: =SUM(E16:E16) -> 0 | U16: =SUM($E16:F16) -> 0 | V16: =SUM($E16:G16) -> 0 | W16: =SUM($E16:H16) -> 50000 | X16: =SUM($E16:I16) -> 100000 | Y16: =SUM($E16:J16) -> 150000 | Z16: =SUM($E16:K16) -> 200000 | AA16: =SUM($E16:L16) -> 250000 | AB16: =SUM($E16:M16) -> 300000 | ... AE16: =SUM($E16:P16) -> 400000 | AG16: =_xlfn.XLOOKUP(A16,'מצטבר יוני'!A:A,'מצטבר יוני'!H:H) -> 7748.72 | AI16: =AJ16 -> 5000 | AJ16: =_xlfn.XLOOKUP($A16,'[1]ישראל חציון שני הערכה '!$B:$B,'[1]ישראל חציון שני הערכה '!L:L) -> 5000 | AK16: =_xlfn.XLOOKUP($A16,'[1]ישראל חציון שני הערכה '!$B:$B,'[1]ישראל חציון שני הערכה '!M:M) -> 5000 | AL16: =_xlfn.XLOOKUP($A16,'[1]ישראל חציון שני הערכה '!$B:$B,'[1]ישראל חציון שני הערכה '!N:N) -> 5000 | AM16: =_xlfn.XLOOKUP($A16,'[1]ישראל חציון שני הערכה '!$B:$B,'[1]ישראל חציון שני הערכה '!O:O) -> 5000 | AN16: =_xlfn.XLOOKUP($A16,'[1]ישראל חציון שני הערכה '!$B:$B,'[1]ישראל חציון שני הערכה '!P:P) -> 5000 | AO16: =SUM(AI16:AN16) -> 30000 | AP16: =SUM(AI16:AN16)+Y16 -> 180000 | AR16: =AI16+AG16 -> 12748.72 | AS16: =AR16+AJ16 -> 17748.72 | AT16: =AS16+AK16 -> 22748.72 | AU16: =AT16+AL16 -> 27748.72 | AV16: =AU16+AM16 -> 32748.72 | AW16: =AV16+AN16 -> 37748.72
A17: 9 | B17: מכוני פיזיותרפיה | C17: מכוני פיזיותרפיה | D17: ISRAEL | E17: 16666.667 | F17: 15873.016 | G17: 18253.968 | H17: 13492.063 | I17: 15873.016 | J17: 17460.317 | K17: 17460.317 | L17: 17460.317 | M17: 15079.365 | N17: 16666.667 | O17: 17460.317 | P17: 18253.968 | Q17: =SUM(E17:P17) -> 200000 | S17: =SUM(E17:E17) -> 16666.667 | U17: =SUM($E17:F17) -> 32539.683 | V17: =SUM($E17:G17) -> 50793.651 | W17: =SUM($E17:H17) -> 64285.714 | X17: =SUM($E17:I17) -> 80158.73 | Y17: =SUM($E17:J17) -> 97619.048 | Z17: =SUM($E17:K17) -> 115079.37 | AA17: =SUM($E17:L17) -> 132539.68 | AB17: =SUM($E17:M17) -> 147619.05 | ... AE17: =SUM($E17:P17) -> 200000 | AG17: =_xlfn.XLOOKUP(A17,'מצטבר יוני'!A:A,'מצטבר יוני'!H:H) -> 89111.1 | AI17: =AJ17 -> 25000 | AJ17: =_xlfn.XLOOKUP($A17,'[1]ישראל חציון שני הערכה '!$B:$B,'[1]ישראל חציון שני הערכה '!L:L) -> 25000 | AK17: =_xlfn.XLOOKUP($A17,'[1]ישראל חציון שני הערכה '!$B:$B,'[1]ישראל חציון שני הערכה '!M:M) -> 25000 | AL17: =_xlfn.XLOOKUP($A17,'[1]ישראל חציון שני הערכה '!$B:$B,'[1]ישראל חציון שני הערכה '!N:N) -> 25000 | AM17: =_xlfn.XLOOKUP($A17,'[1]ישראל חציון שני הערכה '!$B:$B,'[1]ישראל חציון שני הערכה '!O:O) -> 25000 | AN17: =_xlfn.XLOOKUP($A17,'[1]ישראל חציון שני הערכה '!$B:$B,'[1]ישראל חציון שני הערכה '!P:P) -> 25000 | AO17: =SUM(AI17:AN17) -> 150000 | AP17: =SUM(AI17:AN17)+Y17 -> 247619.05 | AR17: =AI17+AG17 -> 114111.1 | AS17: =AR17+AJ17 -> 139111.1 | AT17: =AS17+AK17 -> 164111.1 | AU17: =AT17+AL17 -> 189111.1 | AV17: =AU17+AM17 -> 214111.1 | AW17: =AV17+AN17 -> 239111.1
A18: 2 | B18: לקוחות אינטרנט | C18: לקוחות אינטרנט | D18: ISRAEL | E18: 296610.17 | F18: 444915.25 | G18: 489406.78 | H18: 453601.69 | I18: 592182.2 | J18: 888273.73 | K18: 977100.85 | L18: 1159556.8 | M18: 1012800 | N18: 1300521.2 | O18: 1684810.2 | P18: 1488884.7 | Q18: 10788664 | S18: =SUM(E18:E18) -> 296610.17 | U18: =SUM($E18:F18) -> 741525.42 | V18: =SUM($E18:G18) -> 1230932.2 | W18: =SUM($E18:H18) -> 1684533.9 | X18: =SUM($E18:I18) -> 2276716.1 | Y18: =SUM($E18:J18) -> 3164989.8 | Z18: =SUM($E18:K18) -> 4142090.7 | AA18: =SUM($E18:L18) -> 5301647.5 | AB18: =SUM($E18:M18) -> 6314447.5 | ... AE18: =SUM($E18:P18) -> 10788664 | AG18: =_xlfn.XLOOKUP(A18,'מצטבר יוני'!A:A,'מצטבר יוני'!H:H) -> 2231238.2 | AI18: 450000 | AJ18: =_xlfn.XLOOKUP($A18,'[1]ישראל חציון שני הערכה '!$B:$B,'[1]ישראל חציון שני הערכה '!L:L) -> 481500 | AK18: =_xlfn.XLOOKUP($A18,'[1]ישראל חציון שני הערכה '!$B:$B,'[1]ישראל חציון שני הערכה '!M:M) -> 977100.85 | AL18: =_xlfn.XLOOKUP($A18,'[1]ישראל חציון שני הערכה '!$B:$B,'[1]ישראל חציון שני הערכה '!N:N) -> 1159556.8 | AM18: =_xlfn.XLOOKUP($A18,'[1]ישראל חציון שני הערכה '!$B:$B,'[1]ישראל חציון שני הערכה '!O:O) -> 1012800 | AN18: =_xlfn.XLOOKUP($A18,'[1]ישראל חציון שני הערכה '!$B:$B,'[1]ישראל חציון שני הערכה '!P:P) -> 1300521.2 | AO18: =SUM(AI18:AN18) -> 5381478.8 | AP18: =SUM(AI18:AN18)+Y18 -> 8546468.6 | AR18: =AI18+AG18 -> 2681238.2 | AS18: =AR18+AJ18 -> 3162738.2 | AT18: =AS18+AK18 -> 4139839 | AU18: =AT18+AL18 -> 5299395.8 | AV18: =AU18+AM18 -> 6312195.8 | AW18: =AV18+AN18 -> 7612717
A19: 12 | B19: סופר פארם מרקט פלייס | C19: סופר פארם מרקט פלייס | D19: ISRAEL | E19: 2536.9283 | F19: 2536.9283 | G19: 2536.9283 | H19: 2536.9283 | I19: 2536.9283 | J19: 2536.9283 | K19: 2536.9283 | L19: 2536.9283 | M19: 2536.9283 | N19: 2536.9283 | O19: 2536.9283 | P19: 2536.9283 | Q19: 30443.14 | S19: =SUM(E19:E19) -> 2536.9283 | U19: =SUM($E19:F19) -> 5073.8567 | V19: =SUM($E19:G19) -> 7610.785 | W19: =SUM($E19:H19) -> 10147.713 | X19: =SUM($E19:I19) -> 12684.642 | Y19: =SUM($E19:J19) -> 15221.57 | Z19: =SUM($E19:K19) -> 17758.498 | AA19: =SUM($E19:L19) -> 20295.427 | AB19: =SUM($E19:M19) -> 22832.355 | ... AE19: =SUM($E19:P19) -> 30443.14 | AG19: =_xlfn.XLOOKUP(A19,'מצטבר יוני'!A:A,'מצטבר יוני'!H:H) -> 9807.02 | AI19: =AJ19 -> 5000 | AJ19: =_xlfn.XLOOKUP($A19,'[1]ישראל חציון שני הערכה '!$B:$B,'[1]ישראל חציון שני הערכה '!L:L) -> 5000 | AK19: =_xlfn.XLOOKUP($A19,'[1]ישראל חציון שני הערכה '!$B:$B,'[1]ישראל חציון שני הערכה '!M:M) -> 5000 | AL19: =_xlfn.XLOOKUP($A19,'[1]ישראל חציון שני הערכה '!$B:$B,'[1]ישראל חציון שני הערכה '!N:N) -> 5000 | AM19: =_xlfn.XLOOKUP($A19,'[1]ישראל חציון שני הערכה '!$B:$B,'[1]ישראל חציון שני הערכה '!O:O) -> 5000 | AN19: =_xlfn.XLOOKUP($A19,'[1]ישראל חציון שני הערכה '!$B:$B,'[1]ישראל חציון שני הערכה '!P:P) -> 5000 | AO19: =SUM(AI19:AN19) -> 30000 | AP19: =SUM(AI19:AN19)+Y19 -> 45221.57 | AR19: =AI19+AG19 -> 14807.02 | AS19: =AR19+AJ19 -> 19807.02 | AT19: =AS19+AK19 -> 24807.02 | AU19: =AT19+AL19 -> 29807.02 | AV19: =AU19+AM19 -> 34807.02 | AW19: =AV19+AN19 -> 39807.02
A20: 15 | B20: חנויות נעליים | C20: חנויות נעליים | D20: ISRAEL | E20: 0 | F20: 0 | G20: 0 | H20: 12500 | I20: 0 | J20: 0 | K20: 0 | L20: 0 | M20: 0 | N20: 0 | O20: 12500 | P20: 0 | Q20: =SUM(E20:P20) -> 25000 | S20: =SUM(E20:E20) -> 0 | U20: =SUM($E20:F20) -> 0 | V20: =SUM($E20:G20) -> 0 | W20: =SUM($E20:H20) -> 12500 | X20: =SUM($E20:I20) -> 12500 | Y20: =SUM($E20:J20) -> 12500 | Z20: =SUM($E20:K20) -> 12500 | AA20: =SUM($E20:L20) -> 12500 | AB20: =SUM($E20:M20) -> 12500 | ... AE20: =SUM($E20:P20) -> 25000 | AG20: =_xlfn.XLOOKUP(A20,'מצטבר יוני'!A:A,'מצטבר יוני'!H:H) -> 1896.82 | AI20: =AJ20 -> 5000 | AJ20: =_xlfn.XLOOKUP($A20,'[1]ישראל חציון שני הערכה '!$B:$B,'[1]ישראל חציון שני הערכה '!L:L) -> 5000 | AK20: =_xlfn.XLOOKUP($A20,'[1]ישראל חציון שני הערכה '!$B:$B,'[1]ישראל חציון שני הערכה '!M:M) -> 5000 | AL20: =_xlfn.XLOOKUP($A20,'[1]ישראל חציון שני הערכה '!$B:$B,'[1]ישראל חציון שני הערכה '!N:N) -> 5000 | AM20: =_xlfn.XLOOKUP($A20,'[1]ישראל חציון שני הערכה '!$B:$B,'[1]ישראל חציון שני הערכה '!O:O) -> 5000 | AN20: =_xlfn.XLOOKUP($A20,'[1]ישראל חציון שני הערכה '!$B:$B,'[1]ישראל חציון שני הערכה '!P:P) -> 5000 | AO20: =SUM(AI20:AN20) -> 30000 | AP20: =SUM(AI20:AN20)+Y20 -> 42500 | AR20: =AI20+AG20 -> 6896.82 | AS20: =AR20+AJ20 -> 11896.82 | AT20: =AS20+AK20 -> 16896.82 | AU20: =AT20+AL20 -> 21896.82 | AV20: =AU20+AM20 -> 26896.82 | AW20: =AV20+AN20 -> 31896.82
B21: סה"כ ישראל | E21: =SUM(E5:E20) -> 1852563.8 | F21: =SUM(F5:F20) -> 2046896.6 | G21: =SUM(G5:G20) -> 2233304.8 | H21: =SUM(H5:H20) -> 1997166.4 | I21: =SUM(I5:I20) -> 2297163.6 | J21: =SUM(J5:J20) -> 2723199.5 | K21: =SUM(K5:K20) -> 2812026.7 | L21: =SUM(L5:L20) -> 2994482.6 | ... Q21: =SUM(Q5:Q20) -> 31460107 | S21: =SUM(S5:S20) -> 1852563.8 | U21: =SUM(U5:U20) -> 3899460.4 | V21: =SUM(V5:V20) -> 6132765.2 | W21: =SUM(W5:W20) -> 8129931.6 | X21: =SUM(X5:X20) -> 10427095 | Y21: =SUM(Y5:Y20) -> 13150295 | Z21: =SUM(Z5:Z20) -> 15962321 | AA21: =SUM(AA5:AA20) -> 18956804 | AB21: =SUM(AB5:AB20) -> 21642613 | ... AE21: =SUM(AE5:AE20) -> 31460107 | AG21: =SUM(AG5:AG20) -> 9870594.3 | AI21: =SUM(AI5:AI20) -> 2100000 | AJ21: =SUM(AJ5:AJ20) -> 2131500 | AK21: =SUM(AK5:AK20) -> 2627100.8 | AL21: =SUM(AL5:AL20) -> 2809556.8 | AM21: =SUM(AM5:AM20) -> 2662800 | AN21: =SUM(AN5:AN20) -> 2950521.2 | AO21: =SUM(AO5:AO20) -> 15281479 | AP21: =SUM(AP5:AP20) -> 28431774 | AR21: =AI21+AG21 -> 11970594 | AS21: =AR21+AJ21 -> 14102094 | AT21: =AS21+AK21 -> 16729195 | AU21: =AT21+AL21 -> 19538752 | AV21: =AU21+AM21 -> 22201552 | AW21: =AV21+AN21 -> 25152073
A22: 50 | B22: Total - 301 - Amazon | C22: AMAZON | D22: USA | E22: 272275.11 | F22: 312309.92 | G22: 332824.44 | H22: 367136.19 | I22: 398486.47 | J22: 428463.75 | K22: 461212.92 | L22: 481801.95 | M22: 477395.47 | N22: 443955.52 | O22: 398561.08 | P22: 402156.53 | Q22: 4776579.4 | S22: =SUM(E22:E22) -> 272275.11 | U22: =SUM($E22:F22) -> 584585.03 | V22: =SUM($E22:G22) -> 917409.48 | W22: =SUM($E22:H22) -> 1284545.7 | X22: =SUM($E22:I22) -> 1683032.1 | Y22: =SUM($E22:J22) -> 2111495.9 | Z22: =SUM($E22:K22) -> 2572708.8 | AA22: =SUM($E22:L22) -> 3054510.8 | AB22: =SUM($E22:M22) -> 3531906.2 | ... AE22: =SUM($E22:P22) -> 4776579.4 | AG22: =_xlfn.XLOOKUP(A22,'מצטבר יוני'!A:A,'מצטבר יוני'!H:H) -> 1254357.4 | AI22: =[1]אמזון!$M$29 -> 265966.8 | AJ22: =[1]אמזון!$M$30 -> 305012.4 | AK22: =[1]אמזון!$M$31 -> 327115.8 | AL22: =[1]אמזון!$M$32 -> 321888.6 | AM22: =[1]אמזון!$M$33 -> 326122.5 | AN22: =[1]אמזון!$M$34 -> 297561 | AO22: =SUM(AI22:AN22) -> 1843667.1 | AP22: =SUM(AI22:AN22)+Y22 -> 3955163 | AR22: =AI22+AG22 -> 1520324.2 | AS22: =AR22+AJ22 -> 1825336.6 | AT22: =AS22+AK22 -> 2152452.4 | AU22: =AT22+AL22 -> 2474341 | AV22: =AU22+AM22 -> 2800463.5 | AW22: =AV22+AN22 -> 3098024.5
A23: 20 | B23: Total - 202 - Super-Pharm POLAND | C23: SUPER PHARM POLAND | D23: POLAND | F23: =980000*0.24 -> 235200 | I23: =980000*0.24 -> 235200 | K23: =980000*0.21 -> 205800 | N23: =980000*0.16 -> 156800 | P23: =980000*0.15 -> 147000 | Q23: =SUM(E23:P23) -> 980000 | R23: 980000 | S23: =SUM(E23:E23) -> 0 | U23: =SUM($E23:F23) -> 235200 | V23: =SUM($E23:G23) -> 235200 | W23: =SUM($E23:H23) -> 235200 | X23: =SUM($E23:I23) -> 470400 | Y23: =SUM($E23:J23) -> 470400 | Z23: =SUM($E23:K23) -> 676200 | AA23: =SUM($E23:L23) -> 676200 | AB23: =SUM($E23:M23) -> 676200 | ... AE23: =SUM($E23:P23) -> 980000 | AG23: =_xlfn.XLOOKUP(A23,'מצטבר יוני'!A:A,'מצטבר יוני'!H:H) -> 342081.02 | AI23: =_xlfn.XLOOKUP($A23,'[1]מפיצים הערכה לחציון שני '!$L:$L,'[1]מפיצים הערכה לחציון שני '!O:O) -> 0 | AJ23: =_xlfn.XLOOKUP($A23,'[1]מפיצים הערכה לחציון שני '!$L:$L,'[1]מפיצים הערכה לחציון שני '!P:P) -> 130000 | AK23: =_xlfn.XLOOKUP($A23,'[1]מפיצים הערכה לחציון שני '!$L:$L,'[1]מפיצים הערכה לחציון שני '!Q:Q) -> 0 | AL23: =_xlfn.XLOOKUP($A23,'[1]מפיצים הערכה לחציון שני '!$L:$L,'[1]מפיצים הערכה לחציון שני '!R:R) -> 300000 | AM23: =_xlfn.XLOOKUP($A23,'[1]מפיצים הערכה לחציון שני '!$L:$L,'[1]מפיצים הערכה לחציון שני '!S:S) -> 0 | AN23: =_xlfn.XLOOKUP($A23,'[1]מפיצים הערכה לחציון שני '!$L:$L,'[1]מפיצים הערכה לחציון שני '!T:T) -> 150000 | AO23: =SUM(AI23:AN23) -> 580000 | AP23: =SUM(AI23:AN23)+Y23 -> 1050400 | AR23: =AI23+AG23 -> 342081.02 | AS23: =AR23+AJ23 -> 472081.02 | AT23: =AS23+AK23 -> 472081.02 | AU23: =AT23+AL23 -> 772081.02 | AV23: =AU23+AM23 -> 772081.02 | AW23: =AV23+AN23 -> 922081.02
A24: 21 | B24: Total - 203 - Ortho- Partner ag SWITZERLAND | C24: ORTHO- PARTNER AG. | D24: SWITZERLAND | E24: 124895.37 | F24: =3779*3.1 -> 11714.9 | G24: 15000 | H24: 100000 | I24: 15000 | J24: 35000 | K24: 13390 | L24: 120000 | M24: 15000 | O24: 200000 | Q24: =SUM(E24:P24) -> 650000.27 | R24: 650000 | S24: =SUM(E24:E24) -> 124895.37 | U24: =SUM($E24:F24) -> 136610.27 | V24: =SUM($E24:G24) -> 151610.27 | W24: =SUM($E24:H24) -> 251610.27 | X24: =SUM($E24:I24) -> 266610.27 | Y24: =SUM($E24:J24) -> 301610.27 | Z24: =SUM($E24:K24) -> 315000.27 | AA24: =SUM($E24:L24) -> 435000.27 | AB24: =SUM($E24:M24) -> 450000.27 | ... AE24: =SUM($E24:P24) -> 650000.27 | AG24: =_xlfn.XLOOKUP(A24,'מצטבר יוני'!A:A,'מצטבר יוני'!H:H) -> 333276.52 | AI24: =_xlfn.XLOOKUP($A24,'[1]מפיצים הערכה לחציון שני '!$L:$L,'[1]מפיצים הערכה לחציון שני '!O:O) -> 0 | AJ24: =_xlfn.XLOOKUP($A24,'[1]מפיצים הערכה לחציון שני '!$L:$L,'[1]מפיצים הערכה לחציון שני '!P:P) -> 20000 | AK24: =_xlfn.XLOOKUP($A24,'[1]מפיצים הערכה לחציון שני '!$L:$L,'[1]מפיצים הערכה לחציון שני '!Q:Q) -> 40000 | AL24: =_xlfn.XLOOKUP($A24,'[1]מפיצים הערכה לחציון שני '!$L:$L,'[1]מפיצים הערכה לחציון שני '!R:R) -> 0 | AM24: =_xlfn.XLOOKUP($A24,'[1]מפיצים הערכה לחציון שני '!$L:$L,'[1]מפיצים הערכה לחציון שני '!S:S) -> 220000 | AN24: =_xlfn.XLOOKUP($A24,'[1]מפיצים הערכה לחציון שני '!$L:$L,'[1]מפיצים הערכה לחציון שני '!T:T) -> 0 | AO24: =SUM(AI24:AN24) -> 280000 | AP24: =SUM(AI24:AN24)+Y24 -> 581610.27 | AR24: =AI24+AG24 -> 333276.52 | AS24: =AR24+AJ24 -> 353276.52 | AT24: =AS24+AK24 -> 393276.52 | AU24: =AT24+AL24 -> 393276.52 | AV24: =AU24+AM24 -> 613276.52 | AW24: =AV24+AN24 -> 613276.52
A25: 22 | B25: Total - 204 - Sanaflex Anatomic GREECE | C25: SANAFLEX ANATOMIC | D25: GREECE | E25: 67158.97 | G25: 95000 | I25: 85000 | K25: 85000 | M25: 85000 | O25: 82841 | Q25: =SUM(E25:P25) -> 499999.97 | R25: 500000 | S25: =SUM(E25:E25) -> 67158.97 | U25: =SUM($E25:F25) -> 67158.97 | V25: =SUM($E25:G25) -> 162158.97 | W25: =SUM($E25:H25) -> 162158.97 | X25: =SUM($E25:I25) -> 247158.97 | Y25: =SUM($E25:J25) -> 247158.97 | Z25: =SUM($E25:K25) -> 332158.97 | AA25: =SUM($E25:L25) -> 332158.97 | AB25: =SUM($E25:M25) -> 417158.97 | ... AE25: =SUM($E25:P25) -> 499999.97 | AG25: =_xlfn.XLOOKUP(A25,'מצטבר יוני'!A:A,'מצטבר יוני'!H:H) -> 307053.13 | AI25: =_xlfn.XLOOKUP($A25,'[1]מפיצים הערכה לחציון שני '!$L:$L,'[1]מפיצים הערכה לחציון שני '!O:O) -> 0 | AJ25: =_xlfn.XLOOKUP($A25,'[1]מפיצים הערכה לחציון שני '!$L:$L,'[1]מפיצים הערכה לחציון שני '!P:P) -> 0 | AK25: =_xlfn.XLOOKUP($A25,'[1]מפיצים הערכה לחציון שני '!$L:$L,'[1]מפיצים הערכה לחציון שני '!Q:Q) -> 75000 | AL25: =_xlfn.XLOOKUP($A25,'[1]מפיצים הערכה לחציון שני '!$L:$L,'[1]מפיצים הערכה לחציון שני '!R:R) -> 0 | AM25: =_xlfn.XLOOKUP($A25,'[1]מפיצים הערכה לחציון שני '!$L:$L,'[1]מפיצים הערכה לחציון שני '!S:S) -> 75000 | AN25: =_xlfn.XLOOKUP($A25,'[1]מפיצים הערכה לחציון שני '!$L:$L,'[1]מפיצים הערכה לחציון שני '!T:T) -> 0 | AO25: =SUM(AI25:AN25) -> 150000 | AP25: =SUM(AI25:AN25)+Y25 -> 397158.97 | AR25: =AI25+AG25 -> 307053.13 | AS25: =AR25+AJ25 -> 307053.13 | AT25: =AS25+AK25 -> 382053.13 | AU25: =AT25+AL25 -> 382053.13 | AV25: =AU25+AM25 -> 457053.13 | AW25: =AV25+AN25 -> 457053.13
A26: 23 | B26: Total - 205 - Health Care Prod. Gmbh GERMANY | C26: HEALTH CARE PROD. GMBH | D26: GERMANY | E26: 15774.92 | G26: 17000 | H26: 10000 | I26: 17000 | J26: 10000 | K26: 17000 | L26: 10000 | M26: 17000 | N26: 9225 | O26: 17000 | Q26: =SUM(E26:P26) -> 139999.92 | R26: 140000 | S26: =SUM(E26:E26) -> 15774.92 | U26: =SUM($E26:F26) -> 15774.92 | V26: =SUM($E26:G26) -> 32774.92 | W26: =SUM($E26:H26) -> 42774.92 | X26: =SUM($E26:I26) -> 59774.92 | Y26: =SUM($E26:J26) -> 69774.92 | Z26: =SUM($E26:K26) -> 86774.92 | AA26: =SUM($E26:L26) -> 96774.92 | AB26: =SUM($E26:M26) -> 113774.92 | ... AE26: =SUM($E26:P26) -> 139999.92 | AG26: =_xlfn.XLOOKUP(A26,'מצטבר יוני'!A:A,'מצטבר יוני'!H:H) -> 76678.59 | AI26: =_xlfn.XLOOKUP($A26,'[1]מפיצים הערכה לחציון שני '!$L:$L,'[1]מפיצים הערכה לחציון שני '!O:O) -> 20000 | AJ26: =_xlfn.XLOOKUP($A26,'[1]מפיצים הערכה לחציון שני '!$L:$L,'[1]מפיצים הערכה לחציון שני '!P:P) -> 0 | AK26: =_xlfn.XLOOKUP($A26,'[1]מפיצים הערכה לחציון שני '!$L:$L,'[1]מפיצים הערכה לחציון שני '!Q:Q) -> 15000 | AL26: =_xlfn.XLOOKUP($A26,'[1]מפיצים הערכה לחציון שני '!$L:$L,'[1]מפיצים הערכה לחציון שני '!R:R) -> 0 | AM26: =_xlfn.XLOOKUP($A26,'[1]מפיצים הערכה לחציון שני '!$L:$L,'[1]מפיצים הערכה לחציון שני '!S:S) -> 20000 | AN26: =_xlfn.XLOOKUP($A26,'[1]מפיצים הערכה לחציון שני '!$L:$L,'[1]מפיצים הערכה לחציון שני '!T:T) -> 0 | AO26: =SUM(AI26:AN26) -> 55000 | AP26: =SUM(AI26:AN26)+Y26 -> 124774.92 | AR26: =AI26+AG26 -> 96678.59 | AS26: =AR26+AJ26 -> 96678.59 | AT26: =AS26+AK26 -> 111678.59 | AU26: =AT26+AL26 -> 111678.59 | AV26: =AU26+AM26 -> 131678.59 | AW26: =AV26+AN26 -> 131678.59
A27: 24 | B27: Total - 206 - Orthomed Ltd BULGARIA | C27: ORTHOMED LTD | D27: BULGARIA | G27: 5000 | H27: 5000 | I27: 5000 | J27: 5000 | K27: 5000 | L27: 5000 | M27: 5000 | N27: 5000 | O27: 5000 | P27: 5000 | Q27: =SUM(E27:P27) -> 50000 | R27: 50000 | S27: =SUM(E27:E27) -> 0 | U27: =SUM($E27:F27) -> 0 | V27: =SUM($E27:G27) -> 5000 | W27: =SUM($E27:H27) -> 10000 | X27: =SUM($E27:I27) -> 15000 | Y27: =SUM($E27:J27) -> 20000 | Z27: =SUM($E27:K27) -> 25000 | AA27: =SUM($E27:L27) -> 30000 | AB27: =SUM($E27:M27) -> 35000 | ... AE27: =SUM($E27:P27) -> 50000 | AG27: =_xlfn.XLOOKUP(A27,'מצטבר יוני'!A:A,'מצטבר יוני'!H:H) -> 0 | AI27: =_xlfn.XLOOKUP($A27,'[1]מפיצים הערכה לחציון שני '!$L:$L,'[1]מפיצים הערכה לחציון שני '!O:O) -> 0 | AJ27: =_xlfn.XLOOKUP($A27,'[1]מפיצים הערכה לחציון שני '!$L:$L,'[1]מפיצים הערכה לחציון שני '!P:P) -> 0 | AK27: =_xlfn.XLOOKUP($A27,'[1]מפיצים הערכה לחציון שני '!$L:$L,'[1]מפיצים הערכה לחציון שני '!Q:Q) -> 0 | AL27: =_xlfn.XLOOKUP($A27,'[1]מפיצים הערכה לחציון שני '!$L:$L,'[1]מפיצים הערכה לחציון שני '!R:R) -> 0 | AM27: =_xlfn.XLOOKUP($A27,'[1]מפיצים הערכה לחציון שני '!$L:$L,'[1]מפיצים הערכה לחציון שני '!S:S) -> 0 | AN27: =_xlfn.XLOOKUP($A27,'[1]מפיצים הערכה לחציון שני '!$L:$L,'[1]מפיצים הערכה לחציון שני '!T:T) -> 0 | AO27: =SUM(AI27:AN27) -> 0 | AP27: =SUM(AI27:AN27)+Y27 -> 20000 | AR27: =AI27+AG27 -> 0 | AS27: =AR27+AJ27 -> 0 | AT27: =AS27+AK27 -> 0 | AU27: =AT27+AL27 -> 0 | AV27: =AU27+AM27 -> 0 | AW27: =AV27+AN27 -> 0
A28: 25 | B28: Total - 207 - Salus HUNGARY | C28: SALUS | D28: HUNGARY | H28: 150000 | K28: 150000 | O28: 150000 | Q28: =SUM(E28:P28) -> 450000 | R28: 450000 | S28: =SUM(E28:E28) -> 0 | U28: =SUM($E28:F28) -> 0 | V28: =SUM($E28:G28) -> 0 | W28: =SUM($E28:H28) -> 150000 | X28: =SUM($E28:I28) -> 150000 | Y28: =SUM($E28:J28) -> 150000 | Z28: =SUM($E28:K28) -> 300000 | AA28: =SUM($E28:L28) -> 300000 | AB28: =SUM($E28:M28) -> 300000 | ... AE28: =SUM($E28:P28) -> 450000 | AG28: =_xlfn.XLOOKUP(A28,'מצטבר יוני'!A:A,'מצטבר יוני'!H:H) -> 144147.47 | AI28: =_xlfn.XLOOKUP($A28,'[1]מפיצים הערכה לחציון שני '!$L:$L,'[1]מפיצים הערכה לחציון שני '!O:O) -> 240000 | AJ28: =_xlfn.XLOOKUP($A28,'[1]מפיצים הערכה לחציון שני '!$L:$L,'[1]מפיצים הערכה לחציון שני '!P:P) -> 0 | AK28: =_xlfn.XLOOKUP($A28,'[1]מפיצים הערכה לחציון שני '!$L:$L,'[1]מפיצים הערכה לחציון שני '!Q:Q) -> 70000 | AL28: =_xlfn.XLOOKUP($A28,'[1]מפיצים הערכה לחציון שני '!$L:$L,'[1]מפיצים הערכה לחציון שני '!R:R) -> 0 | AM28: =_xlfn.XLOOKUP($A28,'[1]מפיצים הערכה לחציון שני '!$L:$L,'[1]מפיצים הערכה לחציון שני '!S:S) -> 70000 | AN28: =_xlfn.XLOOKUP($A28,'[1]מפיצים הערכה לחציון שני '!$L:$L,'[1]מפיצים הערכה לחציון שני '!T:T) -> 0 | AO28: =SUM(AI28:AN28) -> 380000 | AP28: =SUM(AI28:AN28)+Y28 -> 530000 | AR28: =AI28+AG28 -> 384147.47 | AS28: =AR28+AJ28 -> 384147.47 | AT28: =AS28+AK28 -> 454147.47 | AU28: =AT28+AL28 -> 454147.47 | AV28: =AU28+AM28 -> 524147.47 | AW28: =AV28+AN28 -> 524147.47
A29: 26 | B29: Total - 216 - Max Konnaris CYPRUS | C29: MAX KONNARIS LTD | D29: CYPRUS | F29: 40000 | H29: 40000 | J29: 40000 | L29: 40000 | O29: 40000 | Q29: =SUM(E29:P29) -> 200000 | R29: 200000 | S29: =SUM(E29:E29) -> 0 | T29: =R29-Q29 -> 0 | U29: =SUM($E29:F29) -> 40000 | V29: =SUM($E29:G29) -> 40000 | W29: =SUM($E29:H29) -> 80000 | X29: =SUM($E29:I29) -> 80000 | Y29: =SUM($E29:J29) -> 120000 | Z29: =SUM($E29:K29) -> 120000 | AA29: =SUM($E29:L29) -> 160000 | AB29: =SUM($E29:M29) -> 160000 | ... AE29: =SUM($E29:P29) -> 200000 | AG29: =_xlfn.XLOOKUP(A29,'מצטבר יוני'!A:A,'מצטבר יוני'!H:H) -> 60694.01 | AI29: =_xlfn.XLOOKUP($A29,'[1]מפיצים הערכה לחציון שני '!$L:$L,'[1]מפיצים הערכה לחציון שני '!O:O) -> 0 | AJ29: =_xlfn.XLOOKUP($A29,'[1]מפיצים הערכה לחציון שני '!$L:$L,'[1]מפיצים הערכה לחציון שני '!P:P) -> 0 | AK29: =_xlfn.XLOOKUP($A29,'[1]מפיצים הערכה לחציון שני '!$L:$L,'[1]מפיצים הערכה לחציון שני '!Q:Q) -> 20000 | AL29: =_xlfn.XLOOKUP($A29,'[1]מפיצים הערכה לחציון שני '!$L:$L,'[1]מפיצים הערכה לחציון שני '!R:R) -> 0 | AM29: =_xlfn.XLOOKUP($A29,'[1]מפיצים הערכה לחציון שני '!$L:$L,'[1]מפיצים הערכה לחציון שני '!S:S) -> 20000 | AN29: =_xlfn.XLOOKUP($A29,'[1]מפיצים הערכה לחציון שני '!$L:$L,'[1]מפיצים הערכה לחציון שני '!T:T) -> 0 | AO29: =SUM(AI29:AN29) -> 40000 | AP29: =SUM(AI29:AN29)+Y29 -> 160000 | AR29: =AI29+AG29 -> 60694.01 | AS29: =AR29+AJ29 -> 60694.01 | AT29: =AS29+AK29 -> 80694.01 | AU29: =AT29+AL29 -> 80694.01 | AV29: =AU29+AM29 -> 100694.01 | AW29: =AV29+AN29 -> 100694.01
A30: 27 | B30: Total - 208 - Medipal Company NABLUS | C30: MEDIPAL COMPANY | D30: NABLUS | L30: 250000 | Q30: =SUM(E30:P30) -> 250000 | R30: 250000 | S30: =SUM(E30:E30) -> 0 | T30: =R30-Q30 -> 0 | U30: =SUM($E30:F30) -> 0 | V30: =SUM($E30:G30) -> 0 | W30: =SUM($E30:H30) -> 0 | X30: =SUM($E30:I30) -> 0 | Y30: =SUM($E30:J30) -> 0 | Z30: =SUM($E30:K30) -> 0 | AA30: =SUM($E30:L30) -> 250000 | AB30: =SUM($E30:M30) -> 250000 | ... AE30: =SUM($E30:P30) -> 250000 | AG30: =_xlfn.XLOOKUP(A30,'מצטבר יוני'!A:A,'מצטבר יוני'!H:H) -> 0 | AI30: =_xlfn.XLOOKUP($A30,'[1]מפיצים הערכה לחציון שני '!$L:$L,'[1]מפיצים הערכה לחציון שני '!O:O) -> 0 | AJ30: =_xlfn.XLOOKUP($A30,'[1]מפיצים הערכה לחציון שני '!$L:$L,'[1]מפיצים הערכה לחציון שני '!P:P) -> 0 | AK30: =_xlfn.XLOOKUP($A30,'[1]מפיצים הערכה לחציון שני '!$L:$L,'[1]מפיצים הערכה לחציון שני '!Q:Q) -> 150000 | AL30: =_xlfn.XLOOKUP($A30,'[1]מפיצים הערכה לחציון שני '!$L:$L,'[1]מפיצים הערכה לחציון שני '!R:R) -> 100000 | AM30: =_xlfn.XLOOKUP($A30,'[1]מפיצים הערכה לחציון שני '!$L:$L,'[1]מפיצים הערכה לחציון שני '!S:S) -> 0 | AN30: =_xlfn.XLOOKUP($A30,'[1]מפיצים הערכה לחציון שני '!$L:$L,'[1]מפיצים הערכה לחציון שני '!T:T) -> 0 | AO30: =SUM(AI30:AN30) -> 250000 | AP30: =SUM(AI30:AN30)+Y30 -> 250000 | AR30: =AI30+AG30 -> 0 | AS30: =AR30+AJ30 -> 0 | AT30: =AS30+AK30 -> 150000 | AU30: =AT30+AL30 -> 250000 | AV30: =AU30+AM30 -> 250000 | AW30: =AV30+AN30 -> 250000
A31: 28 | B31: Total - 209 - Ortoprofil Prod ROMANIA | C31: ORTOPROFIL PROD. ROMANIA | D31: ROMANIA | E31: 27429.74 | F31: =6735*3.7 -> 24919.5 | G31: =(450000-$E$31-$F$31)/10 -> 39765.076 | H31: =(450000-$E$31-$F$31)/10 -> 39765.076 | I31: =(450000-$E$31-$F$31)/10 -> 39765.076 | J31: =(450000-$E$31-$F$31)/10 -> 39765.076 | K31: =(450000-$E$31-$F$31)/10 -> 39765.076 | L31: =(450000-$E$31-$F$31)/10 -> 39765.076 | M31: =(450000-$E$31-$F$31)/10 -> 39765.076 | N31: =(450000-$E$31-$F$31)/10 -> 39765.076 | ... P31: =(450000-$E$31-$F$31)/10 -> 39765.076 | Q31: =SUM(E31:P31) -> 450000 | R31: 450000 | S31: =SUM(E31:E31) -> 27429.74 | T31: =R31-Q31 -> 0 | U31: =SUM($E31:F31) -> 52349.24 | V31: =SUM($E31:G31) -> 92114.316 | W31: =SUM($E31:H31) -> 131879.39 | X31: =SUM($E31:I31) -> 171644.47 | Y31: =SUM($E31:J31) -> 211409.54 | Z31: =SUM($E31:K31) -> 251174.62 | AA31: =SUM($E31:L31) -> 290939.7 | AB31: =SUM($E31:M31) -> 330704.77 | ... AE31: =SUM($E31:P31) -> 450000 | AG31: =_xlfn.XLOOKUP(A31,'מצטבר יוני'!A:A,'מצטבר יוני'!H:H) -> 203207.09 | AI31: =_xlfn.XLOOKUP($A31,'[1]מפיצים הערכה לחציון שני '!$L:$L,'[1]מפיצים הערכה לחציון שני '!O:O) -> 40000 | AJ31: =_xlfn.XLOOKUP($A31,'[1]מפיצים הערכה לחציון שני '!$L:$L,'[1]מפיצים הערכה לחציון שני '!P:P) -> 20000 | AK31: =_xlfn.XLOOKUP($A31,'[1]מפיצים הערכה לחציון שני '!$L:$L,'[1]מפיצים הערכה לחציון שני '!Q:Q) -> 40000 | AL31: =_xlfn.XLOOKUP($A31,'[1]מפיצים הערכה לחציון שני '!$L:$L,'[1]מפיצים הערכה לחציון שני '!R:R) -> 20000 | AM31: =_xlfn.XLOOKUP($A31,'[1]מפיצים הערכה לחציון שני '!$L:$L,'[1]מפיצים הערכה לחציון שני '!S:S) -> 40000 | AN31: =_xlfn.XLOOKUP($A31,'[1]מפיצים הערכה לחציון שני '!$L:$L,'[1]מפיצים הערכה לחציון שני '!T:T) -> 15000 | AO31: =SUM(AI31:AN31) -> 175000 | AP31: =SUM(AI31:AN31)+Y31 -> 386409.54 | AR31: =AI31+AG31 -> 243207.09 | AS31: =AR31+AJ31 -> 263207.09 | AT31: =AS31+AK31 -> 303207.09 | AU31: =AT31+AL31 -> 323207.09 | AV31: =AU31+AM31 -> 363207.09 | AW31: =AV31+AN31 -> 378207.09
A32: 29 | B32: Total - 210 - Oy. Ea. Ab. FINLAND | C32: OY. EA. AB. | D32: FINLAND | H32: 35000 | N32: 35000 | Q32: =SUM(E32:P32) -> 70000 | R32: 70000 | S32: =SUM(E32:E32) -> 0 | T32: =R32-Q32 -> 0 | U32: =SUM($E32:F32) -> 0 | V32: =SUM($E32:G32) -> 0 | W32: =SUM($E32:H32) -> 35000 | X32: =SUM($E32:I32) -> 35000 | Y32: =SUM($E32:J32) -> 35000 | Z32: =SUM($E32:K32) -> 35000 | AA32: =SUM($E32:L32) -> 35000 | AB32: =SUM($E32:M32) -> 35000 | ... AE32: =SUM($E32:P32) -> 70000 | AG32: =_xlfn.XLOOKUP(A32,'מצטבר יוני'!A:A,'מצטבר יוני'!H:H) -> 43116.44 | AI32: =_xlfn.XLOOKUP($A32,'[1]מפיצים הערכה לחציון שני '!$L:$L,'[1]מפיצים הערכה לחציון שני '!O:O) -> 0 | AJ32: =_xlfn.XLOOKUP($A32,'[1]מפיצים הערכה לחציון שני '!$L:$L,'[1]מפיצים הערכה לחציון שני '!P:P) -> 0 | AK32: =_xlfn.XLOOKUP($A32,'[1]מפיצים הערכה לחציון שני '!$L:$L,'[1]מפיצים הערכה לחציון שני '!Q:Q) -> 0 | AL32: =_xlfn.XLOOKUP($A32,'[1]מפיצים הערכה לחציון שני '!$L:$L,'[1]מפיצים הערכה לחציון שני '!R:R) -> 30000 | AM32: =_xlfn.XLOOKUP($A32,'[1]מפיצים הערכה לחציון שני '!$L:$L,'[1]מפיצים הערכה לחציון שני '!S:S) -> 0 | AN32: =_xlfn.XLOOKUP($A32,'[1]מפיצים הערכה לחציון שני '!$L:$L,'[1]מפיצים הערכה לחציון שני '!T:T) -> 0 | AO32: =SUM(AI32:AN32) -> 30000 | AP32: =SUM(AI32:AN32)+Y32 -> 65000 | AR32: =AI32+AG32 -> 43116.44 | AS32: =AR32+AJ32 -> 43116.44 | AT32: =AS32+AK32 -> 43116.44 | AU32: =AT32+AL32 -> 73116.44 | AV32: =AU32+AM32 -> 73116.44 | AW32: =AV32+AN32 -> 73116.44
A33: 30 | B33: Total - 201- Seven Gear FINLAND oy | C33: SEVEN GEAR | D33: FINLAND | G33: 20000 | K33: 20000 | O33: =20000-207 -> 19793 | Q33: =SUM(E33:P33) -> 59793 | R33: 59793.3 | S33: =SUM(E33:E33) -> 0 | T33: =R33-Q33 -> 0.3 | U33: =SUM($E33:F33) -> 0 | V33: =SUM($E33:G33) -> 20000 | W33: =SUM($E33:H33) -> 20000 | X33: =SUM($E33:I33) -> 20000 | Y33: =SUM($E33:J33) -> 20000 | Z33: =SUM($E33:K33) -> 40000 | AA33: =SUM($E33:L33) -> 40000 | AB33: =SUM($E33:M33) -> 40000 | ... AE33: =SUM($E33:P33) -> 59793 | AG33: =_xlfn.XLOOKUP(A33,'מצטבר יוני'!A:A,'מצטבר יוני'!H:H) -> 17809.5 | AI33: =_xlfn.XLOOKUP($A33,'[1]מפיצים הערכה לחציון שני '!$L:$L,'[1]מפיצים הערכה לחציון שני '!O:O) -> 0 | AJ33: =_xlfn.XLOOKUP($A33,'[1]מפיצים הערכה לחציון שני '!$L:$L,'[1]מפיצים הערכה לחציון שני '!P:P) -> 0 | AK33: =_xlfn.XLOOKUP($A33,'[1]מפיצים הערכה לחציון שני '!$L:$L,'[1]מפיצים הערכה לחציון שני '!Q:Q) -> 25000 | AL33: =_xlfn.XLOOKUP($A33,'[1]מפיצים הערכה לחציון שני '!$L:$L,'[1]מפיצים הערכה לחציון שני '!R:R) -> 0 | AM33: =_xlfn.XLOOKUP($A33,'[1]מפיצים הערכה לחציון שני '!$L:$L,'[1]מפיצים הערכה לחציון שני '!S:S) -> 0 | AN33: =_xlfn.XLOOKUP($A33,'[1]מפיצים הערכה לחציון שני '!$L:$L,'[1]מפיצים הערכה לחציון שני '!T:T) -> 0 | AO33: =SUM(AI33:AN33) -> 25000 | AP33: =SUM(AI33:AN33)+Y33 -> 45000 | AR33: =AI33+AG33 -> 17809.5 | AS33: =AR33+AJ33 -> 17809.5 | AT33: =AS33+AK33 -> 42809.5 | AU33: =AT33+AL33 -> 42809.5 | AV33: =AU33+AM33 -> 42809.5 | AW33: =AV33+AN33 -> 42809.5
A34: 31 | B34: 211 - Pharmag Lachmair Ges. Mbh AUSTRIA | C34: PHARMAG LACHMAIR GES. MBH | D34: AUSTRIA | G34: 18000 | K34: 18000 | M34: =85000-18000*2 -> 49000 | Q34: =SUM(E34:P34) -> 85000 | R34: 85000 | S34: =SUM(E34:E34) -> 0 | T34: =R34-Q34 -> 0 | U34: =SUM($E34:F34) -> 0 | V34: =SUM($E34:G34) -> 18000 | W34: =SUM($E34:H34) -> 18000 | X34: =SUM($E34:I34) -> 18000 | Y34: =SUM($E34:J34) -> 18000 | Z34: =SUM($E34:K34) -> 36000 | AA34: =SUM($E34:L34) -> 36000 | AB34: =SUM($E34:M34) -> 85000 | ... AE34: =SUM($E34:P34) -> 85000 | AG34: =_xlfn.XLOOKUP(A34,'מצטבר יוני'!A:A,'מצטבר יוני'!H:H) -> 0 | AI34: =_xlfn.XLOOKUP($A34,'[1]מפיצים הערכה לחציון שני '!$L:$L,'[1]מפיצים הערכה לחציון שני '!O:O) -> 0 | AJ34: =_xlfn.XLOOKUP($A34,'[1]מפיצים הערכה לחציון שני '!$L:$L,'[1]מפיצים הערכה לחציון שני '!P:P) -> 0 | AK34: =_xlfn.XLOOKUP($A34,'[1]מפיצים הערכה לחציון שני '!$L:$L,'[1]מפיצים הערכה לחציון שני '!Q:Q) -> 17500 | AL34: =_xlfn.XLOOKUP($A34,'[1]מפיצים הערכה לחציון שני '!$L:$L,'[1]מפיצים הערכה לחציון שני '!R:R) -> 0 | AM34: =_xlfn.XLOOKUP($A34,'[1]מפיצים הערכה לחציון שני '!$L:$L,'[1]מפיצים הערכה לחציון שני '!S:S) -> 0 | AN34: =_xlfn.XLOOKUP($A34,'[1]מפיצים הערכה לחציון שני '!$L:$L,'[1]מפיצים הערכה לחציון שני '!T:T) -> 0 | AO34: =SUM(AI34:AN34) -> 17500 | AP34: =SUM(AI34:AN34)+Y34 -> 35500 | AR34: =AI34+AG34 -> 0 | AS34: =AR34+AJ34 -> 0 | AT34: =AS34+AK34 -> 17500 | AU34: =AT34+AL34 -> 17500 | AV34: =AU34+AM34 -> 17500 | AW34: =AV34+AN34 -> 17500
A35: 32 | B35: Total - 213 - E.f.m.o. SPAIN | C35: E.F.M.O. | D35: SPAIN | E35: 18792.66 | I35: =40000-E35 -> 21207.34 | Q35: =SUM(E35:P35) -> 40000 | R35: 40000 | S35: =SUM(E35:E35) -> 18792.66 | T35: =R35-Q35 -> 0 | U35: =SUM($E35:F35) -> 18792.66 | V35: =SUM($E35:G35) -> 18792.66 | W35: =SUM($E35:H35) -> 18792.66 | X35: =SUM($E35:I35) -> 40000 | Y35: =SUM($E35:J35) -> 40000 | Z35: =SUM($E35:K35) -> 40000 | AA35: =SUM($E35:L35) -> 40000 | AB35: =SUM($E35:M35) -> 40000 | ... AE35: =SUM($E35:P35) -> 40000 | AG35: =_xlfn.XLOOKUP(A35,'מצטבר יוני'!A:A,'מצטבר יוני'!H:H) -> 18792.66 | AI35: =_xlfn.XLOOKUP($A35,'[1]מפיצים הערכה לחציון שני '!$L:$L,'[1]מפיצים הערכה לחציון שני '!O:O) -> 0 | AJ35: =_xlfn.XLOOKUP($A35,'[1]מפיצים הערכה לחציון שני '!$L:$L,'[1]מפיצים הערכה לחציון שני '!P:P) -> 20000 | AK35: =_xlfn.XLOOKUP($A35,'[1]מפיצים הערכה לחציון שני '!$L:$L,'[1]מפיצים הערכה לחציון שני '!Q:Q) -> 0 | AL35: =_xlfn.XLOOKUP($A35,'[1]מפיצים הערכה לחציון שני '!$L:$L,'[1]מפיצים הערכה לחציון שני '!R:R) -> 0 | AM35: =_xlfn.XLOOKUP($A35,'[1]מפיצים הערכה לחציון שני '!$L:$L,'[1]מפיצים הערכה לחציון שני '!S:S) -> 0 | AN35: =_xlfn.XLOOKUP($A35,'[1]מפיצים הערכה לחציון שני '!$L:$L,'[1]מפיצים הערכה לחציון שני '!T:T) -> 0 | AO35: =SUM(AI35:AN35) -> 20000 | AP35: =SUM(AI35:AN35)+Y35 -> 60000 | AR35: =AI35+AG35 -> 18792.66 | AS35: =AR35+AJ35 -> 38792.66 | AT35: =AS35+AK35 -> 38792.66 | AU35: =AT35+AL35 -> 38792.66 | AV35: =AU35+AM35 -> 38792.66 | AW35: =AV35+AN35 -> 38792.66
A36: 33 | B36: Total - 214 - Alfred Gera& Sons Ltd. MALTA | C36: ALFRED GERA | D36: MALTA | I36: 40000 | O36: 40000 | Q36: =SUM(E36:P36) -> 80000 | R36: 80000 | S36: =SUM(E36:E36) -> 0 | T36: =R36-Q36 -> 0 | U36: =SUM($E36:F36) -> 0 | V36: =SUM($E36:G36) -> 0 | W36: =SUM($E36:H36) -> 0 | X36: =SUM($E36:I36) -> 40000 | Y36: =SUM($E36:J36) -> 40000 | Z36: =SUM($E36:K36) -> 40000 | AA36: =SUM($E36:L36) -> 40000 | AB36: =SUM($E36:M36) -> 40000 | ... AE36: =SUM($E36:P36) -> 80000 | AG36: =_xlfn.XLOOKUP(A36,'מצטבר יוני'!A:A,'מצטבר יוני'!H:H) -> 0 | AI36: =_xlfn.XLOOKUP($A36,'[1]מפיצים הערכה לחציון שני '!$L:$L,'[1]מפיצים הערכה לחציון שני '!O:O) -> 0 | AJ36: =_xlfn.XLOOKUP($A36,'[1]מפיצים הערכה לחציון שני '!$L:$L,'[1]מפיצים הערכה לחציון שני '!P:P) -> 0 | AK36: =_xlfn.XLOOKUP($A36,'[1]מפיצים הערכה לחציון שני '!$L:$L,'[1]מפיצים הערכה לחציון שני '!Q:Q) -> 0 | AL36: =_xlfn.XLOOKUP($A36,'[1]מפיצים הערכה לחציון שני '!$L:$L,'[1]מפיצים הערכה לחציון שני '!R:R) -> 0 | AM36: =_xlfn.XLOOKUP($A36,'[1]מפיצים הערכה לחציון שני '!$L:$L,'[1]מפיצים הערכה לחציון שני '!S:S) -> 0 | AN36: =_xlfn.XLOOKUP($A36,'[1]מפיצים הערכה לחציון שני '!$L:$L,'[1]מפיצים הערכה לחציון שני '!T:T) -> 25000 | AO36: =SUM(AI36:AN36) -> 25000 | AP36: =SUM(AI36:AN36)+Y36 -> 65000 | AR36: =AI36+AG36 -> 0 | AS36: =AR36+AJ36 -> 0 | AT36: =AS36+AK36 -> 0 | AU36: =AT36+AL36 -> 0 | AV36: =AU36+AM36 -> 0 | AW36: =AV36+AN36 -> 25000
A37: 34 | C37: YOUNG IN HEALTHCARE CO., | O37: 20000 | R37: 20000 | T37: =R37-Q37 -> 20000 | AG37: =_xlfn.XLOOKUP(A37,'מצטבר יוני'!A:A,'מצטבר יוני'!H:H) -> 0 | AI37: =_xlfn.XLOOKUP($A37,'[1]מפיצים הערכה לחציון שני '!$L:$L,'[1]מפיצים הערכה לחציון שני '!O:O) -> 0 | AJ37: =_xlfn.XLOOKUP($A37,'[1]מפיצים הערכה לחציון שני '!$L:$L,'[1]מפיצים הערכה לחציון שני '!P:P) -> 0 | AK37: =_xlfn.XLOOKUP($A37,'[1]מפיצים הערכה לחציון שני '!$L:$L,'[1]מפיצים הערכה לחציון שני '!Q:Q) -> 0 | AL37: =_xlfn.XLOOKUP($A37,'[1]מפיצים הערכה לחציון שני '!$L:$L,'[1]מפיצים הערכה לחציון שני '!R:R) -> 0 | AM37: =_xlfn.XLOOKUP($A37,'[1]מפיצים הערכה לחציון שני '!$L:$L,'[1]מפיצים הערכה לחציון שני '!S:S) -> 0 | AN37: =_xlfn.XLOOKUP($A37,'[1]מפיצים הערכה לחציון שני '!$L:$L,'[1]מפיצים הערכה לחציון שני '!T:T) -> 0 | AO37: =SUM(AI37:AN37) -> 0 | AP37: =SUM(AI37:AN37)+Y37 -> 0 | AR37: =AI37+AG37 -> 0 | AS37: =AR37+AJ37 -> 0 | AT37: =AS37+AK37 -> 0 | AU37: =AT37+AL37 -> 0 | AV37: =AU37+AM37 -> 0 | AW37: =AV37+AN37 -> 0
A38: 35 | B38: 200 - ROW : 217 - N3W FOODS USA | C38: HANS | D38: USA | H38: 200000 | L38: 200000 | O38: 200000 | Q38: =SUM(E38:P38) -> 600000 | R38: 600000 | S38: =SUM(E38:E38) -> 0 | T38: =R38-Q38 -> 0 | U38: =SUM($E38:F38) -> 0 | V38: =SUM($E38:G38) -> 0 | W38: =SUM($E38:H38) -> 200000 | X38: =SUM($E38:I38) -> 200000 | Y38: =SUM($E38:J38) -> 200000 | Z38: =SUM($E38:K38) -> 200000 | AA38: =SUM($E38:L38) -> 400000 | AB38: =SUM($E38:M38) -> 400000 | ... AE38: =SUM($E38:P38) -> 600000 | AG38: =_xlfn.XLOOKUP(A38,'מצטבר יוני'!A:A,'מצטבר יוני'!H:H) -> 0 | AI38: =_xlfn.XLOOKUP($A38,'[1]מפיצים הערכה לחציון שני '!$L:$L,'[1]מפיצים הערכה לחציון שני '!O:O) -> 0 | AJ38: =_xlfn.XLOOKUP($A38,'[1]מפיצים הערכה לחציון שני '!$L:$L,'[1]מפיצים הערכה לחציון שני '!P:P) -> 0 | AK38: =_xlfn.XLOOKUP($A38,'[1]מפיצים הערכה לחציון שני '!$L:$L,'[1]מפיצים הערכה לחציון שני '!Q:Q) -> 0 | AL38: =_xlfn.XLOOKUP($A38,'[1]מפיצים הערכה לחציון שני '!$L:$L,'[1]מפיצים הערכה לחציון שני '!R:R) -> 0 | AM38: =_xlfn.XLOOKUP($A38,'[1]מפיצים הערכה לחציון שני '!$L:$L,'[1]מפיצים הערכה לחציון שני '!S:S) -> 0 | AN38: =_xlfn.XLOOKUP($A38,'[1]מפיצים הערכה לחציון שני '!$L:$L,'[1]מפיצים הערכה לחציון שני '!T:T) -> 0 | AO38: =SUM(AI38:AN38) -> 0 | AP38: =SUM(AI38:AN38)+Y38 -> 200000 | AR38: =AI38+AG38 -> 0 | AS38: =AR38+AJ38 -> 0 | AT38: =AS38+AK38 -> 0 | AU38: =AT38+AL38 -> 0 | AV38: =AU38+AM38 -> 0 | AW38: =AV38+AN38 -> 0
A39: 36 | B39: New Distributors | C39: NEW DISTRIBUTORS | J39: 200000 | O39: 200000 | Q39: =SUM(E39:P39) -> 400000 | R39: 400000 | S39: =SUM(E39:E39) -> 0 | T39: =R39-Q39 -> 0 | U39: =SUM($E39:F39) -> 0 | V39: =SUM($E39:G39) -> 0 | W39: =SUM($E39:H39) -> 0 | X39: =SUM($E39:I39) -> 0 | Y39: =SUM($E39:J39) -> 200000 | Z39: =SUM($E39:K39) -> 200000 | AA39: =SUM($E39:L39) -> 200000 | AB39: =SUM($E39:M39) -> 200000 | ... AE39: =SUM($E39:P39) -> 400000 | AG39: =_xlfn.XLOOKUP(A39,'מצטבר יוני'!A:A,'מצטבר יוני'!H:H) -> 0 | AI39: =_xlfn.XLOOKUP($A39,'[1]מפיצים הערכה לחציון שני '!$L:$L,'[1]מפיצים הערכה לחציון שני '!O:O) -> 0 | AJ39: =_xlfn.XLOOKUP($A39,'[1]מפיצים הערכה לחציון שני '!$L:$L,'[1]מפיצים הערכה לחציון שני '!P:P) -> 0 | AK39: =_xlfn.XLOOKUP($A39,'[1]מפיצים הערכה לחציון שני '!$L:$L,'[1]מפיצים הערכה לחציון שני '!Q:Q) -> 0 | AL39: =_xlfn.XLOOKUP($A39,'[1]מפיצים הערכה לחציון שני '!$L:$L,'[1]מפיצים הערכה לחציון שני '!R:R) -> 100000 | AM39: =_xlfn.XLOOKUP($A39,'[1]מפיצים הערכה לחציון שני '!$L:$L,'[1]מפיצים הערכה לחציון שני '!S:S) -> 0 | AN39: =_xlfn.XLOOKUP($A39,'[1]מפיצים הערכה לחציון שני '!$L:$L,'[1]מפיצים הערכה לחציון שני '!T:T) -> 0 | AO39: =SUM(AI39:AN39) -> 100000 | AP39: =SUM(AI39:AN39)+Y39 -> 300000 | AR39: =AI39+AG39 -> 0 | AS39: =AR39+AJ39 -> 0 | AT39: =AS39+AK39 -> 0 | AU39: =AT39+AL39 -> 100000 | AV39: =AU39+AM39 -> 100000 | AW39: =AV39+AN39 -> 100000
B40: סה"כ חו"ל | E40: =SUM(E22:E39) -> 526326.77 | F40: =SUM(F22:F39) -> 624144.32 | G40: =SUM(G22:G39) -> 542589.52 | H40: =SUM(H22:H39) -> 946901.27 | I40: =SUM(I22:I39) -> 856658.89 | J40: =SUM(J22:J39) -> 758228.83 | K40: =SUM(K22:K39) -> 1015168 | L40: =SUM(L22:L39) -> 1146567 | ... S40: =SUM(S22:S39) -> 526326.77 | T40: =R40-Q40 -> -4756579.2 | U40: =SUM(U22:U39) -> 1150471.1 | V40: =SUM(V22:V39) -> 1693060.6 | W40: =SUM(W22:W39) -> 2639961.9 | X40: =SUM(X22:X39) -> 3496620.8 | Y40: =SUM(Y22:Y39) -> 4254849.6 | Z40: =SUM(Z22:Z39) -> 5270017.6 | AA40: =SUM(AA22:AA39) -> 6416584.6 | AB40: =SUM(AB22:AB39) -> 7104745.2 | ... AE40: =SUM(AE22:AE39) -> 9781372.5 | AG40: =SUM(AG22:AG39) -> 2801213.8 | AI40: =SUM(AI22:AI39) -> 565966.8 | AJ40: =SUM(AJ22:AJ39) -> 495012.4 | AK40: =SUM(AK22:AK39) -> 779615.8 | AL40: =SUM(AL22:AL39) -> 871888.6 | AM40: =SUM(AM22:AM39) -> 771122.5 | AN40: =SUM(AN22:AN39) -> 487561 | AO40: =SUM(AO22:AO39) -> 3971167.1 | AP40: =SUM(AP22:AP39) -> 8226016.7 | AR40: =AI40+AG40 -> 3367180.6 | AS40: =SUM(AS22:AS39) -> 3862193 | AT40: =SUM(AT22:AT39) -> 4641808.8 | AU40: =SUM(AU22:AU39) -> 5513697.4 | AV40: =SUM(AV22:AV39) -> 6284819.9 | AW40: =SUM(AW22:AW39) -> 6772380.9
...

Sheet 2025
B1: 2 | C1: 3 | D1: 4 | E1: 5 | F1: 6 | G1: 7 | H1: 8 | I1: 9 | J1: 10 | K1: 11 | L1: 12 | M1: 13
D2: =D35/$O$35 -> 0.12306952 | E2: =E35/$O$35 -> 0.10707745 | F2: =F35/$O$35 -> 0.15914624 | G2: =G35/$O$35 -> 0.00015063993 | H2: =H35/$O$35 -> 0.15805838 | I2: =I35/$O$35 -> 0.075565535 | J2: =J35/$O$35 -> 0.07710397 | K2: =K35/$O$35 -> 0.10192191 | ... M2: =M35/$O$35 -> 0.11625338
A3: Customer | B3: 45658 | C3: 45689 | D3: 45717 | E3: 45748 | F3: 45778 | G3: 45809 | H3: 45839 | I3: 45870 | J3: 46266 | K3: 45931 | L3: 45962 | M3: 45992 | N3: Total | P3: מצטבר | R3: מצטבר פברואר | S3: מצטבר מרץ | T3: מצטבר אפריל | U3: מצטבר מאי | V3: מצטבר יוני | W3: מצטבר יולי | X3: מצטבר אוגוסט | Y3: מצטבר ספטמבר | Z3: מצטבר אוקטובר | AA3: מצטבר נובמבר | AB3: מצטבר דצמבר
B4: Sales | C4: Sales | D4: Sales | E4: Sales | F4: Sales | G4: Sales | H4: Sales | I4: Sales | J4: Sales | K4: Sales | L4: Sales | M4: Sales | N4: Sales | P4: Sales | R4: Sales | S4: Sales | T4: Sales | U4: Sales | V4: Sales | W4: Sales | X4: Sales | Y4: Sales | Z4: Sales | AA4: Sales | AB4: Sales
A5: 110 - Chemipal | B5: 844589.24 | C5: 597568.02 | D5: 638446.17 | E5: 781364.83 | F5: 977752.95 | G5: 689832.37 | H5: 758569.05 | I5: 741932.1 | J5: 656043.57 | K5: 612448.29 | L5: 740101.82 | M5: 650395.29 | N5: 8689043.7 | O5: =SUM(D5:M5) -> 7246886.4 | P5: 2080603.4 | R5: 1442157.3 | S5: 2080603.4 | T5: 2861968.3 | U5: 3839721.2 | V5: 4529553.6 | W5: 5288122.6 | X5: 6030054.7 | Y5: 6686098.3 | Z5: 7298546.6 | AA5: 8038648.4 | AB5: 8689043.7
A6: 102 - Orthopedic institutes | B6: 72633.3 | C6: 46378.11 | D6: 65531.82 | E6: 74555.12 | F6: 94846.85 | G6: 63999.64 | H6: 81305.01 | I6: 61998.83 | J6: 69988.58 | K6: 57765.28 | L6: 96453.83 | M6: 69362.57 | N6: 854818.94 | O6: =SUM(D6:M6) -> 735807.53 | P6: 184543.23 | R6: 119011.41 | S6: 184543.23 | T6: 259098.35 | U6: 353945.2 | V6: 417944.84 | W6: 499249.85 | X6: 561248.68 | Y6: 631237.26 | Z6: 689002.54 | AA6: 785456.37 | AB6: 854818.94
A7: 101 - Factory customers | B7: 16402.68 | C7: 17589.94 | D7: 21300.79 | E7: 15201.7 | F7: 15870.65 | G7: 9192.17 | H7: 10971.32 | I7: 12420.51 | J7: 17490.72 | K7: 9579 | L7: 28016.53 | M7: 11214.5 | N7: 185250.51 | O7: =SUM(D7:M7) -> 151257.89 | P7: 55293.41 | R7: 33992.62 | S7: 55293.41 | T7: 70495.11 | U7: 86365.76 | V7: 95557.93 | W7: 106529.25 | X7: 118949.76 | Y7: 136440.48 | Z7: 146019.48 | AA7: 174036.01 | AB7: 185250.51
A8: 104 - Sports Shop | B8: 0 | C8: 0 | D8: 0 | E8: 0 | F8: 0 | G8: 0 | H8: 0 | I8: 0 | J8: 0 | K8: 514.2 | L8: 0 | M8: 0 | N8: 514.2 | O8: =SUM(D8:M8) -> 514.2 | P8: 0 | R8: 0 | S8: 0 | T8: 0 | U8: 0 | V8: 0 | W8: 0 | X8: 0 | Y8: 0 | Z8: 514.2 | AA8: 514.2 | AB8: 514.2
A9: 103 - Physiotherapy institutes | B9: 15213.91 | C9: 12501.56 | D9: 2138.43 | E9: 5898.37 | F9: 707.66 | G9: 17697.58 | H9: 7828.72 | I9: 5704.97 | J9: 9679.47 | K9: 4038.81 | L9: 12930.62 | M9: 361.5 | N9: 94701.6 | O9: =SUM(D9:M9) -> 66986.13 | P9: 29853.9 | R9: 27715.47 | S9: 29853.9 | T9: 35752.27 | U9: 36459.93 | V9: 54157.51 | W9: 61986.23 | X9: 67691.2 | Y9: 77370.67 | Z9: 81409.48 | AA9: 94340.1 | AB9: 94701.6
A10: 109 - Private Shops | B10: 6025.5 | C10: 4045.81 | D10: 11352.51 | E10: 4054.42 | F10: 5871.12 | G10: 4288.26 | H10: 4990.47 | I10: 1459.42 | J10: 4228.87 | K10: 3274.69 | L10: 1902.07 | M10: 5866.58 | N10: 57359.72 | O10: =SUM(D10:M10) -> 47288.41 | P10: 21423.82 | R10: 10071.31 | S10: 21423.82 | T10: 25478.24 | U10: 31349.36 | V10: 35637.62 | W10: 40628.09 | X10: 42087.51 | Y10: 46316.38 | Z10: 49591.07 | AA10: 51493.14 | AB10: 57359.72
A11: 105 - Pedicure Salons | B11: 1162.85 | C11: 569.45 | D11: 0 | E11: 0 | F11: 0 | G11: 1244.84 | H11: 0 | I11: 0 | J11: 0 | K11: 669.74 | L11: 498.8 | M11: 0 | N11: 4145.68 | O11: =SUM(D11:M11) -> 2413.38 | P11: 1732.3 | R11: 1732.3 | S11: 1732.3 | T11: 1732.3 | U11: 1732.3 | V11: 2977.14 | W11: 2977.14 | X11: 2977.14 | Y11: 2977.14 | Z11: 3646.88 | AA11: 4145.68 | AB11: 4145.68
A12: 111 - Superpharm Life | B12: 58427.8 | C12: 233209.9 | D12: 66608.1 | E12: 336937.6 | F12: 131634 | G12: 0 | H12: 83088 | I12: 243929.1 | J12: 157587.19 | K12: 33955.2 | L12: 265660.9 | M12: 97619.06 | N12: 1708656.9 | O12: =SUM(D12:M12) -> 1417019.1 | P12: 358245.8 | R12: 291637.7 | S12: 358245.8 | T12: 695183.4 | U12: 826817.4 | V12: 826817.4 | W12: 909905.4 | X12: 1153834.5 | Y12: 1311421.7 | Z12: 1345376.9 | AA12: 1611037.8 | AB12: 1708656.9
A13: 108 - Shoe Stores | B13: 0 | C13: 11720.98 | D13: 0 | E13: 0 | F13: 0 | G13: 0 | H13: 0 | I13: 7344.4 | J13: 0 | K13: 0 | L13: 0 | M13: 0 | N13: 19065.38 | O13: =SUM(D13:M13) -> 7344.4 | P13: 11720.98 | R13: 11720.98 | S13: 11720.98 | T13: 11720.98 | U13: 11720.98 | V13: 11720.98 | W13: 11720.98 | X13: 19065.38 | Y13: 19065.38 | Z13: 19065.38 | AA13: 19065.38 | AB13: 19065.38
A14: 106 - Hospitals | B14: 0 | C14: 11067.51 | D14: 0 | E14: 0 | F14: 0 | G14: 0 | H14: 651.15 | I14: 0 | J14: 0 | K14: 0 | L14: 0 | M14: 1813.57 | N14: 13532.23 | O14: =SUM(D14:M14) -> 2464.72 | P14: 11067.51 | R14: 11067.51 | S14: 11067.51 | T14: 11067.51 | U14: 11067.51 | V14: 11067.51 | W14: 11718.66 | X14: 11718.66 | Y14: 11718.66 | Z14: 11718.66 | AA14: 11718.66 | AB14: 13532.23
A15: 107 - Pharmacies | B15: 16943.23 | C15: 8629.41 | D15: 10741.72 | E15: 16562.55 | F15: 18520.67 | G15: 10131.7 | H15: 9190.31 | I15: 6621.54 | J15: 9073.07 | K15: 17028.33 | L15: 21017.63 | M15: 7965.2 | N15: 152425.36 | O15: =SUM(D15:M15) -> 126852.72 | P15: 36314.36 | R15: 25572.64 | S15: 36314.36 | T15: 52876.91 | U15: 71397.58 | V15: 81529.28 | W15: 90719.59 | X15: 97341.13 | Y15: 106414.2 | Z15: 123442.53 | AA15: 144460.16 | AB15: 152425.36
A16: 113 - Kupat Holim Meuhedet | B16: 57834.64 | C16: 82146.14 | D16: 74502.3 | E16: 62433.13 | F16: 88130.8 | G16: 62616.16 | H16: 95914.88 | I16: 81013.09 | J16: 89206.99 | K16: 70789.24 | L16: 68004.57 | M16: 60034.25 | N16: 892626.19 | O16: =SUM(D16:M16) -> 752645.41 | P16: 214483.08 | R16: 139980.78 | S16: 214483.08 | T16: 276916.21 | U16: 365047.01 | V16: 427663.17 | W16: 523578.05 | X16: 604591.14 | Y16: 693798.13 | Z16: 764587.37 | AA16: 832591.94 | AB16: 892626.19
... A38: Total | B38: 1755643.3 | C38: 2087540.5 | D38: 1783327.5 | E38: 2289139.1 | F38: 2304623.7 | G38: 1423912.7 | H38: 2503790.3 | I38: 2006304.5 | J38: 1830821.4 | K38: 1591826.9 | L38: 2559493.1 | M38: 2002293.8 | N38: 24138717 | O38: =SUM(D38:M38) -> 20295533 | P38: 5626511.3 | R38: 3843183.8 | S38: 5626511.3 | T38: 7915650.4 | U38: 10220274 | V38: 11644187 | W38: 14147977 | X38: 16154281 | Y38: 17985103 | Z38: 19576930 | AA38: 22136423 | AB38: 24138717
A40: סופרפארם | B40: 670882.2 | C40: 406825.35 | D40: 437918.57 | E40: 549545.83 | F40: 729180.69 | G40: 452295.98 | H40: 486312.52 | I40: 495074.58 | J40: 465794.42 | K40: 417469.78 | L40: 507426.01 | M40: 453051.69 | N40: 6071777.6 | P40: 1515626.1 | R40: 1077707.5 | S40: 1515626.1 | T40: 2065171.9 | U40: 2794352.6 | V40: 3246648.6 | W40: 3732961.1 | X40: 4228035.7 | Y40: 4693830.1 | Z40: 5111299.9 | AA40: 5618725.9 | AB40: 6071777.6
A41: BE | B41: 54489.89 | C41: 65962.26 | D41: 58257.29 | E41: 75168 | F41: 80577.77 | G41: 87191.65 | H41: 59921.68 | I41: 73631.74 | J41: 64918.49 | K41: 61390.42 | L41: 85930.39 | M41: 61250.28 | N41: 828689.86 | P41: 178709.44 | R41: 120452.15 | S41: 178709.44 | T41: 253877.44 | U41: 334455.21 | V41: 421646.86 | W41: 481568.54 | X41: 555200.28 | Y41: 620118.77 | Z41: 681509.19 | AA41: 767439.58 | AB41: 828689.86
