Workbook

Sheet Index
A1: Sales Comparison 2025 vs 2026 - by Daily-Report Group (PPlay1 of uriel report, grouped per Pplay1 legend) - Annualized + DROP/NEW
A2: Calculation date: | B2: 46284
A3: Each sheet below is a live comparison table (formulas, not hardcoded values) for one daily-report group, summed across its member raw-customer columns from 'Source 2025'/'Source 2026'. Quantity/Amount 2026 and Change% columns here show ACTUAL (partial-year, 1/1-15/9) figures, consistent across all 5 rows; the ANNUALIZED comparison (x12/9.5) is available inside each group sheet. All SUMPRODUCT formulas use "--" to force numeric coercion of boolean arrays (required for correct results in real Excel, not just LibreOffice). See the "Group Mapping" sheet for exactly which raw categories feed each group.
A5: Group | B5: Sheet | C5: # Raw categories | D5: # Codes | E5: # Codes 25 | F5: # Codes 26 | G5: # DROP | H5: # NEW | I5: Total Units Drop 25 | J5: Total Amount Drop 25 | K5: NEW — Quantity 2026 | L5: NEW — Amount 2026 (₪) | M5: Quantity 2025 | N5: Quantity 2026 (Actual) | O5: Quantity 2026 Annualized | P5: Qty Change % (vs Annualized) | Q5: Amount 2025 (₪) | R5: Amount 2026 (Actual) (₪) | S5: Amount 2026 (Annualized) (₪) | T5: Amount Change % (vs Annualized)
A6: בתי מרקחת | B6: בתי מרקחת | C6: 9 | D6: =COUNTA('בתי מרקחת'!$A$9:$A$291) -> 283 | E6: =SUMPRODUCT(--(('בתי מרקחת'!$C$9:$C$291<>0)+('בתי מרקחת'!$H$9:$H$291<>0)>0)) -> 263 | F6: =SUMPRODUCT(--(('בתי מרקחת'!$D$9:$D$291<>0)+('בתי מרקחת'!$I$9:$I$291<>0)>0)) -> 240 | G6: ='בתי מרקחת'!B5 -> 43 | H6: ='בתי מרקחת'!D5 -> 20 | I6: ='בתי מרקחת'!B6 -> 176 | J6: ='בתי מרקחת'!D6 -> 13452.9 | K6: ='בתי מרקחת'!F6 -> 570 | L6: ='בתי מרקחת'!H6 -> 35416.5 | M6: ='בתי מרקחת'!C293 -> 54177 | N6: ='בתי מרקחת'!D293 -> 33487 | O6: ='בתי מרקחת'!E293 -> 42299.368 | P6: =IF('בתי מרקחת'!C293=0,"N/A",('בתי מרקחת'!E293-'בתי מרקחת'!C293)/'בתי מרקחת'!C293) -> -0.21923753 | Q6: ='בתי מרקחת'!H293 -> 1967633.7 | R6: ='בתי מרקחת'!I293 -> 1293807.8 | S6: ='בתי מרקחת'!J293 -> 1634283.5 | T6: =IF('בתי מרקחת'!H293=0,"N/A",('בתי מרקחת'!J293-'בתי מרקחת'!H293)/'בתי מרקחת'!H293) -> -0.16941678
A7: BE | B7: BE | C7: 6 | D7: =COUNTA('BE'!$A$9:$A$171) -> 163 | E7: =SUMPRODUCT(--(('BE'!$C$9:$C$171<>0)+('BE'!$H$9:$H$171<>0)>0)) -> 155 | F7: =SUMPRODUCT(--(('BE'!$D$9:$D$171<>0)+('BE'!$I$9:$I$171<>0)>0)) -> 145 | G7: ='BE'!B5 -> 18 | H7: ='BE'!D5 -> 8 | I7: ='BE'!B6 -> 43 | J7: ='BE'!D6 -> 2818.5 | K7: ='BE'!F6 -> 8 | L7: ='BE'!H6 -> 918.4 | M7: ='BE'!C173 -> 27268 | N7: ='BE'!D173 -> 19109 | O7: ='BE'!E173 -> 24137.684 | P7: =IF('BE'!C173=0,"N/A",('BE'!E173-'BE'!C173)/'BE'!C173) -> -0.11479814 | Q7: ='BE'!H173 -> 889501.1 | R7: ='BE'!I173 -> 676265.8 | S7: ='BE'!J173 -> 854230.48 | T7: =IF('BE'!H173=0,"N/A",('BE'!J173-'BE'!H173)/'BE'!H173) -> -0.039652133
A8: סופר פארם | B8: סופר פארם | C8: 1 | D8: =COUNTA('סופר פארם'!$A$9:$A$227) -> 219 | E8: =SUMPRODUCT(--(('סופר פארם'!$C$9:$C$227<>0)+('סופר פארם'!$H$9:$H$227<>0)>0)) -> 196 | F8: =SUMPRODUCT(--(('סופר פארם'!$D$9:$D$227<>0)+('סופר פארם'!$I$9:$I$227<>0)>0)) -> 196 | G8: ='סופר פארם'!B5 -> 23 | H8: ='סופר פארם'!D5 -> 23 | I8: ='סופר פארם'!B6 -> -44 | J8: ='סופר פארם'!D6 -> -4091.7 | K8: ='סופר פארם'!F6 -> 1952 | L8: ='סופר פארם'!H6 -> 147652.2 | M8: ='סופר פארם'!C229 -> 176505 | N8: ='סופר פארם'!D229 -> 118307 | O8: ='סופר פארם'!E229 -> 149440.42 | P8: =IF('סופר פארם'!C229=0,"N/A",('סופר פארם'!E229-'סופר פארם'!C229)/'סופר פארם'!C229) -> -0.15333605 | Q8: ='סופר פארם'!H229 -> 6689220.5 | R8: ='סופר פארם'!I229 -> 4476515.3 | S8: ='סופר פארם'!J229 -> 5654545.6 | T8: =IF('סופר פארם'!H229=0,"N/A",('סופר פארם'!J229-'סופר פארם'!H229)/'סופר פארם'!H229) -> -0.15467794
A9: מאוחדת | B9: מאוחדת | C9: 1 | D9: =COUNTA('מאוחדת'!$A$9:$A$115) -> 107 | E9: =SUMPRODUCT(--(('מאוחדת'!$C$9:$C$115<>0)+('מאוחדת'!$H$9:$H$115<>0)>0)) -> 0 | F9: =SUMPRODUCT(--(('מאוחדת'!$D$9:$D$115<>0)+('מאוחדת'!$I$9:$I$115<>0)>0)) -> 107 | G9: ='מאוחדת'!B5 -> 0 | H9: ='מאוחדת'!D5 -> 107 | I9: ='מאוחדת'!B6 -> 0 | J9: ='מאוחדת'!D6 -> 0 | K9: ='מאוחדת'!F6 -> 10037 | L9: ='מאוחדת'!H6 -> 307514.4 | M9: ='מאוחדת'!C117 -> 0 | N9: ='מאוחדת'!D117 -> 10037 | O9: ='מאוחדת'!E117 -> 12678.316 | P9: =IF('מאוחדת'!C117=0,"N/A",('מאוחדת'!E117-'מאוחדת'!C117)/'מאוחדת'!C117) -> N/A | Q9: ='מאוחדת'!H117 -> 0 | R9: ='מאוחדת'!I117 -> 307514.4 | S9: ='מאוחדת'!J117 -> 388439.24 | T9: =IF('מאוחדת'!H117=0,"N/A",('מאוחדת'!J117-'מאוחדת'!H117)/'מאוחדת'!H117) -> N/A
A10: 0פארמים | B10: 0פארמים | C10: 1 | D10: =COUNTA('0פארמים'!$A$9:$A$263) -> 255 | E10: =SUMPRODUCT(--(('0פארמים'!$C$9:$C$263<>0)+('0פארמים'!$H$9:$H$263<>0)>0)) -> 235 | F10: =SUMPRODUCT(--(('0פארמים'!$D$9:$D$263<>0)+('0פארמים'!$I$9:$I$263<>0)>0)) -> 231 | G10: ='0פארמים'!B5 -> 24 | H10: ='0פארמים'!D5 -> 20 | I10: ='0פארמים'!B6 -> -40 | J10: ='0פארמים'!D6 -> -2736.3 | K10: ='0פארמים'!F6 -> 1972 | L10: ='0פארמים'!H6 -> 148341.1 | M10: ='0פארמים'!C265 -> 204428 | N10: ='0פארמים'!D265 -> 137851 | O10: ='0פארמים'!E265 -> 174127.58 | P10: =IF('0פארמים'!C265=0,"N/A",('0פארמים'!E265-'0פארמים'!C265)/'0פארמים'!C265) -> -0.1482205 | Q10: ='0פארמים'!H265 -> 7597886.3 | R10: ='0פארמים'!I265 -> 5165969.3 | S10: ='0פארמים'!J265 -> 6525434.9 | T10: =IF('0פארמים'!H265=0,"N/A",('0פארמים'!J265-'0פארמים'!H265)/'0פארמים'!H265) -> -0.14115128

Sheet Group Mapping
A1: Category -> Group mapping (source: daily report Pplay1 legend, 5 unmatched categories confirmed by user on 19/09/2026)
A2: Raw category (PPLAY1 column) | B2: Group # | C2: Group name | D2: Source of mapping
A3: 0בתי טבע | B3: 4 | C3: בתי מרקחת | D3: Confirmed by user 19/09/2026
A4: 0בתי טבע רשתות | B4: 4 | C4: בתי מרקחת | D4: Confirmed by user 19/09/2026
A5: 0בתי מרקחת | B5: 4 | C5: בתי מרקחת | D5: Daily report Pplay1 legend
A6: 0כללי | B6: 4 | C6: בתי מרקחת | D6: Confirmed by user 19/09/2026
A7: 0מפיצי משנה | B7: 4 | C7: בתי מרקחת | D7: Daily report Pplay1 legend
A8: 0צרכנים פרטיים | B8: 4 | C8: בתי מרקחת | D8: Daily report Pplay1 legend
A9: 0שונות | B9: 4 | C9: בתי מרקחת | D9: Daily report Pplay1 legend
A10: גוד פארם | B10: 4 | C10: בתי מרקחת | D10: Daily report Pplay1 legend
A11: גוד פארם מרכז | B11: 4 | C11: בתי מרקחת | D11: Daily report Pplay1 legend
A12: BE | B12: 7 | C12: BE | D12: Confirmed by user 19/09/2026
A13: אילת BE | B13: 7 | C13: BE | D13: Daily report Pplay1 legend
... A20: 0פארמים | B20: (none) | C20: (standalone - no group) | D20: Daily report Pplay1 legend

Sheet בתי מרקחת
A1: Sales Comparison 2025 vs 2026 (Annualized) - Group: בתי מרקחת (by Product CODE)
A2: Calculation date: | B2: 46284
A3: Source: PPlay1 of uriel (Reporter) product x customer pivot reports for 2025 and 2026. Grouping follows the daily report "Pplay1" sheet legend (customer # 4/7/1/8) plus 5 categories confirmed by the user on 19/09/2026 that had no exact-name match in the legend. Group "בתי מרקחת" = sum of raw customer column(s): 0בתי מרקחת, 0מפיצי משנה, גוד פארם, גוד פארם מרכז, 0צרכנים פרטיים, 0שונות, 0בתי טבע, 0בתי טבע רשתות, 0כללי (column(s) F, H, M, N, S, U, D, E, G in 'Source 2025'/'Source 2026'). Each file has two data blocks: "נטו" (Net Amount, NIS) and "סהכ יחידות" (Total Units). Product CODE parsed as the first token of column B in the original file; size/color variants sharing the same base CODE are summed via SUMIFS. Rows below only include product codes with non-zero quantity or amount for this group in at least one of the two years (comparing 2025 actual to 2026 actual, before annualization). Full build (annualization + DROP/NEW + whole-number display) rolled out to all 5 groups on 19/09/2026 - see rows 4-6 for methodology.
A4: Annualization note: 2026 actual data covers approximately 9.5 months (1 Jan - 15 Sep 2026). To make 2026 comparable to a full year, it is scaled up by a simple linear factor = 12 / 9.5 (≈ 1.263158). This is a straight-line extrapolation and does NOT account for seasonality (e.g. holiday-heavy months) - treat as an estimate, not an exact forecast. | I4: Months in full year: | J4: 12 | K4: Months covered by 2026 actual (1/1–15/9): | L4: 9.5
A5: # DROP (sold 2025, 0 in 2026): | B5: =SUMPRODUCT(--((($C$9:$C$291<>0)+($H$9:$H$291<>0)>0)*(($D$9:$D$291=0)*($I$9:$I$291=0)))) -> 43 | C5: # NEW (sold 2026, 0 in 2025): | D5: =SUMPRODUCT(--((($D$9:$D$291<>0)+($I$9:$I$291<>0)>0)*(($C$9:$C$291=0)*($H$9:$H$291=0)))) -> 20 | I5: Normalization factor (J4/L4): | J5: =J4/L4 -> 1.2631579
A6: DROP — Quantity 2025: | B6: =SUMPRODUCT(--((($C$9:$C$291<>0)+($H$9:$H$291<>0)>0)*(($D$9:$D$291=0)*($I$9:$I$291=0)))*$C$9:$C$291) -> 176 | C6: DROP — Amount 2025 (₪): | D6: =SUMPRODUCT(--((($C$9:$C$291<>0)+($H$9:$H$291<>0)>0)*(($D$9:$D$291=0)*($I$9:$I$291=0)))*$H$9:$H$291) -> 13452.9 | E6: NEW — Quantity 2026: | F6: =SUMPRODUCT(--((($D$9:$D$291<>0)+($I$9:$I$291<>0)>0)*(($C$9:$C$291=0)*($H$9:$H$291=0)))*$D$9:$D$291) -> 570 | G6: NEW — Amount 2026 (₪): | H6: =SUMPRODUCT(--((($D$9:$D$291<>0)+($I$9:$I$291<>0)>0)*(($C$9:$C$291=0)*($H$9:$H$291=0)))*$I$9:$I$291) -> 35416.5
A8: Product Code | B8: Product Name | C8: Quantity 2025 | D8: Quantity 2026 (Actual, partial year) | E8: Quantity 2026 (Annualized) | F8: Quantity Change (Annualized vs 2025) | G8: Quantity Change % (Annualized vs 2025) | H8: Amount 2025 (₪) | I8: Amount 2026 (Actual, partial year) (₪) | J8: Amount 2026 (Annualized) (₪) | K8: Amount Change (Annualized vs 2025) (₪) | L8: Amount Change % (Annualized vs 2025)
A9: 21 | B9: =IFERROR(INDEX('Source 2026'!$C:$C,MATCH($A9,'Source 2026'!$B:$B,0)),IFERROR(INDEX('Source 2025'!$C:$C,MATCH($A9,'Source 2025'!$B:$B,0)),"")) -> S חבק יד ארוך | C9: =SUMIFS('Source 2025'!$F:$F,'Source 2025'!$B:$B,$A9,'Source 2025'!$A:$A,"Quantity (units)")+SUMIFS('Source 2025'!$H:$H,'Source 2025'!$B:$B,$A9,'Source 2025'!$A:$A,"Quantity (units)")+SUMIFS('Source 2025'!$M:$M,'Source 2025'!$B:$B,$A9,'Source 2025'!$A:$A,"Quantity (units)")+SUMIFS('Source 2025'!$N:$N,'Source 2025'!$B:$B,$A9,'Source 2025'!$A:$A,"Quantity (units)")+SUMIFS('Source 2025'!$S:$S,'Source 2025'!$B:$B,$A9,'Source 2025'!$A:$A,"Quantity (units)")+SUMIFS('Source 2025'!$U:$U,'Source 2025'!$B:$B,$A9,'Source 2025'!$A:$A,"Quantity (units)")+SUMIFS('Source 2025'!$D:$D,'Source 2025'!$B:$B,$A9,'Source 2025'!$A:$A,"Quantity (units)")+SUMIFS('Source 2025'!$E:$E,'Source 2025'!$B:$B,$A9,'Source 2025'!$A:$A,"Quantity (units)")+SUMIFS('Source 2025'!$G:$G,'Source 2025'!$B:$B,$A9,'Source 2025'!$A:$A,"Quantity (units)") -> 1868 | D9: =SUMIFS('Source 2026'!$F:$F,'Source 2026'!$B:$B,$A9,'Source 2026'!$A:$A,"Quantity (units)")+SUMIFS('Source 2026'!$H:$H,'Source 2026'!$B:$B,$A9,'Source 2026'!$A:$A,"Quantity (units)")+SUMIFS('Source 2026'!$M:$M,'Source 2026'!$B:$B,$A9,'Source 2026'!$A:$A,"Quantity (units)")+SUMIFS('Source 2026'!$N:$N,'Source 2026'!$B:$B,$A9,'Source 2026'!$A:$A,"Quantity (units)")+SUMIFS('Source 2026'!$S:$S,'Source 2026'!$B:$B,$A9,'Source 2026'!$A:$A,"Quantity (units)")+SUMIFS('Source 2026'!$U:$U,'Source 2026'!$B:$B,$A9,'Source 2026'!$A:$A,"Quantity (units)")+SUMIFS('Source 2026'!$D:$D,'Source 2026'!$B:$B,$A9,'Source 2026'!$A:$A,"Quantity (units)")+SUMIFS('Source 2026'!$E:$E,'Source 2026'!$B:$B,$A9,'Source 2026'!$A:$A,"Quantity (units)")+SUMIFS('Source 2026'!$G:$G,'Source 2026'!$B:$B,$A9,'Source 2026'!$A:$A,"Quantity (units)") -> 946 | E9: =D9*$J$5 -> 1194.9474 | F9: =E9-C9 -> -673.05263 | G9: =IF(AND(C9=0,E9=0),0,IF(C9=0,"New",(E9-C9)/C9)) -> -0.36030655 | H9: =SUMIFS('Source 2025'!$F:$F,'Source 2025'!$B:$B,$A9,'Source 2025'!$A:$A,"Amount (NIS)")+SUMIFS('Source 2025'!$H:$H,'Source 2025'!$B:$B,$A9,'Source 2025'!$A:$A,"Amount (NIS)")+SUMIFS('Source 2025'!$M:$M,'Source 2025'!$B:$B,$A9,'Source 2025'!$A:$A,"Amount (NIS)")+SUMIFS('Source 2025'!$N:$N,'Source 2025'!$B:$B,$A9,'Source 2025'!$A:$A,"Amount (NIS)")+SUMIFS('Source 2025'!$S:$S,'Source 2025'!$B:$B,$A9,'Source 2025'!$A:$A,"Amount (NIS)")+SUMIFS('Source 2025'!$U:$U,'Source 2025'!$B:$B,$A9,'Source 2025'!$A:$A,"Amount (NIS)")+SUMIFS('Source 2025'!$D:$D,'Source 2025'!$B:$B,$A9,'Source 2025'!$A:$A,"Amount (NIS)")+SUMIFS('Source 2025'!$E:$E,'Source 2025'!$B:$B,$A9,'Source 2025'!$A:$A,"Amount (NIS)")+SUMIFS('Source 2025'!$G:$G,'Source 2025'!$B:$B,$A9,'Source 2025'!$A:$A,"Amount (NIS)") -> 72420.2 | I9: =SUMIFS('Source 2026'!$F:$F,'Source 2026'!$B:$B,$A9,'Source 2026'!$A:$A,"Amount (NIS)")+SUMIFS('Source 2026'!$H:$H,'Source 2026'!$B:$B,$A9,'Source 2026'!$A:$A,"Amount (NIS)")+SUMIFS('Source 2026'!$M:$M,'Source 2026'!$B:$B,$A9,'Source 2026'!$A:$A,"Amount (NIS)")+SUMIFS('Source 2026'!$N:$N,'Source 2026'!$B:$B,$A9,'Source 2026'!$A:$A,"Amount (NIS)")+SUMIFS('Source 2026'!$S:$S,'Source 2026'!$B:$B,$A9,'Source 2026'!$A:$A,"Amount (NIS)")+SUMIFS('Source 2026'!$U:$U,'Source 2026'!$B:$B,$A9,'Source 2026'!$A:$A,"Amount (NIS)")+SUMIFS('Source 2026'!$D:$D,'Source 2026'!$B:$B,$A9,'Source 2026'!$A:$A,"Amount (NIS)")+SUMIFS('Source 2026'!$E:$E,'Source 2026'!$B:$B,$A9,'Source 2026'!$A:$A,"Amount (NIS)")+SUMIFS('Source 2026'!$G:$G,'Source 2026'!$B:$B,$A9,'Source 2026'!$A:$A,"Amount (NIS)") -> 36879 | J9: =I9*$J$5 -> 46584 | K9: =J9-H9 -> -25836.2 | L9: =IF(AND(H9=0,J9=0),0,IF(H9=0,"New",(J9-H9)/H9)) -> -0.35675405
A10: 397 | B10: =IFERROR(INDEX('Source 2026'!$C:$C,MATCH($A10,'Source 2026'!$B:$B,0)),IFERROR(INDEX('Source 2025'!$C:$C,MATCH($A10,'Source 2025'!$B:$B,0)),"")) -> 35-38 גרבי טיסה מידה | C10: =SUMIFS('Source 2025'!$F:$F,'Source 2025'!$B:$B,$A10,'Source 2025'!$A:$A,"Quantity (units)")+SUMIFS('Source 2025'!$H:$H,'Source 2025'!$B:$B,$A10,'Source 2025'!$A:$A,"Quantity (units)")+SUMIFS('Source 2025'!$M:$M,'Source 2025'!$B:$B,$A10,'Source 2025'!$A:$A,"Quantity (units)")+SUMIFS('Source 2025'!$N:$N,'Source 2025'!$B:$B,$A10,'Source 2025'!$A:$A,"Quantity (units)")+SUMIFS('Source 2025'!$S:$S,'Source 2025'!$B:$B,$A10,'Source 2025'!$A:$A,"Quantity (units)")+SUMIFS('Source 2025'!$U:$U,'Source 2025'!$B:$B,$A10,'Source 2025'!$A:$A,"Quantity (units)")+SUMIFS('Source 2025'!$D:$D,'Source 2025'!$B:$B,$A10,'Source 2025'!$A:$A,"Quantity (units)")+SUMIFS('Source 2025'!$E:$E,'Source 2025'!$B:$B,$A10,'Source 2025'!$A:$A,"Quantity (units)")+SUMIFS('Source 2025'!$G:$G,'Source 2025'!$B:$B,$A10,'Source 2025'!$A:$A,"Quantity (units)") -> 537 | D10: =SUMIFS('Source 2026'!$F:$F,'Source 2026'!$B:$B,$A10,'Source 2026'!$A:$A,"Quantity (units)")+SUMIFS('Source 2026'!$H:$H,'Source 2026'!$B:$B,$A10,'Source 2026'!$A:$A,"Quantity (units)")+SUMIFS('Source 2026'!$M:$M,'Source 2026'!$B:$B,$A10,'Source 2026'!$A:$A,"Quantity (units)")+SUMIFS('Source 2026'!$N:$N,'Source 2026'!$B:$B,$A10,'Source 2026'!$A:$A,"Quantity (units)")+SUMIFS('Source 2026'!$S:$S,'Source 2026'!$B:$B,$A10,'Source 2026'!$A:$A,"Quantity (units)")+SUMIFS('Source 2026'!$U:$U,'Source 2026'!$B:$B,$A10,'Source 2026'!$A:$A,"Quantity (units)")+SUMIFS('Source 2026'!$D:$D,'Source 2026'!$B:$B,$A10,'Source 2026'!$A:$A,"Quantity (units)")+SUMIFS('Source 2026'!$E:$E,'Source 2026'!$B:$B,$A10,'Source 2026'!$A:$A,"Quantity (units)")+SUMIFS('Source 2026'!$G:$G,'Source 2026'!$B:$B,$A10,'Source 2026'!$A:$A,"Quantity (units)") -> -2 | E10: =D10*$J$5 -> -2.5263158 | F10: =E10-C10 -> -539.52632 | G10: =IF(AND(C10=0,E10=0),0,IF(C10=0,"New",(E10-C10)/C10)) -> -1.0047045 | H10: =SUMIFS('Source 2025'!$F:$F,'Source 2025'!$B:$B,$A10,'Source 2025'!$A:$A,"Amount (NIS)")+SUMIFS('Source 2025'!$H:$H,'Source 2025'!$B:$B,$A10,'Source 2025'!$A:$A,"Amount (NIS)")+SUMIFS('Source 2025'!$M:$M,'Source 2025'!$B:$B,$A10,'Source 2025'!$A:$A,"Amount (NIS)")+SUMIFS('Source 2025'!$N:$N,'Source 2025'!$B:$B,$A10,'Source 2025'!$A:$A,"Amount (NIS)")+SUMIFS('Source 2025'!$S:$S,'Source 2025'!$B:$B,$A10,'Source 2025'!$A:$A,"Amount (NIS)")+SUMIFS('Source 2025'!$U:$U,'Source 2025'!$B:$B,$A10,'Source 2025'!$A:$A,"Amount (NIS)")+SUMIFS('Source 2025'!$D:$D,'Source 2025'!$B:$B,$A10,'Source 2025'!$A:$A,"Amount (NIS)")+SUMIFS('Source 2025'!$E:$E,'Source 2025'!$B:$B,$A10,'Source 2025'!$A:$A,"Amount (NIS)")+SUMIFS('Source 2025'!$G:$G,'Source 2025'!$B:$B,$A10,'Source 2025'!$A:$A,"Amount (NIS)") -> 31672.4 | I10: =SUMIFS('Source 2026'!$F:$F,'Source 2026'!$B:$B,$A10,'Source 2026'!$A:$A,"Amount (NIS)")+SUMIFS('Source 2026'!$H:$H,'Source 2026'!$B:$B,$A10,'Source 2026'!$A:$A,"Amount (NIS)")+SUMIFS('Source 2026'!$M:$M,'Source 2026'!$B:$B,$A10,'Source 2026'!$A:$A,"Amount (NIS)")+SUMIFS('Source 2026'!$N:$N,'Source 2026'!$B:$B,$A10,'Source 2026'!$A:$A,"Amount (NIS)")+SUMIFS('Source 2026'!$S:$S,'Source 2026'!$B:$B,$A10,'Source 2026'!$A:$A,"Amount (NIS)")+SUMIFS('Source 2026'!$U:$U,'Source 2026'!$B:$B,$A10,'Source 2026'!$A:$A,"Amount (NIS)")+SUMIFS('Source 2026'!$D:$D,'Source 2026'!$B:$B,$A10,'Source 2026'!$A:$A,"Amount (NIS)")+SUMIFS('Source 2026'!$E:$E,'Source 2026'!$B:$B,$A10,'Source 2026'!$A:$A,"Amount (NIS)")+SUMIFS('Source 2026'!$G:$G,'Source 2026'!$B:$B,$A10,'Source 2026'!$A:$A,"Amount (NIS)") -> -82.3 | J10: =I10*$J$5 -> -103.95789 | K10: =J10-H10 -> -31776.358 | L10: =IF(AND(H10=0,J10=0),0,IF(H10=0,"New",(J10-H10)/H10)) -> -1.0032823
A11: 397A-גרבי | B11: =IFERROR(INDEX('Source 2026'!$C:$C,MATCH($A11,'Source 2026'!$B:$B,0)),IFERROR(INDEX('Source 2025'!$C:$C,MATCH($A11,'Source 2025'!$B:$B,0)),"")) -> טיסה אנטי בקטרי35-38 | C11: =SUMIFS('Source 2025'!$F:$F,'Source 2025'!$B:$B,$A11,'Source 2025'!$A:$A,"Quantity (units)")+SUMIFS('Source 2025'!$H:$H,'Source 2025'!$B:$B,$A11,'Source 2025'!$A:$A,"Quantity (units)")+SUMIFS('Source 2025'!$M:$M,'Source 2025'!$B:$B,$A11,'Source 2025'!$A:$A,"Quantity (units)")+SUMIFS('Source 2025'!$N:$N,'Source 2025'!$B:$B,$A11,'Source 2025'!$A:$A,"Quantity (units)")+SUMIFS('Source 2025'!$S:$S,'Source 2025'!$B:$B,$A11,'Source 2025'!$A:$A,"Quantity (units)")+SUMIFS('Source 2025'!$U:$U,'Source 2025'!$B:$B,$A11,'Source 2025'!$A:$A,"Quantity (units)")+SUMIFS('Source 2025'!$D:$D,'Source 2025'!$B:$B,$A11,'Source 2025'!$A:$A,"Quantity (units)")+SUMIFS('Source 2025'!$E:$E,'Source 2025'!$B:$B,$A11,'Source 2025'!$A:$A,"Quantity (units)")+SUMIFS('Source 2025'!$G:$G,'Source 2025'!$B:$B,$A11,'Source 2025'!$A:$A,"Quantity (units)") -> 0 | D11: =SUMIFS('Source 2026'!$F:$F,'Source 2026'!$B:$B,$A11,'Source 2026'!$A:$A,"Quantity (units)")+SUMIFS('Source 2026'!$H:$H,'Source 2026'!$B:$B,$A11,'Source 2026'!$A:$A,"Quantity (units)")+SUMIFS('Source 2026'!$M:$M,'Source 2026'!$B:$B,$A11,'Source 2026'!$A:$A,"Quantity (units)")+SUMIFS('Source 2026'!$N:$N,'Source 2026'!$B:$B,$A11,'Source 2026'!$A:$A,"Quantity (units)")+SUMIFS('Source 2026'!$S:$S,'Source 2026'!$B:$B,$A11,'Source 2026'!$A:$A,"Quantity (units)")+SUMIFS('Source 2026'!$U:$U,'Source 2026'!$B:$B,$A11,'Source 2026'!$A:$A,"Quantity (units)")+SUMIFS('Source 2026'!$D:$D,'Source 2026'!$B:$B,$A11,'Source 2026'!$A:$A,"Quantity (units)")+SUMIFS('Source 2026'!$E:$E,'Source 2026'!$B:$B,$A11,'Source 2026'!$A:$A,"Quantity (units)")+SUMIFS('Source 2026'!$G:$G,'Source 2026'!$B:$B,$A11,'Source 2026'!$A:$A,"Quantity (units)") -> 456 | E11: =D11*$J$5 -> 576 | F11: =E11-C11 -> 576 | G11: =IF(AND(C11=0,E11=0),0,IF(C11=0,"New",(E11-C11)/C11)) -> New | H11: =SUMIFS('Source 2025'!$F:$F,'Source 2025'!$B:$B,$A11,'Source 2025'!$A:$A,"Amount (NIS)")+SUMIFS('Source 2025'!$H:$H,'Source 2025'!$B:$B,$A11,'Source 2025'!$A:$A,"Amount (NIS)")+SUMIFS('Source 2025'!$M:$M,'Source 2025'!$B:$B,$A11,'Source 2025'!$A:$A,"Amount (NIS)")+SUMIFS('Source 2025'!$N:$N,'Source 2025'!$B:$B,$A11,'Source 2025'!$A:$A,"Amount (NIS)")+SUMIFS('Source 2025'!$S:$S,'Source 2025'!$B:$B,$A11,'Source 2025'!$A:$A,"Amount (NIS)")+SUMIFS('Source 2025'!$U:$U,'Source 2025'!$B:$B,$A11,'Source 2025'!$A:$A,"Amount (NIS)")+SUMIFS('Source 2025'!$D:$D,'Source 2025'!$B:$B,$A11,'Source 2025'!$A:$A,"Amount (NIS)")+SUMIFS('Source 2025'!$E:$E,'Source 2025'!$B:$B,$A11,'Source 2025'!$A:$A,"Amount (NIS)")+SUMIFS('Source 2025'!$G:$G,'Source 2025'!$B:$B,$A11,'Source 2025'!$A:$A,"Amount (NIS)") -> 0 | I11: =SUMIFS('Source 2026'!$F:$F,'Source 2026'!$B:$B,$A11,'Source 2026'!$A:$A,"Amount (NIS)")+SUMIFS('Source 2026'!$H:$H,'Source 2026'!$B:$B,$A11,'Source 2026'!$A:$A,"Amount (NIS)")+SUMIFS('Source 2026'!$M:$M,'Source 2026'!$B:$B,$A11,'Source 2026'!$A:$A,"Amount (NIS)")+SUMIFS('Source 2026'!$N:$N,'Source 2026'!$B:$B,$A11,'Source 2026'!$A:$A,"Amount (NIS)")+SUMIFS('Source 2026'!$S:$S,'Source 2026'!$B:$B,$A11,'Source 2026'!$A:$A,"Amount (NIS)")+SUMIFS('Source 2026'!$U:$U,'Source 2026'!$B:$B,$A11,'Source 2026'!$A:$A,"Amount (NIS)")+SUMIFS('Source 2026'!$D:$D,'Source 2026'!$B:$B,$A11,'Source 2026'!$A:$A,"Amount (NIS)")+SUMIFS('Source 2026'!$E:$E,'Source 2026'!$B:$B,$A11,'Source 2026'!$A:$A,"Amount (NIS)")+SUMIFS('Source 2026'!$G:$G,'Source 2026'!$B:$B,$A11,'Source 2026'!$A:$A,"Amount (NIS)") -> 27020.5 | J11: =I11*$J$5 -> 34131.158 | K11: =J11-H11 -> 34131.158 | L11: =IF(AND(H11=0,J11=0),0,IF(H11=0,"New",(J11-H11)/H11)) -> New
A12: 302 | B12: =IFERROR(INDEX('Source 2026'!$C:$C,MATCH($A12,'Source 2026'!$B:$B,0)),IFERROR(INDEX('Source 2025'!$C:$C,MATCH($A12,'Source 2025'!$B:$B,0)),"")) -> מדרס ג'ל לגבר | C12: =SUMIFS('Source 2025'!$F:$F,'Source 2025'!$B:$B,$A12,'Source 2025'!$A:$A,"Quantity (units)")+SUMIFS('Source 2025'!$H:$H,'Source 2025'!$B:$B,$A12,'Source 2025'!$A:$A,"Quantity (units)")+SUMIFS('Source 2025'!$M:$M,'Source 2025'!$B:$B,$A12,'Source 2025'!$A:$A,"Quantity (units)")+SUMIFS('Source 2025'!$N:$N,'Source 2025'!$B:$B,$A12,'Source 2025'!$A:$A,"Quantity (units)")+SUMIFS('Source 2025'!$S:$S,'Source 2025'!$B:$B,$A12,'Source 2025'!$A:$A,"Quantity (units)")+SUMIFS('Source 2025'!$U:$U,'Source 2025'!$B:$B,$A12,'Source 2025'!$A:$A,"Quantity (units)")+SUMIFS('Source 2025'!$D:$D,'Source 2025'!$B:$B,$A12,'Source 2025'!$A:$A,"Quantity (units)")+SUMIFS('Source 2025'!$E:$E,'Source 2025'!$B:$B,$A12,'Source 2025'!$A:$A,"Quantity (units)")+SUMIFS('Source 2025'!$G:$G,'Source 2025'!$B:$B,$A12,'Source 2025'!$A:$A,"Quantity (units)") -> 841 | D12: =SUMIFS('Source 2026'!$F:$F,'Source 2026'!$B:$B,$A12,'Source 2026'!$A:$A,"Quantity (units)")+SUMIFS('Source 2026'!$H:$H,'Source 2026'!$B:$B,$A12,'Source 2026'!$A:$A,"Quantity (units)")+SUMIFS('Source 2026'!$M:$M,'Source 2026'!$B:$B,$A12,'Source 2026'!$A:$A,"Quantity (units)")+SUMIFS('Source 2026'!$N:$N,'Source 2026'!$B:$B,$A12,'Source 2026'!$A:$A,"Quantity (units)")+SUMIFS('Source 2026'!$S:$S,'Source 2026'!$B:$B,$A12,'Source 2026'!$A:$A,"Quantity (units)")+SUMIFS('Source 2026'!$U:$U,'Source 2026'!$B:$B,$A12,'Source 2026'!$A:$A,"Quantity (units)")+SUMIFS('Source 2026'!$D:$D,'Source 2026'!$B:$B,$A12,'Source 2026'!$A:$A,"Quantity (units)")+SUMIFS('Source 2026'!$E:$E,'Source 2026'!$B:$B,$A12,'Source 2026'!$A:$A,"Quantity (units)")+SUMIFS('Source 2026'!$G:$G,'Source 2026'!$B:$B,$A12,'Source 2026'!$A:$A,"Quantity (units)") -> 378 | E12: =D12*$J$5 -> 477.47368 | F12: =E12-C12 -> -363.52632 | G12: =IF(AND(C12=0,E12=0),0,IF(C12=0,"New",(E12-C12)/C12)) -> -0.43225483 | H12: =SUMIFS('Source 2025'!$F:$F,'Source 2025'!$B:$B,$A12,'Source 2025'!$A:$A,"Amount (NIS)")+SUMIFS('Source 2025'!$H:$H,'Source 2025'!$B:$B,$A12,'Source 2025'!$A:$A,"Amount (NIS)")+SUMIFS('Source 2025'!$M:$M,'Source 2025'!$B:$B,$A12,'Source 2025'!$A:$A,"Amount (NIS)")+SUMIFS('Source 2025'!$N:$N,'Source 2025'!$B:$B,$A12,'Source 2025'!$A:$A,"Amount (NIS)")+SUMIFS('Source 2025'!$S:$S,'Source 2025'!$B:$B,$A12,'Source 2025'!$A:$A,"Amount (NIS)")+SUMIFS('Source 2025'!$U:$U,'Source 2025'!$B:$B,$A12,'Source 2025'!$A:$A,"Amount (NIS)")+SUMIFS('Source 2025'!$D:$D,'Source 2025'!$B:$B,$A12,'Source 2025'!$A:$A,"Amount (NIS)")+SUMIFS('Source 2025'!$E:$E,'Source 2025'!$B:$B,$A12,'Source 2025'!$A:$A,"Amount (NIS)")+SUMIFS('Source 2025'!$G:$G,'Source 2025'!$B:$B,$A12,'Source 2025'!$A:$A,"Amount (NIS)") -> 50057.5 | I12: =SUMIFS('Source 2026'!$F:$F,'Source 2026'!$B:$B,$A12,'Source 2026'!$A:$A,"Amount (NIS)")+SUMIFS('Source 2026'!$H:$H,'Source 2026'!$B:$B,$A12,'Source 2026'!$A:$A,"Amount (NIS)")+SUMIFS('Source 2026'!$M:$M,'Source 2026'!$B:$B,$A12,'Source 2026'!$A:$A,"Amount (NIS)")+SUMIFS('Source 2026'!$N:$N,'Source 2026'!$B:$B,$A12,'Source 2026'!$A:$A,"Amount (NIS)")+SUMIFS('Source 2026'!$S:$S,'Source 2026'!$B:$B,$A12,'Source 2026'!$A:$A,"Amount (NIS)")+SUMIFS('Source 2026'!$U:$U,'Source 2026'!$B:$B,$A12,'Source 2026'!$A:$A,"Amount (NIS)")+SUMIFS('Source 2026'!$D:$D,'Source 2026'!$B:$B,$A12,'Source 2026'!$A:$A,"Amount (NIS)")+SUMIFS('Source 2026'!$E:$E,'Source 2026'!$B:$B,$A12,'Source 2026'!$A:$A,"Amount (NIS)")+SUMIFS('Source 2026'!$G:$G,'Source 2026'!$B:$B,$A12,'Source 2026'!$A:$A,"Amount (NIS)") -> 24242.7 | J12: =I12*$J$5 -> 30622.358 | K12: =J12-H12 -> -19435.142 | L12: =IF(AND(H12=0,J12=0),0,IF(H12=0,"New",(J12-H12)/H12)) -> -0.38825635
A13: AC-07 | B13: =IFERROR(INDEX('Source 2026'!$C:$C,MATCH($A13,'Source 2026'!$B:$B,0)),IFERROR(INDEX('Source 2025'!$C:$C,MATCH($A13,'Source 2025'!$B:$B,0)),"")) -> חגורת גב עם תמיכות | C13: =SUMIFS('Source 2025'!$F:$F,'Source 2025'!$B:$B,$A13,'Source 2025'!$A:$A,"Quantity (units)")+SUMIFS('Source 2025'!$H:$H,'Source 2025'!$B:$B,$A13,'Source 2025'!$A:$A,"Quantity (units)")+SUMIFS('Source 2025'!$M:$M,'Source 2025'!$B:$B,$A13,'Source 2025'!$A:$A,"Quantity (units)")+SUMIFS('Source 2025'!$N:$N,'Source 2025'!$B:$B,$A13,'Source 2025'!$A:$A,"Quantity (units)")+SUMIFS('Source 2025'!$S:$S,'Source 2025'!$B:$B,$A13,'Source 2025'!$A:$A,"Quantity (units)")+SUMIFS('Source 2025'!$U:$U,'Source 2025'!$B:$B,$A13,'Source 2025'!$A:$A,"Quantity (units)")+SUMIFS('Source 2025'!$D:$D,'Source 2025'!$B:$B,$A13,'Source 2025'!$A:$A,"Quantity (units)")+SUMIFS('Source 2025'!$E:$E,'Source 2025'!$B:$B,$A13,'Source 2025'!$A:$A,"Quantity (units)")+SUMIFS('Source 2025'!$G:$G,'Source 2025'!$B:$B,$A13,'Source 2025'!$A:$A,"Quantity (units)") -> 1110 | D13: =SUMIFS('Source 2026'!$F:$F,'Source 2026'!$B:$B,$A13,'Source 2026'!$A:$A,"Quantity (units)")+SUMIFS('Source 2026'!$H:$H,'Source 2026'!$B:$B,$A13,'Source 2026'!$A:$A,"Quantity (units)")+SUMIFS('Source 2026'!$M:$M,'Source 2026'!$B:$B,$A13,'Source 2026'!$A:$A,"Quantity (units)")+SUMIFS('Source 2026'!$N:$N,'Source 2026'!$B:$B,$A13,'Source 2026'!$A:$A,"Quantity (units)")+SUMIFS('Source 2026'!$S:$S,'Source 2026'!$B:$B,$A13,'Source 2026'!$A:$A,"Quantity (units)")+SUMIFS('Source 2026'!$U:$U,'Source 2026'!$B:$B,$A13,'Source 2026'!$A:$A,"Quantity (units)")+SUMIFS('Source 2026'!$D:$D,'Source 2026'!$B:$B,$A13,'Source 2026'!$A:$A,"Quantity (units)")+SUMIFS('Source 2026'!$E:$E,'Source 2026'!$B:$B,$A13,'Source 2026'!$A:$A,"Quantity (units)")+SUMIFS('Source 2026'!$G:$G,'Source 2026'!$B:$B,$A13,'Source 2026'!$A:$A,"Quantity (units)") -> 802 | E13: =D13*$J$5 -> 1013.0526 | F13: =E13-C13 -> -96.947368 | G13: =IF(AND(C13=0,E13=0),0,IF(C13=0,"New",(E13-C13)/C13)) -> -0.087339972 | H13: =SUMIFS('Source 2025'!$F:$F,'Source 2025'!$B:$B,$A13,'Source 2025'!$A:$A,"Amount (NIS)")+SUMIFS('Source 2025'!$H:$H,'Source 2025'!$B:$B,$A13,'Source 2025'!$A:$A,"Amount (NIS)")+SUMIFS('Source 2025'!$M:$M,'Source 2025'!$B:$B,$A13,'Source 2025'!$A:$A,"Amount (NIS)")+SUMIFS('Source 2025'!$N:$N,'Source 2025'!$B:$B,$A13,'Source 2025'!$A:$A,"Amount (NIS)")+SUMIFS('Source 2025'!$S:$S,'Source 2025'!$B:$B,$A13,'Source 2025'!$A:$A,"Amount (NIS)")+SUMIFS('Source 2025'!$U:$U,'Source 2025'!$B:$B,$A13,'Source 2025'!$A:$A,"Amount (NIS)")+SUMIFS('Source 2025'!$D:$D,'Source 2025'!$B:$B,$A13,'Source 2025'!$A:$A,"Amount (NIS)")+SUMIFS('Source 2025'!$E:$E,'Source 2025'!$B:$B,$A13,'Source 2025'!$A:$A,"Amount (NIS)")+SUMIFS('Source 2025'!$G:$G,'Source 2025'!$B:$B,$A13,'Source 2025'!$A:$A,"Amount (NIS)") -> 94616.3 | I13: =SUMIFS('Source 2026'!$F:$F,'Source 2026'!$B:$B,$A13,'Source 2026'!$A:$A,"Amount (NIS)")+SUMIFS('Source 2026'!$H:$H,'Source 2026'!$B:$B,$A13,'Source 2026'!$A:$A,"Amount (NIS)")+SUMIFS('Source 2026'!$M:$M,'Source 2026'!$B:$B,$A13,'Source 2026'!$A:$A,"Amount (NIS)")+SUMIFS('Source 2026'!$N:$N,'Source 2026'!$B:$B,$A13,'Source 2026'!$A:$A,"Amount (NIS)")+SUMIFS('Source 2026'!$S:$S,'Source 2026'!$B:$B,$A13,'Source 2026'!$A:$A,"Amount (NIS)")+SUMIFS('Source 2026'!$U:$U,'Source 2026'!$B:$B,$A13,'Source 2026'!$A:$A,"Amount (NIS)")+SUMIFS('Source 2026'!$D:$D,'Source 2026'!$B:$B,$A13,'Source 2026'!$A:$A,"Amount (NIS)")+SUMIFS('Source 2026'!$E:$E,'Source 2026'!$B:$B,$A13,'Source 2026'!$A:$A,"Amount (NIS)")+SUMIFS('Source 2026'!$G:$G,'Source 2026'!$B:$B,$A13,'Source 2026'!$A:$A,"Amount (NIS)") -> 69090.9 | J13: =I13*$J$5 -> 87272.716 | K13: =J13-H13 -> -7343.5842 | L13: =IF(AND(H13=0,J13=0),0,IF(H13=0,"New",(J13-H13)/H13)) -> -0.077614367
A14: SH422 | B14: =IFERROR(INDEX('Source 2026'!$C:$C,MATCH($A14,'Source 2026'!$B:$B,0)),IFERROR(INDEX('Source 2025'!$C:$C,MATCH($A14,'Source 2025'!$B:$B,0)),"")) -> 1 תומך ברך גנושילד | C14: =SUMIFS('Source 2025'!$F:$F,'Source 2025'!$B:$B,$A14,'Source 2025'!$A:$A,"Quantity (units)")+SUMIFS('Source 2025'!$H:$H,'Source 2025'!$B:$B,$A14,'Source 2025'!$A:$A,"Quantity (units)")+SUMIFS('Source 2025'!$M:$M,'Source 2025'!$B:$B,$A14,'Source 2025'!$A:$A,"Quantity (units)")+SUMIFS('Source 2025'!$N:$N,'Source 2025'!$B:$B,$A14,'Source 2025'!$A:$A,"Quantity (units)")+SUMIFS('Source 2025'!$S:$S,'Source 2025'!$B:$B,$A14,'Source 2025'!$A:$A,"Quantity (units)")+SUMIFS('Source 2025'!$U:$U,'Source 2025'!$B:$B,$A14,'Source 2025'!$A:$A,"Quantity (units)")+SUMIFS('Source 2025'!$D:$D,'Source 2025'!$B:$B,$A14,'Source 2025'!$A:$A,"Quantity (units)")+SUMIFS('Source 2025'!$E:$E,'Source 2025'!$B:$B,$A14,'Source 2025'!$A:$A,"Quantity (units)")+SUMIFS('Source 2025'!$G:$G,'Source 2025'!$B:$B,$A14,'Source 2025'!$A:$A,"Quantity (units)") -> 19 | D14: =SUMIFS('Source 2026'!$F:$F,'Source 2026'!$B:$B,$A14,'Source 2026'!$A:$A,"Quantity (units)")+SUMIFS('Source 2026'!$H:$H,'Source 2026'!$B:$B,$A14,'Source 2026'!$A:$A,"Quantity (units)")+SUMIFS('Source 2026'!$M:$M,'Source 2026'!$B:$B,$A14,'Source 2026'!$A:$A,"Quantity (units)")+SUMIFS('Source 2026'!$N:$N,'Source 2026'!$B:$B,$A14,'Source 2026'!$A:$A,"Quantity (units)")+SUMIFS('Source 2026'!$S:$S,'Source 2026'!$B:$B,$A14,'Source 2026'!$A:$A,"Quantity (units)")+SUMIFS('Source 2026'!$U:$U,'Source 2026'!$B:$B,$A14,'Source 2026'!$A:$A,"Quantity (units)")+SUMIFS('Source 2026'!$D:$D,'Source 2026'!$B:$B,$A14,'Source 2026'!$A:$A,"Quantity (units)")+SUMIFS('Source 2026'!$E:$E,'Source 2026'!$B:$B,$A14,'Source 2026'!$A:$A,"Quantity (units)")+SUMIFS('Source 2026'!$G:$G,'Source 2026'!$B:$B,$A14,'Source 2026'!$A:$A,"Quantity (units)") -> 114 | E14: =D14*$J$5 -> 144 | F14: =E14-C14 -> 125 | G14: =IF(AND(C14=0,E14=0),0,IF(C14=0,"New",(E14-C14)/C14)) -> 6.5789474 | H14: =SUMIFS('Source 2025'!$F:$F,'Source 2025'!$B:$B,$A14,'Source 2025'!$A:$A,"Amount (NIS)")+SUMIFS('Source 2025'!$H:$H,'Source 2025'!$B:$B,$A14,'Source 2025'!$A:$A,"Amount (NIS)")+SUMIFS('Source 2025'!$M:$M,'Source 2025'!$B:$B,$A14,'Source 2025'!$A:$A,"Amount (NIS)")+SUMIFS('Source 2025'!$N:$N,'Source 2025'!$B:$B,$A14,'Source 2025'!$A:$A,"Amount (NIS)")+SUMIFS('Source 2025'!$S:$S,'Source 2025'!$B:$B,$A14,'Source 2025'!$A:$A,"Amount (NIS)")+SUMIFS('Source 2025'!$U:$U,'Source 2025'!$B:$B,$A14,'Source 2025'!$A:$A,"Amount (NIS)")+SUMIFS('Source 2025'!$D:$D,'Source 2025'!$B:$B,$A14,'Source 2025'!$A:$A,"Amount (NIS)")+SUMIFS('Source 2025'!$E:$E,'Source 2025'!$B:$B,$A14,'Source 2025'!$A:$A,"Amount (NIS)")+SUMIFS('Source 2025'!$G:$G,'Source 2025'!$B:$B,$A14,'Source 2025'!$A:$A,"Amount (NIS)") -> 4034.6 | I14: =SUMIFS('Source 2026'!$F:$F,'Source 2026'!$B:$B,$A14,'Source 2026'!$A:$A,"Amount (NIS)")+SUMIFS('Source 2026'!$H:$H,'Source 2026'!$B:$B,$A14,'Source 2026'!$A:$A,"Amount (NIS)")+SUMIFS('Source 2026'!$M:$M,'Source 2026'!$B:$B,$A14,'Source 2026'!$A:$A,"Amount (NIS)")+SUMIFS('Source 2026'!$N:$N,'Source 2026'!$B:$B,$A14,'Source 2026'!$A:$A,"Amount (NIS)")+SUMIFS('Source 2026'!$S:$S,'Source 2026'!$B:$B,$A14,'Source 2026'!$A:$A,"Amount (NIS)")+SUMIFS('Source 2026'!$U:$U,'Source 2026'!$B:$B,$A14,'Source 2026'!$A:$A,"Amount (NIS)")+SUMIFS('Source 2026'!$D:$D,'Source 2026'!$B:$B,$A14,'Source 2026'!$A:$A,"Amount (NIS)")+SUMIFS('Source 2026'!$E:$E,'Source 2026'!$B:$B,$A14,'Source 2026'!$A:$A,"Amount (NIS)")+SUMIFS('Source 2026'!$G:$G,'Source 2026'!$B:$B,$A14,'Source 2026'!$A:$A,"Amount (NIS)") -> 23279.6 | J14: =I14*$J$5 -> 29405.811 | K14: =J14-H14 -> 25371.211 | L14: =IF(AND(H14=0,J14=0),0,IF(H14=0,"New",(J14-H14)/H14)) -> 6.2884079
A15: 307 | B15: =IFERROR(INDEX('Source 2026'!$C:$C,MATCH($A15,'Source 2026'!$B:$B,0)),IFERROR(INDEX('Source 2025'!$C:$C,MATCH($A15,'Source 2025'!$B:$B,0)),"")) -> L עקבים לדורבן-זוג כריות | C15: =SUMIFS('Source 2025'!$F:$F,'Source 2025'!$B:$B,$A15,'Source 2025'!$A:$A,"Quantity (units)")+SUMIFS('Source 2025'!$H:$H,'Source 2025'!$B:$B,$A15,'Source 2025'!$A:$A,"Quantity (units)")+SUMIFS('Source 2025'!$M:$M,'Source 2025'!$B:$B,$A15,'Source 2025'!$A:$A,"Quantity (units)")+SUMIFS('Source 2025'!$N:$N,'Source 2025'!$B:$B,$A15,'Source 2025'!$A:$A,"Quantity (units)")+SUMIFS('Source 2025'!$S:$S,'Source 2025'!$B:$B,$A15,'Source 2025'!$A:$A,"Quantity (units)")+SUMIFS('Source 2025'!$U:$U,'Source 2025'!$B:$B,$A15,'Source 2025'!$A:$A,"Quantity (units)")+SUMIFS('Source 2025'!$D:$D,'Source 2025'!$B:$B,$A15,'Source 2025'!$A:$A,"Quantity (units)")+SUMIFS('Source 2025'!$E:$E,'Source 2025'!$B:$B,$A15,'Source 2025'!$A:$A,"Quantity (units)")+SUMIFS('Source 2025'!$G:$G,'Source 2025'!$B:$B,$A15,'Source 2025'!$A:$A,"Quantity (units)") -> 465 | D15: =SUMIFS('Source 2026'!$F:$F,'Source 2026'!$B:$B,$A15,'Source 2026'!$A:$A,"Quantity (units)")+SUMIFS('Source 2026'!$H:$H,'Source 2026'!$B:$B,$A15,'Source 2026'!$A:$A,"Quantity (units)")+SUMIFS('Source 2026'!$M:$M,'Source 2026'!$B:$B,$A15,'Source 2026'!$A:$A,"Quantity (units)")+SUMIFS('Source 2026'!$N:$N,'Source 2026'!$B:$B,$A15,'Source 2026'!$A:$A,"Quantity (units)")+SUMIFS('Source 2026'!$S:$S,'Source 2026'!$B:$B,$A15,'Source 2026'!$A:$A,"Quantity (units)")+SUMIFS('Source 2026'!$U:$U,'Source 2026'!$B:$B,$A15,'Source 2026'!$A:$A,"Quantity (units)")+SUMIFS('Source 2026'!$D:$D,'Source 2026'!$B:$B,$A15,'Source 2026'!$A:$A,"Quantity (units)")+SUMIFS('Source 2026'!$E:$E,'Source 2026'!$B:$B,$A15,'Source 2026'!$A:$A,"Quantity (units)")+SUMIFS('Source 2026'!$G:$G,'Source 2026'!$B:$B,$A15,'Source 2026'!$A:$A,"Quantity (units)") -> 238 | E15: =D15*$J$5 -> 300.63158 | F15: =E15-C15 -> -164.36842 | G15: =IF(AND(C15=0,E15=0),0,IF(C15=0,"New",(E15-C15)/C15)) -> -0.35348048 | H15: =SUMIFS('Source 2025'!$F:$F,'Source 2025'!$B:$B,$A15,'Source 2025'!$A:$A,"Amount (NIS)")+SUMIFS('Source 2025'!$H:$H,'Source 2025'!$B:$B,$A15,'Source 2025'!$A:$A,"Amount (NIS)")+SUMIFS('Source 2025'!$M:$M,'Source 2025'!$B:$B,$A15,'Source 2025'!$A:$A,"Amount (NIS)")+SUMIFS('Source 2025'!$N:$N,'Source 2025'!$B:$B,$A15,'Source 2025'!$A:$A,"Amount (NIS)")+SUMIFS('Source 2025'!$S:$S,'Source 2025'!$B:$B,$A15,'Source 2025'!$A:$A,"Amount (NIS)")+SUMIFS('Source 2025'!$U:$U,'Source 2025'!$B:$B,$A15,'Source 2025'!$A:$A,"Amount (NIS)")+SUMIFS('Source 2025'!$D:$D,'Source 2025'!$B:$B,$A15,'Source 2025'!$A:$A,"Amount (NIS)")+SUMIFS('Source 2025'!$E:$E,'Source 2025'!$B:$B,$A15,'Source 2025'!$A:$A,"Amount (NIS)")+SUMIFS('Source 2025'!$G:$G,'Source 2025'!$B:$B,$A15,'Source 2025'!$A:$A,"Amount (NIS)") -> 37777.7 | I15: =SUMIFS('Source 2026'!$F:$F,'Source 2026'!$B:$B,$A15,'Source 2026'!$A:$A,"Amount (NIS)")+SUMIFS('Source 2026'!$H:$H,'Source 2026'!$B:$B,$A15,'Source 2026'!$A:$A,"Amount (NIS)")+SUMIFS('Source 2026'!$M:$M,'Source 2026'!$B:$B,$A15,'Source 2026'!$A:$A,"Amount (NIS)")+SUMIFS('Source 2026'!$N:$N,'Source 2026'!$B:$B,$A15,'Source 2026'!$A:$A,"Amount (NIS)")+SUMIFS('Source 2026'!$S:$S,'Source 2026'!$B:$B,$A15,'Source 2026'!$A:$A,"Amount (NIS)")+SUMIFS('Source 2026'!$U:$U,'Source 2026'!$B:$B,$A15,'Source 2026'!$A:$A,"Amount (NIS)")+SUMIFS('Source 2026'!$D:$D,'Source 2026'!$B:$B,$A15,'Source 2026'!$A:$A,"Amount (NIS)")+SUMIFS('Source 2026'!$E:$E,'Source 2026'!$B:$B,$A15,'Source 2026'!$A:$A,"Amount (NIS)")+SUMIFS('Source 2026'!$G:$G,'Source 2026'!$B:$B,$A15,'Source 2026'!$A:$A,"Amount (NIS)") -> 20230.4 | J15: =I15*$J$5 -> 25554.189 | K15: =J15-H15 -> -12223.511 | L15: =IF(AND(H15=0,J15=0),0,IF(H15=0,"New",(J15-H15)/H15)) -> -0.32356418
A16: 26 | B16: =IFERROR(INDEX('Source 2026'!$C:$C,MATCH($A16,'Source 2026'!$B:$B,0)),IFERROR(INDEX('Source 2025'!$C:$C,MATCH($A16,'Source 2025'!$B:$B,0)),"")) -> L סד ליד דו צדדי לאחר שבר | C16: =SUMIFS('Source 2025'!$F:$F,'Source 2025'!$B:$B,$A16,'Source 2025'!$A:$A,"Quantity (units)")+SUMIFS('Source 2025'!$H:$H,'Source 2025'!$B:$B,$A16,'Source 2025'!$A:$A,"Quantity (units)")+SUMIFS('Source 2025'!$M:$M,'Source 2025'!$B:$B,$A16,'Source 2025'!$A:$A,"Quantity (units)")+SUMIFS('Source 2025'!$N:$N,'Source 2025'!$B:$B,$A16,'Source 2025'!$A:$A,"Quantity (units)")+SUMIFS('Source 2025'!$S:$S,'Source 2025'!$B:$B,$A16,'Source 2025'!$A:$A,"Quantity (units)")+SUMIFS('Source 2025'!$U:$U,'Source 2025'!$B:$B,$A16,'Source 2025'!$A:$A,"Quantity (units)")+SUMIFS('Source 2025'!$D:$D,'Source 2025'!$B:$B,$A16,'Source 2025'!$A:$A,"Quantity (units)")+SUMIFS('Source 2025'!$E:$E,'Source 2025'!$B:$B,$A16,'Source 2025'!$A:$A,"Quantity (units)")+SUMIFS('Source 2025'!$G:$G,'Source 2025'!$B:$B,$A16,'Source 2025'!$A:$A,"Quantity (units)") -> 323 | D16: =SUMIFS('Source 2026'!$F:$F,'Source 2026'!$B:$B,$A16,'Source 2026'!$A:$A,"Quantity (units)")+SUMIFS('Source 2026'!$H:$H,'Source 2026'!$B:$B,$A16,'Source 2026'!$A:$A,"Quantity (units)")+SUMIFS('Source 2026'!$M:$M,'Source 2026'!$B:$B,$A16,'Source 2026'!$A:$A,"Quantity (units)")+SUMIFS('Source 2026'!$N:$N,'Source 2026'!$B:$B,$A16,'Source 2026'!$A:$A,"Quantity (units)")+SUMIFS('Source 2026'!$S:$S,'Source 2026'!$B:$B,$A16,'Source 2026'!$A:$A,"Quantity (units)")+SUMIFS('Source 2026'!$U:$U,'Source 2026'!$B:$B,$A16,'Source 2026'!$A:$A,"Quantity (units)")+SUMIFS('Source 2026'!$D:$D,'Source 2026'!$B:$B,$A16,'Source 2026'!$A:$A,"Quantity (units)")+SUMIFS('Source 2026'!$E:$E,'Source 2026'!$B:$B,$A16,'Source 2026'!$A:$A,"Quantity (units)")+SUMIFS('Source 2026'!$G:$G,'Source 2026'!$B:$B,$A16,'Source 2026'!$A:$A,"Quantity (units)") -> 157 | E16: =D16*$J$5 -> 198.31579 | F16: =E16-C16 -> -124.68421 | G16: =IF(AND(C16=0,E16=0),0,IF(C16=0,"New",(E16-C16)/C16)) -> -0.38601923 | H16: =SUMIFS('Source 2025'!$F:$F,'Source 2025'!$B:$B,$A16,'Source 2025'!$A:$A,"Amount (NIS)")+SUMIFS('Source 2025'!$H:$H,'Source 2025'!$B:$B,$A16,'Source 2025'!$A:$A,"Amount (NIS)")+SUMIFS('Source 2025'!$M:$M,'Source 2025'!$B:$B,$A16,'Source 2025'!$A:$A,"Amount (NIS)")+SUMIFS('Source 2025'!$N:$N,'Source 2025'!$B:$B,$A16,'Source 2025'!$A:$A,"Amount (NIS)")+SUMIFS('Source 2025'!$S:$S,'Source 2025'!$B:$B,$A16,'Source 2025'!$A:$A,"Amount (NIS)")+SUMIFS('Source 2025'!$U:$U,'Source 2025'!$B:$B,$A16,'Source 2025'!$A:$A,"Amount (NIS)")+SUMIFS('Source 2025'!$D:$D,'Source 2025'!$B:$B,$A16,'Source 2025'!$A:$A,"Amount (NIS)")+SUMIFS('Source 2025'!$E:$E,'Source 2025'!$B:$B,$A16,'Source 2025'!$A:$A,"Amount (NIS)")+SUMIFS('Source 2025'!$G:$G,'Source 2025'!$B:$B,$A16,'Source 2025'!$A:$A,"Amount (NIS)") -> 31686.2 | I16: =SUMIFS('Source 2026'!$F:$F,'Source 2026'!$B:$B,$A16,'Source 2026'!$A:$A,"Amount (NIS)")+SUMIFS('Source 2026'!$H:$H,'Source 2026'!$B:$B,$A16,'Source 2026'!$A:$A,"Amount (NIS)")+SUMIFS('Source 2026'!$M:$M,'Source 2026'!$B:$B,$A16,'Source 2026'!$A:$A,"Amount (NIS)")+SUMIFS('Source 2026'!$N:$N,'Source 2026'!$B:$B,$A16,'Source 2026'!$A:$A,"Amount (NIS)")+SUMIFS('Source 2026'!$S:$S,'Source 2026'!$B:$B,$A16,'Source 2026'!$A:$A,"Amount (NIS)")+SUMIFS('Source 2026'!$U:$U,'Source 2026'!$B:$B,$A16,'Source 2026'!$A:$A,"Amount (NIS)")+SUMIFS('Source 2026'!$D:$D,'Source 2026'!$B:$B,$A16,'Source 2026'!$A:$A,"Amount (NIS)")+SUMIFS('Source 2026'!$E:$E,'Source 2026'!$B:$B,$A16,'Source 2026'!$A:$A,"Amount (NIS)")+SUMIFS('Source 2026'!$G:$G,'Source 2026'!$B:$B,$A16,'Source 2026'!$A:$A,"Amount (NIS)") -> 15510.4 | J16: =I16*$J$5 -> 19592.084 | K16: =J16-H16 -> -12094.116 | L16: =IF(AND(H16=0,J16=0),0,IF(H16=0,"New",(J16-H16)/H16)) -> -0.38168401
A17: 60 | B17: =IFERROR(INDEX('Source 2026'!$C:$C,MATCH($A17,'Source 2026'!$B:$B,0)),IFERROR(INDEX('Source 2025'!$C:$C,MATCH($A17,'Source 2025'!$B:$B,0)),"")) -> L צוארון ספוגי | C17: =SUMIFS('Source 2025'!$F:$F,'Source 2025'!$B:$B,$A17,'Source 2025'!$A:$A,"Quantity (units)")+SUMIFS('Source 2025'!$H:$H,'Source 2025'!$B:$B,$A17,'Source 2025'!$A:$A,"Quantity (units)")+SUMIFS('Source 2025'!$M:$M,'Source 2025'!$B:$B,$A17,'Source 2025'!$A:$A,"Quantity (units)")+SUMIFS('Source 2025'!$N:$N,'Source 2025'!$B:$B,$A17,'Source 2025'!$A:$A,"Quantity (units)")+SUMIFS('Source 2025'!$S:$S,'Source 2025'!$B:$B,$A17,'Source 2025'!$A:$A,"Quantity (units)")+SUMIFS('Source 2025'!$U:$U,'Source 2025'!$B:$B,$A17,'Source 2025'!$A:$A,"Quantity (units)")+SUMIFS('Source 2025'!$D:$D,'Source 2025'!$B:$B,$A17,'Source 2025'!$A:$A,"Quantity (units)")+SUMIFS('Source 2025'!$E:$E,'Source 2025'!$B:$B,$A17,'Source 2025'!$A:$A,"Quantity (units)")+SUMIFS('Source 2025'!$G:$G,'Source 2025'!$B:$B,$A17,'Source 2025'!$A:$A,"Quantity (units)") -> 539 | D17: =SUMIFS('Source 2026'!$F:$F,'Source 2026'!$B:$B,$A17,'Source 2026'!$A:$A,"Quantity (units)")+SUMIFS('Source 2026'!$H:$H,'Source 2026'!$B:$B,$A17,'Source 2026'!$A:$A,"Quantity (units)")+SUMIFS('Source 2026'!$M:$M,'Source 2026'!$B:$B,$A17,'Source 2026'!$A:$A,"Quantity (units)")+SUMIFS('Source 2026'!$N:$N,'Source 2026'!$B:$B,$A17,'Source 2026'!$A:$A,"Quantity (units)")+SUMIFS('Source 2026'!$S:$S,'Source 2026'!$B:$B,$A17,'Source 2026'!$A:$A,"Quantity (units)")+SUMIFS('Source 2026'!$U:$U,'Source 2026'!$B:$B,$A17,'Source 2026'!$A:$A,"Quantity (units)")+SUMIFS('Source 2026'!$D:$D,'Source 2026'!$B:$B,$A17,'Source 2026'!$A:$A,"Quantity (units)")+SUMIFS('Source 2026'!$E:$E,'Source 2026'!$B:$B,$A17,'Source 2026'!$A:$A,"Quantity (units)")+SUMIFS('Source 2026'!$G:$G,'Source 2026'!$B:$B,$A17,'Source 2026'!$A:$A,"Quantity (units)") -> 227 | E17: =D17*$J$5 -> 286.73684 | F17: =E17-C17 -> -252.26316 | G17: =IF(AND(C17=0,E17=0),0,IF(C17=0,"New",(E17-C17)/C17)) -> -0.4680207 | H17: =SUMIFS('Source 2025'!$F:$F,'Source 2025'!$B:$B,$A17,'Source 2025'!$A:$A,"Amount (NIS)")+SUMIFS('Source 2025'!$H:$H,'Source 2025'!$B:$B,$A17,'Source 2025'!$A:$A,"Amount (NIS)")+SUMIFS('Source 2025'!$M:$M,'Source 2025'!$B:$B,$A17,'Source 2025'!$A:$A,"Amount (NIS)")+SUMIFS('Source 2025'!$N:$N,'Source 2025'!$B:$B,$A17,'Source 2025'!$A:$A,"Amount (NIS)")+SUMIFS('Source 2025'!$S:$S,'Source 2025'!$B:$B,$A17,'Source 2025'!$A:$A,"Amount (NIS)")+SUMIFS('Source 2025'!$U:$U,'Source 2025'!$B:$B,$A17,'Source 2025'!$A:$A,"Amount (NIS)")+SUMIFS('Source 2025'!$D:$D,'Source 2025'!$B:$B,$A17,'Source 2025'!$A:$A,"Amount (NIS)")+SUMIFS('Source 2025'!$E:$E,'Source 2025'!$B:$B,$A17,'Source 2025'!$A:$A,"Amount (NIS)")+SUMIFS('Source 2025'!$G:$G,'Source 2025'!$B:$B,$A17,'Source 2025'!$A:$A,"Amount (NIS)") -> 26071.2 | I17: =SUMIFS('Source 2026'!$F:$F,'Source 2026'!$B:$B,$A17,'Source 2026'!$A:$A,"Amount (NIS)")+SUMIFS('Source 2026'!$H:$H,'Source 2026'!$B:$B,$A17,'Source 2026'!$A:$A,"Amount (NIS)")+SUMIFS('Source 2026'!$M:$M,'Source 2026'!$B:$B,$A17,'Source 2026'!$A:$A,"Amount (NIS)")+SUMIFS('Source 2026'!$N:$N,'Source 2026'!$B:$B,$A17,'Source 2026'!$A:$A,"Amount (NIS)")+SUMIFS('Source 2026'!$S:$S,'Source 2026'!$B:$B,$A17,'Source 2026'!$A:$A,"Amount (NIS)")+SUMIFS('Source 2026'!$U:$U,'Source 2026'!$B:$B,$A17,'Source 2026'!$A:$A,"Amount (NIS)")+SUMIFS('Source 2026'!$D:$D,'Source 2026'!$B:$B,$A17,'Source 2026'!$A:$A,"Amount (NIS)")+SUMIFS('Source 2026'!$E:$E,'Source 2026'!$B:$B,$A17,'Source 2026'!$A:$A,"Amount (NIS)")+SUMIFS('Source 2026'!$G:$G,'Source 2026'!$B:$B,$A17,'Source 2026'!$A:$A,"Amount (NIS)") -> 11000.8 | J17: =I17*$J$5 -> 13895.747 | K17: =J17-H17 -> -12175.453 | L17: =IF(AND(H17=0,J17=0),0,IF(H17=0,"New",(J17-H17)/H17)) -> -0.46700776
A18: 45C | B18: =IFERROR(INDEX('Source 2026'!$C:$C,MATCH($A18,'Source 2026'!$B:$B,0)),IFERROR(INDEX('Source 2025'!$C:$C,MATCH($A18,'Source 2025'!$B:$B,0)),"")) -> S מגן ברך חום | C18: =SUMIFS('Source 2025'!$F:$F,'Source 2025'!$B:$B,$A18,'Source 2025'!$A:$A,"Quantity (units)")+SUMIFS('Source 2025'!$H:$H,'Source 2025'!$B:$B,$A18,'Source 2025'!$A:$A,"Quantity (units)")+SUMIFS('Source 2025'!$M:$M,'Source 2025'!$B:$B,$A18,'Source 2025'!$A:$A,"Quantity (units)")+SUMIFS('Source 2025'!$N:$N,'Source 2025'!$B:$B,$A18,'Source 2025'!$A:$A,"Quantity (units)")+SUMIFS('Source 2025'!$S:$S,'Source 2025'!$B:$B,$A18,'Source 2025'!$A:$A,"Quantity (units)")+SUMIFS('Source 2025'!$U:$U,'Source 2025'!$B:$B,$A18,'Source 2025'!$A:$A,"Quantity (units)")+SUMIFS('Source 2025'!$D:$D,'Source 2025'!$B:$B,$A18,'Source 2025'!$A:$A,"Quantity (units)")+SUMIFS('Source 2025'!$E:$E,'Source 2025'!$B:$B,$A18,'Source 2025'!$A:$A,"Quantity (units)")+SUMIFS('Source 2025'!$G:$G,'Source 2025'!$B:$B,$A18,'Source 2025'!$A:$A,"Quantity (units)") -> 1325 | D18: =SUMIFS('Source 2026'!$F:$F,'Source 2026'!$B:$B,$A18,'Source 2026'!$A:$A,"Quantity (units)")+SUMIFS('Source 2026'!$H:$H,'Source 2026'!$B:$B,$A18,'Source 2026'!$A:$A,"Quantity (units)")+SUMIFS('Source 2026'!$M:$M,'Source 2026'!$B:$B,$A18,'Source 2026'!$A:$A,"Quantity (units)")+SUMIFS('Source 2026'!$N:$N,'Source 2026'!$B:$B,$A18,'Source 2026'!$A:$A,"Quantity (units)")+SUMIFS('Source 2026'!$S:$S,'Source 2026'!$B:$B,$A18,'Source 2026'!$A:$A,"Quantity (units)")+SUMIFS('Source 2026'!$U:$U,'Source 2026'!$B:$B,$A18,'Source 2026'!$A:$A,"Quantity (units)")+SUMIFS('Source 2026'!$D:$D,'Source 2026'!$B:$B,$A18,'Source 2026'!$A:$A,"Quantity (units)")+SUMIFS('Source 2026'!$E:$E,'Source 2026'!$B:$B,$A18,'Source 2026'!$A:$A,"Quantity (units)")+SUMIFS('Source 2026'!$G:$G,'Source 2026'!$B:$B,$A18,'Source 2026'!$A:$A,"Quantity (units)") -> 888 | E18: =D18*$J$5 -> 1121.6842 | F18: =E18-C18 -> -203.31579 | G18: =IF(AND(C18=0,E18=0),0,IF(C18=0,"New",(E18-C18)/C18)) -> -0.15344588 | H18: =SUMIFS('Source 2025'!$F:$F,'Source 2025'!$B:$B,$A18,'Source 2025'!$A:$A,"Amount (NIS)")+SUMIFS('Source 2025'!$H:$H,'Source 2025'!$B:$B,$A18,'Source 2025'!$A:$A,"Amount (NIS)")+SUMIFS('Source 2025'!$M:$M,'Source 2025'!$B:$B,$A18,'Source 2025'!$A:$A,"Amount (NIS)")+SUMIFS('Source 2025'!$N:$N,'Source 2025'!$B:$B,$A18,'Source 2025'!$A:$A,"Amount (NIS)")+SUMIFS('Source 2025'!$S:$S,'Source 2025'!$B:$B,$A18,'Source 2025'!$A:$A,"Amount (NIS)")+SUMIFS('Source 2025'!$U:$U,'Source 2025'!$B:$B,$A18,'Source 2025'!$A:$A,"Amount (NIS)")+SUMIFS('Source 2025'!$D:$D,'Source 2025'!$B:$B,$A18,'Source 2025'!$A:$A,"Amount (NIS)")+SUMIFS('Source 2025'!$E:$E,'Source 2025'!$B:$B,$A18,'Source 2025'!$A:$A,"Amount (NIS)")+SUMIFS('Source 2025'!$G:$G,'Source 2025'!$B:$B,$A18,'Source 2025'!$A:$A,"Amount (NIS)") -> 39752.6 | I18: =SUMIFS('Source 2026'!$F:$F,'Source 2026'!$B:$B,$A18,'Source 2026'!$A:$A,"Amount (NIS)")+SUMIFS('Source 2026'!$H:$H,'Source 2026'!$B:$B,$A18,'Source 2026'!$A:$A,"Amount (NIS)")+SUMIFS('Source 2026'!$M:$M,'Source 2026'!$B:$B,$A18,'Source 2026'!$A:$A,"Amount (NIS)")+SUMIFS('Source 2026'!$N:$N,'Source 2026'!$B:$B,$A18,'Source 2026'!$A:$A,"Amount (NIS)")+SUMIFS('Source 2026'!$S:$S,'Source 2026'!$B:$B,$A18,'Source 2026'!$A:$A,"Amount (NIS)")+SUMIFS('Source 2026'!$U:$U,'Source 2026'!$B:$B,$A18,'Source 2026'!$A:$A,"Amount (NIS)")+SUMIFS('Source 2026'!$D:$D,'Source 2026'!$B:$B,$A18,'Source 2026'!$A:$A,"Amount (NIS)")+SUMIFS('Source 2026'!$E:$E,'Source 2026'!$B:$B,$A18,'Source 2026'!$A:$A,"Amount (NIS)")+SUMIFS('Source 2026'!$G:$G,'Source 2026'!$B:$B,$A18,'Source 2026'!$A:$A,"Amount (NIS)") -> 26812.5 | J18: =I18*$J$5 -> 33868.421 | K18: =J18-H18 -> -5884.1789 | L18: =IF(AND(H18=0,J18=0),0,IF(H18=0,"New",(J18-H18)/H18)) -> -0.14801998
A19: 266 | B19: =IFERROR(INDEX('Source 2026'!$C:$C,MATCH($A19,'Source 2026'!$B:$B,0)),IFERROR(INDEX('Source 2025'!$C:$C,MATCH($A19,'Source 2025'!$B:$B,0)),"")) -> סד ליד דו צדדי | C19: =SUMIFS('Source 2025'!$F:$F,'Source 2025'!$B:$B,$A19,'Source 2025'!$A:$A,"Quantity (units)")+SUMIFS('Source 2025'!$H:$H,'Source 2025'!$B:$B,$A19,'Source 2025'!$A:$A,"Quantity (units)")+SUMIFS('Source 2025'!$M:$M,'Source 2025'!$B:$B,$A19,'Source 2025'!$A:$A,"Quantity (units)")+SUMIFS('Source 2025'!$N:$N,'Source 2025'!$B:$B,$A19,'Source 2025'!$A:$A,"Quantity (units)")+SUMIFS('Source 2025'!$S:$S,'Source 2025'!$B:$B,$A19,'Source 2025'!$A:$A,"Quantity (units)")+SUMIFS('Source 2025'!$U:$U,'Source 2025'!$B:$B,$A19,'Source 2025'!$A:$A,"Quantity (units)")+SUMIFS('Source 2025'!$D:$D,'Source 2025'!$B:$B,$A19,'Source 2025'!$A:$A,"Quantity (units)")+SUMIFS('Source 2025'!$E:$E,'Source 2025'!$B:$B,$A19,'Source 2025'!$A:$A,"Quantity (units)")+SUMIFS('Source 2025'!$G:$G,'Source 2025'!$B:$B,$A19,'Source 2025'!$A:$A,"Quantity (units)") -> 502 | D19: =SUMIFS('Source 2026'!$F:$F,'Source 2026'!$B:$B,$A19,'Source 2026'!$A:$A,"Quantity (units)")+SUMIFS('Source 2026'!$H:$H,'Source 2026'!$B:$B,$A19,'Source 2026'!$A:$A,"Quantity (units)")+SUMIFS('Source 2026'!$M:$M,'Source 2026'!$B:$B,$A19,'Source 2026'!$A:$A,"Quantity (units)")+SUMIFS('Source 2026'!$N:$N,'Source 2026'!$B:$B,$A19,'Source 2026'!$A:$A,"Quantity (units)")+SUMIFS('Source 2026'!$S:$S,'Source 2026'!$B:$B,$A19,'Source 2026'!$A:$A,"Quantity (units)")+SUMIFS('Source 2026'!$U:$U,'Source 2026'!$B:$B,$A19,'Source 2026'!$A:$A,"Quantity (units)")+SUMIFS('Source 2026'!$D:$D,'Source 2026'!$B:$B,$A19,'Source 2026'!$A:$A,"Quantity (units)")+SUMIFS('Source 2026'!$E:$E,'Source 2026'!$B:$B,$A19,'Source 2026'!$A:$A,"Quantity (units)")+SUMIFS('Source 2026'!$G:$G,'Source 2026'!$B:$B,$A19,'Source 2026'!$A:$A,"Quantity (units)") -> 336 | E19: =D19*$J$5 -> 424.42105 | F19: =E19-C19 -> -77.578947 | G19: =IF(AND(C19=0,E19=0),0,IF(C19=0,"New",(E19-C19)/C19)) -> -0.15453974 | H19: =SUMIFS('Source 2025'!$F:$F,'Source 2025'!$B:$B,$A19,'Source 2025'!$A:$A,"Amount (NIS)")+SUMIFS('Source 2025'!$H:$H,'Source 2025'!$B:$B,$A19,'Source 2025'!$A:$A,"Amount (NIS)")+SUMIFS('Source 2025'!$M:$M,'Source 2025'!$B:$B,$A19,'Source 2025'!$A:$A,"Amount (NIS)")+SUMIFS('Source 2025'!$N:$N,'Source 2025'!$B:$B,$A19,'Source 2025'!$A:$A,"Amount (NIS)")+SUMIFS('Source 2025'!$S:$S,'Source 2025'!$B:$B,$A19,'Source 2025'!$A:$A,"Amount (NIS)")+SUMIFS('Source 2025'!$U:$U,'Source 2025'!$B:$B,$A19,'Source 2025'!$A:$A,"Amount (NIS)")+SUMIFS('Source 2025'!$D:$D,'Source 2025'!$B:$B,$A19,'Source 2025'!$A:$A,"Amount (NIS)")+SUMIFS('Source 2025'!$E:$E,'Source 2025'!$B:$B,$A19,'Source 2025'!$A:$A,"Amount (NIS)")+SUMIFS('Source 2025'!$G:$G,'Source 2025'!$B:$B,$A19,'Source 2025'!$A:$A,"Amount (NIS)") -> 38890.7 | I19: =SUMIFS('Source 2026'!$F:$F,'Source 2026'!$B:$B,$A19,'Source 2026'!$A:$A,"Amount (NIS)")+SUMIFS('Source 2026'!$H:$H,'Source 2026'!$B:$B,$A19,'Source 2026'!$A:$A,"Amount (NIS)")+SUMIFS('Source 2026'!$M:$M,'Source 2026'!$B:$B,$A19,'Source 2026'!$A:$A,"Amount (NIS)")+SUMIFS('Source 2026'!$N:$N,'Source 2026'!$B:$B,$A19,'Source 2026'!$A:$A,"Amount (NIS)")+SUMIFS('Source 2026'!$S:$S,'Source 2026'!$B:$B,$A19,'Source 2026'!$A:$A,"Amount (NIS)")+SUMIFS('Source 2026'!$U:$U,'Source 2026'!$B:$B,$A19,'Source 2026'!$A:$A,"Amount (NIS)")+SUMIFS('Source 2026'!$D:$D,'Source 2026'!$B:$B,$A19,'Source 2026'!$A:$A,"Amount (NIS)")+SUMIFS('Source 2026'!$E:$E,'Source 2026'!$B:$B,$A19,'Source 2026'!$A:$A,"Amount (NIS)")+SUMIFS('Source 2026'!$G:$G,'Source 2026'!$B:$B,$A19,'Source 2026'!$A:$A,"Amount (NIS)") -> 26201.4 | J19: =I19*$J$5 -> 33096.505 | K19: =J19-H19 -> -5794.1947 | L19: =IF(AND(H19=0,J19=0),0,IF(H19=0,"New",(J19-H19)/H19)) -> -0.14898664
A20: 28 | B20: =IFERROR(INDEX('Source 2026'!$C:$C,MATCH($A20,'Source 2026'!$B:$B,0)),IFERROR(INDEX('Source 2025'!$C:$C,MATCH($A20,'Source 2025'!$B:$B,0)),"")) -> L סד לאגודל לאחר שבר | C20: =SUMIFS('Source 2025'!$F:$F,'Source 2025'!$B:$B,$A20,'Source 2025'!$A:$A,"Quantity (units)")+SUMIFS('Source 2025'!$H:$H,'Source 2025'!$B:$B,$A20,'Source 2025'!$A:$A,"Quantity (units)")+SUMIFS('Source 2025'!$M:$M,'Source 2025'!$B:$B,$A20,'Source 2025'!$A:$A,"Quantity (units)")+SUMIFS('Source 2025'!$N:$N,'Source 2025'!$B:$B,$A20,'Source 2025'!$A:$A,"Quantity (units)")+SUMIFS('Source 2025'!$S:$S,'Source 2025'!$B:$B,$A20,'Source 2025'!$A:$A,"Quantity (units)")+SUMIFS('Source 2025'!$U:$U,'Source 2025'!$B:$B,$A20,'Source 2025'!$A:$A,"Quantity (units)")+SUMIFS('Source 2025'!$D:$D,'Source 2025'!$B:$B,$A20,'Source 2025'!$A:$A,"Quantity (units)")+SUMIFS('Source 2025'!$E:$E,'Source 2025'!$B:$B,$A20,'Source 2025'!$A:$A,"Quantity (units)")+SUMIFS('Source 2025'!$G:$G,'Source 2025'!$B:$B,$A20,'Source 2025'!$A:$A,"Quantity (units)") -> 237 | D20: =SUMIFS('Source 2026'!$F:$F,'Source 2026'!$B:$B,$A20,'Source 2026'!$A:$A,"Quantity (units)")+SUMIFS('Source 2026'!$H:$H,'Source 2026'!$B:$B,$A20,'Source 2026'!$A:$A,"Quantity (units)")+SUMIFS('Source 2026'!$M:$M,'Source 2026'!$B:$B,$A20,'Source 2026'!$A:$A,"Quantity (units)")+SUMIFS('Source 2026'!$N:$N,'Source 2026'!$B:$B,$A20,'Source 2026'!$A:$A,"Quantity (units)")+SUMIFS('Source 2026'!$S:$S,'Source 2026'!$B:$B,$A20,'Source 2026'!$A:$A,"Quantity (units)")+SUMIFS('Source 2026'!$U:$U,'Source 2026'!$B:$B,$A20,'Source 2026'!$A:$A,"Quantity (units)")+SUMIFS('Source 2026'!$D:$D,'Source 2026'!$B:$B,$A20,'Source 2026'!$A:$A,"Quantity (units)")+SUMIFS('Source 2026'!$E:$E,'Source 2026'!$B:$B,$A20,'Source 2026'!$A:$A,"Quantity (units)")+SUMIFS('Source 2026'!$G:$G,'Source 2026'!$B:$B,$A20,'Source 2026'!$A:$A,"Quantity (units)") -> 109 | E20: =D20*$J$5 -> 137.68421 | F20: =E20-C20 -> -99.315789 | G20: =IF(AND(C20=0,E20=0),0,IF(C20=0,"New",(E20-C20)/C20)) -> -0.41905396 | H20: =SUMIFS('Source 2025'!$F:$F,'Source 2025'!$B:$B,$A20,'Source 2025'!$A:$A,"Amount (NIS)")+SUMIFS('Source 2025'!$H:$H,'Source 2025'!$B:$B,$A20,'Source 2025'!$A:$A,"Amount (NIS)")+SUMIFS('Source 2025'!$M:$M,'Source 2025'!$B:$B,$A20,'Source 2025'!$A:$A,"Amount (NIS)")+SUMIFS('Source 2025'!$N:$N,'Source 2025'!$B:$B,$A20,'Source 2025'!$A:$A,"Amount (NIS)")+SUMIFS('Source 2025'!$S:$S,'Source 2025'!$B:$B,$A20,'Source 2025'!$A:$A,"Amount (NIS)")+SUMIFS('Source 2025'!$U:$U,'Source 2025'!$B:$B,$A20,'Source 2025'!$A:$A,"Amount (NIS)")+SUMIFS('Source 2025'!$D:$D,'Source 2025'!$B:$B,$A20,'Source 2025'!$A:$A,"Amount (NIS)")+SUMIFS('Source 2025'!$E:$E,'Source 2025'!$B:$B,$A20,'Source 2025'!$A:$A,"Amount (NIS)")+SUMIFS('Source 2025'!$G:$G,'Source 2025'!$B:$B,$A20,'Source 2025'!$A:$A,"Amount (NIS)") -> 23347.4 | I20: =SUMIFS('Source 2026'!$F:$F,'Source 2026'!$B:$B,$A20,'Source 2026'!$A:$A,"Amount (NIS)")+SUMIFS('Source 2026'!$H:$H,'Source 2026'!$B:$B,$A20,'Source 2026'!$A:$A,"Amount (NIS)")+SUMIFS('Source 2026'!$M:$M,'Source 2026'!$B:$B,$A20,'Source 2026'!$A:$A,"Amount (NIS)")+SUMIFS('Source 2026'!$N:$N,'Source 2026'!$B:$B,$A20,'Source 2026'!$A:$A,"Amount (NIS)")+SUMIFS('Source 2026'!$S:$S,'Source 2026'!$B:$B,$A20,'Source 2026'!$A:$A,"Amount (NIS)")+SUMIFS('Source 2026'!$U:$U,'Source 2026'!$B:$B,$A20,'Source 2026'!$A:$A,"Amount (NIS)")+SUMIFS('Source 2026'!$D:$D,'Source 2026'!$B:$B,$A20,'Source 2026'!$A:$A,"Amount (NIS)")+SUMIFS('Source 2026'!$E:$E,'Source 2026'!$B:$B,$A20,'Source 2026'!$A:$A,"Amount (NIS)")+SUMIFS('Source 2026'!$G:$G,'Source 2026'!$B:$B,$A20,'Source 2026'!$A:$A,"Amount (NIS)") -> 10734.8 | J20: =I20*$J$5 -> 13559.747 | K20: =J20-H20 -> -9787.6526 | L20: =IF(AND(H20=0,J20=0),0,IF(H20=0,"New",(J20-H20)/H20)) -> -0.4192181
... A291: 63 | B291: =IFERROR(INDEX('Source 2026'!$C:$C,MATCH($A291,'Source 2026'!$B:$B,0)),IFERROR(INDEX('Source 2025'!$C:$C,MATCH($A291,'Source 2025'!$B:$B,0)),"")) -> M צוארון פלסטי מתכוון | C291: =SUMIFS('Source 2025'!$F:$F,'Source 2025'!$B:$B,$A291,'Source 2025'!$A:$A,"Quantity (units)")+SUMIFS('Source 2025'!$H:$H,'Source 2025'!$B:$B,$A291,'Source 2025'!$A:$A,"Quantity (units)")+SUMIFS('Source 2025'!$M:$M,'Source 2025'!$B:$B,$A291,'Source 2025'!$A:$A,"Quantity (units)")+SUMIFS('Source 2025'!$N:$N,'Source 2025'!$B:$B,$A291,'Source 2025'!$A:$A,"Quantity (units)")+SUMIFS('Source 2025'!$S:$S,'Source 2025'!$B:$B,$A291,'Source 2025'!$A:$A,"Quantity (units)")+SUMIFS('Source 2025'!$U:$U,'Source 2025'!$B:$B,$A291,'Source 2025'!$A:$A,"Quantity (units)")+SUMIFS('Source 2025'!$D:$D,'Source 2025'!$B:$B,$A291,'Source 2025'!$A:$A,"Quantity (units)")+SUMIFS('Source 2025'!$E:$E,'Source 2025'!$B:$B,$A291,'Source 2025'!$A:$A,"Quantity (units)")+SUMIFS('Source 2025'!$G:$G,'Source 2025'!$B:$B,$A291,'Source 2025'!$A:$A,"Quantity (units)") -> 1 | D291: =SUMIFS('Source 2026'!$F:$F,'Source 2026'!$B:$B,$A291,'Source 2026'!$A:$A,"Quantity (units)")+SUMIFS('Source 2026'!$H:$H,'Source 2026'!$B:$B,$A291,'Source 2026'!$A:$A,"Quantity (units)")+SUMIFS('Source 2026'!$M:$M,'Source 2026'!$B:$B,$A291,'Source 2026'!$A:$A,"Quantity (units)")+SUMIFS('Source 2026'!$N:$N,'Source 2026'!$B:$B,$A291,'Source 2026'!$A:$A,"Quantity (units)")+SUMIFS('Source 2026'!$S:$S,'Source 2026'!$B:$B,$A291,'Source 2026'!$A:$A,"Quantity (units)")+SUMIFS('Source 2026'!$U:$U,'Source 2026'!$B:$B,$A291,'Source 2026'!$A:$A,"Quantity (units)")+SUMIFS('Source 2026'!$D:$D,'Source 2026'!$B:$B,$A291,'Source 2026'!$A:$A,"Quantity (units)")+SUMIFS('Source 2026'!$E:$E,'Source 2026'!$B:$B,$A291,'Source 2026'!$A:$A,"Quantity (units)")+SUMIFS('Source 2026'!$G:$G,'Source 2026'!$B:$B,$A291,'Source 2026'!$A:$A,"Quantity (units)") -> 1 | E291: =D291*$J$5 -> 1.2631579 | F291: =E291-C291 -> 0.26315789 | G291: =IF(AND(C291=0,E291=0),0,IF(C291=0,"New",(E291-C291)/C291)) -> 0.26315789 | H291: =SUMIFS('Source 2025'!$F:$F,'Source 2025'!$B:$B,$A291,'Source 2025'!$A:$A,"Amount (NIS)")+SUMIFS('Source 2025'!$H:$H,'Source 2025'!$B:$B,$A291,'Source 2025'!$A:$A,"Amount (NIS)")+SUMIFS('Source 2025'!$M:$M,'Source 2025'!$B:$B,$A291,'Source 2025'!$A:$A,"Amount (NIS)")+SUMIFS('Source 2025'!$N:$N,'Source 2025'!$B:$B,$A291,'Source 2025'!$A:$A,"Amount (NIS)")+SUMIFS('Source 2025'!$S:$S,'Source 2025'!$B:$B,$A291,'Source 2025'!$A:$A,"Amount (NIS)")+SUMIFS('Source 2025'!$U:$U,'Source 2025'!$B:$B,$A291,'Source 2025'!$A:$A,"Amount (NIS)")+SUMIFS('Source 2025'!$D:$D,'Source 2025'!$B:$B,$A291,'Source 2025'!$A:$A,"Amount (NIS)")+SUMIFS('Source 2025'!$E:$E,'Source 2025'!$B:$B,$A291,'Source 2025'!$A:$A,"Amount (NIS)")+SUMIFS('Source 2025'!$G:$G,'Source 2025'!$B:$B,$A291,'Source 2025'!$A:$A,"Amount (NIS)") -> 66.5 | I291: =SUMIFS('Source 2026'!$F:$F,'Source 2026'!$B:$B,$A291,'Source 2026'!$A:$A,"Amount (NIS)")+SUMIFS('Source 2026'!$H:$H,'Source 2026'!$B:$B,$A291,'Source 2026'!$A:$A,"Amount (NIS)")+SUMIFS('Source 2026'!$M:$M,'Source 2026'!$B:$B,$A291,'Source 2026'!$A:$A,"Amount (NIS)")+SUMIFS('Source 2026'!$N:$N,'Source 2026'!$B:$B,$A291,'Source 2026'!$A:$A,"Amount (NIS)")+SUMIFS('Source 2026'!$S:$S,'Source 2026'!$B:$B,$A291,'Source 2026'!$A:$A,"Amount (NIS)")+SUMIFS('Source 2026'!$U:$U,'Source 2026'!$B:$B,$A291,'Source 2026'!$A:$A,"Amount (NIS)")+SUMIFS('Source 2026'!$D:$D,'Source 2026'!$B:$B,$A291,'Source 2026'!$A:$A,"Amount (NIS)")+SUMIFS('Source 2026'!$E:$E,'Source 2026'!$B:$B,$A291,'Source 2026'!$A:$A,"Amount (NIS)")+SUMIFS('Source 2026'!$G:$G,'Source 2026'!$B:$B,$A291,'Source 2026'!$A:$A,"Amount (NIS)") -> 66.5 | J291: =I291*$J$5 -> 84 | K291: =J291-H291 -> 17.5 | L291: =IF(AND(H291=0,J291=0),0,IF(H291=0,"New",(J291-H291)/H291)) -> 0.26315789
B293: TOTAL | C293: =SUM(C9:C291) -> 54177 | D293: =SUM(D9:D291) -> 33487 | E293: =SUM(E9:E291) -> 42299.368 | F293: =SUM(F9:F291) -> -11877.632 | G293: =IF(C293=0,"N/A",F293/C293) -> -0.21923753 | H293: =SUM(H9:H291) -> 1967633.7 | I293: =SUM(I9:I291) -> 1293807.8 | J293: =SUM(J9:J291) -> 1634283.5 | K293: =SUM(K9:K291) -> -333350.16 | L293: =IF(H293=0,"N/A",K293/H293) -> -0.16941678

Sheet BE
A1: Sales Comparison 2025 vs 2026 (Annualized) - Group: BE (by Product CODE)
A2: Calculation date: | B2: 46284
A3: Source: PPlay1 of uriel (Reporter) product x customer pivot reports for 2025 and 2026. Grouping follows the daily report "Pplay1" sheet legend (customer # 4/7/1/8) plus 5 categories confirmed by the user on 19/09/2026 that had no exact-name match in the legend. Group "BE" = sum of raw customer column(s): אילת BE, הפרכל הפרפארם, שופרסל BE, זיכויים BE, BE, אילת זיכויי BE (column(s) K, O, R, P, J, L in 'Source 2025'/'Source 2026'). Each file has two data blocks: "נטו" (Net Amount, NIS) and "סהכ יחידות" (Total Units). Product CODE parsed as the first token of column B in the original file; size/color variants sharing the same base CODE are summed via SUMIFS. Rows below only include product codes with non-zero quantity or amount for this group in at least one of the two years (comparing 2025 actual to 2026 actual, before annualization). Full build (annualization + DROP/NEW + whole-number display) rolled out to all 5 groups on 19/09/2026 - see rows 4-6 for methodology.
