Workbook

Sheet Index
A1: Sales Comparison 2025 vs 2026 - by Daily-Report Group, WITH MACCABI (new PPLAY1 export, group # from source row 7)
A2: Calculation date: | B2: 46289
A3: Same methodology/column layout as 2026-09-19-grouped-2025-vs-2026.xlsx!Index (that file was NOT modified) - this is a NEW, separate workbook built from a new PPLAY1 source ("חנה_1", uploaded 24/09/2026) that already combines 2025+2026 with an explicit group # per column. Adds a 5th group, "מכבי" (#20), which did not exist before. Per the user’s decision (24/09/2026), "0פארמים" (standalone group in the 19/09 workbook) is intentionally NOT included here, since the new source file does not contain it. Annualization factor here uses 8.75 months (1/1-23/9, per this source’s own snapshot date), NOT the 9.5 used in the other workbooks - see each group sheet’s row 4 note.
A5: Group | B5: Sheet | C5: # Raw categories | D5: # Codes | E5: # Codes 25 | F5: # Codes 26 | G5: # DROP | H5: # NEW | I5: Total Units Drop 25 | J5: Total Amount Drop 25 | K5: NEW — Quantity 2026 | L5: NEW — Amount 2026 (₪) | M5: NEW — Quantity 2026 Annualized | N5: NEW — Amount 2026 Annualized (₪) | O5: Quantity 2025 | P5: Quantity 2026 (Actual) | Q5: Quantity 2026 Annualized | R5: Qty Change % (vs Annualized) | S5: Amount 2025 (₪) | T5: Amount 2026 (Actual) (₪) | U5: Amount 2026 (Annualized) (₪) | V5: Amount Change % (vs Annualized)
A6: בתי מרקחת | B6: בתי מרקחת | C6: 6 | D6: =COUNTA('בתי מרקחת'!$A$9:$A$593) -> 585 | E6: =SUMPRODUCT(--(('בתי מרקחת'!$C$9:$C$593<>0)+('בתי מרקחת'!$H$9:$H$593<>0)>0)) -> 532 | F6: =SUMPRODUCT(--(('בתי מרקחת'!$D$9:$D$593<>0)+('בתי מרקחת'!$I$9:$I$593<>0)>0)) -> 481 | G6: ='בתי מרקחת'!B5 -> 104 | H6: ='בתי מרקחת'!D5 -> 53 | I6: ='בתי מרקחת'!B6 -> 253 | J6: ='בתי מרקחת'!D6 -> 21183.1 | K6: ='בתי מרקחת'!F6 -> 589 | L6: ='בתי מרקחת'!H6 -> 39128 | M6: ='בתי מרקחת'!J6 -> 807.77143 | N6: ='בתי מרקחת'!L6 -> 53661.257 | O6: ='בתי מרקחת'!C595 -> 54177 | P6: ='בתי מרקחת'!D595 -> 33485 | Q6: ='בתי מרקחת'!E595 -> 45922.286 | R6: =IF('בתי מרקחת'!C595=0,"N/A",('בתי מרקחת'!E595-'בתי מרקחת'!C595)/'בתי מרקחת'!C595) -> -0.15236566 | S6: ='בתי מרקחת'!H595 -> 1967633.7 | T6: ='בתי מרקחת'!I595 -> 1293687.8 | U6: ='בתי מרקחת'!J595 -> 1774200.4 | V6: =IF('בתי מרקחת'!H595=0,"N/A",('בתי מרקחת'!J595-'בתי מרקחת'!H595)/'בתי מרקחת'!H595) -> -0.09830757
A7: BE | B7: BE | C7: 1 | D7: =COUNTA('BE'!$A$9:$A$354) -> 346 | E7: =SUMPRODUCT(--(('BE'!$C$9:$C$354<>0)+('BE'!$H$9:$H$354<>0)>0)) -> 328 | F7: =SUMPRODUCT(--(('BE'!$D$9:$D$354<>0)+('BE'!$I$9:$I$354<>0)>0)) -> 282 | G7: ='BE'!B5 -> 64 | H7: ='BE'!D5 -> 18 | I7: ='BE'!B6 -> 55 | J7: ='BE'!D6 -> 4567.1 | K7: ='BE'!F6 -> 11 | L7: ='BE'!H6 -> 1501.2 | M7: ='BE'!J6 -> 15.085714 | N7: ='BE'!L6 -> 2058.7886 | O7: ='BE'!C356 -> 27268 | P7: ='BE'!D356 -> 19109 | Q7: ='BE'!E356 -> 26206.629 | R7: =IF('BE'!C356=0,"N/A",('BE'!E356-'BE'!C356)/'BE'!C356) -> -0.038923699 | S7: ='BE'!H356 -> 889501.5 | T7: ='BE'!I356 -> 676264.2 | U7: ='BE'!J356 -> 927448.05 | V7: =IF('BE'!H356=0,"N/A",('BE'!J356-'BE'!H356)/'BE'!H356) -> 0.042660463
A8: סופר פארם | B8: סופר פארם | C8: 1 | D8: =COUNTA('סופר פארם'!$A$9:$A$444) -> 436 | E8: =SUMPRODUCT(--(('סופר פארם'!$C$9:$C$444<>0)+('סופר פארם'!$H$9:$H$444<>0)>0)) -> 384 | F8: =SUMPRODUCT(--(('סופר פארם'!$D$9:$D$444<>0)+('סופר פארם'!$I$9:$I$444<>0)>0)) -> 382 | G8: ='סופר פארם'!B5 -> 54 | H8: ='סופר פארם'!D5 -> 52 | I8: ='סופר פארם'!B6 -> 23 | J8: ='סופר פארם'!D6 -> -2700.3 | K8: ='סופר פארם'!F6 -> 1975 | L8: ='סופר פארם'!H6 -> 149982 | M8: ='סופר פארם'!J6 -> 2708.5714 | N8: ='סופר פארם'!L6 -> 205689.6 | O8: ='סופר פארם'!C446 -> 176505 | P8: ='סופר פארם'!D446 -> 119036 | Q8: ='סופר פארם'!E446 -> 163249.37 | R8: =IF('סופר פארם'!C446=0,"N/A",('סופר פארם'!E446-'סופר פארם'!C446)/'סופר פארם'!C446) -> -0.075100584 | S8: ='סופר פארם'!H446 -> 6689220.5 | T8: ='סופר פארם'!I446 -> 4507341 | U8: ='סופר פארם'!J446 -> 6181496.2 | V8: =IF('סופר פארם'!H446=0,"N/A",('סופר פארם'!J446-'סופר פארם'!H446)/'סופר פארם'!H446) -> -0.075901859
A9: מאוחדת | B9: מאוחדת | C9: 1 | D9: =COUNTA('מאוחדת'!$A$9:$A$198) -> 190 | E9: =SUMPRODUCT(--(('מאוחדת'!$C$9:$C$198<>0)+('מאוחדת'!$H$9:$H$198<>0)>0)) -> 0 | F9: =SUMPRODUCT(--(('מאוחדת'!$D$9:$D$198<>0)+('מאוחדת'!$I$9:$I$198<>0)>0)) -> 190 | G9: ='מאוחדת'!B5 -> 0 | H9: ='מאוחדת'!D5 -> 190 | I9: ='מאוחדת'!B6 -> 0 | J9: ='מאוחדת'!D6 -> 0 | K9: ='מאוחדת'!F6 -> 10034 | L9: ='מאוחדת'!H6 -> 306848.4 | M9: ='מאוחדת'!J6 -> 13760.914 | N9: ='מאוחדת'!L6 -> 420820.66 | O9: ='מאוחדת'!C200 -> 0 | P9: ='מאוחדת'!D200 -> 10034 | Q9: ='מאוחדת'!E200 -> 13760.914 | R9: =IF('מאוחדת'!C200=0,"N/A",('מאוחדת'!E200-'מאוחדת'!C200)/'מאוחדת'!C200) -> N/A | S9: ='מאוחדת'!H200 -> 0 | T9: ='מאוחדת'!I200 -> 306848.4 | U9: ='מאוחדת'!J200 -> 420820.66 | V9: =IF('מאוחדת'!H200=0,"N/A",('מאוחדת'!J200-'מאוחדת'!H200)/'מאוחדת'!H200) -> N/A
A10: מכבי | B10: מכבי | C10: 1 | D10: =COUNTA('מכבי'!$A$9:$A$11) -> 3 | E10: =SUMPRODUCT(--(('מכבי'!$C$9:$C$11<>0)+('מכבי'!$H$9:$H$11<>0)>0)) -> 0 | F10: =SUMPRODUCT(--(('מכבי'!$D$9:$D$11<>0)+('מכבי'!$I$9:$I$11<>0)>0)) -> 3 | G10: ='מכבי'!B5 -> 0 | H10: ='מכבי'!D5 -> 3 | I10: ='מכבי'!B6 -> 0 | J10: ='מכבי'!D6 -> 0 | K10: ='מכבי'!F6 -> 3 | L10: ='מכבי'!H6 -> 666 | M10: ='מכבי'!J6 -> 4.1142857 | N10: ='מכבי'!L6 -> 913.37143 | O10: ='מכבי'!C13 -> 0 | P10: ='מכבי'!D13 -> 3 | Q10: ='מכבי'!E13 -> 4.1142857 | R10: =IF('מכבי'!C13=0,"N/A",('מכבי'!E13-'מכבי'!C13)/'מכבי'!C13) -> N/A | S10: ='מכבי'!H13 -> 0 | T10: ='מכבי'!I13 -> 666 | U10: ='מכבי'!J13 -> 913.37143 | V10: =IF('מכבי'!H13=0,"N/A",('מכבי'!J13-'מכבי'!H13)/'מכבי'!H13) -> N/A

Sheet Group Mapping
A1: Category -> Group mapping, sourced directly from row 7 (group #) of the new PPLAY1 export "חנה_1" (24/09/2026)
A2: Raw category (source column) | B2: Group # | C2: Group name | D2: Source of mapping | E2: Note
A3: 0בתי מרקחת | B3: 4 | C3: בתי מרקחת | D3: Row 7 of source file "חנה_1"
A4: גוד פארם | B4: 4 | C4: בתי מרקחת | D4: Row 7 of source file "חנה_1"
A5: גוד פארם מרכז | B5: 4 | C5: בתי מרקחת | D5: Row 7 of source file "חנה_1"
A6: 0מפיצי משנה | B6: 4 | C6: בתי מרקחת | D6: Row 7 of source file "חנה_1"
A7: 0צרכנים פרטיים | B7: 4 | C7: בתי מרקחת | D7: Row 7 of source file "חנה_1"
A8: 0שונות | B8: 4 | C8: בתי מרקחת | D8: Row 7 of source file "חנה_1"
A9: BE | B9: 7 | C9: BE | D9: Row 7 of source file "חנה_1" | E9: This single "BE" column already equals the full old group-7 total (verified against the old raw-customer breakdown: 27,268 units / ₪889,730 in 2025, matching the sum of the 5 old BE sub-customers) - the new export pre-aggregates it, no separate sub-customer columns provided.
A10: סופרפארם | B10: 1 | C10: סופר פארם | D10: Row 7 of source file "חנה_1"
A11: ק.חולים מאוחדת | B11: 8 | C11: מאוחדת | D11: Row 7 of source file "חנה_1"
A12: ק.חולים מכבי | B12: 20 | C12: מכבי | D12: Row 7 of source file "חנה_1" | E12: NEW group (#20) - not present in 2026-09-19-grouped-2025-vs-2026.xlsx. Added per user upload 24/09/2026.
A14: Note: "0פארמים" (standalone group in the 19/09 workbook) is deliberately NOT included here - the new source file does not contain it, and the user decided (24/09/2026) to leave it out rather than pull it from the old raw files.

Sheet בתי מרקחת
A1: Sales Comparison 2025 vs 2026 (Annualized) - Group: בתי מרקחת (by Product CODE) [with Maccabi, 24/09/2026]
A2: Calculation date: | B2: 46289
A3: Source: new PPLAY1 export "חנה_1" (uploaded 24/09/2026, internal snapshot timestamp 23/09/2026 17:01), which combines 2025 and 2026 in one sheet with an explicit group # per customer column (row 7) - used directly instead of the 2025.xls/2026.xls + manual mapping used for the 19/09 workbook. Group "בתי מרקחת" (#4) = sum of raw customer column(s): 0בתי מרקחת, גוד פארם, גוד פארם מרכז, 0מפיצי משנה, 0צרכנים פרטיים, 0שונות (column(s) D, E, F, G, J, M in 'Source 2025'/'Source 2026'). Product CODE = column A ("מקט") in the source, already clean (no parsing needed, unlike the old combined code+name format). Rows below only include product codes with non-zero quantity or amount for this group in at least one of the two years. This is a NEW, SEPARATE workbook - 2026-09-19-grouped-2025-vs-2026.xlsx was NOT modified.
A4: Annualization note: 2026 actual data covers approximately 8.75 months (1 Jan - 23 Sep 2026, per this source file’s own snapshot date - DIFFERENT from the 9.5 months / 15 Sep used in the other workbooks, which were built from an earlier snapshot). Scaled to a full year via factor = 12 / 8.75 (≈ 1.371429) - straight-line extrapolation, no seasonality adjustment. | I4: Months in full year: | J4: 12 | K4: Months covered by 2026 actual (1/1–23/9): | L4: 8.75
A5: # DROP (sold 2025, 0 in 2026): | B5: =SUMPRODUCT(--((($C$9:$C$593<>0)+($H$9:$H$593<>0)>0)*(($D$9:$D$593=0)*($I$9:$I$593=0)))) -> 104 | C5: # NEW (sold 2026, 0 in 2025): | D5: =SUMPRODUCT(--((($D$9:$D$593<>0)+($I$9:$I$593<>0)>0)*(($C$9:$C$593=0)*($H$9:$H$593=0)))) -> 53 | I5: Normalization factor (J4/L4): | J5: =J4/L4 -> 1.3714286
A6: DROP — Quantity 2025: | B6: =SUMPRODUCT(--((($C$9:$C$593<>0)+($H$9:$H$593<>0)>0)*(($D$9:$D$593=0)*($I$9:$I$593=0)))*$C$9:$C$593) -> 253 | C6: DROP — Amount 2025 (₪): | D6: =SUMPRODUCT(--((($C$9:$C$593<>0)+($H$9:$H$593<>0)>0)*(($D$9:$D$593=0)*($I$9:$I$593=0)))*$H$9:$H$593) -> 21183.1 | E6: NEW — Quantity 2026: | F6: =SUMPRODUCT(--((($D$9:$D$593<>0)+($I$9:$I$593<>0)>0)*(($C$9:$C$593=0)*($H$9:$H$593=0)))*$D$9:$D$593) -> 589 | G6: NEW — Amount 2026 (₪): | H6: =SUMPRODUCT(--((($D$9:$D$593<>0)+($I$9:$I$593<>0)>0)*(($C$9:$C$593=0)*($H$9:$H$593=0)))*$I$9:$I$593) -> 39128 | I6: NEW — Quantity 2026 Annualized: | J6: =F6*$J$5 -> 807.77143 | K6: NEW — Amount 2026 Annualized (₪): | L6: =H6*$J$5 -> 53661.257
A8: Product Code | B8: Product Name | C8: Quantity 2025 | D8: Quantity 2026 (Actual, partial year) | E8: Quantity 2026 (Annualized) | F8: Quantity Change (Annualized vs 2025) | G8: Quantity Change % (Annualized vs 2025) | H8: Amount 2025 (₪) | I8: Amount 2026 (Actual, partial year) (₪) | J8: Amount 2026 (Annualized) (₪) | K8: Amount Change (Annualized vs 2025) (₪) | L8: Amount Change % (Annualized vs 2025)
A9: 4408205 | B9: =IFERROR(INDEX('Source 2026'!$C:$C,MATCH($A9,'Source 2026'!$B:$B,0)),IFERROR(INDEX('Source 2025'!$C:$C,MATCH($A9,'Source 2025'!$B:$B,0)),"")) -> AC-07 חגורת גב עם תמיכות | C9: =SUMIFS('Source 2025'!$D:$D,'Source 2025'!$B:$B,$A9,'Source 2025'!$A:$A,"Quantity (units)")+SUMIFS('Source 2025'!$E:$E,'Source 2025'!$B:$B,$A9,'Source 2025'!$A:$A,"Quantity (units)")+SUMIFS('Source 2025'!$F:$F,'Source 2025'!$B:$B,$A9,'Source 2025'!$A:$A,"Quantity (units)")+SUMIFS('Source 2025'!$G:$G,'Source 2025'!$B:$B,$A9,'Source 2025'!$A:$A,"Quantity (units)")+SUMIFS('Source 2025'!$J:$J,'Source 2025'!$B:$B,$A9,'Source 2025'!$A:$A,"Quantity (units)")+SUMIFS('Source 2025'!$M:$M,'Source 2025'!$B:$B,$A9,'Source 2025'!$A:$A,"Quantity (units)") -> 1110 | D9: =SUMIFS('Source 2026'!$D:$D,'Source 2026'!$B:$B,$A9,'Source 2026'!$A:$A,"Quantity (units)")+SUMIFS('Source 2026'!$E:$E,'Source 2026'!$B:$B,$A9,'Source 2026'!$A:$A,"Quantity (units)")+SUMIFS('Source 2026'!$F:$F,'Source 2026'!$B:$B,$A9,'Source 2026'!$A:$A,"Quantity (units)")+SUMIFS('Source 2026'!$G:$G,'Source 2026'!$B:$B,$A9,'Source 2026'!$A:$A,"Quantity (units)")+SUMIFS('Source 2026'!$J:$J,'Source 2026'!$B:$B,$A9,'Source 2026'!$A:$A,"Quantity (units)")+SUMIFS('Source 2026'!$M:$M,'Source 2026'!$B:$B,$A9,'Source 2026'!$A:$A,"Quantity (units)") -> 802 | E9: =D9*$J$5 -> 1099.8857 | F9: =E9-C9 -> -10.114286 | G9: =IF(AND(C9=0,E9=0),0,IF(C9=0,"New",(E9-C9)/C9)) -> -0.0091119691 | H9: =SUMIFS('Source 2025'!$D:$D,'Source 2025'!$B:$B,$A9,'Source 2025'!$A:$A,"Amount (NIS)")+SUMIFS('Source 2025'!$E:$E,'Source 2025'!$B:$B,$A9,'Source 2025'!$A:$A,"Amount (NIS)")+SUMIFS('Source 2025'!$F:$F,'Source 2025'!$B:$B,$A9,'Source 2025'!$A:$A,"Amount (NIS)")+SUMIFS('Source 2025'!$G:$G,'Source 2025'!$B:$B,$A9,'Source 2025'!$A:$A,"Amount (NIS)")+SUMIFS('Source 2025'!$J:$J,'Source 2025'!$B:$B,$A9,'Source 2025'!$A:$A,"Amount (NIS)")+SUMIFS('Source 2025'!$M:$M,'Source 2025'!$B:$B,$A9,'Source 2025'!$A:$A,"Amount (NIS)") -> 94616.3 | I9: =SUMIFS('Source 2026'!$D:$D,'Source 2026'!$B:$B,$A9,'Source 2026'!$A:$A,"Amount (NIS)")+SUMIFS('Source 2026'!$E:$E,'Source 2026'!$B:$B,$A9,'Source 2026'!$A:$A,"Amount (NIS)")+SUMIFS('Source 2026'!$F:$F,'Source 2026'!$B:$B,$A9,'Source 2026'!$A:$A,"Amount (NIS)")+SUMIFS('Source 2026'!$G:$G,'Source 2026'!$B:$B,$A9,'Source 2026'!$A:$A,"Amount (NIS)")+SUMIFS('Source 2026'!$J:$J,'Source 2026'!$B:$B,$A9,'Source 2026'!$A:$A,"Amount (NIS)")+SUMIFS('Source 2026'!$M:$M,'Source 2026'!$B:$B,$A9,'Source 2026'!$A:$A,"Amount (NIS)") -> 69090.9 | J9: =I9*$J$5 -> 94753.234 | K9: =J9-H9 -> 136.93429 | L9: =IF(AND(H9=0,J9=0),0,IF(H9=0,"New",(J9-H9)/H9)) -> 0.0014472589
A10: 4413348 | B10: =IFERROR(INDEX('Source 2026'!$C:$C,MATCH($A10,'Source 2026'!$B:$B,0)),IFERROR(INDEX('Source 2025'!$C:$C,MATCH($A10,'Source 2025'!$B:$B,0)),"")) -> 302 מדרס ג'ל לגבר | C10: =SUMIFS('Source 2025'!$D:$D,'Source 2025'!$B:$B,$A10,'Source 2025'!$A:$A,"Quantity (units)")+SUMIFS('Source 2025'!$E:$E,'Source 2025'!$B:$B,$A10,'Source 2025'!$A:$A,"Quantity (units)")+SUMIFS('Source 2025'!$F:$F,'Source 2025'!$B:$B,$A10,'Source 2025'!$A:$A,"Quantity (units)")+SUMIFS('Source 2025'!$G:$G,'Source 2025'!$B:$B,$A10,'Source 2025'!$A:$A,"Quantity (units)")+SUMIFS('Source 2025'!$J:$J,'Source 2025'!$B:$B,$A10,'Source 2025'!$A:$A,"Quantity (units)")+SUMIFS('Source 2025'!$M:$M,'Source 2025'!$B:$B,$A10,'Source 2025'!$A:$A,"Quantity (units)") -> 569 | D10: =SUMIFS('Source 2026'!$D:$D,'Source 2026'!$B:$B,$A10,'Source 2026'!$A:$A,"Quantity (units)")+SUMIFS('Source 2026'!$E:$E,'Source 2026'!$B:$B,$A10,'Source 2026'!$A:$A,"Quantity (units)")+SUMIFS('Source 2026'!$F:$F,'Source 2026'!$B:$B,$A10,'Source 2026'!$A:$A,"Quantity (units)")+SUMIFS('Source 2026'!$G:$G,'Source 2026'!$B:$B,$A10,'Source 2026'!$A:$A,"Quantity (units)")+SUMIFS('Source 2026'!$J:$J,'Source 2026'!$B:$B,$A10,'Source 2026'!$A:$A,"Quantity (units)")+SUMIFS('Source 2026'!$M:$M,'Source 2026'!$B:$B,$A10,'Source 2026'!$A:$A,"Quantity (units)") -> 255 | E10: =D10*$J$5 -> 349.71429 | F10: =E10-C10 -> -219.28571 | G10: =IF(AND(C10=0,E10=0),0,IF(C10=0,"New",(E10-C10)/C10)) -> -0.3853879 | H10: =SUMIFS('Source 2025'!$D:$D,'Source 2025'!$B:$B,$A10,'Source 2025'!$A:$A,"Amount (NIS)")+SUMIFS('Source 2025'!$E:$E,'Source 2025'!$B:$B,$A10,'Source 2025'!$A:$A,"Amount (NIS)")+SUMIFS('Source 2025'!$F:$F,'Source 2025'!$B:$B,$A10,'Source 2025'!$A:$A,"Amount (NIS)")+SUMIFS('Source 2025'!$G:$G,'Source 2025'!$B:$B,$A10,'Source 2025'!$A:$A,"Amount (NIS)")+SUMIFS('Source 2025'!$J:$J,'Source 2025'!$B:$B,$A10,'Source 2025'!$A:$A,"Amount (NIS)")+SUMIFS('Source 2025'!$M:$M,'Source 2025'!$B:$B,$A10,'Source 2025'!$A:$A,"Amount (NIS)") -> 33796.2 | I10: =SUMIFS('Source 2026'!$D:$D,'Source 2026'!$B:$B,$A10,'Source 2026'!$A:$A,"Amount (NIS)")+SUMIFS('Source 2026'!$E:$E,'Source 2026'!$B:$B,$A10,'Source 2026'!$A:$A,"Amount (NIS)")+SUMIFS('Source 2026'!$F:$F,'Source 2026'!$B:$B,$A10,'Source 2026'!$A:$A,"Amount (NIS)")+SUMIFS('Source 2026'!$G:$G,'Source 2026'!$B:$B,$A10,'Source 2026'!$A:$A,"Amount (NIS)")+SUMIFS('Source 2026'!$J:$J,'Source 2026'!$B:$B,$A10,'Source 2026'!$A:$A,"Amount (NIS)")+SUMIFS('Source 2026'!$M:$M,'Source 2026'!$B:$B,$A10,'Source 2026'!$A:$A,"Amount (NIS)") -> 16329.2 | J10: =I10*$J$5 -> 22394.331 | K10: =J10-H10 -> -11401.869 | L10: =IF(AND(H10=0,J10=0),0,IF(H10=0,"New",(J10-H10)/H10)) -> -0.33737132
A11: 4415158 | B11: =IFERROR(INDEX('Source 2026'!$C:$C,MATCH($A11,'Source 2026'!$B:$B,0)),IFERROR(INDEX('Source 2025'!$C:$C,MATCH($A11,'Source 2025'!$B:$B,0)),"")) -> 266 סד ליד דו צדדי | C11: =SUMIFS('Source 2025'!$D:$D,'Source 2025'!$B:$B,$A11,'Source 2025'!$A:$A,"Quantity (units)")+SUMIFS('Source 2025'!$E:$E,'Source 2025'!$B:$B,$A11,'Source 2025'!$A:$A,"Quantity (units)")+SUMIFS('Source 2025'!$F:$F,'Source 2025'!$B:$B,$A11,'Source 2025'!$A:$A,"Quantity (units)")+SUMIFS('Source 2025'!$G:$G,'Source 2025'!$B:$B,$A11,'Source 2025'!$A:$A,"Quantity (units)")+SUMIFS('Source 2025'!$J:$J,'Source 2025'!$B:$B,$A11,'Source 2025'!$A:$A,"Quantity (units)")+SUMIFS('Source 2025'!$M:$M,'Source 2025'!$B:$B,$A11,'Source 2025'!$A:$A,"Quantity (units)") -> 502 | D11: =SUMIFS('Source 2026'!$D:$D,'Source 2026'!$B:$B,$A11,'Source 2026'!$A:$A,"Quantity (units)")+SUMIFS('Source 2026'!$E:$E,'Source 2026'!$B:$B,$A11,'Source 2026'!$A:$A,"Quantity (units)")+SUMIFS('Source 2026'!$F:$F,'Source 2026'!$B:$B,$A11,'Source 2026'!$A:$A,"Quantity (units)")+SUMIFS('Source 2026'!$G:$G,'Source 2026'!$B:$B,$A11,'Source 2026'!$A:$A,"Quantity (units)")+SUMIFS('Source 2026'!$J:$J,'Source 2026'!$B:$B,$A11,'Source 2026'!$A:$A,"Quantity (units)")+SUMIFS('Source 2026'!$M:$M,'Source 2026'!$B:$B,$A11,'Source 2026'!$A:$A,"Quantity (units)") -> 336 | E11: =D11*$J$5 -> 460.8 | F11: =E11-C11 -> -41.2 | G11: =IF(AND(C11=0,E11=0),0,IF(C11=0,"New",(E11-C11)/C11)) -> -0.082071713 | H11: =SUMIFS('Source 2025'!$D:$D,'Source 2025'!$B:$B,$A11,'Source 2025'!$A:$A,"Amount (NIS)")+SUMIFS('Source 2025'!$E:$E,'Source 2025'!$B:$B,$A11,'Source 2025'!$A:$A,"Amount (NIS)")+SUMIFS('Source 2025'!$F:$F,'Source 2025'!$B:$B,$A11,'Source 2025'!$A:$A,"Amount (NIS)")+SUMIFS('Source 2025'!$G:$G,'Source 2025'!$B:$B,$A11,'Source 2025'!$A:$A,"Amount (NIS)")+SUMIFS('Source 2025'!$J:$J,'Source 2025'!$B:$B,$A11,'Source 2025'!$A:$A,"Amount (NIS)")+SUMIFS('Source 2025'!$M:$M,'Source 2025'!$B:$B,$A11,'Source 2025'!$A:$A,"Amount (NIS)") -> 38890.7 | I11: =SUMIFS('Source 2026'!$D:$D,'Source 2026'!$B:$B,$A11,'Source 2026'!$A:$A,"Amount (NIS)")+SUMIFS('Source 2026'!$E:$E,'Source 2026'!$B:$B,$A11,'Source 2026'!$A:$A,"Amount (NIS)")+SUMIFS('Source 2026'!$F:$F,'Source 2026'!$B:$B,$A11,'Source 2026'!$A:$A,"Amount (NIS)")+SUMIFS('Source 2026'!$G:$G,'Source 2026'!$B:$B,$A11,'Source 2026'!$A:$A,"Amount (NIS)")+SUMIFS('Source 2026'!$J:$J,'Source 2026'!$B:$B,$A11,'Source 2026'!$A:$A,"Amount (NIS)")+SUMIFS('Source 2026'!$M:$M,'Source 2026'!$B:$B,$A11,'Source 2026'!$A:$A,"Amount (NIS)") -> 26201.4 | J11: =I11*$J$5 -> 35933.349 | K11: =J11-H11 -> -2957.3514 | L11: =IF(AND(H11=0,J11=0),0,IF(H11=0,"New",(J11-H11)/H11)) -> -0.076042638
A12: 4403030 | B12: =IFERROR(INDEX('Source 2026'!$C:$C,MATCH($A12,'Source 2026'!$B:$B,0)),IFERROR(INDEX('Source 2025'!$C:$C,MATCH($A12,'Source 2025'!$B:$B,0)),"")) -> 397 43-46 גרבי טיסה מידה | C12: =SUMIFS('Source 2025'!$D:$D,'Source 2025'!$B:$B,$A12,'Source 2025'!$A:$A,"Quantity (units)")+SUMIFS('Source 2025'!$E:$E,'Source 2025'!$B:$B,$A12,'Source 2025'!$A:$A,"Quantity (units)")+SUMIFS('Source 2025'!$F:$F,'Source 2025'!$B:$B,$A12,'Source 2025'!$A:$A,"Quantity (units)")+SUMIFS('Source 2025'!$G:$G,'Source 2025'!$B:$B,$A12,'Source 2025'!$A:$A,"Quantity (units)")+SUMIFS('Source 2025'!$J:$J,'Source 2025'!$B:$B,$A12,'Source 2025'!$A:$A,"Quantity (units)")+SUMIFS('Source 2025'!$M:$M,'Source 2025'!$B:$B,$A12,'Source 2025'!$A:$A,"Quantity (units)") -> 211 | D12: =SUMIFS('Source 2026'!$D:$D,'Source 2026'!$B:$B,$A12,'Source 2026'!$A:$A,"Quantity (units)")+SUMIFS('Source 2026'!$E:$E,'Source 2026'!$B:$B,$A12,'Source 2026'!$A:$A,"Quantity (units)")+SUMIFS('Source 2026'!$F:$F,'Source 2026'!$B:$B,$A12,'Source 2026'!$A:$A,"Quantity (units)")+SUMIFS('Source 2026'!$G:$G,'Source 2026'!$B:$B,$A12,'Source 2026'!$A:$A,"Quantity (units)")+SUMIFS('Source 2026'!$J:$J,'Source 2026'!$B:$B,$A12,'Source 2026'!$A:$A,"Quantity (units)")+SUMIFS('Source 2026'!$M:$M,'Source 2026'!$B:$B,$A12,'Source 2026'!$A:$A,"Quantity (units)") -> -3 | E12: =D12*$J$5 -> -4.1142857 | F12: =E12-C12 -> -215.11429 | G12: =IF(AND(C12=0,E12=0),0,IF(C12=0,"New",(E12-C12)/C12)) -> -1.019499 | H12: =SUMIFS('Source 2025'!$D:$D,'Source 2025'!$B:$B,$A12,'Source 2025'!$A:$A,"Amount (NIS)")+SUMIFS('Source 2025'!$E:$E,'Source 2025'!$B:$B,$A12,'Source 2025'!$A:$A,"Amount (NIS)")+SUMIFS('Source 2025'!$F:$F,'Source 2025'!$B:$B,$A12,'Source 2025'!$A:$A,"Amount (NIS)")+SUMIFS('Source 2025'!$G:$G,'Source 2025'!$B:$B,$A12,'Source 2025'!$A:$A,"Amount (NIS)")+SUMIFS('Source 2025'!$J:$J,'Source 2025'!$B:$B,$A12,'Source 2025'!$A:$A,"Amount (NIS)")+SUMIFS('Source 2025'!$M:$M,'Source 2025'!$B:$B,$A12,'Source 2025'!$A:$A,"Amount (NIS)") -> 12491.9 | I12: =SUMIFS('Source 2026'!$D:$D,'Source 2026'!$B:$B,$A12,'Source 2026'!$A:$A,"Amount (NIS)")+SUMIFS('Source 2026'!$E:$E,'Source 2026'!$B:$B,$A12,'Source 2026'!$A:$A,"Amount (NIS)")+SUMIFS('Source 2026'!$F:$F,'Source 2026'!$B:$B,$A12,'Source 2026'!$A:$A,"Amount (NIS)")+SUMIFS('Source 2026'!$G:$G,'Source 2026'!$B:$B,$A12,'Source 2026'!$A:$A,"Amount (NIS)")+SUMIFS('Source 2026'!$J:$J,'Source 2026'!$B:$B,$A12,'Source 2026'!$A:$A,"Amount (NIS)")+SUMIFS('Source 2026'!$M:$M,'Source 2026'!$B:$B,$A12,'Source 2026'!$A:$A,"Amount (NIS)") -> -164.4 | J12: =I12*$J$5 -> -225.46286 | K12: =J12-H12 -> -12717.363 | L12: =IF(AND(H12=0,J12=0),0,IF(H12=0,"New",(J12-H12)/H12)) -> -1.0180487
A13: 4408052 | B13: =IFERROR(INDEX('Source 2026'!$C:$C,MATCH($A13,'Source 2026'!$B:$B,0)),IFERROR(INDEX('Source 2025'!$C:$C,MATCH($A13,'Source 2025'!$B:$B,0)),"")) -> 21 L חבק יד ארוך | C13: =SUMIFS('Source 2025'!$D:$D,'Source 2025'!$B:$B,$A13,'Source 2025'!$A:$A,"Quantity (units)")+SUMIFS('Source 2025'!$E:$E,'Source 2025'!$B:$B,$A13,'Source 2025'!$A:$A,"Quantity (units)")+SUMIFS('Source 2025'!$F:$F,'Source 2025'!$B:$B,$A13,'Source 2025'!$A:$A,"Quantity (units)")+SUMIFS('Source 2025'!$G:$G,'Source 2025'!$B:$B,$A13,'Source 2025'!$A:$A,"Quantity (units)")+SUMIFS('Source 2025'!$J:$J,'Source 2025'!$B:$B,$A13,'Source 2025'!$A:$A,"Quantity (units)")+SUMIFS('Source 2025'!$M:$M,'Source 2025'!$B:$B,$A13,'Source 2025'!$A:$A,"Quantity (units)") -> 613 | D13: =SUMIFS('Source 2026'!$D:$D,'Source 2026'!$B:$B,$A13,'Source 2026'!$A:$A,"Quantity (units)")+SUMIFS('Source 2026'!$E:$E,'Source 2026'!$B:$B,$A13,'Source 2026'!$A:$A,"Quantity (units)")+SUMIFS('Source 2026'!$F:$F,'Source 2026'!$B:$B,$A13,'Source 2026'!$A:$A,"Quantity (units)")+SUMIFS('Source 2026'!$G:$G,'Source 2026'!$B:$B,$A13,'Source 2026'!$A:$A,"Quantity (units)")+SUMIFS('Source 2026'!$J:$J,'Source 2026'!$B:$B,$A13,'Source 2026'!$A:$A,"Quantity (units)")+SUMIFS('Source 2026'!$M:$M,'Source 2026'!$B:$B,$A13,'Source 2026'!$A:$A,"Quantity (units)") -> 290 | E13: =D13*$J$5 -> 397.71429 | F13: =E13-C13 -> -215.28571 | G13: =IF(AND(C13=0,E13=0),0,IF(C13=0,"New",(E13-C13)/C13)) -> -0.35120019 | H13: =SUMIFS('Source 2025'!$D:$D,'Source 2025'!$B:$B,$A13,'Source 2025'!$A:$A,"Amount (NIS)")+SUMIFS('Source 2025'!$E:$E,'Source 2025'!$B:$B,$A13,'Source 2025'!$A:$A,"Amount (NIS)")+SUMIFS('Source 2025'!$F:$F,'Source 2025'!$B:$B,$A13,'Source 2025'!$A:$A,"Amount (NIS)")+SUMIFS('Source 2025'!$G:$G,'Source 2025'!$B:$B,$A13,'Source 2025'!$A:$A,"Amount (NIS)")+SUMIFS('Source 2025'!$J:$J,'Source 2025'!$B:$B,$A13,'Source 2025'!$A:$A,"Amount (NIS)")+SUMIFS('Source 2025'!$M:$M,'Source 2025'!$B:$B,$A13,'Source 2025'!$A:$A,"Amount (NIS)") -> 23671.9 | I13: =SUMIFS('Source 2026'!$D:$D,'Source 2026'!$B:$B,$A13,'Source 2026'!$A:$A,"Amount (NIS)")+SUMIFS('Source 2026'!$E:$E,'Source 2026'!$B:$B,$A13,'Source 2026'!$A:$A,"Amount (NIS)")+SUMIFS('Source 2026'!$F:$F,'Source 2026'!$B:$B,$A13,'Source 2026'!$A:$A,"Amount (NIS)")+SUMIFS('Source 2026'!$G:$G,'Source 2026'!$B:$B,$A13,'Source 2026'!$A:$A,"Amount (NIS)")+SUMIFS('Source 2026'!$J:$J,'Source 2026'!$B:$B,$A13,'Source 2026'!$A:$A,"Amount (NIS)")+SUMIFS('Source 2026'!$M:$M,'Source 2026'!$B:$B,$A13,'Source 2026'!$A:$A,"Amount (NIS)") -> 11311.7 | J13: =I13*$J$5 -> 15513.189 | K13: =J13-H13 -> -8158.7114 | L13: =IF(AND(H13=0,J13=0),0,IF(H13=0,"New",(J13-H13)/H13)) -> -0.34465807
A14: 4403029 | B14: =IFERROR(INDEX('Source 2026'!$C:$C,MATCH($A14,'Source 2026'!$B:$B,0)),IFERROR(INDEX('Source 2025'!$C:$C,MATCH($A14,'Source 2025'!$B:$B,0)),"")) -> 397 39-42 גרבי טיסה מידה | C14: =SUMIFS('Source 2025'!$D:$D,'Source 2025'!$B:$B,$A14,'Source 2025'!$A:$A,"Quantity (units)")+SUMIFS('Source 2025'!$E:$E,'Source 2025'!$B:$B,$A14,'Source 2025'!$A:$A,"Quantity (units)")+SUMIFS('Source 2025'!$F:$F,'Source 2025'!$B:$B,$A14,'Source 2025'!$A:$A,"Quantity (units)")+SUMIFS('Source 2025'!$G:$G,'Source 2025'!$B:$B,$A14,'Source 2025'!$A:$A,"Quantity (units)")+SUMIFS('Source 2025'!$J:$J,'Source 2025'!$B:$B,$A14,'Source 2025'!$A:$A,"Quantity (units)")+SUMIFS('Source 2025'!$M:$M,'Source 2025'!$B:$B,$A14,'Source 2025'!$A:$A,"Quantity (units)") -> 201 | D14: =SUMIFS('Source 2026'!$D:$D,'Source 2026'!$B:$B,$A14,'Source 2026'!$A:$A,"Quantity (units)")+SUMIFS('Source 2026'!$E:$E,'Source 2026'!$B:$B,$A14,'Source 2026'!$A:$A,"Quantity (units)")+SUMIFS('Source 2026'!$F:$F,'Source 2026'!$B:$B,$A14,'Source 2026'!$A:$A,"Quantity (units)")+SUMIFS('Source 2026'!$G:$G,'Source 2026'!$B:$B,$A14,'Source 2026'!$A:$A,"Quantity (units)")+SUMIFS('Source 2026'!$J:$J,'Source 2026'!$B:$B,$A14,'Source 2026'!$A:$A,"Quantity (units)")+SUMIFS('Source 2026'!$M:$M,'Source 2026'!$B:$B,$A14,'Source 2026'!$A:$A,"Quantity (units)") -> 2 | E14: =D14*$J$5 -> 2.7428571 | F14: =E14-C14 -> -198.25714 | G14: =IF(AND(C14=0,E14=0),0,IF(C14=0,"New",(E14-C14)/C14)) -> -0.98635394 | H14: =SUMIFS('Source 2025'!$D:$D,'Source 2025'!$B:$B,$A14,'Source 2025'!$A:$A,"Amount (NIS)")+SUMIFS('Source 2025'!$E:$E,'Source 2025'!$B:$B,$A14,'Source 2025'!$A:$A,"Amount (NIS)")+SUMIFS('Source 2025'!$F:$F,'Source 2025'!$B:$B,$A14,'Source 2025'!$A:$A,"Amount (NIS)")+SUMIFS('Source 2025'!$G:$G,'Source 2025'!$B:$B,$A14,'Source 2025'!$A:$A,"Amount (NIS)")+SUMIFS('Source 2025'!$J:$J,'Source 2025'!$B:$B,$A14,'Source 2025'!$A:$A,"Amount (NIS)")+SUMIFS('Source 2025'!$M:$M,'Source 2025'!$B:$B,$A14,'Source 2025'!$A:$A,"Amount (NIS)") -> 11825.2 | I14: =SUMIFS('Source 2026'!$D:$D,'Source 2026'!$B:$B,$A14,'Source 2026'!$A:$A,"Amount (NIS)")+SUMIFS('Source 2026'!$E:$E,'Source 2026'!$B:$B,$A14,'Source 2026'!$A:$A,"Amount (NIS)")+SUMIFS('Source 2026'!$F:$F,'Source 2026'!$B:$B,$A14,'Source 2026'!$A:$A,"Amount (NIS)")+SUMIFS('Source 2026'!$G:$G,'Source 2026'!$B:$B,$A14,'Source 2026'!$A:$A,"Amount (NIS)")+SUMIFS('Source 2026'!$J:$J,'Source 2026'!$B:$B,$A14,'Source 2026'!$A:$A,"Amount (NIS)")+SUMIFS('Source 2026'!$M:$M,'Source 2026'!$B:$B,$A14,'Source 2026'!$A:$A,"Amount (NIS)") -> 134.9 | J14: =I14*$J$5 -> 185.00571 | K14: =J14-H14 -> -11640.194 | L14: =IF(AND(H14=0,J14=0),0,IF(H14=0,"New",(J14-H14)/H14)) -> -0.98435496
A15: 4422035 | B15: =IFERROR(INDEX('Source 2026'!$C:$C,MATCH($A15,'Source 2026'!$B:$B,0)),IFERROR(INDEX('Source 2025'!$C:$C,MATCH($A15,'Source 2025'!$B:$B,0)),"")) -> FCתרסיס דאודורנט אנטיבק.נעל333 | C15: =SUMIFS('Source 2025'!$D:$D,'Source 2025'!$B:$B,$A15,'Source 2025'!$A:$A,"Quantity (units)")+SUMIFS('Source 2025'!$E:$E,'Source 2025'!$B:$B,$A15,'Source 2025'!$A:$A,"Quantity (units)")+SUMIFS('Source 2025'!$F:$F,'Source 2025'!$B:$B,$A15,'Source 2025'!$A:$A,"Quantity (units)")+SUMIFS('Source 2025'!$G:$G,'Source 2025'!$B:$B,$A15,'Source 2025'!$A:$A,"Quantity (units)")+SUMIFS('Source 2025'!$J:$J,'Source 2025'!$B:$B,$A15,'Source 2025'!$A:$A,"Quantity (units)")+SUMIFS('Source 2025'!$M:$M,'Source 2025'!$B:$B,$A15,'Source 2025'!$A:$A,"Quantity (units)") -> 956 | D15: =SUMIFS('Source 2026'!$D:$D,'Source 2026'!$B:$B,$A15,'Source 2026'!$A:$A,"Quantity (units)")+SUMIFS('Source 2026'!$E:$E,'Source 2026'!$B:$B,$A15,'Source 2026'!$A:$A,"Quantity (units)")+SUMIFS('Source 2026'!$F:$F,'Source 2026'!$B:$B,$A15,'Source 2026'!$A:$A,"Quantity (units)")+SUMIFS('Source 2026'!$G:$G,'Source 2026'!$B:$B,$A15,'Source 2026'!$A:$A,"Quantity (units)")+SUMIFS('Source 2026'!$J:$J,'Source 2026'!$B:$B,$A15,'Source 2026'!$A:$A,"Quantity (units)")+SUMIFS('Source 2026'!$M:$M,'Source 2026'!$B:$B,$A15,'Source 2026'!$A:$A,"Quantity (units)") -> 341 | E15: =D15*$J$5 -> 467.65714 | F15: =E15-C15 -> -488.34286 | G15: =IF(AND(C15=0,E15=0),0,IF(C15=0,"New",(E15-C15)/C15)) -> -0.51081889 | H15: =SUMIFS('Source 2025'!$D:$D,'Source 2025'!$B:$B,$A15,'Source 2025'!$A:$A,"Amount (NIS)")+SUMIFS('Source 2025'!$E:$E,'Source 2025'!$B:$B,$A15,'Source 2025'!$A:$A,"Amount (NIS)")+SUMIFS('Source 2025'!$F:$F,'Source 2025'!$B:$B,$A15,'Source 2025'!$A:$A,"Amount (NIS)")+SUMIFS('Source 2025'!$G:$G,'Source 2025'!$B:$B,$A15,'Source 2025'!$A:$A,"Amount (NIS)")+SUMIFS('Source 2025'!$J:$J,'Source 2025'!$B:$B,$A15,'Source 2025'!$A:$A,"Amount (NIS)")+SUMIFS('Source 2025'!$M:$M,'Source 2025'!$B:$B,$A15,'Source 2025'!$A:$A,"Amount (NIS)") -> 17801.7 | I15: =SUMIFS('Source 2026'!$D:$D,'Source 2026'!$B:$B,$A15,'Source 2026'!$A:$A,"Amount (NIS)")+SUMIFS('Source 2026'!$E:$E,'Source 2026'!$B:$B,$A15,'Source 2026'!$A:$A,"Amount (NIS)")+SUMIFS('Source 2026'!$F:$F,'Source 2026'!$B:$B,$A15,'Source 2026'!$A:$A,"Amount (NIS)")+SUMIFS('Source 2026'!$G:$G,'Source 2026'!$B:$B,$A15,'Source 2026'!$A:$A,"Amount (NIS)")+SUMIFS('Source 2026'!$J:$J,'Source 2026'!$B:$B,$A15,'Source 2026'!$A:$A,"Amount (NIS)")+SUMIFS('Source 2026'!$M:$M,'Source 2026'!$B:$B,$A15,'Source 2026'!$A:$A,"Amount (NIS)") -> 6493.3 | J15: =I15*$J$5 -> 8905.0971 | K15: =J15-H15 -> -8896.6029 | L15: =IF(AND(H15=0,J15=0),0,IF(H15=0,"New",(J15-H15)/H15)) -> -0.49976142
A16: 4403042 | B16: =IFERROR(INDEX('Source 2026'!$C:$C,MATCH($A16,'Source 2026'!$B:$B,0)),IFERROR(INDEX('Source 2025'!$C:$C,MATCH($A16,'Source 2025'!$B:$B,0)),"")) -> 397A-גרבי טיסה אנטי בקטרי39-42 | C16: =SUMIFS('Source 2025'!$D:$D,'Source 2025'!$B:$B,$A16,'Source 2025'!$A:$A,"Quantity (units)")+SUMIFS('Source 2025'!$E:$E,'Source 2025'!$B:$B,$A16,'Source 2025'!$A:$A,"Quantity (units)")+SUMIFS('Source 2025'!$F:$F,'Source 2025'!$B:$B,$A16,'Source 2025'!$A:$A,"Quantity (units)")+SUMIFS('Source 2025'!$G:$G,'Source 2025'!$B:$B,$A16,'Source 2025'!$A:$A,"Quantity (units)")+SUMIFS('Source 2025'!$J:$J,'Source 2025'!$B:$B,$A16,'Source 2025'!$A:$A,"Quantity (units)")+SUMIFS('Source 2025'!$M:$M,'Source 2025'!$B:$B,$A16,'Source 2025'!$A:$A,"Quantity (units)") -> 0 | D16: =SUMIFS('Source 2026'!$D:$D,'Source 2026'!$B:$B,$A16,'Source 2026'!$A:$A,"Quantity (units)")+SUMIFS('Source 2026'!$E:$E,'Source 2026'!$B:$B,$A16,'Source 2026'!$A:$A,"Quantity (units)")+SUMIFS('Source 2026'!$F:$F,'Source 2026'!$B:$B,$A16,'Source 2026'!$A:$A,"Quantity (units)")+SUMIFS('Source 2026'!$G:$G,'Source 2026'!$B:$B,$A16,'Source 2026'!$A:$A,"Quantity (units)")+SUMIFS('Source 2026'!$J:$J,'Source 2026'!$B:$B,$A16,'Source 2026'!$A:$A,"Quantity (units)")+SUMIFS('Source 2026'!$M:$M,'Source 2026'!$B:$B,$A16,'Source 2026'!$A:$A,"Quantity (units)") -> 190 | E16: =D16*$J$5 -> 260.57143 | F16: =E16-C16 -> 260.57143 | G16: =IF(AND(C16=0,E16=0),0,IF(C16=0,"New",(E16-C16)/C16)) -> New | H16: =SUMIFS('Source 2025'!$D:$D,'Source 2025'!$B:$B,$A16,'Source 2025'!$A:$A,"Amount (NIS)")+SUMIFS('Source 2025'!$E:$E,'Source 2025'!$B:$B,$A16,'Source 2025'!$A:$A,"Amount (NIS)")+SUMIFS('Source 2025'!$F:$F,'Source 2025'!$B:$B,$A16,'Source 2025'!$A:$A,"Amount (NIS)")+SUMIFS('Source 2025'!$G:$G,'Source 2025'!$B:$B,$A16,'Source 2025'!$A:$A,"Amount (NIS)")+SUMIFS('Source 2025'!$J:$J,'Source 2025'!$B:$B,$A16,'Source 2025'!$A:$A,"Amount (NIS)")+SUMIFS('Source 2025'!$M:$M,'Source 2025'!$B:$B,$A16,'Source 2025'!$A:$A,"Amount (NIS)") -> 0 | I16: =SUMIFS('Source 2026'!$D:$D,'Source 2026'!$B:$B,$A16,'Source 2026'!$A:$A,"Amount (NIS)")+SUMIFS('Source 2026'!$E:$E,'Source 2026'!$B:$B,$A16,'Source 2026'!$A:$A,"Amount (NIS)")+SUMIFS('Source 2026'!$F:$F,'Source 2026'!$B:$B,$A16,'Source 2026'!$A:$A,"Amount (NIS)")+SUMIFS('Source 2026'!$G:$G,'Source 2026'!$B:$B,$A16,'Source 2026'!$A:$A,"Amount (NIS)")+SUMIFS('Source 2026'!$J:$J,'Source 2026'!$B:$B,$A16,'Source 2026'!$A:$A,"Amount (NIS)")+SUMIFS('Source 2026'!$M:$M,'Source 2026'!$B:$B,$A16,'Source 2026'!$A:$A,"Amount (NIS)") -> 11246.6 | J16: =I16*$J$5 -> 15423.909 | K16: =J16-H16 -> 15423.909 | L16: =IF(AND(H16=0,J16=0),0,IF(H16=0,"New",(J16-H16)/H16)) -> New
A17: 4408098 | B17: =IFERROR(INDEX('Source 2026'!$C:$C,MATCH($A17,'Source 2026'!$B:$B,0)),IFERROR(INDEX('Source 2025'!$C:$C,MATCH($A17,'Source 2025'!$B:$B,0)),"")) -> T25-חבק יד אגודלי | C17: =SUMIFS('Source 2025'!$D:$D,'Source 2025'!$B:$B,$A17,'Source 2025'!$A:$A,"Quantity (units)")+SUMIFS('Source 2025'!$E:$E,'Source 2025'!$B:$B,$A17,'Source 2025'!$A:$A,"Quantity (units)")+SUMIFS('Source 2025'!$F:$F,'Source 2025'!$B:$B,$A17,'Source 2025'!$A:$A,"Quantity (units)")+SUMIFS('Source 2025'!$G:$G,'Source 2025'!$B:$B,$A17,'Source 2025'!$A:$A,"Quantity (units)")+SUMIFS('Source 2025'!$J:$J,'Source 2025'!$B:$B,$A17,'Source 2025'!$A:$A,"Quantity (units)")+SUMIFS('Source 2025'!$M:$M,'Source 2025'!$B:$B,$A17,'Source 2025'!$A:$A,"Quantity (units)") -> 554 | D17: =SUMIFS('Source 2026'!$D:$D,'Source 2026'!$B:$B,$A17,'Source 2026'!$A:$A,"Quantity (units)")+SUMIFS('Source 2026'!$E:$E,'Source 2026'!$B:$B,$A17,'Source 2026'!$A:$A,"Quantity (units)")+SUMIFS('Source 2026'!$F:$F,'Source 2026'!$B:$B,$A17,'Source 2026'!$A:$A,"Quantity (units)")+SUMIFS('Source 2026'!$G:$G,'Source 2026'!$B:$B,$A17,'Source 2026'!$A:$A,"Quantity (units)")+SUMIFS('Source 2026'!$J:$J,'Source 2026'!$B:$B,$A17,'Source 2026'!$A:$A,"Quantity (units)")+SUMIFS('Source 2026'!$M:$M,'Source 2026'!$B:$B,$A17,'Source 2026'!$A:$A,"Quantity (units)") -> 299 | E17: =D17*$J$5 -> 410.05714 | F17: =E17-C17 -> -143.94286 | G17: =IF(AND(C17=0,E17=0),0,IF(C17=0,"New",(E17-C17)/C17)) -> -0.25982465 | H17: =SUMIFS('Source 2025'!$D:$D,'Source 2025'!$B:$B,$A17,'Source 2025'!$A:$A,"Amount (NIS)")+SUMIFS('Source 2025'!$E:$E,'Source 2025'!$B:$B,$A17,'Source 2025'!$A:$A,"Amount (NIS)")+SUMIFS('Source 2025'!$F:$F,'Source 2025'!$B:$B,$A17,'Source 2025'!$A:$A,"Amount (NIS)")+SUMIFS('Source 2025'!$G:$G,'Source 2025'!$B:$B,$A17,'Source 2025'!$A:$A,"Amount (NIS)")+SUMIFS('Source 2025'!$J:$J,'Source 2025'!$B:$B,$A17,'Source 2025'!$A:$A,"Amount (NIS)")+SUMIFS('Source 2025'!$M:$M,'Source 2025'!$B:$B,$A17,'Source 2025'!$A:$A,"Amount (NIS)") -> 24683.5 | I17: =SUMIFS('Source 2026'!$D:$D,'Source 2026'!$B:$B,$A17,'Source 2026'!$A:$A,"Amount (NIS)")+SUMIFS('Source 2026'!$E:$E,'Source 2026'!$B:$B,$A17,'Source 2026'!$A:$A,"Amount (NIS)")+SUMIFS('Source 2026'!$F:$F,'Source 2026'!$B:$B,$A17,'Source 2026'!$A:$A,"Amount (NIS)")+SUMIFS('Source 2026'!$G:$G,'Source 2026'!$B:$B,$A17,'Source 2026'!$A:$A,"Amount (NIS)")+SUMIFS('Source 2026'!$J:$J,'Source 2026'!$B:$B,$A17,'Source 2026'!$A:$A,"Amount (NIS)")+SUMIFS('Source 2026'!$M:$M,'Source 2026'!$B:$B,$A17,'Source 2026'!$A:$A,"Amount (NIS)") -> 13677.8 | J17: =I17*$J$5 -> 18758.126 | K17: =J17-H17 -> -5925.3743 | L17: =IF(AND(H17=0,J17=0),0,IF(H17=0,"New",(J17-H17)/H17)) -> -0.24005406
A18: 4408053 | B18: =IFERROR(INDEX('Source 2026'!$C:$C,MATCH($A18,'Source 2026'!$B:$B,0)),IFERROR(INDEX('Source 2025'!$C:$C,MATCH($A18,'Source 2025'!$B:$B,0)),"")) -> 21 M חבק יד ארוך | C18: =SUMIFS('Source 2025'!$D:$D,'Source 2025'!$B:$B,$A18,'Source 2025'!$A:$A,"Quantity (units)")+SUMIFS('Source 2025'!$E:$E,'Source 2025'!$B:$B,$A18,'Source 2025'!$A:$A,"Quantity (units)")+SUMIFS('Source 2025'!$F:$F,'Source 2025'!$B:$B,$A18,'Source 2025'!$A:$A,"Quantity (units)")+SUMIFS('Source 2025'!$G:$G,'Source 2025'!$B:$B,$A18,'Source 2025'!$A:$A,"Quantity (units)")+SUMIFS('Source 2025'!$J:$J,'Source 2025'!$B:$B,$A18,'Source 2025'!$A:$A,"Quantity (units)")+SUMIFS('Source 2025'!$M:$M,'Source 2025'!$B:$B,$A18,'Source 2025'!$A:$A,"Quantity (units)") -> 665 | D18: =SUMIFS('Source 2026'!$D:$D,'Source 2026'!$B:$B,$A18,'Source 2026'!$A:$A,"Quantity (units)")+SUMIFS('Source 2026'!$E:$E,'Source 2026'!$B:$B,$A18,'Source 2026'!$A:$A,"Quantity (units)")+SUMIFS('Source 2026'!$F:$F,'Source 2026'!$B:$B,$A18,'Source 2026'!$A:$A,"Quantity (units)")+SUMIFS('Source 2026'!$G:$G,'Source 2026'!$B:$B,$A18,'Source 2026'!$A:$A,"Quantity (units)")+SUMIFS('Source 2026'!$J:$J,'Source 2026'!$B:$B,$A18,'Source 2026'!$A:$A,"Quantity (units)")+SUMIFS('Source 2026'!$M:$M,'Source 2026'!$B:$B,$A18,'Source 2026'!$A:$A,"Quantity (units)") -> 380 | E18: =D18*$J$5 -> 521.14286 | F18: =E18-C18 -> -143.85714 | G18: =IF(AND(C18=0,E18=0),0,IF(C18=0,"New",(E18-C18)/C18)) -> -0.21632653 | H18: =SUMIFS('Source 2025'!$D:$D,'Source 2025'!$B:$B,$A18,'Source 2025'!$A:$A,"Amount (NIS)")+SUMIFS('Source 2025'!$E:$E,'Source 2025'!$B:$B,$A18,'Source 2025'!$A:$A,"Amount (NIS)")+SUMIFS('Source 2025'!$F:$F,'Source 2025'!$B:$B,$A18,'Source 2025'!$A:$A,"Amount (NIS)")+SUMIFS('Source 2025'!$G:$G,'Source 2025'!$B:$B,$A18,'Source 2025'!$A:$A,"Amount (NIS)")+SUMIFS('Source 2025'!$J:$J,'Source 2025'!$B:$B,$A18,'Source 2025'!$A:$A,"Amount (NIS)")+SUMIFS('Source 2025'!$M:$M,'Source 2025'!$B:$B,$A18,'Source 2025'!$A:$A,"Amount (NIS)") -> 25850.9 | I18: =SUMIFS('Source 2026'!$D:$D,'Source 2026'!$B:$B,$A18,'Source 2026'!$A:$A,"Amount (NIS)")+SUMIFS('Source 2026'!$E:$E,'Source 2026'!$B:$B,$A18,'Source 2026'!$A:$A,"Amount (NIS)")+SUMIFS('Source 2026'!$F:$F,'Source 2026'!$B:$B,$A18,'Source 2026'!$A:$A,"Amount (NIS)")+SUMIFS('Source 2026'!$G:$G,'Source 2026'!$B:$B,$A18,'Source 2026'!$A:$A,"Amount (NIS)")+SUMIFS('Source 2026'!$J:$J,'Source 2026'!$B:$B,$A18,'Source 2026'!$A:$A,"Amount (NIS)")+SUMIFS('Source 2026'!$M:$M,'Source 2026'!$B:$B,$A18,'Source 2026'!$A:$A,"Amount (NIS)") -> 14853.3 | J18: =I18*$J$5 -> 20370.24 | K18: =J18-H18 -> -5480.66 | L18: =IF(AND(H18=0,J18=0),0,IF(H18=0,"New",(J18-H18)/H18)) -> -0.21201041
A19: 4421000 | B19: =IFERROR(INDEX('Source 2026'!$C:$C,MATCH($A19,'Source 2026'!$B:$B,0)),IFERROR(INDEX('Source 2025'!$C:$C,MATCH($A19,'Source 2025'!$B:$B,0)),"")) -> 3655 שרוול מסיליקון לאצבע | C19: =SUMIFS('Source 2025'!$D:$D,'Source 2025'!$B:$B,$A19,'Source 2025'!$A:$A,"Quantity (units)")+SUMIFS('Source 2025'!$E:$E,'Source 2025'!$B:$B,$A19,'Source 2025'!$A:$A,"Quantity (units)")+SUMIFS('Source 2025'!$F:$F,'Source 2025'!$B:$B,$A19,'Source 2025'!$A:$A,"Quantity (units)")+SUMIFS('Source 2025'!$G:$G,'Source 2025'!$B:$B,$A19,'Source 2025'!$A:$A,"Quantity (units)")+SUMIFS('Source 2025'!$J:$J,'Source 2025'!$B:$B,$A19,'Source 2025'!$A:$A,"Quantity (units)")+SUMIFS('Source 2025'!$M:$M,'Source 2025'!$B:$B,$A19,'Source 2025'!$A:$A,"Quantity (units)") -> 1693 | D19: =SUMIFS('Source 2026'!$D:$D,'Source 2026'!$B:$B,$A19,'Source 2026'!$A:$A,"Quantity (units)")+SUMIFS('Source 2026'!$E:$E,'Source 2026'!$B:$B,$A19,'Source 2026'!$A:$A,"Quantity (units)")+SUMIFS('Source 2026'!$F:$F,'Source 2026'!$B:$B,$A19,'Source 2026'!$A:$A,"Quantity (units)")+SUMIFS('Source 2026'!$G:$G,'Source 2026'!$B:$B,$A19,'Source 2026'!$A:$A,"Quantity (units)")+SUMIFS('Source 2026'!$J:$J,'Source 2026'!$B:$B,$A19,'Source 2026'!$A:$A,"Quantity (units)")+SUMIFS('Source 2026'!$M:$M,'Source 2026'!$B:$B,$A19,'Source 2026'!$A:$A,"Quantity (units)") -> 1072 | E19: =D19*$J$5 -> 1470.1714 | F19: =E19-C19 -> -222.82857 | G19: =IF(AND(C19=0,E19=0),0,IF(C19=0,"New",(E19-C19)/C19)) -> -0.13161759 | H19: =SUMIFS('Source 2025'!$D:$D,'Source 2025'!$B:$B,$A19,'Source 2025'!$A:$A,"Amount (NIS)")+SUMIFS('Source 2025'!$E:$E,'Source 2025'!$B:$B,$A19,'Source 2025'!$A:$A,"Amount (NIS)")+SUMIFS('Source 2025'!$F:$F,'Source 2025'!$B:$B,$A19,'Source 2025'!$A:$A,"Amount (NIS)")+SUMIFS('Source 2025'!$G:$G,'Source 2025'!$B:$B,$A19,'Source 2025'!$A:$A,"Amount (NIS)")+SUMIFS('Source 2025'!$J:$J,'Source 2025'!$B:$B,$A19,'Source 2025'!$A:$A,"Amount (NIS)")+SUMIFS('Source 2025'!$M:$M,'Source 2025'!$B:$B,$A19,'Source 2025'!$A:$A,"Amount (NIS)") -> 29905.1 | I19: =SUMIFS('Source 2026'!$D:$D,'Source 2026'!$B:$B,$A19,'Source 2026'!$A:$A,"Amount (NIS)")+SUMIFS('Source 2026'!$E:$E,'Source 2026'!$B:$B,$A19,'Source 2026'!$A:$A,"Amount (NIS)")+SUMIFS('Source 2026'!$F:$F,'Source 2026'!$B:$B,$A19,'Source 2026'!$A:$A,"Amount (NIS)")+SUMIFS('Source 2026'!$G:$G,'Source 2026'!$B:$B,$A19,'Source 2026'!$A:$A,"Amount (NIS)")+SUMIFS('Source 2026'!$J:$J,'Source 2026'!$B:$B,$A19,'Source 2026'!$A:$A,"Amount (NIS)")+SUMIFS('Source 2026'!$M:$M,'Source 2026'!$B:$B,$A19,'Source 2026'!$A:$A,"Amount (NIS)") -> 19015.4 | J19: =I19*$J$5 -> 26078.263 | K19: =J19-H19 -> -3826.8371 | L19: =IF(AND(H19=0,J19=0),0,IF(H19=0,"New",(J19-H19)/H19)) -> -0.12796604
A20: 4422036 | B20: =IFERROR(INDEX('Source 2026'!$C:$C,MATCH($A20,'Source 2026'!$B:$B,0)),IFERROR(INDEX('Source 2025'!$C:$C,MATCH($A20,'Source 2025'!$B:$B,0)),"")) -> FC334 תרסיס דאודורנט לכף הרגל | C20: =SUMIFS('Source 2025'!$D:$D,'Source 2025'!$B:$B,$A20,'Source 2025'!$A:$A,"Quantity (units)")+SUMIFS('Source 2025'!$E:$E,'Source 2025'!$B:$B,$A20,'Source 2025'!$A:$A,"Quantity (units)")+SUMIFS('Source 2025'!$F:$F,'Source 2025'!$B:$B,$A20,'Source 2025'!$A:$A,"Quantity (units)")+SUMIFS('Source 2025'!$G:$G,'Source 2025'!$B:$B,$A20,'Source 2025'!$A:$A,"Quantity (units)")+SUMIFS('Source 2025'!$J:$J,'Source 2025'!$B:$B,$A20,'Source 2025'!$A:$A,"Quantity (units)")+SUMIFS('Source 2025'!$M:$M,'Source 2025'!$B:$B,$A20,'Source 2025'!$A:$A,"Quantity (units)") -> 1000 | D20: =SUMIFS('Source 2026'!$D:$D,'Source 2026'!$B:$B,$A20,'Source 2026'!$A:$A,"Quantity (units)")+SUMIFS('Source 2026'!$E:$E,'Source 2026'!$B:$B,$A20,'Source 2026'!$A:$A,"Quantity (units)")+SUMIFS('Source 2026'!$F:$F,'Source 2026'!$B:$B,$A20,'Source 2026'!$A:$A,"Quantity (units)")+SUMIFS('Source 2026'!$G:$G,'Source 2026'!$B:$B,$A20,'Source 2026'!$A:$A,"Quantity (units)")+SUMIFS('Source 2026'!$J:$J,'Source 2026'!$B:$B,$A20,'Source 2026'!$A:$A,"Quantity (units)")+SUMIFS('Source 2026'!$M:$M,'Source 2026'!$B:$B,$A20,'Source 2026'!$A:$A,"Quantity (units)") -> 468 | E20: =D20*$J$5 -> 641.82857 | F20: =E20-C20 -> -358.17143 | G20: =IF(AND(C20=0,E20=0),0,IF(C20=0,"New",(E20-C20)/C20)) -> -0.35817143 | H20: =SUMIFS('Source 2025'!$D:$D,'Source 2025'!$B:$B,$A20,'Source 2025'!$A:$A,"Amount (NIS)")+SUMIFS('Source 2025'!$E:$E,'Source 2025'!$B:$B,$A20,'Source 2025'!$A:$A,"Amount (NIS)")+SUMIFS('Source 2025'!$F:$F,'Source 2025'!$B:$B,$A20,'Source 2025'!$A:$A,"Amount (NIS)")+SUMIFS('Source 2025'!$G:$G,'Source 2025'!$B:$B,$A20,'Source 2025'!$A:$A,"Amount (NIS)")+SUMIFS('Source 2025'!$J:$J,'Source 2025'!$B:$B,$A20,'Source 2025'!$A:$A,"Amount (NIS)")+SUMIFS('Source 2025'!$M:$M,'Source 2025'!$B:$B,$A20,'Source 2025'!$A:$A,"Amount (NIS)") -> 19629.5 | I20: =SUMIFS('Source 2026'!$D:$D,'Source 2026'!$B:$B,$A20,'Source 2026'!$A:$A,"Amount (NIS)")+SUMIFS('Source 2026'!$E:$E,'Source 2026'!$B:$B,$A20,'Source 2026'!$A:$A,"Amount (NIS)")+SUMIFS('Source 2026'!$F:$F,'Source 2026'!$B:$B,$A20,'Source 2026'!$A:$A,"Amount (NIS)")+SUMIFS('Source 2026'!$G:$G,'Source 2026'!$B:$B,$A20,'Source 2026'!$A:$A,"Amount (NIS)")+SUMIFS('Source 2026'!$J:$J,'Source 2026'!$B:$B,$A20,'Source 2026'!$A:$A,"Amount (NIS)")+SUMIFS('Source 2026'!$M:$M,'Source 2026'!$B:$B,$A20,'Source 2026'!$A:$A,"Amount (NIS)") -> 9873.9 | J20: =I20*$J$5 -> 13541.349 | K20: =J20-H20 -> -6088.1514 | L20: =IF(AND(H20=0,J20=0),0,IF(H20=0,"New",(J20-H20)/H20)) -> -0.31015316
... A593: 4418006 | B593: =IFERROR(INDEX('Source 2026'!$C:$C,MATCH($A593,'Source 2026'!$B:$B,0)),IFERROR(INDEX('Source 2025'!$C:$C,MATCH($A593,'Source 2025'!$B:$B,0)),"")) -> 63 M צוארון פלסטי מתכוון | C593: =SUMIFS('Source 2025'!$D:$D,'Source 2025'!$B:$B,$A593,'Source 2025'!$A:$A,"Quantity (units)")+SUMIFS('Source 2025'!$E:$E,'Source 2025'!$B:$B,$A593,'Source 2025'!$A:$A,"Quantity (units)")+SUMIFS('Source 2025'!$F:$F,'Source 2025'!$B:$B,$A593,'Source 2025'!$A:$A,"Quantity (units)")+SUMIFS('Source 2025'!$G:$G,'Source 2025'!$B:$B,$A593,'Source 2025'!$A:$A,"Quantity (units)")+SUMIFS('Source 2025'!$J:$J,'Source 2025'!$B:$B,$A593,'Source 2025'!$A:$A,"Quantity (units)")+SUMIFS('Source 2025'!$M:$M,'Source 2025'!$B:$B,$A593,'Source 2025'!$A:$A,"Quantity (units)") -> 1 | D593: =SUMIFS('Source 2026'!$D:$D,'Source 2026'!$B:$B,$A593,'Source 2026'!$A:$A,"Quantity (units)")+SUMIFS('Source 2026'!$E:$E,'Source 2026'!$B:$B,$A593,'Source 2026'!$A:$A,"Quantity (units)")+SUMIFS('Source 2026'!$F:$F,'Source 2026'!$B:$B,$A593,'Source 2026'!$A:$A,"Quantity (units)")+SUMIFS('Source 2026'!$G:$G,'Source 2026'!$B:$B,$A593,'Source 2026'!$A:$A,"Quantity (units)")+SUMIFS('Source 2026'!$J:$J,'Source 2026'!$B:$B,$A593,'Source 2026'!$A:$A,"Quantity (units)")+SUMIFS('Source 2026'!$M:$M,'Source 2026'!$B:$B,$A593,'Source 2026'!$A:$A,"Quantity (units)") -> 1 | E593: =D593*$J$5 -> 1.3714286 | F593: =E593-C593 -> 0.37142857 | G593: =IF(AND(C593=0,E593=0),0,IF(C593=0,"New",(E593-C593)/C593)) -> 0.37142857 | H593: =SUMIFS('Source 2025'!$D:$D,'Source 2025'!$B:$B,$A593,'Source 2025'!$A:$A,"Amount (NIS)")+SUMIFS('Source 2025'!$E:$E,'Source 2025'!$B:$B,$A593,'Source 2025'!$A:$A,"Amount (NIS)")+SUMIFS('Source 2025'!$F:$F,'Source 2025'!$B:$B,$A593,'Source 2025'!$A:$A,"Amount (NIS)")+SUMIFS('Source 2025'!$G:$G,'Source 2025'!$B:$B,$A593,'Source 2025'!$A:$A,"Amount (NIS)")+SUMIFS('Source 2025'!$J:$J,'Source 2025'!$B:$B,$A593,'Source 2025'!$A:$A,"Amount (NIS)")+SUMIFS('Source 2025'!$M:$M,'Source 2025'!$B:$B,$A593,'Source 2025'!$A:$A,"Amount (NIS)") -> 66.5 | I593: =SUMIFS('Source 2026'!$D:$D,'Source 2026'!$B:$B,$A593,'Source 2026'!$A:$A,"Amount (NIS)")+SUMIFS('Source 2026'!$E:$E,'Source 2026'!$B:$B,$A593,'Source 2026'!$A:$A,"Amount (NIS)")+SUMIFS('Source 2026'!$F:$F,'Source 2026'!$B:$B,$A593,'Source 2026'!$A:$A,"Amount (NIS)")+SUMIFS('Source 2026'!$G:$G,'Source 2026'!$B:$B,$A593,'Source 2026'!$A:$A,"Amount (NIS)")+SUMIFS('Source 2026'!$J:$J,'Source 2026'!$B:$B,$A593,'Source 2026'!$A:$A,"Amount (NIS)")+SUMIFS('Source 2026'!$M:$M,'Source 2026'!$B:$B,$A593,'Source 2026'!$A:$A,"Amount (NIS)") -> 66.5 | J593: =I593*$J$5 -> 91.2 | K593: =J593-H593 -> 24.7 | L593: =IF(AND(H593=0,J593=0),0,IF(H593=0,"New",(J593-H593)/H593)) -> 0.37142857
B595: TOTAL | C595: =SUM(C9:C593) -> 54177 | D595: =SUM(D9:D593) -> 33485 | E595: =SUM(E9:E593) -> 45922.286 | F595: =SUM(F9:F593) -> -8254.7143 | G595: =IF(C595=0,"N/A",F595/C595) -> -0.15236566 | H595: =SUM(H9:H593) -> 1967633.7 | I595: =SUM(I9:I593) -> 1293687.8 | J595: =SUM(J9:J593) -> 1774200.4 | K595: =SUM(K9:K593) -> -193433.29 | L595: =IF(H595=0,"N/A",K595/H595) -> -0.09830757

Sheet BE
A1: Sales Comparison 2025 vs 2026 (Annualized) - Group: BE (by Product CODE) [with Maccabi, 24/09/2026]
A2: Calculation date: | B2: 46289
A3: Source: new PPLAY1 export "חנה_1" (uploaded 24/09/2026, internal snapshot timestamp 23/09/2026 17:01), which combines 2025 and 2026 in one sheet with an explicit group # per customer column (row 7) - used directly instead of the 2025.xls/2026.xls + manual mapping used for the 19/09 workbook. Group "BE" (#7) = sum of raw customer column(s): BE (column(s) I in 'Source 2025'/'Source 2026'). Product CODE = column A ("מקט") in the source, already clean (no parsing needed, unlike the old combined code+name format). Rows below only include product codes with non-zero quantity or amount for this group in at least one of the two years. This is a NEW, SEPARATE workbook - 2026-09-19-grouped-2025-vs-2026.xlsx was NOT modified.
A4: Annualization note: 2026 actual data covers approximately 8.75 months (1 Jan - 23 Sep 2026, per this source file’s own snapshot date - DIFFERENT from the 9.5 months / 15 Sep used in the other workbooks, which were built from an earlier snapshot). Scaled to a full year via factor = 12 / 8.75 (≈ 1.371429) - straight-line extrapolation, no seasonality adjustment. | I4: Months in full year: | J4: 12 | K4: Months covered by 2026 actual (1/1–23/9): | L4: 8.75
A5: # DROP (sold 2025, 0 in 2026): | B5: =SUMPRODUCT(--((($C$9:$C$354<>0)+($H$9:$H$354<>0)>0)*(($D$9:$D$354=0)*($I$9:$I$354=0)))) -> 64 | C5: # NEW (sold 2026, 0 in 2025): | D5: =SUMPRODUCT(--((($D$9:$D$354<>0)+($I$9:$I$354<>0)>0)*(($C$9:$C$354=0)*($H$9:$H$354=0)))) -> 18 | I5: Normalization factor (J4/L4): | J5: =J4/L4 -> 1.3714286
A6: DROP — Quantity 2025: | B6: =SUMPRODUCT(--((($C$9:$C$354<>0)+($H$9:$H$354<>0)>0)*(($D$9:$D$354=0)*($I$9:$I$354=0)))*$C$9:$C$354) -> 55 | C6: DROP — Amount 2025 (₪): | D6: =SUMPRODUCT(--((($C$9:$C$354<>0)+($H$9:$H$354<>0)>0)*(($D$9:$D$354=0)*($I$9:$I$354=0)))*$H$9:$H$354) -> 4567.1 | E6: NEW — Quantity 2026: | F6: =SUMPRODUCT(--((($D$9:$D$354<>0)+($I$9:$I$354<>0)>0)*(($C$9:$C$354=0)*($H$9:$H$354=0)))*$D$9:$D$354) -> 11 | G6: NEW — Amount 2026 (₪): | H6: =SUMPRODUCT(--((($D$9:$D$354<>0)+($I$9:$I$354<>0)>0)*(($C$9:$C$354=0)*($H$9:$H$354=0)))*$I$9:$I$354) -> 1501.2 | I6: NEW — Quantity 2026 Annualized: | J6: =F6*$J$5 -> 15.085714 | K6: NEW — Amount 2026 Annualized (₪): | L6: =H6*$J$5 -> 2058.7886
A8: Product Code | B8: Product Name | C8: Quantity 2025 | D8: Quantity 2026 (Actual, partial year) | E8: Quantity 2026 (Annualized) | F8: Quantity Change (Annualized vs 2025) | G8: Quantity Change % (Annualized vs 2025) | H8: Amount 2025 (₪) | I8: Amount 2026 (Actual, partial year) (₪) | J8: Amount 2026 (Annualized) (₪) | K8: Amount Change (Annualized vs 2025) (₪) | L8: Amount Change % (Annualized vs 2025)
A9: 4403029 | B9: =IFERROR(INDEX('Source 2026'!$C:$C,MATCH($A9,'Source 2026'!$B:$B,0)),IFERROR(INDEX('Source 2025'!$C:$C,MATCH($A9,'Source 2025'!$B:$B,0)),"")) -> 397 39-42 גרבי טיסה מידה | C9: =SUMIFS('Source 2025'!$I:$I,'Source 2025'!$B:$B,$A9,'Source 2025'!$A:$A,"Quantity (units)") -> 247 | D9: =SUMIFS('Source 2026'!$I:$I,'Source 2026'!$B:$B,$A9,'Source 2026'!$A:$A,"Quantity (units)") -> 5 | E9: =D9*$J$5 -> 6.8571429 | F9: =E9-C9 -> -240.14286 | G9: =IF(AND(C9=0,E9=0),0,IF(C9=0,"New",(E9-C9)/C9)) -> -0.97223829 | H9: =SUMIFS('Source 2025'!$I:$I,'Source 2025'!$B:$B,$A9,'Source 2025'!$A:$A,"Amount (NIS)") -> 14037 | I9: =SUMIFS('Source 2026'!$I:$I,'Source 2026'!$B:$B,$A9,'Source 2026'!$A:$A,"Amount (NIS)") -> 284.2 | J9: =I9*$J$5 -> 389.76 | K9: =J9-H9 -> -13647.24 | L9: =IF(AND(H9=0,J9=0),0,IF(H9=0,"New",(J9-H9)/H9)) -> -0.97223338
A10: 4409004 | B10: =IFERROR(INDEX('Source 2026'!$C:$C,MATCH($A10,'Source 2026'!$B:$B,0)),IFERROR(INDEX('Source 2025'!$C:$C,MATCH($A10,'Source 2025'!$B:$B,0)),"")) -> FC335 טלק מעושר באלוורה | C10: =SUMIFS('Source 2025'!$I:$I,'Source 2025'!$B:$B,$A10,'Source 2025'!$A:$A,"Quantity (units)") -> 1341 | D10: =SUMIFS('Source 2026'!$I:$I,'Source 2026'!$B:$B,$A10,'Source 2026'!$A:$A,"Quantity (units)") -> 735 | E10: =D10*$J$5 -> 1008 | F10: =E10-C10 -> -333 | G10: =IF(AND(C10=0,E10=0),0,IF(C10=0,"New",(E10-C10)/C10)) -> -0.24832215 | H10: =SUMIFS('Source 2025'!$I:$I,'Source 2025'!$B:$B,$A10,'Source 2025'!$A:$A,"Amount (NIS)") -> 23461.9 | I10: =SUMIFS('Source 2026'!$I:$I,'Source 2026'!$B:$B,$A10,'Source 2026'!$A:$A,"Amount (NIS)") -> 12652.2 | J10: =I10*$J$5 -> 17351.589 | K10: =J10-H10 -> -6110.3114 | L10: =IF(AND(H10=0,J10=0),0,IF(H10=0,"New",(J10-H10)/H10)) -> -0.26043549
A11: 4403030 | B11: =IFERROR(INDEX('Source 2026'!$C:$C,MATCH($A11,'Source 2026'!$B:$B,0)),IFERROR(INDEX('Source 2025'!$C:$C,MATCH($A11,'Source 2025'!$B:$B,0)),"")) -> 397 43-46 גרבי טיסה מידה | C11: =SUMIFS('Source 2025'!$I:$I,'Source 2025'!$B:$B,$A11,'Source 2025'!$A:$A,"Quantity (units)") -> 149 | D11: =SUMIFS('Source 2026'!$I:$I,'Source 2026'!$B:$B,$A11,'Source 2026'!$A:$A,"Quantity (units)") -> -2 | E11: =D11*$J$5 -> -2.7428571 | F11: =E11-C11 -> -151.74286 | G11: =IF(AND(C11=0,E11=0),0,IF(C11=0,"New",(E11-C11)/C11)) -> -1.0184084 | H11: =SUMIFS('Source 2025'!$I:$I,'Source 2025'!$B:$B,$A11,'Source 2025'!$A:$A,"Amount (NIS)") -> 8467.7 | I11: =SUMIFS('Source 2026'!$I:$I,'Source 2026'!$B:$B,$A11,'Source 2026'!$A:$A,"Amount (NIS)") -> -113.7 | J11: =I11*$J$5 -> -155.93143 | K11: =J11-H11 -> -8623.6314 | L11: =IF(AND(H11=0,J11=0),0,IF(H11=0,"New",(J11-H11)/H11)) -> -1.0184149
A12: 4403028 | B12: =IFERROR(INDEX('Source 2026'!$C:$C,MATCH($A12,'Source 2026'!$B:$B,0)),IFERROR(INDEX('Source 2025'!$C:$C,MATCH($A12,'Source 2025'!$B:$B,0)),"")) -> 397 35-38 גרבי טיסה מידה | C12: =SUMIFS('Source 2025'!$I:$I,'Source 2025'!$B:$B,$A12,'Source 2025'!$A:$A,"Quantity (units)") -> 141 | D12: =SUMIFS('Source 2026'!$I:$I,'Source 2026'!$B:$B,$A12,'Source 2026'!$A:$A,"Quantity (units)") -> -2 | E12: =D12*$J$5 -> -2.7428571 | F12: =E12-C12 -> -143.74286 | G12: =IF(AND(C12=0,E12=0),0,IF(C12=0,"New",(E12-C12)/C12)) -> -1.0194529 | H12: =SUMIFS('Source 2025'!$I:$I,'Source 2025'!$B:$B,$A12,'Source 2025'!$A:$A,"Amount (NIS)") -> 8026.6 | I12: =SUMIFS('Source 2026'!$I:$I,'Source 2026'!$B:$B,$A12,'Source 2026'!$A:$A,"Amount (NIS)") -> -113.7 | J12: =I12*$J$5 -> -155.93143 | K12: =J12-H12 -> -8182.5314 | L12: =IF(AND(H12=0,J12=0),0,IF(H12=0,"New",(J12-H12)/H12)) -> -1.0194268
A13: 4413135 | B13: =IFERROR(INDEX('Source 2026'!$C:$C,MATCH($A13,'Source 2026'!$B:$B,0)),IFERROR(INDEX('Source 2025'!$C:$C,MATCH($A13,'Source 2025'!$B:$B,0)),"")) -> 85 L (מתלה ליד )כיס | C13: =SUMIFS('Source 2025'!$I:$I,'Source 2025'!$B:$B,$A13,'Source 2025'!$A:$A,"Quantity (units)") -> 319 | D13: =SUMIFS('Source 2026'!$I:$I,'Source 2026'!$B:$B,$A13,'Source 2026'!$A:$A,"Quantity (units)") -> 207 | E13: =D13*$J$5 -> 283.88571 | F13: =E13-C13 -> -35.114286 | G13: =IF(AND(C13=0,E13=0),0,IF(C13=0,"New",(E13-C13)/C13)) -> -0.11007613 | H13: =SUMIFS('Source 2025'!$I:$I,'Source 2025'!$B:$B,$A13,'Source 2025'!$A:$A,"Amount (NIS)") -> 16783.9 | I13: =SUMIFS('Source 2026'!$I:$I,'Source 2026'!$B:$B,$A13,'Source 2026'!$A:$A,"Amount (NIS)") -> 10870.2 | J13: =I13*$J$5 -> 14907.703 | K13: =J13-H13 -> -1876.1971 | L13: =IF(AND(H13=0,J13=0),0,IF(H13=0,"New",(J13-H13)/H13)) -> -0.11178553
A14: 4422023 | B14: =IFERROR(INDEX('Source 2026'!$C:$C,MATCH($A14,'Source 2026'!$B:$B,0)),IFERROR(INDEX('Source 2025'!$C:$C,MATCH($A14,'Source 2025'!$B:$B,0)),"")) -> 806CB-BEIGE תחבושת א.נצמ | C14: =SUMIFS('Source 2025'!$I:$I,'Source 2025'!$B:$B,$A14,'Source 2025'!$A:$A,"Quantity (units)") -> 797 | D14: =SUMIFS('Source 2026'!$I:$I,'Source 2026'!$B:$B,$A14,'Source 2026'!$A:$A,"Quantity (units)") -> 283 | E14: =D14*$J$5 -> 388.11429 | F14: =E14-C14 -> -408.88571 | G14: =IF(AND(C14=0,E14=0),0,IF(C14=0,"New",(E14-C14)/C14)) -> -0.51303101 | H14: =SUMIFS('Source 2025'!$I:$I,'Source 2025'!$B:$B,$A14,'Source 2025'!$A:$A,"Amount (NIS)") -> 8758.2 | I14: =SUMIFS('Source 2026'!$I:$I,'Source 2026'!$B:$B,$A14,'Source 2026'!$A:$A,"Amount (NIS)") -> 3107.3 | J14: =I14*$J$5 -> 4261.44 | K14: =J14-H14 -> -4496.76 | L14: =IF(AND(H14=0,J14=0),0,IF(H14=0,"New",(J14-H14)/H14)) -> -0.51343427
A15: 4419006 | B15: =IFERROR(INDEX('Source 2026'!$C:$C,MATCH($A15,'Source 2026'!$B:$B,0)),IFERROR(INDEX('Source 2025'!$C:$C,MATCH($A15,'Source 2025'!$B:$B,0)),"")) -> PD340-קוצץ ציפורניים | C15: =SUMIFS('Source 2025'!$I:$I,'Source 2025'!$B:$B,$A15,'Source 2025'!$A:$A,"Quantity (units)") -> 928 | D15: =SUMIFS('Source 2026'!$I:$I,'Source 2026'!$B:$B,$A15,'Source 2026'!$A:$A,"Quantity (units)") -> 514 | E15: =D15*$J$5 -> 704.91429 | F15: =E15-C15 -> -223.08571 | G15: =IF(AND(C15=0,E15=0),0,IF(C15=0,"New",(E15-C15)/C15)) -> -0.24039409 | H15: =SUMIFS('Source 2025'!$I:$I,'Source 2025'!$B:$B,$A15,'Source 2025'!$A:$A,"Amount (NIS)") -> 12205.1 | I15: =SUMIFS('Source 2026'!$I:$I,'Source 2026'!$B:$B,$A15,'Source 2026'!$A:$A,"Amount (NIS)") -> 6760.2 | J15: =I15*$J$5 -> 9271.1314 | K15: =J15-H15 -> -2933.9686 | L15: =IF(AND(H15=0,J15=0),0,IF(H15=0,"New",(J15-H15)/H15)) -> -0.24038874
A16: 4408098 | B16: =IFERROR(INDEX('Source 2026'!$C:$C,MATCH($A16,'Source 2026'!$B:$B,0)),IFERROR(INDEX('Source 2025'!$C:$C,MATCH($A16,'Source 2025'!$B:$B,0)),"")) -> T25-חבק יד אגודלי | C16: =SUMIFS('Source 2025'!$I:$I,'Source 2025'!$B:$B,$A16,'Source 2025'!$A:$A,"Quantity (units)") -> 386 | D16: =SUMIFS('Source 2026'!$I:$I,'Source 2026'!$B:$B,$A16,'Source 2026'!$A:$A,"Quantity (units)") -> 257 | E16: =D16*$J$5 -> 352.45714 | F16: =E16-C16 -> -33.542857 | G16: =IF(AND(C16=0,E16=0),0,IF(C16=0,"New",(E16-C16)/C16)) -> -0.086898594 | H16: =SUMIFS('Source 2025'!$I:$I,'Source 2025'!$B:$B,$A16,'Source 2025'!$A:$A,"Amount (NIS)") -> 15339.9 | I16: =SUMIFS('Source 2026'!$I:$I,'Source 2026'!$B:$B,$A16,'Source 2026'!$A:$A,"Amount (NIS)") -> 10215.3 | J16: =I16*$J$5 -> 14009.554 | K16: =J16-H16 -> -1330.3457 | L16: =IF(AND(H16=0,J16=0),0,IF(H16=0,"New",(J16-H16)/H16)) -> -0.086724536
A17: 4421000 | B17: =IFERROR(INDEX('Source 2026'!$C:$C,MATCH($A17,'Source 2026'!$B:$B,0)),IFERROR(INDEX('Source 2025'!$C:$C,MATCH($A17,'Source 2025'!$B:$B,0)),"")) -> 3655 שרוול מסיליקון לאצבע | C17: =SUMIFS('Source 2025'!$I:$I,'Source 2025'!$B:$B,$A17,'Source 2025'!$A:$A,"Quantity (units)") -> 885 | D17: =SUMIFS('Source 2026'!$I:$I,'Source 2026'!$B:$B,$A17,'Source 2026'!$A:$A,"Quantity (units)") -> 617 | E17: =D17*$J$5 -> 846.17143 | F17: =E17-C17 -> -38.828571 | G17: =IF(AND(C17=0,E17=0),0,IF(C17=0,"New",(E17-C17)/C17)) -> -0.043874092 | H17: =SUMIFS('Source 2025'!$I:$I,'Source 2025'!$B:$B,$A17,'Source 2025'!$A:$A,"Amount (NIS)") -> 14919 | I17: =SUMIFS('Source 2026'!$I:$I,'Source 2026'!$B:$B,$A17,'Source 2026'!$A:$A,"Amount (NIS)") -> 10390.5 | J17: =I17*$J$5 -> 14249.829 | K17: =J17-H17 -> -669.17143 | L17: =IF(AND(H17=0,J17=0),0,IF(H17=0,"New",(J17-H17)/H17)) -> -0.044853638
A18: 4413041 | B18: =IFERROR(INDEX('Source 2026'!$C:$C,MATCH($A18,'Source 2026'!$B:$B,0)),IFERROR(INDEX('Source 2025'!$C:$C,MATCH($A18,'Source 2025'!$B:$B,0)),"")) -> 34 M מגן קרסול עקב סגור | C18: =SUMIFS('Source 2025'!$I:$I,'Source 2025'!$B:$B,$A18,'Source 2025'!$A:$A,"Quantity (units)") -> 201 | D18: =SUMIFS('Source 2026'!$I:$I,'Source 2026'!$B:$B,$A18,'Source 2026'!$A:$A,"Quantity (units)") -> 106 | E18: =D18*$J$5 -> 145.37143 | F18: =E18-C18 -> -55.628571 | G18: =IF(AND(C18=0,E18=0),0,IF(C18=0,"New",(E18-C18)/C18)) -> -0.27675906 | H18: =SUMIFS('Source 2025'!$I:$I,'Source 2025'!$B:$B,$A18,'Source 2025'!$A:$A,"Amount (NIS)") -> 8140.5 | I18: =SUMIFS('Source 2026'!$I:$I,'Source 2026'!$B:$B,$A18,'Source 2026'!$A:$A,"Amount (NIS)") -> 4293 | J18: =I18*$J$5 -> 5887.5429 | K18: =J18-H18 -> -2252.9571 | L18: =IF(AND(H18=0,J18=0),0,IF(H18=0,"New",(J18-H18)/H18)) -> -0.27675906
A19: 4409014 | B19: =IFERROR(INDEX('Source 2026'!$C:$C,MATCH($A19,'Source 2026'!$B:$B,0)),IFERROR(INDEX('Source 2025'!$C:$C,MATCH($A19,'Source 2025'!$B:$B,0)),"")) -> 808KT-P טייפ קינזיולוגי | C19: =SUMIFS('Source 2025'!$I:$I,'Source 2025'!$B:$B,$A19,'Source 2025'!$A:$A,"Quantity (units)") -> 256 | D19: =SUMIFS('Source 2026'!$I:$I,'Source 2026'!$B:$B,$A19,'Source 2026'!$A:$A,"Quantity (units)") -> 173 | E19: =D19*$J$5 -> 237.25714 | F19: =E19-C19 -> -18.742857 | G19: =IF(AND(C19=0,E19=0),0,IF(C19=0,"New",(E19-C19)/C19)) -> -0.073214286 | H19: =SUMIFS('Source 2025'!$I:$I,'Source 2025'!$B:$B,$A19,'Source 2025'!$A:$A,"Amount (NIS)") -> 11284.5 | I19: =SUMIFS('Source 2026'!$I:$I,'Source 2026'!$B:$B,$A19,'Source 2026'!$A:$A,"Amount (NIS)") -> 7625.8 | J19: =I19*$J$5 -> 10458.24 | K19: =J19-H19 -> -826.26 | L19: =IF(AND(H19=0,J19=0),0,IF(H19=0,"New",(J19-H19)/H19)) -> -0.07322079
A20: 4413136 | B20: =IFERROR(INDEX('Source 2026'!$C:$C,MATCH($A20,'Source 2026'!$B:$B,0)),IFERROR(INDEX('Source 2025'!$C:$C,MATCH($A20,'Source 2025'!$B:$B,0)),"")) -> 85 M (מתלה ליד )כיס | C20: =SUMIFS('Source 2025'!$I:$I,'Source 2025'!$B:$B,$A20,'Source 2025'!$A:$A,"Quantity (units)") -> 193 | D20: =SUMIFS('Source 2026'!$I:$I,'Source 2026'!$B:$B,$A20,'Source 2026'!$A:$A,"Quantity (units)") -> 124 | E20: =D20*$J$5 -> 170.05714 | F20: =E20-C20 -> -22.942857 | G20: =IF(AND(C20=0,E20=0),0,IF(C20=0,"New",(E20-C20)/C20)) -> -0.11887491 | H20: =SUMIFS('Source 2025'!$I:$I,'Source 2025'!$B:$B,$A20,'Source 2025'!$A:$A,"Amount (NIS)") -> 10096.7 | I20: =SUMIFS('Source 2026'!$I:$I,'Source 2026'!$B:$B,$A20,'Source 2026'!$A:$A,"Amount (NIS)") -> 6530 | J20: =I20*$J$5 -> 8955.4286 | K20: =J20-H20 -> -1141.2714 | L20: =IF(AND(H20=0,J20=0),0,IF(H20=0,"New",(J20-H20)/H20)) -> -0.1130341
... A354: 4413368 | B354: =IFERROR(INDEX('Source 2026'!$C:$C,MATCH($A354,'Source 2026'!$B:$B,0)),IFERROR(INDEX('Source 2025'!$C:$C,MATCH($A354,'Source 2025'!$B:$B,0)),"")) -> 95C XS'מגן מרפק בז | C354: =SUMIFS('Source 2025'!$I:$I,'Source 2025'!$B:$B,$A354,'Source 2025'!$A:$A,"Quantity (units)") -> 44 | D354: =SUMIFS('Source 2026'!$I:$I,'Source 2026'!$B:$B,$A354,'Source 2026'!$A:$A,"Quantity (units)") -> 44 | E354: =D354*$J$5 -> 60.342857 | F354: =E354-C354 -> 16.342857 | G354: =IF(AND(C354=0,E354=0),0,IF(C354=0,"New",(E354-C354)/C354)) -> 0.37142857 | H354: =SUMIFS('Source 2025'!$I:$I,'Source 2025'!$B:$B,$A354,'Source 2025'!$A:$A,"Amount (NIS)") -> 1221.4 | I354: =SUMIFS('Source 2026'!$I:$I,'Source 2026'!$B:$B,$A354,'Source 2026'!$A:$A,"Amount (NIS)") -> 1221.4 | J354: =I354*$J$5 -> 1675.0629 | K354: =J354-H354 -> 453.66286 | L354: =IF(AND(H354=0,J354=0),0,IF(H354=0,"New",(J354-H354)/H354)) -> 0.37142857
