Workbook

Sheet גיליון1
A1: מוצרים חדשים - התאמת כמות/כסף 2026 בפועל (YTD) לפי ערוץ מכירה - גרסה סופית (כל 5 אי-הוודאויות הוכרעו ע"י המשתמש)
A2: תאריך חישוב: | B2: 46290
A3: תיקון (25/09/2026): בגרסה הקודמת נעשה שימוש בקוד CHEMIPAL המספרי (כמו 4411030) כמפתח חיפוש עבור דגמים שהותאמו דרך TRANS/הקטלוג (213 CTS, SH422, 397A, SH333) - זה תפס נכון מול 5 גיליונות CEMIUP0.9 (שם עמודת הקוד היא באמת הקוד המספרי), אבל פספס לגמרי את 29 גיליונות ה-SALES הישירים (שם עמודת "Product Code" מכילה את הקוד הטקסטואלי הגולמי כמו "213CTSR L", לא את הקוד המספרי) - בעיית אי-התאמת סוג-מפתח, לא בדיוק בעיית רווחים כפי שהועלתה. התיקון: סריקה חדשה לגמרי שמחפשת את קידומת-הבסיס הטקסטואלית (עם נרמול רווחים/מקפים/פלוס) ישירות מול עמודת הקוד הגולמית + שם המוצר בכל 34 המקורות (5 CEMIUP0.9 + 29 SALES, ללא 107/113 שכבר כלולות בתוך בתי מרקחת/מאוחדת - מניעת כפל ספירה). כמות/כסף = 2026 בפועל עד היום (YTD), לא מנורמל. כאשר דגם כלל וריאנטים (מידות/צדדים) - מסוכם לכל ערוץ. שורות בצבע אדום = התאמה לא-ודאית (T40B "רצועה לפיקה" - קוד דומה בלבד, סומן ולא הוכרע). עדכון 26/09/2026: כל 5 אי-הוודאויות שעלו בסריקה המורחבת (59 / 3051 x3 / MSG001F 0 / cervical collar) הוכרעו במפורש ע"י המשתמש ועודכנו בטבלה הראשית: "59", "3051" (×3) ו-"cervical collar" נקבעו כ-0 יחידות/NA (לא אותו מוצר, לא מוזג); "MSG001F 0" מוזג כעת מכל 3 גווני הצבע (שחור/קרם/לבן) יחד לשורה אחת מאוחדת, כולל שורת הזיכוי השלילית בגוון הלבן כפי שהיא בנתונים.
A5: # | B5: דגם (מקור) | C5: ערוץ מכירה | D5: כמות 2026 (בפועל, YTD) | E5: כסף 2026 (בפועל, YTD, ₪) | F5: # וריאנטים ממוזגים | G5: הערה
A6: 1 | B6: 213 CTS | C6: 114 - IL online | D6: 337 | E6: 66538.17 | F6: 6
A7: 1 | B7: 213 CTS | C7: 203 - Ortho-Partner SWITZERLAND | D7: 200 | E7: 7216.87 | F7: 6
A8: 1 | B8: 213 CTS | C8: סופר פארם | D8: 188 | E8: 17187.81 | F8: 6
A9: 1 | B9: 213 CTS | C9: 209 - Ortoprofil Prod ROMANIA | D9: 178 | E9: 7746.15 | F9: 6
A10: 1 | B10: 213 CTS | C10: 216 - Max Konnaris CYPRUS | D10: 100 | E10: 4317.2 | F10: 6
A11: 1 | B11: 213 CTS | C11: מאוחדת | D11: 53 | E11: 3424.33 | F11: 6
A12: 1 | B12: 213 CTS | C12: 102 - Orthopedic institutes | D12: 44 | E12: 3960.01 | F12: 6
A13: 1 | B13: 213 CTS | C13: 214 - Alfred Gera Sons MALTA | D13: 14 | E13: 578.88 | F13: 6
A14: 1 | B14: 213 CTS | C14: בתי מרקחת | D14: 8 | E14: 852.67 | F14: 6
A15: 1 | B15: 213 CTS | C15: 103 - Physiotherapy institutes | D15: 8 | E15: 882.78 | F15: 6
A16: 1 | B16: 213 CTS | C16: 101 - Factory customers | D16: 3 | E16: 47.64 | F16: 6
A17: 1 | B17: 213 CTS | C17: 204 - Sanaflex Anatomic GREECE | D17: 2 | E17: 0.06 | F17: 2
B18: -- סה"כ 213 CTS -- | D18: 1135 | E18: 112752.57
A19: 2 | B19: SH422 | C19: סופר פארם | D19: 149 | E19: 24472.72 | F19: 6
A20: 2 | B20: SH422 | C20: בתי מרקחת | D20: 137 | E20: 24853.25 | F20: 6
A21: 2 | B21: SH422 | C21: 102 - Orthopedic institutes | D21: 135 | E21: 15120.04 | F21: 6
A22: 2 | B22: SH422 | C22: 203 - Ortho-Partner SWITZERLAND | D22: 122 | E22: 9832.38 | F22: 6
A23: 2 | B23: SH422 | C23: מאוחדת | D23: 97 | E23: 11033.75 | F23: 5
A24: 2 | B24: SH422 | C24: 114 - IL online | D24: 78 | E24: 27763.17 | F24: 6
A25: 2 | B25: SH422 | C25: 216 - Max Konnaris CYPRUS | D25: 70 | E25: 6892.81 | F25: 5
A26: 2 | B26: SH422 | C26: 103 - Physiotherapy institutes | D26: 33 | E26: 3570.9 | F26: 6
A27: 2 | B27: SH422 | C27: 210 - Oy. Ea. Ab. FINLAND | D27: 30 | E27: 2674.35 | F27: 5
A28: 2 | B28: SH422 | C28: 101 - Factory customers | D28: 10 | E28: 1742.17 | F28: 6
A29: 2 | B29: SH422 | C29: 204 - Sanaflex Anatomic GREECE | D29: 1 | E29: 0.03 | F29: 1
B30: -- סה"כ SH422 -- | D30: 862 | E30: 127955.57
A31: 3 | B31: 397A | C31: 202 - Super-Pharm POLAND | D31: 1570 | E31: 46938.98 | F31: 3
A32: 3 | B32: 397A | C32: סופר פארם | D32: 1552 | E32: 77132.51 | F32: 3
A33: 3 | B33: 397A | C33: 114 - IL online | D33: 1052 | E33: 109316.76 | F33: 3
A34: 3 | B34: 397A | C34: בתי מרקחת | D34: 544 | E34: 30153.11 | F34: 3
A35: 3 | B35: 397A | C35: מאוחדת | D35: 411 | E35: 15276.06 | F35: 3
A36: 3 | B36: 397A | C36: 201- Seven Gear FINLAND oy | D36: 370 | E36: 10606.85 | F36: 3
A37: 3 | B37: 397A | C37: 102 - Orthopedic institutes | D37: 159 | E37: 9944.26 | F37: 3
A38: 3 | B38: 397A | C38: 216 - Max Konnaris CYPRUS | D38: 80 | E38: 2291.18 | F38: 3
A39: 3 | B39: 397A | C39: 101 - Factory customers | D39: 48 | E39: 2982.65 | F39: 3
A40: 3 | B40: 397A | C40: 109 - Private Shops | D40: 19 | E40: 1074.92 | F40: 3
A41: 3 | B41: 397A | C41: 301 - Amazon | D41: 13 | E41: 727.07 | F41: 3
...

Sheet Plan vs Actual
A1: Plan vs Actual - תוכנית 2026 מול ביצוע בפועל (YTD) למוצרים חדשים
X2: דודו | Y2: 26 | Z2: 2 | AA2: 3 | AB2: 70 | AC2: =SUM(Y2:AB2) -> 101
X3: חיים | Y3: 14 | Z3: 1 | AA3: 5 | AB3: 59 | AC3: =SUM(Y3:AB3) -> 79 | AI3: תוספת | AJ3: =AJ7-AJ5 -> 941750 | AK3: =AK7-AK5 -> 199916 | AL3: =AL7-AL5 -> 2518537.7 | AM3: =SUBTOTAL(9,AJ3:AL3) -> 3660203.7
X4: סטאס | Y4: 17 | Z4: 5 | AA4: 2 | AB4: 63 | AC4: =SUM(Y4:AB4) -> 87
A5: תאריך חישוב: | B5: 46290 | X5: חזאם | Y5: 27 | Z5: 12 | AA5: 5 | AB5: 211 | AC5: =SUM(Y5:AB5) -> 255 | AI5: תקציב | AJ5: 356500 | AK5: 100000 | AL5: 439462.35 | AM5: =SUBTOTAL(9,AJ5:AL5) -> 895962.35
A6: אזהרה מתודולוגית חשובה: עמודות התוכנית (C-F) הן יעד ל-2026 המלאה (12 חודשים). עמודות הבפועל (G-I) הן YTD חלקי בלבד (כפי שמחושב בגיליון "גיליון1" - מבוסס על ~9.5 חודשי נתונים בפועל, לא מנורמל לשנה מלאה כאן בכוונה, כדי להשוות "מה כבר נמכר בפועל" מול "היעד השנתי" ישירות). % הביצוע (K-L) הוא לכן ביחס ליעד שנתי מלא בעוד שהמונה הוא רק חלק מהשנה - לכן % נמוך (למשל 30-60%) בשלב הזה של השנה אינו בהכרח "פיגור", אלא צפוי אם קצב המכירות המנורמל עדיין תואם/עולה על היעד. T40B ו-3051 מופיעים כל אחד 2-3 פעמים ברשימת המקור (מופעים נפרדים עם ערוצי-יעד שונים) - ה-actual זהה בשני מופעי T40B (הנתון הגולמי לא ניתן לפיצול בין המופעים) ולכן בשורת הסה"כ הכללי בתחתית, ה-actual של T40B נספר פעם אחת בלבד (לא כפול) כדי לא לנפח את הביצוע בפועל - הפלאן עדיין מסוכם משני המופעים כפי שהם. 3051 = 0 בפועל בכל 3 המופעים (הוכרע ע"י המשתמש כמוצר לא-זהה) - לא רלוונטי לכפל.
C7: 10780 | N7: 2027 | O7: Orthopedic institutes | X7: סה"כ | Y7: =SUBTOTAL(9,Y2:Y5) -> 84 | Z7: =SUBTOTAL(9,Z2:Z5) -> 20 | AA7: =SUBTOTAL(9,AA2:AA5) -> 15 | AB7: =SUBTOTAL(9,AB2:AB5) -> 403 | AC7: =SUM(Y7:AB7) -> 522 | AF7: =SUM(AF9:AF32) -> 35557.5 | AG7: =SUM(AG9:AG32) -> 4556166 | AI7: חדש | AJ7: =SUM(AJ9:AJ32) -> 1298250 | AK7: =SUM(AK9:AK32) -> 299916 | AL7: =SUM(AL9:AL32) -> 2958000 | AM7: =SUBTOTAL(9,AJ7:AL7) -> 4556166
A8: # | B8: דגם | C8: כמות מתוכננת (שנתי) | D8: מחיר ליח' (₪) | E8: מכירות מתוכננות (שנתי, ₪) | F8: ערוץ מתוכנן | G8: כמות בפועל (YTD) | H8: כסף בפועל (YTD, ₪) | I8: ערוץ מוביל בפועל (Top Source) | J8: ערוץ תואם? | K8: % ביצוע כמות (YTD/יעד שנתי) | L8: % ביצוע כסף (YTD/יעד שנתי) | M8: הערות | N8: Units | O8: Amount | Q8: חנה | R8: חודשים | S8: מחיר מטרה | T8: סה"כ | W8: חודשים | X8: הזמנה | Y8: אורט | Z8: פיזט | AA8: פרטיים | AB8: בתי מרקחת | AC8: חנויות סה"כ | AD8: יחידות סה"כ | AE8: גלגול | AF8: סה"כ יחידות | AG8: כסף סה"כ | AJ8: אורט | AK8: פיזט | AL8: בתי מרקחת
A9: 1 | B9: 213 CTS | C9: 2160 | D9: 90 | E9: 194400 | F9: מכוני אורטופדיה | G9: 1135 | H9: 112752.57 | I9: 114 - IL online | J9: שונה | K9: 0.52546296 | L9: 0.58000293 | N9: 500 | O9: =N9*D9 -> 45000 | Q9: 300 | R9: 12 | S9: 90 | T9: =S9*Q9 -> 27000 | U9: גיבוי | W9: =R9 -> 12 | X9: 4 | Y9: 75 | Z9: 18 | AB9: 300 | AC9: =SUM(Y9:AB9) -> 393 | AD9: =(AC9*X9) -> 1572 | AE9: 4 | AF9: =AE9*AD9 -> 6288 | AG9: =AF9*S9 -> 565920 | AJ9: =Y9*X9*AE9*S9 -> 108000 | AK9: =Z9*X9*AE9*S9 -> 25920 | AL9: =AB9*AE9*X9*S9 -> 432000
A10: 2 | B10: SH422 | C10: 2880 | D10: 100 | E10: 288000 | F10: מכוני אורטופדיה | G10: 862 | H10: 127955.57 | I10: סופר פארם | J10: שונה | K10: 0.29930556 | L10: 0.44429017 | N10: 500 | O10: =N10*D10 -> 50000 | Q10: 400 | R10: 12 | S10: 100 | T10: =S10*Q10 -> 40000 | W10: =R10 -> 12 | X10: 3 | Y10: 75 | Z10: 18 | AB10: 300 | AC10: =SUM(Y10:AB10) -> 393 | AD10: =(AC10*X10) -> 1179 | AE10: 4 | AF10: =AE10*AD10 -> 4716 | AG10: =AF10*S10 -> 471600 | AJ10: =Y10*X10*AE10*S10 -> 90000 | AK10: =Z10*X10*AE10*S10 -> 21600 | AL10: =AB10*AE10*X10*S10 -> 360000
A11: 3 | B11: 397A | C11: 2000 | D11: 50 | E11: 100000 | F11: סופרפארם | G11: 5823 | H11: 306760.51 | I11: 202 - Super-Pharm POLAND | J11: שונה | K11: 2.9115 | L11: 3.0676051 | M11: כמעט תיקו מול סופר פארם ישראל (1552, הפרש 18 יח' בלבד) | W11: 12
A12: 4 | B12: SH333 | C12: 1000 | D12: 70 | E12: 70000 | F12: מכוני אורטופדיה | G12: 131 | H12: 13889.9 | I12: סופר פארם | J12: שונה | K12: 0.131 | L12: 0.19842714 | N12: 300 | O12: =N12*D12 -> 21000 | Q12: 300 | R12: 12 | S12: 40 | T12: =S12*Q12 -> 12000 | W12: =R12 -> 12 | X12: 3 | Y12: 75 | Z12: 18 | AC12: =SUM(Y12:AB12) -> 93 | AD12: =(AC12*X12) -> 279 | AE12: 4 | AF12: =AE12*AD12 -> 1116 | AG12: =AF12*S12 -> 44640 | AJ12: =Y12*X12*AE12*S12 -> 36000 | AK12: =Z12*X12*AE12*S12 -> 8640 | AL12: =AB12*AE12*X12*S12 -> 0
A13: 5 | B13: SH776 | C13: 220 | D13: 350 | E13: 77000 | F13: מכוני אורטופדיה | G13: 103 | H13: 40501.05 | I13: 102 - Orthopedic institutes | J13: תואם | K13: 0.46818182 | L13: 0.52598766 | N13: 200 | O13: =N13*D13 -> 70000 | Q13: 200 | R13: 12 | S13: 300 | T13: =S13*Q13 -> 60000 | W13: =R13 -> 12 | X13: 3 | Y13: 75 | Z13: 18 | AB13: 300 | AC13: =SUM(Y13:AB13) -> 393 | AD13: =(AC13*X13) -> 1179 | AE13: 4 | AF13: =AE13*AD13 -> 4716 | AG13: =AF13*S13 -> 1414800 | AJ13: =Y13*X13*AE13*S13 -> 270000 | AK13: =Z13*X13*AE13*S13 -> 64800 | AL13: =AB13*AE13*X13*S13 -> 1080000
A14: 6 | B14: SH322 | C14: 280 | D14: 70 | E14: 19600 | F14: מכוני אורטופדיה | G14: 1 | H14: 0.03 | I14: 207 - Salus HUNGARY | J14: שונה | K14: 0.0035714286 | L14: 1.5306122e-06 | N14: 200 | O14: =N14*D14 -> 14000 | Q14: 300 | R14: 12 | S14: 70 | T14: =S14*Q14 -> 21000 | W14: =R14 -> 12 | X14: 3 | Y14: 75 | Z14: 18 | AB14: 300 | AC14: =SUM(Y14:AB14) -> 393 | AD14: =(AC14*X14) -> 1179 | AE14: 4 | AF14: =AE14*AD14 -> 4716 | AG14: =AF14*S14 -> 330120 | AJ14: =Y14*X14*AE14*S14 -> 63000 | AK14: =Z14*X14*AE14*S14 -> 15120 | AL14: =AB14*AE14*X14*S14 -> 252000
A15: 7 | B15: SH922 | C15: 280 | D15: 80 | E15: 22400 | F15: מכוני אורטופדיה | G15: 0 | H15: 0 | I15: NA (0 בפועל) | J15: אין בפועל (0%) | K15: 0 | L15: 0 | N15: 200 | O15: =N15*D15 -> 16000 | Q15: 150 | R15: 6 | S15: 80 | T15: =S15*Q15 -> 12000 | W15: =R15 -> 6 | X15: 3 | Y15: 75 | Z15: 18 | AB15: 300 | AC15: =SUM(Y15:AB15) -> 393 | AD15: =(AC15*X15) -> 1179 | AE15: 2 | AF15: =AE15*AD15 -> 2358 | AG15: =AF15*S15 -> 188640 | AJ15: =Y15*X15*AE15*S15 -> 36000 | AK15: =Z15*X15*AE15*S15 -> 8640 | AL15: =AB15*AE15*X15*S15 -> 144000
A16: 8 | B16: SH423 | C16: 200 | D16: 260 | E16: 52000 | F16: מכוני אורטופדיה | G16: 1 | H16: 0.03 | I16: 207 - Salus HUNGARY | J16: שונה | K16: 0.005 | L16: 5.7692308e-07 | N16: 200 | O16: =N16*D16 -> 52000 | Q16: 200 | R16: 10 | S16: 260 | T16: =S16*Q16 -> 52000 | W16: =R16 -> 10 | X16: 4 | Y16: 75 | Z16: 18 | AC16: =SUM(Y16:AB16) -> 93 | AD16: =(AC16*X16) -> 372 | AE16: 3 | AF16: =AE16*AD16 -> 1116 | AG16: =AF16*S16 -> 290160 | AJ16: =Y16*X16*AE16*S16 -> 234000 | AK16: =Z16*X16*AE16*S16 -> 56160 | AL16: =AB16*AE16*X16*S16 -> 0
A17: 9 | B17: 364 xl+ | C17: 1000 | D17: 24 | E17: 24000 | F17: בתי מרקחת | G17: 6 | H17: 50.25 | I17: 103 - Physiotherapy institutes | J17: שונה | K17: 0.006 | L17: 0.00209375 | W17: 12
A18: 10 | B18: SC34+ | C18: — | D18: 130 | E18: 0 | F18: סופרפארם | G18: 0 | H18: 0 | I18: NA (0 בפועל) | J18: אין בפועל (0%) | K18: — | L18: — | W18: 12
A19: 11 | B19: 809PW | C19: 2000 | D19: 12 | E19: 24000 | F19: מכוני אורטופדיה | G19: 16 | H19: 170.2 | I19: 103 - Physiotherapy institutes | J19: שונה | K19: 0.008 | L19: 0.0070916667 | N19: 1000 | O19: =N19*D19 -> 12000 | Q19: 500 | R19: 12 | S19: 10.5 | T19: =S19*Q19 -> 5250 | W19: =R19 -> 12 | X19: 6 | Z19: 18 | AC19: =SUM(Y19:AB19) -> 18 | AD19: =(AC19*X19) -> 108 | AE19: 4 | AF19: =AE19*AD19 -> 432 | AG19: =AF19*S19 -> 4536 | AJ19: =Y19*X19*AE19*S19 -> 0 | AK19: =Z19*X19*AE19*S19 -> 4536 | AL19: =AB19*AE19*X19*S19 -> 0
A20: 12 | B20: 59 | C20: 500 | D20: 150 | E20: 75000 | F20: — | G20: 0 | H20: 0 | I20: NA (0 בפועל) | J20: אין ערוץ מתוכנן | K20: 0 | L20: 0
A21: 13 | B21: T40B (מופע 1) | C21: 1000 | D21: 60.61 | E21: 60606 | F21: סופרפארם | G21: 51 | H21: 4794.24 | I21: 114 - IL online | J21: שונה | K21: 0.051 | L21: 0.079105039 | M21: כולל 8 יח'/588.13 ש"ח משורה לא-ודאית ("T40B רצועה לפיקה")
A22: 14 | B22: T40B (מופע 2) | C22: 300 | D22: 70 | E22: 21000 | F22: מכוני אורטופדיה | G22: 51 | H22: 4794.24 | I22: 114 - IL online | J22: שונה | K22: 0.17 | L22: 0.22829714 | M22: כולל 8 יח'/588.13 ש"ח משורה לא-ודאית ("T40B רצועה לפיקה") | O22: =N22*D22 -> 0 | Q22: 300 | R22: 12 | S22: 70 | T22: =S22*Q22 -> 21000 | W22: =R22 -> 12 | X22: 1 | Y22: 75 | Z22: 18 | AB22: 300 | AC22: =SUM(Y22:AB22) -> 393 | AD22: =(AC22*X22) -> 393 | AE22: 4 | AF22: =AE22*AD22 -> 1572 | AG22: =AF22*S22 -> 110040 | AJ22: =Y22*X22*AE22*S22 -> 21000 | AK22: =Z22*X22*AE22*S22 -> 5040 | AL22: =AB22*AE22*X22*S22 -> 84000
A23: 15 | B23: T066 | C23: 300 | D23: 140 | E23: 42000 | F23: מכוני אורטופדיה | G23: 6 | H23: 568.6 | I23: 103 - Physiotherapy institutes | J23: שונה | K23: 0.02 | L23: 0.013538095 | N23: 200 | O23: =N23*D23 -> 28000 | Q23: 300 | R23: 12 | S23: 140 | T23: =S23*Q23 -> 42000 | W23: =R23 -> 12 | X23: 2 | Y23: 75 | Z23: 18 | AB23: 300 | AC23: =SUM(Y23:AB23) -> 393 | AD23: =(AC23*X23) -> 786 | AE23: 4 | AF23: =AE23*AD23 -> 3144 | AG23: =AF23*S23 -> 440160 | AJ23: =Y23*X23*AE23*S23 -> 84000 | AK23: =Z23*X23*AE23*S23 -> 20160 | AL23: =AB23*AE23*X23*S23 -> 336000
A24: 16 | B24: 3051 (מופע 1) | C24: 500 | D24: 75 | E24: 37500 | F24: סופרפארם | G24: 0 | H24: 0 | I24: NA (0 בפועל) | J24: אין בפועל (0%) | K24: 0 | L24: 0 | W24: 12
A25: 17 | B25: 3051 (מופע 2) | C25: 300 | D25: 75 | E25: 22500 | F25: מכוני אורטופדיה | G25: 0 | H25: 0 | I25: NA (0 בפועל) | J25: אין בפועל (0%) | K25: 0 | L25: 0 | N25: 300 | O25: =N25*D25 -> 22500 | Q25: 200 | R25: 9 | S25: 75 | T25: =S25*Q25 -> 15000 | W25: =R25 -> 9 | X25: 4 | Y25: 75 | AB25: 300 | AC25: =SUM(Y25:AB25) -> 375 | AD25: =(AC25*X25) -> 1500 | AE25: 3 | AF25: =AE25*AD25 -> 4500 | AG25: =AF25*S25 -> 337500 | AJ25: =Y25*X25*AE25*S25 -> 67500 | AK25: =Z25*X25*AE25*S25 -> 0 | AL25: =AB25*AE25*X25*S25 -> 270000
A26: 18 | B26: 3051 (מופע 3) | C26: 200 | D26: 75 | E26: 15000 | F26: בתי מרקחת | G26: 0 | H26: 0 | I26: NA (0 בפועל) | J26: אין בפועל (0%) | K26: 0 | L26: 0 | W26: 12
A27: 19 | B27: MSG001F 0 | C27: 100 | D27: 550 | E27: 55000 | F27: מכוני אורטופדיה | G27: 46 | H27: 37922.88 | I27: 114 - IL online | J27: שונה | K27: 0.46 | L27: 0.68950691 | N27: 50 | O27: =N27*D27 -> 27500 | S27: 550 | T27: =S27*Q27 -> 0 | U27: גיבוי | W27: 12 | X27: 1 | Y27: 75 | Z27: 18 | AC27: =SUM(Y27:AB27) -> 93 | AD27: =(AC27*X27) -> 93 | AE27: 2 | AF27: =AE27*AD27 -> 186 | AG27: =AF27*S27 -> 102300 | AJ27: =Y27*X27*AE27*S27 -> 82500 | AK27: =Z27*X27*AE27*S27 -> 19800 | AL27: =AB27*AE27*X27*S27 -> 0
A28: 20 | B28: MSG002S 0 | C28: 100 | D28: 550 | E28: 55000 | F28: מכוני אורטופדיה | G28: 30 | H28: 21838.24 | I28: 114 - IL online | J28: שונה | K28: 0.3 | L28: 0.39705891 | N28: 50 | O28: =N28*D28 -> 27500 | S28: 550 | T28: =S28*Q28 -> 0 | U28: גיבוי | W28: 12 | X28: 1 | Y28: 75 | Z28: 18 | AC28: =SUM(Y28:AB28) -> 93 | AD28: =(AC28*X28) -> 93 | AE28: 2 | AF28: =AE28*AD28 -> 186 | AG28: =AF28*S28 -> 102300 | AJ28: =Y28*X28*AE28*S28 -> 82500 | AK28: =Z28*X28*AE28*S28 -> 19800 | AL28: =AB28*AE28*X28*S28 -> 0
A29: 21 | B29: T-scoop רגל | C29: 200 | D29: 265 | E29: 53000 | F29: מכוני אורטופדיה | G29: 0 | H29: 0 | I29: NA (0 בפועל) | J29: אין בפועל (0%) | K29: 0 | L29: 0 | N29: 100 | O29: =N29*D29 -> 26500 | S29: 265 | T29: =S29*Q29 -> 0 | W29: 3 | X29: 1 | Y29: 75 | Z29: 18 | AC29: =SUM(Y29:AB29) -> 93 | AD29: =(AC29*X29) -> 93 | AE29: 2 | AF29: =AE29*AD29 -> 186 | AG29: =AF29*S29 -> 49290 | AJ29: =Y29*X29*AE29*S29 -> 39750 | AK29: =Z29*X29*AE29*S29 -> 9540 | AL29: =AB29*AE29*X29*S29 -> 0
A30: 22 | B30: T-scoop יד | C30: 50 | D30: 350 | E30: 17500 | F30: מכוני אורטופדיה | G30: 0 | H30: 0 | I30: NA (0 בפועל) | J30: אין בפועל (0%) | K30: 0 | L30: 0 | N30: 50 | O30: =N30*D30 -> 17500 | Q30: 50 | R30: 3 | S30: 265 | T30: =S30*Q30 -> 13250 | W30: 0 | X30: 0 | Y30: 0 | Z30: 0 | AC30: =SUM(Y30:AB30) -> 0 | AD30: =(AC30*X30) -> 0 | AE30: 2 | AF30: =AE30*AD30 -> 0 | AG30: =AF30*S30 -> 0 | AJ30: =Y30*X30*AE30*S30 -> 0 | AK30: =Z30*X30*AE30*S30 -> 0 | AL30: =AB30*AE30*X30*S30 -> 0
A31: 23 | B31: חגורת Jewett | C31: 60 | D31: 440 | E31: 26400 | F31: מכוני אורטופדיה | G31: 0 | H31: 0 | I31: NA (0 בפועל) | J31: אין בפועל (0%) | K31: 0 | L31: 0 | N31: 50 | O31: =N31*D31 -> 22000 | Q31: 60 | R31: 12 | S31: 440 | T31: =S31*Q31 -> 26400 | W31: =R31 -> 12 | X31: 1 | Y31: 75 | Z31: 18 | AC31: =SUM(Y31:AB31) -> 93 | AD31: =(AC31*X31) -> 93 | AE31: 2 | AF31: =AE31*AD31 -> 186 | AG31: =AF31*S31 -> 81840 | AJ31: =Y31*X31*AE31*S31 -> 66000 | AK31: =Z31*X31*AE31*S31 -> 15840 | AL31: =AB31*AE31*X31*S31 -> 0
A32: 24 | B32: מגף (ווקר) | C32: 350 | D32: 160 | E32: 56000 | F32: מכוני אורטופדיה | G32: 0 | H32: 0 | I32: NA (0 בפועל) | J32: אין בפועל (0%) | K32: 0 | L32: 0 | N32: 50 | O32: =N32*D32 -> 8000 | Q32: 60 | R32: 4 | S32: 160 | T32: =S32*Q32 -> 9600 | W32: =R32 -> 4 | X32: 1 | Y32: 75 | Z32: 18 | AC32: =SUM(Y32:AB32) -> 93 | AD32: =(AC32*X32) -> 93 | AE32: 1.5 | AF32: =AE32*AD32 -> 139.5 | AG32: =AF32*S32 -> 22320 | AJ32: =Y32*X32*AE32*S32 -> 18000 | AK32: =Z32*X32*AE32*S32 -> 4320 | AL32: =AB32*AE32*X32*S32 -> 0
A33: 25 | B33: cervical collar | C33: — | D33: — | E33: 0 | F33: — | G33: 0 | H33: 0 | I33: NA (0 בפועל) | J33: אין ערוץ מתוכנן | K33: — | L33: —
A34: 26 | B34: Miami brace | C34: — | D34: — | E34: — | F34: — | G34: 0 | H34: 0 | I34: NA (0 בפועל) | J34: אין ערוץ מתוכנן | K34: — | L34: —
A35: 27 | B35: T46B | C35: 300 | D35: 65 | E35: 19500 | F35: סופרפארם | G35: 7 | H35: 406.05 | I35: 103 - Physiotherapy institutes | J35: שונה | K35: 0.023333333 | L35: 0.020823077
A36: 28 | B36: T36B | C36: 100 | D36: 75 | E36: 7500 | F36: בתי מרקחת | G36: 2 | H36: 0.04 | I36: 101-Factory customers / 207-Salus HUNGARY (תיקו) | J36: שונה | K36: 0.02 | L36: 5.3333333e-06 | M36: תיקו בין 2 ערוצים - 1 יח' כל אחד, אין ערוץ מוביל יחיד
O37: =N37*D37 -> 0
B38: -- סה"כ (כל 28 שורות התוכנית, plan ללא כפל) -- | C38: 16380 | E38: 1434906 | G38: 8271 | H38: 672404.4 | L38: 0.46860519 | N38: =SUBTOTAL(9,N9:N37) -> 3950 | O38: =SUBTOTAL(9,O9:O37) -> 459500
B39: -- סה"כ מתוקן (T40B נספר פעם אחת - לא כפול) -- | C39: 16380 | E39: 1434906 | G39: 8220 | H39: 667610.16 | K39: 0.5018315 | L39: 0.46526404
N40: =SUBTOTAL(9,N9:N38) -> 3950 | O40: =SUBTOTAL(9,O9:O38) -> 459500 | Q40: =SUBTOTAL(9,Q9:Q38) -> 3320 | T40: =SUBTOTAL(9,T9:T38) -> 356500
...

Sheet Plan vs Actual (סוכן)
A1: Plan vs Actual - תוכנית 2026 מול ביצוע בפועל (YTD) למוצרים חדשים
F2: דודו | G2: 26 | H2: 2 | I2: 70 | J2: =SUM(G2:I2) -> 98
F3: חיים | G3: 14 | H3: 1 | I3: 59 | J3: =SUM(G3:I3) -> 74
F4: סטאס | G4: 17 | H4: 5 | I4: 63 | J4: =SUM(G4:I4) -> 85
A5: תאריך חישוב: | B5: 46290 | F5: חזאם | G5: 27 | H5: 12 | I5: 211 | J5: =SUM(G5:I5) -> 250
A6: אזהרה מתודולוגית חשובה: עמודות התוכנית (C-F) הן יעד ל-2026 המלאה (12 חודשים). עמודות הבפועל (G-I) הן YTD חלקי בלבד (כפי שמחושב בגיליון "גיליון1" - מבוסס על ~9.5 חודשי נתונים בפועל, לא מנורמל לשנה מלאה כאן בכוונה, כדי להשוות "מה כבר נמכר בפועל" מול "היעד השנתי" ישירות). % הביצוע (K-L) הוא לכן ביחס ליעד שנתי מלא בעוד שהמונה הוא רק חלק מהשנה - לכן % נמוך (למשל 30-60%) בשלב הזה של השנה אינו בהכרח "פיגור", אלא צפוי אם קצב המכירות המנורמל עדיין תואם/עולה על היעד. T40B ו-3051 מופיעים כל אחד 2-3 פעמים ברשימת המקור (מופעים נפרדים עם ערוצי-יעד שונים) - ה-actual זהה בשני מופעי T40B (הנתון הגולמי לא ניתן לפיצול בין המופעים) ולכן בשורת הסה"כ הכללי בתחתית, ה-actual של T40B נספר פעם אחת בלבד (לא כפול) כדי לא לנפח את הביצוע בפועל - הפלאן עדיין מסוכם משני המופעים כפי שהם. 3051 = 0 בפועל בכל 3 המופעים (הוכרע ע"י המשתמש כמוצר לא-זהה) - לא רלוונטי לכפל.
F7: סה"כ | G7: =SUBTOTAL(9,G2:G5) -> 84 | H7: =SUBTOTAL(9,H2:H5) -> 20 | I7: =SUBTOTAL(9,I2:I5) -> 403 | J7: =SUM(G7:I7) -> 507 | K7: דודו | V7: חיים
K8: 0.9 | L8: 1 | M8: 0.85 | V8: 0.9 | W8: 1 | X8: 0.85
G9: 0.2 | K9: =G2 -> 26 | L9: =H2 -> 2 | M9: =I2 -> 70 | S9: =SUM(S11:S30) -> 18000 | T9: =SUM(T11:T30) -> 1933402.4 | V9: =G3 -> 14 | W9: =H3 -> 1 | X9: =I3 -> 59 | AD9: =SUM(AD11:AD30) -> 13739 | AE9: =SUM(AE11:AE30) -> 1476534.5
A10: # | B10: דגם | D10: מחיר ליח' (₪) | E10: מכירות מתוכננות (שנתי, ₪) | F10: מחיר מטרה | G10: הנחה | H10: חודשים | I10: מידות | K10: אורט | L10: פיזט | M10: בתי מרקחת | N10: חנויות סה"כ | O10: הזמנה ראשונה | P10: השלמה | Q10: גלגול | R10: סה"כ | S10: יחידות סה"כ | T10: מכירות | V10: אורט | W10: פיזט | X10: בתי מרקחת | Y10: חנויות סה"כ | Z10: הזמנה ראשונה | AA10: השלמה | AB10: גלגול | AC10: סה"כ | AD10: יחידות סה"כ | AE10: מכירות
B11: 213 CTS | C11: כפפה | D11: 90 | E11: 194400 | F11: 90 | G11: =F11*(100%-$G$9) -> 72 | H11: 12 | I11: 3 | K11: =ROUNDUP($K$9*$K$8,0) -> 24 | L11: 2 | M11: =ROUNDUP($M$9*$M$8,0) -> 60 | N11: =SUM(K11:M11) -> 86 | O11: 6 | P11: 4 | Q11: 3 | R11: =O11+(P11*Q11) -> 18 | S11: =R11*N11 -> 1548 | T11: =S11*$G11 -> 111456 | V11: =ROUNDUP($V$9*$V$8,0) -> 13 | W11: 1 | X11: =ROUNDUP($X$9*$X$8,0) -> 51 | Y11: =SUM(V11:X11) -> 65 | Z11: 6 | AA11: 4 | AB11: 3 | AC11: =Z11+(AA11*AB11) -> 18 | AD11: =AC11*Y11 -> 1170 | AE11: =AD11*$G11 -> 84240
B12: SH422 | C12: גנו תומך ברק | D12: 100 | E12: 288000 | F12: 100 | G12: =F12*(100%-$G$9) -> 80 | H12: 12 | I12: 3 | K12: =ROUNDUP($K$9*$K$8,0) -> 24 | L12: 2 | M12: =ROUNDUP($M$9*$M$8,0) -> 60 | N12: =SUM(K12:M12) -> 86 | O12: 6 | P12: 3 | Q12: 3 | R12: =O12+(P12*Q12) -> 15 | S12: =R12*N12 -> 1290 | T12: =S12*$G12 -> 103200 | V12: =ROUNDUP($V$9*$V$8,0) -> 13 | W12: 1 | X12: =ROUNDUP($X$9*$X$8,0) -> 51 | Y12: =SUM(V12:X12) -> 65 | Z12: 6 | AA12: 3 | AB12: 3 | AC12: =Z12+(AA12*AB12) -> 15 | AD12: =AC12*Y12 -> 975 | AE12: =AD12*$G12 -> 78000
B13: SH333 | C13: מקבע קרסול מתנפח | D13: 70 | E13: 70000 | F13: 40 | G13: =F13*(100%-$G$9) -> 32 | H13: 12 | I13: 1 | K13: =ROUNDUP($K$9*$K$8,0) -> 24 | L13: 2 | M13: =ROUNDUP($M$9*$M$8,0) -> 60 | N13: =SUM(K13:M13) -> 86 | O13: 6 | P13: 4 | Q13: 3 | R13: =O13+(P13*Q13) -> 18 | S13: =R13*N13 -> 1548 | T13: =S13*$G13 -> 49536 | V13: =ROUNDUP($V$9*$V$8,0) -> 13 | W13: 1 | X13: =ROUNDUP($X$9*$X$8,0) -> 51 | Y13: =SUM(V13:X13) -> 65 | Z13: 6 | AA13: 4 | AB13: 3 | AC13: =Z13+(AA13*AB13) -> 18 | AD13: =AC13*Y13 -> 1170 | AE13: =AD13*$G13 -> 37440
B14: SH776 | C14: SpinaShield | חגורת תיקון יציבה לעמוד שדרה וכתפיים | D14: 350 | E14: 77000 | F14: 300 | G14: =F14*(100%-$G$9) -> 240 | H14: 12 | I14: 5 | K14: =ROUNDUP($K$9*$K$8,0) -> 24 | L14: 2 | M14: =ROUNDUP($M$9*$M$8,0) -> 60 | N14: =SUM(K14:M14) -> 86 | O14: 6 | P14: 4 | Q14: 3 | R14: =O14+(P14*Q14) -> 18 | S14: =R14*N14 -> 1548 | T14: =S14*$G14 -> 371520 | V14: =ROUNDUP($V$9*$V$8,0) -> 13 | W14: 1 | X14: =ROUNDUP($X$9*$X$8,0) -> 51 | Y14: =SUM(V14:X14) -> 65 | Z14: 6 | AA14: 4 | AB14: 3 | AC14: =Z14+(AA14*AB14) -> 18 | AD14: =AC14*Y14 -> 1170 | AE14: =AD14*$G14 -> 280800
B15: SH322 | C15: מגיני קרסול | D15: 70 | E15: 19600 | F15: 70 | G15: =F15*(100%-$G$9) -> 56 | H15: 12 | I15: 6 | K15: =ROUNDUP($K$9*$K$8,0) -> 24 | L15: 2 | M15: =ROUNDUP($M$9*$M$8,0) -> 60 | N15: =SUM(K15:M15) -> 86 | O15: 6 | P15: 4 | Q15: 3 | R15: =O15+(P15*Q15) -> 18 | S15: =R15*N15 -> 1548 | T15: =S15*$G15 -> 86688 | V15: =ROUNDUP($V$9*$V$8,0) -> 13 | W15: 1 | X15: =ROUNDUP($X$9*$X$8,0) -> 51 | Y15: =SUM(V15:X15) -> 65 | Z15: 6 | AA15: 4 | AB15: 3 | AC15: =Z15+(AA15*AB15) -> 18 | AD15: =AC15*Y15 -> 1170 | AE15: =AD15*$G15 -> 65520
B16: SH922 | C16: תומך מרפק עם כריות ג'ל | D16: 80 | E16: 22400 | F16: 80 | G16: =F16*(100%-$G$9) -> 64 | H16: 6 | I16: 6 | K16: =ROUNDUP($K$9*$K$8,0) -> 24 | L16: 2 | M16: =ROUNDUP($M$9*$M$8,0) -> 60 | N16: =SUM(K16:M16) -> 86 | O16: 6 | P16: 4 | Q16: 3 | R16: =O16+(P16*Q16) -> 18 | S16: =R16*N16 -> 1548 | T16: =S16*$G16 -> 99072 | V16: =ROUNDUP($V$9*$V$8,0) -> 13 | W16: 1 | X16: =ROUNDUP($X$9*$X$8,0) -> 51 | Y16: =SUM(V16:X16) -> 65 | Z16: 6 | AA16: 4 | AB16: 3 | AC16: =Z16+(AA16*AB16) -> 18 | AD16: =AC16*Y16 -> 1170 | AE16: =AD16*$G16 -> 74880
B17: SH423 | C17: גנו פרו מייצב ברך עם צירים- שמאל/ימין | D17: 260 | E17: 52000 | F17: 260 | G17: =F17*(100%-$G$9) -> 208 | H17: 10 | I17: 12 | K17: =ROUNDUP($K$9*$K$8,0) -> 24 | L17: 2 | M17: =ROUNDUP($M$9*$M$8,0) -> 60 | N17: =SUM(K17:M17) -> 86 | O17: 6 | P17: 4 | Q17: 3 | R17: =O17+(P17*Q17) -> 18 | S17: =R17*N17 -> 1548 | T17: =S17*$G17 -> 321984 | V17: =ROUNDUP($V$9*$V$8,0) -> 13 | W17: 1 | X17: =ROUNDUP($X$9*$X$8,0) -> 51 | Y17: =SUM(V17:X17) -> 65 | Z17: 6 | AA17: 4 | AB17: 3 | AC17: =Z17+(AA17*AB17) -> 18 | AD17: =AC17*Y17 -> 1170 | AE17: =AD17*$G17 -> 243360
B18: 364 XL+ | C18: מפריד בוהן עם רצועה | D18: 24 | E18: 24000 | F18: 34.3 | G18: =F18*(100%-$G$9) -> 27.44 | H18: 12 | I18: 1 | J18: בתי | K18: 0 | L18: 0 | M18: 70 | N18: =SUM(K18:M18) -> 70 | O18: 3 | P18: 2 | Q18: 5 | R18: =O18+(P18*Q18) -> 13 | S18: =R18*N18 -> 910 | T18: =S18*$G18 -> 24970.4 | V18: 0 | W18: 0 | X18: 59 | Y18: =SUM(V18:X18) -> 59 | Z18: 3 | AA18: 2 | AB18: 5 | AC18: =Z18+(AA18*AB18) -> 13 | AD18: =AC18*Y18 -> 767 | AE18: =AD18*$G18 -> 21046.48
B19: 809PW | C19: טייפ | D19: 12 | E19: 24000 | F19: 10.5 | G19: =F19*(100%-$G$9) -> 8.4 | H19: 12 | I19: 1 | K19: 0 | L19: 2 | M19: 70 | N19: =SUM(K19:M19) -> 72 | O19: 6 | P19: 3 | Q19: 4 | R19: =O19+(P19*Q19) -> 18 | S19: =R19*N19 -> 1296 | T19: =S19*$G19 -> 10886.4 | V19: 0 | W19: 1 | X19: 59 | Y19: =SUM(V19:X19) -> 60 | Z19: 6 | AA19: 3 | AB19: 4 | AC19: =Z19+(AA19*AB19) -> 18 | AD19: =AC19*Y19 -> 1080 | AE19: =AD19*$G19 -> 9072
B20: T40B | C20: רצועת רטייה לפיקת הברך | D20: 70 | E20: 21000 | F20: 70 | G20: =F20*(100%-$G$9) -> 56 | H20: 12 | I20: 1 | J20: אור | K20: =ROUNDUP($K$9*$K$8,0) -> 24 | L20: 0 | M20: =ROUNDUP($M$9*$M$8,0) -> 60 | N20: =SUM(K20:M20) -> 84 | O20: 3 | P20: 2 | Q20: 5 | R20: =O20+(P20*Q20) -> 13 | S20: =R20*N20 -> 1092 | T20: =S20*$G20 -> 61152 | V20: =ROUNDUP($V$9*$V$8,0) -> 13 | W20: 0 | X20: =ROUNDUP($X$9*$X$8,0) -> 51 | Y20: =SUM(V20:X20) -> 64 | Z20: 3 | AA20: 2 | AB20: 5 | AC20: =Z20+(AA20*AB20) -> 13 | AD20: =AC20*Y20 -> 832 | AE20: =AD20*$G20 -> 46592
B21: T066B | C21: חגורה לגב | D21: 140 | E21: 42000 | F21: 140 | G21: =F21*(100%-$G$9) -> 112 | H21: 12 | I21: 2 | K21: =ROUNDUP($K$9*$K$8,0) -> 24 | L21: 2 | M21: =ROUNDUP($M$9*$M$8,0) -> 60 | N21: =SUM(K21:M21) -> 86 | O21: 2 | P21: 1 | Q21: 3 | R21: =O21+(P21*Q21) -> 5 | S21: =R21*N21 -> 430 | T21: =S21*$G21 -> 48160 | V21: =ROUNDUP($V$9*$V$8,0) -> 13 | W21: 1 | X21: =ROUNDUP($X$9*$X$8,0) -> 51 | Y21: =SUM(V21:X21) -> 65 | Z21: 2 | AA21: 1 | AB21: 3 | AC21: =Z21+(AA21*AB21) -> 5 | AD21: =AC21*Y21 -> 325 | AE21: =AD21*$G21 -> 36400
B22: 3051 | C22: מדרסים | D22: 75 | E22: 37500 | F22: 156 | G22: =F22*(100%-$G$9) -> 124.8 | H22: 9 | I22: 5 | K22: =ROUNDUP($K$9*$K$8,0) -> 24 | L22: 2 | M22: =ROUNDUP($M$9*$M$8,0) -> 60 | N22: =SUM(K22:M22) -> 86 | O22: 5 | P22: 4 | Q22: 3 | R22: =O22+(P22*Q22) -> 17 | S22: =R22*N22 -> 1462 | T22: =S22*$G22 -> 182457.6 | V22: =ROUNDUP($V$9*$V$8,0) -> 13 | W22: 1 | X22: =ROUNDUP($X$9*$X$8,0) -> 51 | Y22: =SUM(V22:X22) -> 65 | Z22: 5 | AA22: 4 | AB22: 3 | AC22: =Z22+(AA22*AB22) -> 17 | AD22: =AC22*Y22 -> 1105 | AE22: =AD22*$G22 -> 137904
B23: MSG001F 0 | C23: מכשיר עיסוי | D23: 550 | E23: 55000 | F23: 550 | G23: =F23*(100%-$G$9) -> 440 | H23: 12 | I23: 1 | K23: =ROUNDUP($K$9*$K$8,0) -> 24 | L23: 2 | M23: 20 | N23: =SUM(K23:M23) -> 46 | O23: 1 | P23: 1 | Q23: 2 | R23: =O23+(P23*Q23) -> 3 | S23: =R23*N23 -> 138 | T23: =S23*$G23 -> 60720 | V23: =ROUNDUP($V$9*$V$8,0) -> 13 | W23: 1 | X23: 30 | Y23: =SUM(V23:X23) -> 44 | Z23: 1 | AA23: 1 | AB23: 2 | AC23: =Z23+(AA23*AB23) -> 3 | AD23: =AC23*Y23 -> 132 | AE23: =AD23*$G23 -> 58080
B24: MSG002S 0 | C24: כרית עיסוי | D24: 550 | E24: 55000 | F24: 550 | G24: =F24*(100%-$G$9) -> 440 | H24: 12 | I24: 1 | K24: =ROUNDUP($K$9*$K$8,0) -> 24 | L24: 2 | M24: 20 | N24: =SUM(K24:M24) -> 46 | O24: 1 | P24: 1 | Q24: 2 | R24: =O24+(P24*Q24) -> 3 | S24: =R24*N24 -> 138 | T24: =S24*$G24 -> 60720 | V24: =ROUNDUP($V$9*$V$8,0) -> 13 | W24: 1 | X24: 30 | Y24: =SUM(V24:X24) -> 44 | Z24: 1 | AA24: 1 | AB24: 2 | AC24: =Z24+(AA24*AB24) -> 3 | AD24: =AC24*Y24 -> 132 | AE24: =AD24*$G24 -> 58080
B25: T-scoop רגל | D25: 265 | E25: 53000 | F25: 265 | G25: =F25*(100%-$G$9) -> 212 | H25: 3 | I25: 1 | K25: =ROUNDUP($K$9*$K$8,0) -> 24 | L25: 2 | M25: 0 | N25: =SUM(K25:M25) -> 26 | O25: 1 | P25: 1 | Q25: 1 | R25: =O25+(P25*Q25) -> 2 | S25: =R25*N25 -> 52 | T25: =S25*$G25 -> 11024 | V25: =ROUNDUP($V$9*$V$8,0) -> 13 | W25: 1 | X25: 0 | Y25: =SUM(V25:X25) -> 14 | Z25: 1 | AA25: 1 | AB25: 1 | AC25: =Z25+(AA25*AB25) -> 2 | AD25: =AC25*Y25 -> 28 | AE25: =AD25*$G25 -> 5936
B26: T-scoop יד | D26: 350 | E26: 17500 | F26: 265 | G26: =F26*(100%-$G$9) -> 212 | H26: 0 | I26: 1 | K26: =ROUNDUP($K$9*$K$8,0) -> 24 | L26: 2 | M26: 0 | N26: =SUM(K26:M26) -> 26 | O26: 0 | R26: =O26+(P26*Q26) -> 0 | S26: =R26*N26 -> 0 | T26: =S26*$G26 -> 0 | V26: =ROUNDUP($V$9*$V$8,0) -> 13 | W26: 1 | X26: 0 | Y26: =SUM(V26:X26) -> 14 | Z26: 0 | AC26: =Z26+(AA26*AB26) -> 0 | AD26: =AC26*Y26 -> 0 | AE26: =AD26*$G26 -> 0
B27: SH779 חגורת Jewett | C27: חגורת קיבוע מתקדמת לעמוד השדרה העליון והתחתון | D27: 440 | E27: 26400 | F27: 440 | G27: =F27*(100%-$G$9) -> 352 | H27: 12 | I27: 4 | K27: =ROUNDUP($K$9*$K$8,0) -> 24 | L27: 2 | M27: =ROUNDUP($M$9*$M$8,0) -> 60 | N27: =SUM(K27:M27) -> 86 | O27: 2 | P27: 1 | Q27: 3 | R27: =O27+(P27*Q27) -> 5 | S27: =R27*N27 -> 430 | T27: =S27*$G27 -> 151360 | V27: =ROUNDUP($V$9*$V$8,0) -> 13 | W27: 1 | X27: =ROUNDUP($X$9*$X$8,0) -> 51 | Y27: =SUM(V27:X27) -> 65 | Z27: 2 | AA27: 1 | AB27: 3 | AC27: =Z27+(AA27*AB27) -> 5 | AD27: =AC27*Y27 -> 325 | AE27: =AD27*$G27 -> 114400
B28: מגף (ווקר) | D28: 160 | E28: 56000 | F28: 160 | G28: =F28*(100%-$G$9) -> 128 | H28: 4 | I28: 2 | K28: =ROUNDUP($K$9*$K$8,0) -> 24 | L28: 2 | M28: 20 | N28: =SUM(K28:M28) -> 46 | O28: 1 | P28: 1 | Q28: 1 | R28: =O28+(P28*Q28) -> 2 | S28: =R28*N28 -> 92 | T28: =S28*$G28 -> 11776 | V28: =ROUNDUP($V$9*$V$8,0) -> 13 | W28: 1 | X28: 20 | Y28: =SUM(V28:X28) -> 34 | Z28: 1 | AA28: 1 | AB28: 1 | AC28: =Z28+(AA28*AB28) -> 2 | AD28: =AC28*Y28 -> 68 | AE28: =AD28*$G28 -> 8704
B29: SH660 cervical collar | C29: מקבע צוואר קשיח מתכוונן | F29: 280 | G29: =F29*(100%-$G$9) -> 224 | H29: 12 | I29: 1 | K29: =ROUNDUP($K$9*$K$8,0) -> 24 | L29: 2 | M29: 20 | N29: =SUM(K29:M29) -> 46 | O29: 2 | P29: 1 | Q29: 3 | R29: =O29+(P29*Q29) -> 5 | S29: =R29*N29 -> 230 | T29: =S29*$G29 -> 51520 | V29: =ROUNDUP($V$9*$V$8,0) -> 13 | W29: 1 | X29: 20 | Y29: =SUM(V29:X29) -> 34 | Z29: 2 | AA29: 1 | AB29: 3 | AC29: =Z29+(AA29*AB29) -> 5 | AD29: =AC29*Y29 -> 170 | AE29: =AD29*$G29 -> 38080
B30: T36B | C30: תומך קרסול תרמי לתמיכה | D30: 75 | E30: 7500 | F30: 125 | G30: =F30*(100%-$G$9) -> 100 | I30: 6 | K30: =ROUNDUP($K$9*$K$8,0) -> 24 | L30: 2 | M30: 70 | N30: =SUM(K30:M30) -> 96 | O30: 6 | P30: 3 | Q30: 2 | R30: =O30+(P30*Q30) -> 12 | S30: =R30*N30 -> 1152 | T30: =S30*$G30 -> 115200 | V30: =ROUNDUP($V$9*$V$8,0) -> 13 | W30: 1 | X30: =ROUNDUP($X$9*$X$8,0) -> 51 | Y30: =SUM(V30:X30) -> 65 | Z30: 6 | AA30: 3 | AB30: 2 | AC30: =Z30+(AA30*AB30) -> 12 | AD30: =AC30*Y30 -> 780 | AE30: =AD30*$G30 -> 78000
B32: Miami brace
K34: סטאס | V34: חזאם
K35: 0.9 | L35: 1 | M35: 0.85 | V35: 0.9 | W35: 0.9 | X35: 0.85
G36: 0.2 | K36: =G4 -> 17 | L36: =H4 -> 5 | M36: =I4 -> 63 | S36: =SUM(S38:S57) -> 15678 | T36: =SUM(T38:T57) -> 1677595 | V36: =G5 -> 27 | W36: =H5 -> 12 | X36: =I5 -> 211 | AD36: =SUM(AD38:AD57) -> 43445 | AE36: =SUM(AE38:AE57) -> 4688528.8
A37: # | B37: דגם | D37: מחיר ליח' (₪) | E37: מכירות מתוכננות (שנתי, ₪) | F37: מחיר מטרה | G37: הנחה | H37: חודשים | I37: מידות | K37: אורט | L37: פיזט | M37: בתי מרקחת | N37: חנויות סה"כ | O37: הזמנה ראשונה | P37: השלמה | Q37: גלגול | R37: סה"כ | S37: יחידות סה"כ | T37: מכירות | V37: אורט | W37: פיזט | X37: בתי מרקחת | Y37: חנויות סה"כ | Z37: הזמנה ראשונה | AA37: השלמה | AB37: גלגול | AC37: סה"כ | AD37: יחידות סה"כ | AE37: מכירות
B38: 213 CTS | C38: כפפה | D38: 90 | E38: 194400 | F38: 90 | G38: =F38*(100%-$G$9) -> 72 | H38: 12 | I38: 3 | K38: =ROUNDUP($K$36*$K$35,0) -> 16 | L38: 5 | M38: =ROUNDUP($M$36*$M$35,0) -> 54 | N38: =SUM(K38:M38) -> 75 | O38: 6 | P38: 4 | Q38: 3 | R38: =O38+(P38*Q38) -> 18 | S38: =R38*N38 -> 1350 | T38: =S38*$G38 -> 97200 | V38: =ROUNDUP($V$36*$V$35,0) -> 25 | W38: =ROUNDUP($W$36*$W$35,0) -> 11 | X38: =ROUNDUP($X$36*$X$35,0) -> 180 | Y38: =SUM(V38:X38) -> 216 | Z38: 6 | AA38: 4 | AB38: 3 | AC38: =Z38+(AA38*AB38) -> 18 | AD38: =AC38*Y38 -> 3888 | AE38: =AD38*$G38 -> 279936
B39: SH422 | C39: גנו תומך ברק | D39: 100 | E39: 288000 | F39: 100 | G39: =F39*(100%-$G$9) -> 80 | H39: 12 | I39: 3 | K39: =ROUNDUP($K$36*$K$35,0) -> 16 | L39: 5 | M39: =ROUNDUP($M$36*$M$35,0) -> 54 | N39: =SUM(K39:M39) -> 75 | O39: 6 | P39: 3 | Q39: 3 | R39: =O39+(P39*Q39) -> 15 | S39: =R39*N39 -> 1125 | T39: =S39*$G39 -> 90000 | V39: =ROUNDUP($V$36*$V$35,0) -> 25 | W39: =ROUNDUP($W$36*$W$35,0) -> 11 | X39: =ROUNDUP($X$36*$X$35,0) -> 180 | Y39: =SUM(V39:X39) -> 216 | Z39: 6 | AA39: 3 | AB39: 3 | AC39: =Z39+(AA39*AB39) -> 15 | AD39: =AC39*Y39 -> 3240 | AE39: =AD39*$G39 -> 259200
B40: SH333 | C40: מקבע קרסול מתנפח | D40: 70 | E40: 70000 | F40: 40 | G40: =F40*(100%-$G$9) -> 32 | H40: 12 | I40: 1 | K40: =ROUNDUP($K$36*$K$35,0) -> 16 | L40: 5 | M40: =ROUNDUP($M$36*$M$35,0) -> 54 | N40: =SUM(K40:M40) -> 75 | O40: 6 | P40: 4 | Q40: 3 | R40: =O40+(P40*Q40) -> 18 | S40: =R40*N40 -> 1350 | T40: =S40*$G40 -> 43200 | V40: =ROUNDUP($V$36*$V$35,0) -> 25 | W40: =ROUNDUP($W$36*$W$35,0) -> 11 | X40: =ROUNDUP($X$36*$X$35,0) -> 180 | Y40: =SUM(V40:X40) -> 216 | Z40: 6 | AA40: 4 | AB40: 3 | AC40: =Z40+(AA40*AB40) -> 18 | AD40: =AC40*Y40 -> 3888 | AE40: =AD40*$G40 -> 124416
B41: SH776 | C41: SpinaShield | חגורת תיקון יציבה לעמוד שדרה וכתפיים | D41: 350 | E41: 77000 | F41: 300 | G41: =F41*(100%-$G$9) -> 240 | H41: 12 | I41: 5 | K41: =ROUNDUP($K$36*$K$35,0) -> 16 | L41: 5 | M41: =ROUNDUP($M$36*$M$35,0) -> 54 | N41: =SUM(K41:M41) -> 75 | O41: 6 | P41: 4 | Q41: 3 | R41: =O41+(P41*Q41) -> 18 | S41: =R41*N41 -> 1350 | T41: =S41*$G41 -> 324000 | V41: =ROUNDUP($V$36*$V$35,0) -> 25 | W41: =ROUNDUP($W$36*$W$35,0) -> 11 | X41: =ROUNDUP($X$36*$X$35,0) -> 180 | Y41: =SUM(V41:X41) -> 216 | Z41: 6 | AA41: 4 | AB41: 3 | AC41: =Z41+(AA41*AB41) -> 18 | AD41: =AC41*Y41 -> 3888 | AE41: =AD41*$G41 -> 933120
B42: SH322 | C42: מגיני קרסול | D42: 70 | E42: 19600 | F42: 70 | G42: =F42*(100%-$G$9) -> 56 | H42: 12 | I42: 6 | K42: =ROUNDUP($K$36*$K$35,0) -> 16 | L42: 5 | M42: =ROUNDUP($M$36*$M$35,0) -> 54 | N42: =SUM(K42:M42) -> 75 | O42: 6 | P42: 4 | Q42: 3 | R42: =O42+(P42*Q42) -> 18 | S42: =R42*N42 -> 1350 | T42: =S42*$G42 -> 75600 | V42: =ROUNDUP($V$36*$V$35,0) -> 25 | W42: =ROUNDUP($W$36*$W$35,0) -> 11 | X42: =ROUNDUP($X$36*$X$35,0) -> 180 | Y42: =SUM(V42:X42) -> 216 | Z42: 6 | AA42: 4 | AB42: 3 | AC42: =Z42+(AA42*AB42) -> 18 | AD42: =AC42*Y42 -> 3888 | AE42: =AD42*$G42 -> 217728
...

Sheet פירוט לסוכן
A1: פירוט לסוכן - יחידות ומכירות לפי ערוץ (אורט / פיזט / בתי מרקחת) למוצרים חדשים
A2: תאריך חישוב: | B2: 46312
A3: מקור: גיליון "Plan vs Actual (סוכן)" (קריאה בלבד). לכל מוצר: יחידות-ערוץ = R (סה"כ) × מספר חנויות באותו ערוץ (K/L/M או V/W/X); מכירות-ערוץ = יחידות-ערוץ × G (מחיר אחרי הנחה). סכום 3 הערוצים לכל מוצר-סוכן שווה בדיוק ל-S/T (או AD/AE) המקוריים.
A5: סוכן: דודו
B6: אורט | F6: פיזט | J6: בתי מרקחת
B7: דגם | C7: יחידות (שנתי) | D7: מכירות (₪) | F7: דגם | G7: יחידות (שנתי) | H7: מכירות (₪) | J7: דגם | K7: יחידות (שנתי) | L7: מכירות (₪)
B8: ='Plan vs Actual (סוכן)'!B11 -> 213 CTS | C8: ='Plan vs Actual (סוכן)'!R11*'Plan vs Actual (סוכן)'!K11 -> 432 | D8: =C8*'Plan vs Actual (סוכן)'!G11 -> 31104 | F8: ='Plan vs Actual (סוכן)'!B11 -> 213 CTS | G8: ='Plan vs Actual (סוכן)'!R11*'Plan vs Actual (סוכן)'!L11 -> 36 | H8: =G8*'Plan vs Actual (סוכן)'!G11 -> 2592 | J8: ='Plan vs Actual (סוכן)'!B11 -> 213 CTS | K8: ='Plan vs Actual (סוכן)'!R11*'Plan vs Actual (סוכן)'!M11 -> 1080 | L8: =K8*'Plan vs Actual (סוכן)'!G11 -> 77760
B9: ='Plan vs Actual (סוכן)'!B12 -> SH422 | C9: ='Plan vs Actual (סוכן)'!R12*'Plan vs Actual (סוכן)'!K12 -> 360 | D9: =C9*'Plan vs Actual (סוכן)'!G12 -> 28800 | F9: ='Plan vs Actual (סוכן)'!B12 -> SH422 | G9: ='Plan vs Actual (סוכן)'!R12*'Plan vs Actual (סוכן)'!L12 -> 30 | H9: =G9*'Plan vs Actual (סוכן)'!G12 -> 2400 | J9: ='Plan vs Actual (סוכן)'!B12 -> SH422 | K9: ='Plan vs Actual (סוכן)'!R12*'Plan vs Actual (סוכן)'!M12 -> 900 | L9: =K9*'Plan vs Actual (סוכן)'!G12 -> 72000
B10: ='Plan vs Actual (סוכן)'!B13 -> SH333 | C10: ='Plan vs Actual (סוכן)'!R13*'Plan vs Actual (סוכן)'!K13 -> 432 | D10: =C10*'Plan vs Actual (סוכן)'!G13 -> 13824 | F10: ='Plan vs Actual (סוכן)'!B13 -> SH333 | G10: ='Plan vs Actual (סוכן)'!R13*'Plan vs Actual (סוכן)'!L13 -> 36 | H10: =G10*'Plan vs Actual (סוכן)'!G13 -> 1152 | J10: ='Plan vs Actual (סוכן)'!B13 -> SH333 | K10: ='Plan vs Actual (סוכן)'!R13*'Plan vs Actual (סוכן)'!M13 -> 1080 | L10: =K10*'Plan vs Actual (סוכן)'!G13 -> 34560
B11: ='Plan vs Actual (סוכן)'!B14 -> SH776 | C11: ='Plan vs Actual (סוכן)'!R14*'Plan vs Actual (סוכן)'!K14 -> 432 | D11: =C11*'Plan vs Actual (סוכן)'!G14 -> 103680 | F11: ='Plan vs Actual (סוכן)'!B14 -> SH776 | G11: ='Plan vs Actual (סוכן)'!R14*'Plan vs Actual (סוכן)'!L14 -> 36 | H11: =G11*'Plan vs Actual (סוכן)'!G14 -> 8640 | J11: ='Plan vs Actual (סוכן)'!B14 -> SH776 | K11: ='Plan vs Actual (סוכן)'!R14*'Plan vs Actual (סוכן)'!M14 -> 1080 | L11: =K11*'Plan vs Actual (סוכן)'!G14 -> 259200
B12: ='Plan vs Actual (סוכן)'!B15 -> SH322 | C12: ='Plan vs Actual (סוכן)'!R15*'Plan vs Actual (סוכן)'!K15 -> 432 | D12: =C12*'Plan vs Actual (סוכן)'!G15 -> 24192 | F12: ='Plan vs Actual (סוכן)'!B15 -> SH322 | G12: ='Plan vs Actual (סוכן)'!R15*'Plan vs Actual (סוכן)'!L15 -> 36 | H12: =G12*'Plan vs Actual (סוכן)'!G15 -> 2016 | J12: ='Plan vs Actual (סוכן)'!B15 -> SH322 | K12: ='Plan vs Actual (סוכן)'!R15*'Plan vs Actual (סוכן)'!M15 -> 1080 | L12: =K12*'Plan vs Actual (סוכן)'!G15 -> 60480
B13: ='Plan vs Actual (סוכן)'!B16 -> SH922 | C13: ='Plan vs Actual (סוכן)'!R16*'Plan vs Actual (סוכן)'!K16 -> 432 | D13: =C13*'Plan vs Actual (סוכן)'!G16 -> 27648 | F13: ='Plan vs Actual (סוכן)'!B16 -> SH922 | G13: ='Plan vs Actual (סוכן)'!R16*'Plan vs Actual (סוכן)'!L16 -> 36 | H13: =G13*'Plan vs Actual (סוכן)'!G16 -> 2304 | J13: ='Plan vs Actual (סוכן)'!B16 -> SH922 | K13: ='Plan vs Actual (סוכן)'!R16*'Plan vs Actual (סוכן)'!M16 -> 1080 | L13: =K13*'Plan vs Actual (סוכן)'!G16 -> 69120
B14: ='Plan vs Actual (סוכן)'!B17 -> SH423 | C14: ='Plan vs Actual (סוכן)'!R17*'Plan vs Actual (סוכן)'!K17 -> 432 | D14: =C14*'Plan vs Actual (סוכן)'!G17 -> 89856 | F14: ='Plan vs Actual (סוכן)'!B17 -> SH423 | G14: ='Plan vs Actual (סוכן)'!R17*'Plan vs Actual (סוכן)'!L17 -> 36 | H14: =G14*'Plan vs Actual (סוכן)'!G17 -> 7488 | J14: ='Plan vs Actual (סוכן)'!B17 -> SH423 | K14: ='Plan vs Actual (סוכן)'!R17*'Plan vs Actual (סוכן)'!M17 -> 1080 | L14: =K14*'Plan vs Actual (סוכן)'!G17 -> 224640
B15: ='Plan vs Actual (סוכן)'!B18 -> 364 XL+ | C15: ='Plan vs Actual (סוכן)'!R18*'Plan vs Actual (סוכן)'!K18 -> 0 | D15: =C15*'Plan vs Actual (סוכן)'!G18 -> 0 | F15: ='Plan vs Actual (סוכן)'!B18 -> 364 XL+ | G15: ='Plan vs Actual (סוכן)'!R18*'Plan vs Actual (סוכן)'!L18 -> 0 | H15: =G15*'Plan vs Actual (סוכן)'!G18 -> 0 | J15: ='Plan vs Actual (סוכן)'!B18 -> 364 XL+ | K15: ='Plan vs Actual (סוכן)'!R18*'Plan vs Actual (סוכן)'!M18 -> 910 | L15: =K15*'Plan vs Actual (סוכן)'!G18 -> 24970.4
B16: ='Plan vs Actual (סוכן)'!B19 -> 809PW | C16: ='Plan vs Actual (סוכן)'!R19*'Plan vs Actual (סוכן)'!K19 -> 0 | D16: =C16*'Plan vs Actual (סוכן)'!G19 -> 0 | F16: ='Plan vs Actual (סוכן)'!B19 -> 809PW | G16: ='Plan vs Actual (סוכן)'!R19*'Plan vs Actual (סוכן)'!L19 -> 36 | H16: =G16*'Plan vs Actual (סוכן)'!G19 -> 302.4 | J16: ='Plan vs Actual (סוכן)'!B19 -> 809PW | K16: ='Plan vs Actual (סוכן)'!R19*'Plan vs Actual (סוכן)'!M19 -> 1260 | L16: =K16*'Plan vs Actual (סוכן)'!G19 -> 10584
B17: ='Plan vs Actual (סוכן)'!B20 -> T40B | C17: ='Plan vs Actual (סוכן)'!R20*'Plan vs Actual (סוכן)'!K20 -> 312 | D17: =C17*'Plan vs Actual (סוכן)'!G20 -> 17472 | F17: ='Plan vs Actual (סוכן)'!B20 -> T40B | G17: ='Plan vs Actual (סוכן)'!R20*'Plan vs Actual (סוכן)'!L20 -> 0 | H17: =G17*'Plan vs Actual (סוכן)'!G20 -> 0 | J17: ='Plan vs Actual (סוכן)'!B20 -> T40B | K17: ='Plan vs Actual (סוכן)'!R20*'Plan vs Actual (סוכן)'!M20 -> 780 | L17: =K17*'Plan vs Actual (סוכן)'!G20 -> 43680
B18: ='Plan vs Actual (סוכן)'!B21 -> T066B | C18: ='Plan vs Actual (סוכן)'!R21*'Plan vs Actual (סוכן)'!K21 -> 120 | D18: =C18*'Plan vs Actual (סוכן)'!G21 -> 13440 | F18: ='Plan vs Actual (סוכן)'!B21 -> T066B | G18: ='Plan vs Actual (סוכן)'!R21*'Plan vs Actual (סוכן)'!L21 -> 10 | H18: =G18*'Plan vs Actual (סוכן)'!G21 -> 1120 | J18: ='Plan vs Actual (סוכן)'!B21 -> T066B | K18: ='Plan vs Actual (סוכן)'!R21*'Plan vs Actual (סוכן)'!M21 -> 300 | L18: =K18*'Plan vs Actual (סוכן)'!G21 -> 33600
B19: ='Plan vs Actual (סוכן)'!B22 -> 3051 | C19: ='Plan vs Actual (סוכן)'!R22*'Plan vs Actual (סוכן)'!K22 -> 408 | D19: =C19*'Plan vs Actual (סוכן)'!G22 -> 50918.4 | F19: ='Plan vs Actual (סוכן)'!B22 -> 3051 | G19: ='Plan vs Actual (סוכן)'!R22*'Plan vs Actual (סוכן)'!L22 -> 34 | H19: =G19*'Plan vs Actual (סוכן)'!G22 -> 4243.2 | J19: ='Plan vs Actual (סוכן)'!B22 -> 3051 | K19: ='Plan vs Actual (סוכן)'!R22*'Plan vs Actual (סוכן)'!M22 -> 1020 | L19: =K19*'Plan vs Actual (סוכן)'!G22 -> 127296
... B27: ='Plan vs Actual (סוכן)'!B30 -> T36B | C27: ='Plan vs Actual (סוכן)'!R30*'Plan vs Actual (סוכן)'!K30 -> 288 | D27: =C27*'Plan vs Actual (סוכן)'!G30 -> 28800 | F27: ='Plan vs Actual (סוכן)'!B30 -> T36B | G27: ='Plan vs Actual (סוכן)'!R30*'Plan vs Actual (סוכן)'!L30 -> 24 | H27: =G27*'Plan vs Actual (סוכן)'!G30 -> 2400 | J27: ='Plan vs Actual (סוכן)'!B30 -> T36B | K27: ='Plan vs Actual (סוכן)'!R30*'Plan vs Actual (סוכן)'!M30 -> 840 | L27: =K27*'Plan vs Actual (סוכן)'!G30 -> 84000
B28: סה"כ | C28: =SUM(C8:C27) -> 4560 | D28: =SUM(D8:D27) -> 578534.4 | F28: סה"כ | G28: =SUM(G8:G27) -> 390 | H28: =SUM(H8:H27) -> 47057.6 | J28: סה"כ | K28: =SUM(K8:K27) -> 13050 | L28: =SUM(L8:L27) -> 1307810.4
A30: סוכן: חיים
B31: אורט | F31: פיזט | J31: בתי מרקחת
B32: דגם | C32: יחידות (שנתי) | D32: מכירות (₪) | F32: דגם | G32: יחידות (שנתי) | H32: מכירות (₪) | J32: דגם | K32: יחידות (שנתי) | L32: מכירות (₪)
B33: ='Plan vs Actual (סוכן)'!B11 -> 213 CTS | C33: ='Plan vs Actual (סוכן)'!R11*'Plan vs Actual (סוכן)'!V11 -> 234 | D33: =C33*'Plan vs Actual (סוכן)'!G11 -> 16848 | F33: ='Plan vs Actual (סוכן)'!B11 -> 213 CTS | G33: ='Plan vs Actual (סוכן)'!R11*'Plan vs Actual (סוכן)'!W11 -> 18 | H33: =G33*'Plan vs Actual (סוכן)'!G11 -> 1296 | J33: ='Plan vs Actual (סוכן)'!B11 -> 213 CTS | K33: ='Plan vs Actual (סוכן)'!R11*'Plan vs Actual (סוכן)'!X11 -> 918 | L33: =K33*'Plan vs Actual (סוכן)'!G11 -> 66096
B34: ='Plan vs Actual (סוכן)'!B12 -> SH422 | C34: ='Plan vs Actual (סוכן)'!R12*'Plan vs Actual (סוכן)'!V12 -> 195 | D34: =C34*'Plan vs Actual (סוכן)'!G12 -> 15600 | F34: ='Plan vs Actual (סוכן)'!B12 -> SH422 | G34: ='Plan vs Actual (סוכן)'!R12*'Plan vs Actual (סוכן)'!W12 -> 15 | H34: =G34*'Plan vs Actual (סוכן)'!G12 -> 1200 | J34: ='Plan vs Actual (סוכן)'!B12 -> SH422 | K34: ='Plan vs Actual (סוכן)'!R12*'Plan vs Actual (סוכן)'!X12 -> 765 | L34: =K34*'Plan vs Actual (סוכן)'!G12 -> 61200
B35: ='Plan vs Actual (סוכן)'!B13 -> SH333 | C35: ='Plan vs Actual (סוכן)'!R13*'Plan vs Actual (סוכן)'!V13 -> 234 | D35: =C35*'Plan vs Actual (סוכן)'!G13 -> 7488 | F35: ='Plan vs Actual (סוכן)'!B13 -> SH333 | G35: ='Plan vs Actual (סוכן)'!R13*'Plan vs Actual (סוכן)'!W13 -> 18 | H35: =G35*'Plan vs Actual (סוכן)'!G13 -> 576 | J35: ='Plan vs Actual (סוכן)'!B13 -> SH333 | K35: ='Plan vs Actual (סוכן)'!R13*'Plan vs Actual (סוכן)'!X13 -> 918 | L35: =K35*'Plan vs Actual (סוכן)'!G13 -> 29376
B36: ='Plan vs Actual (סוכן)'!B14 -> SH776 | C36: ='Plan vs Actual (סוכן)'!R14*'Plan vs Actual (סוכן)'!V14 -> 234 | D36: =C36*'Plan vs Actual (סוכן)'!G14 -> 56160 | F36: ='Plan vs Actual (סוכן)'!B14 -> SH776 | G36: ='Plan vs Actual (סוכן)'!R14*'Plan vs Actual (סוכן)'!W14 -> 18 | H36: =G36*'Plan vs Actual (סוכן)'!G14 -> 4320 | J36: ='Plan vs Actual (סוכן)'!B14 -> SH776 | K36: ='Plan vs Actual (סוכן)'!R14*'Plan vs Actual (סוכן)'!X14 -> 918 | L36: =K36*'Plan vs Actual (סוכן)'!G14 -> 220320
B37: ='Plan vs Actual (סוכן)'!B15 -> SH322 | C37: ='Plan vs Actual (סוכן)'!R15*'Plan vs Actual (סוכן)'!V15 -> 234 | D37: =C37*'Plan vs Actual (סוכן)'!G15 -> 13104 | F37: ='Plan vs Actual (סוכן)'!B15 -> SH322 | G37: ='Plan vs Actual (סוכן)'!R15*'Plan vs Actual (סוכן)'!W15 -> 18 | H37: =G37*'Plan vs Actual (סוכן)'!G15 -> 1008 | J37: ='Plan vs Actual (סוכן)'!B15 -> SH322 | K37: ='Plan vs Actual (סוכן)'!R15*'Plan vs Actual (סוכן)'!X15 -> 918 | L37: =K37*'Plan vs Actual (סוכן)'!G15 -> 51408
B38: ='Plan vs Actual (סוכן)'!B16 -> SH922 | C38: ='Plan vs Actual (סוכן)'!R16*'Plan vs Actual (סוכן)'!V16 -> 234 | D38: =C38*'Plan vs Actual (סוכן)'!G16 -> 14976 | F38: ='Plan vs Actual (סוכן)'!B16 -> SH922 | G38: ='Plan vs Actual (סוכן)'!R16*'Plan vs Actual (סוכן)'!W16 -> 18 | H38: =G38*'Plan vs Actual (סוכן)'!G16 -> 1152 | J38: ='Plan vs Actual (סוכן)'!B16 -> SH922 | K38: ='Plan vs Actual (סוכן)'!R16*'Plan vs Actual (סוכן)'!X16 -> 918 | L38: =K38*'Plan vs Actual (סוכן)'!G16 -> 58752
B39: ='Plan vs Actual (סוכן)'!B17 -> SH423 | C39: ='Plan vs Actual (סוכן)'!R17*'Plan vs Actual (סוכן)'!V17 -> 234 | D39: =C39*'Plan vs Actual (סוכן)'!G17 -> 48672 | F39: ='Plan vs Actual (סוכן)'!B17 -> SH423 | G39: ='Plan vs Actual (סוכן)'!R17*'Plan vs Actual (סוכן)'!W17 -> 18 | H39: =G39*'Plan vs Actual (סוכן)'!G17 -> 3744 | J39: ='Plan vs Actual (סוכן)'!B17 -> SH423 | K39: ='Plan vs Actual (סוכן)'!R17*'Plan vs Actual (סוכן)'!X17 -> 918 | L39: =K39*'Plan vs Actual (סוכן)'!G17 -> 190944
B40: ='Plan vs Actual (סוכן)'!B18 -> 364 XL+ | C40: ='Plan vs Actual (סוכן)'!R18*'Plan vs Actual (סוכן)'!V18 -> 0 | D40: =C40*'Plan vs Actual (סוכן)'!G18 -> 0 | F40: ='Plan vs Actual (סוכן)'!B18 -> 364 XL+ | G40: ='Plan vs Actual (סוכן)'!R18*'Plan vs Actual (סוכן)'!W18 -> 0 | H40: =G40*'Plan vs Actual (סוכן)'!G18 -> 0 | J40: ='Plan vs Actual (סוכן)'!B18 -> 364 XL+ | K40: ='Plan vs Actual (סוכן)'!R18*'Plan vs Actual (סוכן)'!X18 -> 767 | L40: =K40*'Plan vs Actual (סוכן)'!G18 -> 21046.48
B41: ='Plan vs Actual (סוכן)'!B19 -> 809PW | C41: ='Plan vs Actual (סוכן)'!R19*'Plan vs Actual (סוכן)'!V19 -> 0 | D41: =C41*'Plan vs Actual (סוכן)'!G19 -> 0 | F41: ='Plan vs Actual (סוכן)'!B19 -> 809PW | G41: ='Plan vs Actual (סוכן)'!R19*'Plan vs Actual (סוכן)'!W19 -> 18 | H41: =G41*'Plan vs Actual (סוכן)'!G19 -> 151.2 | J41: ='Plan vs Actual (סוכן)'!B19 -> 809PW | K41: ='Plan vs Actual (סוכן)'!R19*'Plan vs Actual (סוכן)'!X19 -> 1062 | L41: =K41*'Plan vs Actual (סוכן)'!G19 -> 8920.8
B42: ='Plan vs Actual (סוכן)'!B20 -> T40B | C42: ='Plan vs Actual (סוכן)'!R20*'Plan vs Actual (סוכן)'!V20 -> 169 | D42: =C42*'Plan vs Actual (סוכן)'!G20 -> 9464 | F42: ='Plan vs Actual (סוכן)'!B20 -> T40B | G42: ='Plan vs Actual (סוכן)'!R20*'Plan vs Actual (סוכן)'!W20 -> 0 | H42: =G42*'Plan vs Actual (סוכן)'!G20 -> 0 | J42: ='Plan vs Actual (סוכן)'!B20 -> T40B | K42: ='Plan vs Actual (סוכן)'!R20*'Plan vs Actual (סוכן)'!X20 -> 663 | L42: =K42*'Plan vs Actual (סוכן)'!G20 -> 37128
B43: ='Plan vs Actual (סוכן)'!B21 -> T066B | C43: ='Plan vs Actual (סוכן)'!R21*'Plan vs Actual (סוכן)'!V21 -> 65 | D43: =C43*'Plan vs Actual (סוכן)'!G21 -> 7280 | F43: ='Plan vs Actual (סוכן)'!B21 -> T066B | G43: ='Plan vs Actual (סוכן)'!R21*'Plan vs Actual (סוכן)'!W21 -> 5 | H43: =G43*'Plan vs Actual (סוכן)'!G21 -> 560 | J43: ='Plan vs Actual (סוכן)'!B21 -> T066B | K43: ='Plan vs Actual (סוכן)'!R21*'Plan vs Actual (סוכן)'!X21 -> 255 | L43: =K43*'Plan vs Actual (סוכן)'!G21 -> 28560
B44: ='Plan vs Actual (סוכן)'!B22 -> 3051 | C44: ='Plan vs Actual (סוכן)'!R22*'Plan vs Actual (סוכן)'!V22 -> 221 | D44: =C44*'Plan vs Actual (סוכן)'!G22 -> 27580.8 | F44: ='Plan vs Actual (סוכן)'!B22 -> 3051 | G44: ='Plan vs Actual (סוכן)'!R22*'Plan vs Actual (סוכן)'!W22 -> 17 | H44: =G44*'Plan vs Actual (סוכן)'!G22 -> 2121.6 | J44: ='Plan vs Actual (סוכן)'!B22 -> 3051 | K44: ='Plan vs Actual (סוכן)'!R22*'Plan vs Actual (סוכן)'!X22 -> 867 | L44: =K44*'Plan vs Actual (סוכן)'!G22 -> 108201.6
... B52: ='Plan vs Actual (סוכן)'!B30 -> T36B | C52: ='Plan vs Actual (סוכן)'!R30*'Plan vs Actual (סוכן)'!V30 -> 156 | D52: =C52*'Plan vs Actual (סוכן)'!G30 -> 15600 | F52: ='Plan vs Actual (סוכן)'!B30 -> T36B | G52: ='Plan vs Actual (סוכן)'!R30*'Plan vs Actual (סוכן)'!W30 -> 12 | H52: =G52*'Plan vs Actual (סוכן)'!G30 -> 1200 | J52: ='Plan vs Actual (סוכן)'!B30 -> T36B | K52: ='Plan vs Actual (סוכן)'!R30*'Plan vs Actual (סוכן)'!X30 -> 612 | L52: =K52*'Plan vs Actual (סוכן)'!G30 -> 61200
B53: סה"כ | C53: =SUM(C33:C52) -> 2470 | D53: =SUM(D33:D52) -> 313372.8 | F53: סה"כ | G53: =SUM(G33:G52) -> 195 | H53: =SUM(H33:H52) -> 23528.8 | J53: סה"כ | K53: =SUM(K33:K52) -> 11074 | L53: =SUM(L33:L52) -> 1139632.9
A55: סוכן: סטאס
B56: אורט | F56: פיזט | J56: בתי מרקחת
B57: דגם | C57: יחידות (שנתי) | D57: מכירות (₪) | F57: דגם | G57: יחידות (שנתי) | H57: מכירות (₪) | J57: דגם | K57: יחידות (שנתי) | L57: מכירות (₪)
...

Sheet ניתוח לפי ערוץ
A1: ניתוח לפי ערוץ - סיכום יחידות ומכירות למוצרים חדשים (4 סוכנים מאוחד: דודו+חיים+סטאס+חזאם)
A2: תאריך חישוב: | B2: 46312
A3: מקור: גיליון "פירוט לסוכן" (קריאה בלבד). לכל מוצר ולכל ערוץ: יחידות = סכום היחידות של 4 הסוכנים (דודו+חיים+סטאס+חזאם) באותו ערוץ; מכירות (₪) = סכום המכירות של 4 הסוכנים באותו ערוץ. אין פירוק לפי סוכן בגיליון הזה - ראו "פירוט לסוכן" לפירוט המלא.
A5: כל הסוכנים מאוחד - לפי ערוץ
B6: אורט | F6: פיזט | J6: בתי מרקחת
B7: דגם | C7: יחידות (שנתי) | D7: מכירות (₪) | F7: דגם | G7: יחידות (שנתי) | H7: מכירות (₪) | J7: דגם | K7: יחידות (שנתי) | L7: מכירות (₪)
B8: ='פירוט לסוכן'!B8 -> 213 CTS | C8: ='פירוט לסוכן'!C8+'פירוט לסוכן'!C33+'פירוט לסוכן'!C58+'פירוט לסוכן'!C83 -> 1404 | D8: ='פירוט לסוכן'!D8+'פירוט לסוכן'!D33+'פירוט לסוכן'!D58+'פירוט לסוכן'!D83 -> 101088 | F8: ='פירוט לסוכן'!B8 -> 213 CTS | G8: ='פירוט לסוכן'!G8+'פירוט לסוכן'!G33+'פירוט לסוכן'!G58+'פירוט לסוכן'!G83 -> 342 | H8: ='פירוט לסוכן'!H8+'פירוט לסוכן'!H33+'פירוט לסוכן'!H58+'פירוט לסוכן'!H83 -> 24624 | J8: ='פירוט לסוכן'!B8 -> 213 CTS | K8: ='פירוט לסוכן'!K8+'פירוט לסוכן'!K33+'פירוט לסוכן'!K58+'פירוט לסוכן'!K83 -> 6210 | L8: ='פירוט לסוכן'!L8+'פירוט לסוכן'!L33+'פירוט לסוכן'!L58+'פירוט לסוכן'!L83 -> 447120
B9: ='פירוט לסוכן'!B9 -> SH422 | C9: ='פירוט לסוכן'!C9+'פירוט לסוכן'!C34+'פירוט לסוכן'!C59+'פירוט לסוכן'!C84 -> 1170 | D9: ='פירוט לסוכן'!D9+'פירוט לסוכן'!D34+'פירוט לסוכן'!D59+'פירוט לסוכן'!D84 -> 93600 | F9: ='פירוט לסוכן'!B9 -> SH422 | G9: ='פירוט לסוכן'!G9+'פירוט לסוכן'!G34+'פירוט לסוכן'!G59+'פירוט לסוכן'!G84 -> 285 | H9: ='פירוט לסוכן'!H9+'פירוט לסוכן'!H34+'פירוט לסוכן'!H59+'פירוט לסוכן'!H84 -> 22800 | J9: ='פירוט לסוכן'!B9 -> SH422 | K9: ='פירוט לסוכן'!K9+'פירוט לסוכן'!K34+'פירוט לסוכן'!K59+'פירוט לסוכן'!K84 -> 5175 | L9: ='פירוט לסוכן'!L9+'פירוט לסוכן'!L34+'פירוט לסוכן'!L59+'פירוט לסוכן'!L84 -> 414000
B10: ='פירוט לסוכן'!B10 -> SH333 | C10: ='פירוט לסוכן'!C10+'פירוט לסוכן'!C35+'פירוט לסוכן'!C60+'פירוט לסוכן'!C85 -> 1404 | D10: ='פירוט לסוכן'!D10+'פירוט לסוכן'!D35+'פירוט לסוכן'!D60+'פירוט לסוכן'!D85 -> 44928 | F10: ='פירוט לסוכן'!B10 -> SH333 | G10: ='פירוט לסוכן'!G10+'פירוט לסוכן'!G35+'פירוט לסוכן'!G60+'פירוט לסוכן'!G85 -> 342 | H10: ='פירוט לסוכן'!H10+'פירוט לסוכן'!H35+'פירוט לסוכן'!H60+'פירוט לסוכן'!H85 -> 10944 | J10: ='פירוט לסוכן'!B10 -> SH333 | K10: ='פירוט לסוכן'!K10+'פירוט לסוכן'!K35+'פירוט לסוכן'!K60+'פירוט לסוכן'!K85 -> 6210 | L10: ='פירוט לסוכן'!L10+'פירוט לסוכן'!L35+'פירוט לסוכן'!L60+'פירוט לסוכן'!L85 -> 198720
B11: ='פירוט לסוכן'!B11 -> SH776 | C11: ='פירוט לסוכן'!C11+'פירוט לסוכן'!C36+'פירוט לסוכן'!C61+'פירוט לסוכן'!C86 -> 1404 | D11: ='פירוט לסוכן'!D11+'פירוט לסוכן'!D36+'פירוט לסוכן'!D61+'פירוט לסוכן'!D86 -> 336960 | F11: ='פירוט לסוכן'!B11 -> SH776 | G11: ='פירוט לסוכן'!G11+'פירוט לסוכן'!G36+'פירוט לסוכן'!G61+'פירוט לסוכן'!G86 -> 342 | H11: ='פירוט לסוכן'!H11+'פירוט לסוכן'!H36+'פירוט לסוכן'!H61+'פירוט לסוכן'!H86 -> 82080 | J11: ='פירוט לסוכן'!B11 -> SH776 | K11: ='פירוט לסוכן'!K11+'פירוט לסוכן'!K36+'פירוט לסוכן'!K61+'פירוט לסוכן'!K86 -> 6210 | L11: ='פירוט לסוכן'!L11+'פירוט לסוכן'!L36+'פירוט לסוכן'!L61+'פירוט לסוכן'!L86 -> 1490400
B12: ='פירוט לסוכן'!B12 -> SH322 | C12: ='פירוט לסוכן'!C12+'פירוט לסוכן'!C37+'פירוט לסוכן'!C62+'פירוט לסוכן'!C87 -> 1404 | D12: ='פירוט לסוכן'!D12+'פירוט לסוכן'!D37+'פירוט לסוכן'!D62+'פירוט לסוכן'!D87 -> 78624 | F12: ='פירוט לסוכן'!B12 -> SH322 | G12: ='פירוט לסוכן'!G12+'פירוט לסוכן'!G37+'פירוט לסוכן'!G62+'פירוט לסוכן'!G87 -> 342 | H12: ='פירוט לסוכן'!H12+'פירוט לסוכן'!H37+'פירוט לסוכן'!H62+'פירוט לסוכן'!H87 -> 19152 | J12: ='פירוט לסוכן'!B12 -> SH322 | K12: ='פירוט לסוכן'!K12+'פירוט לסוכן'!K37+'פירוט לסוכן'!K62+'פירוט לסוכן'!K87 -> 6210 | L12: ='פירוט לסוכן'!L12+'פירוט לסוכן'!L37+'פירוט לסוכן'!L62+'פירוט לסוכן'!L87 -> 347760
B13: ='פירוט לסוכן'!B13 -> SH922 | C13: ='פירוט לסוכן'!C13+'פירוט לסוכן'!C38+'פירוט לסוכן'!C63+'פירוט לסוכן'!C88 -> 1404 | D13: ='פירוט לסוכן'!D13+'פירוט לסוכן'!D38+'פירוט לסוכן'!D63+'פירוט לסוכן'!D88 -> 89856 | F13: ='פירוט לסוכן'!B13 -> SH922 | G13: ='פירוט לסוכן'!G13+'פירוט לסוכן'!G38+'פירוט לסוכן'!G63+'פירוט לסוכן'!G88 -> 342 | H13: ='פירוט לסוכן'!H13+'פירוט לסוכן'!H38+'פירוט לסוכן'!H63+'פירוט לסוכן'!H88 -> 21888 | J13: ='פירוט לסוכן'!B13 -> SH922 | K13: ='פירוט לסוכן'!K13+'פירוט לסוכן'!K38+'פירוט לסוכן'!K63+'פירוט לסוכן'!K88 -> 6210 | L13: ='פירוט לסוכן'!L13+'פירוט לסוכן'!L38+'פירוט לסוכן'!L63+'פירוט לסוכן'!L88 -> 397440
B14: ='פירוט לסוכן'!B14 -> SH423 | C14: ='פירוט לסוכן'!C14+'פירוט לסוכן'!C39+'פירוט לסוכן'!C64+'פירוט לסוכן'!C89 -> 1404 | D14: ='פירוט לסוכן'!D14+'פירוט לסוכן'!D39+'פירוט לסוכן'!D64+'פירוט לסוכן'!D89 -> 292032 | F14: ='פירוט לסוכן'!B14 -> SH423 | G14: ='פירוט לסוכן'!G14+'פירוט לסוכן'!G39+'פירוט לסוכן'!G64+'פירוט לסוכן'!G89 -> 342 | H14: ='פירוט לסוכן'!H14+'פירוט לסוכן'!H39+'פירוט לסוכן'!H64+'פירוט לסוכן'!H89 -> 71136 | J14: ='פירוט לסוכן'!B14 -> SH423 | K14: ='פירוט לסוכן'!K14+'פירוט לסוכן'!K39+'פירוט לסוכן'!K64+'פירוט לסוכן'!K89 -> 6210 | L14: ='פירוט לסוכן'!L14+'פירוט לסוכן'!L39+'פירוט לסוכן'!L64+'פירוט לסוכן'!L89 -> 1291680
B15: ='פירוט לסוכן'!B15 -> 364 XL+ | C15: ='פירוט לסוכן'!C15+'פירוט לסוכן'!C40+'פירוט לסוכן'!C65+'פירוט לסוכן'!C90 -> 0 | D15: ='פירוט לסוכן'!D15+'פירוט לסוכן'!D40+'פירוט לסוכן'!D65+'פירוט לסוכן'!D90 -> 0 | F15: ='פירוט לסוכן'!B15 -> 364 XL+ | G15: ='פירוט לסוכן'!G15+'פירוט לסוכן'!G40+'פירוט לסוכן'!G65+'פירוט לסוכן'!G90 -> 0 | H15: ='פירוט לסוכן'!H15+'פירוט לסוכן'!H40+'פירוט לסוכן'!H65+'פירוט לסוכן'!H90 -> 0 | J15: ='פירוט לסוכן'!B15 -> 364 XL+ | K15: ='פירוט לסוכן'!K15+'פירוט לסוכן'!K40+'פירוט לסוכן'!K65+'פירוט לסוכן'!K90 -> 5096 | L15: ='פירוט לסוכן'!L15+'פירוט לסוכן'!L40+'פירוט לסוכן'!L65+'פירוט לסוכן'!L90 -> 139834.24
B16: ='פירוט לסוכן'!B16 -> 809PW | C16: ='פירוט לסוכן'!C16+'פירוט לסוכן'!C41+'פירוט לסוכן'!C66+'פירוט לסוכן'!C91 -> 0 | D16: ='פירוט לסוכן'!D16+'פירוט לסוכן'!D41+'פירוט לסוכן'!D66+'פירוט לסוכן'!D91 -> 0 | F16: ='פירוט לסוכן'!B16 -> 809PW | G16: ='פירוט לסוכן'!G16+'פירוט לסוכן'!G41+'פירוט לסוכן'!G66+'פירוט לסוכן'!G91 -> 342 | H16: ='פירוט לסוכן'!H16+'פירוט לסוכן'!H41+'פירוט לסוכן'!H66+'פירוט לסוכן'!H91 -> 2872.8 | J16: ='פירוט לסוכן'!B16 -> 809PW | K16: ='פירוט לסוכן'!K16+'פירוט לסוכן'!K41+'פירוט לסוכן'!K66+'פירוט לסוכן'!K91 -> 5256 | L16: ='פירוט לסוכן'!L16+'פירוט לסוכן'!L41+'פירוט לסוכן'!L66+'פירוט לסוכן'!L91 -> 44150.4
B17: ='פירוט לסוכן'!B17 -> T40B | C17: ='פירוט לסוכן'!C17+'פירוט לסוכן'!C42+'פירוט לסוכן'!C67+'פירוט לסוכן'!C92 -> 1014 | D17: ='פירוט לסוכן'!D17+'פירוט לסוכן'!D42+'פירוט לסוכן'!D67+'פירוט לסוכן'!D92 -> 56784 | F17: ='פירוט לסוכן'!B17 -> T40B | G17: ='פירוט לסוכן'!G17+'פירוט לסוכן'!G42+'פירוט לסוכן'!G67+'פירוט לסוכן'!G92 -> 0 | H17: ='פירוט לסוכן'!H17+'פירוט לסוכן'!H42+'פירוט לסוכן'!H67+'פירוט לסוכן'!H92 -> 0 | J17: ='פירוט לסוכן'!B17 -> T40B | K17: ='פירוט לסוכן'!K17+'פירוט לסוכן'!K42+'פירוט לסוכן'!K67+'פירוט לסוכן'!K92 -> 4485 | L17: ='פירוט לסוכן'!L17+'פירוט לסוכן'!L42+'פירוט לסוכן'!L67+'פירוט לסוכן'!L92 -> 251160
B18: ='פירוט לסוכן'!B18 -> T066B | C18: ='פירוט לסוכן'!C18+'פירוט לסוכן'!C43+'פירוט לסוכן'!C68+'פירוט לסוכן'!C93 -> 390 | D18: ='פירוט לסוכן'!D18+'פירוט לסוכן'!D43+'פירוט לסוכן'!D68+'פירוט לסוכן'!D93 -> 43680 | F18: ='פירוט לסוכן'!B18 -> T066B | G18: ='פירוט לסוכן'!G18+'פירוט לסוכן'!G43+'פירוט לסוכן'!G68+'פירוט לסוכן'!G93 -> 95 | H18: ='פירוט לסוכן'!H18+'פירוט לסוכן'!H43+'פירוט לסוכן'!H68+'פירוט לסוכן'!H93 -> 10640 | J18: ='פירוט לסוכן'!B18 -> T066B | K18: ='פירוט לסוכן'!K18+'פירוט לסוכן'!K43+'פירוט לסוכן'!K68+'פירוט לסוכן'!K93 -> 1725 | L18: ='פירוט לסוכן'!L18+'פירוט לסוכן'!L43+'פירוט לסוכן'!L68+'פירוט לסוכן'!L93 -> 193200
B19: ='פירוט לסוכן'!B19 -> 3051 | C19: ='פירוט לסוכן'!C19+'פירוט לסוכן'!C44+'פירוט לסוכן'!C69+'פירוט לסוכן'!C94 -> 1326 | D19: ='פירוט לסוכן'!D19+'פירוט לסוכן'!D44+'פירוט לסוכן'!D69+'פירוט לסוכן'!D94 -> 165484.8 | F19: ='פירוט לסוכן'!B19 -> 3051 | G19: ='פירוט לסוכן'!G19+'פירוט לסוכן'!G44+'פירוט לסוכן'!G69+'פירוט לסוכן'!G94 -> 323 | H19: ='פירוט לסוכן'!H19+'פירוט לסוכן'!H44+'פירוט לסוכן'!H69+'פירוט לסוכן'!H94 -> 40310.4 | J19: ='פירוט לסוכן'!B19 -> 3051 | K19: ='פירוט לסוכן'!K19+'פירוט לסוכן'!K44+'פירוט לסוכן'!K69+'פירוט לסוכן'!K94 -> 5865 | L19: ='פירוט לסוכן'!L19+'פירוט לסוכן'!L44+'פירוט לסוכן'!L69+'פירוט לסוכן'!L94 -> 731952
... B27: ='פירוט לסוכן'!B27 -> T36B | C27: ='פירוט לסוכן'!C27+'פירוט לסוכן'!C52+'פירוט לסוכן'!C77+'פירוט לסוכן'!C102 -> 936 | D27: ='פירוט לסוכן'!D27+'פירוט לסוכן'!D52+'פירוט לסוכן'!D77+'פירוט לסוכן'!D102 -> 93600 | F27: ='פירוט לסוכן'!B27 -> T36B | G27: ='פירוט לסוכן'!G27+'פירוט לסוכן'!G52+'פירוט לסוכן'!G77+'פירוט לסוכן'!G102 -> 228 | H27: ='פירוט לסוכן'!H27+'פירוט לסוכן'!H52+'פירוט לסוכן'!H77+'פירוט לסוכן'!H102 -> 22800 | J27: ='פירוט לסוכן'!B27 -> T36B | K27: ='פירוט לסוכן'!K27+'פירוט לסוכן'!K52+'פירוט לסוכן'!K77+'פירוט לסוכן'!K102 -> 4260 | L27: ='פירוט לסוכן'!L27+'פירוט לסוכן'!L52+'פירוט לסוכן'!L77+'פירוט לסוכן'!L102 -> 426000
B28: סה"כ | C28: =SUM(C8:C27) -> 14820 | D28: =SUM(D8:D27) -> 1880236.8 | F28: סה"כ | G28: =SUM(G8:G27) -> 3705 | H28: =SUM(H8:H27) -> 447047.2 | J28: סה"כ | K28: =SUM(K8:K27) -> 72337 | L28: =SUM(L8:L27) -> 7448776.6
A30: בדיקת שפיות - סה"כ לכל ערוץ (כאן) מול סכום 4 הסוכנים בגיליון "פירוט לסוכן"
A31: ערוץ | B31: יחידות - סה"כ (כאן) | C31: יחידות - סה"כ (4 סוכנים, "פירוט לסוכן") | D31: התאמה (יחידות) | E31: מכירות - סה"כ (כאן) | F31: מכירות - סה"כ (4 סוכנים, "פירוט לסוכן") | G31: התאמה (מכירות)
A32: אורט | B32: =C28 -> 14820 | C32: ='פירוט לסוכן'!C28+'פירוט לסוכן'!C53+'פירוט לסוכן'!C78+'פירוט לסוכן'!C103 -> 14820 | D32: =IF(B32=C32,"TRUE","FALSE") -> TRUE | E32: =D28 -> 1880236.8 | F32: ='פירוט לסוכן'!D28+'פירוט לסוכן'!D53+'פירוט לסוכן'!D78+'פירוט לסוכן'!D103 -> 1880236.8 | G32: =IF(E32=F32,"TRUE","FALSE") -> TRUE
A33: פיזט | B33: =G28 -> 3705 | C33: ='פירוט לסוכן'!G28+'פירוט לסוכן'!G53+'פירוט לסוכן'!G78+'פירוט לסוכן'!G103 -> 3705 | D33: =IF(B33=C33,"TRUE","FALSE") -> TRUE | E33: =H28 -> 447047.2 | F33: ='פירוט לסוכן'!H28+'פירוט לסוכן'!H53+'פירוט לסוכן'!H78+'פירוט לסוכן'!H103 -> 447047.2 | G33: =IF(E33=F33,"TRUE","FALSE") -> TRUE
A34: בתי מרקחת | B34: =K28 -> 72337 | C34: ='פירוט לסוכן'!K28+'פירוט לסוכן'!K53+'פירוט לסוכן'!K78+'פירוט לסוכן'!K103 -> 72337 | D34: =IF(B34=C34,"TRUE","FALSE") -> TRUE | E34: =L28 -> 7448776.6 | F34: ='פירוט לסוכן'!L28+'פירוט לסוכן'!L53+'פירוט לסוכן'!L78+'פירוט לסוכן'!L103 -> 7448776.6 | G34: =IF(E34=F34,"TRUE","FALSE") -> TRUE
A35: סה"כ 3 ערוצים | B35: =SUM(B32:B34) -> 90862 | C35: =SUM(C32:C34) -> 90862 | D35: =IF(B35=C35,"TRUE","FALSE") -> TRUE | E35: =SUM(E32:E34) -> 9776060.6 | F35: =SUM(F32:F34) -> 9776060.6 | G35: =IF(E35=F35,"TRUE","FALSE") -> TRUE
A36: סה"כ 4 סוכנים ("פירוט לסוכן" שורות 108-111, מאומת כבר מול "Plan vs Actual (סוכן)") | B36: ='פירוט לסוכן'!B108+'פירוט לסוכן'!B109+'פירוט לסוכן'!B110+'פירוט לסוכן'!B111 -> 90862 | E36: ='פירוט לסוכן'!E108+'פירוט לסוכן'!E109+'פירוט לסוכן'!E110+'פירוט לסוכן'!E111 -> 9776060.6
A37: התאמה סופית (שרשרת מלאה: Plan vs Actual (סוכן) -> פירוט לסוכן -> ניתוח לפי ערוץ) | B37: =IF(B35=B36,"TRUE","FALSE") -> TRUE | E37: =IF(E35=E36,"TRUE","FALSE") -> TRUE
