Workbook

Sheet Index
A1: Sales Comparison 2025 vs 2026 - by Customer (NetSuite "1-Sales: Customer by Item")
A2: Calculation date: | B2: 46284
A3: Same 18-column format as Index in 2026-09-19-grouped-2025-vs-2026.xlsx (no annualized columns here - annualization lives inside each customer sheet only). "# Raw categories" is not meaningful for a single NetSuite customer - shown as N/A. Excludes Chemipal (150000, largest customer, explicitly out of scope per the user) and "- No Customer/Project -" (not a real customer).
A5: Group | B5: Sheet | C5: # Raw categories | D5: # Product Codes | E5: # Product Codes 2025 | F5: # Product Codes 2026 | G5: # DROP (sold 2025, 0 in 2026) | H5: # NEW (sold 2026, 0 in 2025) | I5: DROP — Quantity 2025 | J5: DROP — Amount 2025 (₪) | K5: NEW — Quantity 2026 | L5: NEW — Amount 2026 (₪) | M5: Quantity 2025 | N5: Quantity 2026 | O5: Qty Change % | P5: Amount 2025 (₪) | Q5: Amount 2026 (₪) | R5: Amount Change %
A6: 152501 קופ"ח כללית 1203-9 | B6: קופת חולים כללית | C6: N/A | D6: =COUNTA('קופת חולים כללית'!$A$9:$A$41) -> 33 | E6: =SUMPRODUCT(--(('קופת חולים כללית'!$C$9:$C$41<>0)+('קופת חולים כללית'!$H$9:$H$41<>0)>0)) -> 32 | F6: =SUMPRODUCT(--(('קופת חולים כללית'!$D$9:$D$41<>0)+('קופת חולים כללית'!$I$9:$I$41<>0)>0)) -> 32 | G6: ='קופת חולים כללית'!B5 -> 1 | H6: ='קופת חולים כללית'!D5 -> 1 | I6: ='קופת חולים כללית'!B6 -> -1 | J6: ='קופת חולים כללית'!D6 -> -62.43 | K6: ='קופת חולים כללית'!F6 -> -2 | L6: ='קופת חולים כללית'!H6 -> -1176 | M6: ='קופת חולים כללית'!C43 -> 152395 | N6: ='קופת חולים כללית'!D43 -> 110137 | O6: =IF('קופת חולים כללית'!C43=0,"N/A",('קופת חולים כללית'!D43-'קופת חולים כללית'!C43)/'קופת חולים כללית'!C43) -> -0.27729256 | P6: ='קופת חולים כללית'!H43 -> 3809616.4 | Q6: ='קופת חולים כללית'!I43 -> 2569653 | R6: =IF('קופת חולים כללית'!H43=0,"N/A",('קופת חולים כללית'!I43-'קופת חולים כללית'!H43)/'קופת חולים כללית'!H43) -> -0.32548247
A7: 155138 לקוח אינטרנט | B7: 155138 לקוח אינטרנט | C7: N/A | D7: =COUNTA('155138 לקוח אינטרנט'!$A$9:$A$728) -> 720 | E7: =SUMPRODUCT(--(('155138 לקוח אינטרנט'!$C$9:$C$728<>0)+('155138 לקוח אינטרנט'!$H$9:$H$728<>0)>0)) -> 618 | F7: =SUMPRODUCT(--(('155138 לקוח אינטרנט'!$D$9:$D$728<>0)+('155138 לקוח אינטרנט'!$I$9:$I$728<>0)>0)) -> 632 | G7: ='155138 לקוח אינטרנט'!B5 -> 88 | H7: ='155138 לקוח אינטרנט'!D5 -> 102 | I7: ='155138 לקוח אינטרנט'!B6 -> 580 | J7: ='155138 לקוח אינטרנט'!D6 -> 69822.79 | K7: ='155138 לקוח אינטרנט'!F6 -> 2375 | L7: ='155138 לקוח אינטרנט'!H6 -> 147591.2 | M7: ='155138 לקוח אינטרנט'!C730 -> 20444 | N7: ='155138 לקוח אינטרנט'!D730 -> 28580 | O7: =IF('155138 לקוח אינטרנט'!C730=0,"N/A",('155138 לקוח אינטרנט'!D730-'155138 לקוח אינטרנט'!C730)/'155138 לקוח אינטרנט'!C730) -> 0.39796517 | P7: ='155138 לקוח אינטרנט'!H730 -> 1655344.3 | Q7: ='155138 לקוח אינטרנט'!I730 -> 3196334.6 | R7: =IF('155138 לקוח אינטרנט'!H730=0,"N/A",('155138 לקוח אינטרנט'!I730-'155138 לקוח אינטרנט'!H730)/'155138 לקוח אינטרנט'!H730) -> 0.93091833
A8: 160251 AMAZON | B8: 160251 AMAZON | C8: N/A | D8: =COUNTA('160251 AMAZON'!$A$9:$A$87) -> 79 | E8: =SUMPRODUCT(--(('160251 AMAZON'!$C$9:$C$87<>0)+('160251 AMAZON'!$H$9:$H$87<>0)>0)) -> 73 | F8: =SUMPRODUCT(--(('160251 AMAZON'!$D$9:$D$87<>0)+('160251 AMAZON'!$I$9:$I$87<>0)>0)) -> 62 | G8: ='160251 AMAZON'!B5 -> 17 | H8: ='160251 AMAZON'!D5 -> 6 | I8: ='160251 AMAZON'!B6 -> 448 | J8: ='160251 AMAZON'!D6 -> 94856.4 | K8: ='160251 AMAZON'!F6 -> 47 | L8: ='160251 AMAZON'!H6 -> 3274.06 | M8: ='160251 AMAZON'!C89 -> 27158 | N8: ='160251 AMAZON'!D89 -> 18808 | O8: =IF('160251 AMAZON'!C89=0,"N/A",('160251 AMAZON'!D89-'160251 AMAZON'!C89)/'160251 AMAZON'!C89) -> -0.30746005 | P8: ='160251 AMAZON'!H89 -> 2705391.2 | Q8: ='160251 AMAZON'!I89 -> 1632890.8 | R8: =IF('160251 AMAZON'!H89=0,"N/A",('160251 AMAZON'!I89-'160251 AMAZON'!H89)/'160251 AMAZON'!H89) -> -0.3964308
A9: 150390 סופר פארם ישראל | B9: 150390 סופר פארם ישראל | C9: N/A | D9: =COUNTA('150390 סופר פארם ישראל'!$A$9:$A$29) -> 21 | E9: =SUMPRODUCT(--(('150390 סופר פארם ישראל'!$C$9:$C$29<>0)+('150390 סופר פארם ישראל'!$H$9:$H$29<>0)>0)) -> 21 | F9: =SUMPRODUCT(--(('150390 סופר פארם ישראל'!$D$9:$D$29<>0)+('150390 סופר פארם ישראל'!$I$9:$I$29<>0)>0)) -> 20 | G9: ='150390 סופר פארם ישראל'!B5 -> 1 | H9: ='150390 סופר פארם ישראל'!D5 -> 0 | I9: ='150390 סופר פארם ישראל'!B6 -> 0 | J9: ='150390 סופר פארם ישראל'!D6 -> 7427.59 | K9: ='150390 סופר פארם ישראל'!F6 -> 0 | L9: ='150390 סופר פארם ישראל'!H6 -> 0 | M9: ='150390 סופר פארם ישראל'!C31 -> 118392 | N9: ='150390 סופר פארם ישראל'!D31 -> 62455 | O9: =IF('150390 סופר פארם ישראל'!C31=0,"N/A",('150390 סופר פארם ישראל'!D31-'150390 סופר פארם ישראל'!C31)/'150390 סופר פארם ישראל'!C31) -> -0.4724728 | P9: ='150390 סופר פארם ישראל'!H31 -> 1708656.9 | Q9: ='150390 סופר פארם ישראל'!I31 -> 1113833.9 | R9: =IF('150390 סופר פארם ישראל'!H31=0,"N/A",('150390 סופר פארם ישראל'!I31-'150390 סופר פארם ישראל'!H31)/'150390 סופר פארם ישראל'!H31) -> -0.34812315
A10: 160134 SUPER-PHARM HOLDING. SP.ZO.O | B10: 160134 SUPER-PHARM HOLDING. SP | C10: N/A | D10: =COUNTA('160134 SUPER-PHARM HOLDING. SP'!$A$9:$A$143) -> 135 | E10: =SUMPRODUCT(--(('160134 SUPER-PHARM HOLDING. SP'!$C$9:$C$143<>0)+('160134 SUPER-PHARM HOLDING. SP'!$H$9:$H$143<>0)>0)) -> 130 | F10: =SUMPRODUCT(--(('160134 SUPER-PHARM HOLDING. SP'!$D$9:$D$143<>0)+('160134 SUPER-PHARM HOLDING. SP'!$I$9:$I$143<>0)>0)) -> 123 | G10: ='160134 SUPER-PHARM HOLDING. SP'!B5 -> 12 | H10: ='160134 SUPER-PHARM HOLDING. SP'!D5 -> 5 | I10: ='160134 SUPER-PHARM HOLDING. SP'!B6 -> 3550 | J10: ='160134 SUPER-PHARM HOLDING. SP'!D6 -> 92320.46 | K10: ='160134 SUPER-PHARM HOLDING. SP'!F6 -> 250 | L10: ='160134 SUPER-PHARM HOLDING. SP'!H6 -> 11540.57 | M10: ='160134 SUPER-PHARM HOLDING. SP'!C145 -> 48363 | N10: ='160134 SUPER-PHARM HOLDING. SP'!D145 -> 28188 | O10: =IF('160134 SUPER-PHARM HOLDING. SP'!C145=0,"N/A",('160134 SUPER-PHARM HOLDING. SP'!D145-'160134 SUPER-PHARM HOLDING. SP'!C145)/'160134 SUPER-PHARM HOLDING. SP'!C145) -> -0.41715774 | P10: ='160134 SUPER-PHARM HOLDING. SP'!H145 -> 902537.64 | Q10: ='160134 SUPER-PHARM HOLDING. SP'!I145 -> 474182.59 | R10: =IF('160134 SUPER-PHARM HOLDING. SP'!H145=0,"N/A",('160134 SUPER-PHARM HOLDING. SP'!I145-'160134 SUPER-PHARM HOLDING. SP'!H145)/'160134 SUPER-PHARM HOLDING. SP'!H145) -> -0.47461184
A11: 160351 ORTHO- PARTNER AG. | B11: 160351 ORTHO- PARTNER AG. | C11: N/A | D11: =COUNTA('160351 ORTHO- PARTNER AG.'!$A$9:$A$119) -> 111 | E11: =SUMPRODUCT(--(('160351 ORTHO- PARTNER AG.'!$C$9:$C$119<>0)+('160351 ORTHO- PARTNER AG.'!$H$9:$H$119<>0)>0)) -> 99 | F11: =SUMPRODUCT(--(('160351 ORTHO- PARTNER AG.'!$D$9:$D$119<>0)+('160351 ORTHO- PARTNER AG.'!$I$9:$I$119<>0)>0)) -> 78 | G11: ='160351 ORTHO- PARTNER AG.'!B5 -> 33 | H11: ='160351 ORTHO- PARTNER AG.'!D5 -> 12 | I11: ='160351 ORTHO- PARTNER AG.'!B6 -> 563 | J11: ='160351 ORTHO- PARTNER AG.'!D6 -> 21452.36 | K11: ='160351 ORTHO- PARTNER AG.'!F6 -> 131 | L11: ='160351 ORTHO- PARTNER AG.'!H6 -> 4054.38 | M11: ='160351 ORTHO- PARTNER AG.'!C121 -> 6959 | N11: ='160351 ORTHO- PARTNER AG.'!D121 -> 6740 | O11: =IF('160351 ORTHO- PARTNER AG.'!C121=0,"N/A",('160351 ORTHO- PARTNER AG.'!D121-'160351 ORTHO- PARTNER AG.'!C121)/'160351 ORTHO- PARTNER AG.'!C121) -> -0.031470039 | P11: ='160351 ORTHO- PARTNER AG.'!H121 -> 405920.85 | Q11: ='160351 ORTHO- PARTNER AG.'!I121 -> 344263.09 | R11: =IF('160351 ORTHO- PARTNER AG.'!H121=0,"N/A",('160351 ORTHO- PARTNER AG.'!I121-'160351 ORTHO- PARTNER AG.'!H121)/'160351 ORTHO- PARTNER AG.'!H121) -> -0.15189602
A12: 160955 ORTOPROFIL PROD. ROMANIA | B12: 160955 ORTOPROFIL PROD. ROMANIA | C12: N/A | D12: =COUNTA('160955 ORTOPROFIL PROD. ROMANIA'!$A$9:$A$99) -> 91 | E12: =SUMPRODUCT(--(('160955 ORTOPROFIL PROD. ROMANIA'!$C$9:$C$99<>0)+('160955 ORTOPROFIL PROD. ROMANIA'!$H$9:$H$99<>0)>0)) -> 83 | F12: =SUMPRODUCT(--(('160955 ORTOPROFIL PROD. ROMANIA'!$D$9:$D$99<>0)+('160955 ORTOPROFIL PROD. ROMANIA'!$I$9:$I$99<>0)>0)) -> 74 | G12: ='160955 ORTOPROFIL PROD. ROMANIA'!B5 -> 17 | H12: ='160955 ORTOPROFIL PROD. ROMANIA'!D5 -> 8 | I12: ='160955 ORTOPROFIL PROD. ROMANIA'!B6 -> 184 | J12: ='160955 ORTOPROFIL PROD. ROMANIA'!D6 -> 2098.73 | K12: ='160955 ORTOPROFIL PROD. ROMANIA'!F6 -> 147 | L12: ='160955 ORTOPROFIL PROD. ROMANIA'!H6 -> 6167.14 | M12: ='160955 ORTOPROFIL PROD. ROMANIA'!C101 -> 13479 | N12: ='160955 ORTOPROFIL PROD. ROMANIA'!D101 -> 9703 | O12: =IF('160955 ORTOPROFIL PROD. ROMANIA'!C101=0,"N/A",('160955 ORTOPROFIL PROD. ROMANIA'!D101-'160955 ORTOPROFIL PROD. ROMANIA'!C101)/'160955 ORTOPROFIL PROD. ROMANIA'!C101) -> -0.28013948 | P12: ='160955 ORTOPROFIL PROD. ROMANIA'!H101 -> 407234.61 | Q12: ='160955 ORTOPROFIL PROD. ROMANIA'!I101 -> 300835.19 | R12: =IF('160955 ORTOPROFIL PROD. ROMANIA'!H101=0,"N/A",('160955 ORTOPROFIL PROD. ROMANIA'!I101-'160955 ORTOPROFIL PROD. ROMANIA'!H101)/'160955 ORTOPROFIL PROD. ROMANIA'!H101) -> -0.26127303
A13: C02266 SANAFLEX L.P | B13: C02266 SANAFLEX L.P | C13: N/A | D13: =COUNTA('C02266 SANAFLEX L.P'!$A$9:$A$212) -> 204 | E13: =SUMPRODUCT(--(('C02266 SANAFLEX L.P'!$C$9:$C$212<>0)+('C02266 SANAFLEX L.P'!$H$9:$H$212<>0)>0)) -> 185 | F13: =SUMPRODUCT(--(('C02266 SANAFLEX L.P'!$D$9:$D$212<>0)+('C02266 SANAFLEX L.P'!$I$9:$I$212<>0)>0)) -> 173 | G13: ='C02266 SANAFLEX L.P'!B5 -> 31 | H13: ='C02266 SANAFLEX L.P'!D5 -> 19 | I13: ='C02266 SANAFLEX L.P'!B6 -> 347 | J13: ='C02266 SANAFLEX L.P'!D6 -> 10736.31 | K13: ='C02266 SANAFLEX L.P'!F6 -> 154 | L13: ='C02266 SANAFLEX L.P'!H6 -> 3246.9 | M13: ='C02266 SANAFLEX L.P'!C214 -> 20757 | N13: ='C02266 SANAFLEX L.P'!D214 -> 18128 | O13: =IF('C02266 SANAFLEX L.P'!C214=0,"N/A",('C02266 SANAFLEX L.P'!D214-'C02266 SANAFLEX L.P'!C214)/'C02266 SANAFLEX L.P'!C214) -> -0.12665607 | P13: ='C02266 SANAFLEX L.P'!H214 -> 395351.38 | Q13: ='C02266 SANAFLEX L.P'!I214 -> 307055.17 | R13: =IF('C02266 SANAFLEX L.P'!H214=0,"N/A",('C02266 SANAFLEX L.P'!I214-'C02266 SANAFLEX L.P'!H214)/'C02266 SANAFLEX L.P'!H214) -> -0.22333604
A14: 160920 SALUS | B14: 160920 SALUS | C14: N/A | D14: =COUNTA('160920 SALUS'!$A$9:$A$225) -> 217 | E14: =SUMPRODUCT(--(('160920 SALUS'!$C$9:$C$225<>0)+('160920 SALUS'!$H$9:$H$225<>0)>0)) -> 195 | F14: =SUMPRODUCT(--(('160920 SALUS'!$D$9:$D$225<>0)+('160920 SALUS'!$I$9:$I$225<>0)>0)) -> 151 | G14: ='160920 SALUS'!B5 -> 66 | H14: ='160920 SALUS'!D5 -> 22 | I14: ='160920 SALUS'!B6 -> 797 | J14: ='160920 SALUS'!D6 -> 28651.54 | K14: ='160920 SALUS'!F6 -> 991 | L14: ='160920 SALUS'!H6 -> 14625 | M14: ='160920 SALUS'!C227 -> 18268 | N14: ='160920 SALUS'!D227 -> 20601 | O14: =IF('160920 SALUS'!C227=0,"N/A",('160920 SALUS'!D227-'160920 SALUS'!C227)/'160920 SALUS'!C227) -> 0.12770966 | P14: ='160920 SALUS'!H227 -> 319558.55 | Q14: ='160920 SALUS'!I227 -> 365555.25 | R14: =IF('160920 SALUS'!H227=0,"N/A",('160920 SALUS'!I227-'160920 SALUS'!H227)/'160920 SALUS'!H227) -> 0.14393825
A15: 160951 MEDIPAL COMPANY | B15: 160951 MEDIPAL COMPANY | C15: N/A | D15: =COUNTA('160951 MEDIPAL COMPANY'!$A$9:$A$98) -> 90 | E15: =SUMPRODUCT(--(('160951 MEDIPAL COMPANY'!$C$9:$C$98<>0)+('160951 MEDIPAL COMPANY'!$H$9:$H$98<>0)>0)) -> 90 | F15: =SUMPRODUCT(--(('160951 MEDIPAL COMPANY'!$D$9:$D$98<>0)+('160951 MEDIPAL COMPANY'!$I$9:$I$98<>0)>0)) -> 0 | G15: ='160951 MEDIPAL COMPANY'!B5 -> 90 | H15: ='160951 MEDIPAL COMPANY'!D5 -> 0 | I15: ='160951 MEDIPAL COMPANY'!B6 -> 6687 | J15: ='160951 MEDIPAL COMPANY'!D6 -> 256772.1 | K15: ='160951 MEDIPAL COMPANY'!F6 -> 0 | L15: ='160951 MEDIPAL COMPANY'!H6 -> 0 | M15: ='160951 MEDIPAL COMPANY'!C100 -> 6687 | N15: ='160951 MEDIPAL COMPANY'!D100 -> 0 | O15: =IF('160951 MEDIPAL COMPANY'!C100=0,"N/A",('160951 MEDIPAL COMPANY'!D100-'160951 MEDIPAL COMPANY'!C100)/'160951 MEDIPAL COMPANY'!C100) -> -1 | P15: ='160951 MEDIPAL COMPANY'!H100 -> 256772.1 | Q15: ='160951 MEDIPAL COMPANY'!I100 -> 0 | R15: =IF('160951 MEDIPAL COMPANY'!H100=0,"N/A",('160951 MEDIPAL COMPANY'!I100-'160951 MEDIPAL COMPANY'!H100)/'160951 MEDIPAL COMPANY'!H100) -> -1
A16: 160226 HEALTH CARE PROD. GMBH | B16: 160226 HEALTH CARE PROD. GMBH | C16: N/A | D16: =COUNTA('160226 HEALTH CARE PROD. GMBH'!$A$9:$A$45) -> 37 | E16: =SUMPRODUCT(--(('160226 HEALTH CARE PROD. GMBH'!$C$9:$C$45<>0)+('160226 HEALTH CARE PROD. GMBH'!$H$9:$H$45<>0)>0)) -> 37 | F16: =SUMPRODUCT(--(('160226 HEALTH CARE PROD. GMBH'!$D$9:$D$45<>0)+('160226 HEALTH CARE PROD. GMBH'!$I$9:$I$45<>0)>0)) -> 23 | G16: ='160226 HEALTH CARE PROD. GMBH'!B5 -> 14 | H16: ='160226 HEALTH CARE PROD. GMBH'!D5 -> 0 | I16: ='160226 HEALTH CARE PROD. GMBH'!B6 -> 653 | J16: ='160226 HEALTH CARE PROD. GMBH'!D6 -> 14501.3 | K16: ='160226 HEALTH CARE PROD. GMBH'!F6 -> 0 | L16: ='160226 HEALTH CARE PROD. GMBH'!H6 -> 0 | M16: ='160226 HEALTH CARE PROD. GMBH'!C47 -> 12986 | N16: ='160226 HEALTH CARE PROD. GMBH'!D47 -> 12906 | O16: =IF('160226 HEALTH CARE PROD. GMBH'!C47=0,"N/A",('160226 HEALTH CARE PROD. GMBH'!D47-'160226 HEALTH CARE PROD. GMBH'!C47)/'160226 HEALTH CARE PROD. GMBH'!C47) -> -0.0061604805 | P16: ='160226 HEALTH CARE PROD. GMBH'!H47 -> 122339 | Q16: ='160226 HEALTH CARE PROD. GMBH'!I47 -> 96129.82 | R16: =IF('160226 HEALTH CARE PROD. GMBH'!H47=0,"N/A",('160226 HEALTH CARE PROD. GMBH'!I47-'160226 HEALTH CARE PROD. GMBH'!H47)/'160226 HEALTH CARE PROD. GMBH'!H47) -> -0.21423405
A17: 160150 MAX KONNARIS LTD | B17: 160150 MAX KONNARIS LTD | C17: N/A | D17: =COUNTA('160150 MAX KONNARIS LTD'!$A$9:$A$253) -> 245 | E17: =SUMPRODUCT(--(('160150 MAX KONNARIS LTD'!$C$9:$C$253<>0)+('160150 MAX KONNARIS LTD'!$H$9:$H$253<>0)>0)) -> 177 | F17: =SUMPRODUCT(--(('160150 MAX KONNARIS LTD'!$D$9:$D$253<>0)+('160150 MAX KONNARIS LTD'!$I$9:$I$253<>0)>0)) -> 154 | G17: ='160150 MAX KONNARIS LTD'!B5 -> 91 | H17: ='160150 MAX KONNARIS LTD'!D5 -> 68 | I17: ='160150 MAX KONNARIS LTD'!B6 -> 1696 | J17: ='160150 MAX KONNARIS LTD'!D6 -> 47367.29 | K17: ='160150 MAX KONNARIS LTD'!F6 -> 754 | L17: ='160150 MAX KONNARIS LTD'!H6 -> 27727.77 | M17: ='160150 MAX KONNARIS LTD'!C255 -> 3507 | N17: ='160150 MAX KONNARIS LTD'!D255 -> 2337 | O17: =IF('160150 MAX KONNARIS LTD'!C255=0,"N/A",('160150 MAX KONNARIS LTD'!D255-'160150 MAX KONNARIS LTD'!C255)/'160150 MAX KONNARIS LTD'!C255) -> -0.33361848 | P17: ='160150 MAX KONNARIS LTD'!H255 -> 86855.65 | Q17: ='160150 MAX KONNARIS LTD'!I255 -> 60462.39 | R17: =IF('160150 MAX KONNARIS LTD'!H255=0,"N/A",('160150 MAX KONNARIS LTD'!I255-'160150 MAX KONNARIS LTD'!H255)/'160150 MAX KONNARIS LTD'!H255) -> -0.30387499
A18: 151209 רוני אורטופדיה בע"מ - רמבם | B18: 151209 רוני אורטופדיה בע"מ - | C18: N/A | D18: =COUNTA('151209 רוני אורטופדיה בע"מ -'!$A$9:$A$173) -> 165 | E18: =SUMPRODUCT(--(('151209 רוני אורטופדיה בע"מ -'!$C$9:$C$173<>0)+('151209 רוני אורטופדיה בע"מ -'!$H$9:$H$173<>0)>0)) -> 148 | F18: =SUMPRODUCT(--(('151209 רוני אורטופדיה בע"מ -'!$D$9:$D$173<>0)+('151209 רוני אורטופדיה בע"מ -'!$I$9:$I$173<>0)>0)) -> 82 | G18: ='151209 רוני אורטופדיה בע"מ -'!B5 -> 83 | H18: ='151209 רוני אורטופדיה בע"מ -'!D5 -> 17 | I18: ='151209 רוני אורטופדיה בע"מ -'!B6 -> 243 | J18: ='151209 רוני אורטופדיה בע"מ -'!D6 -> 13460.59 | K18: ='151209 רוני אורטופדיה בע"מ -'!F6 -> 52 | L18: ='151209 רוני אורטופדיה בע"מ -'!H6 -> 3461.13 | M18: ='151209 רוני אורטופדיה בע"מ -'!C175 -> 600 | N18: ='151209 רוני אורטופדיה בע"מ -'!D175 -> 502 | O18: =IF('151209 רוני אורטופדיה בע"מ -'!C175=0,"N/A",('151209 רוני אורטופדיה בע"מ -'!D175-'151209 רוני אורטופדיה בע"מ -'!C175)/'151209 רוני אורטופדיה בע"מ -'!C175) -> -0.16333333 | P18: ='151209 רוני אורטופדיה בע"מ -'!H175 -> 54526.13 | Q18: ='151209 רוני אורטופדיה בע"מ -'!I175 -> 63540.64 | R18: =IF('151209 רוני אורטופדיה בע"מ -'!H175=0,"N/A",('151209 רוני אורטופדיה בע"מ -'!I175-'151209 רוני אורטופדיה בע"מ -'!H175)/'151209 רוני אורטופדיה בע"מ -'!H175) -> 0.16532459
A19: 160450 OY. EA. AB. | B19: 160450 OY. EA. AB. | C19: N/A | D19: =COUNTA('160450 OY. EA. AB.'!$A$9:$A$191) -> 183 | E19: =SUMPRODUCT(--(('160450 OY. EA. AB.'!$C$9:$C$191<>0)+('160450 OY. EA. AB.'!$H$9:$H$191<>0)>0)) -> 128 | F19: =SUMPRODUCT(--(('160450 OY. EA. AB.'!$D$9:$D$191<>0)+('160450 OY. EA. AB.'!$I$9:$I$191<>0)>0)) -> 145 | G19: ='160450 OY. EA. AB.'!B5 -> 38 | H19: ='160450 OY. EA. AB.'!D5 -> 55 | I19: ='160450 OY. EA. AB.'!B6 -> 533 | J19: ='160450 OY. EA. AB.'!D6 -> 15504.74 | K19: ='160450 OY. EA. AB.'!F6 -> 360 | L19: ='160450 OY. EA. AB.'!H6 -> 16342.42 | M19: ='160450 OY. EA. AB.'!C193 -> 2672 | N19: ='160450 OY. EA. AB.'!D193 -> 1516 | O19: =IF('160450 OY. EA. AB.'!C193=0,"N/A",('160450 OY. EA. AB.'!D193-'160450 OY. EA. AB.'!C193)/'160450 OY. EA. AB.'!C193) -> -0.43263473 | P19: ='160450 OY. EA. AB.'!H193 -> 64554.59 | Q19: ='160450 OY. EA. AB.'!I193 -> 43116.44 | R19: =IF('160450 OY. EA. AB.'!H193=0,"N/A",('160450 OY. EA. AB.'!I193-'160450 OY. EA. AB.'!H193)/'160450 OY. EA. AB.'!H193) -> -0.33209335
A20: 150366 א.א.אורטופדיה איתי-יהוד | B20: 150366 א.א.אורטופדיה איתי-יהוד | C20: N/A | D20: =COUNTA('150366 א.א.אורטופדיה איתי-יהוד'!$A$9:$A$104) -> 96 | E20: =SUMPRODUCT(--(('150366 א.א.אורטופדיה איתי-יהוד'!$C$9:$C$104<>0)+('150366 א.א.אורטופדיה איתי-יהוד'!$H$9:$H$104<>0)>0)) -> 68 | F20: =SUMPRODUCT(--(('150366 א.א.אורטופדיה איתי-יהוד'!$D$9:$D$104<>0)+('150366 א.א.אורטופדיה איתי-יהוד'!$I$9:$I$104<>0)>0)) -> 63 | G20: ='150366 א.א.אורטופדיה איתי-יהוד'!B5 -> 33 | H20: ='150366 א.א.אורטופדיה איתי-יהוד'!D5 -> 28 | I20: ='150366 א.א.אורטופדיה איתי-יהוד'!B6 -> 187 | J20: ='150366 א.א.אורטופדיה איתי-יהוד'!D6 -> 12103.28 | K20: ='150366 א.א.אורטופדיה איתי-יהוד'!F6 -> -30 | L20: ='150366 א.א.אורטופדיה איתי-יהוד'!H6 -> 695.09 | M20: ='150366 א.א.אורטופדיה איתי-יהוד'!C106 -> 864 | N20: ='150366 א.א.אורטופדיה איתי-יהוד'!D106 -> 588 | O20: =IF('150366 א.א.אורטופדיה איתי-יהוד'!C106=0,"N/A",('150366 א.א.אורטופדיה איתי-יהוד'!D106-'150366 א.א.אורטופדיה איתי-יהוד'!C106)/'150366 א.א.אורטופדיה איתי-יהוד'!C106) -> -0.31944444 | P20: ='150366 א.א.אורטופדיה איתי-יהוד'!H106 -> 58517.41 | Q20: ='150366 א.א.אורטופדיה איתי-יהוד'!I106 -> 46019.93 | R20: =IF('150366 א.א.אורטופדיה איתי-יהוד'!H106=0,"N/A",('150366 א.א.אורטופדיה איתי-יהוד'!I106-'150366 א.א.אורטופדיה איתי-יהוד'!H106)/'150366 א.א.אורטופדיה איתי-יהוד'!H106) -> -0.21356858
A21: 157464 מדיקל הצפון ב.מ-חורי | B21: 157464 מדיקל הצפון ב.מ-חורי | C21: N/A | D21: =COUNTA('157464 מדיקל הצפון ב.מ-חורי'!$A$9:$A$220) -> 212 | E21: =SUMPRODUCT(--(('157464 מדיקל הצפון ב.מ-חורי'!$C$9:$C$220<>0)+('157464 מדיקל הצפון ב.מ-חורי'!$H$9:$H$220<>0)>0)) -> 168 | F21: =SUMPRODUCT(--(('157464 מדיקל הצפון ב.מ-חורי'!$D$9:$D$220<>0)+('157464 מדיקל הצפון ב.מ-חורי'!$I$9:$I$220<>0)>0)) -> 147 | G21: ='157464 מדיקל הצפון ב.מ-חורי'!B5 -> 65 | H21: ='157464 מדיקל הצפון ב.מ-חורי'!D5 -> 44 | I21: ='157464 מדיקל הצפון ב.מ-חורי'!B6 -> 188 | J21: ='157464 מדיקל הצפון ב.מ-חורי'!D6 -> 13951.94 | K21: ='157464 מדיקל הצפון ב.מ-חורי'!F6 -> 123 | L21: ='157464 מדיקל הצפון ב.מ-חורי'!H6 -> 10518.59 | M21: ='157464 מדיקל הצפון ב.מ-חורי'!C222 -> 589 | N21: ='157464 מדיקל הצפון ב.מ-חורי'!D222 -> 617 | O21: =IF('157464 מדיקל הצפון ב.מ-חורי'!C222=0,"N/A",('157464 מדיקל הצפון ב.מ-חורי'!D222-'157464 מדיקל הצפון ב.מ-חורי'!C222)/'157464 מדיקל הצפון ב.מ-חורי'!C222) -> 0.0475382 | P21: ='157464 מדיקל הצפון ב.מ-חורי'!H222 -> 46725.38 | Q21: ='157464 מדיקל הצפון ב.מ-חורי'!I222 -> 50813.46 | R21: =IF('157464 מדיקל הצפון ב.מ-חורי'!H222=0,"N/A",('157464 מדיקל הצפון ב.מ-חורי'!I222-'157464 מדיקל הצפון ב.מ-חורי'!H222)/'157464 מדיקל הצפון ב.מ-חורי'!H222) -> 0.087491637

Sheet קופת חולים כללית
A1: Sales Comparison 2025 vs 2026 (Annualized) - Customer: 152501 קופ"ח כללית 1203-9 (by Product CODE)
A2: Calculation date: | B2: 46284
A3: Source: NetSuite report "1-Sales: Customer by Item" (01/01/2025-31/12/2026), customer = "152501 קופ"ח כללית 1203-9" only (exact match on the "Customer" column). Product CODE = column "Item: Name" (F in the original report) - NOT "Item: Name (Grouped)" (E), which carries a PARENT prefix. 2025 = columns J/K (Quantity/Amount Net); 2026 = columns O/P. Multiple rows per CODE per customer (one per unit-price tier) are summed (SUMIFS) per CODE, not taken from a single row. Raw rows kept unchanged in the shared "Source" sheet (filtered to only these 16 customers, not the full 32,141-row report). IMPORTANT: the source file’s own header states the report range as "01 January 2025 - 31 December 2026", but has no per-row date/timestamp field, so the exact 2026 cutoff cannot be verified from the data itself. Same assumption used across this whole workbook for consistency: 2026 actual covers approximately 9.5 months (1 Jan - 15 Sep).
A4: Annualization note: 2026 actual data is assumed to cover approximately 9.5 months (1 Jan - 15 Sep 2026), consistent with the rest of this workbook. Scaled to a full year via a simple linear factor = 12 / 9.5 (≈ 1.263158) - straight-line extrapolation, does NOT account for seasonality. Treat as an estimate. | I4: Months in full year: | J4: 12 | K4: Months covered by 2026 actual (assumed 1/1–15/9): | L4: 9.5
A5: # DROP (sold 2025, 0 in 2026): | B5: =SUMPRODUCT(--(((C9:C41<>0)+(H9:H41<>0)>0)*((D9:D41=0)*(I9:I41=0)))) -> 1 | C5: # NEW (sold 2026, 0 in 2025): | D5: =SUMPRODUCT(--(((D9:D41<>0)+(I9:I41<>0)>0)*((C9:C41=0)*(H9:H41=0)))) -> 1 | I5: Normalization factor (J4/L4): | J5: =J4/L4 -> 1.2631579
A6: DROP — Quantity 2025: | B6: =SUMPRODUCT(--(((C9:C41<>0)+(H9:H41<>0)>0)*((D9:D41=0)*(I9:I41=0)))*C9:C41) -> -1 | C6: DROP — Amount 2025 (₪): | D6: =SUMPRODUCT(--(((C9:C41<>0)+(H9:H41<>0)>0)*((D9:D41=0)*(I9:I41=0)))*H9:H41) -> -62.43 | E6: NEW — Quantity 2026: | F6: =SUMPRODUCT(--(((D9:D41<>0)+(I9:I41<>0)>0)*((C9:C41=0)*(H9:H41=0)))*D9:D41) -> -2 | G6: NEW — Amount 2026 (₪): | H6: =SUMPRODUCT(--(((D9:D41<>0)+(I9:I41<>0)>0)*((C9:C41=0)*(H9:H41=0)))*I9:I41) -> -1176
A8: Product Code | B8: Item Display Name | C8: Quantity 2025 | D8: Quantity 2026 (Actual, partial year) | E8: Quantity 2026 (Annualized) | F8: Quantity Change (Annualized vs 2025) | G8: Quantity Change % (Annualized vs 2025) | H8: Amount 2025 (₪) | I8: Amount 2026 (Actual, partial year) (₪) | J8: Amount 2026 (Annualized) (₪) | K8: Amount Change (Annualized vs 2025) (₪) | L8: Amount Change % (Annualized vs 2025) | M8: Note
A9: KST422 0 | B9: =IFERROR(INDEX('Source'!$C:$C,MATCH($A9,'Source'!$B:$B,0)),"") -> מגן ברך עם כרית ג'ל | C9: =SUMIFS('Source'!$D:$D,'Source'!$A:$A,"152501 קופ""ח כללית 1203-9",'Source'!$B:$B,$A9) -> 13299 | D9: =SUMIFS('Source'!$F:$F,'Source'!$A:$A,"152501 קופ""ח כללית 1203-9",'Source'!$B:$B,$A9) -> 9589 | E9: =D9*$J$5 -> 12112.421 | F9: =E9-C9 -> -1186.5789 | G9: =IF(AND(C9=0,E9=0),0,IF(C9=0,"New",(E9-C9)/C9)) -> -0.089223171 | H9: =SUMIFS('Source'!$E:$E,'Source'!$A:$A,"152501 קופ""ח כללית 1203-9",'Source'!$B:$B,$A9) -> 577794.6 | I9: =SUMIFS('Source'!$G:$G,'Source'!$A:$A,"152501 קופ""ח כללית 1203-9",'Source'!$B:$B,$A9) -> 396984.6 | J9: =I9*$J$5 -> 501454.23 | K9: =J9-H9 -> -76340.368 | L9: =IF(AND(H9=0,J9=0),0,IF(H9=0,"New",(J9-H9)/H9)) -> -0.13212371 | M9: =IF(AND(OR(C9<>0,H9<>0),D9=0,I9=0),"DROP",IF(AND(OR(D9<>0,I9<>0),C9=0,H9=0),"NEW",""))
A10: K078 L | B10: =IFERROR(INDEX('Source'!$C:$C,MATCH($A10,'Source'!$B:$B,0)),"") -> חגורת גב+סגירה כפולה | C10: =SUMIFS('Source'!$D:$D,'Source'!$A:$A,"152501 קופ""ח כללית 1203-9",'Source'!$B:$B,$A10) -> 7450 | D10: =SUMIFS('Source'!$F:$F,'Source'!$A:$A,"152501 קופ""ח כללית 1203-9",'Source'!$B:$B,$A10) -> 5000 | E10: =D10*$J$5 -> 6315.7895 | F10: =E10-C10 -> -1134.2105 | G10: =IF(AND(C10=0,E10=0),0,IF(C10=0,"New",(E10-C10)/C10)) -> -0.15224302 | H10: =SUMIFS('Source'!$E:$E,'Source'!$A:$A,"152501 קופ""ח כללית 1203-9",'Source'!$B:$B,$A10) -> 422328 | I10: =SUMIFS('Source'!$G:$G,'Source'!$A:$A,"152501 קופ""ח כללית 1203-9",'Source'!$B:$B,$A10) -> 272050 | J10: =I10*$J$5 -> 343642.11 | K10: =J10-H10 -> -78685.895 | L10: =IF(AND(H10=0,J10=0),0,IF(H10=0,"New",(J10-H10)/H10)) -> -0.18631465 | M10: =IF(AND(OR(C10<>0,H10<>0),D10=0,I10=0),"DROP",IF(AND(OR(D10<>0,I10<>0),C10=0,H10=0),"NEW",""))
A11: K078 XL | B11: =IFERROR(INDEX('Source'!$C:$C,MATCH($A11,'Source'!$B:$B,0)),"") -> חגורת גב+סגירה כפולה | C11: =SUMIFS('Source'!$D:$D,'Source'!$A:$A,"152501 קופ""ח כללית 1203-9",'Source'!$B:$B,$A11) -> 5850 | D11: =SUMIFS('Source'!$F:$F,'Source'!$A:$A,"152501 קופ""ח כללית 1203-9",'Source'!$B:$B,$A11) -> 3700 | E11: =D11*$J$5 -> 4673.6842 | F11: =E11-C11 -> -1176.3158 | G11: =IF(AND(C11=0,E11=0),0,IF(C11=0,"New",(E11-C11)/C11)) -> -0.20107962 | H11: =SUMIFS('Source'!$E:$E,'Source'!$A:$A,"152501 קופ""ח כללית 1203-9",'Source'!$B:$B,$A11) -> 332000 | I11: =SUMIFS('Source'!$G:$G,'Source'!$A:$A,"152501 קופ""ח כללית 1203-9",'Source'!$B:$B,$A11) -> 201317 | J11: =I11*$J$5 -> 254295.16 | K11: =J11-H11 -> -77704.842 | L11: =IF(AND(H11=0,J11=0),0,IF(H11=0,"New",(J11-H11)/H11)) -> -0.23405073 | M11: =IF(AND(OR(C11<>0,H11<>0),D11=0,I11=0),"DROP",IF(AND(OR(D11<>0,I11<>0),C11=0,H11=0),"NEW",""))
A12: KST25 0 | B12: =IFERROR(INDEX('Source'!$C:$C,MATCH($A12,'Source'!$B:$B,0)),"") -> חבק יד | C12: =SUMIFS('Source'!$D:$D,'Source'!$A:$A,"152501 קופ""ח כללית 1203-9",'Source'!$B:$B,$A12) -> 21480 | D12: =SUMIFS('Source'!$F:$F,'Source'!$A:$A,"152501 קופ""ח כללית 1203-9",'Source'!$B:$B,$A12) -> 15110 | E12: =D12*$J$5 -> 19086.316 | F12: =E12-C12 -> -2393.6842 | G12: =IF(AND(C12=0,E12=0),0,IF(C12=0,"New",(E12-C12)/C12)) -> -0.11143781 | H12: =SUMIFS('Source'!$E:$E,'Source'!$A:$A,"152501 קופ""ח כללית 1203-9",'Source'!$B:$B,$A12) -> 344287.2 | I12: =SUMIFS('Source'!$G:$G,'Source'!$A:$A,"152501 קופ""ח כללית 1203-9",'Source'!$B:$B,$A12) -> 227103.3 | J12: =I12*$J$5 -> 286867.33 | K12: =J12-H12 -> -57419.874 | L12: =IF(AND(H12=0,J12=0),0,IF(H12=0,"New",(J12-H12)/H12)) -> -0.166779 | M12: =IF(AND(OR(C12<>0,H12<>0),D12=0,I12=0),"DROP",IF(AND(OR(D12<>0,I12<>0),C12=0,H12=0),"NEW",""))
A13: K078 M | B13: =IFERROR(INDEX('Source'!$C:$C,MATCH($A13,'Source'!$B:$B,0)),"") -> חגורת גב+סגירה כפולה | C13: =SUMIFS('Source'!$D:$D,'Source'!$A:$A,"152501 קופ""ח כללית 1203-9",'Source'!$B:$B,$A13) -> 3800 | D13: =SUMIFS('Source'!$F:$F,'Source'!$A:$A,"152501 קופ""ח כללית 1203-9",'Source'!$B:$B,$A13) -> 2200 | E13: =D13*$J$5 -> 2778.9474 | F13: =E13-C13 -> -1021.0526 | G13: =IF(AND(C13=0,E13=0),0,IF(C13=0,"New",(E13-C13)/C13)) -> -0.26869806 | H13: =SUMIFS('Source'!$E:$E,'Source'!$A:$A,"152501 קופ""ח כללית 1203-9",'Source'!$B:$B,$A13) -> 215142.5 | I13: =SUMIFS('Source'!$G:$G,'Source'!$A:$A,"152501 קופ""ח כללית 1203-9",'Source'!$B:$B,$A13) -> 119702 | J13: =I13*$J$5 -> 151202.53 | K13: =J13-H13 -> -63939.974 | L13: =IF(AND(H13=0,J13=0),0,IF(H13=0,"New",(J13-H13)/H13)) -> -0.29719825 | M13: =IF(AND(OR(C13<>0,H13<>0),D13=0,I13=0),"DROP",IF(AND(OR(D13<>0,I13<>0),C13=0,H13=0),"NEW",""))
A14: K078 XXL | B14: =IFERROR(INDEX('Source'!$C:$C,MATCH($A14,'Source'!$B:$B,0)),"") -> חגורת גב+סגירה כפולה | C14: =SUMIFS('Source'!$D:$D,'Source'!$A:$A,"152501 קופ""ח כללית 1203-9",'Source'!$B:$B,$A14) -> 2565 | D14: =SUMIFS('Source'!$F:$F,'Source'!$A:$A,"152501 קופ""ח כללית 1203-9",'Source'!$B:$B,$A14) -> 1305 | E14: =D14*$J$5 -> 1648.4211 | F14: =E14-C14 -> -916.57895 | G14: =IF(AND(C14=0,E14=0),0,IF(C14=0,"New",(E14-C14)/C14)) -> -0.35734072 | H14: =SUMIFS('Source'!$E:$E,'Source'!$A:$A,"152501 קופ""ח כללית 1203-9",'Source'!$B:$B,$A14) -> 146555.55 | I14: =SUMIFS('Source'!$G:$G,'Source'!$A:$A,"152501 קופ""ח כללית 1203-9",'Source'!$B:$B,$A14) -> 71005.05 | J14: =I14*$J$5 -> 89690.589 | K14: =J14-H14 -> -56864.961 | L14: =IF(AND(H14=0,J14=0),0,IF(H14=0,"New",(J14-H14)/H14)) -> -0.3880096 | M14: =IF(AND(OR(C14<>0,H14<>0),D14=0,I14=0),"DROP",IF(AND(OR(D14<>0,I14<>0),C14=0,H14=0),"NEW",""))
A15: KST27R 0 | B15: =IFERROR(INDEX('Source'!$C:$C,MATCH($A15,'Source'!$B:$B,0)),"") -> סד יד | C15: =SUMIFS('Source'!$D:$D,'Source'!$A:$A,"152501 קופ""ח כללית 1203-9",'Source'!$B:$B,$A15) -> 5600 | D15: =SUMIFS('Source'!$F:$F,'Source'!$A:$A,"152501 קופ""ח כללית 1203-9",'Source'!$B:$B,$A15) -> 3920 | E15: =D15*$J$5 -> 4951.5789 | F15: =E15-C15 -> -648.42105 | G15: =IF(AND(C15=0,E15=0),0,IF(C15=0,"New",(E15-C15)/C15)) -> -0.11578947 | H15: =SUMIFS('Source'!$E:$E,'Source'!$A:$A,"152501 קופ""ח כללית 1203-9",'Source'!$B:$B,$A15) -> 135200 | I15: =SUMIFS('Source'!$G:$G,'Source'!$A:$A,"152501 קופ""ח כללית 1203-9",'Source'!$B:$B,$A15) -> 88200 | J15: =I15*$J$5 -> 111410.53 | K15: =J15-H15 -> -23789.474 | L15: =IF(AND(H15=0,J15=0),0,IF(H15=0,"New",(J15-H15)/H15)) -> -0.17595765 | M15: =IF(AND(OR(C15<>0,H15<>0),D15=0,I15=0),"DROP",IF(AND(OR(D15<>0,I15<>0),C15=0,H15=0),"NEW",""))
A16: KST95 0 | B16: =IFERROR(INDEX('Source'!$C:$C,MATCH($A16,'Source'!$B:$B,0)),"") -> מגן מרפק | C16: =SUMIFS('Source'!$D:$D,'Source'!$A:$A,"152501 קופ""ח כללית 1203-9",'Source'!$B:$B,$A16) -> 5040 | D16: =SUMIFS('Source'!$F:$F,'Source'!$A:$A,"152501 קופ""ח כללית 1203-9",'Source'!$B:$B,$A16) -> 3360 | E16: =D16*$J$5 -> 4244.2105 | F16: =E16-C16 -> -795.78947 | G16: =IF(AND(C16=0,E16=0),0,IF(C16=0,"New",(E16-C16)/C16)) -> -0.15789474 | H16: =SUMIFS('Source'!$E:$E,'Source'!$A:$A,"152501 קופ""ח כללית 1203-9",'Source'!$B:$B,$A16) -> 114775.2 | I16: =SUMIFS('Source'!$G:$G,'Source'!$A:$A,"152501 קופ""ח כללית 1203-9",'Source'!$B:$B,$A16) -> 71467.2 | J16: =I16*$J$5 -> 90274.358 | K16: =J16-H16 -> -24500.842 | L16: =IF(AND(H16=0,J16=0),0,IF(H16=0,"New",(J16-H16)/H16)) -> -0.21346808 | M16: =IF(AND(OR(C16<>0,H16<>0),D16=0,I16=0),"DROP",IF(AND(OR(D16<>0,I16<>0),C16=0,H16=0),"NEW",""))
A17: K45 XL | B17: =IFERROR(INDEX('Source'!$C:$C,MATCH($A17,'Source'!$B:$B,0)),"") -> מגן ברך רגיל | C17: =SUMIFS('Source'!$D:$D,'Source'!$A:$A,"152501 קופ""ח כללית 1203-9",'Source'!$B:$B,$A17) -> 9960 | D17: =SUMIFS('Source'!$F:$F,'Source'!$A:$A,"152501 קופ""ח כללית 1203-9",'Source'!$B:$B,$A17) -> 6840 | E17: =D17*$J$5 -> 8640 | F17: =E17-C17 -> -1320 | G17: =IF(AND(C17=0,E17=0),0,IF(C17=0,"New",(E17-C17)/C17)) -> -0.13253012 | H17: =SUMIFS('Source'!$E:$E,'Source'!$A:$A,"152501 קופ""ח כללית 1203-9",'Source'!$B:$B,$A17) -> 124737.6 | I17: =SUMIFS('Source'!$G:$G,'Source'!$A:$A,"152501 קופ""ח כללית 1203-9",'Source'!$B:$B,$A17) -> 81806.4 | J17: =I17*$J$5 -> 103334.4 | K17: =J17-H17 -> -21403.2 | L17: =IF(AND(H17=0,J17=0),0,IF(H17=0,"New",(J17-H17)/H17)) -> -0.17158579 | M17: =IF(AND(OR(C17<>0,H17<>0),D17=0,I17=0),"DROP",IF(AND(OR(D17<>0,I17<>0),C17=0,H17=0),"NEW",""))
A18: K35 L | B18: =IFERROR(INDEX('Source'!$C:$C,MATCH($A18,'Source'!$B:$B,0)),"") -> מגן קרסול פתוח | C18: =SUMIFS('Source'!$D:$D,'Source'!$A:$A,"152501 קופ""ח כללית 1203-9",'Source'!$B:$B,$A18) -> 7320 | D18: =SUMIFS('Source'!$F:$F,'Source'!$A:$A,"152501 קופ""ח כללית 1203-9",'Source'!$B:$B,$A18) -> 4200 | E18: =D18*$J$5 -> 5305.2632 | F18: =E18-C18 -> -2014.7368 | G18: =IF(AND(C18=0,E18=0),0,IF(C18=0,"New",(E18-C18)/C18)) -> -0.27523727 | H18: =SUMIFS('Source'!$E:$E,'Source'!$A:$A,"152501 קופ""ח כללית 1203-9",'Source'!$B:$B,$A18) -> 92964 | I18: =SUMIFS('Source'!$G:$G,'Source'!$A:$A,"152501 קופ""ח כללית 1203-9",'Source'!$B:$B,$A18) -> 53340 | J18: =I18*$J$5 -> 67376.842 | K18: =J18-H18 -> -25587.158 | L18: =IF(AND(H18=0,J18=0),0,IF(H18=0,"New",(J18-H18)/H18)) -> -0.27523727 | M18: =IF(AND(OR(C18<>0,H18<>0),D18=0,I18=0),"DROP",IF(AND(OR(D18<>0,I18<>0),C18=0,H18=0),"NEW",""))
A19: KST37 0 | B19: =IFERROR(INDEX('Source'!$C:$C,MATCH($A19,'Source'!$B:$B,0)),"") -> מגן קרסול | C19: =SUMIFS('Source'!$D:$D,'Source'!$A:$A,"152501 קופ""ח כללית 1203-9",'Source'!$B:$B,$A19) -> 7800 | D19: =SUMIFS('Source'!$F:$F,'Source'!$A:$A,"152501 קופ""ח כללית 1203-9",'Source'!$B:$B,$A19) -> 6120 | E19: =D19*$J$5 -> 7730.5263 | F19: =E19-C19 -> -69.473684 | G19: =IF(AND(C19=0,E19=0),0,IF(C19=0,"New",(E19-C19)/C19)) -> -0.0089068826 | H19: =SUMIFS('Source'!$E:$E,'Source'!$A:$A,"152501 קופ""ח כללית 1203-9",'Source'!$B:$B,$A19) -> 145066.8 | I19: =SUMIFS('Source'!$G:$G,'Source'!$A:$A,"152501 קופ""ח כללית 1203-9",'Source'!$B:$B,$A19) -> 107283.6 | J19: =I19*$J$5 -> 135516.13 | K19: =J19-H19 -> -9550.6737 | L19: =IF(AND(H19=0,J19=0),0,IF(H19=0,"New",(J19-H19)/H19)) -> -0.065836385 | M19: =IF(AND(OR(C19<>0,H19<>0),D19=0,I19=0),"DROP",IF(AND(OR(D19<>0,I19<>0),C19=0,H19=0),"NEW",""))
A20: KST28 0 | B20: =IFERROR(INDEX('Source'!$C:$C,MATCH($A20,'Source'!$B:$B,0)),"") -> סד יד | C20: =SUMIFS('Source'!$D:$D,'Source'!$A:$A,"152501 קופ""ח כללית 1203-9",'Source'!$B:$B,$A20) -> 6240 | D20: =SUMIFS('Source'!$F:$F,'Source'!$A:$A,"152501 קופ""ח כללית 1203-9",'Source'!$B:$B,$A20) -> 4956 | E20: =D20*$J$5 -> 6260.2105 | F20: =E20-C20 -> 20.210526 | G20: =IF(AND(C20=0,E20=0),0,IF(C20=0,"New",(E20-C20)/C20)) -> 0.0032388664 | H20: =SUMIFS('Source'!$E:$E,'Source'!$A:$A,"152501 קופ""ח כללית 1203-9",'Source'!$B:$B,$A20) -> 119520 | I20: =SUMIFS('Source'!$G:$G,'Source'!$A:$A,"152501 קופ""ח כללית 1203-9",'Source'!$B:$B,$A20) -> 88216.8 | J20: =I20*$J$5 -> 111431.75 | K20: =J20-H20 -> -8088.2526 | L20: =IF(AND(H20=0,J20=0),0,IF(H20=0,"New",(J20-H20)/H20)) -> -0.067672796 | M20: =IF(AND(OR(C20<>0,H20<>0),D20=0,I20=0),"DROP",IF(AND(OR(D20<>0,I20<>0),C20=0,H20=0),"NEW",""))
... A41: ST27L 0 | B41: =IFERROR(INDEX('Source'!$C:$C,MATCH($A41,'Source'!$B:$B,0)),"") -> סד יד | C41: =SUMIFS('Source'!$D:$D,'Source'!$A:$A,"152501 קופ""ח כללית 1203-9",'Source'!$B:$B,$A41) -> -1 | D41: =SUMIFS('Source'!$F:$F,'Source'!$A:$A,"152501 קופ""ח כללית 1203-9",'Source'!$B:$B,$A41) -> 0 | E41: =D41*$J$5 -> 0 | F41: =E41-C41 -> 1 | G41: =IF(AND(C41=0,E41=0),0,IF(C41=0,"New",(E41-C41)/C41)) -> -1 | H41: =SUMIFS('Source'!$E:$E,'Source'!$A:$A,"152501 קופ""ח כללית 1203-9",'Source'!$B:$B,$A41) -> -62.43 | I41: =SUMIFS('Source'!$G:$G,'Source'!$A:$A,"152501 קופ""ח כללית 1203-9",'Source'!$B:$B,$A41) -> 0 | J41: =I41*$J$5 -> 0 | K41: =J41-H41 -> 62.43 | L41: =IF(AND(H41=0,J41=0),0,IF(H41=0,"New",(J41-H41)/H41)) -> -1 | M41: =IF(AND(OR(C41<>0,H41<>0),D41=0,I41=0),"DROP",IF(AND(OR(D41<>0,I41<>0),C41=0,H41=0),"NEW","")) -> DROP
B43: TOTAL | C43: =SUM(C9:C41) -> 152395 | D43: =SUM(D9:D41) -> 110137 | E43: =SUM(E9:E41) -> 139120.42 | F43: =SUM(F9:F41) -> -13274.579 | G43: =IF(C43=0,"N/A",F43/C43) -> -0.087106394 | H43: =SUM(H9:H41) -> 3809616.4 | I43: =SUM(I9:I41) -> 2569653 | J43: =SUM(J9:J41) -> 3245877.5 | K43: =SUM(K9:K41) -> -563738.88 | L43: =IF(H43=0,"N/A",K43/H43) -> -0.14797786

Sheet 155138 לקוח אינטרנט
A1: Sales Comparison 2025 vs 2026 (Annualized) - Customer: 155138 לקוח אינטרנט (by Product CODE)
A2: Calculation date: | B2: 46284
A3: Source: NetSuite report "1-Sales: Customer by Item" (01/01/2025-31/12/2026), customer = "155138 לקוח אינטרנט" only (exact match on the "Customer" column). Product CODE = column "Item: Name" (F in the original report) - NOT "Item: Name (Grouped)" (E), which carries a PARENT prefix. 2025 = columns J/K (Quantity/Amount Net); 2026 = columns O/P. Multiple rows per CODE per customer (one per unit-price tier) are summed (SUMIFS) per CODE, not taken from a single row. Raw rows kept unchanged in the shared "Source" sheet (filtered to only these 16 customers, not the full 32,141-row report). IMPORTANT: the source file’s own header states the report range as "01 January 2025 - 31 December 2026", but has no per-row date/timestamp field, so the exact 2026 cutoff cannot be verified from the data itself. Same assumption used across this whole workbook for consistency: 2026 actual covers approximately 9.5 months (1 Jan - 15 Sep).
A4: Annualization note: 2026 actual data is assumed to cover approximately 9.5 months (1 Jan - 15 Sep 2026), consistent with the rest of this workbook. Scaled to a full year via a simple linear factor = 12 / 9.5 (≈ 1.263158) - straight-line extrapolation, does NOT account for seasonality. Treat as an estimate. | I4: Months in full year: | J4: 12 | K4: Months covered by 2026 actual (assumed 1/1–15/9): | L4: 9.5
A5: # DROP (sold 2025, 0 in 2026): | B5: =SUMPRODUCT(--(((C9:C728<>0)+(H9:H728<>0)>0)*((D9:D728=0)*(I9:I728=0)))) -> 88 | C5: # NEW (sold 2026, 0 in 2025): | D5: =SUMPRODUCT(--(((D9:D728<>0)+(I9:I728<>0)>0)*((C9:C728=0)*(H9:H728=0)))) -> 102 | I5: Normalization factor (J4/L4): | J5: =J4/L4 -> 1.2631579
A6: DROP — Quantity 2025: | B6: =SUMPRODUCT(--(((C9:C728<>0)+(H9:H728<>0)>0)*((D9:D728=0)*(I9:I728=0)))*C9:C728) -> 580 | C6: DROP — Amount 2025 (₪): | D6: =SUMPRODUCT(--(((C9:C728<>0)+(H9:H728<>0)>0)*((D9:D728=0)*(I9:I728=0)))*H9:H728) -> 69822.79 | E6: NEW — Quantity 2026: | F6: =SUMPRODUCT(--(((D9:D728<>0)+(I9:I728<>0)>0)*((C9:C728=0)*(H9:H728=0)))*D9:D728) -> 2375 | G6: NEW — Amount 2026 (₪): | H6: =SUMPRODUCT(--(((D9:D728<>0)+(I9:I728<>0)>0)*((C9:C728=0)*(H9:H728=0)))*I9:I728) -> 147591.2
A8: Product Code | B8: Item Display Name | C8: Quantity 2025 | D8: Quantity 2026 (Actual, partial year) | E8: Quantity 2026 (Annualized) | F8: Quantity Change (Annualized vs 2025) | G8: Quantity Change % (Annualized vs 2025) | H8: Amount 2025 (₪) | I8: Amount 2026 (Actual, partial year) (₪) | J8: Amount 2026 (Annualized) (₪) | K8: Amount Change (Annualized vs 2025) (₪) | L8: Amount Change % (Annualized vs 2025) | M8: Note
A9: 67 0 | B9: =IFERROR(INDEX('Source'!$C:$C,MATCH($A9,'Source'!$B:$B,0)),"") -> כרית שינה חלומית | C9: =SUMIFS('Source'!$D:$D,'Source'!$A:$A,"155138 לקוח אינטרנט",'Source'!$B:$B,$A9) -> 231 | D9: =SUMIFS('Source'!$F:$F,'Source'!$A:$A,"155138 לקוח אינטרנט",'Source'!$B:$B,$A9) -> 3486 | E9: =D9*$J$5 -> 4403.3684 | F9: =E9-C9 -> 4172.3684 | G9: =IF(AND(C9=0,E9=0),0,IF(C9=0,"New",(E9-C9)/C9)) -> 18.062201 | H9: =SUMIFS('Source'!$E:$E,'Source'!$A:$A,"155138 לקוח אינטרנט",'Source'!$B:$B,$A9) -> 59147.42 | I9: =SUMIFS('Source'!$G:$G,'Source'!$A:$A,"155138 לקוח אינטרנט",'Source'!$B:$B,$A9) -> 946061.13 | J9: =I9*$J$5 -> 1195024.6 | K9: =J9-H9 -> 1135877.2 | L9: =IF(AND(H9=0,J9=0),0,IF(H9=0,"New",(J9-H9)/H9)) -> 19.204171 | M9: =IF(AND(OR(C9<>0,H9<>0),D9=0,I9=0),"DROP",IF(AND(OR(D9<>0,I9<>0),C9=0,H9=0),"NEW",""))
A10: AC75-S-XL | B10: =IFERROR(INDEX('Source'!$C:$C,MATCH($A10,'Source'!$B:$B,0)),"") -> מיישר כתפיים | C10: =SUMIFS('Source'!$D:$D,'Source'!$A:$A,"155138 לקוח אינטרנט",'Source'!$B:$B,$A10) -> 489 | D10: =SUMIFS('Source'!$F:$F,'Source'!$A:$A,"155138 לקוח אינטרנט",'Source'!$B:$B,$A10) -> 5248 | E10: =D10*$J$5 -> 6629.0526 | F10: =E10-C10 -> 6140.0526 | G10: =IF(AND(C10=0,E10=0),0,IF(C10=0,"New",(E10-C10)/C10)) -> 12.556345 | H10: =SUMIFS('Source'!$E:$E,'Source'!$A:$A,"155138 לקוח אינטרנט",'Source'!$B:$B,$A10) -> 59910.55 | I10: =SUMIFS('Source'!$G:$G,'Source'!$A:$A,"155138 לקוח אינטרנט",'Source'!$B:$B,$A10) -> 711931.41 | J10: =I10*$J$5 -> 899281.78 | K10: =J10-H10 -> 839371.23 | L10: =IF(AND(H10=0,J10=0),0,IF(H10=0,"New",(J10-H10)/H10)) -> 14.010408 | M10: =IF(AND(OR(C10<>0,H10<>0),D10=0,I10=0),"DROP",IF(AND(OR(D10<>0,I10<>0),C10=0,H10=0),"NEW",""))
A11: WEB-AC75-S-XL | B11: =IFERROR(INDEX('Source'!$C:$C,MATCH($A11,'Source'!$B:$B,0)),"") -> מיישר כתפיים | C11: =SUMIFS('Source'!$D:$D,'Source'!$A:$A,"155138 לקוח אינטרנט",'Source'!$B:$B,$A11) -> 1815 | D11: =SUMIFS('Source'!$F:$F,'Source'!$A:$A,"155138 לקוח אינטרנט",'Source'!$B:$B,$A11) -> 20 | E11: =D11*$J$5 -> 25.263158 | F11: =E11-C11 -> -1789.7368 | G11: =IF(AND(C11=0,E11=0),0,IF(C11=0,"New",(E11-C11)/C11)) -> -0.9860809 | H11: =SUMIFS('Source'!$E:$E,'Source'!$A:$A,"155138 לקוח אינטרנט",'Source'!$B:$B,$A11) -> 240271.27 | I11: =SUMIFS('Source'!$G:$G,'Source'!$A:$A,"155138 לקוח אינטרנט",'Source'!$B:$B,$A11) -> 2706.8 | J11: =I11*$J$5 -> 3419.1158 | K11: =J11-H11 -> -236852.15 | L11: =IF(AND(H11=0,J11=0),0,IF(H11=0,"New",(J11-H11)/H11)) -> -0.98576977 | M11: =IF(AND(OR(C11<>0,H11<>0),D11=0,I11=0),"DROP",IF(AND(OR(D11<>0,I11<>0),C11=0,H11=0),"NEW",""))
A12: AC75 XXL | B12: =IFERROR(INDEX('Source'!$C:$C,MATCH($A12,'Source'!$B:$B,0)),"") -> מיישר כתפיים | C12: =SUMIFS('Source'!$D:$D,'Source'!$A:$A,"155138 לקוח אינטרנט",'Source'!$B:$B,$A12) -> 128 | D12: =SUMIFS('Source'!$F:$F,'Source'!$A:$A,"155138 לקוח אינטרנט",'Source'!$B:$B,$A12) -> 903 | E12: =D12*$J$5 -> 1140.6316 | F12: =E12-C12 -> 1012.6316 | G12: =IF(AND(C12=0,E12=0),0,IF(C12=0,"New",(E12-C12)/C12)) -> 7.9111842 | H12: =SUMIFS('Source'!$E:$E,'Source'!$A:$A,"155138 לקוח אינטרנט",'Source'!$B:$B,$A12) -> 15662.12 | I12: =SUMIFS('Source'!$G:$G,'Source'!$A:$A,"155138 לקוח אינטרנט",'Source'!$B:$B,$A12) -> 121131.92 | J12: =I12*$J$5 -> 153008.74 | K12: =J12-H12 -> 137346.62 | L12: =IF(AND(H12=0,J12=0),0,IF(H12=0,"New",(J12-H12)/H12)) -> 8.7693506 | M12: =IF(AND(OR(C12<>0,H12<>0),D12=0,I12=0),"DROP",IF(AND(OR(D12<>0,I12<>0),C12=0,H12=0),"NEW",""))
A13: 397A-39-42 | B13: =IFERROR(INDEX('Source'!$C:$C,MATCH($A13,'Source'!$B:$B,0)),"") -> גרבי נסיעות אנטיבקטריאלי | C13: =SUMIFS('Source'!$D:$D,'Source'!$A:$A,"155138 לקוח אינטרנט",'Source'!$B:$B,$A13) -> 21 | D13: =SUMIFS('Source'!$F:$F,'Source'!$A:$A,"155138 לקוח אינטרנט",'Source'!$B:$B,$A13) -> 488 | E13: =D13*$J$5 -> 616.42105 | F13: =E13-C13 -> 595.42105 | G13: =IF(AND(C13=0,E13=0),0,IF(C13=0,"New",(E13-C13)/C13)) -> 28.353383 | H13: =SUMIFS('Source'!$E:$E,'Source'!$A:$A,"155138 לקוח אינטרנט",'Source'!$B:$B,$A13) -> 2194.94 | I13: =SUMIFS('Source'!$G:$G,'Source'!$A:$A,"155138 לקוח אינטרנט",'Source'!$B:$B,$A13) -> 50859.04 | J13: =I13*$J$5 -> 64242.998 | K13: =J13-H13 -> 62048.058 | L13: =IF(AND(H13=0,J13=0),0,IF(H13=0,"New",(J13-H13)/H13)) -> 28.268681 | M13: =IF(AND(OR(C13<>0,H13<>0),D13=0,I13=0),"DROP",IF(AND(OR(D13<>0,I13<>0),C13=0,H13=0),"NEW",""))
A14: WEB-AC75 XXL | B14: =IFERROR(INDEX('Source'!$C:$C,MATCH($A14,'Source'!$B:$B,0)),"") -> מיישר כתפיים | C14: =SUMIFS('Source'!$D:$D,'Source'!$A:$A,"155138 לקוח אינטרנט",'Source'!$B:$B,$A14) -> 342 | D14: =SUMIFS('Source'!$F:$F,'Source'!$A:$A,"155138 לקוח אינטרנט",'Source'!$B:$B,$A14) -> 4 | E14: =D14*$J$5 -> 5.0526316 | F14: =E14-C14 -> -336.94737 | G14: =IF(AND(C14=0,E14=0),0,IF(C14=0,"New",(E14-C14)/C14)) -> -0.98522622 | H14: =SUMIFS('Source'!$E:$E,'Source'!$A:$A,"155138 לקוח אינטרנט",'Source'!$B:$B,$A14) -> 45417.98 | I14: =SUMIFS('Source'!$G:$G,'Source'!$A:$A,"155138 לקוח אינטרנט",'Source'!$B:$B,$A14) -> 532.72 | J14: =I14*$J$5 -> 672.90947 | K14: =J14-H14 -> -44745.071 | L14: =IF(AND(H14=0,J14=0),0,IF(H14=0,"New",(J14-H14)/H14)) -> -0.98518407 | M14: =IF(AND(OR(C14<>0,H14<>0),D14=0,I14=0),"DROP",IF(AND(OR(D14<>0,I14<>0),C14=0,H14=0),"NEW",""))
A15: 397A-43-46 | B15: =IFERROR(INDEX('Source'!$C:$C,MATCH($A15,'Source'!$B:$B,0)),"") -> גרבי נסיעות אנטיבקטריאלי | C15: =SUMIFS('Source'!$D:$D,'Source'!$A:$A,"155138 לקוח אינטרנט",'Source'!$B:$B,$A15) -> 15 | D15: =SUMIFS('Source'!$F:$F,'Source'!$A:$A,"155138 לקוח אינטרנט",'Source'!$B:$B,$A15) -> 348 | E15: =D15*$J$5 -> 439.57895 | F15: =E15-C15 -> 424.57895 | G15: =IF(AND(C15=0,E15=0),0,IF(C15=0,"New",(E15-C15)/C15)) -> 28.305263 | H15: =SUMIFS('Source'!$E:$E,'Source'!$A:$A,"155138 לקוח אינטרנט",'Source'!$B:$B,$A15) -> 1497.59 | I15: =SUMIFS('Source'!$G:$G,'Source'!$A:$A,"155138 לקוח אינטרנט",'Source'!$B:$B,$A15) -> 35869.72 | J15: =I15*$J$5 -> 45309.12 | K15: =J15-H15 -> 43811.53 | L15: =IF(AND(H15=0,J15=0),0,IF(H15=0,"New",(J15-H15)/H15)) -> 29.254689 | M15: =IF(AND(OR(C15<>0,H15<>0),D15=0,I15=0),"DROP",IF(AND(OR(D15<>0,I15<>0),C15=0,H15=0),"NEW",""))
A16: M95 | B16: =IFERROR(INDEX('Source'!$C:$C,MATCH($A16,'Source'!$B:$B,0)),"") -> איסוף מנקודת מסירה | C16: =SUMIFS('Source'!$D:$D,'Source'!$A:$A,"155138 לקוח אינטרנט",'Source'!$B:$B,$A16) -> 4978 | D16: =SUMIFS('Source'!$F:$F,'Source'!$A:$A,"155138 לקוח אינטרנט",'Source'!$B:$B,$A16) -> 3342 | E16: =D16*$J$5 -> 4221.4737 | F16: =E16-C16 -> -756.52632 | G16: =IF(AND(C16=0,E16=0),0,IF(C16=0,"New",(E16-C16)/C16)) -> -0.15197395 | H16: =SUMIFS('Source'!$E:$E,'Source'!$A:$A,"155138 לקוח אינטרנט",'Source'!$B:$B,$A16) -> 83925.83 | I16: =SUMIFS('Source'!$G:$G,'Source'!$A:$A,"155138 לקוח אינטרנט",'Source'!$B:$B,$A16) -> 51232.76 | J16: =I16*$J$5 -> 64715.065 | K16: =J16-H16 -> -19210.765 | L16: =IF(AND(H16=0,J16=0),0,IF(H16=0,"New",(J16-H16)/H16)) -> -0.22890169 | M16: =IF(AND(OR(C16<>0,H16<>0),D16=0,I16=0),"DROP",IF(AND(OR(D16<>0,I16<>0),C16=0,H16=0),"NEW",""))
A17: M94 | B17: =IFERROR(INDEX('Source'!$C:$C,MATCH($A17,'Source'!$B:$B,0)),"") -> משלוח מהיר | C17: =SUMIFS('Source'!$D:$D,'Source'!$A:$A,"155138 לקוח אינטרנט",'Source'!$B:$B,$A17) -> 1942 | D17: =SUMIFS('Source'!$F:$F,'Source'!$A:$A,"155138 לקוח אינטרנט",'Source'!$B:$B,$A17) -> 1329 | E17: =D17*$J$5 -> 1678.7368 | F17: =E17-C17 -> -263.26316 | G17: =IF(AND(C17=0,E17=0),0,IF(C17=0,"New",(E17-C17)/C17)) -> -0.1355629 | H17: =SUMIFS('Source'!$E:$E,'Source'!$A:$A,"155138 לקוח אינטרנט",'Source'!$B:$B,$A17) -> 82126.22 | I17: =SUMIFS('Source'!$G:$G,'Source'!$A:$A,"155138 לקוח אינטרנט",'Source'!$B:$B,$A17) -> 54328.93 | J17: =I17*$J$5 -> 68626.017 | K17: =J17-H17 -> -13500.203 | L17: =IF(AND(H17=0,J17=0),0,IF(H17=0,"New",(J17-H17)/H17)) -> -0.16438359 | M17: =IF(AND(OR(C17<>0,H17<>0),D17=0,I17=0),"DROP",IF(AND(OR(D17<>0,I17<>0),C17=0,H17=0),"NEW",""))
A18: MSG001FB 0 | B18: =IFERROR(INDEX('Source'!$C:$C,MATCH($A18,'Source'!$B:$B,0)),"") -> מכשיר עיסוי ויטלימד פלקסי - פלוס שחור | C18: =SUMIFS('Source'!$D:$D,'Source'!$A:$A,"155138 לקוח אינטרנט",'Source'!$B:$B,$A18) -> 0 | D18: =SUMIFS('Source'!$F:$F,'Source'!$A:$A,"155138 לקוח אינטרנט",'Source'!$B:$B,$A18) -> 25 | E18: =D18*$J$5 -> 31.578947 | F18: =E18-C18 -> 31.578947 | G18: =IF(AND(C18=0,E18=0),0,IF(C18=0,"New",(E18-C18)/C18)) -> New | H18: =SUMIFS('Source'!$E:$E,'Source'!$A:$A,"155138 לקוח אינטרנט",'Source'!$B:$B,$A18) -> 0 | I18: =SUMIFS('Source'!$G:$G,'Source'!$A:$A,"155138 לקוח אינטרנט",'Source'!$B:$B,$A18) -> 23150.68 | J18: =I18*$J$5 -> 29242.964 | K18: =J18-H18 -> 29242.964 | L18: =IF(AND(H18=0,J18=0),0,IF(H18=0,"New",(J18-H18)/H18)) -> New | M18: =IF(AND(OR(C18<>0,H18<>0),D18=0,I18=0),"DROP",IF(AND(OR(D18<>0,I18<>0),C18=0,H18=0),"NEW","")) -> NEW
A19: 397A-35-38 | B19: =IFERROR(INDEX('Source'!$C:$C,MATCH($A19,'Source'!$B:$B,0)),"") -> גרבי נסיעות אנטיבקטריאלי | C19: =SUMIFS('Source'!$D:$D,'Source'!$A:$A,"155138 לקוח אינטרנט",'Source'!$B:$B,$A19) -> 12 | D19: =SUMIFS('Source'!$F:$F,'Source'!$A:$A,"155138 לקוח אינטרנט",'Source'!$B:$B,$A19) -> 216 | E19: =D19*$J$5 -> 272.84211 | F19: =E19-C19 -> 260.84211 | G19: =IF(AND(C19=0,E19=0),0,IF(C19=0,"New",(E19-C19)/C19)) -> 21.736842 | H19: =SUMIFS('Source'!$E:$E,'Source'!$A:$A,"155138 לקוח אינטרנט",'Source'!$B:$B,$A19) -> 1234.64 | I19: =SUMIFS('Source'!$G:$G,'Source'!$A:$A,"155138 לקוח אינטרנט",'Source'!$B:$B,$A19) -> 22588 | J19: =I19*$J$5 -> 28532.211 | K19: =J19-H19 -> 27297.571 | L19: =IF(AND(H19=0,J19=0),0,IF(H19=0,"New",(J19-H19)/H19)) -> 22.109741 | M19: =IF(AND(OR(C19<>0,H19<>0),D19=0,I19=0),"DROP",IF(AND(OR(D19<>0,I19<>0),C19=0,H19=0),"NEW",""))
A20: 397-39-42 | B20: =IFERROR(INDEX('Source'!$C:$C,MATCH($A20,'Source'!$B:$B,0)),"") -> גרבי טיסה | C20: =SUMIFS('Source'!$D:$D,'Source'!$A:$A,"155138 לקוח אינטרנט",'Source'!$B:$B,$A20) -> 174 | D20: =SUMIFS('Source'!$F:$F,'Source'!$A:$A,"155138 לקוח אינטרנט",'Source'!$B:$B,$A20) -> 1 | E20: =D20*$J$5 -> 1.2631579 | F20: =E20-C20 -> -172.73684 | G20: =IF(AND(C20=0,E20=0),0,IF(C20=0,"New",(E20-C20)/C20)) -> -0.99274047 | H20: =SUMIFS('Source'!$E:$E,'Source'!$A:$A,"155138 לקוח אינטרנט",'Source'!$B:$B,$A20) -> 17260.97 | I20: =SUMIFS('Source'!$G:$G,'Source'!$A:$A,"155138 לקוח אינטרנט",'Source'!$B:$B,$A20) -> 97.17 | J20: =I20*$J$5 -> 122.74105 | K20: =J20-H20 -> -17138.229 | L20: =IF(AND(H20=0,J20=0),0,IF(H20=0,"New",(J20-H20)/H20)) -> -0.9928891 | M20: =IF(AND(OR(C20<>0,H20<>0),D20=0,I20=0),"DROP",IF(AND(OR(D20<>0,I20<>0),C20=0,H20=0),"NEW",""))
... A728: 422EB XL | B728: =IFERROR(INDEX('Source'!$C:$C,MATCH($A728,'Source'!$B:$B,0)),"") -> מגן ברך סיליקון - אנטומיק | C728: =SUMIFS('Source'!$D:$D,'Source'!$A:$A,"155138 לקוח אינטרנט",'Source'!$B:$B,$A728) -> 1 | D728: =SUMIFS('Source'!$F:$F,'Source'!$A:$A,"155138 לקוח אינטרנט",'Source'!$B:$B,$A728) -> 1 | E728: =D728*$J$5 -> 1.2631579 | F728: =E728-C728 -> 0.26315789 | G728: =IF(AND(C728=0,E728=0),0,IF(C728=0,"New",(E728-C728)/C728)) -> 0.26315789 | H728: =SUMIFS('Source'!$E:$E,'Source'!$A:$A,"155138 לקוח אינטרנט",'Source'!$B:$B,$A728) -> 367.71 | I728: =SUMIFS('Source'!$G:$G,'Source'!$A:$A,"155138 לקוח אינטרנט",'Source'!$B:$B,$A728) -> 367.71 | J728: =I728*$J$5 -> 464.47579 | K728: =J728-H728 -> 96.765789 | L728: =IF(AND(H728=0,J728=0),0,IF(H728=0,"New",(J728-H728)/H728)) -> 0.26315789 | M728: =IF(AND(OR(C728<>0,H728<>0),D728=0,I728=0),"DROP",IF(AND(OR(D728<>0,I728<>0),C728=0,H728=0),"NEW",""))
B730: TOTAL | C730: =SUM(C9:C728) -> 20444 | D730: =SUM(D9:D728) -> 28580 | E730: =SUM(E9:E728) -> 36101.053 | F730: =SUM(F9:F728) -> 15657.053 | G730: =IF(C730=0,"N/A",F730/C730) -> 0.76585075 | H730: =SUM(H9:H728) -> 1655344.3 | I730: =SUM(I9:I728) -> 3196334.6 | J730: =SUM(J9:J728) -> 4037475.3 | K730: =SUM(K9:K728) -> 2382131 | L730: =IF(H730=0,"N/A",K730/H730) -> 1.4390547

Sheet 160251 AMAZON
A1: Sales Comparison 2025 vs 2026 (Annualized) - Customer: 160251 AMAZON (by Product CODE)
A2: Calculation date: | B2: 46284
A3: Source: NetSuite report "1-Sales: Customer by Item" (01/01/2025-31/12/2026), customer = "160251 AMAZON" only (exact match on the "Customer" column). Product CODE = column "Item: Name" (F in the original report) - NOT "Item: Name (Grouped)" (E), which carries a PARENT prefix. 2025 = columns J/K (Quantity/Amount Net); 2026 = columns O/P. Multiple rows per CODE per customer (one per unit-price tier) are summed (SUMIFS) per CODE, not taken from a single row. Raw rows kept unchanged in the shared "Source" sheet (filtered to only these 16 customers, not the full 32,141-row report). IMPORTANT: the source file’s own header states the report range as "01 January 2025 - 31 December 2026", but has no per-row date/timestamp field, so the exact 2026 cutoff cannot be verified from the data itself. Same assumption used across this whole workbook for consistency: 2026 actual covers approximately 9.5 months (1 Jan - 15 Sep).
A4: Annualization note: 2026 actual data is assumed to cover approximately 9.5 months (1 Jan - 15 Sep 2026), consistent with the rest of this workbook. Scaled to a full year via a simple linear factor = 12 / 9.5 (≈ 1.263158) - straight-line extrapolation, does NOT account for seasonality. Treat as an estimate. | I4: Months in full year: | J4: 12 | K4: Months covered by 2026 actual (assumed 1/1–15/9): | L4: 9.5
A5: # DROP (sold 2025, 0 in 2026): | B5: =SUMPRODUCT(--(((C9:C87<>0)+(H9:H87<>0)>0)*((D9:D87=0)*(I9:I87=0)))) -> 17 | C5: # NEW (sold 2026, 0 in 2025): | D5: =SUMPRODUCT(--(((D9:D87<>0)+(I9:I87<>0)>0)*((C9:C87=0)*(H9:H87=0)))) -> 6 | I5: Normalization factor (J4/L4): | J5: =J4/L4 -> 1.2631579
A6: DROP — Quantity 2025: | B6: =SUMPRODUCT(--(((C9:C87<>0)+(H9:H87<>0)>0)*((D9:D87=0)*(I9:I87=0)))*C9:C87) -> 448 | C6: DROP — Amount 2025 (₪): | D6: =SUMPRODUCT(--(((C9:C87<>0)+(H9:H87<>0)>0)*((D9:D87=0)*(I9:I87=0)))*H9:H87) -> 94856.4 | E6: NEW — Quantity 2026: | F6: =SUMPRODUCT(--(((D9:D87<>0)+(I9:I87<>0)>0)*((C9:C87=0)*(H9:H87=0)))*D9:D87) -> 47 | G6: NEW — Amount 2026 (₪): | H6: =SUMPRODUCT(--(((D9:D87<>0)+(I9:I87<>0)>0)*((C9:C87=0)*(H9:H87=0)))*I9:I87) -> 3274.06
A8: Product Code | B8: Item Display Name | C8: Quantity 2025 | D8: Quantity 2026 (Actual, partial year) | E8: Quantity 2026 (Annualized) | F8: Quantity Change (Annualized vs 2025) | G8: Quantity Change % (Annualized vs 2025) | H8: Amount 2025 (₪) | I8: Amount 2026 (Actual, partial year) (₪) | J8: Amount 2026 (Annualized) (₪) | K8: Amount Change (Annualized vs 2025) (₪) | L8: Amount Change % (Annualized vs 2025) | M8: Note
A9: FC342 0 | B9: =IFERROR(INDEX('Source'!$C:$C,MATCH($A9,'Source'!$B:$B,0)),"") -> נוזל לריכוך ציפורן חודרנית | C9: =SUMIFS('Source'!$D:$D,'Source'!$A:$A,"160251 AMAZON",'Source'!$B:$B,$A9) -> 16341 | D9: =SUMIFS('Source'!$F:$F,'Source'!$A:$A,"160251 AMAZON",'Source'!$B:$B,$A9) -> 11785 | E9: =D9*$J$5 -> 14886.316 | F9: =E9-C9 -> -1454.6842 | G9: =IF(AND(C9=0,E9=0),0,IF(C9=0,"New",(E9-C9)/C9)) -> -0.089020513 | H9: =SUMIFS('Source'!$E:$E,'Source'!$A:$A,"160251 AMAZON",'Source'!$B:$B,$A9) -> 1097384.5 | I9: =SUMIFS('Source'!$G:$G,'Source'!$A:$A,"160251 AMAZON",'Source'!$B:$B,$A9) -> 705962.26 | J9: =I9*$J$5 -> 891741.8 | K9: =J9-H9 -> -205642.68 | L9: =IF(AND(H9=0,J9=0),0,IF(H9=0,"New",(J9-H9)/H9)) -> -0.18739346 | M9: =IF(AND(OR(C9<>0,H9<>0),D9=0,I9=0),"DROP",IF(AND(OR(D9<>0,I9<>0),C9=0,H9=0),"NEW",""))
A10: EC-59R M | B10: =IFERROR(INDEX('Source'!$C:$C,MATCH($A10,'Source'!$B:$B,0)),"") -> חגורת שבר | C10: =SUMIFS('Source'!$D:$D,'Source'!$A:$A,"160251 AMAZON",'Source'!$B:$B,$A10) -> 1141 | D10: =SUMIFS('Source'!$F:$F,'Source'!$A:$A,"160251 AMAZON",'Source'!$B:$B,$A10) -> 343 | E10: =D10*$J$5 -> 433.26316 | F10: =E10-C10 -> -707.73684 | G10: =IF(AND(C10=0,E10=0),0,IF(C10=0,"New",(E10-C10)/C10)) -> -0.62027769 | H10: =SUMIFS('Source'!$E:$E,'Source'!$A:$A,"160251 AMAZON",'Source'!$B:$B,$A10) -> 191075.16 | I10: =SUMIFS('Source'!$G:$G,'Source'!$A:$A,"160251 AMAZON",'Source'!$B:$B,$A10) -> 55207.3 | J10: =I10*$J$5 -> 69735.537 | K10: =J10-H10 -> -121339.62 | L10: =IF(AND(H10=0,J10=0),0,IF(H10=0,"New",(J10-H10)/H10)) -> -0.63503609 | M10: =IF(AND(OR(C10<>0,H10<>0),D10=0,I10=0),"DROP",IF(AND(OR(D10<>0,I10<>0),C10=0,H10=0),"NEW",""))
A11: EC-59L M | B11: =IFERROR(INDEX('Source'!$C:$C,MATCH($A11,'Source'!$B:$B,0)),"") -> חגורת שבר | C11: =SUMIFS('Source'!$D:$D,'Source'!$A:$A,"160251 AMAZON",'Source'!$B:$B,$A11) -> 670 | D11: =SUMIFS('Source'!$F:$F,'Source'!$A:$A,"160251 AMAZON",'Source'!$B:$B,$A11) -> 313 | E11: =D11*$J$5 -> 395.36842 | F11: =E11-C11 -> -274.63158 | G11: =IF(AND(C11=0,E11=0),0,IF(C11=0,"New",(E11-C11)/C11)) -> -0.40989788 | H11: =SUMIFS('Source'!$E:$E,'Source'!$A:$A,"160251 AMAZON",'Source'!$B:$B,$A11) -> 119782.01 | I11: =SUMIFS('Source'!$G:$G,'Source'!$A:$A,"160251 AMAZON",'Source'!$B:$B,$A11) -> 49927.51 | J11: =I11*$J$5 -> 63066.328 | K11: =J11-H11 -> -56715.682 | L11: =IF(AND(H11=0,J11=0),0,IF(H11=0,"New",(J11-H11)/H11)) -> -0.47349082 | M11: =IF(AND(OR(C11<>0,H11<>0),D11=0,I11=0),"DROP",IF(AND(OR(D11<>0,I11<>0),C11=0,H11=0),"NEW",""))
A12: EC-59R S | B12: =IFERROR(INDEX('Source'!$C:$C,MATCH($A12,'Source'!$B:$B,0)),"") -> חגורת שבר | C12: =SUMIFS('Source'!$D:$D,'Source'!$A:$A,"160251 AMAZON",'Source'!$B:$B,$A12) -> 502 | D12: =SUMIFS('Source'!$F:$F,'Source'!$A:$A,"160251 AMAZON",'Source'!$B:$B,$A12) -> 189 | E12: =D12*$J$5 -> 238.73684 | F12: =E12-C12 -> -263.26316 | G12: =IF(AND(C12=0,E12=0),0,IF(C12=0,"New",(E12-C12)/C12)) -> -0.5244286 | H12: =SUMIFS('Source'!$E:$E,'Source'!$A:$A,"160251 AMAZON",'Source'!$B:$B,$A12) -> 92438.48 | I12: =SUMIFS('Source'!$G:$G,'Source'!$A:$A,"160251 AMAZON",'Source'!$B:$B,$A12) -> 30425.69 | J12: =I12*$J$5 -> 38432.451 | K12: =J12-H12 -> -54006.029 | L12: =IF(AND(H12=0,J12=0),0,IF(H12=0,"New",(J12-H12)/H12)) -> -0.58423753 | M12: =IF(AND(OR(C12<>0,H12<>0),D12=0,I12=0),"DROP",IF(AND(OR(D12<>0,I12<>0),C12=0,H12=0),"NEW",""))
A13: FC3422 0 | B13: =IFERROR(INDEX('Source'!$C:$C,MATCH($A13,'Source'!$B:$B,0)),"") -> נוזל לריכוך ציפורן חודרנית | C13: =SUMIFS('Source'!$D:$D,'Source'!$A:$A,"160251 AMAZON",'Source'!$B:$B,$A13) -> 1355 | D13: =SUMIFS('Source'!$F:$F,'Source'!$A:$A,"160251 AMAZON",'Source'!$B:$B,$A13) -> 750 | E13: =D13*$J$5 -> 947.36842 | F13: =E13-C13 -> -407.63158 | G13: =IF(AND(C13=0,E13=0),0,IF(C13=0,"New",(E13-C13)/C13)) -> -0.30083511 | H13: =SUMIFS('Source'!$E:$E,'Source'!$A:$A,"160251 AMAZON",'Source'!$B:$B,$A13) -> 109768.29 | I13: =SUMIFS('Source'!$G:$G,'Source'!$A:$A,"160251 AMAZON",'Source'!$B:$B,$A13) -> 56592.53 | J13: =I13*$J$5 -> 71485.301 | K13: =J13-H13 -> -38282.989 | L13: =IF(AND(H13=0,J13=0),0,IF(H13=0,"New",(J13-H13)/H13)) -> -0.34876182 | M13: =IF(AND(OR(C13<>0,H13<>0),D13=0,I13=0),"DROP",IF(AND(OR(D13<>0,I13<>0),C13=0,H13=0),"NEW",""))
A14: FC342K 0 | B14: =IFERROR(INDEX('Source'!$C:$C,MATCH($A14,'Source'!$B:$B,0)),"") -> קיט טיפות + 365 XL | C14: =SUMIFS('Source'!$D:$D,'Source'!$A:$A,"160251 AMAZON",'Source'!$B:$B,$A14) -> 1189 | D14: =SUMIFS('Source'!$F:$F,'Source'!$A:$A,"160251 AMAZON",'Source'!$B:$B,$A14) -> 475 | E14: =D14*$J$5 -> 600 | F14: =E14-C14 -> -589 | G14: =IF(AND(C14=0,E14=0),0,IF(C14=0,"New",(E14-C14)/C14)) -> -0.49537426 | H14: =SUMIFS('Source'!$E:$E,'Source'!$A:$A,"160251 AMAZON",'Source'!$B:$B,$A14) -> 85731.85 | I14: =SUMIFS('Source'!$G:$G,'Source'!$A:$A,"160251 AMAZON",'Source'!$B:$B,$A14) -> 32628.14 | J14: =I14*$J$5 -> 41214.493 | K14: =J14-H14 -> -44517.357 | L14: =IF(AND(H14=0,J14=0),0,IF(H14=0,"New",(J14-H14)/H14)) -> -0.51926276 | M14: =IF(AND(OR(C14<>0,H14<>0),D14=0,I14=0),"DROP",IF(AND(OR(D14<>0,I14<>0),C14=0,H14=0),"NEW",""))
A15: EC-59R L | B15: =IFERROR(INDEX('Source'!$C:$C,MATCH($A15,'Source'!$B:$B,0)),"") -> חגורת שבר | C15: =SUMIFS('Source'!$D:$D,'Source'!$A:$A,"160251 AMAZON",'Source'!$B:$B,$A15) -> 403 | D15: =SUMIFS('Source'!$F:$F,'Source'!$A:$A,"160251 AMAZON",'Source'!$B:$B,$A15) -> 141 | E15: =D15*$J$5 -> 178.10526 | F15: =E15-C15 -> -224.89474 | G15: =IF(AND(C15=0,E15=0),0,IF(C15=0,"New",(E15-C15)/C15)) -> -0.55805146 | H15: =SUMIFS('Source'!$E:$E,'Source'!$A:$A,"160251 AMAZON",'Source'!$B:$B,$A15) -> 73333.84 | I15: =SUMIFS('Source'!$G:$G,'Source'!$A:$A,"160251 AMAZON",'Source'!$B:$B,$A15) -> 22516.1 | J15: =I15*$J$5 -> 28441.389 | K15: =J15-H15 -> -44892.451 | L15: =IF(AND(H15=0,J15=0),0,IF(H15=0,"New",(J15-H15)/H15)) -> -0.61216555 | M15: =IF(AND(OR(C15<>0,H15<>0),D15=0,I15=0),"DROP",IF(AND(OR(D15<>0,I15<>0),C15=0,H15=0),"NEW",""))
A16: EC-59RB M | B16: =IFERROR(INDEX('Source'!$C:$C,MATCH($A16,'Source'!$B:$B,0)),"") -> חגורת שבר שחור | C16: =SUMIFS('Source'!$D:$D,'Source'!$A:$A,"160251 AMAZON",'Source'!$B:$B,$A16) -> 769 | D16: =SUMIFS('Source'!$F:$F,'Source'!$A:$A,"160251 AMAZON",'Source'!$B:$B,$A16) -> 1146 | E16: =D16*$J$5 -> 1447.5789 | F16: =E16-C16 -> 678.57895 | G16: =IF(AND(C16=0,E16=0),0,IF(C16=0,"New",(E16-C16)/C16)) -> 0.88241736 | H16: =SUMIFS('Source'!$E:$E,'Source'!$A:$A,"160251 AMAZON",'Source'!$B:$B,$A16) -> 135894.77 | I16: =SUMIFS('Source'!$G:$G,'Source'!$A:$A,"160251 AMAZON",'Source'!$B:$B,$A16) -> 183863.79 | J16: =I16*$J$5 -> 232249 | K16: =J16-H16 -> 96354.228 | L16: =IF(AND(H16=0,J16=0),0,IF(H16=0,"New",(J16-H16)/H16)) -> 0.70903559 | M16: =IF(AND(OR(C16<>0,H16<>0),D16=0,I16=0),"DROP",IF(AND(OR(D16<>0,I16<>0),C16=0,H16=0),"NEW",""))
A17: EC-DIFF | B17: =IFERROR(INDEX('Source'!$C:$C,MATCH($A17,'Source'!$B:$B,0)),"") -> הפרשים אמזון | C17: =SUMIFS('Source'!$D:$D,'Source'!$A:$A,"160251 AMAZON",'Source'!$B:$B,$A17) -> 0 | D17: =SUMIFS('Source'!$F:$F,'Source'!$A:$A,"160251 AMAZON",'Source'!$B:$B,$A17) -> 0 | E17: =D17*$J$5 -> 0 | F17: =E17-C17 -> 0 | G17: =IF(AND(C17=0,E17=0),0,IF(C17=0,"New",(E17-C17)/C17)) -> 0 | H17: =SUMIFS('Source'!$E:$E,'Source'!$A:$A,"160251 AMAZON",'Source'!$B:$B,$A17) -> 42266.02 | I17: =SUMIFS('Source'!$G:$G,'Source'!$A:$A,"160251 AMAZON",'Source'!$B:$B,$A17) -> 0 | J17: =I17*$J$5 -> 0 | K17: =J17-H17 -> -42266.02 | L17: =IF(AND(H17=0,J17=0),0,IF(H17=0,"New",(J17-H17)/H17)) -> -1 | M17: =IF(AND(OR(C17<>0,H17<>0),D17=0,I17=0),"DROP",IF(AND(OR(D17<>0,I17<>0),C17=0,H17=0),"NEW","")) -> DROP
A18: EC-59D M | B18: =IFERROR(INDEX('Source'!$C:$C,MATCH($A18,'Source'!$B:$B,0)),"") -> חגורת שבר | C18: =SUMIFS('Source'!$D:$D,'Source'!$A:$A,"160251 AMAZON",'Source'!$B:$B,$A18) -> 346 | D18: =SUMIFS('Source'!$F:$F,'Source'!$A:$A,"160251 AMAZON",'Source'!$B:$B,$A18) -> 147 | E18: =D18*$J$5 -> 185.68421 | F18: =E18-C18 -> -160.31579 | G18: =IF(AND(C18=0,E18=0),0,IF(C18=0,"New",(E18-C18)/C18)) -> -0.46334043 | H18: =SUMIFS('Source'!$E:$E,'Source'!$A:$A,"160251 AMAZON",'Source'!$B:$B,$A18) -> 66008.37 | I18: =SUMIFS('Source'!$G:$G,'Source'!$A:$A,"160251 AMAZON",'Source'!$B:$B,$A18) -> 24805.76 | J18: =I18*$J$5 -> 31333.592 | K18: =J18-H18 -> -34674.778 | L18: =IF(AND(H18=0,J18=0),0,IF(H18=0,"New",(J18-H18)/H18)) -> -0.52530881 | M18: =IF(AND(OR(C18<>0,H18<>0),D18=0,I18=0),"DROP",IF(AND(OR(D18<>0,I18<>0),C18=0,H18=0),"NEW",""))
A19: EC-11STO XXL | B19: =IFERROR(INDEX('Source'!$C:$C,MATCH($A19,'Source'!$B:$B,0)),"") -> חגורה אחרי ניתוח | C19: =SUMIFS('Source'!$D:$D,'Source'!$A:$A,"160251 AMAZON",'Source'!$B:$B,$A19) -> 224 | D19: =SUMIFS('Source'!$F:$F,'Source'!$A:$A,"160251 AMAZON",'Source'!$B:$B,$A19) -> 61 | E19: =D19*$J$5 -> 77.052632 | F19: =E19-C19 -> -146.94737 | G19: =IF(AND(C19=0,E19=0),0,IF(C19=0,"New",(E19-C19)/C19)) -> -0.65601504 | H19: =SUMIFS('Source'!$E:$E,'Source'!$A:$A,"160251 AMAZON",'Source'!$B:$B,$A19) -> 30949.19 | I19: =SUMIFS('Source'!$G:$G,'Source'!$A:$A,"160251 AMAZON",'Source'!$B:$B,$A19) -> 8220.14 | J19: =I19*$J$5 -> 10383.335 | K19: =J19-H19 -> -20565.855 | L19: =IF(AND(H19=0,J19=0),0,IF(H19=0,"New",(J19-H19)/H19)) -> -0.66450383 | M19: =IF(AND(OR(C19<>0,H19<>0),D19=0,I19=0),"DROP",IF(AND(OR(D19<>0,I19<>0),C19=0,H19=0),"NEW",""))
