Workbook

Sheet Index
A1: ITEMISR — Consolidated Product List (12 categories), 2025 vs 2026 (Normalized) — v2: merged by product
A2: Calculation date: | B2: 46290
A3: UPDATED 25/09/2026 (v2): "Main List" scope narrowed to 12 categories - 101/102/103/104/105/106/108/109/114/115 pulled directly from SALES (matched to CHEMIPAL Code via TRANS then Catalog) + 107/113 pulled from kirill/outputs/2026-09-25-CEMIUP0.9-grouped-2025-vs-2026.xlsx ("בתי מרקחת"/"מאוחדת", already CEMI+SALES combined + 0.91-adjusted there - NOT re-pulled from SALES, to avoid double-counting). BE / סופר פארם / מכבי are NOT included this time (not requested). "110-Chemipal" excluded (not relevant). "111-Superpharm Life" and "112-Kupat Holim Clalit" remain in their OWN separate sheets - NOT in Main List or any consolidated total (unaffected by this update, still per-row not merged). KEY CHANGE: each CHEMIPAL Code (or raw item name, if unmatched) now appears ONLY ONCE in Main List - Quantity/Amount are SUMMED across every included category where it was sold. DROP/NEW (red/green) are determined on this summed total (a product sold in 2025 via one category and 2026 via a different one is NOT DROP). "Source Category" lists ALL contributing categories per row (comma-separated). 0.91: already baked into 107/113's CEMI-sourced portions upstream, not re-applied; never applied to the 10 direct-SALES categories. 2026 = normalized to a full year (×12/9.5 for direct-SALES rows; 107/113 already annualized upstream). Sorted by Quantity 2026 (normalized), descending. RED = DROP (sold 2025, exactly 0 in 2026, summed). GREEN = NEW (0 in 2025, sold in 2026, summed).
A5: Sheet map
A6: Sheet | B6: Contents
A7: Main List | B7: Merged by product across 12 categories (101/102/103/104/105/106/108/109/114/115 direct + 107/113 from CEMIUP0.9), sorted by Quantity 2026 desc, DROP/NEW colored. Each product appears once (summed across categories). CHEMIPAL Code blank when unmatched (ITEM NAME/שם מוצר still shown). "Top Source"/"2nd Source" columns (by Qty 2026) replace the old full category list.
A8: 111 - Superpharm Life | B8: Standalone - not in Main List/totals. Sale Type "111 - Superpharm Life" from SALES, matched via TRANS/Catalog (0% matched - private-label SKUs).
A9: 112 - Kupat Holim Clalit | B9: Standalone - not in Main List/totals. Sale Type "112 - Kupat Holim Clalit" from SALES, matched via TRANS/Catalog (0% matched - private-label SKUs).
A10: SALES Raw | B10: Pre-aggregated item-level data (per category+item) for all 28 SALES-sourced categories (26 direct + 111 + 112), with live CHEMIPAL Code match.
A11: CEMIUP0.9 Raw | B11: Already-resolved product rows imported from CEMIUP0.9 (107/113/BE/סופר פארם/מכבי) - literal values, that file is the audit trail.
A12: TRANS | B12: Crosswalk table (short NetSuite-style codes -> CHEMIPAL Code) - primary match source for SALES Raw.
A13: Catalog | B13: Global מק"ט<->item-name catalog (PPLAY1-format) - fallback match source for SALES Raw.
A15: Summary
A16: Sheet | B16: # Rows | C16: Qty 2025 | D16: Amt 2025 (₪) | E16: Qty 2026 (norm) | F16: Amt 2026 (norm, ₪) | G16: # DROP | H16: # NEW
A17: Main List | B17: 1085 | C17: 126608 | D17: 5750554.5 | E17: 117536 | F17: 7456362.1 | G17: 209 | H17: 157
A18: 111 - Superpharm Life | B18: 21 | C18: 118392 | D18: 1708656.9 | E18: 78891 | F18: 1406948 | G18: 1 | H18: 0
A19: 112 - Kupat Holim Clalit | B19: 33 | C19: 152395 | D19: 3809616.4 | E19: 139120 | F19: 3245877.5 | G19: 1 | H19: 1

Sheet Main List
A1: Main List — merged by product (CHEMIPAL Code / raw name), 10 direct-SALES categories + 107/113 (from CEMIUP0.9)
A2: Calculation date: | B2: 46290
A3: UPDATED 25/09/2026 (v3, per explicit instruction): CHEMIPAL Code (col A) is now BLANK for unmatched items (previously showed the raw item name as a stand-in - fixed for consistency with how BETI/מאוחדת always leave the code blank when unmatched). ITEM NAME (col B) and שם מוצר (col C) still show the raw/descriptive identifier regardless of match status. The internal Product Key used by all formulas here (CHEMIPAL Code when matched, else the raw item name) is kept visible in column J for full transparency/audit, since it is what actually drives every SUMIFS below. Source Category (single comma-separated list) REPLACED by two columns per instruction: "Top Source" = the single category that contributed the most Quantity 2026 (normalized) to this product, "2nd Source" = the second-most (blank if only one category contributed). Chosen criterion: Quantity 2026 (normalized), for consistency with the list's own sort order. Everything else unchanged from the previous version: merged by product across 12 categories - 101/102/103/104/105/106/108/109/114/115 direct from SALES (matched via TRANS then Catalog) + 107/113 from kirill/outputs/2026-09-25-CEMIUP0.9-grouped-2025-vs-2026.xlsx (already CEMI+SALES combined + 0.91-adjusted there, NOT re-pulled from SALES). BE/סופר פארם/מכבי NOT included. 111/112 remain in their own separate sheets, unaffected. 0.91 not re-applied here; not applied to the 10 direct-SALES categories. 2026 = normalized to a full year (×12/9.5 for direct-SALES; 107/113 already annualized upstream). Sorted by Quantity 2026 (normalized), descending.
A4: Normalization factor (2026, direct-SALES categories only - 107/113 already annualized upstream): | G4: Factor (12/9.5): | H4: =12/9.5 -> 1.2631579
A6: CHEMIPAL Code | B6: ITEM NAME | C6: שם מוצר | D6: כמות 2025 | E6: כסף 2025 (₪) | F6: כמות 2026 (מנורמל) | G6: כסף 2026 (מנורמל, ₪) | H6: Top Source | I6: 2nd Source | J6: Internal Product Key (audit)
A7: =IF(ISNUMBER($J7),$J7,"") -> 4413453 | B7: =IFERROR(INDEX('SALES Raw'!$B$6:$B$4467,MATCH($J7,'SALES Raw'!$J$6:$J$4467,0)),IFERROR(INDEX('CEMIUP0.9 Raw'!$B$6:$B$1712,MATCH($J7,'CEMIUP0.9 Raw'!$B$6:$B$1712,0)),$J7)) -> AC75-S-XL | C7: =IF(ISNUMBER($J7),IFERROR(INDEX('TRANS'!$C:$C,MATCH($J7,'TRANS'!$B:$B,0)),IFERROR(INDEX('Catalog'!$B:$B,MATCH($J7,'Catalog'!$A:$A,0)),$B7)),$B7) -> AC75 מישר כתפיים אקטיב | D7: =SUMIFS('SALES Raw'!$C$6:$C$4467,'SALES Raw'!$J$6:$J$4467,$J7,'SALES Raw'!$K$6:$K$4467,"Y")+SUMIFS('CEMIUP0.9 Raw'!$D$6:$D$1712,'CEMIUP0.9 Raw'!$B$6:$B$1712,$J7,'CEMIUP0.9 Raw'!$H$6:$H$1712,"Y") -> 1781 | E7: =SUMIFS('SALES Raw'!$D$6:$D$4467,'SALES Raw'!$J$6:$J$4467,$J7,'SALES Raw'!$K$6:$K$4467,"Y")+SUMIFS('CEMIUP0.9 Raw'!$E$6:$E$1712,'CEMIUP0.9 Raw'!$B$6:$B$1712,$J7,'CEMIUP0.9 Raw'!$H$6:$H$1712,"Y") -> 144784.45 | F7: =SUMIFS('SALES Raw'!$E$6:$E$4467,'SALES Raw'!$J$6:$J$4467,$J7,'SALES Raw'!$K$6:$K$4467,"Y")*$H$4+SUMIFS('CEMIUP0.9 Raw'!$F$6:$F$1712,'CEMIUP0.9 Raw'!$B$6:$B$1712,$J7,'CEMIUP0.9 Raw'!$H$6:$H$1712,"Y") -> 7918.7368 | G7: =SUMIFS('SALES Raw'!$F$6:$F$4467,'SALES Raw'!$J$6:$J$4467,$J7,'SALES Raw'!$K$6:$K$4467,"Y")*$H$4+SUMIFS('CEMIUP0.9 Raw'!$G$6:$G$1712,'CEMIUP0.9 Raw'!$B$6:$B$1712,$J7,'CEMIUP0.9 Raw'!$H$6:$H$1712,"Y") -> 993545.67 | H7: 114 - IL online | I7: 107 - Pharmacies | J7: 4413453
A8: =IF(ISNUMBER($J8),$J8,"") | B8: =IFERROR(INDEX('SALES Raw'!$B$6:$B$4467,MATCH($J8,'SALES Raw'!$J$6:$J$4467,0)),IFERROR(INDEX('CEMIUP0.9 Raw'!$B$6:$B$1712,MATCH($J8,'CEMIUP0.9 Raw'!$B$6:$B$1712,0)),$J8)) -> 67 0 | C8: =IF(ISNUMBER($J8),IFERROR(INDEX('TRANS'!$C:$C,MATCH($J8,'TRANS'!$B:$B,0)),IFERROR(INDEX('Catalog'!$B:$B,MATCH($J8,'Catalog'!$A:$A,0)),$B8)),$B8) -> 67 0 | D8: =SUMIFS('SALES Raw'!$C$6:$C$4467,'SALES Raw'!$J$6:$J$4467,$J8,'SALES Raw'!$K$6:$K$4467,"Y")+SUMIFS('CEMIUP0.9 Raw'!$D$6:$D$1712,'CEMIUP0.9 Raw'!$B$6:$B$1712,$J8,'CEMIUP0.9 Raw'!$H$6:$H$1712,"Y") -> 1074 | E8: =SUMIFS('SALES Raw'!$D$6:$D$4467,'SALES Raw'!$J$6:$J$4467,$J8,'SALES Raw'!$K$6:$K$4467,"Y")+SUMIFS('CEMIUP0.9 Raw'!$E$6:$E$1712,'CEMIUP0.9 Raw'!$B$6:$B$1712,$J8,'CEMIUP0.9 Raw'!$H$6:$H$1712,"Y") -> 169815.61 | F8: =SUMIFS('SALES Raw'!$E$6:$E$4467,'SALES Raw'!$J$6:$J$4467,$J8,'SALES Raw'!$K$6:$K$4467,"Y")*$H$4+SUMIFS('CEMIUP0.9 Raw'!$F$6:$F$1712,'CEMIUP0.9 Raw'!$B$6:$B$1712,$J8,'CEMIUP0.9 Raw'!$H$6:$H$1712,"Y") -> 5014.7368 | G8: =SUMIFS('SALES Raw'!$F$6:$F$4467,'SALES Raw'!$J$6:$J$4467,$J8,'SALES Raw'!$K$6:$K$4467,"Y")*$H$4+SUMIFS('CEMIUP0.9 Raw'!$G$6:$G$1712,'CEMIUP0.9 Raw'!$B$6:$B$1712,$J8,'CEMIUP0.9 Raw'!$H$6:$H$1712,"Y") -> 1298169.8 | H8: 114 - IL online | I8: 102 - Orthopedic institutes | J8: 67 0
A9: =IF(ISNUMBER($J9),$J9,"") | B9: =IFERROR(INDEX('SALES Raw'!$B$6:$B$4467,MATCH($J9,'SALES Raw'!$J$6:$J$4467,0)),IFERROR(INDEX('CEMIUP0.9 Raw'!$B$6:$B$1712,MATCH($J9,'CEMIUP0.9 Raw'!$B$6:$B$1712,0)),$J9)) -> M95 | C9: =IF(ISNUMBER($J9),IFERROR(INDEX('TRANS'!$C:$C,MATCH($J9,'TRANS'!$B:$B,0)),IFERROR(INDEX('Catalog'!$B:$B,MATCH($J9,'Catalog'!$A:$A,0)),$B9)),$B9) -> M95 | D9: =SUMIFS('SALES Raw'!$C$6:$C$4467,'SALES Raw'!$J$6:$J$4467,$J9,'SALES Raw'!$K$6:$K$4467,"Y")+SUMIFS('CEMIUP0.9 Raw'!$D$6:$D$1712,'CEMIUP0.9 Raw'!$B$6:$B$1712,$J9,'CEMIUP0.9 Raw'!$H$6:$H$1712,"Y") -> 4982 | E9: =SUMIFS('SALES Raw'!$D$6:$D$4467,'SALES Raw'!$J$6:$J$4467,$J9,'SALES Raw'!$K$6:$K$4467,"Y")+SUMIFS('CEMIUP0.9 Raw'!$E$6:$E$1712,'CEMIUP0.9 Raw'!$B$6:$B$1712,$J9,'CEMIUP0.9 Raw'!$H$6:$H$1712,"Y") -> 84006.41 | F9: =SUMIFS('SALES Raw'!$E$6:$E$4467,'SALES Raw'!$J$6:$J$4467,$J9,'SALES Raw'!$K$6:$K$4467,"Y")*$H$4+SUMIFS('CEMIUP0.9 Raw'!$F$6:$F$1712,'CEMIUP0.9 Raw'!$B$6:$B$1712,$J9,'CEMIUP0.9 Raw'!$H$6:$H$1712,"Y") -> 4221.4737 | G9: =SUMIFS('SALES Raw'!$F$6:$F$4467,'SALES Raw'!$J$6:$J$4467,$J9,'SALES Raw'!$K$6:$K$4467,"Y")*$H$4+SUMIFS('CEMIUP0.9 Raw'!$G$6:$G$1712,'CEMIUP0.9 Raw'!$B$6:$B$1712,$J9,'CEMIUP0.9 Raw'!$H$6:$H$1712,"Y") -> 64715.065 | H9: 114 - IL online | I9: 101 - Factory customers | J9: M95
A10: =IF(ISNUMBER($J10),$J10,"") -> 4421000 | B10: =IFERROR(INDEX('SALES Raw'!$B$6:$B$4467,MATCH($J10,'SALES Raw'!$J$6:$J$4467,0)),IFERROR(INDEX('CEMIUP0.9 Raw'!$B$6:$B$1712,MATCH($J10,'CEMIUP0.9 Raw'!$B$6:$B$1712,0)),$J10)) -> 3655 0 | C10: =IF(ISNUMBER($J10),IFERROR(INDEX('TRANS'!$C:$C,MATCH($J10,'TRANS'!$B:$B,0)),IFERROR(INDEX('Catalog'!$B:$B,MATCH($J10,'Catalog'!$A:$A,0)),$B10)),$B10) -> 3655 שרוול מסיליקון לאצבע | D10: =SUMIFS('SALES Raw'!$C$6:$C$4467,'SALES Raw'!$J$6:$J$4467,$J10,'SALES Raw'!$K$6:$K$4467,"Y")+SUMIFS('CEMIUP0.9 Raw'!$D$6:$D$1712,'CEMIUP0.9 Raw'!$B$6:$B$1712,$J10,'CEMIUP0.9 Raw'!$H$6:$H$1712,"Y") -> 3237 | E10: =SUMIFS('SALES Raw'!$D$6:$D$4467,'SALES Raw'!$J$6:$J$4467,$J10,'SALES Raw'!$K$6:$K$4467,"Y")+SUMIFS('CEMIUP0.9 Raw'!$E$6:$E$1712,'CEMIUP0.9 Raw'!$B$6:$B$1712,$J10,'CEMIUP0.9 Raw'!$H$6:$H$1712,"Y") -> 49596.691 | F10: =SUMIFS('SALES Raw'!$E$6:$E$4467,'SALES Raw'!$J$6:$J$4467,$J10,'SALES Raw'!$K$6:$K$4467,"Y")*$H$4+SUMIFS('CEMIUP0.9 Raw'!$F$6:$F$1712,'CEMIUP0.9 Raw'!$B$6:$B$1712,$J10,'CEMIUP0.9 Raw'!$H$6:$H$1712,"Y") -> 2573.0526 | G10: =SUMIFS('SALES Raw'!$F$6:$F$4467,'SALES Raw'!$J$6:$J$4467,$J10,'SALES Raw'!$K$6:$K$4467,"Y")*$H$4+SUMIFS('CEMIUP0.9 Raw'!$G$6:$G$1712,'CEMIUP0.9 Raw'!$B$6:$B$1712,$J10,'CEMIUP0.9 Raw'!$H$6:$H$1712,"Y") -> 41177.859 | H10: 107 - Pharmacies | I10: 113 - Kupat Holim Meuhedet | J10: 4421000
A11: =IF(ISNUMBER($J11),$J11,"") | B11: =IFERROR(INDEX('SALES Raw'!$B$6:$B$4467,MATCH($J11,'SALES Raw'!$J$6:$J$4467,0)),IFERROR(INDEX('CEMIUP0.9 Raw'!$B$6:$B$1712,MATCH($J11,'CEMIUP0.9 Raw'!$B$6:$B$1712,0)),$J11)) -> M92 | C11: =IF(ISNUMBER($J11),IFERROR(INDEX('TRANS'!$C:$C,MATCH($J11,'TRANS'!$B:$B,0)),IFERROR(INDEX('Catalog'!$B:$B,MATCH($J11,'Catalog'!$A:$A,0)),$B11)),$B11) -> M92 | D11: =SUMIFS('SALES Raw'!$C$6:$C$4467,'SALES Raw'!$J$6:$J$4467,$J11,'SALES Raw'!$K$6:$K$4467,"Y")+SUMIFS('CEMIUP0.9 Raw'!$D$6:$D$1712,'CEMIUP0.9 Raw'!$B$6:$B$1712,$J11,'CEMIUP0.9 Raw'!$H$6:$H$1712,"Y") -> 1349 | E11: =SUMIFS('SALES Raw'!$D$6:$D$4467,'SALES Raw'!$J$6:$J$4467,$J11,'SALES Raw'!$K$6:$K$4467,"Y")+SUMIFS('CEMIUP0.9 Raw'!$E$6:$E$1712,'CEMIUP0.9 Raw'!$B$6:$B$1712,$J11,'CEMIUP0.9 Raw'!$H$6:$H$1712,"Y") -> 13.45 | F11: =SUMIFS('SALES Raw'!$E$6:$E$4467,'SALES Raw'!$J$6:$J$4467,$J11,'SALES Raw'!$K$6:$K$4467,"Y")*$H$4+SUMIFS('CEMIUP0.9 Raw'!$F$6:$F$1712,'CEMIUP0.9 Raw'!$B$6:$B$1712,$J11,'CEMIUP0.9 Raw'!$H$6:$H$1712,"Y") -> 2232 | G11: =SUMIFS('SALES Raw'!$F$6:$F$4467,'SALES Raw'!$J$6:$J$4467,$J11,'SALES Raw'!$K$6:$K$4467,"Y")*$H$4+SUMIFS('CEMIUP0.9 Raw'!$G$6:$G$1712,'CEMIUP0.9 Raw'!$B$6:$B$1712,$J11,'CEMIUP0.9 Raw'!$H$6:$H$1712,"Y") -> -5947.5411 | H11: 114 - IL online | I11: 115-SuperPharm Online | J11: M92
A12: =IF(ISNUMBER($J12),$J12,"") -> 4415158 | B12: =IFERROR(INDEX('SALES Raw'!$B$6:$B$4467,MATCH($J12,'SALES Raw'!$J$6:$J$4467,0)),IFERROR(INDEX('CEMIUP0.9 Raw'!$B$6:$B$1712,MATCH($J12,'CEMIUP0.9 Raw'!$B$6:$B$1712,0)),$J12)) -> 266 0 | C12: =IF(ISNUMBER($J12),IFERROR(INDEX('TRANS'!$C:$C,MATCH($J12,'TRANS'!$B:$B,0)),IFERROR(INDEX('Catalog'!$B:$B,MATCH($J12,'Catalog'!$A:$A,0)),$B12)),$B12) -> 266 סד ליד דו צדדי | D12: =SUMIFS('SALES Raw'!$C$6:$C$4467,'SALES Raw'!$J$6:$J$4467,$J12,'SALES Raw'!$K$6:$K$4467,"Y")+SUMIFS('CEMIUP0.9 Raw'!$D$6:$D$1712,'CEMIUP0.9 Raw'!$B$6:$B$1712,$J12,'CEMIUP0.9 Raw'!$H$6:$H$1712,"Y") -> 2464 | E12: =SUMIFS('SALES Raw'!$D$6:$D$4467,'SALES Raw'!$J$6:$J$4467,$J12,'SALES Raw'!$K$6:$K$4467,"Y")+SUMIFS('CEMIUP0.9 Raw'!$E$6:$E$1712,'CEMIUP0.9 Raw'!$B$6:$B$1712,$J12,'CEMIUP0.9 Raw'!$H$6:$H$1712,"Y") -> 136520.11 | F12: =SUMIFS('SALES Raw'!$E$6:$E$4467,'SALES Raw'!$J$6:$J$4467,$J12,'SALES Raw'!$K$6:$K$4467,"Y")*$H$4+SUMIFS('CEMIUP0.9 Raw'!$F$6:$F$1712,'CEMIUP0.9 Raw'!$B$6:$B$1712,$J12,'CEMIUP0.9 Raw'!$H$6:$H$1712,"Y") -> 2047.5789 | G12: =SUMIFS('SALES Raw'!$F$6:$F$4467,'SALES Raw'!$J$6:$J$4467,$J12,'SALES Raw'!$K$6:$K$4467,"Y")*$H$4+SUMIFS('CEMIUP0.9 Raw'!$G$6:$G$1712,'CEMIUP0.9 Raw'!$B$6:$B$1712,$J12,'CEMIUP0.9 Raw'!$H$6:$H$1712,"Y") -> 111723.78 | H12: 113 - Kupat Holim Meuhedet | I12: 107 - Pharmacies | J12: 4415158
A13: =IF(ISNUMBER($J13),$J13,"") | B13: =IFERROR(INDEX('SALES Raw'!$B$6:$B$4467,MATCH($J13,'SALES Raw'!$J$6:$J$4467,0)),IFERROR(INDEX('CEMIUP0.9 Raw'!$B$6:$B$1712,MATCH($J13,'CEMIUP0.9 Raw'!$B$6:$B$1712,0)),$J13)) -> M94 | C13: =IF(ISNUMBER($J13),IFERROR(INDEX('TRANS'!$C:$C,MATCH($J13,'TRANS'!$B:$B,0)),IFERROR(INDEX('Catalog'!$B:$B,MATCH($J13,'Catalog'!$A:$A,0)),$B13)),$B13) -> M94 | D13: =SUMIFS('SALES Raw'!$C$6:$C$4467,'SALES Raw'!$J$6:$J$4467,$J13,'SALES Raw'!$K$6:$K$4467,"Y")+SUMIFS('CEMIUP0.9 Raw'!$D$6:$D$1712,'CEMIUP0.9 Raw'!$B$6:$B$1712,$J13,'CEMIUP0.9 Raw'!$H$6:$H$1712,"Y") -> 1944 | E13: =SUMIFS('SALES Raw'!$D$6:$D$4467,'SALES Raw'!$J$6:$J$4467,$J13,'SALES Raw'!$K$6:$K$4467,"Y")+SUMIFS('CEMIUP0.9 Raw'!$E$6:$E$1712,'CEMIUP0.9 Raw'!$B$6:$B$1712,$J13,'CEMIUP0.9 Raw'!$H$6:$H$1712,"Y") -> 82198.51 | F13: =SUMIFS('SALES Raw'!$E$6:$E$4467,'SALES Raw'!$J$6:$J$4467,$J13,'SALES Raw'!$K$6:$K$4467,"Y")*$H$4+SUMIFS('CEMIUP0.9 Raw'!$F$6:$F$1712,'CEMIUP0.9 Raw'!$B$6:$B$1712,$J13,'CEMIUP0.9 Raw'!$H$6:$H$1712,"Y") -> 1678.7368 | G13: =SUMIFS('SALES Raw'!$F$6:$F$4467,'SALES Raw'!$J$6:$J$4467,$J13,'SALES Raw'!$K$6:$K$4467,"Y")*$H$4+SUMIFS('CEMIUP0.9 Raw'!$G$6:$G$1712,'CEMIUP0.9 Raw'!$B$6:$B$1712,$J13,'CEMIUP0.9 Raw'!$H$6:$H$1712,"Y") -> 68626.017 | H13: 114 - IL online | I13: 101 - Factory customers | J13: M94
A14: =IF(ISNUMBER($J14),$J14,"") | B14: =IFERROR(INDEX('SALES Raw'!$B$6:$B$4467,MATCH($J14,'SALES Raw'!$J$6:$J$4467,0)),IFERROR(INDEX('CEMIUP0.9 Raw'!$B$6:$B$1712,MATCH($J14,'CEMIUP0.9 Raw'!$B$6:$B$1712,0)),$J14)) -> 30 Nights Trial | C14: =IF(ISNUMBER($J14),IFERROR(INDEX('TRANS'!$C:$C,MATCH($J14,'TRANS'!$B:$B,0)),IFERROR(INDEX('Catalog'!$B:$B,MATCH($J14,'Catalog'!$A:$A,0)),$B14)),$B14) -> 30 Nights Trial | D14: =SUMIFS('SALES Raw'!$C$6:$C$4467,'SALES Raw'!$J$6:$J$4467,$J14,'SALES Raw'!$K$6:$K$4467,"Y")+SUMIFS('CEMIUP0.9 Raw'!$D$6:$D$1712,'CEMIUP0.9 Raw'!$B$6:$B$1712,$J14,'CEMIUP0.9 Raw'!$H$6:$H$1712,"Y") -> 0 | E14: =SUMIFS('SALES Raw'!$D$6:$D$4467,'SALES Raw'!$J$6:$J$4467,$J14,'SALES Raw'!$K$6:$K$4467,"Y")+SUMIFS('CEMIUP0.9 Raw'!$E$6:$E$1712,'CEMIUP0.9 Raw'!$B$6:$B$1712,$J14,'CEMIUP0.9 Raw'!$H$6:$H$1712,"Y") -> 0 | F14: =SUMIFS('SALES Raw'!$E$6:$E$4467,'SALES Raw'!$J$6:$J$4467,$J14,'SALES Raw'!$K$6:$K$4467,"Y")*$H$4+SUMIFS('CEMIUP0.9 Raw'!$F$6:$F$1712,'CEMIUP0.9 Raw'!$B$6:$B$1712,$J14,'CEMIUP0.9 Raw'!$H$6:$H$1712,"Y") -> 1626.9474 | G14: =SUMIFS('SALES Raw'!$F$6:$F$4467,'SALES Raw'!$J$6:$J$4467,$J14,'SALES Raw'!$K$6:$K$4467,"Y")*$H$4+SUMIFS('CEMIUP0.9 Raw'!$G$6:$G$1712,'CEMIUP0.9 Raw'!$B$6:$B$1712,$J14,'CEMIUP0.9 Raw'!$H$6:$H$1712,"Y") -> 0 | H14: 114 - IL online | J14: 30 Nights Trial
A15: =IF(ISNUMBER($J15),$J15,"") -> 4413059 | B15: =IFERROR(INDEX('SALES Raw'!$B$6:$B$4467,MATCH($J15,'SALES Raw'!$J$6:$J$4467,0)),IFERROR(INDEX('CEMIUP0.9 Raw'!$B$6:$B$1712,MATCH($J15,'CEMIUP0.9 Raw'!$B$6:$B$1712,0)),$J15)) -> 364-S-L | C15: =IF(ISNUMBER($J15),IFERROR(INDEX('TRANS'!$C:$C,MATCH($J15,'TRANS'!$B:$B,0)),IFERROR(INDEX('Catalog'!$B:$B,MATCH($J15,'Catalog'!$A:$A,0)),$B15)),$B15) -> 364S Lמפר.אצבע סיליק. ליבל.זוג | D15: =SUMIFS('SALES Raw'!$C$6:$C$4467,'SALES Raw'!$J$6:$J$4467,$J15,'SALES Raw'!$K$6:$K$4467,"Y")+SUMIFS('CEMIUP0.9 Raw'!$D$6:$D$1712,'CEMIUP0.9 Raw'!$B$6:$B$1712,$J15,'CEMIUP0.9 Raw'!$H$6:$H$1712,"Y") -> 1940 | E15: =SUMIFS('SALES Raw'!$D$6:$D$4467,'SALES Raw'!$J$6:$J$4467,$J15,'SALES Raw'!$K$6:$K$4467,"Y")+SUMIFS('CEMIUP0.9 Raw'!$E$6:$E$1712,'CEMIUP0.9 Raw'!$B$6:$B$1712,$J15,'CEMIUP0.9 Raw'!$H$6:$H$1712,"Y") -> 23014.194 | F15: =SUMIFS('SALES Raw'!$E$6:$E$4467,'SALES Raw'!$J$6:$J$4467,$J15,'SALES Raw'!$K$6:$K$4467,"Y")*$H$4+SUMIFS('CEMIUP0.9 Raw'!$F$6:$F$1712,'CEMIUP0.9 Raw'!$B$6:$B$1712,$J15,'CEMIUP0.9 Raw'!$H$6:$H$1712,"Y") -> 1408.4211 | G15: =SUMIFS('SALES Raw'!$F$6:$F$4467,'SALES Raw'!$J$6:$J$4467,$J15,'SALES Raw'!$K$6:$K$4467,"Y")*$H$4+SUMIFS('CEMIUP0.9 Raw'!$G$6:$G$1712,'CEMIUP0.9 Raw'!$B$6:$B$1712,$J15,'CEMIUP0.9 Raw'!$H$6:$H$1712,"Y") -> 16699.368 | H15: 107 - Pharmacies | I15: 113 - Kupat Holim Meuhedet | J15: 4413059
A16: =IF(ISNUMBER($J16),$J16,"") -> 4409004 | B16: =IFERROR(INDEX('SALES Raw'!$B$6:$B$4467,MATCH($J16,'SALES Raw'!$J$6:$J$4467,0)),IFERROR(INDEX('CEMIUP0.9 Raw'!$B$6:$B$1712,MATCH($J16,'CEMIUP0.9 Raw'!$B$6:$B$1712,0)),$J16)) -> FC335 0 | C16: =IF(ISNUMBER($J16),IFERROR(INDEX('TRANS'!$C:$C,MATCH($J16,'TRANS'!$B:$B,0)),IFERROR(INDEX('Catalog'!$B:$B,MATCH($J16,'Catalog'!$A:$A,0)),$B16)),$B16) -> FC335 טלק מעושר באלוורה | D16: =SUMIFS('SALES Raw'!$C$6:$C$4467,'SALES Raw'!$J$6:$J$4467,$J16,'SALES Raw'!$K$6:$K$4467,"Y")+SUMIFS('CEMIUP0.9 Raw'!$D$6:$D$1712,'CEMIUP0.9 Raw'!$B$6:$B$1712,$J16,'CEMIUP0.9 Raw'!$H$6:$H$1712,"Y") -> 2372 | E16: =SUMIFS('SALES Raw'!$D$6:$D$4467,'SALES Raw'!$J$6:$J$4467,$J16,'SALES Raw'!$K$6:$K$4467,"Y")+SUMIFS('CEMIUP0.9 Raw'!$E$6:$E$1712,'CEMIUP0.9 Raw'!$B$6:$B$1712,$J16,'CEMIUP0.9 Raw'!$H$6:$H$1712,"Y") -> 40174.281 | F16: =SUMIFS('SALES Raw'!$E$6:$E$4467,'SALES Raw'!$J$6:$J$4467,$J16,'SALES Raw'!$K$6:$K$4467,"Y")*$H$4+SUMIFS('CEMIUP0.9 Raw'!$F$6:$F$1712,'CEMIUP0.9 Raw'!$B$6:$B$1712,$J16,'CEMIUP0.9 Raw'!$H$6:$H$1712,"Y") -> 1374.3158 | G16: =SUMIFS('SALES Raw'!$F$6:$F$4467,'SALES Raw'!$J$6:$J$4467,$J16,'SALES Raw'!$K$6:$K$4467,"Y")*$H$4+SUMIFS('CEMIUP0.9 Raw'!$G$6:$G$1712,'CEMIUP0.9 Raw'!$B$6:$B$1712,$J16,'CEMIUP0.9 Raw'!$H$6:$H$1712,"Y") -> 23143.013 | H16: 113 - Kupat Holim Meuhedet | I16: 102 - Orthopedic institutes | J16: 4409004
A17: =IF(ISNUMBER($J17),$J17,"") -> 4419006 | B17: =IFERROR(INDEX('SALES Raw'!$B$6:$B$4467,MATCH($J17,'SALES Raw'!$J$6:$J$4467,0)),IFERROR(INDEX('CEMIUP0.9 Raw'!$B$6:$B$1712,MATCH($J17,'CEMIUP0.9 Raw'!$B$6:$B$1712,0)),$J17)) -> PD340 0 | C17: =IF(ISNUMBER($J17),IFERROR(INDEX('TRANS'!$C:$C,MATCH($J17,'TRANS'!$B:$B,0)),IFERROR(INDEX('Catalog'!$B:$B,MATCH($J17,'Catalog'!$A:$A,0)),$B17)),$B17) -> PD340-קוצץ ציפורניים | D17: =SUMIFS('SALES Raw'!$C$6:$C$4467,'SALES Raw'!$J$6:$J$4467,$J17,'SALES Raw'!$K$6:$K$4467,"Y")+SUMIFS('CEMIUP0.9 Raw'!$D$6:$D$1712,'CEMIUP0.9 Raw'!$B$6:$B$1712,$J17,'CEMIUP0.9 Raw'!$H$6:$H$1712,"Y") -> 1618 | E17: =SUMIFS('SALES Raw'!$D$6:$D$4467,'SALES Raw'!$J$6:$J$4467,$J17,'SALES Raw'!$K$6:$K$4467,"Y")+SUMIFS('CEMIUP0.9 Raw'!$E$6:$E$1712,'CEMIUP0.9 Raw'!$B$6:$B$1712,$J17,'CEMIUP0.9 Raw'!$H$6:$H$1712,"Y") -> 19584.525 | F17: =SUMIFS('SALES Raw'!$E$6:$E$4467,'SALES Raw'!$J$6:$J$4467,$J17,'SALES Raw'!$K$6:$K$4467,"Y")*$H$4+SUMIFS('CEMIUP0.9 Raw'!$F$6:$F$1712,'CEMIUP0.9 Raw'!$B$6:$B$1712,$J17,'CEMIUP0.9 Raw'!$H$6:$H$1712,"Y") -> 1269.4737 | G17: =SUMIFS('SALES Raw'!$F$6:$F$4467,'SALES Raw'!$J$6:$J$4467,$J17,'SALES Raw'!$K$6:$K$4467,"Y")*$H$4+SUMIFS('CEMIUP0.9 Raw'!$G$6:$G$1712,'CEMIUP0.9 Raw'!$B$6:$B$1712,$J17,'CEMIUP0.9 Raw'!$H$6:$H$1712,"Y") -> 14761.074 | H17: 107 - Pharmacies | I17: 113 - Kupat Holim Meuhedet | J17: 4419006
A18: =IF(ISNUMBER($J18),$J18,"") -> 4413456 | B18: =IFERROR(INDEX('SALES Raw'!$B$6:$B$4467,MATCH($J18,'SALES Raw'!$J$6:$J$4467,0)),IFERROR(INDEX('CEMIUP0.9 Raw'!$B$6:$B$1712,MATCH($J18,'CEMIUP0.9 Raw'!$B$6:$B$1712,0)),$J18)) -> AC75 XXL | C18: =IF(ISNUMBER($J18),IFERROR(INDEX('TRANS'!$C:$C,MATCH($J18,'TRANS'!$B:$B,0)),IFERROR(INDEX('Catalog'!$B:$B,MATCH($J18,'Catalog'!$A:$A,0)),$B18)),$B18) -> AC75 XXL מיישר כתפיים אקטיב | D18: =SUMIFS('SALES Raw'!$C$6:$C$4467,'SALES Raw'!$J$6:$J$4467,$J18,'SALES Raw'!$K$6:$K$4467,"Y")+SUMIFS('CEMIUP0.9 Raw'!$D$6:$D$1712,'CEMIUP0.9 Raw'!$B$6:$B$1712,$J18,'CEMIUP0.9 Raw'!$H$6:$H$1712,"Y") -> 269 | E18: =SUMIFS('SALES Raw'!$D$6:$D$4467,'SALES Raw'!$J$6:$J$4467,$J18,'SALES Raw'!$K$6:$K$4467,"Y")+SUMIFS('CEMIUP0.9 Raw'!$E$6:$E$1712,'CEMIUP0.9 Raw'!$B$6:$B$1712,$J18,'CEMIUP0.9 Raw'!$H$6:$H$1712,"Y") -> 24481.645 | F18: =SUMIFS('SALES Raw'!$E$6:$E$4467,'SALES Raw'!$J$6:$J$4467,$J18,'SALES Raw'!$K$6:$K$4467,"Y")*$H$4+SUMIFS('CEMIUP0.9 Raw'!$F$6:$F$1712,'CEMIUP0.9 Raw'!$B$6:$B$1712,$J18,'CEMIUP0.9 Raw'!$H$6:$H$1712,"Y") -> 1260.6316 | G18: =SUMIFS('SALES Raw'!$F$6:$F$4467,'SALES Raw'!$J$6:$J$4467,$J18,'SALES Raw'!$K$6:$K$4467,"Y")*$H$4+SUMIFS('CEMIUP0.9 Raw'!$G$6:$G$1712,'CEMIUP0.9 Raw'!$B$6:$B$1712,$J18,'CEMIUP0.9 Raw'!$H$6:$H$1712,"Y") -> 161946.38 | H18: 114 - IL online | I18: 107 - Pharmacies | J18: 4413456
A19: =IF(ISNUMBER($J19),$J19,"") -> 4422035 | B19: =IFERROR(INDEX('SALES Raw'!$B$6:$B$4467,MATCH($J19,'SALES Raw'!$J$6:$J$4467,0)),IFERROR(INDEX('CEMIUP0.9 Raw'!$B$6:$B$1712,MATCH($J19,'CEMIUP0.9 Raw'!$B$6:$B$1712,0)),$J19)) -> FC333 0 | C19: =IF(ISNUMBER($J19),IFERROR(INDEX('TRANS'!$C:$C,MATCH($J19,'TRANS'!$B:$B,0)),IFERROR(INDEX('Catalog'!$B:$B,MATCH($J19,'Catalog'!$A:$A,0)),$B19)),$B19) -> FCתרסיס דאודורנט אנטיבק.נעל333 | D19: =SUMIFS('SALES Raw'!$C$6:$C$4467,'SALES Raw'!$J$6:$J$4467,$J19,'SALES Raw'!$K$6:$K$4467,"Y")+SUMIFS('CEMIUP0.9 Raw'!$D$6:$D$1712,'CEMIUP0.9 Raw'!$B$6:$B$1712,$J19,'CEMIUP0.9 Raw'!$H$6:$H$1712,"Y") -> 2548 | E19: =SUMIFS('SALES Raw'!$D$6:$D$4467,'SALES Raw'!$J$6:$J$4467,$J19,'SALES Raw'!$K$6:$K$4467,"Y")+SUMIFS('CEMIUP0.9 Raw'!$E$6:$E$1712,'CEMIUP0.9 Raw'!$B$6:$B$1712,$J19,'CEMIUP0.9 Raw'!$H$6:$H$1712,"Y") -> 46740.527 | F19: =SUMIFS('SALES Raw'!$E$6:$E$4467,'SALES Raw'!$J$6:$J$4467,$J19,'SALES Raw'!$K$6:$K$4467,"Y")*$H$4+SUMIFS('CEMIUP0.9 Raw'!$F$6:$F$1712,'CEMIUP0.9 Raw'!$B$6:$B$1712,$J19,'CEMIUP0.9 Raw'!$H$6:$H$1712,"Y") -> 1205.0526 | G19: =SUMIFS('SALES Raw'!$F$6:$F$4467,'SALES Raw'!$J$6:$J$4467,$J19,'SALES Raw'!$K$6:$K$4467,"Y")*$H$4+SUMIFS('CEMIUP0.9 Raw'!$G$6:$G$1712,'CEMIUP0.9 Raw'!$B$6:$B$1712,$J19,'CEMIUP0.9 Raw'!$H$6:$H$1712,"Y") -> 23150.212 | H19: 107 - Pharmacies | I19: 113 - Kupat Holim Meuhedet | J19: 4422035
A20: =IF(ISNUMBER($J20),$J20,"") -> 4403042 | B20: =IFERROR(INDEX('SALES Raw'!$B$6:$B$4467,MATCH($J20,'SALES Raw'!$J$6:$J$4467,0)),IFERROR(INDEX('CEMIUP0.9 Raw'!$B$6:$B$1712,MATCH($J20,'CEMIUP0.9 Raw'!$B$6:$B$1712,0)),$J20)) -> 397A-39-42 | C20: =IF(ISNUMBER($J20),IFERROR(INDEX('TRANS'!$C:$C,MATCH($J20,'TRANS'!$B:$B,0)),IFERROR(INDEX('Catalog'!$B:$B,MATCH($J20,'Catalog'!$A:$A,0)),$B20)),$B20) -> 397A-גרבי טיסה אנטי בקטרי39-42 | D20: =SUMIFS('SALES Raw'!$C$6:$C$4467,'SALES Raw'!$J$6:$J$4467,$J20,'SALES Raw'!$K$6:$K$4467,"Y")+SUMIFS('CEMIUP0.9 Raw'!$D$6:$D$1712,'CEMIUP0.9 Raw'!$B$6:$B$1712,$J20,'CEMIUP0.9 Raw'!$H$6:$H$1712,"Y") -> 23 | E20: =SUMIFS('SALES Raw'!$D$6:$D$4467,'SALES Raw'!$J$6:$J$4467,$J20,'SALES Raw'!$K$6:$K$4467,"Y")+SUMIFS('CEMIUP0.9 Raw'!$E$6:$E$1712,'CEMIUP0.9 Raw'!$B$6:$B$1712,$J20,'CEMIUP0.9 Raw'!$H$6:$H$1712,"Y") -> 2321.4 | F20: =SUMIFS('SALES Raw'!$E$6:$E$4467,'SALES Raw'!$J$6:$J$4467,$J20,'SALES Raw'!$K$6:$K$4467,"Y")*$H$4+SUMIFS('CEMIUP0.9 Raw'!$F$6:$F$1712,'CEMIUP0.9 Raw'!$B$6:$B$1712,$J20,'CEMIUP0.9 Raw'!$H$6:$H$1712,"Y") -> 1202.5263 | G20: =SUMIFS('SALES Raw'!$F$6:$F$4467,'SALES Raw'!$J$6:$J$4467,$J20,'SALES Raw'!$K$6:$K$4467,"Y")*$H$4+SUMIFS('CEMIUP0.9 Raw'!$G$6:$G$1712,'CEMIUP0.9 Raw'!$B$6:$B$1712,$J20,'CEMIUP0.9 Raw'!$H$6:$H$1712,"Y") -> 94302.186 | H20: 114 - IL online | I20: 107 - Pharmacies | J20: 4403042
A21: =IF(ISNUMBER($J21),$J21,"") -> 4422023 | B21: =IFERROR(INDEX('SALES Raw'!$B$6:$B$4467,MATCH($J21,'SALES Raw'!$J$6:$J$4467,0)),IFERROR(INDEX('CEMIUP0.9 Raw'!$B$6:$B$1712,MATCH($J21,'CEMIUP0.9 Raw'!$B$6:$B$1712,0)),$J21)) -> 806CB-C | C21: =IF(ISNUMBER($J21),IFERROR(INDEX('TRANS'!$C:$C,MATCH($J21,'TRANS'!$B:$B,0)),IFERROR(INDEX('Catalog'!$B:$B,MATCH($J21,'Catalog'!$A:$A,0)),$B21)),$B21) -> 806CB-BEIGE תחבושת א.נצמ | D21: =SUMIFS('SALES Raw'!$C$6:$C$4467,'SALES Raw'!$J$6:$J$4467,$J21,'SALES Raw'!$K$6:$K$4467,"Y")+SUMIFS('CEMIUP0.9 Raw'!$D$6:$D$1712,'CEMIUP0.9 Raw'!$B$6:$B$1712,$J21,'CEMIUP0.9 Raw'!$H$6:$H$1712,"Y") -> 1625 | E21: =SUMIFS('SALES Raw'!$D$6:$D$4467,'SALES Raw'!$J$6:$J$4467,$J21,'SALES Raw'!$K$6:$K$4467,"Y")+SUMIFS('CEMIUP0.9 Raw'!$E$6:$E$1712,'CEMIUP0.9 Raw'!$B$6:$B$1712,$J21,'CEMIUP0.9 Raw'!$H$6:$H$1712,"Y") -> 15143.588 | F21: =SUMIFS('SALES Raw'!$E$6:$E$4467,'SALES Raw'!$J$6:$J$4467,$J21,'SALES Raw'!$K$6:$K$4467,"Y")*$H$4+SUMIFS('CEMIUP0.9 Raw'!$F$6:$F$1712,'CEMIUP0.9 Raw'!$B$6:$B$1712,$J21,'CEMIUP0.9 Raw'!$H$6:$H$1712,"Y") -> 1191.1579 | G21: =SUMIFS('SALES Raw'!$F$6:$F$4467,'SALES Raw'!$J$6:$J$4467,$J21,'SALES Raw'!$K$6:$K$4467,"Y")*$H$4+SUMIFS('CEMIUP0.9 Raw'!$G$6:$G$1712,'CEMIUP0.9 Raw'!$B$6:$B$1712,$J21,'CEMIUP0.9 Raw'!$H$6:$H$1712,"Y") -> 12670.258 | H21: 107 - Pharmacies | I21: 114 - IL online | J21: 4422023
A22: =IF(ISNUMBER($J22),$J22,"") -> 4415028 | B22: =IFERROR(INDEX('SALES Raw'!$B$6:$B$4467,MATCH($J22,'SALES Raw'!$J$6:$J$4467,0)),IFERROR(INDEX('CEMIUP0.9 Raw'!$B$6:$B$1712,MATCH($J22,'CEMIUP0.9 Raw'!$B$6:$B$1712,0)),$J22)) -> AC28 0 | C22: =IF(ISNUMBER($J22),IFERROR(INDEX('TRANS'!$C:$C,MATCH($J22,'TRANS'!$B:$B,0)),IFERROR(INDEX('Catalog'!$B:$B,MATCH($J22,'Catalog'!$A:$A,0)),$B22)),$B22) -> AC-28 סד לאגודל | D22: =SUMIFS('SALES Raw'!$C$6:$C$4467,'SALES Raw'!$J$6:$J$4467,$J22,'SALES Raw'!$K$6:$K$4467,"Y")+SUMIFS('CEMIUP0.9 Raw'!$D$6:$D$1712,'CEMIUP0.9 Raw'!$B$6:$B$1712,$J22,'CEMIUP0.9 Raw'!$H$6:$H$1712,"Y") -> 1429 | E22: =SUMIFS('SALES Raw'!$D$6:$D$4467,'SALES Raw'!$J$6:$J$4467,$J22,'SALES Raw'!$K$6:$K$4467,"Y")+SUMIFS('CEMIUP0.9 Raw'!$E$6:$E$1712,'CEMIUP0.9 Raw'!$B$6:$B$1712,$J22,'CEMIUP0.9 Raw'!$H$6:$H$1712,"Y") -> 43853.164 | F22: =SUMIFS('SALES Raw'!$E$6:$E$4467,'SALES Raw'!$J$6:$J$4467,$J22,'SALES Raw'!$K$6:$K$4467,"Y")*$H$4+SUMIFS('CEMIUP0.9 Raw'!$F$6:$F$1712,'CEMIUP0.9 Raw'!$B$6:$B$1712,$J22,'CEMIUP0.9 Raw'!$H$6:$H$1712,"Y") -> 1169.6842 | G22: =SUMIFS('SALES Raw'!$F$6:$F$4467,'SALES Raw'!$J$6:$J$4467,$J22,'SALES Raw'!$K$6:$K$4467,"Y")*$H$4+SUMIFS('CEMIUP0.9 Raw'!$G$6:$G$1712,'CEMIUP0.9 Raw'!$B$6:$B$1712,$J22,'CEMIUP0.9 Raw'!$H$6:$H$1712,"Y") -> 40381.109 | H22: 107 - Pharmacies | I22: 113 - Kupat Holim Meuhedet | J22: 4415028
A23: =IF(ISNUMBER($J23),$J23,"") -> 4408207 | B23: =IFERROR(INDEX('SALES Raw'!$B$6:$B$4467,MATCH($J23,'SALES Raw'!$J$6:$J$4467,0)),IFERROR(INDEX('CEMIUP0.9 Raw'!$B$6:$B$1712,MATCH($J23,'CEMIUP0.9 Raw'!$B$6:$B$1712,0)),$J23)) -> AC25 0 | C23: =IF(ISNUMBER($J23),IFERROR(INDEX('TRANS'!$C:$C,MATCH($J23,'TRANS'!$B:$B,0)),IFERROR(INDEX('Catalog'!$B:$B,MATCH($J23,'Catalog'!$A:$A,0)),$B23)),$B23) -> AC-25 חבק לשורש כף היד | D23: =SUMIFS('SALES Raw'!$C$6:$C$4467,'SALES Raw'!$J$6:$J$4467,$J23,'SALES Raw'!$K$6:$K$4467,"Y")+SUMIFS('CEMIUP0.9 Raw'!$D$6:$D$1712,'CEMIUP0.9 Raw'!$B$6:$B$1712,$J23,'CEMIUP0.9 Raw'!$H$6:$H$1712,"Y") -> 1279 | E23: =SUMIFS('SALES Raw'!$D$6:$D$4467,'SALES Raw'!$J$6:$J$4467,$J23,'SALES Raw'!$K$6:$K$4467,"Y")+SUMIFS('CEMIUP0.9 Raw'!$E$6:$E$1712,'CEMIUP0.9 Raw'!$B$6:$B$1712,$J23,'CEMIUP0.9 Raw'!$H$6:$H$1712,"Y") -> 39713.686 | F23: =SUMIFS('SALES Raw'!$E$6:$E$4467,'SALES Raw'!$J$6:$J$4467,$J23,'SALES Raw'!$K$6:$K$4467,"Y")*$H$4+SUMIFS('CEMIUP0.9 Raw'!$F$6:$F$1712,'CEMIUP0.9 Raw'!$B$6:$B$1712,$J23,'CEMIUP0.9 Raw'!$H$6:$H$1712,"Y") -> 1152 | G23: =SUMIFS('SALES Raw'!$F$6:$F$4467,'SALES Raw'!$J$6:$J$4467,$J23,'SALES Raw'!$K$6:$K$4467,"Y")*$H$4+SUMIFS('CEMIUP0.9 Raw'!$G$6:$G$1712,'CEMIUP0.9 Raw'!$B$6:$B$1712,$J23,'CEMIUP0.9 Raw'!$H$6:$H$1712,"Y") -> 37435.275 | H23: 107 - Pharmacies | I23: 102 - Orthopedic institutes | J23: 4408207
A24: =IF(ISNUMBER($J24),$J24,"") -> 4408205 | B24: =IFERROR(INDEX('SALES Raw'!$B$6:$B$4467,MATCH($J24,'SALES Raw'!$J$6:$J$4467,0)),IFERROR(INDEX('CEMIUP0.9 Raw'!$B$6:$B$1712,MATCH($J24,'CEMIUP0.9 Raw'!$B$6:$B$1712,0)),$J24)) -> AC07 0 | C24: =IF(ISNUMBER($J24),IFERROR(INDEX('TRANS'!$C:$C,MATCH($J24,'TRANS'!$B:$B,0)),IFERROR(INDEX('Catalog'!$B:$B,MATCH($J24,'Catalog'!$A:$A,0)),$B24)),$B24) -> AC-07 חגורת גב עם תמיכות | D24: =SUMIFS('SALES Raw'!$C$6:$C$4467,'SALES Raw'!$J$6:$J$4467,$J24,'SALES Raw'!$K$6:$K$4467,"Y")+SUMIFS('CEMIUP0.9 Raw'!$D$6:$D$1712,'CEMIUP0.9 Raw'!$B$6:$B$1712,$J24,'CEMIUP0.9 Raw'!$H$6:$H$1712,"Y") -> 1281 | E24: =SUMIFS('SALES Raw'!$D$6:$D$4467,'SALES Raw'!$J$6:$J$4467,$J24,'SALES Raw'!$K$6:$K$4467,"Y")+SUMIFS('CEMIUP0.9 Raw'!$E$6:$E$1712,'CEMIUP0.9 Raw'!$B$6:$B$1712,$J24,'CEMIUP0.9 Raw'!$H$6:$H$1712,"Y") -> 101632.32 | F24: =SUMIFS('SALES Raw'!$E$6:$E$4467,'SALES Raw'!$J$6:$J$4467,$J24,'SALES Raw'!$K$6:$K$4467,"Y")*$H$4+SUMIFS('CEMIUP0.9 Raw'!$F$6:$F$1712,'CEMIUP0.9 Raw'!$B$6:$B$1712,$J24,'CEMIUP0.9 Raw'!$H$6:$H$1712,"Y") -> 1106.5263 | G24: =SUMIFS('SALES Raw'!$F$6:$F$4467,'SALES Raw'!$J$6:$J$4467,$J24,'SALES Raw'!$K$6:$K$4467,"Y")*$H$4+SUMIFS('CEMIUP0.9 Raw'!$G$6:$G$1712,'CEMIUP0.9 Raw'!$B$6:$B$1712,$J24,'CEMIUP0.9 Raw'!$H$6:$H$1712,"Y") -> 89404.142 | H24: 107 - Pharmacies | I24: 114 - IL online | J24: 4408205
A25: =IF(ISNUMBER($J25),$J25,"") -> 4422031 | B25: =IFERROR(INDEX('SALES Raw'!$B$6:$B$4467,MATCH($J25,'SALES Raw'!$J$6:$J$4467,0)),IFERROR(INDEX('CEMIUP0.9 Raw'!$B$6:$B$1712,MATCH($J25,'CEMIUP0.9 Raw'!$B$6:$B$1712,0)),$J25)) -> 807CB-C | C25: =IF(ISNUMBER($J25),IFERROR(INDEX('TRANS'!$C:$C,MATCH($J25,'TRANS'!$B:$B,0)),IFERROR(INDEX('Catalog'!$B:$B,MATCH($J25,'Catalog'!$A:$A,0)),$B25)),$B25) -> 807CB-Cתחבושת נצמדת בז' 20 מ""""מ | D25: =SUMIFS('SALES Raw'!$C$6:$C$4467,'SALES Raw'!$J$6:$J$4467,$J25,'SALES Raw'!$K$6:$K$4467,"Y")+SUMIFS('CEMIUP0.9 Raw'!$D$6:$D$1712,'CEMIUP0.9 Raw'!$B$6:$B$1712,$J25,'CEMIUP0.9 Raw'!$H$6:$H$1712,"Y") -> 736 | E25: =SUMIFS('SALES Raw'!$D$6:$D$4467,'SALES Raw'!$J$6:$J$4467,$J25,'SALES Raw'!$K$6:$K$4467,"Y")+SUMIFS('CEMIUP0.9 Raw'!$E$6:$E$1712,'CEMIUP0.9 Raw'!$B$6:$B$1712,$J25,'CEMIUP0.9 Raw'!$H$6:$H$1712,"Y") -> 7031.191 | F25: =SUMIFS('SALES Raw'!$E$6:$E$4467,'SALES Raw'!$J$6:$J$4467,$J25,'SALES Raw'!$K$6:$K$4467,"Y")*$H$4+SUMIFS('CEMIUP0.9 Raw'!$F$6:$F$1712,'CEMIUP0.9 Raw'!$B$6:$B$1712,$J25,'CEMIUP0.9 Raw'!$H$6:$H$1712,"Y") -> 1021.8947 | G25: =SUMIFS('SALES Raw'!$F$6:$F$4467,'SALES Raw'!$J$6:$J$4467,$J25,'SALES Raw'!$K$6:$K$4467,"Y")*$H$4+SUMIFS('CEMIUP0.9 Raw'!$G$6:$G$1712,'CEMIUP0.9 Raw'!$B$6:$B$1712,$J25,'CEMIUP0.9 Raw'!$H$6:$H$1712,"Y") -> 10935.032 | H25: 107 - Pharmacies | I25: 114 - IL online | J25: 4422031
A26: =IF(ISNUMBER($J26),$J26,"") -> 4420002 | B26: =IFERROR(INDEX('SALES Raw'!$B$6:$B$4467,MATCH($J26,'SALES Raw'!$J$6:$J$4467,0)),IFERROR(INDEX('CEMIUP0.9 Raw'!$B$6:$B$1712,MATCH($J26,'CEMIUP0.9 Raw'!$B$6:$B$1712,0)),$J26)) -> 372 0 | C26: =IF(ISNUMBER($J26),IFERROR(INDEX('TRANS'!$C:$C,MATCH($J26,'TRANS'!$B:$B,0)),IFERROR(INDEX('Catalog'!$B:$B,MATCH($J26,'Catalog'!$A:$A,0)),$B26)),$B26) -> 372 רפידת אנטי ריח -זוג | D26: =SUMIFS('SALES Raw'!$C$6:$C$4467,'SALES Raw'!$J$6:$J$4467,$J26,'SALES Raw'!$K$6:$K$4467,"Y")+SUMIFS('CEMIUP0.9 Raw'!$D$6:$D$1712,'CEMIUP0.9 Raw'!$B$6:$B$1712,$J26,'CEMIUP0.9 Raw'!$H$6:$H$1712,"Y") -> 1496 | E26: =SUMIFS('SALES Raw'!$D$6:$D$4467,'SALES Raw'!$J$6:$J$4467,$J26,'SALES Raw'!$K$6:$K$4467,"Y")+SUMIFS('CEMIUP0.9 Raw'!$E$6:$E$1712,'CEMIUP0.9 Raw'!$B$6:$B$1712,$J26,'CEMIUP0.9 Raw'!$H$6:$H$1712,"Y") -> 17769.837 | F26: =SUMIFS('SALES Raw'!$E$6:$E$4467,'SALES Raw'!$J$6:$J$4467,$J26,'SALES Raw'!$K$6:$K$4467,"Y")*$H$4+SUMIFS('CEMIUP0.9 Raw'!$F$6:$F$1712,'CEMIUP0.9 Raw'!$B$6:$B$1712,$J26,'CEMIUP0.9 Raw'!$H$6:$H$1712,"Y") -> 986.52632 | G26: =SUMIFS('SALES Raw'!$F$6:$F$4467,'SALES Raw'!$J$6:$J$4467,$J26,'SALES Raw'!$K$6:$K$4467,"Y")*$H$4+SUMIFS('CEMIUP0.9 Raw'!$G$6:$G$1712,'CEMIUP0.9 Raw'!$B$6:$B$1712,$J26,'CEMIUP0.9 Raw'!$H$6:$H$1712,"Y") -> 12019.901 | H26: 107 - Pharmacies | I26: 113 - Kupat Holim Meuhedet | J26: 4420002
... A62: =IF(ISNUMBER($J62),$J62,"") -> 4415027 | B62: =IFERROR(INDEX('SALES Raw'!$B$6:$B$4467,MATCH($J62,'SALES Raw'!$J$6:$J$4467,0)),IFERROR(INDEX('CEMIUP0.9 Raw'!$B$6:$B$1712,MATCH($J62,'CEMIUP0.9 Raw'!$B$6:$B$1712,0)),$J62)) -> AC27R 0 | C62: =IF(ISNUMBER($J62),IFERROR(INDEX('TRANS'!$C:$C,MATCH($J62,'TRANS'!$B:$B,0)),IFERROR(INDEX('Catalog'!$B:$B,MATCH($J62,'Catalog'!$A:$A,0)),$B62)),$B62) -> AC-27R סד לש.כף יד ימין | D62: =SUMIFS('SALES Raw'!$C$6:$C$4467,'SALES Raw'!$J$6:$J$4467,$J62,'SALES Raw'!$K$6:$K$4467,"Y")+SUMIFS('CEMIUP0.9 Raw'!$D$6:$D$1712,'CEMIUP0.9 Raw'!$B$6:$B$1712,$J62,'CEMIUP0.9 Raw'!$H$6:$H$1712,"Y") -> 471 | E62: =SUMIFS('SALES Raw'!$D$6:$D$4467,'SALES Raw'!$J$6:$J$4467,$J62,'SALES Raw'!$K$6:$K$4467,"Y")+SUMIFS('CEMIUP0.9 Raw'!$E$6:$E$1712,'CEMIUP0.9 Raw'!$B$6:$B$1712,$J62,'CEMIUP0.9 Raw'!$H$6:$H$1712,"Y") -> 18535.297 | F62: =SUMIFS('SALES Raw'!$E$6:$E$4467,'SALES Raw'!$J$6:$J$4467,$J62,'SALES Raw'!$K$6:$K$4467,"Y")*$H$4+SUMIFS('CEMIUP0.9 Raw'!$F$6:$F$1712,'CEMIUP0.9 Raw'!$B$6:$B$1712,$J62,'CEMIUP0.9 Raw'!$H$6:$H$1712,"Y") -> 462.31579 | G62: =SUMIFS('SALES Raw'!$F$6:$F$4467,'SALES Raw'!$J$6:$J$4467,$J62,'SALES Raw'!$K$6:$K$4467,"Y")*$H$4+SUMIFS('CEMIUP0.9 Raw'!$G$6:$G$1712,'CEMIUP0.9 Raw'!$B$6:$B$1712,$J62,'CEMIUP0.9 Raw'!$H$6:$H$1712,"Y") -> 21773.502 | H62: 107 - Pharmacies | I62: 114 - IL online | J62: 4415027
A63: =IF(ISNUMBER($J63),$J63,"") | B63: =IFERROR(INDEX('SALES Raw'!$B$6:$B$4467,MATCH($J63,'SALES Raw'!$J$6:$J$4467,0)),IFERROR(INDEX('CEMIUP0.9 Raw'!$B$6:$B$1712,MATCH($J63,'CEMIUP0.9 Raw'!$B$6:$B$1712,0)),$J63)) -> 8011 0 | C63: =IF(ISNUMBER($J63),IFERROR(INDEX('TRANS'!$C:$C,MATCH($J63,'TRANS'!$B:$B,0)),IFERROR(INDEX('Catalog'!$B:$B,MATCH($J63,'Catalog'!$A:$A,0)),$B63)),$B63) -> 8011 0 | D63: =SUMIFS('SALES Raw'!$C$6:$C$4467,'SALES Raw'!$J$6:$J$4467,$J63,'SALES Raw'!$K$6:$K$4467,"Y")+SUMIFS('CEMIUP0.9 Raw'!$D$6:$D$1712,'CEMIUP0.9 Raw'!$B$6:$B$1712,$J63,'CEMIUP0.9 Raw'!$H$6:$H$1712,"Y") -> 34 | E63: =SUMIFS('SALES Raw'!$D$6:$D$4467,'SALES Raw'!$J$6:$J$4467,$J63,'SALES Raw'!$K$6:$K$4467,"Y")+SUMIFS('CEMIUP0.9 Raw'!$E$6:$E$1712,'CEMIUP0.9 Raw'!$B$6:$B$1712,$J63,'CEMIUP0.9 Raw'!$H$6:$H$1712,"Y") -> 176.64 | F63: =SUMIFS('SALES Raw'!$E$6:$E$4467,'SALES Raw'!$J$6:$J$4467,$J63,'SALES Raw'!$K$6:$K$4467,"Y")*$H$4+SUMIFS('CEMIUP0.9 Raw'!$F$6:$F$1712,'CEMIUP0.9 Raw'!$B$6:$B$1712,$J63,'CEMIUP0.9 Raw'!$H$6:$H$1712,"Y") -> 458.52632 | G63: =SUMIFS('SALES Raw'!$F$6:$F$4467,'SALES Raw'!$J$6:$J$4467,$J63,'SALES Raw'!$K$6:$K$4467,"Y")*$H$4+SUMIFS('CEMIUP0.9 Raw'!$G$6:$G$1712,'CEMIUP0.9 Raw'!$B$6:$B$1712,$J63,'CEMIUP0.9 Raw'!$H$6:$H$1712,"Y") -> 2559.6379 | H63: 114 - IL online | I63: 109 - Private Shops | J63: 8011 0
A64: =IF(ISNUMBER($J64),$J64,"") -> 4408098 | B64: =IFERROR(INDEX('SALES Raw'!$B$6:$B$4467,MATCH($J64,'SALES Raw'!$J$6:$J$4467,0)),IFERROR(INDEX('CEMIUP0.9 Raw'!$B$6:$B$1712,MATCH($J64,'CEMIUP0.9 Raw'!$B$6:$B$1712,0)),$J64)) -> T25 0 | C64: =IF(ISNUMBER($J64),IFERROR(INDEX('TRANS'!$C:$C,MATCH($J64,'TRANS'!$B:$B,0)),IFERROR(INDEX('Catalog'!$B:$B,MATCH($J64,'Catalog'!$A:$A,0)),$B64)),$B64) -> T25-חבק יד אגודלי | D64: =SUMIFS('SALES Raw'!$C$6:$C$4467,'SALES Raw'!$J$6:$J$4467,$J64,'SALES Raw'!$K$6:$K$4467,"Y")+SUMIFS('CEMIUP0.9 Raw'!$D$6:$D$1712,'CEMIUP0.9 Raw'!$B$6:$B$1712,$J64,'CEMIUP0.9 Raw'!$H$6:$H$1712,"Y") -> 643 | E64: =SUMIFS('SALES Raw'!$D$6:$D$4467,'SALES Raw'!$J$6:$J$4467,$J64,'SALES Raw'!$K$6:$K$4467,"Y")+SUMIFS('CEMIUP0.9 Raw'!$E$6:$E$1712,'CEMIUP0.9 Raw'!$B$6:$B$1712,$J64,'CEMIUP0.9 Raw'!$H$6:$H$1712,"Y") -> 27082.205 | F64: =SUMIFS('SALES Raw'!$E$6:$E$4467,'SALES Raw'!$J$6:$J$4467,$J64,'SALES Raw'!$K$6:$K$4467,"Y")*$H$4+SUMIFS('CEMIUP0.9 Raw'!$F$6:$F$1712,'CEMIUP0.9 Raw'!$B$6:$B$1712,$J64,'CEMIUP0.9 Raw'!$H$6:$H$1712,"Y") -> 450.94737 | G64: =SUMIFS('SALES Raw'!$F$6:$F$4467,'SALES Raw'!$J$6:$J$4467,$J64,'SALES Raw'!$K$6:$K$4467,"Y")*$H$4+SUMIFS('CEMIUP0.9 Raw'!$G$6:$G$1712,'CEMIUP0.9 Raw'!$B$6:$B$1712,$J64,'CEMIUP0.9 Raw'!$H$6:$H$1712,"Y") -> 19571.315 | H64: 107 - Pharmacies | I64: 102 - Orthopedic institutes | J64: 4408098
A65: =IF(ISNUMBER($J65),$J65,"") -> 4413043 | B65: =IFERROR(INDEX('SALES Raw'!$B$6:$B$4467,MATCH($J65,'SALES Raw'!$J$6:$J$4467,0)),IFERROR(INDEX('CEMIUP0.9 Raw'!$B$6:$B$1712,MATCH($J65,'CEMIUP0.9 Raw'!$B$6:$B$1712,0)),$J65)) -> 34 L | C65: =IF(ISNUMBER($J65),IFERROR(INDEX('TRANS'!$C:$C,MATCH($J65,'TRANS'!$B:$B,0)),IFERROR(INDEX('Catalog'!$B:$B,MATCH($J65,'Catalog'!$A:$A,0)),$B65)),$B65) -> 34 L מגן קרסול עקב סגור | D65: =SUMIFS('SALES Raw'!$C$6:$C$4467,'SALES Raw'!$J$6:$J$4467,$J65,'SALES Raw'!$K$6:$K$4467,"Y")+SUMIFS('CEMIUP0.9 Raw'!$D$6:$D$1712,'CEMIUP0.9 Raw'!$B$6:$B$1712,$J65,'CEMIUP0.9 Raw'!$H$6:$H$1712,"Y") -> 550 | E65: =SUMIFS('SALES Raw'!$D$6:$D$4467,'SALES Raw'!$J$6:$J$4467,$J65,'SALES Raw'!$K$6:$K$4467,"Y")+SUMIFS('CEMIUP0.9 Raw'!$E$6:$E$1712,'CEMIUP0.9 Raw'!$B$6:$B$1712,$J65,'CEMIUP0.9 Raw'!$H$6:$H$1712,"Y") -> 19398.849 | F65: =SUMIFS('SALES Raw'!$E$6:$E$4467,'SALES Raw'!$J$6:$J$4467,$J65,'SALES Raw'!$K$6:$K$4467,"Y")*$H$4+SUMIFS('CEMIUP0.9 Raw'!$F$6:$F$1712,'CEMIUP0.9 Raw'!$B$6:$B$1712,$J65,'CEMIUP0.9 Raw'!$H$6:$H$1712,"Y") -> 450.94737 | G65: =SUMIFS('SALES Raw'!$F$6:$F$4467,'SALES Raw'!$J$6:$J$4467,$J65,'SALES Raw'!$K$6:$K$4467,"Y")*$H$4+SUMIFS('CEMIUP0.9 Raw'!$G$6:$G$1712,'CEMIUP0.9 Raw'!$B$6:$B$1712,$J65,'CEMIUP0.9 Raw'!$H$6:$H$1712,"Y") -> 15640.571 | H65: 113 - Kupat Holim Meuhedet | I65: 107 - Pharmacies | J65: 4413043
A66: =IF(ISNUMBER($J66),$J66,"") -> 4420003 | B66: =IFERROR(INDEX('SALES Raw'!$B$6:$B$4467,MATCH($J66,'SALES Raw'!$J$6:$J$4467,0)),IFERROR(INDEX('CEMIUP0.9 Raw'!$B$6:$B$1712,MATCH($J66,'CEMIUP0.9 Raw'!$B$6:$B$1712,0)),$J66)) -> 374 0 | C66: =IF(ISNUMBER($J66),IFERROR(INDEX('TRANS'!$C:$C,MATCH($J66,'TRANS'!$B:$B,0)),IFERROR(INDEX('Catalog'!$B:$B,MATCH($J66,'Catalog'!$A:$A,0)),$B66)),$B66) -> 374 רפידת בולמת זעזועים -זוג | D66: =SUMIFS('SALES Raw'!$C$6:$C$4467,'SALES Raw'!$J$6:$J$4467,$J66,'SALES Raw'!$K$6:$K$4467,"Y")+SUMIFS('CEMIUP0.9 Raw'!$D$6:$D$1712,'CEMIUP0.9 Raw'!$B$6:$B$1712,$J66,'CEMIUP0.9 Raw'!$H$6:$H$1712,"Y") -> 615 | E66: =SUMIFS('SALES Raw'!$D$6:$D$4467,'SALES Raw'!$J$6:$J$4467,$J66,'SALES Raw'!$K$6:$K$4467,"Y")+SUMIFS('CEMIUP0.9 Raw'!$E$6:$E$1712,'CEMIUP0.9 Raw'!$B$6:$B$1712,$J66,'CEMIUP0.9 Raw'!$H$6:$H$1712,"Y") -> 7630.552 | F66: =SUMIFS('SALES Raw'!$E$6:$E$4467,'SALES Raw'!$J$6:$J$4467,$J66,'SALES Raw'!$K$6:$K$4467,"Y")*$H$4+SUMIFS('CEMIUP0.9 Raw'!$F$6:$F$1712,'CEMIUP0.9 Raw'!$B$6:$B$1712,$J66,'CEMIUP0.9 Raw'!$H$6:$H$1712,"Y") -> 432 | G66: =SUMIFS('SALES Raw'!$F$6:$F$4467,'SALES Raw'!$J$6:$J$4467,$J66,'SALES Raw'!$K$6:$K$4467,"Y")*$H$4+SUMIFS('CEMIUP0.9 Raw'!$G$6:$G$1712,'CEMIUP0.9 Raw'!$B$6:$B$1712,$J66,'CEMIUP0.9 Raw'!$H$6:$H$1712,"Y") -> 5516.6716 | H66: 107 - Pharmacies | I66: 113 - Kupat Holim Meuhedet | J66: 4420003
A67: =IF(ISNUMBER($J67),$J67,"") -> 4413102 | B67: =IFERROR(INDEX('SALES Raw'!$B$6:$B$4467,MATCH($J67,'SALES Raw'!$J$6:$J$4467,0)),IFERROR(INDEX('CEMIUP0.9 Raw'!$B$6:$B$1712,MATCH($J67,'CEMIUP0.9 Raw'!$B$6:$B$1712,0)),$J67)) -> 45E L | C67: =IF(ISNUMBER($J67),IFERROR(INDEX('TRANS'!$C:$C,MATCH($J67,'TRANS'!$B:$B,0)),IFERROR(INDEX('Catalog'!$B:$B,MATCH($J67,'Catalog'!$A:$A,0)),$B67)),$B67) -> 45E L מגן ברך ארוך לבן | D67: =SUMIFS('SALES Raw'!$C$6:$C$4467,'SALES Raw'!$J$6:$J$4467,$J67,'SALES Raw'!$K$6:$K$4467,"Y")+SUMIFS('CEMIUP0.9 Raw'!$D$6:$D$1712,'CEMIUP0.9 Raw'!$B$6:$B$1712,$J67,'CEMIUP0.9 Raw'!$H$6:$H$1712,"Y") -> 547 | E67: =SUMIFS('SALES Raw'!$D$6:$D$4467,'SALES Raw'!$J$6:$J$4467,$J67,'SALES Raw'!$K$6:$K$4467,"Y")+SUMIFS('CEMIUP0.9 Raw'!$E$6:$E$1712,'CEMIUP0.9 Raw'!$B$6:$B$1712,$J67,'CEMIUP0.9 Raw'!$H$6:$H$1712,"Y") -> 13691.029 | F67: =SUMIFS('SALES Raw'!$E$6:$E$4467,'SALES Raw'!$J$6:$J$4467,$J67,'SALES Raw'!$K$6:$K$4467,"Y")*$H$4+SUMIFS('CEMIUP0.9 Raw'!$F$6:$F$1712,'CEMIUP0.9 Raw'!$B$6:$B$1712,$J67,'CEMIUP0.9 Raw'!$H$6:$H$1712,"Y") -> 430.73684 | G67: =SUMIFS('SALES Raw'!$F$6:$F$4467,'SALES Raw'!$J$6:$J$4467,$J67,'SALES Raw'!$K$6:$K$4467,"Y")*$H$4+SUMIFS('CEMIUP0.9 Raw'!$G$6:$G$1712,'CEMIUP0.9 Raw'!$B$6:$B$1712,$J67,'CEMIUP0.9 Raw'!$H$6:$H$1712,"Y") -> 10404.75 | H67: 113 - Kupat Holim Meuhedet | I67: 107 - Pharmacies | J67: 4413102
A68: =IF(ISNUMBER($J68),$J68,"") -> 4409017 | B68: =IFERROR(INDEX('SALES Raw'!$B$6:$B$4467,MATCH($J68,'SALES Raw'!$J$6:$J$4467,0)),IFERROR(INDEX('CEMIUP0.9 Raw'!$B$6:$B$1712,MATCH($J68,'CEMIUP0.9 Raw'!$B$6:$B$1712,0)),$J68)) -> 808KT-B | C68: =IF(ISNUMBER($J68),IFERROR(INDEX('TRANS'!$C:$C,MATCH($J68,'TRANS'!$B:$B,0)),IFERROR(INDEX('Catalog'!$B:$B,MATCH($J68,'Catalog'!$A:$A,0)),$B68)),$B68) -> 808KT-B טייפ קינזיולוגי | D68: =SUMIFS('SALES Raw'!$C$6:$C$4467,'SALES Raw'!$J$6:$J$4467,$J68,'SALES Raw'!$K$6:$K$4467,"Y")+SUMIFS('CEMIUP0.9 Raw'!$D$6:$D$1712,'CEMIUP0.9 Raw'!$B$6:$B$1712,$J68,'CEMIUP0.9 Raw'!$H$6:$H$1712,"Y") -> 605 | E68: =SUMIFS('SALES Raw'!$D$6:$D$4467,'SALES Raw'!$J$6:$J$4467,$J68,'SALES Raw'!$K$6:$K$4467,"Y")+SUMIFS('CEMIUP0.9 Raw'!$E$6:$E$1712,'CEMIUP0.9 Raw'!$B$6:$B$1712,$J68,'CEMIUP0.9 Raw'!$H$6:$H$1712,"Y") -> 17733.278 | F68: =SUMIFS('SALES Raw'!$E$6:$E$4467,'SALES Raw'!$J$6:$J$4467,$J68,'SALES Raw'!$K$6:$K$4467,"Y")*$H$4+SUMIFS('CEMIUP0.9 Raw'!$F$6:$F$1712,'CEMIUP0.9 Raw'!$B$6:$B$1712,$J68,'CEMIUP0.9 Raw'!$H$6:$H$1712,"Y") -> 428.21053 | G68: =SUMIFS('SALES Raw'!$F$6:$F$4467,'SALES Raw'!$J$6:$J$4467,$J68,'SALES Raw'!$K$6:$K$4467,"Y")*$H$4+SUMIFS('CEMIUP0.9 Raw'!$G$6:$G$1712,'CEMIUP0.9 Raw'!$B$6:$B$1712,$J68,'CEMIUP0.9 Raw'!$H$6:$H$1712,"Y") -> 14138.368 | H68: 107 - Pharmacies | I68: 113 - Kupat Holim Meuhedet | J68: 4409017
A69: =IF(ISNUMBER($J69),$J69,"") -> 4413048 | B69: =IFERROR(INDEX('SALES Raw'!$B$6:$B$4467,MATCH($J69,'SALES Raw'!$J$6:$J$4467,0)),IFERROR(INDEX('CEMIUP0.9 Raw'!$B$6:$B$1712,MATCH($J69,'CEMIUP0.9 Raw'!$B$6:$B$1712,0)),$J69)) -> 35 L | C69: =IF(ISNUMBER($J69),IFERROR(INDEX('TRANS'!$C:$C,MATCH($J69,'TRANS'!$B:$B,0)),IFERROR(INDEX('Catalog'!$B:$B,MATCH($J69,'Catalog'!$A:$A,0)),$B69)),$B69) -> 35 L מגן קרסול לבן | D69: =SUMIFS('SALES Raw'!$C$6:$C$4467,'SALES Raw'!$J$6:$J$4467,$J69,'SALES Raw'!$K$6:$K$4467,"Y")+SUMIFS('CEMIUP0.9 Raw'!$D$6:$D$1712,'CEMIUP0.9 Raw'!$B$6:$B$1712,$J69,'CEMIUP0.9 Raw'!$H$6:$H$1712,"Y") -> 474 | E69: =SUMIFS('SALES Raw'!$D$6:$D$4467,'SALES Raw'!$J$6:$J$4467,$J69,'SALES Raw'!$K$6:$K$4467,"Y")+SUMIFS('CEMIUP0.9 Raw'!$E$6:$E$1712,'CEMIUP0.9 Raw'!$B$6:$B$1712,$J69,'CEMIUP0.9 Raw'!$H$6:$H$1712,"Y") -> 10731.752 | F69: =SUMIFS('SALES Raw'!$E$6:$E$4467,'SALES Raw'!$J$6:$J$4467,$J69,'SALES Raw'!$K$6:$K$4467,"Y")*$H$4+SUMIFS('CEMIUP0.9 Raw'!$F$6:$F$1712,'CEMIUP0.9 Raw'!$B$6:$B$1712,$J69,'CEMIUP0.9 Raw'!$H$6:$H$1712,"Y") -> 424.42105 | G69: =SUMIFS('SALES Raw'!$F$6:$F$4467,'SALES Raw'!$J$6:$J$4467,$J69,'SALES Raw'!$K$6:$K$4467,"Y")*$H$4+SUMIFS('CEMIUP0.9 Raw'!$G$6:$G$1712,'CEMIUP0.9 Raw'!$B$6:$B$1712,$J69,'CEMIUP0.9 Raw'!$H$6:$H$1712,"Y") -> 9389.3861 | H69: 113 - Kupat Holim Meuhedet | I69: 107 - Pharmacies | J69: 4413048
A70: =IF(ISNUMBER($J70),$J70,"") -> 4413063 | B70: =IFERROR(INDEX('SALES Raw'!$B$6:$B$4467,MATCH($J70,'SALES Raw'!$J$6:$J$4467,0)),IFERROR(INDEX('CEMIUP0.9 Raw'!$B$6:$B$1712,MATCH($J70,'CEMIUP0.9 Raw'!$B$6:$B$1712,0)),$J70)) -> 366S 0 | C70: =IF(ISNUMBER($J70),IFERROR(INDEX('TRANS'!$C:$C,MATCH($J70,'TRANS'!$B:$B,0)),IFERROR(INDEX('Catalog'!$B:$B,MATCH($J70,'Catalog'!$A:$A,0)),$B70)),$B70) -> 366S-'מדבק.לשחרור לחץ מיבלת2יח | D70: =SUMIFS('SALES Raw'!$C$6:$C$4467,'SALES Raw'!$J$6:$J$4467,$J70,'SALES Raw'!$K$6:$K$4467,"Y")+SUMIFS('CEMIUP0.9 Raw'!$D$6:$D$1712,'CEMIUP0.9 Raw'!$B$6:$B$1712,$J70,'CEMIUP0.9 Raw'!$H$6:$H$1712,"Y") -> 487 | E70: =SUMIFS('SALES Raw'!$D$6:$D$4467,'SALES Raw'!$J$6:$J$4467,$J70,'SALES Raw'!$K$6:$K$4467,"Y")+SUMIFS('CEMIUP0.9 Raw'!$E$6:$E$1712,'CEMIUP0.9 Raw'!$B$6:$B$1712,$J70,'CEMIUP0.9 Raw'!$H$6:$H$1712,"Y") -> 6724.339 | F70: =SUMIFS('SALES Raw'!$E$6:$E$4467,'SALES Raw'!$J$6:$J$4467,$J70,'SALES Raw'!$K$6:$K$4467,"Y")*$H$4+SUMIFS('CEMIUP0.9 Raw'!$F$6:$F$1712,'CEMIUP0.9 Raw'!$B$6:$B$1712,$J70,'CEMIUP0.9 Raw'!$H$6:$H$1712,"Y") -> 414.31579 | G70: =SUMIFS('SALES Raw'!$F$6:$F$4467,'SALES Raw'!$J$6:$J$4467,$J70,'SALES Raw'!$K$6:$K$4467,"Y")*$H$4+SUMIFS('CEMIUP0.9 Raw'!$G$6:$G$1712,'CEMIUP0.9 Raw'!$B$6:$B$1712,$J70,'CEMIUP0.9 Raw'!$H$6:$H$1712,"Y") -> 5692.6648 | H70: 107 - Pharmacies | I70: 113 - Kupat Holim Meuhedet | J70: 4413063
A71: =IF(ISNUMBER($J71),$J71,"") -> 4413136 | B71: =IFERROR(INDEX('SALES Raw'!$B$6:$B$4467,MATCH($J71,'SALES Raw'!$J$6:$J$4467,0)),IFERROR(INDEX('CEMIUP0.9 Raw'!$B$6:$B$1712,MATCH($J71,'CEMIUP0.9 Raw'!$B$6:$B$1712,0)),$J71)) -> 85 M | C71: =IF(ISNUMBER($J71),IFERROR(INDEX('TRANS'!$C:$C,MATCH($J71,'TRANS'!$B:$B,0)),IFERROR(INDEX('Catalog'!$B:$B,MATCH($J71,'Catalog'!$A:$A,0)),$B71)),$B71) -> 85 M (מתלה ליד )כיס | D71: =SUMIFS('SALES Raw'!$C$6:$C$4467,'SALES Raw'!$J$6:$J$4467,$J71,'SALES Raw'!$K$6:$K$4467,"Y")+SUMIFS('CEMIUP0.9 Raw'!$D$6:$D$1712,'CEMIUP0.9 Raw'!$B$6:$B$1712,$J71,'CEMIUP0.9 Raw'!$H$6:$H$1712,"Y") -> 588 | E71: =SUMIFS('SALES Raw'!$D$6:$D$4467,'SALES Raw'!$J$6:$J$4467,$J71,'SALES Raw'!$K$6:$K$4467,"Y")+SUMIFS('CEMIUP0.9 Raw'!$E$6:$E$1712,'CEMIUP0.9 Raw'!$B$6:$B$1712,$J71,'CEMIUP0.9 Raw'!$H$6:$H$1712,"Y") -> 24971.805 | F71: =SUMIFS('SALES Raw'!$E$6:$E$4467,'SALES Raw'!$J$6:$J$4467,$J71,'SALES Raw'!$K$6:$K$4467,"Y")*$H$4+SUMIFS('CEMIUP0.9 Raw'!$F$6:$F$1712,'CEMIUP0.9 Raw'!$B$6:$B$1712,$J71,'CEMIUP0.9 Raw'!$H$6:$H$1712,"Y") -> 414.31579 | G71: =SUMIFS('SALES Raw'!$F$6:$F$4467,'SALES Raw'!$J$6:$J$4467,$J71,'SALES Raw'!$K$6:$K$4467,"Y")*$H$4+SUMIFS('CEMIUP0.9 Raw'!$G$6:$G$1712,'CEMIUP0.9 Raw'!$B$6:$B$1712,$J71,'CEMIUP0.9 Raw'!$H$6:$H$1712,"Y") -> 17726.893 | H71: 113 - Kupat Holim Meuhedet | I71: 107 - Pharmacies | J71: 4413136
A72: =IF(ISNUMBER($J72),$J72,"") -> 4413053 | B72: =IFERROR(INDEX('SALES Raw'!$B$6:$B$4467,MATCH($J72,'SALES Raw'!$J$6:$J$4467,0)),IFERROR(INDEX('CEMIUP0.9 Raw'!$B$6:$B$1712,MATCH($J72,'CEMIUP0.9 Raw'!$B$6:$B$1712,0)),$J72)) -> 35C L | C72: =IF(ISNUMBER($J72),IFERROR(INDEX('TRANS'!$C:$C,MATCH($J72,'TRANS'!$B:$B,0)),IFERROR(INDEX('Catalog'!$B:$B,MATCH($J72,'Catalog'!$A:$A,0)),$B72)),$B72) -> 35C L מגן קרסול חום | D72: =SUMIFS('SALES Raw'!$C$6:$C$4467,'SALES Raw'!$J$6:$J$4467,$J72,'SALES Raw'!$K$6:$K$4467,"Y")+SUMIFS('CEMIUP0.9 Raw'!$D$6:$D$1712,'CEMIUP0.9 Raw'!$B$6:$B$1712,$J72,'CEMIUP0.9 Raw'!$H$6:$H$1712,"Y") -> 443 | E72: =SUMIFS('SALES Raw'!$D$6:$D$4467,'SALES Raw'!$J$6:$J$4467,$J72,'SALES Raw'!$K$6:$K$4467,"Y")+SUMIFS('CEMIUP0.9 Raw'!$E$6:$E$1712,'CEMIUP0.9 Raw'!$B$6:$B$1712,$J72,'CEMIUP0.9 Raw'!$H$6:$H$1712,"Y") -> 12438.356 | F72: =SUMIFS('SALES Raw'!$E$6:$E$4467,'SALES Raw'!$J$6:$J$4467,$J72,'SALES Raw'!$K$6:$K$4467,"Y")*$H$4+SUMIFS('CEMIUP0.9 Raw'!$F$6:$F$1712,'CEMIUP0.9 Raw'!$B$6:$B$1712,$J72,'CEMIUP0.9 Raw'!$H$6:$H$1712,"Y") -> 414.31579 | G72: =SUMIFS('SALES Raw'!$F$6:$F$4467,'SALES Raw'!$J$6:$J$4467,$J72,'SALES Raw'!$K$6:$K$4467,"Y")*$H$4+SUMIFS('CEMIUP0.9 Raw'!$G$6:$G$1712,'CEMIUP0.9 Raw'!$B$6:$B$1712,$J72,'CEMIUP0.9 Raw'!$H$6:$H$1712,"Y") -> 11659.645 | H72: 107 - Pharmacies | I72: 102 - Orthopedic institutes | J72: 4413053
A73: =IF(ISNUMBER($J73),$J73,"") -> 4413098 | B73: =IFERROR(INDEX('SALES Raw'!$B$6:$B$4467,MATCH($J73,'SALES Raw'!$J$6:$J$4467,0)),IFERROR(INDEX('CEMIUP0.9 Raw'!$B$6:$B$1712,MATCH($J73,'CEMIUP0.9 Raw'!$B$6:$B$1712,0)),$J73)) -> 45C L | C73: =IF(ISNUMBER($J73),IFERROR(INDEX('TRANS'!$C:$C,MATCH($J73,'TRANS'!$B:$B,0)),IFERROR(INDEX('Catalog'!$B:$B,MATCH($J73,'Catalog'!$A:$A,0)),$B73)),$B73) -> 45C L מגן ברך חום | D73: =SUMIFS('SALES Raw'!$C$6:$C$4467,'SALES Raw'!$J$6:$J$4467,$J73,'SALES Raw'!$K$6:$K$4467,"Y")+SUMIFS('CEMIUP0.9 Raw'!$D$6:$D$1712,'CEMIUP0.9 Raw'!$B$6:$B$1712,$J73,'CEMIUP0.9 Raw'!$H$6:$H$1712,"Y") -> 545 | E73: =SUMIFS('SALES Raw'!$D$6:$D$4467,'SALES Raw'!$J$6:$J$4467,$J73,'SALES Raw'!$K$6:$K$4467,"Y")+SUMIFS('CEMIUP0.9 Raw'!$E$6:$E$1712,'CEMIUP0.9 Raw'!$B$6:$B$1712,$J73,'CEMIUP0.9 Raw'!$H$6:$H$1712,"Y") -> 15359.907 | F73: =SUMIFS('SALES Raw'!$E$6:$E$4467,'SALES Raw'!$J$6:$J$4467,$J73,'SALES Raw'!$K$6:$K$4467,"Y")*$H$4+SUMIFS('CEMIUP0.9 Raw'!$F$6:$F$1712,'CEMIUP0.9 Raw'!$B$6:$B$1712,$J73,'CEMIUP0.9 Raw'!$H$6:$H$1712,"Y") -> 411.78947 | G73: =SUMIFS('SALES Raw'!$F$6:$F$4467,'SALES Raw'!$J$6:$J$4467,$J73,'SALES Raw'!$K$6:$K$4467,"Y")*$H$4+SUMIFS('CEMIUP0.9 Raw'!$G$6:$G$1712,'CEMIUP0.9 Raw'!$B$6:$B$1712,$J73,'CEMIUP0.9 Raw'!$H$6:$H$1712,"Y") -> 11623.986 | H73: 107 - Pharmacies | I73: 102 - Orthopedic institutes | J73: 4413098
A74: =IF(ISNUMBER($J74),$J74,"") -> 4413049 | B74: =IFERROR(INDEX('SALES Raw'!$B$6:$B$4467,MATCH($J74,'SALES Raw'!$J$6:$J$4467,0)),IFERROR(INDEX('CEMIUP0.9 Raw'!$B$6:$B$1712,MATCH($J74,'CEMIUP0.9 Raw'!$B$6:$B$1712,0)),$J74)) -> 35 M | C74: =IF(ISNUMBER($J74),IFERROR(INDEX('TRANS'!$C:$C,MATCH($J74,'TRANS'!$B:$B,0)),IFERROR(INDEX('Catalog'!$B:$B,MATCH($J74,'Catalog'!$A:$A,0)),$B74)),$B74) -> 35 M מגן קרסול לבן | D74: =SUMIFS('SALES Raw'!$C$6:$C$4467,'SALES Raw'!$J$6:$J$4467,$J74,'SALES Raw'!$K$6:$K$4467,"Y")+SUMIFS('CEMIUP0.9 Raw'!$D$6:$D$1712,'CEMIUP0.9 Raw'!$B$6:$B$1712,$J74,'CEMIUP0.9 Raw'!$H$6:$H$1712,"Y") -> 524 | E74: =SUMIFS('SALES Raw'!$D$6:$D$4467,'SALES Raw'!$J$6:$J$4467,$J74,'SALES Raw'!$K$6:$K$4467,"Y")+SUMIFS('CEMIUP0.9 Raw'!$E$6:$E$1712,'CEMIUP0.9 Raw'!$B$6:$B$1712,$J74,'CEMIUP0.9 Raw'!$H$6:$H$1712,"Y") -> 11565.168 | F74: =SUMIFS('SALES Raw'!$E$6:$E$4467,'SALES Raw'!$J$6:$J$4467,$J74,'SALES Raw'!$K$6:$K$4467,"Y")*$H$4+SUMIFS('CEMIUP0.9 Raw'!$F$6:$F$1712,'CEMIUP0.9 Raw'!$B$6:$B$1712,$J74,'CEMIUP0.9 Raw'!$H$6:$H$1712,"Y") -> 406.73684 | G74: =SUMIFS('SALES Raw'!$F$6:$F$4467,'SALES Raw'!$J$6:$J$4467,$J74,'SALES Raw'!$K$6:$K$4467,"Y")*$H$4+SUMIFS('CEMIUP0.9 Raw'!$G$6:$G$1712,'CEMIUP0.9 Raw'!$B$6:$B$1712,$J74,'CEMIUP0.9 Raw'!$H$6:$H$1712,"Y") -> 8992.3251 | H74: 113 - Kupat Holim Meuhedet | I74: 107 - Pharmacies | J74: 4413049
A75: =IF(ISNUMBER($J75),$J75,"") -> 4413041 | B75: =IFERROR(INDEX('SALES Raw'!$B$6:$B$4467,MATCH($J75,'SALES Raw'!$J$6:$J$4467,0)),IFERROR(INDEX('CEMIUP0.9 Raw'!$B$6:$B$1712,MATCH($J75,'CEMIUP0.9 Raw'!$B$6:$B$1712,0)),$J75)) -> 34 M | C75: =IF(ISNUMBER($J75),IFERROR(INDEX('TRANS'!$C:$C,MATCH($J75,'TRANS'!$B:$B,0)),IFERROR(INDEX('Catalog'!$B:$B,MATCH($J75,'Catalog'!$A:$A,0)),$B75)),$B75) -> 34 M מגן קרסול עקב סגור | D75: =SUMIFS('SALES Raw'!$C$6:$C$4467,'SALES Raw'!$J$6:$J$4467,$J75,'SALES Raw'!$K$6:$K$4467,"Y")+SUMIFS('CEMIUP0.9 Raw'!$D$6:$D$1712,'CEMIUP0.9 Raw'!$B$6:$B$1712,$J75,'CEMIUP0.9 Raw'!$H$6:$H$1712,"Y") -> 524 | E75: =SUMIFS('SALES Raw'!$D$6:$D$4467,'SALES Raw'!$J$6:$J$4467,$J75,'SALES Raw'!$K$6:$K$4467,"Y")+SUMIFS('CEMIUP0.9 Raw'!$E$6:$E$1712,'CEMIUP0.9 Raw'!$B$6:$B$1712,$J75,'CEMIUP0.9 Raw'!$H$6:$H$1712,"Y") -> 18177.959 | F75: =SUMIFS('SALES Raw'!$E$6:$E$4467,'SALES Raw'!$J$6:$J$4467,$J75,'SALES Raw'!$K$6:$K$4467,"Y")*$H$4+SUMIFS('CEMIUP0.9 Raw'!$F$6:$F$1712,'CEMIUP0.9 Raw'!$B$6:$B$1712,$J75,'CEMIUP0.9 Raw'!$H$6:$H$1712,"Y") -> 396.63158 | G75: =SUMIFS('SALES Raw'!$F$6:$F$4467,'SALES Raw'!$J$6:$J$4467,$J75,'SALES Raw'!$K$6:$K$4467,"Y")*$H$4+SUMIFS('CEMIUP0.9 Raw'!$G$6:$G$1712,'CEMIUP0.9 Raw'!$B$6:$B$1712,$J75,'CEMIUP0.9 Raw'!$H$6:$H$1712,"Y") -> 13144.293 | H75: 113 - Kupat Holim Meuhedet | I75: 107 - Pharmacies | J75: 4413041
... A165: =IF(ISNUMBER($J165),$J165,"") -> 4413047 | B165: =IFERROR(INDEX('SALES Raw'!$B$6:$B$4467,MATCH($J165,'SALES Raw'!$J$6:$J$4467,0)),IFERROR(INDEX('CEMIUP0.9 Raw'!$B$6:$B$1712,MATCH($J165,'CEMIUP0.9 Raw'!$B$6:$B$1712,0)),$J165)) -> 35 S | C165: =IF(ISNUMBER($J165),IFERROR(INDEX('TRANS'!$C:$C,MATCH($J165,'TRANS'!$B:$B,0)),IFERROR(INDEX('Catalog'!$B:$B,MATCH($J165,'Catalog'!$A:$A,0)),$B165)),$B165) -> 35 S מגן קרסול לבן | D165: =SUMIFS('SALES Raw'!$C$6:$C$4467,'SALES Raw'!$J$6:$J$4467,$J165,'SALES Raw'!$K$6:$K$4467,"Y")+SUMIFS('CEMIUP0.9 Raw'!$D$6:$D$1712,'CEMIUP0.9 Raw'!$B$6:$B$1712,$J165,'CEMIUP0.9 Raw'!$H$6:$H$1712,"Y") -> 218 | E165: =SUMIFS('SALES Raw'!$D$6:$D$4467,'SALES Raw'!$J$6:$J$4467,$J165,'SALES Raw'!$K$6:$K$4467,"Y")+SUMIFS('CEMIUP0.9 Raw'!$E$6:$E$1712,'CEMIUP0.9 Raw'!$B$6:$B$1712,$J165,'CEMIUP0.9 Raw'!$H$6:$H$1712,"Y") -> 5041.787 | F165: =SUMIFS('SALES Raw'!$E$6:$E$4467,'SALES Raw'!$J$6:$J$4467,$J165,'SALES Raw'!$K$6:$K$4467,"Y")*$H$4+SUMIFS('CEMIUP0.9 Raw'!$F$6:$F$1712,'CEMIUP0.9 Raw'!$B$6:$B$1712,$J165,'CEMIUP0.9 Raw'!$H$6:$H$1712,"Y") -> 170.52632 | G165: =SUMIFS('SALES Raw'!$F$6:$F$4467,'SALES Raw'!$J$6:$J$4467,$J165,'SALES Raw'!$K$6:$K$4467,"Y")*$H$4+SUMIFS('CEMIUP0.9 Raw'!$G$6:$G$1712,'CEMIUP0.9 Raw'!$B$6:$B$1712,$J165,'CEMIUP0.9 Raw'!$H$6:$H$1712,"Y") -> 3871.7457 | H165: 113 - Kupat Holim Meuhedet | I165: 107 - Pharmacies | J165: 4413047
...

Sheet 111 - Superpharm Life
A1: 111 - Superpharm Life
A2: Calculation date: | B2: 46290
A3: 111 - Superpharm Life - Source: kirill/outputs/2026-09-20-salestype-2025-vs-2026.xlsx, "Source" sheet, Sale Type = "111 - Superpharm Life". Kept as its OWN separate sheet per explicit instruction - NOT included in "Main List" or any consolidated total. No 0.91 factor (NetSuite-sourced). 2026 normalized to a full year (×12/9.5). Same columns/sort/coloring convention as Main List. Match rate against TRANS/Catalog was 0% for this category - all items use a private-label SKU naming convention not covered by either crosswalk (confirmed by direct inspection, not a data error) - every item is kept as its own row (raw item name as key), not guessed/dropped.
A4: Normalization factor (2026, SALES-sourced rows only - CEMIUP0.9 rows already annualized upstream): | G4: Factor (12/9.5): | H4: =12/9.5 -> 1.2631579
A6: CHEMIPAL Code | B6: ITEM NAME | C6: שם מוצר | D6: כמות 2025 | E6: כסף 2025 (₪) | F6: כמות 2026 (מנורמל) | G6: כסף 2026 (מנורמל, ₪) | H6: Source Category
A7: ='SALES Raw'!G1997 | B7: ='SALES Raw'!B1997 -> LU302M 0 | C7: ='SALES Raw'!H1997 -> LU302M 0 | D7: ='SALES Raw'!C1997 -> 6300 | E7: ='SALES Raw'!D1997 -> 297486 | F7: ='SALES Raw'!E1997*$H$4 -> 8033.6842 | G7: ='SALES Raw'!F1997*$H$4 -> 379350.57 | H7: ='SALES Raw'!A1997 -> 111 - Superpharm Life
A8: ='SALES Raw'!G2009 | B8: ='SALES Raw'!B2009 -> LU370 0 | C8: ='SALES Raw'!H2009 -> LU370 0 | D8: ='SALES Raw'!C2009 -> 14000 | E8: ='SALES Raw'!D2009 -> 105840 | F8: ='SALES Raw'!E2009*$H$4 -> 7578.9474 | G8: ='SALES Raw'!F2009*$H$4 -> 57296.842 | H8: ='SALES Raw'!A2009 -> 111 - Superpharm Life
A9: ='SALES Raw'!G2011 | B9: ='SALES Raw'!B2011 -> LU374 0 | C9: ='SALES Raw'!H2011 -> LU374 0 | D9: ='SALES Raw'!C2011 -> 9000 | E9: ='SALES Raw'!D2011 -> 88020 | F9: ='SALES Raw'!E2011*$H$4 -> 7578.9474 | G9: ='SALES Raw'!F2011*$H$4 -> 74122.105 | H9: ='SALES Raw'!A2011 -> 111 - Superpharm Life
A10: ='SALES Raw'!G2002 | B10: ='SALES Raw'!B2002 -> LU364-S-L | C10: ='SALES Raw'!H2002 -> LU364-S-L | D10: ='SALES Raw'!C2002 -> 8100 | E10: ='SALES Raw'!D2002 -> 81891 | F10: ='SALES Raw'!E2002*$H$4 -> 6821.0526 | G10: ='SALES Raw'!F2002*$H$4 -> 68960.842 | H10: ='SALES Raw'!A2002 -> 111 - Superpharm Life
A11: ='SALES Raw'!G2010 | B11: ='SALES Raw'!B2010 -> LU372 0 | C11: ='SALES Raw'!H2010 -> LU372 0 | D11: ='SALES Raw'!C2010 -> 9600 | E11: ='SALES Raw'!D2010 -> 93888 | F11: ='SALES Raw'!E2010*$H$4 -> 6063.1579 | G11: ='SALES Raw'!F2010*$H$4 -> 59297.684 | H11: ='SALES Raw'!A2010 -> 111 - Superpharm Life
A12: ='SALES Raw'!G2001 | B12: ='SALES Raw'!B2001 -> LU313 0 | C12: ='SALES Raw'!H2001 -> LU313 0 | D12: ='SALES Raw'!C2001 -> 4320 | E12: ='SALES Raw'!D2001 -> 67910.4 | F12: ='SALES Raw'!E2001*$H$4 -> 5456.8421 | G12: ='SALES Raw'!F2001*$H$4 -> 85781.558 | H12: ='SALES Raw'!A2001 -> 111 - Superpharm Life
A13: ='SALES Raw'!G2016 | B13: ='SALES Raw'!B2016 -> LUPD344 0 | C13: ='SALES Raw'!H2016 -> LUPD344 0 | D13: ='SALES Raw'!C2016 -> 7000 | E13: ='SALES Raw'!D2016 -> 39270 | F13: ='SALES Raw'!E2016*$H$4 -> 4136.8421 | G13: ='SALES Raw'!F2016*$H$4 -> 23207.684 | H13: ='SALES Raw'!A2016 -> 111 - Superpharm Life
A14: ='SALES Raw'!G2006 | B14: ='SALES Raw'!B2006 -> LU3655 0 | C14: ='SALES Raw'!H2006 -> LU3655 0 | D14: ='SALES Raw'!C2006 -> 17820 | E14: ='SALES Raw'!D2006 -> 219007.8 | F14: ='SALES Raw'!E2006*$H$4 -> 3789.4737 | G14: ='SALES Raw'!F2006*$H$4 -> 46572.632 | H14: ='SALES Raw'!A2006 -> 111 - Superpharm Life
A15: ='SALES Raw'!G2013 | B15: ='SALES Raw'!B2013 -> LULF373 0 | C15: ='SALES Raw'!H2013 -> LULF373 0 | D15: ='SALES Raw'!C2013 -> 4200 | E15: ='SALES Raw'!D2013 -> 61824 | F15: ='SALES Raw'!E2013*$H$4 -> 3536.8421 | G15: ='SALES Raw'!F2013*$H$4 -> 52062.316 | H15: ='SALES Raw'!A2013 -> 111 - Superpharm Life
A16: ='SALES Raw'!G2007 | B16: ='SALES Raw'!B2007 -> LU366S 0 | C16: ='SALES Raw'!H2007 -> LU366S 0 | D16: ='SALES Raw'!C2007 -> 4860 | E16: ='SALES Raw'!D2007 -> 47239.2 | F16: ='SALES Raw'!E2007*$H$4 -> 3069.4737 | G16: ='SALES Raw'!F2007*$H$4 -> 29835.284 | H16: ='SALES Raw'!A2007 -> 111 - Superpharm Life
A17: ='SALES Raw'!G1998 | B17: ='SALES Raw'!B1998 -> LU302W 0 | C17: ='SALES Raw'!H1998 -> LU302W 0 | D17: ='SALES Raw'!C1998 -> 2400 | E17: ='SALES Raw'!D1998 -> 113328 | F17: ='SALES Raw'!E1998*$H$4 -> 3031.5789 | G17: ='SALES Raw'!F1998*$H$4 -> 143151.16 | H17: ='SALES Raw'!A1998 -> 111 - Superpharm Life
A18: ='SALES Raw'!G2000 | B18: ='SALES Raw'!B2000 -> LU308 M | C18: ='SALES Raw'!H2000 -> LU308 M | D18: ='SALES Raw'!C2000 -> 2400 | E18: ='SALES Raw'!D2000 -> 94656 | F18: ='SALES Raw'!E2000*$H$4 -> 3031.5789 | G18: ='SALES Raw'!F2000*$H$4 -> 119565.47 | H18: ='SALES Raw'!A2000 -> 111 - Superpharm Life
A19: ='SALES Raw'!G2015 | B19: ='SALES Raw'!B2015 -> LUPD342 0 | C19: ='SALES Raw'!H2015 -> LUPD342 0 | D19: ='SALES Raw'!C2015 -> 4152 | E19: ='SALES Raw'!D2015 -> 73822.56 | F19: ='SALES Raw'!E2015*$H$4 -> 3031.5789 | G19: ='SALES Raw'!F2015*$H$4 -> 53901.474 | H19: ='SALES Raw'!A2015 -> 111 - Superpharm Life
A20: ='SALES Raw'!G2005 | B20: ='SALES Raw'!B2005 -> LU365-S-L | C20: ='SALES Raw'!H2005 -> LU365-S-L | D20: ='SALES Raw'!C2005 -> 4860 | E20: ='SALES Raw'!D2005 -> 47239.2 | F20: ='SALES Raw'!E2005*$H$4 -> 2728.4211 | G20: ='SALES Raw'!F2005*$H$4 -> 26520.253 | H20: ='SALES Raw'!A2005 -> 111 - Superpharm Life
A21: ='SALES Raw'!G2014 | B21: ='SALES Raw'!B2014 -> LUPD340 0 | C21: ='SALES Raw'!H2014 -> LUPD340 0 | D21: ='SALES Raw'!C2014 -> 5400 | E21: ='SALES Raw'!D2014 -> 47844 | F21: ='SALES Raw'!E2014*$H$4 -> 2273.6842 | G21: ='SALES Raw'!F2014*$H$4 -> 20144.842 | H21: ='SALES Raw'!A2014 -> 111 - Superpharm Life
A22: ='SALES Raw'!G1999 | B22: ='SALES Raw'!B1999 -> LU308 L | C22: ='SALES Raw'!H1999 -> LU308 L | D22: ='SALES Raw'!C1999 -> 1600 | E22: ='SALES Raw'!D1999 -> 63104 | F22: ='SALES Raw'!E1999*$H$4 -> 2021.0526 | G22: ='SALES Raw'!F1999*$H$4 -> 79710.316 | H22: ='SALES Raw'!A1999 -> 111 - Superpharm Life
A23: ='SALES Raw'!G2012 | B23: ='SALES Raw'!B2012 -> LULF370 0 | C23: ='SALES Raw'!H2012 -> LULF370 0 | D23: ='SALES Raw'!C2012 -> 3200 | E23: ='SALES Raw'!D2012 -> 45856 | F23: ='SALES Raw'!E2012*$H$4 -> 2021.0526 | G23: ='SALES Raw'!F2012*$H$4 -> 28961.684 | H23: ='SALES Raw'!A2012 -> 111 - Superpharm Life
A24: ='SALES Raw'!G2003 | B24: ='SALES Raw'!B2003 -> LU364 XL | C24: ='SALES Raw'!H2003 -> LU364 XL | D24: ='SALES Raw'!C2003 -> 4050 | E24: ='SALES Raw'!D2003 -> 40945.5 | F24: ='SALES Raw'!E2003*$H$4 -> 1705.2632 | G24: ='SALES Raw'!F2003*$H$4 -> 17240.211 | H24: ='SALES Raw'!A2003 -> 111 - Superpharm Life
A25: ='SALES Raw'!G2008 | B25: ='SALES Raw'!B2008 -> LU3677S 0 | C25: ='SALES Raw'!H2008 -> LU3677S 0 | D25: ='SALES Raw'!C2008 -> 1350 | E25: ='SALES Raw'!D2008 -> 18306 | F25: ='SALES Raw'!E2008*$H$4 -> 1705.2632 | G25: ='SALES Raw'!F2008*$H$4 -> 23123.368 | H25: ='SALES Raw'!A2008 -> 111 - Superpharm Life
