Workbook

Sheet Index
A1: Sales Comparison 2025 vs 2026 - by Sale Type (NetSuite "1-Sales: Customer by Item")
A2: Calculation date: | B2: 46284
A3: Same 18-column format as Index in 2026-09-19-grouped-2025-vs-2026.xlsx / 2026-09-19-top-customers-2025-vs-2026.xlsx (no annualized columns here - annualization lives inside each Sale Type sheet only). "# Raw categories" is not meaningful for a single Sale Type - shown as N/A. 31 categories = the full canonical "Sale Type" list from the source file’s "list" sheet (includes Chemipal this time, per the user’s explicit instruction - different from the Customer-based exclusion used in top-customers).
A5: Group | B5: Sheet | C5: # Raw categories | D5: # Product Codes | E5: # Product Codes 2025 | F5: # Product Codes 2026 | G5: # DROP (sold 2025, 0 in 2026) | H5: # NEW (sold 2026, 0 in 2025) | I5: DROP — Quantity 2025 | J5: DROP — Amount 2025 (₪) | K5: NEW — Quantity 2026 | L5: NEW — Amount 2026 (₪) | M5: Quantity 2025 | N5: Quantity 2026 | O5: Qty Change % | P5: Amount 2025 (₪) | Q5: Amount 2026 (₪) | R5: Amount Change %
A6: 110 - Chemipal | B6: 110 - Chemipal | C6: N/A | D6: =COUNTA('110 - Chemipal'!$A$9:$A$569) -> 561 | E6: =SUMPRODUCT(--(('110 - Chemipal'!$C$9:$C$569<>0)+('110 - Chemipal'!$H$9:$H$569<>0)>0)) -> 559 | F6: =SUMPRODUCT(--(('110 - Chemipal'!$D$9:$D$569<>0)+('110 - Chemipal'!$I$9:$I$569<>0)>0)) -> 3 | G6: ='110 - Chemipal'!B5 -> 558 | H6: ='110 - Chemipal'!D5 -> 2 | I6: ='110 - Chemipal'!B6 -> 156696 | J6: ='110 - Chemipal'!D6 -> 5726866.7 | K6: ='110 - Chemipal'!F6 -> 3 | L6: ='110 - Chemipal'!H6 -> 0 | M6: ='110 - Chemipal'!C571 -> 156690 | N6: ='110 - Chemipal'!D571 -> 11 | O6: =IF('110 - Chemipal'!C571=0,"N/A",('110 - Chemipal'!D571-'110 - Chemipal'!C571)/'110 - Chemipal'!C571) -> -0.9999298 | P6: ='110 - Chemipal'!H571 -> 8447136.6 | Q6: ='110 - Chemipal'!I571 -> 5794673.6 | R6: =IF('110 - Chemipal'!H571=0,"N/A",('110 - Chemipal'!I571-'110 - Chemipal'!H571)/'110 - Chemipal'!H571) -> -0.31400735
A7: 102 - Orthopedic institutes | B7: 102 - Orthopedic institutes | C7: N/A | D7: =COUNTA('102 - Orthopedic institutes'!$A$9:$A$668) -> 660 | E7: =SUMPRODUCT(--(('102 - Orthopedic institutes'!$C$9:$C$668<>0)+('102 - Orthopedic institutes'!$H$9:$H$668<>0)>0)) -> 595 | F7: =SUMPRODUCT(--(('102 - Orthopedic institutes'!$D$9:$D$668<>0)+('102 - Orthopedic institutes'!$I$9:$I$668<>0)>0)) -> 475 | G7: ='102 - Orthopedic institutes'!B5 -> 185 | H7: ='102 - Orthopedic institutes'!D5 -> 65 | I7: ='102 - Orthopedic institutes'!B6 -> 826 | J7: ='102 - Orthopedic institutes'!D6 -> 59526.19 | K7: ='102 - Orthopedic institutes'!F6 -> 728 | L7: ='102 - Orthopedic institutes'!H6 -> 56220.09 | M7: ='102 - Orthopedic institutes'!C670 -> 11637 | N7: ='102 - Orthopedic institutes'!D670 -> 7815 | O7: =IF('102 - Orthopedic institutes'!C670=0,"N/A",('102 - Orthopedic institutes'!D670-'102 - Orthopedic institutes'!C670)/'102 - Orthopedic institutes'!C670) -> -0.32843516 | P7: ='102 - Orthopedic institutes'!H670 -> 850045.24 | Q7: ='102 - Orthopedic institutes'!I670 -> 647626.01 | R7: =IF('102 - Orthopedic institutes'!H670=0,"N/A",('102 - Orthopedic institutes'!I670-'102 - Orthopedic institutes'!H670)/'102 - Orthopedic institutes'!H670) -> -0.2381276
A8: 101 - Factory customers | B8: 101 - Factory customers | C8: N/A | D8: =COUNTA('101 - Factory customers'!$A$9:$A$528) -> 520 | E8: =SUMPRODUCT(--(('101 - Factory customers'!$C$9:$C$528<>0)+('101 - Factory customers'!$H$9:$H$528<>0)>0)) -> 424 | F8: =SUMPRODUCT(--(('101 - Factory customers'!$D$9:$D$528<>0)+('101 - Factory customers'!$I$9:$I$528<>0)>0)) -> 302 | G8: ='101 - Factory customers'!B5 -> 218 | H8: ='101 - Factory customers'!D5 -> 96 | I8: ='101 - Factory customers'!B6 -> 1086 | J8: ='101 - Factory customers'!D6 -> 55244.81 | K8: ='101 - Factory customers'!F6 -> 253 | L8: ='101 - Factory customers'!H6 -> 13716.33 | M8: ='101 - Factory customers'!C530 -> 3679 | N8: ='101 - Factory customers'!D530 -> 1378 | O8: =IF('101 - Factory customers'!C530=0,"N/A",('101 - Factory customers'!D530-'101 - Factory customers'!C530)/'101 - Factory customers'!C530) -> -0.6254417 | P8: ='101 - Factory customers'!H530 -> 185250.51 | Q8: ='101 - Factory customers'!I530 -> 78194.51 | R8: =IF('101 - Factory customers'!H530=0,"N/A",('101 - Factory customers'!I530-'101 - Factory customers'!H530)/'101 - Factory customers'!H530) -> -0.57789854
A9: 104 - Sports Shop | B9: 104 - Sports Shop | C9: N/A | D9: =COUNTA('104 - Sports Shop'!$A$9:$A$36) -> 28 | E9: =SUMPRODUCT(--(('104 - Sports Shop'!$C$9:$C$36<>0)+('104 - Sports Shop'!$H$9:$H$36<>0)>0)) -> 3 | F9: =SUMPRODUCT(--(('104 - Sports Shop'!$D$9:$D$36<>0)+('104 - Sports Shop'!$I$9:$I$36<>0)>0)) -> 25 | G9: ='104 - Sports Shop'!B5 -> 3 | H9: ='104 - Sports Shop'!D5 -> 25 | I9: ='104 - Sports Shop'!B6 -> 16 | J9: ='104 - Sports Shop'!D6 -> 514.2 | K9: ='104 - Sports Shop'!F6 -> 59 | L9: ='104 - Sports Shop'!H6 -> 1896.82 | M9: ='104 - Sports Shop'!C38 -> 16 | N9: ='104 - Sports Shop'!D38 -> 59 | O9: =IF('104 - Sports Shop'!C38=0,"N/A",('104 - Sports Shop'!D38-'104 - Sports Shop'!C38)/'104 - Sports Shop'!C38) -> 2.6875 | P9: ='104 - Sports Shop'!H38 -> 514.2 | Q9: ='104 - Sports Shop'!I38 -> 1896.82 | R9: =IF('104 - Sports Shop'!H38=0,"N/A",('104 - Sports Shop'!I38-'104 - Sports Shop'!H38)/'104 - Sports Shop'!H38) -> 2.6888759
A10: 103 - Physiotherapy institutes | B10: 103 - Physiotherapy institutes | C10: N/A | D10: =COUNTA('103 - Physiotherapy institutes'!$A$9:$A$437) -> 429 | E10: =SUMPRODUCT(--(('103 - Physiotherapy institutes'!$C$9:$C$437<>0)+('103 - Physiotherapy institutes'!$H$9:$H$437<>0)>0)) -> 301 | F10: =SUMPRODUCT(--(('103 - Physiotherapy institutes'!$D$9:$D$437<>0)+('103 - Physiotherapy institutes'!$I$9:$I$437<>0)>0)) -> 282 | G10: ='103 - Physiotherapy institutes'!B5 -> 147 | H10: ='103 - Physiotherapy institutes'!D5 -> 128 | I10: ='103 - Physiotherapy institutes'!B6 -> 550 | J10: ='103 - Physiotherapy institutes'!D6 -> 25758.28 | K10: ='103 - Physiotherapy institutes'!F6 -> 322 | L10: ='103 - Physiotherapy institutes'!H6 -> 27429.03 | M10: ='103 - Physiotherapy institutes'!C439 -> 1673 | N10: ='103 - Physiotherapy institutes'!D439 -> 1518 | O10: =IF('103 - Physiotherapy institutes'!C439=0,"N/A",('103 - Physiotherapy institutes'!D439-'103 - Physiotherapy institutes'!C439)/'103 - Physiotherapy institutes'!C439) -> -0.092647938 | P10: ='103 - Physiotherapy institutes'!H439 -> 98528.23 | Q10: ='103 - Physiotherapy institutes'!I439 -> 113347.12 | R10: =IF('103 - Physiotherapy institutes'!H439=0,"N/A",('103 - Physiotherapy institutes'!I439-'103 - Physiotherapy institutes'!H439)/'103 - Physiotherapy institutes'!H439) -> 0.15040248
A11: 109 - Private Shops | B11: 109 - Private Shops | C11: N/A | D11: =COUNTA('109 - Private Shops'!$A$9:$A$223) -> 215 | E11: =SUMPRODUCT(--(('109 - Private Shops'!$C$9:$C$223<>0)+('109 - Private Shops'!$H$9:$H$223<>0)>0)) -> 150 | F11: =SUMPRODUCT(--(('109 - Private Shops'!$D$9:$D$223<>0)+('109 - Private Shops'!$I$9:$I$223<>0)>0)) -> 133 | G11: ='109 - Private Shops'!B5 -> 82 | H11: ='109 - Private Shops'!D5 -> 65 | I11: ='109 - Private Shops'!B6 -> 290 | J11: ='109 - Private Shops'!D6 -> 14416.63 | K11: ='109 - Private Shops'!F6 -> 244 | L11: ='109 - Private Shops'!H6 -> 18033.75 | M11: ='109 - Private Shops'!C225 -> 1208 | N11: ='109 - Private Shops'!D225 -> 660 | O11: =IF('109 - Private Shops'!C225=0,"N/A",('109 - Private Shops'!D225-'109 - Private Shops'!C225)/'109 - Private Shops'!C225) -> -0.45364238 | P11: ='109 - Private Shops'!H225 -> 58306.79 | Q11: ='109 - Private Shops'!I225 -> 46507.15 | R11: =IF('109 - Private Shops'!H225=0,"N/A",('109 - Private Shops'!I225-'109 - Private Shops'!H225)/'109 - Private Shops'!H225) -> -0.20237163
A12: 105 - Pedicure Salons | B12: 105 - Pedicure Salons | C12: N/A | D12: =COUNTA('105 - Pedicure Salons'!$A$9:$A$30) -> 22 | E12: =SUMPRODUCT(--(('105 - Pedicure Salons'!$C$9:$C$30<>0)+('105 - Pedicure Salons'!$H$9:$H$30<>0)>0)) -> 17 | F12: =SUMPRODUCT(--(('105 - Pedicure Salons'!$D$9:$D$30<>0)+('105 - Pedicure Salons'!$I$9:$I$30<>0)>0)) -> 18 | G12: ='105 - Pedicure Salons'!B5 -> 4 | H12: ='105 - Pedicure Salons'!D5 -> 5 | I12: ='105 - Pedicure Salons'!B6 -> 5 | J12: ='105 - Pedicure Salons'!D6 -> 229.17 | K12: ='105 - Pedicure Salons'!F6 -> 18 | L12: ='105 - Pedicure Salons'!H6 -> 1012.72 | M12: ='105 - Pedicure Salons'!C32 -> 114 | N12: ='105 - Pedicure Salons'!D32 -> 97 | O12: =IF('105 - Pedicure Salons'!C32=0,"N/A",('105 - Pedicure Salons'!D32-'105 - Pedicure Salons'!C32)/'105 - Pedicure Salons'!C32) -> -0.14912281 | P12: ='105 - Pedicure Salons'!H32 -> 4145.68 | Q12: ='105 - Pedicure Salons'!I32 -> 4305.02 | R12: =IF('105 - Pedicure Salons'!H32=0,"N/A",('105 - Pedicure Salons'!I32-'105 - Pedicure Salons'!H32)/'105 - Pedicure Salons'!H32) -> 0.03843519
A13: 111 - Superpharm Life | B13: 111 - Superpharm Life | C13: N/A | D13: =COUNTA('111 - Superpharm Life'!$A$9:$A$29) -> 21 | E13: =SUMPRODUCT(--(('111 - Superpharm Life'!$C$9:$C$29<>0)+('111 - Superpharm Life'!$H$9:$H$29<>0)>0)) -> 21 | F13: =SUMPRODUCT(--(('111 - Superpharm Life'!$D$9:$D$29<>0)+('111 - Superpharm Life'!$I$9:$I$29<>0)>0)) -> 20 | G13: ='111 - Superpharm Life'!B5 -> 1 | H13: ='111 - Superpharm Life'!D5 -> 0 | I13: ='111 - Superpharm Life'!B6 -> 0 | J13: ='111 - Superpharm Life'!D6 -> 7427.59 | K13: ='111 - Superpharm Life'!F6 -> 0 | L13: ='111 - Superpharm Life'!H6 -> 0 | M13: ='111 - Superpharm Life'!C31 -> 118392 | N13: ='111 - Superpharm Life'!D31 -> 62455 | O13: =IF('111 - Superpharm Life'!C31=0,"N/A",('111 - Superpharm Life'!D31-'111 - Superpharm Life'!C31)/'111 - Superpharm Life'!C31) -> -0.4724728 | P13: ='111 - Superpharm Life'!H31 -> 1708656.9 | Q13: ='111 - Superpharm Life'!I31 -> 1113833.9 | R13: =IF('111 - Superpharm Life'!H31=0,"N/A",('111 - Superpharm Life'!I31-'111 - Superpharm Life'!H31)/'111 - Superpharm Life'!H31) -> -0.34812315
A14: 106 - Hospitals | B14: 106 - Hospitals | C14: N/A | D14: =COUNTA('106 - Hospitals'!$A$9:$A$93) -> 85 | E14: =SUMPRODUCT(--(('106 - Hospitals'!$C$9:$C$93<>0)+('106 - Hospitals'!$H$9:$H$93<>0)>0)) -> 74 | F14: =SUMPRODUCT(--(('106 - Hospitals'!$D$9:$D$93<>0)+('106 - Hospitals'!$I$9:$I$93<>0)>0)) -> 45 | G14: ='106 - Hospitals'!B5 -> 40 | H14: ='106 - Hospitals'!D5 -> 11 | I14: ='106 - Hospitals'!B6 -> 94 | J14: ='106 - Hospitals'!D6 -> 5729.29 | K14: ='106 - Hospitals'!F6 -> 41 | L14: ='106 - Hospitals'!H6 -> 4381.47 | M14: ='106 - Hospitals'!C95 -> 286 | N14: ='106 - Hospitals'!D95 -> 207 | O14: =IF('106 - Hospitals'!C95=0,"N/A",('106 - Hospitals'!D95-'106 - Hospitals'!C95)/'106 - Hospitals'!C95) -> -0.27622378 | P14: ='106 - Hospitals'!H95 -> 13532.23 | Q14: ='106 - Hospitals'!I95 -> 11739.83 | R14: =IF('106 - Hospitals'!H95=0,"N/A",('106 - Hospitals'!I95-'106 - Hospitals'!H95)/'106 - Hospitals'!H95) -> -0.13245415
A15: 107 - Pharmacies | B15: 107 - Pharmacies | C15: N/A | D15: =COUNTA('107 - Pharmacies'!$A$9:$A$397) -> 389 | E15: =SUMPRODUCT(--(('107 - Pharmacies'!$C$9:$C$397<>0)+('107 - Pharmacies'!$H$9:$H$397<>0)>0)) -> 325 | F15: =SUMPRODUCT(--(('107 - Pharmacies'!$D$9:$D$397<>0)+('107 - Pharmacies'!$I$9:$I$397<>0)>0)) -> 273 | G15: ='107 - Pharmacies'!B5 -> 116 | H15: ='107 - Pharmacies'!D5 -> 64 | I15: ='107 - Pharmacies'!B6 -> 471 | J15: ='107 - Pharmacies'!D6 -> 33959.3 | K15: ='107 - Pharmacies'!F6 -> 362 | L15: ='107 - Pharmacies'!H6 -> 27791.49 | M15: ='107 - Pharmacies'!C399 -> 2498 | N15: ='107 - Pharmacies'!D399 -> 1623 | O15: =IF('107 - Pharmacies'!C399=0,"N/A",('107 - Pharmacies'!D399-'107 - Pharmacies'!C399)/'107 - Pharmacies'!C399) -> -0.35028022 | P15: ='107 - Pharmacies'!H399 -> 152425.36 | Q15: ='107 - Pharmacies'!I399 -> 110887.07 | R15: =IF('107 - Pharmacies'!H399=0,"N/A",('107 - Pharmacies'!I399-'107 - Pharmacies'!H399)/'107 - Pharmacies'!H399) -> -0.27251561
A16: 112 - Kupat Holim Clalit | B16: 112 - Kupat Holim Clalit | C16: N/A | D16: =COUNTA('112 - Kupat Holim Clalit'!$A$9:$A$41) -> 33 | E16: =SUMPRODUCT(--(('112 - Kupat Holim Clalit'!$C$9:$C$41<>0)+('112 - Kupat Holim Clalit'!$H$9:$H$41<>0)>0)) -> 32 | F16: =SUMPRODUCT(--(('112 - Kupat Holim Clalit'!$D$9:$D$41<>0)+('112 - Kupat Holim Clalit'!$I$9:$I$41<>0)>0)) -> 32 | G16: ='112 - Kupat Holim Clalit'!B5 -> 1 | H16: ='112 - Kupat Holim Clalit'!D5 -> 1 | I16: ='112 - Kupat Holim Clalit'!B6 -> -1 | J16: ='112 - Kupat Holim Clalit'!D6 -> -62.43 | K16: ='112 - Kupat Holim Clalit'!F6 -> -2 | L16: ='112 - Kupat Holim Clalit'!H6 -> -1176 | M16: ='112 - Kupat Holim Clalit'!C43 -> 152395 | N16: ='112 - Kupat Holim Clalit'!D43 -> 110137 | O16: =IF('112 - Kupat Holim Clalit'!C43=0,"N/A",('112 - Kupat Holim Clalit'!D43-'112 - Kupat Holim Clalit'!C43)/'112 - Kupat Holim Clalit'!C43) -> -0.27729256 | P16: ='112 - Kupat Holim Clalit'!H43 -> 3809616.4 | Q16: ='112 - Kupat Holim Clalit'!I43 -> 2569653 | R16: =IF('112 - Kupat Holim Clalit'!H43=0,"N/A",('112 - Kupat Holim Clalit'!I43-'112 - Kupat Holim Clalit'!H43)/'112 - Kupat Holim Clalit'!H43) -> -0.32548247
A17: 113 - Kupat Holim Meuhedet | B17: 113 - Kupat Holim Meuhedet | C17: N/A | D17: =COUNTA('113 - Kupat Holim Meuhedet'!$A$9:$A$240) -> 232 | E17: =SUMPRODUCT(--(('113 - Kupat Holim Meuhedet'!$C$9:$C$240<>0)+('113 - Kupat Holim Meuhedet'!$H$9:$H$240<>0)>0)) -> 223 | F17: =SUMPRODUCT(--(('113 - Kupat Holim Meuhedet'!$D$9:$D$240<>0)+('113 - Kupat Holim Meuhedet'!$I$9:$I$240<>0)>0)) -> 206 | G17: ='113 - Kupat Holim Meuhedet'!B5 -> 26 | H17: ='113 - Kupat Holim Meuhedet'!D5 -> 9 | I17: ='113 - Kupat Holim Meuhedet'!B6 -> 301 | J17: ='113 - Kupat Holim Meuhedet'!D6 -> 12248.01 | K17: ='113 - Kupat Holim Meuhedet'!F6 -> 23 | L17: ='113 - Kupat Holim Meuhedet'!H6 -> 1236.65 | M17: ='113 - Kupat Holim Meuhedet'!C242 -> 29601 | N17: ='113 - Kupat Holim Meuhedet'!D242 -> 7385 | O17: =IF('113 - Kupat Holim Meuhedet'!C242=0,"N/A",('113 - Kupat Holim Meuhedet'!D242-'113 - Kupat Holim Meuhedet'!C242)/'113 - Kupat Holim Meuhedet'!C242) -> -0.75051519 | P17: ='113 - Kupat Holim Meuhedet'!H242 -> 860680.72 | Q17: ='113 - Kupat Holim Meuhedet'!I242 -> 186688.02 | R17: =IF('113 - Kupat Holim Meuhedet'!H242=0,"N/A",('113 - Kupat Holim Meuhedet'!I242-'113 - Kupat Holim Meuhedet'!H242)/'113 - Kupat Holim Meuhedet'!H242) -> -0.7830926
A18: 114 - IL online | B18: 114 - IL online | C18: N/A | D18: =COUNTA('114 - IL online'!$A$9:$A$728) -> 720 | E18: =SUMPRODUCT(--(('114 - IL online'!$C$9:$C$728<>0)+('114 - IL online'!$H$9:$H$728<>0)>0)) -> 618 | F18: =SUMPRODUCT(--(('114 - IL online'!$D$9:$D$728<>0)+('114 - IL online'!$I$9:$I$728<>0)>0)) -> 632 | G18: ='114 - IL online'!B5 -> 88 | H18: ='114 - IL online'!D5 -> 102 | I18: ='114 - IL online'!B6 -> 581 | J18: ='114 - IL online'!D6 -> 69907.37 | K18: ='114 - IL online'!F6 -> 2375 | L18: ='114 - IL online'!H6 -> 147591.2 | M18: ='114 - IL online'!C730 -> 20470 | N18: ='114 - IL online'!D730 -> 28582 | O18: =IF('114 - IL online'!C730=0,"N/A",('114 - IL online'!D730-'114 - IL online'!C730)/'114 - IL online'!C730) -> 0.39628725 | P18: ='114 - IL online'!H730 -> 1657320.8 | Q18: ='114 - IL online'!I730 -> 3196470.1 | R18: =IF('114 - IL online'!H730=0,"N/A",('114 - IL online'!I730-'114 - IL online'!H730)/'114 - IL online'!H730) -> 0.92869733
A19: 115-SuperPharm Online | B19: 115-SuperPharm Online | C19: N/A | D19: =COUNTA('115-SuperPharm Online'!$A$9:$A$77) -> 69 | E19: =SUMPRODUCT(--(('115-SuperPharm Online'!$C$9:$C$77<>0)+('115-SuperPharm Online'!$H$9:$H$77<>0)>0)) -> 59 | F19: =SUMPRODUCT(--(('115-SuperPharm Online'!$D$9:$D$77<>0)+('115-SuperPharm Online'!$I$9:$I$77<>0)>0)) -> 38 | G19: ='115-SuperPharm Online'!B5 -> 31 | H19: ='115-SuperPharm Online'!D5 -> 10 | I19: ='115-SuperPharm Online'!B6 -> 58 | J19: ='115-SuperPharm Online'!D6 -> 8738.33 | K19: ='115-SuperPharm Online'!F6 -> 12 | L19: ='115-SuperPharm Online'!H6 -> 1716.98 | M19: ='115-SuperPharm Online'!C79 -> 415 | N19: ='115-SuperPharm Online'!D79 -> 200 | O19: =IF('115-SuperPharm Online'!C79=0,"N/A",('115-SuperPharm Online'!D79-'115-SuperPharm Online'!C79)/'115-SuperPharm Online'!C79) -> -0.51807229 | P19: ='115-SuperPharm Online'!H79 -> 27325.74 | Q19: ='115-SuperPharm Online'!I79 -> 13033.46 | R19: =IF('115-SuperPharm Online'!H79=0,"N/A",('115-SuperPharm Online'!I79-'115-SuperPharm Online'!H79)/'115-SuperPharm Online'!H79) -> -0.52303359
A20: 202 - Super-Pharm POLAND | B20: 202 - Super-Pharm POLAND | C20: N/A | D20: =COUNTA('202 - Super-Pharm POLAND'!$A$9:$A$143) -> 135 | E20: =SUMPRODUCT(--(('202 - Super-Pharm POLAND'!$C$9:$C$143<>0)+('202 - Super-Pharm POLAND'!$H$9:$H$143<>0)>0)) -> 130 | F20: =SUMPRODUCT(--(('202 - Super-Pharm POLAND'!$D$9:$D$143<>0)+('202 - Super-Pharm POLAND'!$I$9:$I$143<>0)>0)) -> 123 | G20: ='202 - Super-Pharm POLAND'!B5 -> 12 | H20: ='202 - Super-Pharm POLAND'!D5 -> 5 | I20: ='202 - Super-Pharm POLAND'!B6 -> 3550 | J20: ='202 - Super-Pharm POLAND'!D6 -> 92320.46 | K20: ='202 - Super-Pharm POLAND'!F6 -> 250 | L20: ='202 - Super-Pharm POLAND'!H6 -> 11540.57 | M20: ='202 - Super-Pharm POLAND'!C145 -> 48363 | N20: ='202 - Super-Pharm POLAND'!D145 -> 28188 | O20: =IF('202 - Super-Pharm POLAND'!C145=0,"N/A",('202 - Super-Pharm POLAND'!D145-'202 - Super-Pharm POLAND'!C145)/'202 - Super-Pharm POLAND'!C145) -> -0.41715774 | P20: ='202 - Super-Pharm POLAND'!H145 -> 902537.64 | Q20: ='202 - Super-Pharm POLAND'!I145 -> 474182.59 | R20: =IF('202 - Super-Pharm POLAND'!H145=0,"N/A",('202 - Super-Pharm POLAND'!I145-'202 - Super-Pharm POLAND'!H145)/'202 - Super-Pharm POLAND'!H145) -> -0.47461184
A21: 201- Seven Gear FINLAND oy | B21: 201- Seven Gear FINLAND oy | C21: N/A | D21: =COUNTA('201- Seven Gear FINLAND oy'!$A$9:$A$56) -> 48 | E21: =SUMPRODUCT(--(('201- Seven Gear FINLAND oy'!$C$9:$C$56<>0)+('201- Seven Gear FINLAND oy'!$H$9:$H$56<>0)>0)) -> 44 | F21: =SUMPRODUCT(--(('201- Seven Gear FINLAND oy'!$D$9:$D$56<>0)+('201- Seven Gear FINLAND oy'!$I$9:$I$56<>0)>0)) -> 21 | G21: ='201- Seven Gear FINLAND oy'!B5 -> 27 | H21: ='201- Seven Gear FINLAND oy'!D5 -> 4 | I21: ='201- Seven Gear FINLAND oy'!B6 -> 1219 | J21: ='201- Seven Gear FINLAND oy'!D6 -> 27555.1 | K21: ='201- Seven Gear FINLAND oy'!F6 -> 260 | L21: ='201- Seven Gear FINLAND oy'!H6 -> 5860.29 | M21: ='201- Seven Gear FINLAND oy'!C58 -> 2980 | N21: ='201- Seven Gear FINLAND oy'!D58 -> 1630 | O21: =IF('201- Seven Gear FINLAND oy'!C58=0,"N/A",('201- Seven Gear FINLAND oy'!D58-'201- Seven Gear FINLAND oy'!C58)/'201- Seven Gear FINLAND oy'!C58) -> -0.45302013 | P21: ='201- Seven Gear FINLAND oy'!H58 -> 60908.2 | Q21: ='201- Seven Gear FINLAND oy'!I58 -> 32804.59 | R21: =IF('201- Seven Gear FINLAND oy'!H58=0,"N/A",('201- Seven Gear FINLAND oy'!I58-'201- Seven Gear FINLAND oy'!H58)/'201- Seven Gear FINLAND oy'!H58) -> -0.4614093
A22: 216 - Max Konnaris CYPRUS | B22: 216 - Max Konnaris CYPRUS | C22: N/A | D22: =COUNTA('216 - Max Konnaris CYPRUS'!$A$9:$A$253) -> 245 | E22: =SUMPRODUCT(--(('216 - Max Konnaris CYPRUS'!$C$9:$C$253<>0)+('216 - Max Konnaris CYPRUS'!$H$9:$H$253<>0)>0)) -> 177 | F22: =SUMPRODUCT(--(('216 - Max Konnaris CYPRUS'!$D$9:$D$253<>0)+('216 - Max Konnaris CYPRUS'!$I$9:$I$253<>0)>0)) -> 154 | G22: ='216 - Max Konnaris CYPRUS'!B5 -> 91 | H22: ='216 - Max Konnaris CYPRUS'!D5 -> 68 | I22: ='216 - Max Konnaris CYPRUS'!B6 -> 1696 | J22: ='216 - Max Konnaris CYPRUS'!D6 -> 47367.29 | K22: ='216 - Max Konnaris CYPRUS'!F6 -> 754 | L22: ='216 - Max Konnaris CYPRUS'!H6 -> 27727.77 | M22: ='216 - Max Konnaris CYPRUS'!C255 -> 3507 | N22: ='216 - Max Konnaris CYPRUS'!D255 -> 2337 | O22: =IF('216 - Max Konnaris CYPRUS'!C255=0,"N/A",('216 - Max Konnaris CYPRUS'!D255-'216 - Max Konnaris CYPRUS'!C255)/'216 - Max Konnaris CYPRUS'!C255) -> -0.33361848 | P22: ='216 - Max Konnaris CYPRUS'!H255 -> 86855.65 | Q22: ='216 - Max Konnaris CYPRUS'!I255 -> 60462.39 | R22: =IF('216 - Max Konnaris CYPRUS'!H255=0,"N/A",('216 - Max Konnaris CYPRUS'!I255-'216 - Max Konnaris CYPRUS'!H255)/'216 - Max Konnaris CYPRUS'!H255) -> -0.30387499
A23: 200 - ROW : 217 - N3W FOODS USA | B23: 200 - ROW - 217 - N3W FOODS USA | C23: N/A | D23: =COUNTA('200 - ROW - 217 - N3W FOODS USA'!$A$9:$A$13) -> 5 | E23: =SUMPRODUCT(--(('200 - ROW - 217 - N3W FOODS USA'!$C$9:$C$13<>0)+('200 - ROW - 217 - N3W FOODS USA'!$H$9:$H$13<>0)>0)) -> 5 | F23: =SUMPRODUCT(--(('200 - ROW - 217 - N3W FOODS USA'!$D$9:$D$13<>0)+('200 - ROW - 217 - N3W FOODS USA'!$I$9:$I$13<>0)>0)) -> 0 | G23: ='200 - ROW - 217 - N3W FOODS USA'!B5 -> 5 | H23: ='200 - ROW - 217 - N3W FOODS USA'!D5 -> 0 | I23: ='200 - ROW - 217 - N3W FOODS USA'!B6 -> 24 | J23: ='200 - ROW - 217 - N3W FOODS USA'!D6 -> 248.59 | K23: ='200 - ROW - 217 - N3W FOODS USA'!F6 -> 0 | L23: ='200 - ROW - 217 - N3W FOODS USA'!H6 -> 0 | M23: ='200 - ROW - 217 - N3W FOODS USA'!C15 -> 24 | N23: ='200 - ROW - 217 - N3W FOODS USA'!D15 -> 0 | O23: =IF('200 - ROW - 217 - N3W FOODS USA'!C15=0,"N/A",('200 - ROW - 217 - N3W FOODS USA'!D15-'200 - ROW - 217 - N3W FOODS USA'!C15)/'200 - ROW - 217 - N3W FOODS USA'!C15) -> -1 | P23: ='200 - ROW - 217 - N3W FOODS USA'!H15 -> 248.59 | Q23: ='200 - ROW - 217 - N3W FOODS USA'!I15 -> 0 | R23: =IF('200 - ROW - 217 - N3W FOODS USA'!H15=0,"N/A",('200 - ROW - 217 - N3W FOODS USA'!I15-'200 - ROW - 217 - N3W FOODS USA'!H15)/'200 - ROW - 217 - N3W FOODS USA'!H15) -> -1
A24: 205 - Health Care Prod. Gmbh GERMANY | B24: 205 - Health Care Prod. GERMANY | C24: N/A | D24: =COUNTA('205 - Health Care Prod. GERMANY'!$A$9:$A$45) -> 37 | E24: =SUMPRODUCT(--(('205 - Health Care Prod. GERMANY'!$C$9:$C$45<>0)+('205 - Health Care Prod. GERMANY'!$H$9:$H$45<>0)>0)) -> 37 | F24: =SUMPRODUCT(--(('205 - Health Care Prod. GERMANY'!$D$9:$D$45<>0)+('205 - Health Care Prod. GERMANY'!$I$9:$I$45<>0)>0)) -> 23 | G24: ='205 - Health Care Prod. GERMANY'!B5 -> 14 | H24: ='205 - Health Care Prod. GERMANY'!D5 -> 0 | I24: ='205 - Health Care Prod. GERMANY'!B6 -> 653 | J24: ='205 - Health Care Prod. GERMANY'!D6 -> 14501.3 | K24: ='205 - Health Care Prod. GERMANY'!F6 -> 0 | L24: ='205 - Health Care Prod. GERMANY'!H6 -> 0 | M24: ='205 - Health Care Prod. GERMANY'!C47 -> 12986 | N24: ='205 - Health Care Prod. GERMANY'!D47 -> 12906 | O24: =IF('205 - Health Care Prod. GERMANY'!C47=0,"N/A",('205 - Health Care Prod. GERMANY'!D47-'205 - Health Care Prod. GERMANY'!C47)/'205 - Health Care Prod. GERMANY'!C47) -> -0.0061604805 | P24: ='205 - Health Care Prod. GERMANY'!H47 -> 122339 | Q24: ='205 - Health Care Prod. GERMANY'!I47 -> 96129.82 | R24: =IF('205 - Health Care Prod. GERMANY'!H47=0,"N/A",('205 - Health Care Prod. GERMANY'!I47-'205 - Health Care Prod. GERMANY'!H47)/'205 - Health Care Prod. GERMANY'!H47) -> -0.21423405
A25: 301 - Amazon | B25: 301 - Amazon | C25: N/A | D25: =COUNTA('301 - Amazon'!$A$9:$A$87) -> 79 | E25: =SUMPRODUCT(--(('301 - Amazon'!$C$9:$C$87<>0)+('301 - Amazon'!$H$9:$H$87<>0)>0)) -> 73 | F25: =SUMPRODUCT(--(('301 - Amazon'!$D$9:$D$87<>0)+('301 - Amazon'!$I$9:$I$87<>0)>0)) -> 62 | G25: ='301 - Amazon'!B5 -> 17 | H25: ='301 - Amazon'!D5 -> 6 | I25: ='301 - Amazon'!B6 -> 448 | J25: ='301 - Amazon'!D6 -> 94856.4 | K25: ='301 - Amazon'!F6 -> 47 | L25: ='301 - Amazon'!H6 -> 3274.06 | M25: ='301 - Amazon'!C89 -> 27158 | N25: ='301 - Amazon'!D89 -> 18808 | O25: =IF('301 - Amazon'!C89=0,"N/A",('301 - Amazon'!D89-'301 - Amazon'!C89)/'301 - Amazon'!C89) -> -0.30746005 | P25: ='301 - Amazon'!H89 -> 2705391.2 | Q25: ='301 - Amazon'!I89 -> 1632890.8 | R25: =IF('301 - Amazon'!H89=0,"N/A",('301 - Amazon'!I89-'301 - Amazon'!H89)/'301 - Amazon'!H89) -> -0.3964308
A26: 206 - Orthomed Ltd BULGARIA | B26: 206 - Orthomed Ltd BULGARIA | C26: N/A | D26: =COUNTA('206 - Orthomed Ltd BULGARIA'!$A$9:$A$94) -> 86 | E26: =SUMPRODUCT(--(('206 - Orthomed Ltd BULGARIA'!$C$9:$C$94<>0)+('206 - Orthomed Ltd BULGARIA'!$H$9:$H$94<>0)>0)) -> 86 | F26: =SUMPRODUCT(--(('206 - Orthomed Ltd BULGARIA'!$D$9:$D$94<>0)+('206 - Orthomed Ltd BULGARIA'!$I$9:$I$94<>0)>0)) -> 0 | G26: ='206 - Orthomed Ltd BULGARIA'!B5 -> 86 | H26: ='206 - Orthomed Ltd BULGARIA'!D5 -> 0 | I26: ='206 - Orthomed Ltd BULGARIA'!B6 -> 1817 | J26: ='206 - Orthomed Ltd BULGARIA'!D6 -> 52899.82 | K26: ='206 - Orthomed Ltd BULGARIA'!F6 -> 0 | L26: ='206 - Orthomed Ltd BULGARIA'!H6 -> 0 | M26: ='206 - Orthomed Ltd BULGARIA'!C96 -> 1817 | N26: ='206 - Orthomed Ltd BULGARIA'!D96 -> 0 | O26: =IF('206 - Orthomed Ltd BULGARIA'!C96=0,"N/A",('206 - Orthomed Ltd BULGARIA'!D96-'206 - Orthomed Ltd BULGARIA'!C96)/'206 - Orthomed Ltd BULGARIA'!C96) -> -1 | P26: ='206 - Orthomed Ltd BULGARIA'!H96 -> 52899.82 | Q26: ='206 - Orthomed Ltd BULGARIA'!I96 -> 0 | R26: =IF('206 - Orthomed Ltd BULGARIA'!H96=0,"N/A",('206 - Orthomed Ltd BULGARIA'!I96-'206 - Orthomed Ltd BULGARIA'!H96)/'206 - Orthomed Ltd BULGARIA'!H96) -> -1
A27: 203 - Ortho- Partner ag SWITZERLAND | B27: 203 - Ortho-Partner SWITZERLAND | C27: N/A | D27: =COUNTA('203 - Ortho-Partner SWITZERLAND'!$A$9:$A$119) -> 111 | E27: =SUMPRODUCT(--(('203 - Ortho-Partner SWITZERLAND'!$C$9:$C$119<>0)+('203 - Ortho-Partner SWITZERLAND'!$H$9:$H$119<>0)>0)) -> 99 | F27: =SUMPRODUCT(--(('203 - Ortho-Partner SWITZERLAND'!$D$9:$D$119<>0)+('203 - Ortho-Partner SWITZERLAND'!$I$9:$I$119<>0)>0)) -> 78 | G27: ='203 - Ortho-Partner SWITZERLAND'!B5 -> 33 | H27: ='203 - Ortho-Partner SWITZERLAND'!D5 -> 12 | I27: ='203 - Ortho-Partner SWITZERLAND'!B6 -> 563 | J27: ='203 - Ortho-Partner SWITZERLAND'!D6 -> 21452.36 | K27: ='203 - Ortho-Partner SWITZERLAND'!F6 -> 131 | L27: ='203 - Ortho-Partner SWITZERLAND'!H6 -> 4054.38 | M27: ='203 - Ortho-Partner SWITZERLAND'!C121 -> 6959 | N27: ='203 - Ortho-Partner SWITZERLAND'!D121 -> 6740 | O27: =IF('203 - Ortho-Partner SWITZERLAND'!C121=0,"N/A",('203 - Ortho-Partner SWITZERLAND'!D121-'203 - Ortho-Partner SWITZERLAND'!C121)/'203 - Ortho-Partner SWITZERLAND'!C121) -> -0.031470039 | P27: ='203 - Ortho-Partner SWITZERLAND'!H121 -> 405920.85 | Q27: ='203 - Ortho-Partner SWITZERLAND'!I121 -> 344263.09 | R27: =IF('203 - Ortho-Partner SWITZERLAND'!H121=0,"N/A",('203 - Ortho-Partner SWITZERLAND'!I121-'203 - Ortho-Partner SWITZERLAND'!H121)/'203 - Ortho-Partner SWITZERLAND'!H121) -> -0.15189602
A28: 210 - Oy. Ea. Ab. FINLAND | B28: 210 - Oy. Ea. Ab. FINLAND | C28: N/A | D28: =COUNTA('210 - Oy. Ea. Ab. FINLAND'!$A$9:$A$191) -> 183 | E28: =SUMPRODUCT(--(('210 - Oy. Ea. Ab. FINLAND'!$C$9:$C$191<>0)+('210 - Oy. Ea. Ab. FINLAND'!$H$9:$H$191<>0)>0)) -> 128 | F28: =SUMPRODUCT(--(('210 - Oy. Ea. Ab. FINLAND'!$D$9:$D$191<>0)+('210 - Oy. Ea. Ab. FINLAND'!$I$9:$I$191<>0)>0)) -> 145 | G28: ='210 - Oy. Ea. Ab. FINLAND'!B5 -> 38 | H28: ='210 - Oy. Ea. Ab. FINLAND'!D5 -> 55 | I28: ='210 - Oy. Ea. Ab. FINLAND'!B6 -> 533 | J28: ='210 - Oy. Ea. Ab. FINLAND'!D6 -> 15504.74 | K28: ='210 - Oy. Ea. Ab. FINLAND'!F6 -> 360 | L28: ='210 - Oy. Ea. Ab. FINLAND'!H6 -> 16342.42 | M28: ='210 - Oy. Ea. Ab. FINLAND'!C193 -> 2672 | N28: ='210 - Oy. Ea. Ab. FINLAND'!D193 -> 1516 | O28: =IF('210 - Oy. Ea. Ab. FINLAND'!C193=0,"N/A",('210 - Oy. Ea. Ab. FINLAND'!D193-'210 - Oy. Ea. Ab. FINLAND'!C193)/'210 - Oy. Ea. Ab. FINLAND'!C193) -> -0.43263473 | P28: ='210 - Oy. Ea. Ab. FINLAND'!H193 -> 64554.59 | Q28: ='210 - Oy. Ea. Ab. FINLAND'!I193 -> 43116.44 | R28: =IF('210 - Oy. Ea. Ab. FINLAND'!H193=0,"N/A",('210 - Oy. Ea. Ab. FINLAND'!I193-'210 - Oy. Ea. Ab. FINLAND'!H193)/'210 - Oy. Ea. Ab. FINLAND'!H193) -> -0.33209335
A29: 204 - Sanaflex Anatomic GREECE | B29: 204 - Sanaflex Anatomic GREECE | C29: N/A | D29: =COUNTA('204 - Sanaflex Anatomic GREECE'!$A$9:$A$212) -> 204 | E29: =SUMPRODUCT(--(('204 - Sanaflex Anatomic GREECE'!$C$9:$C$212<>0)+('204 - Sanaflex Anatomic GREECE'!$H$9:$H$212<>0)>0)) -> 185 | F29: =SUMPRODUCT(--(('204 - Sanaflex Anatomic GREECE'!$D$9:$D$212<>0)+('204 - Sanaflex Anatomic GREECE'!$I$9:$I$212<>0)>0)) -> 173 | G29: ='204 - Sanaflex Anatomic GREECE'!B5 -> 31 | H29: ='204 - Sanaflex Anatomic GREECE'!D5 -> 19 | I29: ='204 - Sanaflex Anatomic GREECE'!B6 -> 347 | J29: ='204 - Sanaflex Anatomic GREECE'!D6 -> 10736.31 | K29: ='204 - Sanaflex Anatomic GREECE'!F6 -> 154 | L29: ='204 - Sanaflex Anatomic GREECE'!H6 -> 3246.9 | M29: ='204 - Sanaflex Anatomic GREECE'!C214 -> 21177 | N29: ='204 - Sanaflex Anatomic GREECE'!D214 -> 18128 | O29: =IF('204 - Sanaflex Anatomic GREECE'!C214=0,"N/A",('204 - Sanaflex Anatomic GREECE'!D214-'204 - Sanaflex Anatomic GREECE'!C214)/'204 - Sanaflex Anatomic GREECE'!C214) -> -0.14397696 | P29: ='204 - Sanaflex Anatomic GREECE'!H214 -> 414072.64 | Q29: ='204 - Sanaflex Anatomic GREECE'!I214 -> 307055.17 | R29: =IF('204 - Sanaflex Anatomic GREECE'!H214=0,"N/A",('204 - Sanaflex Anatomic GREECE'!I214-'204 - Sanaflex Anatomic GREECE'!H214)/'204 - Sanaflex Anatomic GREECE'!H214) -> -0.25845096
A30: 214 - Alfred Gera& Sons Ltd. MALTA | B30: 214 - Alfred Gera Sons MALTA | C30: N/A | D30: =COUNTA('214 - Alfred Gera Sons MALTA'!$A$9:$A$29) -> 21 | E30: =SUMPRODUCT(--(('214 - Alfred Gera Sons MALTA'!$C$9:$C$29<>0)+('214 - Alfred Gera Sons MALTA'!$H$9:$H$29<>0)>0)) -> 21 | F30: =SUMPRODUCT(--(('214 - Alfred Gera Sons MALTA'!$D$9:$D$29<>0)+('214 - Alfred Gera Sons MALTA'!$I$9:$I$29<>0)>0)) -> 16 | G30: ='214 - Alfred Gera Sons MALTA'!B5 -> 5 | H30: ='214 - Alfred Gera Sons MALTA'!D5 -> 0 | I30: ='214 - Alfred Gera Sons MALTA'!B6 -> 23 | J30: ='214 - Alfred Gera Sons MALTA'!D6 -> 889.12 | K30: ='214 - Alfred Gera Sons MALTA'!F6 -> 0 | L30: ='214 - Alfred Gera Sons MALTA'!H6 -> 0 | M30: ='214 - Alfred Gera Sons MALTA'!C31 -> 1737 | N30: ='214 - Alfred Gera Sons MALTA'!D31 -> 978 | O30: =IF('214 - Alfred Gera Sons MALTA'!C31=0,"N/A",('214 - Alfred Gera Sons MALTA'!D31-'214 - Alfred Gera Sons MALTA'!C31)/'214 - Alfred Gera Sons MALTA'!C31) -> -0.43696028 | P30: ='214 - Alfred Gera Sons MALTA'!H31 -> 53863.18 | Q30: ='214 - Alfred Gera Sons MALTA'!I31 -> 26105.72 | R30: =IF('214 - Alfred Gera Sons MALTA'!H31=0,"N/A",('214 - Alfred Gera Sons MALTA'!I31-'214 - Alfred Gera Sons MALTA'!H31)/'214 - Alfred Gera Sons MALTA'!H31) -> -0.51533274
A31: 211 - Pharmag Lachmair Ges. Mbh AUSTRIA | B31: 211 - Pharmag Lachmair AUSTRIA | C31: N/A | D31: =COUNTA('211 - Pharmag Lachmair AUSTRIA'!$A$9:$A$40) -> 32 | E31: =SUMPRODUCT(--(('211 - Pharmag Lachmair AUSTRIA'!$C$9:$C$40<>0)+('211 - Pharmag Lachmair AUSTRIA'!$H$9:$H$40<>0)>0)) -> 31 | F31: =SUMPRODUCT(--(('211 - Pharmag Lachmair AUSTRIA'!$D$9:$D$40<>0)+('211 - Pharmag Lachmair AUSTRIA'!$I$9:$I$40<>0)>0)) -> 9 | G31: ='211 - Pharmag Lachmair AUSTRIA'!B5 -> 23 | H31: ='211 - Pharmag Lachmair AUSTRIA'!D5 -> 1 | I31: ='211 - Pharmag Lachmair AUSTRIA'!B6 -> 1650 | J31: ='211 - Pharmag Lachmair AUSTRIA'!D6 -> 56507.31 | K31: ='211 - Pharmag Lachmair AUSTRIA'!F6 -> 5 | L31: ='211 - Pharmag Lachmair AUSTRIA'!H6 -> 86.54 | M31: ='211 - Pharmag Lachmair AUSTRIA'!C42 -> 3060 | N31: ='211 - Pharmag Lachmair AUSTRIA'!D42 -> 674 | O31: =IF('211 - Pharmag Lachmair AUSTRIA'!C42=0,"N/A",('211 - Pharmag Lachmair AUSTRIA'!D42-'211 - Pharmag Lachmair AUSTRIA'!C42)/'211 - Pharmag Lachmair AUSTRIA'!C42) -> -0.77973856 | P31: ='211 - Pharmag Lachmair AUSTRIA'!H42 -> 81786.57 | Q31: ='211 - Pharmag Lachmair AUSTRIA'!I42 -> 10037.15 | R31: =IF('211 - Pharmag Lachmair AUSTRIA'!H42=0,"N/A",('211 - Pharmag Lachmair AUSTRIA'!I42-'211 - Pharmag Lachmair AUSTRIA'!H42)/'211 - Pharmag Lachmair AUSTRIA'!H42) -> -0.87727631
A32: 213 - E.f.m.o. SPAIN | B32: 213 - E.f.m.o. SPAIN | C32: N/A | D32: =COUNTA('213 - E.f.m.o. SPAIN'!$A$9:$A$53) -> 45 | E32: =SUMPRODUCT(--(('213 - E.f.m.o. SPAIN'!$C$9:$C$53<>0)+('213 - E.f.m.o. SPAIN'!$H$9:$H$53<>0)>0)) -> 38 | F32: =SUMPRODUCT(--(('213 - E.f.m.o. SPAIN'!$D$9:$D$53<>0)+('213 - E.f.m.o. SPAIN'!$I$9:$I$53<>0)>0)) -> 36 | G32: ='213 - E.f.m.o. SPAIN'!B5 -> 9 | H32: ='213 - E.f.m.o. SPAIN'!D5 -> 7 | I32: ='213 - E.f.m.o. SPAIN'!B6 -> 45 | J32: ='213 - E.f.m.o. SPAIN'!D6 -> 4777.25 | K32: ='213 - E.f.m.o. SPAIN'!F6 -> 56 | L32: ='213 - E.f.m.o. SPAIN'!H6 -> 1430.29 | M32: ='213 - E.f.m.o. SPAIN'!C55 -> 1359 | N32: ='213 - E.f.m.o. SPAIN'!D55 -> 1532 | O32: =IF('213 - E.f.m.o. SPAIN'!C55=0,"N/A",('213 - E.f.m.o. SPAIN'!D55-'213 - E.f.m.o. SPAIN'!C55)/'213 - E.f.m.o. SPAIN'!C55) -> 0.12729948 | P32: ='213 - E.f.m.o. SPAIN'!H55 -> 39713.57 | Q32: ='213 - E.f.m.o. SPAIN'!I55 -> 37142.74 | R32: =IF('213 - E.f.m.o. SPAIN'!H55=0,"N/A",('213 - E.f.m.o. SPAIN'!I55-'213 - E.f.m.o. SPAIN'!H55)/'213 - E.f.m.o. SPAIN'!H55) -> -0.064734296
A33: 207 - Salus HUNGARY | B33: 207 - Salus HUNGARY | C33: N/A | D33: =COUNTA('207 - Salus HUNGARY'!$A$9:$A$225) -> 217 | E33: =SUMPRODUCT(--(('207 - Salus HUNGARY'!$C$9:$C$225<>0)+('207 - Salus HUNGARY'!$H$9:$H$225<>0)>0)) -> 195 | F33: =SUMPRODUCT(--(('207 - Salus HUNGARY'!$D$9:$D$225<>0)+('207 - Salus HUNGARY'!$I$9:$I$225<>0)>0)) -> 151 | G33: ='207 - Salus HUNGARY'!B5 -> 66 | H33: ='207 - Salus HUNGARY'!D5 -> 22 | I33: ='207 - Salus HUNGARY'!B6 -> 797 | J33: ='207 - Salus HUNGARY'!D6 -> 28651.54 | K33: ='207 - Salus HUNGARY'!F6 -> 991 | L33: ='207 - Salus HUNGARY'!H6 -> 14625 | M33: ='207 - Salus HUNGARY'!C227 -> 18268 | N33: ='207 - Salus HUNGARY'!D227 -> 20601 | O33: =IF('207 - Salus HUNGARY'!C227=0,"N/A",('207 - Salus HUNGARY'!D227-'207 - Salus HUNGARY'!C227)/'207 - Salus HUNGARY'!C227) -> 0.12770966 | P33: ='207 - Salus HUNGARY'!H227 -> 319558.55 | Q33: ='207 - Salus HUNGARY'!I227 -> 365555.25 | R33: =IF('207 - Salus HUNGARY'!H227=0,"N/A",('207 - Salus HUNGARY'!I227-'207 - Salus HUNGARY'!H227)/'207 - Salus HUNGARY'!H227) -> 0.14393825
A34: 208 - Medipal Company NABLUS | B34: 208 - Medipal Company NABLUS | C34: N/A | D34: =COUNTA('208 - Medipal Company NABLUS'!$A$9:$A$98) -> 90 | E34: =SUMPRODUCT(--(('208 - Medipal Company NABLUS'!$C$9:$C$98<>0)+('208 - Medipal Company NABLUS'!$H$9:$H$98<>0)>0)) -> 90 | F34: =SUMPRODUCT(--(('208 - Medipal Company NABLUS'!$D$9:$D$98<>0)+('208 - Medipal Company NABLUS'!$I$9:$I$98<>0)>0)) -> 0 | G34: ='208 - Medipal Company NABLUS'!B5 -> 90 | H34: ='208 - Medipal Company NABLUS'!D5 -> 0 | I34: ='208 - Medipal Company NABLUS'!B6 -> 6687 | J34: ='208 - Medipal Company NABLUS'!D6 -> 256772.1 | K34: ='208 - Medipal Company NABLUS'!F6 -> 0 | L34: ='208 - Medipal Company NABLUS'!H6 -> 0 | M34: ='208 - Medipal Company NABLUS'!C100 -> 6687 | N34: ='208 - Medipal Company NABLUS'!D100 -> 0 | O34: =IF('208 - Medipal Company NABLUS'!C100=0,"N/A",('208 - Medipal Company NABLUS'!D100-'208 - Medipal Company NABLUS'!C100)/'208 - Medipal Company NABLUS'!C100) -> -1 | P34: ='208 - Medipal Company NABLUS'!H100 -> 256772.1 | Q34: ='208 - Medipal Company NABLUS'!I100 -> 0 | R34: =IF('208 - Medipal Company NABLUS'!H100=0,"N/A",('208 - Medipal Company NABLUS'!I100-'208 - Medipal Company NABLUS'!H100)/'208 - Medipal Company NABLUS'!H100) -> -1
A35: 209 - Ortoprofil Prod ROMANIA | B35: 209 - Ortoprofil Prod ROMANIA | C35: N/A | D35: =COUNTA('209 - Ortoprofil Prod ROMANIA'!$A$9:$A$99) -> 91 | E35: =SUMPRODUCT(--(('209 - Ortoprofil Prod ROMANIA'!$C$9:$C$99<>0)+('209 - Ortoprofil Prod ROMANIA'!$H$9:$H$99<>0)>0)) -> 83 | F35: =SUMPRODUCT(--(('209 - Ortoprofil Prod ROMANIA'!$D$9:$D$99<>0)+('209 - Ortoprofil Prod ROMANIA'!$I$9:$I$99<>0)>0)) -> 74 | G35: ='209 - Ortoprofil Prod ROMANIA'!B5 -> 17 | H35: ='209 - Ortoprofil Prod ROMANIA'!D5 -> 8 | I35: ='209 - Ortoprofil Prod ROMANIA'!B6 -> 184 | J35: ='209 - Ortoprofil Prod ROMANIA'!D6 -> 2098.73 | K35: ='209 - Ortoprofil Prod ROMANIA'!F6 -> 147 | L35: ='209 - Ortoprofil Prod ROMANIA'!H6 -> 6167.14 | M35: ='209 - Ortoprofil Prod ROMANIA'!C101 -> 13479 | N35: ='209 - Ortoprofil Prod ROMANIA'!D101 -> 9703 | O35: =IF('209 - Ortoprofil Prod ROMANIA'!C101=0,"N/A",('209 - Ortoprofil Prod ROMANIA'!D101-'209 - Ortoprofil Prod ROMANIA'!C101)/'209 - Ortoprofil Prod ROMANIA'!C101) -> -0.28013948 | P35: ='209 - Ortoprofil Prod ROMANIA'!H101 -> 407234.61 | Q35: ='209 - Ortoprofil Prod ROMANIA'!I101 -> 300835.19 | R35: =IF('209 - Ortoprofil Prod ROMANIA'!H101=0,"N/A",('209 - Ortoprofil Prod ROMANIA'!I101-'209 - Ortoprofil Prod ROMANIA'!H101)/'209 - Ortoprofil Prod ROMANIA'!H101) -> -0.26127303
A36: 108 - Shoe Stores | B36: 108 - Shoe Stores | C36: N/A | D36: =COUNTA('108 - Shoe Stores'!$A$9:$A$39) -> 31 | E36: =SUMPRODUCT(--(('108 - Shoe Stores'!$C$9:$C$39<>0)+('108 - Shoe Stores'!$H$9:$H$39<>0)>0)) -> 31 | F36: =SUMPRODUCT(--(('108 - Shoe Stores'!$D$9:$D$39<>0)+('108 - Shoe Stores'!$I$9:$I$39<>0)>0)) -> 0 | G36: ='108 - Shoe Stores'!B5 -> 31 | H36: ='108 - Shoe Stores'!D5 -> 0 | I36: ='108 - Shoe Stores'!B6 -> 833 | J36: ='108 - Shoe Stores'!D6 -> 19065.38 | K36: ='108 - Shoe Stores'!F6 -> 0 | L36: ='108 - Shoe Stores'!H6 -> 0 | M36: ='108 - Shoe Stores'!C41 -> 833 | N36: ='108 - Shoe Stores'!D41 -> 0 | O36: =IF('108 - Shoe Stores'!C41=0,"N/A",('108 - Shoe Stores'!D41-'108 - Shoe Stores'!C41)/'108 - Shoe Stores'!C41) -> -1 | P36: ='108 - Shoe Stores'!H41 -> 19065.38 | Q36: ='108 - Shoe Stores'!I41 -> 0 | R36: =IF('108 - Shoe Stores'!H41=0,"N/A",('108 - Shoe Stores'!I41-'108 - Shoe Stores'!H41)/'108 - Shoe Stores'!H41) -> -1

Sheet 110 - Chemipal
A1: Sales Comparison 2025 vs 2026 (Annualized) - Sale Type: 110 - Chemipal (by Product CODE)
A2: Calculation date: | B2: 46284
A3: Source: NetSuite report "1-Sales: Customer by Item" (01/01/2025-31/12/2026), Sale Type = "110 - Chemipal" only (exact match on the "Sale Type" column, per the canonical 31-value list in the source file’s "list" sheet). Product CODE = column "Item: Name" (F in the original report) - NOT "Item: Name (Grouped)" (E), which carries a PARENT prefix. 2025 = columns J/K (Quantity/Amount Net); 2026 = columns O/P. Multiple rows per CODE per Sale Type (one per unit-price tier / customer within this category) are summed (SUMIFS) per CODE, not taken from a single row. Raw rows kept unchanged in the shared "Source" sheet (filtered to only these 31 categories - built-in "Total"/"Total - <category>"/"- Unassigned -" rows excluded to avoid double-counting). IMPORTANT: the source file’s own header states the report range as "01 January 2025 - 31 December 2026", but has no per-row date/timestamp field, so the exact 2026 cutoff cannot be verified from the data itself. Same assumption used across this whole workbook family for consistency: 2026 actual covers approximately 9.5 months (1 Jan - 15 Sep).
A4: Annualization note: 2026 actual data is assumed to cover approximately 9.5 months (1 Jan - 15 Sep 2026), consistent with the rest of this workbook family. Scaled to a full year via a simple linear factor = 12 / 9.5 (≈ 1.263158) - straight-line extrapolation, does NOT account for seasonality. Treat as an estimate. | I4: Months in full year: | J4: 12 | K4: Months covered by 2026 actual (assumed 1/1–15/9): | L4: 9.5
A5: # DROP (sold 2025, 0 in 2026): | B5: =SUMPRODUCT(--(((C9:C569<>0)+(H9:H569<>0)>0)*((D9:D569=0)*(I9:I569=0)))) -> 558 | C5: # NEW (sold 2026, 0 in 2025): | D5: =SUMPRODUCT(--(((D9:D569<>0)+(I9:I569<>0)>0)*((C9:C569=0)*(H9:H569=0)))) -> 2 | I5: Normalization factor (J4/L4): | J5: =J4/L4 -> 1.2631579
A6: DROP — Quantity 2025: | B6: =SUMPRODUCT(--(((C9:C569<>0)+(H9:H569<>0)>0)*((D9:D569=0)*(I9:I569=0)))*C9:C569) -> 156696 | C6: DROP — Amount 2025 (₪): | D6: =SUMPRODUCT(--(((C9:C569<>0)+(H9:H569<>0)>0)*((D9:D569=0)*(I9:I569=0)))*H9:H569) -> 5726866.7 | E6: NEW — Quantity 2026: | F6: =SUMPRODUCT(--(((D9:D569<>0)+(I9:I569<>0)>0)*((C9:C569=0)*(H9:H569=0)))*D9:D569) -> 3 | G6: NEW — Amount 2026 (₪): | H6: =SUMPRODUCT(--(((D9:D569<>0)+(I9:I569<>0)>0)*((C9:C569=0)*(H9:H569=0)))*I9:I569) -> 0
A8: Product Code | B8: Item Display Name | C8: Quantity 2025 | D8: Quantity 2026 (Actual, partial year) | E8: Quantity 2026 (Annualized) | F8: Quantity Change (Annualized vs 2025) | G8: Quantity Change % (Annualized vs 2025) | H8: Amount 2025 (₪) | I8: Amount 2026 (Actual, partial year) (₪) | J8: Amount 2026 (Annualized) (₪) | K8: Amount Change (Annualized vs 2025) (₪) | L8: Amount Change % (Annualized vs 2025) | M8: Note
A9: 99 Chemipal Inv Item | B9: =IFERROR(INDEX('Source'!$C:$C,MATCH($A9,'Source'!$B:$B,0)),"") -> 99 Chemipal Inv Item | C9: =SUMIFS('Source'!$D:$D,'Source'!$A:$A,"110 - Chemipal",'Source'!$B:$B,$A9) -> -6 | D9: =SUMIFS('Source'!$F:$F,'Source'!$A:$A,"110 - Chemipal",'Source'!$B:$B,$A9) -> 8 | E9: =D9*$J$5 -> 10.105263 | F9: =E9-C9 -> 16.105263 | G9: =IF(AND(C9=0,E9=0),0,IF(C9=0,"New",(E9-C9)/C9)) -> -2.6842105 | H9: =SUMIFS('Source'!$E:$E,'Source'!$A:$A,"110 - Chemipal",'Source'!$B:$B,$A9) -> 2720270 | I9: =SUMIFS('Source'!$G:$G,'Source'!$A:$A,"110 - Chemipal",'Source'!$B:$B,$A9) -> 5794673.6 | J9: =I9*$J$5 -> 7319587.8 | K9: =J9-H9 -> 4599317.8 | L9: =IF(AND(H9=0,J9=0),0,IF(H9=0,"New",(J9-H9)/H9)) -> 1.6907579 | M9: =IF(AND(OR(C9<>0,H9<>0),D9=0,I9=0),"DROP",IF(AND(OR(D9<>0,I9<>0),C9=0,H9=0),"NEW",""))
A10: בונוסים ללקוחות | B10: =IFERROR(INDEX('Source'!$C:$C,MATCH($A10,'Source'!$B:$B,0)),"") -> 0 | C10: =SUMIFS('Source'!$D:$D,'Source'!$A:$A,"110 - Chemipal",'Source'!$B:$B,$A10) -> -1 | D10: =SUMIFS('Source'!$F:$F,'Source'!$A:$A,"110 - Chemipal",'Source'!$B:$B,$A10) -> 0 | E10: =D10*$J$5 -> 0 | F10: =E10-C10 -> 1 | G10: =IF(AND(C10=0,E10=0),0,IF(C10=0,"New",(E10-C10)/C10)) -> -1 | H10: =SUMIFS('Source'!$E:$E,'Source'!$A:$A,"110 - Chemipal",'Source'!$B:$B,$A10) -> -240000 | I10: =SUMIFS('Source'!$G:$G,'Source'!$A:$A,"110 - Chemipal",'Source'!$B:$B,$A10) -> 0 | J10: =I10*$J$5 -> 0 | K10: =J10-H10 -> 240000 | L10: =IF(AND(H10=0,J10=0),0,IF(H10=0,"New",(J10-H10)/H10)) -> -1 | M10: =IF(AND(OR(C10<>0,H10<>0),D10=0,I10=0),"DROP",IF(AND(OR(D10<>0,I10<>0),C10=0,H10=0),"NEW","")) -> DROP
A11: 266 0 | B11: =IFERROR(INDEX('Source'!$C:$C,MATCH($A11,'Source'!$B:$B,0)),"") -> סד יד דו צדדי | C11: =SUMIFS('Source'!$D:$D,'Source'!$A:$A,"110 - Chemipal",'Source'!$B:$B,$A11) -> 3078 | D11: =SUMIFS('Source'!$F:$F,'Source'!$A:$A,"110 - Chemipal",'Source'!$B:$B,$A11) -> 0 | E11: =D11*$J$5 -> 0 | F11: =E11-C11 -> -3078 | G11: =IF(AND(C11=0,E11=0),0,IF(C11=0,"New",(E11-C11)/C11)) -> -1 | H11: =SUMIFS('Source'!$E:$E,'Source'!$A:$A,"110 - Chemipal",'Source'!$B:$B,$A11) -> 211474.64 | I11: =SUMIFS('Source'!$G:$G,'Source'!$A:$A,"110 - Chemipal",'Source'!$B:$B,$A11) -> 0 | J11: =I11*$J$5 -> 0 | K11: =J11-H11 -> -211474.64 | L11: =IF(AND(H11=0,J11=0),0,IF(H11=0,"New",(J11-H11)/H11)) -> -1 | M11: =IF(AND(OR(C11<>0,H11<>0),D11=0,I11=0),"DROP",IF(AND(OR(D11<>0,I11<>0),C11=0,H11=0),"NEW","")) -> DROP
A12: T25C 0 | B12: =IFERROR(INDEX('Source'!$C:$C,MATCH($A12,'Source'!$B:$B,0)),"") -> חבק יד אגודלי ימ | C12: =SUMIFS('Source'!$D:$D,'Source'!$A:$A,"110 - Chemipal",'Source'!$B:$B,$A12) -> 3441 | D12: =SUMIFS('Source'!$F:$F,'Source'!$A:$A,"110 - Chemipal",'Source'!$B:$B,$A12) -> 0 | E12: =D12*$J$5 -> 0 | F12: =E12-C12 -> -3441 | G12: =IF(AND(C12=0,E12=0),0,IF(C12=0,"New",(E12-C12)/C12)) -> -1 | H12: =SUMIFS('Source'!$E:$E,'Source'!$A:$A,"110 - Chemipal",'Source'!$B:$B,$A12) -> 128934.22 | I12: =SUMIFS('Source'!$G:$G,'Source'!$A:$A,"110 - Chemipal",'Source'!$B:$B,$A12) -> 0 | J12: =I12*$J$5 -> 0 | K12: =J12-H12 -> -128934.22 | L12: =IF(AND(H12=0,J12=0),0,IF(H12=0,"New",(J12-H12)/H12)) -> -1 | M12: =IF(AND(OR(C12<>0,H12<>0),D12=0,I12=0),"DROP",IF(AND(OR(D12<>0,I12<>0),C12=0,H12=0),"NEW","")) -> DROP
A13: T25 0 | B13: =IFERROR(INDEX('Source'!$C:$C,MATCH($A13,'Source'!$B:$B,0)),"") -> חבק יד אגודלי ימ | C13: =SUMIFS('Source'!$D:$D,'Source'!$A:$A,"110 - Chemipal",'Source'!$B:$B,$A13) -> 3024 | D13: =SUMIFS('Source'!$F:$F,'Source'!$A:$A,"110 - Chemipal",'Source'!$B:$B,$A13) -> 0 | E13: =D13*$J$5 -> 0 | F13: =E13-C13 -> -3024 | G13: =IF(AND(C13=0,E13=0),0,IF(C13=0,"New",(E13-C13)/C13)) -> -1 | H13: =SUMIFS('Source'!$E:$E,'Source'!$A:$A,"110 - Chemipal",'Source'!$B:$B,$A13) -> 113949.94 | I13: =SUMIFS('Source'!$G:$G,'Source'!$A:$A,"110 - Chemipal",'Source'!$B:$B,$A13) -> 0 | J13: =I13*$J$5 -> 0 | K13: =J13-H13 -> -113949.94 | L13: =IF(AND(H13=0,J13=0),0,IF(H13=0,"New",(J13-H13)/H13)) -> -1 | M13: =IF(AND(OR(C13<>0,H13<>0),D13=0,I13=0),"DROP",IF(AND(OR(D13<>0,I13<>0),C13=0,H13=0),"NEW","")) -> DROP
A14: 078G L | B14: =IFERROR(INDEX('Source'!$C:$C,MATCH($A14,'Source'!$B:$B,0)),"") -> חגורת גב אפורה | C14: =SUMIFS('Source'!$D:$D,'Source'!$A:$A,"110 - Chemipal",'Source'!$B:$B,$A14) -> 1111 | D14: =SUMIFS('Source'!$F:$F,'Source'!$A:$A,"110 - Chemipal",'Source'!$B:$B,$A14) -> 0 | E14: =D14*$J$5 -> 0 | F14: =E14-C14 -> -1111 | G14: =IF(AND(C14=0,E14=0),0,IF(C14=0,"New",(E14-C14)/C14)) -> -1 | H14: =SUMIFS('Source'!$E:$E,'Source'!$A:$A,"110 - Chemipal",'Source'!$B:$B,$A14) -> 103511.38 | I14: =SUMIFS('Source'!$G:$G,'Source'!$A:$A,"110 - Chemipal",'Source'!$B:$B,$A14) -> 0 | J14: =I14*$J$5 -> 0 | K14: =J14-H14 -> -103511.38 | L14: =IF(AND(H14=0,J14=0),0,IF(H14=0,"New",(J14-H14)/H14)) -> -1 | M14: =IF(AND(OR(C14<>0,H14<>0),D14=0,I14=0),"DROP",IF(AND(OR(D14<>0,I14<>0),C14=0,H14=0),"NEW","")) -> DROP
A15: 379WRK-43-46 | B15: =IFERROR(INDEX('Source'!$C:$C,MATCH($A15,'Source'!$B:$B,0)),"") -> מדרסי ג'ל וורק | C15: =SUMIFS('Source'!$D:$D,'Source'!$A:$A,"110 - Chemipal",'Source'!$B:$B,$A15) -> 999 | D15: =SUMIFS('Source'!$F:$F,'Source'!$A:$A,"110 - Chemipal",'Source'!$B:$B,$A15) -> 0 | E15: =D15*$J$5 -> 0 | F15: =E15-C15 -> -999 | G15: =IF(AND(C15=0,E15=0),0,IF(C15=0,"New",(E15-C15)/C15)) -> -1 | H15: =SUMIFS('Source'!$E:$E,'Source'!$A:$A,"110 - Chemipal",'Source'!$B:$B,$A15) -> 92034.03 | I15: =SUMIFS('Source'!$G:$G,'Source'!$A:$A,"110 - Chemipal",'Source'!$B:$B,$A15) -> 0 | J15: =I15*$J$5 -> 0 | K15: =J15-H15 -> -92034.03 | L15: =IF(AND(H15=0,J15=0),0,IF(H15=0,"New",(J15-H15)/H15)) -> -1 | M15: =IF(AND(OR(C15<>0,H15<>0),D15=0,I15=0),"DROP",IF(AND(OR(D15<>0,I15<>0),C15=0,H15=0),"NEW","")) -> DROP
A16: 078G XL | B16: =IFERROR(INDEX('Source'!$C:$C,MATCH($A16,'Source'!$B:$B,0)),"") -> חגורת גב אפורה | C16: =SUMIFS('Source'!$D:$D,'Source'!$A:$A,"110 - Chemipal",'Source'!$B:$B,$A16) -> 986 | D16: =SUMIFS('Source'!$F:$F,'Source'!$A:$A,"110 - Chemipal",'Source'!$B:$B,$A16) -> 0 | E16: =D16*$J$5 -> 0 | F16: =E16-C16 -> -986 | G16: =IF(AND(C16=0,E16=0),0,IF(C16=0,"New",(E16-C16)/C16)) -> -1 | H16: =SUMIFS('Source'!$E:$E,'Source'!$A:$A,"110 - Chemipal",'Source'!$B:$B,$A16) -> 91706.88 | I16: =SUMIFS('Source'!$G:$G,'Source'!$A:$A,"110 - Chemipal",'Source'!$B:$B,$A16) -> 0 | J16: =I16*$J$5 -> 0 | K16: =J16-H16 -> -91706.88 | L16: =IF(AND(H16=0,J16=0),0,IF(H16=0,"New",(J16-H16)/H16)) -> -1 | M16: =IF(AND(OR(C16<>0,H16<>0),D16=0,I16=0),"DROP",IF(AND(OR(D16<>0,I16<>0),C16=0,H16=0),"NEW","")) -> DROP
A17: 379WRK-39-42 | B17: =IFERROR(INDEX('Source'!$C:$C,MATCH($A17,'Source'!$B:$B,0)),"") -> מדרסי ג'ל וורק | C17: =SUMIFS('Source'!$D:$D,'Source'!$A:$A,"110 - Chemipal",'Source'!$B:$B,$A17) -> 972 | D17: =SUMIFS('Source'!$F:$F,'Source'!$A:$A,"110 - Chemipal",'Source'!$B:$B,$A17) -> 0 | E17: =D17*$J$5 -> 0 | F17: =E17-C17 -> -972 | G17: =IF(AND(C17=0,E17=0),0,IF(C17=0,"New",(E17-C17)/C17)) -> -1 | H17: =SUMIFS('Source'!$E:$E,'Source'!$A:$A,"110 - Chemipal",'Source'!$B:$B,$A17) -> 89796.6 | I17: =SUMIFS('Source'!$G:$G,'Source'!$A:$A,"110 - Chemipal",'Source'!$B:$B,$A17) -> 0 | J17: =I17*$J$5 -> 0 | K17: =J17-H17 -> -89796.6 | L17: =IF(AND(H17=0,J17=0),0,IF(H17=0,"New",(J17-H17)/H17)) -> -1 | M17: =IF(AND(OR(C17<>0,H17<>0),D17=0,I17=0),"DROP",IF(AND(OR(D17<>0,I17<>0),C17=0,H17=0),"NEW","")) -> DROP
A18: 379MSP-43-46 | B18: =IFERROR(INDEX('Source'!$C:$C,MATCH($A18,'Source'!$B:$B,0)),"") -> מדרסי ג'ל מולטי ספורט | C18: =SUMIFS('Source'!$D:$D,'Source'!$A:$A,"110 - Chemipal",'Source'!$B:$B,$A18) -> 960 | D18: =SUMIFS('Source'!$F:$F,'Source'!$A:$A,"110 - Chemipal",'Source'!$B:$B,$A18) -> 0 | E18: =D18*$J$5 -> 0 | F18: =E18-C18 -> -960 | G18: =IF(AND(C18=0,E18=0),0,IF(C18=0,"New",(E18-C18)/C18)) -> -1 | H18: =SUMIFS('Source'!$E:$E,'Source'!$A:$A,"110 - Chemipal",'Source'!$B:$B,$A18) -> 88734.96 | I18: =SUMIFS('Source'!$G:$G,'Source'!$A:$A,"110 - Chemipal",'Source'!$B:$B,$A18) -> 0 | J18: =I18*$J$5 -> 0 | K18: =J18-H18 -> -88734.96 | L18: =IF(AND(H18=0,J18=0),0,IF(H18=0,"New",(J18-H18)/H18)) -> -1 | M18: =IF(AND(OR(C18<>0,H18<>0),D18=0,I18=0),"DROP",IF(AND(OR(D18<>0,I18<>0),C18=0,H18=0),"NEW","")) -> DROP
A19: 379COM-43-46 | B19: =IFERROR(INDEX('Source'!$C:$C,MATCH($A19,'Source'!$B:$B,0)),"") -> מדרסי ג'ל קומפורט | C19: =SUMIFS('Source'!$D:$D,'Source'!$A:$A,"110 - Chemipal",'Source'!$B:$B,$A19) -> 923 | D19: =SUMIFS('Source'!$F:$F,'Source'!$A:$A,"110 - Chemipal",'Source'!$B:$B,$A19) -> 0 | E19: =D19*$J$5 -> 0 | F19: =E19-C19 -> -923 | G19: =IF(AND(C19=0,E19=0),0,IF(C19=0,"New",(E19-C19)/C19)) -> -1 | H19: =SUMIFS('Source'!$E:$E,'Source'!$A:$A,"110 - Chemipal",'Source'!$B:$B,$A19) -> 85202.41 | I19: =SUMIFS('Source'!$G:$G,'Source'!$A:$A,"110 - Chemipal",'Source'!$B:$B,$A19) -> 0 | J19: =I19*$J$5 -> 0 | K19: =J19-H19 -> -85202.41 | L19: =IF(AND(H19=0,J19=0),0,IF(H19=0,"New",(J19-H19)/H19)) -> -1 | M19: =IF(AND(OR(C19<>0,H19<>0),D19=0,I19=0),"DROP",IF(AND(OR(D19<>0,I19<>0),C19=0,H19=0),"NEW","")) -> DROP
A20: 379COM-39-42 | B20: =IFERROR(INDEX('Source'!$C:$C,MATCH($A20,'Source'!$B:$B,0)),"") -> מדרסי ג'ל קומפורט | C20: =SUMIFS('Source'!$D:$D,'Source'!$A:$A,"110 - Chemipal",'Source'!$B:$B,$A20) -> 909 | D20: =SUMIFS('Source'!$F:$F,'Source'!$A:$A,"110 - Chemipal",'Source'!$B:$B,$A20) -> 0 | E20: =D20*$J$5 -> 0 | F20: =E20-C20 -> -909 | G20: =IF(AND(C20=0,E20=0),0,IF(C20=0,"New",(E20-C20)/C20)) -> -1 | H20: =SUMIFS('Source'!$E:$E,'Source'!$A:$A,"110 - Chemipal",'Source'!$B:$B,$A20) -> 83933.44 | I20: =SUMIFS('Source'!$G:$G,'Source'!$A:$A,"110 - Chemipal",'Source'!$B:$B,$A20) -> 0 | J20: =I20*$J$5 -> 0 | K20: =J20-H20 -> -83933.44 | L20: =IF(AND(H20=0,J20=0),0,IF(H20=0,"New",(J20-H20)/H20)) -> -1 | M20: =IF(AND(OR(C20<>0,H20<>0),D20=0,I20=0),"DROP",IF(AND(OR(D20<>0,I20<>0),C20=0,H20=0),"NEW","")) -> DROP
... A569: 67813000 | B569: =IFERROR(INDEX('Source'!$C:$C,MATCH($A569,'Source'!$B:$B,0)),"") -> סטנד URIEL שחור מסתובב מתכת 35 ס''מ לבתי מרקחת | C569: =SUMIFS('Source'!$D:$D,'Source'!$A:$A,"110 - Chemipal",'Source'!$B:$B,$A569) -> 0 | D569: =SUMIFS('Source'!$F:$F,'Source'!$A:$A,"110 - Chemipal",'Source'!$B:$B,$A569) -> 1 | E569: =D569*$J$5 -> 1.2631579 | F569: =E569-C569 -> 1.2631579 | G569: =IF(AND(C569=0,E569=0),0,IF(C569=0,"New",(E569-C569)/C569)) -> New | H569: =SUMIFS('Source'!$E:$E,'Source'!$A:$A,"110 - Chemipal",'Source'!$B:$B,$A569) -> 0 | I569: =SUMIFS('Source'!$G:$G,'Source'!$A:$A,"110 - Chemipal",'Source'!$B:$B,$A569) -> 0 | J569: =I569*$J$5 -> 0 | K569: =J569-H569 -> 0 | L569: =IF(AND(H569=0,J569=0),0,IF(H569=0,"New",(J569-H569)/H569)) -> 0 | M569: =IF(AND(OR(C569<>0,H569<>0),D569=0,I569=0),"DROP",IF(AND(OR(D569<>0,I569<>0),C569=0,H569=0),"NEW","")) -> NEW
B571: TOTAL | C571: =SUM(C9:C569) -> 156690 | D571: =SUM(D9:D569) -> 11 | E571: =SUM(E9:E569) -> 13.894737 | F571: =SUM(F9:F569) -> -156676.11 | G571: =IF(C571=0,"N/A",F571/C571) -> -0.99991132 | H571: =SUM(H9:H569) -> 8447136.6 | I571: =SUM(I9:I569) -> 5794673.6 | J571: =SUM(J9:J569) -> 7319587.8 | K571: =SUM(K9:K569) -> -1127548.9 | L571: =IF(H571=0,"N/A",K571/H571) -> -0.13348297

Sheet 102 - Orthopedic institutes
A1: Sales Comparison 2025 vs 2026 (Annualized) - Sale Type: 102 - Orthopedic institutes (by Product CODE)
A2: Calculation date: | B2: 46284
A3: Source: NetSuite report "1-Sales: Customer by Item" (01/01/2025-31/12/2026), Sale Type = "102 - Orthopedic institutes" only (exact match on the "Sale Type" column, per the canonical 31-value list in the source file’s "list" sheet). Product CODE = column "Item: Name" (F in the original report) - NOT "Item: Name (Grouped)" (E), which carries a PARENT prefix. 2025 = columns J/K (Quantity/Amount Net); 2026 = columns O/P. Multiple rows per CODE per Sale Type (one per unit-price tier / customer within this category) are summed (SUMIFS) per CODE, not taken from a single row. Raw rows kept unchanged in the shared "Source" sheet (filtered to only these 31 categories - built-in "Total"/"Total - <category>"/"- Unassigned -" rows excluded to avoid double-counting). IMPORTANT: the source file’s own header states the report range as "01 January 2025 - 31 December 2026", but has no per-row date/timestamp field, so the exact 2026 cutoff cannot be verified from the data itself. Same assumption used across this whole workbook family for consistency: 2026 actual covers approximately 9.5 months (1 Jan - 15 Sep).
A4: Annualization note: 2026 actual data is assumed to cover approximately 9.5 months (1 Jan - 15 Sep 2026), consistent with the rest of this workbook family. Scaled to a full year via a simple linear factor = 12 / 9.5 (≈ 1.263158) - straight-line extrapolation, does NOT account for seasonality. Treat as an estimate. | I4: Months in full year: | J4: 12 | K4: Months covered by 2026 actual (assumed 1/1–15/9): | L4: 9.5
A5: # DROP (sold 2025, 0 in 2026): | B5: =SUMPRODUCT(--(((C9:C668<>0)+(H9:H668<>0)>0)*((D9:D668=0)*(I9:I668=0)))) -> 185 | C5: # NEW (sold 2026, 0 in 2025): | D5: =SUMPRODUCT(--(((D9:D668<>0)+(I9:I668<>0)>0)*((C9:C668=0)*(H9:H668=0)))) -> 65 | I5: Normalization factor (J4/L4): | J5: =J4/L4 -> 1.2631579
A6: DROP — Quantity 2025: | B6: =SUMPRODUCT(--(((C9:C668<>0)+(H9:H668<>0)>0)*((D9:D668=0)*(I9:I668=0)))*C9:C668) -> 826 | C6: DROP — Amount 2025 (₪): | D6: =SUMPRODUCT(--(((C9:C668<>0)+(H9:H668<>0)>0)*((D9:D668=0)*(I9:I668=0)))*H9:H668) -> 59526.19 | E6: NEW — Quantity 2026: | F6: =SUMPRODUCT(--(((D9:D668<>0)+(I9:I668<>0)>0)*((C9:C668=0)*(H9:H668=0)))*D9:D668) -> 728 | G6: NEW — Amount 2026 (₪): | H6: =SUMPRODUCT(--(((D9:D668<>0)+(I9:I668<>0)>0)*((C9:C668=0)*(H9:H668=0)))*I9:I668) -> 56220.09
A8: Product Code | B8: Item Display Name | C8: Quantity 2025 | D8: Quantity 2026 (Actual, partial year) | E8: Quantity 2026 (Annualized) | F8: Quantity Change (Annualized vs 2025) | G8: Quantity Change % (Annualized vs 2025) | H8: Amount 2025 (₪) | I8: Amount 2026 (Actual, partial year) (₪) | J8: Amount 2026 (Annualized) (₪) | K8: Amount Change (Annualized vs 2025) (₪) | L8: Amount Change % (Annualized vs 2025) | M8: Note
A9: 87 M | B9: =IFERROR(INDEX('Source'!$C:$C,MATCH($A9,'Source'!$B:$B,0)),"") -> חגורת קיבוע לכתף | C9: =SUMIFS('Source'!$D:$D,'Source'!$A:$A,"102 - Orthopedic institutes",'Source'!$B:$B,$A9) -> 178 | D9: =SUMIFS('Source'!$F:$F,'Source'!$A:$A,"102 - Orthopedic institutes",'Source'!$B:$B,$A9) -> 107 | E9: =D9*$J$5 -> 135.15789 | F9: =E9-C9 -> -42.842105 | G9: =IF(AND(C9=0,E9=0),0,IF(C9=0,"New",(E9-C9)/C9)) -> -0.24068598 | H9: =SUMIFS('Source'!$E:$E,'Source'!$A:$A,"102 - Orthopedic institutes",'Source'!$B:$B,$A9) -> 24223.45 | I9: =SUMIFS('Source'!$G:$G,'Source'!$A:$A,"102 - Orthopedic institutes",'Source'!$B:$B,$A9) -> 14980.23 | J9: =I9*$J$5 -> 18922.396 | K9: =J9-H9 -> -5301.0542 | L9: =IF(AND(H9=0,J9=0),0,IF(H9=0,"New",(J9-H9)/H9)) -> -0.21883977 | M9: =IF(AND(OR(C9<>0,H9<>0),D9=0,I9=0),"DROP",IF(AND(OR(D9<>0,I9<>0),C9=0,H9=0),"NEW",""))
A10: 70N S | B10: =IFERROR(INDEX('Source'!$C:$C,MATCH($A10,'Source'!$B:$B,0)),"") -> חגורת פאבליק (רצועות אבדוקציה) | C10: =SUMIFS('Source'!$D:$D,'Source'!$A:$A,"102 - Orthopedic institutes",'Source'!$B:$B,$A10) -> 140 | D10: =SUMIFS('Source'!$F:$F,'Source'!$A:$A,"102 - Orthopedic institutes",'Source'!$B:$B,$A10) -> 169 | E10: =D10*$J$5 -> 213.47368 | F10: =E10-C10 -> 73.473684 | G10: =IF(AND(C10=0,E10=0),0,IF(C10=0,"New",(E10-C10)/C10)) -> 0.52481203 | H10: =SUMIFS('Source'!$E:$E,'Source'!$A:$A,"102 - Orthopedic institutes",'Source'!$B:$B,$A10) -> 34014.09 | I10: =SUMIFS('Source'!$G:$G,'Source'!$A:$A,"102 - Orthopedic institutes",'Source'!$B:$B,$A10) -> 42271.95 | J10: =I10*$J$5 -> 53396.147 | K10: =J10-H10 -> 19382.057 | L10: =IF(AND(H10=0,J10=0),0,IF(H10=0,"New",(J10-H10)/H10)) -> 0.56982437 | M10: =IF(AND(OR(C10<>0,H10<>0),D10=0,I10=0),"DROP",IF(AND(OR(D10<>0,I10<>0),C10=0,H10=0),"NEW",""))
A11: SH776 L | B11: =IFERROR(INDEX('Source'!$C:$C,MATCH($A11,'Source'!$B:$B,0)),"") -> SpinaShield | חגורת תיקון יציבה לעמוד שדרה וכתפיים | C11: =SUMIFS('Source'!$D:$D,'Source'!$A:$A,"102 - Orthopedic institutes",'Source'!$B:$B,$A11) -> 0 | D11: =SUMIFS('Source'!$F:$F,'Source'!$A:$A,"102 - Orthopedic institutes",'Source'!$B:$B,$A11) -> 23 | E11: =D11*$J$5 -> 29.052632 | F11: =E11-C11 -> 29.052632 | G11: =IF(AND(C11=0,E11=0),0,IF(C11=0,"New",(E11-C11)/C11)) -> New | H11: =SUMIFS('Source'!$E:$E,'Source'!$A:$A,"102 - Orthopedic institutes",'Source'!$B:$B,$A11) -> 0 | I11: =SUMIFS('Source'!$G:$G,'Source'!$A:$A,"102 - Orthopedic institutes",'Source'!$B:$B,$A11) -> 8075 | J11: =I11*$J$5 -> 10200 | K11: =J11-H11 -> 10200 | L11: =IF(AND(H11=0,J11=0),0,IF(H11=0,"New",(J11-H11)/H11)) -> New | M11: =IF(AND(OR(C11<>0,H11<>0),D11=0,I11=0),"DROP",IF(AND(OR(D11<>0,I11<>0),C11=0,H11=0),"NEW","")) -> NEW
A12: 394B-39-42 | B12: =IFERROR(INDEX('Source'!$C:$C,MATCH($A12,'Source'!$B:$B,0)),"") -> גרבי נוחות קיץ שחור | C12: =SUMIFS('Source'!$D:$D,'Source'!$A:$A,"102 - Orthopedic institutes",'Source'!$B:$B,$A12) -> 326 | D12: =SUMIFS('Source'!$F:$F,'Source'!$A:$A,"102 - Orthopedic institutes",'Source'!$B:$B,$A12) -> 7 | E12: =D12*$J$5 -> 8.8421053 | F12: =E12-C12 -> -317.15789 | G12: =IF(AND(C12=0,E12=0),0,IF(C12=0,"New",(E12-C12)/C12)) -> -0.97287698 | H12: =SUMIFS('Source'!$E:$E,'Source'!$A:$A,"102 - Orthopedic institutes",'Source'!$B:$B,$A12) -> 7739.01 | I12: =SUMIFS('Source'!$G:$G,'Source'!$A:$A,"102 - Orthopedic institutes",'Source'!$B:$B,$A12) -> 174.98 | J12: =I12*$J$5 -> 221.02737 | K12: =J12-H12 -> -7517.9826 | L12: =IF(AND(H12=0,J12=0),0,IF(H12=0,"New",(J12-H12)/H12)) -> -0.97143984 | M12: =IF(AND(OR(C12<>0,H12<>0),D12=0,I12=0),"DROP",IF(AND(OR(D12<>0,I12<>0),C12=0,H12=0),"NEW",""))
A13: 394B-43-46 | B13: =IFERROR(INDEX('Source'!$C:$C,MATCH($A13,'Source'!$B:$B,0)),"") -> גרבי נוחות קיץ שחור | C13: =SUMIFS('Source'!$D:$D,'Source'!$A:$A,"102 - Orthopedic institutes",'Source'!$B:$B,$A13) -> 374 | D13: =SUMIFS('Source'!$F:$F,'Source'!$A:$A,"102 - Orthopedic institutes",'Source'!$B:$B,$A13) -> 54 | E13: =D13*$J$5 -> 68.210526 | F13: =E13-C13 -> -305.78947 | G13: =IF(AND(C13=0,E13=0),0,IF(C13=0,"New",(E13-C13)/C13)) -> -0.81761891 | H13: =SUMIFS('Source'!$E:$E,'Source'!$A:$A,"102 - Orthopedic institutes",'Source'!$B:$B,$A13) -> 8728.94 | I13: =SUMIFS('Source'!$G:$G,'Source'!$A:$A,"102 - Orthopedic institutes",'Source'!$B:$B,$A13) -> 1349.68 | J13: =I13*$J$5 -> 1704.8589 | K13: =J13-H13 -> -7024.0811 | L13: =IF(AND(H13=0,J13=0),0,IF(H13=0,"New",(J13-H13)/H13)) -> -0.80468889 | M13: =IF(AND(OR(C13<>0,H13<>0),D13=0,I13=0),"DROP",IF(AND(OR(D13<>0,I13<>0),C13=0,H13=0),"NEW",""))
A14: 395B-43-46 | B14: =IFERROR(INDEX('Source'!$C:$C,MATCH($A14,'Source'!$B:$B,0)),"") -> גרבי קיץ אנטיבקטריאלי שחור | C14: =SUMIFS('Source'!$D:$D,'Source'!$A:$A,"102 - Orthopedic institutes",'Source'!$B:$B,$A14) -> 0 | D14: =SUMIFS('Source'!$F:$F,'Source'!$A:$A,"102 - Orthopedic institutes",'Source'!$B:$B,$A14) -> 237 | E14: =D14*$J$5 -> 299.36842 | F14: =E14-C14 -> 299.36842 | G14: =IF(AND(C14=0,E14=0),0,IF(C14=0,"New",(E14-C14)/C14)) -> New | H14: =SUMIFS('Source'!$E:$E,'Source'!$A:$A,"102 - Orthopedic institutes",'Source'!$B:$B,$A14) -> 0 | I14: =SUMIFS('Source'!$G:$G,'Source'!$A:$A,"102 - Orthopedic institutes",'Source'!$B:$B,$A14) -> 6903.62 | J14: =I14*$J$5 -> 8720.3621 | K14: =J14-H14 -> 8720.3621 | L14: =IF(AND(H14=0,J14=0),0,IF(H14=0,"New",(J14-H14)/H14)) -> New | M14: =IF(AND(OR(C14<>0,H14<>0),D14=0,I14=0),"DROP",IF(AND(OR(D14<>0,I14<>0),C14=0,H14=0),"NEW","")) -> NEW
A15: SH776 XL | B15: =IFERROR(INDEX('Source'!$C:$C,MATCH($A15,'Source'!$B:$B,0)),"") -> SpinaShield | חגורת תיקון יציבה לעמוד שדרה וכתפיים | C15: =SUMIFS('Source'!$D:$D,'Source'!$A:$A,"102 - Orthopedic institutes",'Source'!$B:$B,$A15) -> 0 | D15: =SUMIFS('Source'!$F:$F,'Source'!$A:$A,"102 - Orthopedic institutes",'Source'!$B:$B,$A15) -> 19 | E15: =D15*$J$5 -> 24 | F15: =E15-C15 -> 24 | G15: =IF(AND(C15=0,E15=0),0,IF(C15=0,"New",(E15-C15)/C15)) -> New | H15: =SUMIFS('Source'!$E:$E,'Source'!$A:$A,"102 - Orthopedic institutes",'Source'!$B:$B,$A15) -> 0 | I15: =SUMIFS('Source'!$G:$G,'Source'!$A:$A,"102 - Orthopedic institutes",'Source'!$B:$B,$A15) -> 6650.03 | J15: =I15*$J$5 -> 8400.0379 | K15: =J15-H15 -> 8400.0379 | L15: =IF(AND(H15=0,J15=0),0,IF(H15=0,"New",(J15-H15)/H15)) -> New | M15: =IF(AND(OR(C15<>0,H15<>0),D15=0,I15=0),"DROP",IF(AND(OR(D15<>0,I15<>0),C15=0,H15=0),"NEW","")) -> NEW
