Workbook

Sheet השוואה כוללת
A1: השוואה כוללת - מכירות ינואר-אוגוסט, 2025 מול 2026
A2: תאריך חישוב: | B2: 46243
A3: מקורות: month-01.xlsx עד month-08.xlsx (ינואר-אוגוסט 2026 מול אותם חודשים ב-2025), kirill/reference/2026-sales-comparison/
A5: קוד SKU | B5: שם מוצר | C5: יחידות ינואר-יולי 2025 | D5: יחידות ינואר-יולי 2026 | E5: הפרש (יחידות) | F5: שינוי %
A6: 8616 | B6: URI 3623 1 כרית ליישור אצבע | C6: =SUMIF('מקור-01'!$A:$A,$A6,'מקור-01'!$C:$C)+SUMIF('מקור-02'!$A:$A,$A6,'מקור-02'!$C:$C)+SUMIF('מקור-03'!$A:$A,$A6,'מקור-03'!$C:$C)+SUMIF('מקור-04'!$A:$A,$A6,'מקור-04'!$C:$C)+SUMIF('מקור-05'!$A:$A,$A6,'מקור-05'!$C:$C)+SUMIF('מקור-06'!$A:$A,$A6,'מקור-06'!$C:$C)+SUMIF('מקור-07'!$A:$A,$A6,'מקור-07'!$C:$C)+SUMIF('מקור-08'!$A:$A,$A6,'מקור-08'!$C:$C) -> 100 | D6: =SUMIF('מקור-01'!$A:$A,$A6,'מקור-01'!$D:$D)+SUMIF('מקור-02'!$A:$A,$A6,'מקור-02'!$D:$D)+SUMIF('מקור-03'!$A:$A,$A6,'מקור-03'!$D:$D)+SUMIF('מקור-04'!$A:$A,$A6,'מקור-04'!$D:$D)+SUMIF('מקור-05'!$A:$A,$A6,'מקור-05'!$D:$D)+SUMIF('מקור-06'!$A:$A,$A6,'מקור-06'!$D:$D)+SUMIF('מקור-07'!$A:$A,$A6,'מקור-07'!$D:$D)+SUMIF('מקור-08'!$A:$A,$A6,'מקור-08'!$D:$D) -> 109 | E6: =D6-C6 -> 9 | F6: =IF(C6=0,"מוצר חדש",(D6-C6)/C6) -> 0.09
A7: 8618 | B7: URI 311 1 מדבקת ג'ל | C7: =SUMIF('מקור-01'!$A:$A,$A7,'מקור-01'!$C:$C)+SUMIF('מקור-02'!$A:$A,$A7,'מקור-02'!$C:$C)+SUMIF('מקור-03'!$A:$A,$A7,'מקור-03'!$C:$C)+SUMIF('מקור-04'!$A:$A,$A7,'מקור-04'!$C:$C)+SUMIF('מקור-05'!$A:$A,$A7,'מקור-05'!$C:$C)+SUMIF('מקור-06'!$A:$A,$A7,'מקור-06'!$C:$C)+SUMIF('מקור-07'!$A:$A,$A7,'מקור-07'!$C:$C)+SUMIF('מקור-08'!$A:$A,$A7,'מקור-08'!$C:$C) -> 151 | D7: =SUMIF('מקור-01'!$A:$A,$A7,'מקור-01'!$D:$D)+SUMIF('מקור-02'!$A:$A,$A7,'מקור-02'!$D:$D)+SUMIF('מקור-03'!$A:$A,$A7,'מקור-03'!$D:$D)+SUMIF('מקור-04'!$A:$A,$A7,'מקור-04'!$D:$D)+SUMIF('מקור-05'!$A:$A,$A7,'מקור-05'!$D:$D)+SUMIF('מקור-06'!$A:$A,$A7,'מקור-06'!$D:$D)+SUMIF('מקור-07'!$A:$A,$A7,'מקור-07'!$D:$D)+SUMIF('מקור-08'!$A:$A,$A7,'מקור-08'!$D:$D) -> 150 | E7: =D7-C7 -> -1 | F7: =IF(C7=0,"מוצר חדש",(D7-C7)/C7) -> -0.0066225166
A8: 9771 | B8: URI 307 M 1 זוג עקב סיל+נ כ | C8: =SUMIF('מקור-01'!$A:$A,$A8,'מקור-01'!$C:$C)+SUMIF('מקור-02'!$A:$A,$A8,'מקור-02'!$C:$C)+SUMIF('מקור-03'!$A:$A,$A8,'מקור-03'!$C:$C)+SUMIF('מקור-04'!$A:$A,$A8,'מקור-04'!$C:$C)+SUMIF('מקור-05'!$A:$A,$A8,'מקור-05'!$C:$C)+SUMIF('מקור-06'!$A:$A,$A8,'מקור-06'!$C:$C)+SUMIF('מקור-07'!$A:$A,$A8,'מקור-07'!$C:$C)+SUMIF('מקור-08'!$A:$A,$A8,'מקור-08'!$C:$C) -> 157 | D8: =SUMIF('מקור-01'!$A:$A,$A8,'מקור-01'!$D:$D)+SUMIF('מקור-02'!$A:$A,$A8,'מקור-02'!$D:$D)+SUMIF('מקור-03'!$A:$A,$A8,'מקור-03'!$D:$D)+SUMIF('מקור-04'!$A:$A,$A8,'מקור-04'!$D:$D)+SUMIF('מקור-05'!$A:$A,$A8,'מקור-05'!$D:$D)+SUMIF('מקור-06'!$A:$A,$A8,'מקור-06'!$D:$D)+SUMIF('מקור-07'!$A:$A,$A8,'מקור-07'!$D:$D)+SUMIF('מקור-08'!$A:$A,$A8,'מקור-08'!$D:$D) -> 165 | E8: =D8-C8 -> 8 | F8: =IF(C8=0,"מוצר חדש",(D8-C8)/C8) -> 0.050955414
A9: 9772 | B9: URI 307 L 1 זוג עקב סיל+נ כ | C9: =SUMIF('מקור-01'!$A:$A,$A9,'מקור-01'!$C:$C)+SUMIF('מקור-02'!$A:$A,$A9,'מקור-02'!$C:$C)+SUMIF('מקור-03'!$A:$A,$A9,'מקור-03'!$C:$C)+SUMIF('מקור-04'!$A:$A,$A9,'מקור-04'!$C:$C)+SUMIF('מקור-05'!$A:$A,$A9,'מקור-05'!$C:$C)+SUMIF('מקור-06'!$A:$A,$A9,'מקור-06'!$C:$C)+SUMIF('מקור-07'!$A:$A,$A9,'מקור-07'!$C:$C)+SUMIF('מקור-08'!$A:$A,$A9,'מקור-08'!$C:$C) -> 164 | D9: =SUMIF('מקור-01'!$A:$A,$A9,'מקור-01'!$D:$D)+SUMIF('מקור-02'!$A:$A,$A9,'מקור-02'!$D:$D)+SUMIF('מקור-03'!$A:$A,$A9,'מקור-03'!$D:$D)+SUMIF('מקור-04'!$A:$A,$A9,'מקור-04'!$D:$D)+SUMIF('מקור-05'!$A:$A,$A9,'מקור-05'!$D:$D)+SUMIF('מקור-06'!$A:$A,$A9,'מקור-06'!$D:$D)+SUMIF('מקור-07'!$A:$A,$A9,'מקור-07'!$D:$D)+SUMIF('מקור-08'!$A:$A,$A9,'מקור-08'!$D:$D) -> 156 | E9: =D9-C9 -> -8 | F9: =IF(C9=0,"מוצר חדש",(D9-C9)/C9) -> -0.048780488
A10: 16211 | B10: 394B-35-381 גרבי קיץ לסוכרת | C10: =SUMIF('מקור-01'!$A:$A,$A10,'מקור-01'!$C:$C)+SUMIF('מקור-02'!$A:$A,$A10,'מקור-02'!$C:$C)+SUMIF('מקור-03'!$A:$A,$A10,'מקור-03'!$C:$C)+SUMIF('מקור-04'!$A:$A,$A10,'מקור-04'!$C:$C)+SUMIF('מקור-05'!$A:$A,$A10,'מקור-05'!$C:$C)+SUMIF('מקור-06'!$A:$A,$A10,'מקור-06'!$C:$C)+SUMIF('מקור-07'!$A:$A,$A10,'מקור-07'!$C:$C)+SUMIF('מקור-08'!$A:$A,$A10,'מקור-08'!$C:$C) -> 41 | D10: =SUMIF('מקור-01'!$A:$A,$A10,'מקור-01'!$D:$D)+SUMIF('מקור-02'!$A:$A,$A10,'מקור-02'!$D:$D)+SUMIF('מקור-03'!$A:$A,$A10,'מקור-03'!$D:$D)+SUMIF('מקור-04'!$A:$A,$A10,'מקור-04'!$D:$D)+SUMIF('מקור-05'!$A:$A,$A10,'מקור-05'!$D:$D)+SUMIF('מקור-06'!$A:$A,$A10,'מקור-06'!$D:$D)+SUMIF('מקור-07'!$A:$A,$A10,'מקור-07'!$D:$D)+SUMIF('מקור-08'!$A:$A,$A10,'מקור-08'!$D:$D) -> 35 | E10: =D10-C10 -> -6 | F10: =IF(C10=0,"מוצר חדש",(D10-C10)/C10) -> -0.14634146
A11: 16212 | B11: 394B-39-421 גרבי קיץ לסוכרת | C11: =SUMIF('מקור-01'!$A:$A,$A11,'מקור-01'!$C:$C)+SUMIF('מקור-02'!$A:$A,$A11,'מקור-02'!$C:$C)+SUMIF('מקור-03'!$A:$A,$A11,'מקור-03'!$C:$C)+SUMIF('מקור-04'!$A:$A,$A11,'מקור-04'!$C:$C)+SUMIF('מקור-05'!$A:$A,$A11,'מקור-05'!$C:$C)+SUMIF('מקור-06'!$A:$A,$A11,'מקור-06'!$C:$C)+SUMIF('מקור-07'!$A:$A,$A11,'מקור-07'!$C:$C)+SUMIF('מקור-08'!$A:$A,$A11,'מקור-08'!$C:$C) -> 107 | D11: =SUMIF('מקור-01'!$A:$A,$A11,'מקור-01'!$D:$D)+SUMIF('מקור-02'!$A:$A,$A11,'מקור-02'!$D:$D)+SUMIF('מקור-03'!$A:$A,$A11,'מקור-03'!$D:$D)+SUMIF('מקור-04'!$A:$A,$A11,'מקור-04'!$D:$D)+SUMIF('מקור-05'!$A:$A,$A11,'מקור-05'!$D:$D)+SUMIF('מקור-06'!$A:$A,$A11,'מקור-06'!$D:$D)+SUMIF('מקור-07'!$A:$A,$A11,'מקור-07'!$D:$D)+SUMIF('מקור-08'!$A:$A,$A11,'מקור-08'!$D:$D) -> 55 | E11: =D11-C11 -> -52 | F11: =IF(C11=0,"מוצר חדש",(D11-C11)/C11) -> -0.48598131
A12: 16213 | B12: 394B-43-461 גרבי קיץ לסוכרת | C12: =SUMIF('מקור-01'!$A:$A,$A12,'מקור-01'!$C:$C)+SUMIF('מקור-02'!$A:$A,$A12,'מקור-02'!$C:$C)+SUMIF('מקור-03'!$A:$A,$A12,'מקור-03'!$C:$C)+SUMIF('מקור-04'!$A:$A,$A12,'מקור-04'!$C:$C)+SUMIF('מקור-05'!$A:$A,$A12,'מקור-05'!$C:$C)+SUMIF('מקור-06'!$A:$A,$A12,'מקור-06'!$C:$C)+SUMIF('מקור-07'!$A:$A,$A12,'מקור-07'!$C:$C)+SUMIF('מקור-08'!$A:$A,$A12,'מקור-08'!$C:$C) -> 131 | D12: =SUMIF('מקור-01'!$A:$A,$A12,'מקור-01'!$D:$D)+SUMIF('מקור-02'!$A:$A,$A12,'מקור-02'!$D:$D)+SUMIF('מקור-03'!$A:$A,$A12,'מקור-03'!$D:$D)+SUMIF('מקור-04'!$A:$A,$A12,'מקור-04'!$D:$D)+SUMIF('מקור-05'!$A:$A,$A12,'מקור-05'!$D:$D)+SUMIF('מקור-06'!$A:$A,$A12,'מקור-06'!$D:$D)+SUMIF('מקור-07'!$A:$A,$A12,'מקור-07'!$D:$D)+SUMIF('מקור-08'!$A:$A,$A12,'מקור-08'!$D:$D) -> 87 | E12: =D12-C12 -> -44 | F12: =IF(C12=0,"מוצר חדש",(D12-C12)/C12) -> -0.33587786
A13: 16214 | B13: 394-G-35-31 גרבי קיץ לסוכרת | C13: =SUMIF('מקור-01'!$A:$A,$A13,'מקור-01'!$C:$C)+SUMIF('מקור-02'!$A:$A,$A13,'מקור-02'!$C:$C)+SUMIF('מקור-03'!$A:$A,$A13,'מקור-03'!$C:$C)+SUMIF('מקור-04'!$A:$A,$A13,'מקור-04'!$C:$C)+SUMIF('מקור-05'!$A:$A,$A13,'מקור-05'!$C:$C)+SUMIF('מקור-06'!$A:$A,$A13,'מקור-06'!$C:$C)+SUMIF('מקור-07'!$A:$A,$A13,'מקור-07'!$C:$C)+SUMIF('מקור-08'!$A:$A,$A13,'מקור-08'!$C:$C) -> 20 | D13: =SUMIF('מקור-01'!$A:$A,$A13,'מקור-01'!$D:$D)+SUMIF('מקור-02'!$A:$A,$A13,'מקור-02'!$D:$D)+SUMIF('מקור-03'!$A:$A,$A13,'מקור-03'!$D:$D)+SUMIF('מקור-04'!$A:$A,$A13,'מקור-04'!$D:$D)+SUMIF('מקור-05'!$A:$A,$A13,'מקור-05'!$D:$D)+SUMIF('מקור-06'!$A:$A,$A13,'מקור-06'!$D:$D)+SUMIF('מקור-07'!$A:$A,$A13,'מקור-07'!$D:$D)+SUMIF('מקור-08'!$A:$A,$A13,'מקור-08'!$D:$D) -> 19 | E13: =D13-C13 -> -1 | F13: =IF(C13=0,"מוצר חדש",(D13-C13)/C13) -> -0.05
A14: 16217 | B14: 394G-39-421 גרבי קיץ לסוכרת | C14: =SUMIF('מקור-01'!$A:$A,$A14,'מקור-01'!$C:$C)+SUMIF('מקור-02'!$A:$A,$A14,'מקור-02'!$C:$C)+SUMIF('מקור-03'!$A:$A,$A14,'מקור-03'!$C:$C)+SUMIF('מקור-04'!$A:$A,$A14,'מקור-04'!$C:$C)+SUMIF('מקור-05'!$A:$A,$A14,'מקור-05'!$C:$C)+SUMIF('מקור-06'!$A:$A,$A14,'מקור-06'!$C:$C)+SUMIF('מקור-07'!$A:$A,$A14,'מקור-07'!$C:$C)+SUMIF('מקור-08'!$A:$A,$A14,'מקור-08'!$C:$C) -> 33 | D14: =SUMIF('מקור-01'!$A:$A,$A14,'מקור-01'!$D:$D)+SUMIF('מקור-02'!$A:$A,$A14,'מקור-02'!$D:$D)+SUMIF('מקור-03'!$A:$A,$A14,'מקור-03'!$D:$D)+SUMIF('מקור-04'!$A:$A,$A14,'מקור-04'!$D:$D)+SUMIF('מקור-05'!$A:$A,$A14,'מקור-05'!$D:$D)+SUMIF('מקור-06'!$A:$A,$A14,'מקור-06'!$D:$D)+SUMIF('מקור-07'!$A:$A,$A14,'מקור-07'!$D:$D)+SUMIF('מקור-08'!$A:$A,$A14,'מקור-08'!$D:$D) -> 18 | E14: =D14-C14 -> -15 | F14: =IF(C14=0,"מוצר חדש",(D14-C14)/C14) -> -0.45454545
A15: 16237 | B15: 394G-43-461 גרבי קיץ לסוכרת | C15: =SUMIF('מקור-01'!$A:$A,$A15,'מקור-01'!$C:$C)+SUMIF('מקור-02'!$A:$A,$A15,'מקור-02'!$C:$C)+SUMIF('מקור-03'!$A:$A,$A15,'מקור-03'!$C:$C)+SUMIF('מקור-04'!$A:$A,$A15,'מקור-04'!$C:$C)+SUMIF('מקור-05'!$A:$A,$A15,'מקור-05'!$C:$C)+SUMIF('מקור-06'!$A:$A,$A15,'מקור-06'!$C:$C)+SUMIF('מקור-07'!$A:$A,$A15,'מקור-07'!$C:$C)+SUMIF('מקור-08'!$A:$A,$A15,'מקור-08'!$C:$C) -> 36 | D15: =SUMIF('מקור-01'!$A:$A,$A15,'מקור-01'!$D:$D)+SUMIF('מקור-02'!$A:$A,$A15,'מקור-02'!$D:$D)+SUMIF('מקור-03'!$A:$A,$A15,'מקור-03'!$D:$D)+SUMIF('מקור-04'!$A:$A,$A15,'מקור-04'!$D:$D)+SUMIF('מקור-05'!$A:$A,$A15,'מקור-05'!$D:$D)+SUMIF('מקור-06'!$A:$A,$A15,'מקור-06'!$D:$D)+SUMIF('מקור-07'!$A:$A,$A15,'מקור-07'!$D:$D)+SUMIF('מקור-08'!$A:$A,$A15,'מקור-08'!$D:$D) -> 10 | E15: =D15-C15 -> -26 | F15: =IF(C15=0,"מוצר חדש",(D15-C15)/C15) -> -0.72222222
A16: 16239 | B16: 394W-35-381 גרבי קיץ לסוכרת | C16: =SUMIF('מקור-01'!$A:$A,$A16,'מקור-01'!$C:$C)+SUMIF('מקור-02'!$A:$A,$A16,'מקור-02'!$C:$C)+SUMIF('מקור-03'!$A:$A,$A16,'מקור-03'!$C:$C)+SUMIF('מקור-04'!$A:$A,$A16,'מקור-04'!$C:$C)+SUMIF('מקור-05'!$A:$A,$A16,'מקור-05'!$C:$C)+SUMIF('מקור-06'!$A:$A,$A16,'מקור-06'!$C:$C)+SUMIF('מקור-07'!$A:$A,$A16,'מקור-07'!$C:$C)+SUMIF('מקור-08'!$A:$A,$A16,'מקור-08'!$C:$C) -> 30 | D16: =SUMIF('מקור-01'!$A:$A,$A16,'מקור-01'!$D:$D)+SUMIF('מקור-02'!$A:$A,$A16,'מקור-02'!$D:$D)+SUMIF('מקור-03'!$A:$A,$A16,'מקור-03'!$D:$D)+SUMIF('מקור-04'!$A:$A,$A16,'מקור-04'!$D:$D)+SUMIF('מקור-05'!$A:$A,$A16,'מקור-05'!$D:$D)+SUMIF('מקור-06'!$A:$A,$A16,'מקור-06'!$D:$D)+SUMIF('מקור-07'!$A:$A,$A16,'מקור-07'!$D:$D)+SUMIF('מקור-08'!$A:$A,$A16,'מקור-08'!$D:$D) -> 18 | E16: =D16-C16 -> -12 | F16: =IF(C16=0,"מוצר חדש",(D16-C16)/C16) -> -0.4
A17: 16244 | B17: 394W-39-421 גרבי קיץ לסוכרת | C17: =SUMIF('מקור-01'!$A:$A,$A17,'מקור-01'!$C:$C)+SUMIF('מקור-02'!$A:$A,$A17,'מקור-02'!$C:$C)+SUMIF('מקור-03'!$A:$A,$A17,'מקור-03'!$C:$C)+SUMIF('מקור-04'!$A:$A,$A17,'מקור-04'!$C:$C)+SUMIF('מקור-05'!$A:$A,$A17,'מקור-05'!$C:$C)+SUMIF('מקור-06'!$A:$A,$A17,'מקור-06'!$C:$C)+SUMIF('מקור-07'!$A:$A,$A17,'מקור-07'!$C:$C)+SUMIF('מקור-08'!$A:$A,$A17,'מקור-08'!$C:$C) -> 31 | D17: =SUMIF('מקור-01'!$A:$A,$A17,'מקור-01'!$D:$D)+SUMIF('מקור-02'!$A:$A,$A17,'מקור-02'!$D:$D)+SUMIF('מקור-03'!$A:$A,$A17,'מקור-03'!$D:$D)+SUMIF('מקור-04'!$A:$A,$A17,'מקור-04'!$D:$D)+SUMIF('מקור-05'!$A:$A,$A17,'מקור-05'!$D:$D)+SUMIF('מקור-06'!$A:$A,$A17,'מקור-06'!$D:$D)+SUMIF('מקור-07'!$A:$A,$A17,'מקור-07'!$D:$D)+SUMIF('מקור-08'!$A:$A,$A17,'מקור-08'!$D:$D) -> 26 | E17: =D17-C17 -> -5 | F17: =IF(C17=0,"מוצר חדש",(D17-C17)/C17) -> -0.16129032
... A239: 43469 | B239: SH422 6 1 תומך ברך גנושילד | C239: =SUMIF('מקור-01'!$A:$A,$A239,'מקור-01'!$C:$C)+SUMIF('מקור-02'!$A:$A,$A239,'מקור-02'!$C:$C)+SUMIF('מקור-03'!$A:$A,$A239,'מקור-03'!$C:$C)+SUMIF('מקור-04'!$A:$A,$A239,'מקור-04'!$C:$C)+SUMIF('מקור-05'!$A:$A,$A239,'מקור-05'!$C:$C)+SUMIF('מקור-06'!$A:$A,$A239,'מקור-06'!$C:$C)+SUMIF('מקור-07'!$A:$A,$A239,'מקור-07'!$C:$C)+SUMIF('מקור-08'!$A:$A,$A239,'מקור-08'!$C:$C) -> 0 | D239: =SUMIF('מקור-01'!$A:$A,$A239,'מקור-01'!$D:$D)+SUMIF('מקור-02'!$A:$A,$A239,'מקור-02'!$D:$D)+SUMIF('מקור-03'!$A:$A,$A239,'מקור-03'!$D:$D)+SUMIF('מקור-04'!$A:$A,$A239,'מקור-04'!$D:$D)+SUMIF('מקור-05'!$A:$A,$A239,'מקור-05'!$D:$D)+SUMIF('מקור-06'!$A:$A,$A239,'מקור-06'!$D:$D)+SUMIF('מקור-07'!$A:$A,$A239,'מקור-07'!$D:$D)+SUMIF('מקור-08'!$A:$A,$A239,'מקור-08'!$D:$D) -> 1 | E239: =D239-C239 -> 1 | F239: =IF(C239=0,"מוצר חדש",(D239-C239)/C239) -> מוצר חדש
A240: סה"כ כללי | C240: =SUM(C6:C239) -> 16642 | D240: =SUM(D6:D239) -> 17314 | E240: =D240-C240 -> 672 | F240: =IF(C240=0,"",(D240-C240)/C240) -> 0.040379762

Sheet סה"כ לפי חודש
B1: סה"כ יחידות לפי חודש - 2025 מול 2026 (ינואר-אוגוסט)
B2: תאריך חישוב: | C2: ='השוואה כוללת'!B2 -> 46243
B3: מקורות: מקור-01 עד מקור-08 (ינואר-אוגוסט 2026 מול אותם חודשים ב-2025)
B5: חודש | C5: יחידות 2025 | D5: יחידות 2026 | E5: הפרש (יחידות) | F5: שינוי %
B6: ינואר | C6: =SUM('מקור-01'!$C$3:$C$191) -> 2241 | D6: =SUM('מקור-01'!$D$3:$D$191) -> 2119 | E6: =D6-C6 -> -122 | F6: =IF(C6=0,"",(D6-C6)/C6) -> -0.054439982
B7: פברואר | C7: =SUM('מקור-02'!$C$3:$C$185) -> 1942 | D7: =SUM('מקור-02'!$D$3:$D$185) -> 2203 | E7: =D7-C7 -> 261 | F7: =IF(C7=0,"",(D7-C7)/C7) -> 0.13439753
B8: מרץ | C8: =SUM('מקור-03'!$C$3:$C$191) -> 2063 | D8: =SUM('מקור-03'!$D$3:$D$191) -> 1781 | E8: =D8-C8 -> -282 | F8: =IF(C8=0,"",(D8-C8)/C8) -> -0.13669413
B9: אפריל | C9: =SUM('מקור-04'!$C$3:$C$181) -> 2021 | D9: =SUM('מקור-04'!$D$3:$D$181) -> 2002 | E9: =D9-C9 -> -19 | F9: =IF(C9=0,"",(D9-C9)/C9) -> -0.0094012865
B10: מאי | C10: =SUM('מקור-05'!$C$3:$C$192) -> 2249 | D10: =SUM('מקור-05'!$D$3:$D$192) -> 2321 | E10: =D10-C10 -> 72 | F10: =IF(C10=0,"",(D10-C10)/C10) -> 0.032014229
B11: יוני | C11: =SUM('מקור-06'!$C$3:$C$185) -> 1924 | D11: =SUM('מקור-06'!$D$3:$D$185) -> 2374 | E11: =D11-C11 -> 450 | F11: =IF(C11=0,"",(D11-C11)/C11) -> 0.23388773
B12: יולי | C12: =SUM('מקור-07'!$C$3:$C$200) -> 2261 | D12: =SUM('מקור-07'!$D$3:$D$200) -> 2315 | E12: =D12-C12 -> 54 | F12: =IF(C12=0,"",(D12-C12)/C12) -> 0.023883238
B13: אוגוסט | C13: =SUM('מקור-08'!$C$3:$C$193) -> 1941 | D13: =SUM('מקור-08'!$D$3:$D$193) -> 2199 | E13: =D13-C13 -> 258 | F13: =IF(C13=0,"",(D13-C13)/C13) -> 0.13292117
B14: סה"כ כללי | C14: =SUM(C6:C13) -> 16642 | D14: =SUM(D6:D13) -> 17314 | E14: =D14-C14 -> 672 | F14: =IF(C14=0,"",(D14-C14)/C14) -> 0.040379762

Sheet הכי נמכרים 2025
A1: הכי נמכרים 2025 - Top 20 לפי יחידות ינואר-אוגוסט 2025 (עם השוואה ל-2026)
A3: # | B3: קוד SKU | C3: שם מוצר | D3: יחידות ינואר-אוגוסט 2025 | E3: יחידות ינואר-אוגוסט 2026
A4: 1 | B4: ='השוואה כוללת'!A65 -> 51567 | C4: ='השוואה כוללת'!B65 -> 1 סד יד דו צדדי | D4: ='השוואה כוללת'!C65 -> 1085 | E4: ='השוואה כוללת'!D65 -> 1104
A5: 2 | B5: ='השוואה כוללת'!A213 -> 83668 | C5: ='השוואה כוללת'!B213 -> URI FC335 1 טלק לכף הרגל | D5: ='השוואה כוללת'!C213 -> 841 | E5: ='השוואה כוללת'!D213 -> 549
A6: 3 | B6: ='השוואה כוללת'!A150 -> 71204 | C6: ='השוואה כוללת'!B150 -> URI 3655 1 שרוול מסיליקון | D6: ='השוואה כוללת'!C150 -> 733 | E6: ='השוואה כוללת'!D150 -> 631
A7: 4 | B7: ='השוואה כוללת'!A84 -> 59679 | C7: ='השוואה כוללת'!B84 -> URI 364 S M 1 | D7: ='השוואה כוללת'!C84 -> 442 | E7: ='השוואה כוללת'!D84 -> 359
A8: 5 | B8: ='השוואה כוללת'!A98 -> 63360 | C8: ='השוואה כוללת'!B98 -> URI 45 L 1 מגן ברךBOX | D8: ='השוואה כוללת'!C98 -> 374 | E8: ='השוואה כוללת'!D98 -> 372
A9: 6 | B9: ='השוואה כוללת'!A30 -> 24612 | C9: ='השוואה כוללת'!B30 -> URI AC28 1 סד לאגודל | D9: ='השוואה כוללת'!C30 -> 363 | E9: ='השוואה כוללת'!D30 -> 286
A10: 7 | B10: ='השוואה כוללת'!A45 -> 31188 | C10: ='השוואה כוללת'!B45 -> URI 372 1 רפידת אנטי ריח | D10: ='השוואה כוללת'!C45 -> 359 | E10: ='השוואה כוללת'!D45 -> 352
A11: 8 | B11: ='השוואה כוללת'!A66 -> 51568 | C11: ='השוואה כוללת'!B66 -> 1 סד לאגודל | D11: ='השוואה כוללת'!C66 -> 347 | E11: ='השוואה כוללת'!D66 -> 472
A12: 9 | B12: ='השוואה כוללת'!A97 -> 63359 | C12: ='השוואה כוללת'!B97 -> URI 45 M 1 מגן ברך | D12: ='השוואה כוללת'!C97 -> 311 | E12: ='השוואה כוללת'!D97 -> 297
A13: 10 | B13: ='השוואה כוללת'!A162 -> 74709 | C13: ='השוואה כוללת'!B162 -> URI 21 M 1 חבק יד ארוך | D13: ='השוואה כוללת'!C162 -> 274 | E13: ='השוואה כוללת'!D162 -> 252
A14: 11 | B14: ='השוואה כוללת'!A87 -> 60472 | C14: ='השוואה כוללת'!B87 -> URI PD340 1 קוצץ ציפורניים | D14: ='השוואה כוללת'!C87 -> 266 | E14: ='השוואה כוללת'!D87 -> 350
A15: 12 | B15: ='השוואה כוללת'!A85 -> 59694 | C15: ='השוואה כוללת'!B85 -> URI 365 S-L 1 טבעת אלסטית | D15: ='השוואה כוללת'!C85 -> 258 | E15: ='השוואה כוללת'!D85 -> 240
A16: 13 | B16: ='השוואה כוללת'!A135 -> 67385 | C16: ='השוואה כוללת'!B135 -> URI 302M 0 1 מדרס ג'ל לגבר | D16: ='השוואה כוללת'!C135 -> 256 | E16: ='השוואה כוללת'!D135 -> 119
A17: 14 | B17: ='השוואה כוללת'!A167 -> 74799 | C17: ='השוואה כוללת'!B167 -> URI 45E L1 מגן ברך ארוך לבן | D17: ='השוואה כוללת'!C167 -> 244 | E17: ='השוואה כוללת'!D167 -> 237
A18: 15 | B18: ='השוואה כוללת'!A131 -> 66745 | C18: ='השוואה כוללת'!B131 -> 1 תרסיס דיאו.אנטי בקטר.לנעל | D18: ='השוואה כוללת'!C131 -> 235 | E18: ='השוואה כוללת'!D131 -> 336
A19: 16 | B19: ='השוואה כוללת'!A99 -> 63361 | C19: ='השוואה כוללת'!B99 -> URI 45 XL 1 מגן ברך | D19: ='השוואה כוללת'!C99 -> 226 | E19: ='השוואה כוללת'!D99 -> 217
A20: 17 | B20: ='השוואה כוללת'!A168 -> 74800 | C20: ='השוואה כוללת'!B168 -> URI 45E M 1 מגן ברך ארוך | D20: ='השוואה כוללת'!C168 -> 222 | E20: ='השוואה כוללת'!D168 -> 192
A21: 18 | B21: ='השוואה כוללת'!A44 -> 31183 | C21: ='השוואה כוללת'!B44 -> URI 370 1 רפידת נוחות | D21: ='השוואה כוללת'!C44 -> 219 | E21: ='השוואה כוללת'!D44 -> 221
A22: 19 | B22: ='השוואה כוללת'!A108 -> 63415 | C22: ='השוואה כוללת'!B108 -> URI 85 L 1 מתלה ליד | D22: ='השוואה כוללת'!C108 -> 214 | E22: ='השוואה כוללת'!D108 -> 241
A23: 20 | B23: ='השוואה כוללת'!A29 -> 23008 | C23: ='השוואה כוללת'!B29 -> URI 364 XL 1 | D23: ='השוואה כוללת'!C29 -> 212 | E23: ='השוואה כוללת'!D29 -> 246

Sheet הכי נמכרים 2026
A1: הכי נמכרים 2026 - Top 20 לפי יחידות ינואר-אוגוסט 2026 (עם השוואה ל-2025)
A3: # | B3: קוד SKU | C3: שם מוצר | D3: יחידות ינואר-אוגוסט 2025 | E3: יחידות ינואר-אוגוסט 2026
A4: 1 | B4: ='השוואה כוללת'!A65 -> 51567 | C4: ='השוואה כוללת'!B65 -> 1 סד יד דו צדדי | D4: ='השוואה כוללת'!C65 -> 1085 | E4: ='השוואה כוללת'!D65 -> 1104
A5: 2 | B5: ='השוואה כוללת'!A150 -> 71204 | C5: ='השוואה כוללת'!B150 -> URI 3655 1 שרוול מסיליקון | D5: ='השוואה כוללת'!C150 -> 733 | E5: ='השוואה כוללת'!D150 -> 631
A6: 3 | B6: ='השוואה כוללת'!A213 -> 83668 | C6: ='השוואה כוללת'!B213 -> URI FC335 1 טלק לכף הרגל | D6: ='השוואה כוללת'!C213 -> 841 | E6: ='השוואה כוללת'!D213 -> 549
A7: 4 | B7: ='השוואה כוללת'!A207 -> 82206 | C7: ='השוואה כוללת'!B207 -> ST25 1 חבק לשורש כף היד | D7: ='השוואה כוללת'!C207 -> 138 | E7: ='השוואה כוללת'!D207 -> 498
A8: 5 | B8: ='השוואה כוללת'!A66 -> 51568 | C8: ='השוואה כוללת'!B66 -> 1 סד לאגודל | D8: ='השוואה כוללת'!C66 -> 347 | E8: ='השוואה כוללת'!D66 -> 472
A9: 6 | B9: ='השוואה כוללת'!A98 -> 63360 | C9: ='השוואה כוללת'!B98 -> URI 45 L 1 מגן ברךBOX | D9: ='השוואה כוללת'!C98 -> 374 | E9: ='השוואה כוללת'!D98 -> 372
A10: 7 | B10: ='השוואה כוללת'!A84 -> 59679 | C10: ='השוואה כוללת'!B84 -> URI 364 S M 1 | D10: ='השוואה כוללת'!C84 -> 442 | E10: ='השוואה כוללת'!D84 -> 359
A11: 8 | B11: ='השוואה כוללת'!A45 -> 31188 | C11: ='השוואה כוללת'!B45 -> URI 372 1 רפידת אנטי ריח | D11: ='השוואה כוללת'!C45 -> 359 | E11: ='השוואה כוללת'!D45 -> 352
A12: 9 | B12: ='השוואה כוללת'!A87 -> 60472 | C12: ='השוואה כוללת'!B87 -> URI PD340 1 קוצץ ציפורניים | D12: ='השוואה כוללת'!C87 -> 266 | E12: ='השוואה כוללת'!D87 -> 350
A13: 10 | B13: ='השוואה כוללת'!A131 -> 66745 | C13: ='השוואה כוללת'!B131 -> 1 תרסיס דיאו.אנטי בקטר.לנעל | D13: ='השוואה כוללת'!C131 -> 235 | E13: ='השוואה כוללת'!D131 -> 336
A14: 11 | B14: ='השוואה כוללת'!A97 -> 63359 | C14: ='השוואה כוללת'!B97 -> URI 45 M 1 מגן ברך | D14: ='השוואה כוללת'!C97 -> 311 | E14: ='השוואה כוללת'!D97 -> 297
A15: 12 | B15: ='השוואה כוללת'!A30 -> 24612 | C15: ='השוואה כוללת'!B30 -> URI AC28 1 סד לאגודל | D15: ='השוואה כוללת'!C30 -> 363 | E15: ='השוואה כוללת'!D30 -> 286
A16: 13 | B16: ='השוואה כוללת'!A162 -> 74709 | C16: ='השוואה כוללת'!B162 -> URI 21 M 1 חבק יד ארוך | D16: ='השוואה כוללת'!C162 -> 274 | E16: ='השוואה כוללת'!D162 -> 252
A17: 14 | B17: ='השוואה כוללת'!A29 -> 23008 | C17: ='השוואה כוללת'!B29 -> URI 364 XL 1 | D17: ='השוואה כוללת'!C29 -> 212 | E17: ='השוואה כוללת'!D29 -> 246
A18: 15 | B18: ='השוואה כוללת'!A108 -> 63415 | C18: ='השוואה כוללת'!B108 -> URI 85 L 1 מתלה ליד | D18: ='השוואה כוללת'!C108 -> 214 | E18: ='השוואה כוללת'!D108 -> 241
A19: 16 | B19: ='השוואה כוללת'!A85 -> 59694 | C19: ='השוואה כוללת'!B85 -> URI 365 S-L 1 טבעת אלסטית | D19: ='השוואה כוללת'!C85 -> 258 | E19: ='השוואה כוללת'!D85 -> 240
A20: 17 | B20: ='השוואה כוללת'!A167 -> 74799 | C20: ='השוואה כוללת'!B167 -> URI 45E L1 מגן ברך ארוך לבן | D20: ='השוואה כוללת'!C167 -> 244 | E20: ='השוואה כוללת'!D167 -> 237
A21: 18 | B21: ='השוואה כוללת'!A44 -> 31183 | C21: ='השוואה כוללת'!B44 -> URI 370 1 רפידת נוחות | D21: ='השוואה כוללת'!C44 -> 219 | E21: ='השוואה כוללת'!D44 -> 221
A22: 19 | B22: ='השוואה כוללת'!A99 -> 63361 | C22: ='השוואה כוללת'!B99 -> URI 45 XL 1 מגן ברך | D22: ='השוואה כוללת'!C99 -> 226 | E22: ='השוואה כוללת'!D99 -> 217
A23: 20 | B23: ='השוואה כוללת'!A90 -> 60476 | C23: ='השוואה כוללת'!B90 -> URI PD344 1 אבן טבעית | D23: ='השוואה כוללת'!C90 -> 192 | E23: ='השוואה כוללת'!D90 -> 207

Sheet עליות הכי גדולות
A1: עליות הכי גדולות - Top 20 לפי אחוז עלייה מ-2025 ל-2026
A2: סף מינימלי: רק מוצרים עם לפחות 5 יחידות שנמכרו בינואר-אוגוסט 2025 (מוצאים מוצרים חדשים/שוליים עם בסיס נמוך שמעוותים אחוזים).
A4: # | B4: קוד SKU | C4: שם מוצר | D4: יחידות ינואר-אוגוסט 2025 | E4: יחידות ינואר-אוגוסט 2026 | F4: שינוי %
A5: 1 | B5: ='השוואה כוללת'!A207 -> 82206 | C5: ='השוואה כוללת'!B207 -> ST25 1 חבק לשורש כף היד | D5: ='השוואה כוללת'!C207 -> 138 | E5: ='השוואה כוללת'!D207 -> 498 | F5: ='השוואה כוללת'!F207 -> 2.6086957
A6: 2 | B6: ='השוואה כוללת'!A77 -> 57662 | C6: ='השוואה כוללת'!B77 -> 808KT-P 1 טייפ קינזיולוגי | D6: ='השוואה כוללת'!C77 -> 16 | E6: ='השוואה כוללת'!D77 -> 56 | F6: ='השוואה כוללת'!F77 -> 2.5
A7: 3 | B7: ='השוואה כוללת'!A80 -> 57696 | C7: ='השוואה כוללת'!B80 -> 808KT-B 1 טייפ קינזיולוגי | D7: ='השוואה כוללת'!C80 -> 20 | E7: ='השוואה כוללת'!D80 -> 70 | F7: ='השוואה כוללת'!F80 -> 2.5
A8: 4 | B8: ='השוואה כוללת'!A209 -> 82208 | C8: ='השוואה כוללת'!B209 -> URI ST37 1 חבק לקרסול | D8: ='השוואה כוללת'!C209 -> 49 | E8: ='השוואה כוללת'!D209 -> 166 | F8: ='השוואה כוללת'!F209 -> 2.3877551
A9: 5 | B9: ='השוואה כוללת'!A79 -> 57690 | C9: ='השוואה כוללת'!B79 -> 808KT-C 1 טייפ קינזיולוגי | D9: ='השוואה כוללת'!C79 -> 27 | E9: ='השוואה כוללת'!D79 -> 89 | F9: ='השוואה כוללת'!F79 -> 2.2962963
A10: 6 | B10: ='השוואה כוללת'!A212 -> 83420 | C10: ='השוואה כוללת'!B212 -> URI ST4221 מגן ברך +כ סיליק | D10: ='השוואה כוללת'!C212 -> 33 | E10: ='השוואה כוללת'!D212 -> 105 | F10: ='השוואה כוללת'!F212 -> 2.1818182
A11: 7 | B11: ='השוואה כוללת'!A206 -> 82202 | C11: ='השוואה כוללת'!B206 -> ST91 1 מגן מרפק לטניס | D11: ='השוואה כוללת'!C206 -> 56 | E11: ='השוואה כוללת'!D206 -> 175 | F11: ='השוואה כוללת'!F206 -> 2.125
A12: 8 | B12: ='השוואה כוללת'!A78 -> 57664 | C12: ='השוואה כוללת'!B78 -> 808KT-BL 1 טייפ קינזיולוגי | D12: ='השוואה כוללת'!C78 -> 26 | E12: ='השוואה כוללת'!D78 -> 80 | F12: ='השוואה כוללת'!F78 -> 2.0769231
A13: 9 | B13: ='השוואה כוללת'!A208 -> 82207 | C13: ='השוואה כוללת'!B208 -> ST20 1 חבק יד | D13: ='השוואה כוללת'!C208 -> 39 | E13: ='השוואה כוללת'!D208 -> 116 | F13: ='השוואה כוללת'!F208 -> 1.974359
A14: 10 | B14: ='השוואה כוללת'!A122 -> 64635 | C14: ='השוואה כוללת'!B122 -> URI 390B 43-46 1 גרבי כסף | D14: ='השוואה כוללת'!C122 -> 25 | E14: ='השוואה כוללת'!D122 -> 59 | F14: ='השוואה כוללת'!F122 -> 1.36
A15: 11 | B15: ='השוואה כוללת'!A185 -> 74848 | C15: ='השוואה כוללת'!B185 -> URI 76 XL 1 מיישר כתף | D15: ='השוואה כוללת'!C185 -> 6 | E15: ='השוואה כוללת'!D185 -> 14 | F15: ='השוואה כוללת'!F185 -> 1.3333333
A16: 12 | B16: ='השוואה כוללת'!A217 -> 87819 | C16: ='השוואה כוללת'!B217 -> ST433 H 1 מגן ברך עם ציר | D16: ='השוואה כוללת'!C217 -> 12 | E16: ='השוואה כוללת'!D217 -> 28 | F16: ='השוואה כוללת'!F217 -> 1.3333333
A17: 13 | B17: ='השוואה כוללת'!A210 -> 82213 | C17: ='השוואה כוללת'!B210 -> ST28 1 סט אגודלי+מוט תמיכה | D17: ='השוואה כוללת'!C210 -> 80 | E17: ='השוואה כוללת'!D210 -> 175 | F17: ='השוואה כוללת'!F210 -> 1.1875
A18: 14 | B18: ='השוואה כוללת'!A147 -> 71086 | C18: ='השוואה כוללת'!B147 -> URI 078M 1 | D18: ='השוואה כוללת'!C147 -> 24 | E18: ='השוואה כוללת'!D147 -> 48 | F18: ='השוואה כוללת'!F147 -> 1
A19: 15 | B19: ='השוואה כוללת'!A41 -> 29977 | C19: ='השוואה כוללת'!B41 -> URI 11TO XXL 1 חגורת בטן | D19: ='השוואה כוללת'!C41 -> 5 | E19: ='השוואה כוללת'!D41 -> 9 | F19: ='השוואה כוללת'!F41 -> 0.8
A20: 16 | B20: ='השוואה כוללת'!A67 -> 52147 | C20: ='השוואה כוללת'!B67 -> URI FC321 1 מלח אמבט לכף ר | D20: ='השוואה כוללת'!C67 -> 80 | E20: ='השוואה כוללת'!D67 -> 139 | F20: ='השוואה כוללת'!F67 -> 0.7375
A21: 17 | B21: ='השוואה כוללת'!A70 -> 52326 | C21: ='השוואה כוללת'!B70 -> URI 078G S 1 חגורת גב אפורה | D21: ='השוואה כוללת'!C70 -> 6 | E21: ='השוואה כוללת'!D70 -> 10 | F21: ='השוואה כוללת'!F70 -> 0.66666667
A22: 18 | B22: ='השוואה כוללת'!A131 -> 66745 | C22: ='השוואה כוללת'!B131 -> 1 תרסיס דיאו.אנטי בקטר.לנעל | D22: ='השוואה כוללת'!C131 -> 235 | E22: ='השוואה כוללת'!D131 -> 336 | F22: ='השוואה כוללת'!F131 -> 0.42978723
A23: 19 | B23: ='השוואה כוללת'!A183 -> 74846 | C23: ='השוואה כוללת'!B183 -> URI 76 L 1 מיישר כתף | D23: ='השוואה כוללת'!C183 -> 14 | E23: ='השוואה כוללת'!D183 -> 20 | F23: ='השוואה כוללת'!F183 -> 0.42857143
A24: 20 | B24: ='השוואה כוללת'!A195 -> 75762 | C24: ='השוואה כוללת'!B195 -> URI 16 L-XL 1 חגורת הריון | D24: ='השוואה כוללת'!C195 -> 38 | E24: ='השוואה כוללת'!D195 -> 54 | F24: ='השוואה כוללת'!F195 -> 0.42105263

Sheet ירידות הכי גדולות
A1: ירידות הכי גדולות - Top 20 לפי אחוז ירידה מ-2025 ל-2026
A2: סף מינימלי: רק מוצרים עם לפחות 5 יחידות שנמכרו בינואר-אוגוסט 2025 (מוצאים מוצרים חדשים/שוליים עם בסיס נמוך שמעוותים אחוזים).
A4: # | B4: קוד SKU | C4: שם מוצר | D4: יחידות ינואר-אוגוסט 2025 | E4: יחידות ינואר-אוגוסט 2026 | F4: שינוי %
A5: 1 | B5: ='השוואה כוללת'!A28 -> 21897 | C5: ='השוואה כוללת'!B28 -> URI 388R 1 סד לילה לבוהן | D5: ='השוואה כוללת'!C28 -> 9 | E5: ='השוואה כוללת'!D28 -> 1 | F5: ='השוואה כוללת'!F28 -> -0.88888889
A6: 2 | B6: ='השוואה כוללת'!A136 -> 67895 | C6: ='השוואה כוללת'!B136 -> URI 11 1 ח בטן אורירית | D6: ='השוואה כוללת'!C136 -> 17 | E6: ='השוואה כוללת'!D136 -> 4 | F6: ='השוואה כוללת'!F136 -> -0.76470588
A7: 3 | B7: ='השוואה כוללת'!A15 -> 16237 | C7: ='השוואה כוללת'!B15 -> 394G-43-461 גרבי קיץ לסוכרת | D7: ='השוואה כוללת'!C15 -> 36 | E7: ='השוואה כוללת'!D15 -> 10 | F7: ='השוואה כוללת'!F15 -> -0.72222222
A8: 4 | B8: ='השוואה כוללת'!A43 -> 29984 | C8: ='השוואה כוללת'!B43 -> URI 95 XS 1 מגן מרפק | D8: ='השוואה כוללת'!C43 -> 26 | E8: ='השוואה כוללת'!D43 -> 9 | F8: ='השוואה כוללת'!F43 -> -0.65384615
A9: 5 | B9: ='השוואה כוללת'!A27 -> 21896 | C9: ='השוואה כוללת'!B27 -> URI 388L 1 סד לילה לבוהן | D9: ='השוואה כוללת'!C27 -> 8 | E9: ='השוואה כוללת'!D27 -> 3 | F9: ='השוואה כוללת'!F27 -> -0.625
A10: 6 | B10: ='השוואה כוללת'!A124 -> 64637 | C10: ='השוואה כוללת'!B124 -> URI 390G 39-42 1 גרבי כסף | D10: ='השוואה כוללת'!C124 -> 20 | E10: ='השוואה כוללת'!D124 -> 8 | F10: ='השוואה כוללת'!F124 -> -0.6
A11: 7 | B11: ='השוואה כוללת'!A33 -> 28302 | C11: ='השוואה כוללת'!B33 -> URI 34+XXL1 מ קרסול+עכב סגו | D11: ='השוואה כוללת'!C33 -> 14 | E11: ='השוואה כוללת'!D33 -> 6 | F11: ='השוואה כוללת'!F33 -> -0.57142857
A12: 8 | B12: ='השוואה כוללת'!A63 -> 50057 | C12: ='השוואה כוללת'!B63 -> URI 76 1 מיישר כתף | D12: ='השוואה כוללת'!C63 -> 9 | E12: ='השוואה כוללת'!D63 -> 4 | F12: ='השוואה כוללת'!F63 -> -0.55555556
A13: 9 | B13: ='השוואה כוללת'!A135 -> 67385 | C13: ='השוואה כוללת'!B135 -> URI 302M 0 1 מדרס ג'ל לגבר | D13: ='השוואה כוללת'!C135 -> 256 | E13: ='השוואה כוללת'!D135 -> 119 | F13: ='השוואה כוללת'!F135 -> -0.53515625
A14: 10 | B14: ='השוואה כוללת'!A177 -> 74824 | C14: ='השוואה כוללת'!B177 -> URI 59 L M 1 חגורת שבר צד ש | D14: ='השוואה כוללת'!C177 -> 8 | E14: ='השוואה כוללת'!D177 -> 4 | F14: ='השוואה כוללת'!F177 -> -0.5
A15: 11 | B15: ='השוואה כוללת'!A74 -> 53791 | C15: ='השוואה כוללת'!B74 -> URI 397-43-46 1 גרבי טיסה | D15: ='השוואה כוללת'!C74 -> 53 | E15: ='השוואה כוללת'!D74 -> 27 | F15: ='השוואה כוללת'!F74 -> -0.49056604
A16: 12 | B16: ='השוואה כוללת'!A11 -> 16212 | C16: ='השוואה כוללת'!B11 -> 394B-39-421 גרבי קיץ לסוכרת | D16: ='השוואה כוללת'!C11 -> 107 | E16: ='השוואה כוללת'!D11 -> 55 | F16: ='השוואה כוללת'!F11 -> -0.48598131
A17: 13 | B17: ='השוואה כוללת'!A152 -> 74670 | C17: ='השוואה כוללת'!B152 -> URI 07AU L 1 ח.גב איטלקית | D17: ='השוואה כוללת'!C152 -> 40 | E17: ='השוואה כוללת'!D152 -> 21 | F17: ='השוואה כוללת'!F152 -> -0.475
A18: 14 | B18: ='השוואה כוללת'!A14 -> 16217 | C18: ='השוואה כוללת'!B14 -> 394G-39-421 גרבי קיץ לסוכרת | D18: ='השוואה כוללת'!C14 -> 33 | E18: ='השוואה כוללת'!D14 -> 18 | F18: ='השוואה כוללת'!F14 -> -0.45454545
A19: 15 | B19: ='השוואה כוללת'!A47 -> 34874 | C19: ='השוואה כוללת'!B47 -> URI 333 1 סד לקרסול | D19: ='השוואה כוללת'!C47 -> 22 | E19: ='השוואה כוללת'!D47 -> 12 | F19: ='השוואה כוללת'!F47 -> -0.45454545
A20: 16 | B20: ='השוואה כוללת'!A105 -> 63406 | C20: ='השוואה כוללת'!B105 -> URI 11U L 1 ח בטן אחר ניתוח | D20: ='השוואה כוללת'!C105 -> 9 | E20: ='השוואה כוללת'!D105 -> 5 | F20: ='השוואה כוללת'!F105 -> -0.44444444
A21: 17 | B21: ='השוואה כוללת'!A42 -> 29981 | C21: ='השוואה כוללת'!B42 -> URI 35 XXL 1 מגן קרסול לבן | D21: ='השוואה כוללת'!C42 -> 50 | E21: ='השוואה כוללת'!D42 -> 28 | F21: ='השוואה כוללת'!F42 -> -0.44
A22: 18 | B22: ='השוואה כוללת'!A173 -> 74820 | C22: ='השוואה כוללת'!B173 -> URI 59R L.1 חגורת שבר לצד י | D22: ='השוואה כוללת'!C173 -> 7 | E22: ='השוואה כוללת'!D173 -> 4 | F22: ='השוואה כוללת'!F173 -> -0.42857143
A23: 19 | B23: ='השוואה כוללת'!A16 -> 16239 | C23: ='השוואה כוללת'!B16 -> 394W-35-381 גרבי קיץ לסוכרת | D23: ='השוואה כוללת'!C16 -> 30 | E23: ='השוואה כוללת'!D16 -> 18 | F23: ='השוואה כוללת'!F16 -> -0.4
A24: 20 | B24: ='השוואה כוללת'!A62 -> 50055 | C24: ='השוואה כוללת'!B62 -> URI 74 1 רצועה לשבר בעצם | D24: ='השוואה כוללת'!C62 -> 5 | E24: ='השוואה כוללת'!D62 -> 3 | F24: ='השוואה כוללת'!F62 -> -0.4

Sheet סיכום ומסקנות
A1: סיכום ומסקנות - השוואת מכירות ינואר-אוגוסט 2025 מול 2026
A2: תאריך חישוב: | B2: ='השוואה כוללת'!B2 -> 46243
A4: נתונים כלליים:
A5: - סה"כ יחידות שנמכרו בינואר-אוגוסט 2025: 16,642 (נוסחה: ='השוואה כוללת'!C240)
A6: - סה"כ יחידות שנמכרו בינואר-אוגוסט 2026: 17,314 (נוסחה: ='השוואה כוללת'!D240)
A7: - שינוי כולל: +672 יחידות, +4.0%
A9: המגמה הכללית: הוספת אוגוסט חיזקה את מגמת העלייה - מ-+2.8% (ינואר-יולי) ל-+4.0% (ינואר-אוגוסט). אוגוסט עצמו היה חודש חזק במיוחד: 1,941 יחידות ב-2025 מול 2,199 ב-2026, כ-+13.3% - החודש השני-בעוצמתו אחרי יוני (+23.4%) מתוך כל שמונת החודשים. כלומר שני החודשים האחרונים (יוני, אוגוסט) הם שדוחפים את המגמה השנתית מעלייה שולית לעלייה משמעותית.
A11: סה"כ נבדקו 234 SKU-ים ייחודיים על פני 8 החודשים (228 מתוך ינואר-יולי, ועוד 6 SKU-ים חדשים שהופיעו לראשונה באוגוסט). מתוכם 168 עומדים בסף המינימלי של 5 יחידות ב-2025 (ינואר-אוגוסט) ונכללים בטבלאות העליות/ירידות למטה - זה מסנן מוצרים שוליים עם בסיס נמוך שמעוותים אחוזי שינוי.
A13: העליות הבולטות ביותר:
A14: 1. ST25 1 חבק לשורש כף היד (SKU 82206): 138 -> 498 יחידות (+261%)
A15: 2. 808KT-P 1 טייפ קינזיולוגי (SKU 57662): 16 -> 56 יחידות (+250%)
A16: 3. 808KT-B 1 טייפ קינזיולוגי (SKU 57696): 20 -> 70 יחידות (+250%)
A17: 4. URI ST37 1 חבק לקרסול (SKU 82208): 49 -> 166 יחידות (+239%)
A18: 5. 808KT-C 1 טייפ קינזיולוגי (SKU 57690): 27 -> 89 יחידות (+230%)
... A36: - מוצרים עם 0 יחידות ב-2025 וסכום חיובי ב-2026 מסומנים בגיליון "השוואה כוללת" כ-"מוצר חדש" (במקום חלוקה באפס). 6 SKU-ים חדשים שלא הופיעו כלל בינואר-יולי נוספו לטבלת ה"השוואה כוללת" (שורות 234-239) עם נתוני אוגוסט בלבד.

Sheet מקור-01
A1: נתוני מקור - ינואר (2025 מול 2026) - מקור: month-01.xlsx
A2: קוד SKU | B2: שם מוצר | C2: יחידות ינואר 2025 | D2: יחידות ינואר 2026
A3: 71086 | B3: URI 078M 1 | C3: 1 | D3: 5
A4: 29981 | B4: URI 35 XXL 1 מגן קרסול לבן | C4: 2 | D4: 8
A5: 16239 | B5: 394W-35-381 גרבי קיץ לסוכרת | C5: 2 | D5: 6
A6: 74672 | B6: URI 07AU XL 1 ח.גב איטלקית | C6: 1 | D6: 3
A7: 74683 | B7: URI 11 M 1 ח.בטן אורירית | C7: 3 | D7: 8
A8: 59659 | B8: URI 369 S-L 1 | C8: 10 | D8: 25
A9: 63416 | B9: URI 85 XL 1 מתלה ליד | C9: 5 | D9: 11
A10: 67935 | B10: URI 45 S 1 מגן ברך | C10: 6 | D10: 13
A11: 52147 | B11: URI FC321 1 מלח אמבט לכף ר | C11: 8 | D11: 17
A12: 64632 | B12: URI 390W 43-46 1 גרבי כסף | C12: 1 | D12: 2
A13: 74824 | B13: URI 59 L M 1 חגורת שבר צד ש | C13: 1 | D13: 2
A14: 20948 | B14: URI 35 XST 1 מגן קרסול פתוח | C14: 1 | D14: 2
... A191: 74825 | B191: URI 59L XL 1 חגורת שבר צד ש | C191: 0 | D191: -1

Sheet מקור-02
A1: נתוני מקור - פברואר (2025 מול 2026) - מקור: month-02.xlsx
A2: קוד SKU | B2: שם מוצר | C2: יחידות פברואר 2025 | D2: יחידות פברואר 2026
A3: 75762 | B3: URI 16 L-XL 1 חגורת הריון | C3: 2 | D3: 14
A4: 60478 | B4: URI PD3461 10 סכינים למקצוע | C4: 1 | D4: 5
A5: 8616 | B5: URI 3623 1 כרית ליישור אצבע | C5: 5 | D5: 20
A6: 25386 | B6: URI 3666 1 מפריד הלקס+כרית | C6: 2 | D6: 7
A7: 67960 | B7: URI 85 S 1 מיתלה ליד | C7: 3 | D7: 10
A8: 63421 | B8: URI 95 L 1 מגן מרפק | C8: 5 | D8: 15
A9: 71683 | B9: URI S 3622 1 מדבקה לשחרור ל | C9: 3 | D9: 9
A10: 71088 | B10: URI 078XL 1 | C10: 4 | D10: 10
A11: 75764 | B11: URI 16 XXL 1 חגורת הריון | C11: 2 | D11: 5
A12: 64632 | B12: URI 390W 43-46 1 גרבי כסף | C12: 2 | D12: 5
A13: 63418 | B13: URI 87 L1 חגו.לקיבוע תמ.אמה | C13: 5 | D13: 12
A14: 61962 | B14: URI 3677 1 מדבקה לשחרור לחץ | C14: 3 | D14: 7
... A185: 29790 | B185: URI 11STO L1 חגורה אחר ניתו | C185: 0 | D185: 1

Sheet מקור-03
A1: נתוני מקור - מרץ (2025 מול 2026) - מקור: month-03.xlsx
A2: קוד SKU | B2: שם מוצר | C2: יחידות מרץ 2025 | D2: יחידות מרץ 2026
A3: 45264 | B3: URI 34+ 1 מגן לקרסול | C3: 1 | D3: 6
A4: 86583 | B4: URI 87 XXL 1 מקבע כתף ויד | C4: 1 | D4: 5
A5: 29881 | B5: URI 34 XXL 1 מגן קרסול סגור | C5: 1 | D5: 4
A6: 60473 | B6: URI PD341 1 מקצוע להסרת עור | C6: 1 | D6: 4
A7: 64634 | B7: URI 390B 39-42 1 גרבי כסף | C7: 1 | D7: 4
A8: 71086 | B8: URI 078M 1 | C8: 2 | D8: 6
A9: 64631 | B9: URI 390W 39-42 1 גרבי כסף | C9: 1 | D9: 3
A10: 63419 | B10: URI 87 XL1 חגו.קיבוע תמ.אמה | C10: 2 | D10: 5
A11: 63421 | B11: URI 95 L 1 מגן מרפק | C11: 6 | D11: 14
A12: 60478 | B12: URI PD3461 10 סכינים למקצוע | C12: 2 | D12: 4
A13: 29977 | B13: URI 11TO XXL 1 חגורת בטן | C13: 1 | D13: 2
A14: 63407 | B14: URI 11U XL1 ח בטן אחר ניתוח | C14: 1 | D14: 2
... A191: 50061 | B191: URI 87 S 1 חגו.קיבוע תמ.אמה | C191: 0 | D191: 0

Sheet מקור-04
A1: נתוני מקור - אפריל (2025 מול 2026) - מקור: month-04.xlsx
A2: קוד SKU | B2: שם מוצר | C2: יחידות אפריל 2025 | D2: יחידות אפריל 2026
A3: 25386 | B3: URI 3666 1 מפריד הלקס+כרית | C3: 1 | D3: 6
A4: 64635 | B4: URI 390B 43-46 1 גרבי כסף | C4: 2 | D4: 11
A5: 16217 | B5: 394G-39-421 גרבי קיץ לסוכרת | C5: 1 | D5: 5
A6: 67925 | B6: URI 35 S 1 מגן קרסול לבן | C6: 3 | D6: 10
A7: 74846 | B7: URI 76 L 1 מיישר כתף | C7: 2 | D7: 6
A8: 74806 | B8: URI 49 M 1 מגן ירך | C8: 1 | D8: 3
A9: 21004 | B9: URI 45E XXL 1 מגן ברך ארוך | C9: 4 | D9: 10
A10: 52324 | B10: URI 078G M 1 חגורת גב אפורה | C10: 4 | D10: 10
A11: 20998 | B11: URI 11 XXL 1 ח.בטן אורירית | C11: 2 | D11: 5
A12: 71086 | B12: URI 078M 1 | C12: 2 | D12: 5
A13: 74684 | B13: URI 11 XL 1 ח.בטן אורירית | C13: 4 | D13: 9
A14: 52147 | B14: URI FC321 1 מלח אמבט לכף ר | C14: 5 | D14: 11
... A181: 82551 | B181: URI ST11 1 חגורת בטן | C181: 0 | D181: 1

Sheet מקור-05
A1: נתוני מקור - מאי (2025 מול 2026) - מקור: month-05.xlsx
A2: קוד SKU | B2: שם מוצר | C2: יחידות מאי 2025 | D2: יחידות מאי 2026
A3: 82208 | B3: URI ST37 1 חבק לקרסול | C3: 2 | D3: 23
A4: 83420 | B4: URI ST4221 מגן ברך +כ סיליק | C4: 2 | D4: 17
A5: 57696 | B5: 808KT-B 1 טייפ קינזיולוגי | C5: 2 | D5: 14
A6: 82202 | B6: ST91 1 מגן מרפק לטניס | C6: 4 | D6: 25
A7: 82206 | B7: ST25 1 חבק לשורש כף היד | C7: 10 | D7: 61
A8: 82207 | B8: ST20 1 חבק יד | C8: 4 | D8: 24
A9: 57662 | B9: 808KT-P 1 טייפ קינזיולוגי | C9: 2 | D9: 10
A10: 75764 | B10: URI 16 XXL 1 חגורת הריון | C10: 1 | D10: 5
A11: 63417 | B11: URI 87 M1 חגו.לקיבוע תמ.אמה | C11: 2 | D11: 9
A12: 19083 | B12: URI 40 1 רצועת פיקה לברך | C12: 1 | D12: 4
A13: 68750 | B13: 388B L 1 סד לילה שחור לבוהן | C13: 1 | D13: 4
A14: 57664 | B14: 808KT-BL 1 טייפ קינזיולוגי | C14: 4 | D14: 14
... A192: 88479 | B192: URI LF377 M 1 מדרס סיליקון | C192: 0 | D192: 1

Sheet מקור-06
A1: נתוני מקור - יוני (2025 מול 2026) - מקור: month-06.xlsx
A2: קוד SKU | B2: שם מוצר | C2: יחידות יוני 2025 | D2: יחידות יוני 2026
A3: 19083 | B3: URI 40 1 רצועת פיקה לברך | C3: 1 | D3: 7
A4: 57662 | B4: 808KT-P 1 טייפ קינזיולוגי | C4: 1 | D4: 7
A5: 35339 | B5: URI 307 S 1 זוג עקב סיל+נ כ | C5: 1 | D5: 6
A6: 80182 | B6: URI 3667 1 מגן בונין | C6: 4 | D6: 22
A7: 76453 | B7: URI 3675 1 מגן זרת מסיליקון | C7: 2 | D7: 8
A8: 60471 | B8: URI 365 XL 1 טבעת אלסטית | C8: 4 | D8: 14
A9: 63449 | B9: URI 40221 רצועה לפיקה +כרית | C9: 2 | D9: 7
A10: 52147 | B10: URI FC321 1 מלח אמבט לכף ר | C10: 12 | D10: 36
A11: 74684 | B11: URI 11 XL 1 ח.בטן אורירית | C11: 5 | D11: 15
A12: 71086 | B12: URI 078M 1 | C12: 2 | D12: 6
A13: 68750 | B13: 388B L 1 סד לילה שחור לבוהן | C13: 1 | D13: 3
A14: 82207 | B14: ST20 1 חבק יד | C14: 6 | D14: 16
... A141: 86583 | B141: URI 87 XXL 1 מקבע כתף ויד | C141: 1 | D141: 0
A142: 16214 | B142: 394-G-35-31 גרבי קיץ לסוכרת | C142: 2
A143: 28302 | B143: URI 34+XXL1 מ קרסול+עכב סגו | C143: 1
A144: 28323 | B144: URI T33 XXL 1 סד לקרסול | C144: 1
A145: 34874 | B145: URI 333 1 סד לקרסול | C145: 3
A146: 44007 | B146: URI 07AU 1 חגור.גב איטלקית | C146: 2
A147: 46309 | B147: STRAP4U 239B L-XL 1 | C147: 1
A148: 50055 | B148: URI 74 1 רצועה לשבר בעצם | C148: 1
A149: 50057 | B149: URI 76 1 מיישר כתף | C149: 2
A150: 64631 | B150: URI 390W 39-42 1 גרבי כסף | C150: 2
A151: 67053 | B151: URI 34 XS 1 מגן קרסול סגור | C151: 3
A152: 74806 | B152: URI 49 M 1 מגן ירך | C152: 1
A153: 74822 | B153: URI 59R XL1 חגורת שבר צד י | C153: 1
... A158: 88480 | B158: URI LF377 S 1 מדרס סיליקון | C158: 1
A159: 43277 | B159: 397A-39-42 1 גרבי טיסה | D159: 20
A160: 43283 | B160: 397A-43-46 1 גרבי טיסה | D160: 10
A161: 43248 | B161: 397A-35-38 1 גרבי טיסה | D161: 7
A162: 64635 | B162: URI 390B 43-46 1 גרבי כסף | D162: 7
A163: 68751 | B163: 388B R 1 סד לילה שחור לבוהן | D163: 6
A164: 74687 | B164: URI 11 TO L 1 ח בטן | D164: 4
A165: 74827 | B165: URI 59D M 1 חגורת שבר דו צד | D165: 3
A166: 74807 | B166: URI 49 XL 1 מגן ירך | D166: 2
A167: 74846 | B167: URI 76 L 1 מיישר כתף | D167: 2
A168: 74848 | B168: URI 76 XL 1 מיישר כתף | D168: 2
A169: 87828 | B169: ST49 1 מגן ירך | D169: 2
A170: 20996 | B170: URI 07AU XXL 1 | D170: 1
...

Sheet מקור-07
A1: נתוני מקור - יולי (2025 מול 2026) - מקור: month-07.xlsx
A2: קוד SKU | B2: שם מוצר | C2: יחידות יולי 2025 | D2: יחידות יולי 2026
A3: 18559 | B3: URI 8200 1 כרית חום וקור | C3: 1 | D3: 12
A4: 74683 | B4: URI 11 M 1 ח.בטן אורירית | C4: 1 | D4: 7
A5: 64635 | B5: URI 390B 43-46 1 גרבי כסף | C5: 1 | D5: 5
A6: 75762 | B6: URI 16 L-XL 1 חגורת הריון | C6: 2 | D6: 8
A7: 65743 | B7: URI LF 360 1 מדרס מטטרזלי | C7: 2 | D7: 7
A8: 75763 | B8: URI 16 S-M 1 חגורת הריון | C8: 2 | D8: 7
A9: 16244 | B9: 394W-39-421 גרבי קיץ לסוכרת | C9: 2 | D9: 6
A10: 74821 | B10: URI 59R M.1 חגורת שבר צד י | C10: 1 | D10: 3
A11: 71087 | B11: URI 078L 1 | C11: 6 | D11: 15
A12: 16214 | B12: 394-G-35-31 גרבי קיץ לסוכרת | C12: 2 | D12: 5
A13: 74846 | B13: URI 76 L 1 מיישר כתף | C13: 2 | D13: 5
A14: 74710 | B14: URI 21 XL 1 חבק יד ארוך | C14: 7 | D14: 17
... A151: 29984 | B151: URI 95 XS 1 מגן מרפק | C151: 8 | D151: 1
A152: 28297 | B152: URI 13 XL1 חגורה ללשבר טבור | C152: 1
A153: 28331 | B153: URI T78 XXL 1 תומך זרוע כתף | C153: 1
A154: 29794 | B154: URI 11STO XXL1 חגורה א ניתו | C154: 1
A155: 29977 | B155: URI 11TO XXL 1 חגורת בטן | C155: 2
A156: 37229 | B156: URI 59R 1 חגורת שבר לצד י | C156: 1
A157: 44007 | B157: URI 07AU 1 חגור.גב איטלקית | C157: 1
A158: 46306 | B158: STRAP4U 239B S-M 1 | C158: 2
A159: 50022 | B159: URI 38 1 חבישת הלוקס ולגוס | C159: 1
A160: 64637 | B160: URI 390G 39-42 1 גרבי כסף | C160: 1
A161: 74671 | B161: URI 07AU M 1 ח גב איטלקית | C161: 1
A162: 74672 | B162: URI 07AU XL 1 ח.גב איטלקית | C162: 6
A163: 74824 | B163: URI 59 L M 1 חגורת שבר צד ש | C163: 3
... A174: 88479 | B174: URI LF377 M 1 מדרס סיליקון | C174: 1
A175: 43277 | B175: 397A-39-42 1 גרבי טיסה | D175: 29
A176: 43283 | B176: 397A-43-46 1 גרבי טיסה | D176: 25
A177: 43248 | B177: 397A-35-38 1 גרבי טיסה | D177: 12
A178: 64638 | B178: URI 390G 43-46 1 גרבי כסף | D178: 4
A179: 68750 | B179: 388B L 1 סד לילה שחור לבוהן | C179: 0 | D179: 2
A180: 75764 | B180: URI 16 XXL 1 חגורת הריון | D180: 2
A181: 88480 | B181: URI LF377 S 1 מדרס סיליקון | D181: 2
A182: 28937 | B182: URI 70N XS 1 חגורת פאבליק | D182: 1
A183: 37498 | B183: URI SH333 1 מקבע קרסול | D183: 1
A184: 43454 | B184: SH422 5 1 תומך ברך גנושילד | D184: 1
A185: 50055 | B185: URI 74 1 רצועה לשבר בעצם | D185: 1
A186: 63404 | B186: URI 11U S 1 ח בטן אחר ניתוח | D186: 1
...

Sheet מקור-08
A1: נתוני מקור - אוגוסט (2025 מול 2026) - מקור: month-08.xlsx
A2: קוד SKU | B2: שם מוצר | C2: יחידות אוגוסט 2025 | D2: יחידות אוגוסט 2026
A3: 60478 | B3: URI PD3461 10 סכינים למקצוע | C3: 1 | D3: 8
A4: 68750 | B4: 388B L 1 סד לילה שחור לבוהן | C4: 1 | D4: 5
A5: 64638 | B5: URI 390G 43-46 1 גרבי כסף | C5: 1 | D5: 4
A6: 75762 | B6: URI 16 L-XL 1 חגורת הריון | C6: 2 | D6: 7
A7: 71086 | B7: URI 078M 1 | C7: 3 | D7: 9
A8: 45264 | B8: URI 34+ 1 מגן לקרסול | C8: 2 | D8: 6
A9: 66485 | B9: URI 801 ICE GO 1 תחבושת אל | C9: 6 | D9: 17
A10: 57664 | B10: 808KT-BL 1 טייפ קינזיולוגי | C10: 4 | D10: 11
A11: 35339 | B11: URI 307 S 1 זוג עקב סיל+נ כ | C11: 3 | D11: 8
A12: 60472 | B12: URI PD340 1 קוצץ ציפורניים | C12: 29 | D12: 75
A13: 9771 | B13: URI 307 M 1 זוג עקב סיל+נ כ | C13: 14 | D13: 33
A14: 16245 | B14: 394W-43-461 גרבי קיץ לסוכרת | C14: 3 | D14: 7
... A193: 88475 | B193: URI LF371 0 1 ריפוד סיליקון | C193: 0 | D193: 0

Sheet יוני-יולי-אוגוסט 2026
A1: השוואת כמויות (יחידות, 2026 בלבד) לפי קוד SKU — יוני, יולי, אוגוסט
A2: שים לב: זו השוואת מגמה בתוך 2026 בלבד (יוני מול יולי מול אוגוסט), ללא השוואה ל-2025 - שונה מיתר הגיליונות בקובץ הזה. המקור: מקור-06 (יוני), מקור-07 (יולי), מקור-08 (אוגוסט), עמודה D (יחידות 2026) בכל אחד. 219 קודי SKU ייחודיים על פני שלושת החודשים.
A4: קוד SKU | B4: שם מוצר | C4: יוני 2026 | D4: יולי 2026 | E4: אוגוסט 2026 | F4: סה"כ 3 חודשים
A5: 51567 | B5: 1 סד יד דו צדדי | C5: =SUMIF('מקור-06'!$A:$A,$A5,'מקור-06'!$D:$D) -> 144 | D5: =SUMIF('מקור-07'!$A:$A,$A5,'מקור-07'!$D:$D) -> 130 | E5: =SUMIF('מקור-08'!$A:$A,$A5,'מקור-08'!$D:$D) -> 151 | F5: =C5+D5+E5 -> 425
A6: 83668 | B6: URI FC335 1 טלק לכף הרגל | C6: =SUMIF('מקור-06'!$A:$A,$A6,'מקור-06'!$D:$D) -> 71 | D6: =SUMIF('מקור-07'!$A:$A,$A6,'מקור-07'!$D:$D) -> 81 | E6: =SUMIF('מקור-08'!$A:$A,$A6,'מקור-08'!$D:$D) -> 87 | F6: =C6+D6+E6 -> 239
A7: 82206 | B7: ST25 1 חבק לשורש כף היד | C7: =SUMIF('מקור-06'!$A:$A,$A7,'מקור-06'!$D:$D) -> 81 | D7: =SUMIF('מקור-07'!$A:$A,$A7,'מקור-07'!$D:$D) -> 81 | E7: =SUMIF('מקור-08'!$A:$A,$A7,'מקור-08'!$D:$D) -> 60 | F7: =C7+D7+E7 -> 222
A8: 71204 | B8: URI 3655 1 שרוול מסיליקון | C8: =SUMIF('מקור-06'!$A:$A,$A8,'מקור-06'!$D:$D) -> 80 | D8: =SUMIF('מקור-07'!$A:$A,$A8,'מקור-07'!$D:$D) -> 65 | E8: =SUMIF('מקור-08'!$A:$A,$A8,'מקור-08'!$D:$D) -> 70 | F8: =C8+D8+E8 -> 215
A9: 51568 | B9: 1 סד לאגודל | C9: =SUMIF('מקור-06'!$A:$A,$A9,'מקור-06'!$D:$D) -> 59 | D9: =SUMIF('מקור-07'!$A:$A,$A9,'מקור-07'!$D:$D) -> 64 | E9: =SUMIF('מקור-08'!$A:$A,$A9,'מקור-08'!$D:$D) -> 57 | F9: =C9+D9+E9 -> 180
A10: 60472 | B10: URI PD340 1 קוצץ ציפורניים | C10: =SUMIF('מקור-06'!$A:$A,$A10,'מקור-06'!$D:$D) -> 45 | D10: =SUMIF('מקור-07'!$A:$A,$A10,'מקור-07'!$D:$D) -> 50 | E10: =SUMIF('מקור-08'!$A:$A,$A10,'מקור-08'!$D:$D) -> 75 | F10: =C10+D10+E10 -> 170
A11: 63360 | B11: URI 45 L 1 מגן ברךBOX | C11: =SUMIF('מקור-06'!$A:$A,$A11,'מקור-06'!$D:$D) -> 57 | D11: =SUMIF('מקור-07'!$A:$A,$A11,'מקור-07'!$D:$D) -> 53 | E11: =SUMIF('מקור-08'!$A:$A,$A11,'מקור-08'!$D:$D) -> 54 | F11: =C11+D11+E11 -> 164
A12: 31188 | B12: URI 372 1 רפידת אנטי ריח | C12: =SUMIF('מקור-06'!$A:$A,$A12,'מקור-06'!$D:$D) -> 52 | D12: =SUMIF('מקור-07'!$A:$A,$A12,'מקור-07'!$D:$D) -> 42 | E12: =SUMIF('מקור-08'!$A:$A,$A12,'מקור-08'!$D:$D) -> 41 | F12: =C12+D12+E12 -> 135
A13: 66745 | B13: 1 תרסיס דיאו.אנטי בקטר.לנעל | C13: =SUMIF('מקור-06'!$A:$A,$A13,'מקור-06'!$D:$D) -> 53 | D13: =SUMIF('מקור-07'!$A:$A,$A13,'מקור-07'!$D:$D) -> 31 | E13: =SUMIF('מקור-08'!$A:$A,$A13,'מקור-08'!$D:$D) -> 45 | F13: =C13+D13+E13 -> 129
A14: 63359 | B14: URI 45 M 1 מגן ברך | C14: =SUMIF('מקור-06'!$A:$A,$A14,'מקור-06'!$D:$D) -> 57 | D14: =SUMIF('מקור-07'!$A:$A,$A14,'מקור-07'!$D:$D) -> 34 | E14: =SUMIF('מקור-08'!$A:$A,$A14,'מקור-08'!$D:$D) -> 35 | F14: =C14+D14+E14 -> 126
A15: 24612 | B15: URI AC28 1 סד לאגודל | C15: =SUMIF('מקור-06'!$A:$A,$A15,'מקור-06'!$D:$D) -> 44 | D15: =SUMIF('מקור-07'!$A:$A,$A15,'מקור-07'!$D:$D) -> 36 | E15: =SUMIF('מקור-08'!$A:$A,$A15,'מקור-08'!$D:$D) -> 31 | F15: =C15+D15+E15 -> 111
A16: 60476 | B16: URI PD344 1 אבן טבעית | C16: =SUMIF('מקור-06'!$A:$A,$A16,'מקור-06'!$D:$D) -> 36 | D16: =SUMIF('מקור-07'!$A:$A,$A16,'מקור-07'!$D:$D) -> 38 | E16: =SUMIF('מקור-08'!$A:$A,$A16,'מקור-08'!$D:$D) -> 29 | F16: =C16+D16+E16 -> 103
... A223: 44007 | B223: URI 07AU 1 חגור.גב איטלקית | C223: =SUMIF('מקור-06'!$A:$A,$A223,'מקור-06'!$D:$D) -> 0 | D223: =SUMIF('מקור-07'!$A:$A,$A223,'מקור-07'!$D:$D) -> 0 | E223: =SUMIF('מקור-08'!$A:$A,$A223,'מקור-08'!$D:$D) -> 0 | F223: =C223+D223+E223 -> 0
B224: סה"כ כללי | C224: =SUM(C5:C223) -> 2374 | D224: =SUM(D5:D223) -> 2315 | E224: =SUM(E5:E223) -> 2199 | F224: =SUM(F5:F223) -> 6888
