Workbook

Sheet Index
A1: ITEMDIS — International Distribution Product List, 2025 vs 2026 (Normalized)
A2: Calculation date: | B2: 46290
A3: Technical note (not a conclusion): Same methodology as ITEMISR. "Main List" merges the 15 international distribution Sale Types from kirill/outputs/2026-09-20-salestype-2025-vs-2026.xlsx ("Source" sheet) by product - matched to CHEMIPAL Code via TRANS (primary) then the "חנה_1" Catalog (fallback), exact then whitespace-normalized; unmatched items kept as their own row (raw item name as key), not dropped. "301 - Amazon" is EXCLUDED from Main List and kept on its own standalone sheet - not part of any consolidated total (mirrors the 111/112 pattern in ITEMISR). No 0.91 factor anywhere in this file (pure SALES/NetSuite source). 2026 normalized to a full year (×12/9.5). DROP/NEW uses a near-zero tolerance (ROUND(...,2)=0 instead of exact equality) from the start, per the fix applied elsewhere this session. Match rates vary significantly by category (as low as ~19-34% of amount for Switzerland/Spain) - this is expected given each distributor uses its own SKU-naming convention not fully covered by TRANS/Catalog, not a data error; unmatched rows are kept, never guessed or dropped.
A5: Sheet map
A6: Sheet | B6: Contents
A7: Main List | B7: Merged by product across all 15 ITEMDIS categories except 301-Amazon, sorted by Qty 2026 desc, DROP/NEW colored.
A8: 301 - Amazon | B8: Standalone - not in Main List or any consolidated total. Sale Type "301 - Amazon", matched via TRANS/Catalog. Cross-validated against the source file's own native "301 - Amazon" DROP/NEW totals.
A9: SALES Raw | B9: Pre-aggregated item-level data (per category+item) for all 16 ITEMDIS categories, with live CHEMIPAL Code match + scope helper columns.
A10: TRANS | B10: Crosswalk table (short NetSuite-style item codes -> CHEMIPAL Code) - primary match source.
A11: Catalog | B11: Global מק"ט <-> item-name catalog ("חנה_1", PPLAY1-format) - fallback match source.
A13: Summary
A14: Sheet | B14: # Rows | C14: Qty 2025 | D14: Amt 2025 (₪) | E14: Qty 2026 (norm) | F14: Amt 2026 (norm, ₪) | G14: # DROP | H14: # NEW
A15: Main List | B15: 557 | C15: 145075 | D15: 3269265.6 | E15: 132547 | F15: 2649713.9 | G15: 129 | H15: 45
A16: 301 - Amazon | B16: 79 | C16: 27158 | D16: 2705391.2 | E16: 23757 | F16: 2062598.9 | G16: 17 | H16: 6
A18: Per-category match rate (Main List, 15 categories + Amazon shown separately)
A19: Category | B19: # Items | C19: # Unmatched | D19: Qty match % | E19: Amt match %
A20: 202 - Super-Pharm POLAND | B20: 136 | C20: 15 | D20: 0.7937 | E20: 0.7785
A21: 201- Seven Gear FINLAND oy | B21: 49 | C21: 5 | D21: 0.9518 | E21: 0.926
A22: 216 - Max Konnaris CYPRUS | B22: 246 | C22: 33 | D22: 0.8522 | E22: 0.8475
A23: 200 - ROW : 217 - N3W FOODS USA | B23: 6 | C23: 1 | D23: 1 | E23: 1
A24: 205 - Health Care Prod. Gmbh GERMANY | B24: 38 | C24: 9 | D24: 0.9825 | E24: 0.9621
A25: 301 - Amazon | B25: 80 | C25: 58 | D25: 0.632 | E25: 0.4268
A26: 206 - Orthomed Ltd BULGARIA | B26: 87 | C26: 15 | D26: 0.8646 | E26: 0.7472
A27: 203 - Ortho- Partner ag SWITZERLAND | B27: 112 | C27: 45 | D27: 0.3391 | E27: 0.1866
A28: 210 - Oy. Ea. Ab. FINLAND | B28: 184 | C28: 50 | D28: 0.7982 | E28: 0.7787
A29: 204 - Sanaflex Anatomic GREECE | B29: 205 | C29: 44 | D29: 0.8927 | E29: 0.8627
A30: 214 - Alfred Gera& Sons Ltd. MALTA | B30: 22 | C30: 1 | D30: 1 | E30: 1
A31: 211 - Pharmag Lachmair Ges. Mbh AUSTRIA | B31: 33 | C31: 12 | D31: 0.6837 | E31: 0.6929
... A35: 209 - Ortoprofil Prod ROMANIA | B35: 92 | C35: 10 | D35: 0.8341 | E35: 0.8154

Sheet Main List
A1: Main List — merged by product, 15 sources (all ITEMDIS categories except 301-Amazon)
A2: Calculation date: | B2: 46290
A3: Technical note (not a conclusion): merges the 15 international-distribution Sale Types from kirill/outputs/2026-09-20-salestype-2025-vs-2026.xlsx (Source sheet), matched to CHEMIPAL Code via TRANS (primary) then the "חנה_1" Catalog (fallback), exact then whitespace-normalized. Each CHEMIPAL Code / raw item name appears ONCE, Quantity/Amount summed across all 15 categories that report it. CHEMIPAL Code blank when unmatched (kept as its own row, keyed by raw item name - not dropped). "301 - Amazon" is EXCLUDED here and kept on its own standalone sheet - not part of this Main List or any consolidated total, per instruction (mirrors the 111/112 pattern in the ITEMISR file). No 0.91 factor anywhere in this file (pure SALES/NetSuite source, not PPLAY1). 2026 normalized to a full year (×12/9.5). DROP/NEW classification uses a near-zero tolerance (ROUND(...,2)=0) instead of exact equality, to avoid floating-point residue misclassifying a true zero as nonzero (per the fix applied across the other files in this session — built in here from the start). Sorted by Quantity 2026 (normalized), descending. RED = DROP, GREEN = NEW.
A4: Normalization factor (2026, full year): | G4: Factor (12/9.5): | H4: =12/9.5 -> 1.2631579
A6: CHEMIPAL Code | B6: ITEM NAME | C6: שם מוצר | D6: כמות 2025 | E6: כסף 2025 (₪) | F6: כמות 2026 (מנורמל) | G6: כסף 2026 (מנורמל, ₪) | H6: Top Source | I6: 2nd Source | J6: Internal Product Key (audit)
A7: =IF(ISNUMBER($J7),$J7,"") -> 4408267 | B7: =IFERROR(INDEX('SALES Raw'!$B$6:$B$1634,MATCH($J7,'SALES Raw'!$J$6:$J$1634,0)),$J7) -> ST25 0 | C7: =IF(ISNUMBER($J7),IFERROR(INDEX('TRANS'!$C:$C,MATCH($J7,'TRANS'!$B:$B,0)),IFERROR(INDEX('Catalog'!$B:$B,MATCH($J7,'Catalog'!$A:$A,0)),$B7)),$B7) -> ST25 חבק שורש לכף היד | D7: =SUMIFS('SALES Raw'!$C$6:$C$1634,'SALES Raw'!$J$6:$J$1634,$J7,'SALES Raw'!$K$6:$K$1634,"Y") -> 5918 | E7: =SUMIFS('SALES Raw'!$D$6:$D$1634,'SALES Raw'!$J$6:$J$1634,$J7,'SALES Raw'!$K$6:$K$1634,"Y") -> 82554.57 | F7: =SUMIFS('SALES Raw'!$E$6:$E$1634,'SALES Raw'!$J$6:$J$1634,$J7,'SALES Raw'!$K$6:$K$1634,"Y")*$H$4 -> 8182.7368 | G7: =SUMIFS('SALES Raw'!$F$6:$F$1634,'SALES Raw'!$J$6:$J$1634,$J7,'SALES Raw'!$K$6:$K$1634,"Y")*$H$4 -> 113752.76 | H7: 207 - Salus HUNGARY | I7: 211 - Pharmag Lachmair Ges. Mbh AUSTRIA | J7: 4408267
A8: =IF(ISNUMBER($J8),$J8,"") -> 4401002 | B8: =IFERROR(INDEX('SALES Raw'!$B$6:$B$1634,MATCH($J8,'SALES Raw'!$J$6:$J$1634,0)),$J8) -> PD344 0 | C8: =IF(ISNUMBER($J8),IFERROR(INDEX('TRANS'!$C:$C,MATCH($J8,'TRANS'!$B:$B,0)),IFERROR(INDEX('Catalog'!$B:$B,MATCH($J8,'Catalog'!$A:$A,0)),$B8)),$B8) -> PD 344-אבן טבעית להסרת עור קשה | D8: =SUMIFS('SALES Raw'!$C$6:$C$1634,'SALES Raw'!$J$6:$J$1634,$J8,'SALES Raw'!$K$6:$K$1634,"Y") -> 4400 | E8: =SUMIFS('SALES Raw'!$D$6:$D$1634,'SALES Raw'!$J$6:$J$1634,$J8,'SALES Raw'!$K$6:$K$1634,"Y") -> 20662.34 | F8: =SUMIFS('SALES Raw'!$E$6:$E$1634,'SALES Raw'!$J$6:$J$1634,$J8,'SALES Raw'!$K$6:$K$1634,"Y")*$H$4 -> 7200 | G8: =SUMIFS('SALES Raw'!$F$6:$F$1634,'SALES Raw'!$J$6:$J$1634,$J8,'SALES Raw'!$K$6:$K$1634,"Y")*$H$4 -> 30682.535 | H8: 205 - Health Care Prod. Gmbh GERMANY | J8: 4401002
A9: =IF(ISNUMBER($J9),$J9,"") | B9: =IFERROR(INDEX('SALES Raw'!$B$6:$B$1634,MATCH($J9,'SALES Raw'!$J$6:$J$1634,0)),$J9) -> ST45X 0 | C9: =IF(ISNUMBER($J9),IFERROR(INDEX('TRANS'!$C:$C,MATCH($J9,'TRANS'!$B:$B,0)),IFERROR(INDEX('Catalog'!$B:$B,MATCH($J9,'Catalog'!$A:$A,0)),$B9)),$B9) -> ST45X 0 | D9: =SUMIFS('SALES Raw'!$C$6:$C$1634,'SALES Raw'!$J$6:$J$1634,$J9,'SALES Raw'!$K$6:$K$1634,"Y") -> 2423 | E9: =SUMIFS('SALES Raw'!$D$6:$D$1634,'SALES Raw'!$J$6:$J$1634,$J9,'SALES Raw'!$K$6:$K$1634,"Y") -> 43468.16 | F9: =SUMIFS('SALES Raw'!$E$6:$E$1634,'SALES Raw'!$J$6:$J$1634,$J9,'SALES Raw'!$K$6:$K$1634,"Y")*$H$4 -> 4172.2105 | G9: =SUMIFS('SALES Raw'!$F$6:$F$1634,'SALES Raw'!$J$6:$J$1634,$J9,'SALES Raw'!$K$6:$K$1634,"Y")*$H$4 -> 69031.213 | H9: 207 - Salus HUNGARY | I9: 213 - E.f.m.o. SPAIN | J9: ST45X 0
A10: =IF(ISNUMBER($J10),$J10,"") -> 4421000 | B10: =IFERROR(INDEX('SALES Raw'!$B$6:$B$1634,MATCH($J10,'SALES Raw'!$J$6:$J$1634,0)),$J10) -> 3655 0 | C10: =IF(ISNUMBER($J10),IFERROR(INDEX('TRANS'!$C:$C,MATCH($J10,'TRANS'!$B:$B,0)),IFERROR(INDEX('Catalog'!$B:$B,MATCH($J10,'Catalog'!$A:$A,0)),$B10)),$B10) -> 3655 שרוול מסיליקון לאצבע | D10: =SUMIFS('SALES Raw'!$C$6:$C$1634,'SALES Raw'!$J$6:$J$1634,$J10,'SALES Raw'!$K$6:$K$1634,"Y") -> 3370 | E10: =SUMIFS('SALES Raw'!$D$6:$D$1634,'SALES Raw'!$J$6:$J$1634,$J10,'SALES Raw'!$K$6:$K$1634,"Y") -> 33479.31 | F10: =SUMIFS('SALES Raw'!$E$6:$E$1634,'SALES Raw'!$J$6:$J$1634,$J10,'SALES Raw'!$K$6:$K$1634,"Y")*$H$4 -> 3786.9474 | G10: =SUMIFS('SALES Raw'!$F$6:$F$1634,'SALES Raw'!$J$6:$J$1634,$J10,'SALES Raw'!$K$6:$K$1634,"Y")*$H$4 -> 33298.434 | H10: 205 - Health Care Prod. Gmbh GERMANY | I10: 207 - Salus HUNGARY | J10: 4421000
A11: =IF(ISNUMBER($J11),$J11,"") -> 4422000 | B11: =IFERROR(INDEX('SALES Raw'!$B$6:$B$1634,MATCH($J11,'SALES Raw'!$J$6:$J$1634,0)),$J11) -> 801 0 | C11: =IF(ISNUMBER($J11),IFERROR(INDEX('TRANS'!$C:$C,MATCH($J11,'TRANS'!$B:$B,0)),IFERROR(INDEX('Catalog'!$B:$B,MATCH($J11,'Catalog'!$A:$A,0)),$B11)),$B11) -> 801 תחבושת אלסטית מקררת | D11: =SUMIFS('SALES Raw'!$C$6:$C$1634,'SALES Raw'!$J$6:$J$1634,$J11,'SALES Raw'!$K$6:$K$1634,"Y") -> 3155 | E11: =SUMIFS('SALES Raw'!$D$6:$D$1634,'SALES Raw'!$J$6:$J$1634,$J11,'SALES Raw'!$K$6:$K$1634,"Y") -> 34776.77 | F11: =SUMIFS('SALES Raw'!$E$6:$E$1634,'SALES Raw'!$J$6:$J$1634,$J11,'SALES Raw'!$K$6:$K$1634,"Y")*$H$4 -> 3776.8421 | G11: =SUMIFS('SALES Raw'!$F$6:$F$1634,'SALES Raw'!$J$6:$J$1634,$J11,'SALES Raw'!$K$6:$K$1634,"Y")*$H$4 -> 37543.187 | H11: 205 - Health Care Prod. Gmbh GERMANY | I11: 202 - Super-Pharm POLAND | J11: 4422000
A12: =IF(ISNUMBER($J12),$J12,"") -> 4408207 | B12: =IFERROR(INDEX('SALES Raw'!$B$6:$B$1634,MATCH($J12,'SALES Raw'!$J$6:$J$1634,0)),$J12) -> AC25 0 | C12: =IF(ISNUMBER($J12),IFERROR(INDEX('TRANS'!$C:$C,MATCH($J12,'TRANS'!$B:$B,0)),IFERROR(INDEX('Catalog'!$B:$B,MATCH($J12,'Catalog'!$A:$A,0)),$B12)),$B12) -> AC-25 חבק לשורש כף היד | D12: =SUMIFS('SALES Raw'!$C$6:$C$1634,'SALES Raw'!$J$6:$J$1634,$J12,'SALES Raw'!$K$6:$K$1634,"Y") -> 3919 | E12: =SUMIFS('SALES Raw'!$D$6:$D$1634,'SALES Raw'!$J$6:$J$1634,$J12,'SALES Raw'!$K$6:$K$1634,"Y") -> 63285.34 | F12: =SUMIFS('SALES Raw'!$E$6:$E$1634,'SALES Raw'!$J$6:$J$1634,$J12,'SALES Raw'!$K$6:$K$1634,"Y")*$H$4 -> 3645.4737 | G12: =SUMIFS('SALES Raw'!$F$6:$F$1634,'SALES Raw'!$J$6:$J$1634,$J12,'SALES Raw'!$K$6:$K$1634,"Y")*$H$4 -> 53520.846 | H12: 207 - Salus HUNGARY | I12: 204 - Sanaflex Anatomic GREECE | J12: 4408207
A13: =IF(ISNUMBER($J13),$J13,"") -> 4415028 | B13: =IFERROR(INDEX('SALES Raw'!$B$6:$B$1634,MATCH($J13,'SALES Raw'!$J$6:$J$1634,0)),$J13) -> AC28 0 | C13: =IF(ISNUMBER($J13),IFERROR(INDEX('TRANS'!$C:$C,MATCH($J13,'TRANS'!$B:$B,0)),IFERROR(INDEX('Catalog'!$B:$B,MATCH($J13,'Catalog'!$A:$A,0)),$B13)),$B13) -> AC-28 סד לאגודל | D13: =SUMIFS('SALES Raw'!$C$6:$C$1634,'SALES Raw'!$J$6:$J$1634,$J13,'SALES Raw'!$K$6:$K$1634,"Y") -> 2555 | E13: =SUMIFS('SALES Raw'!$D$6:$D$1634,'SALES Raw'!$J$6:$J$1634,$J13,'SALES Raw'!$K$6:$K$1634,"Y") -> 41350.21 | F13: =SUMIFS('SALES Raw'!$E$6:$E$1634,'SALES Raw'!$J$6:$J$1634,$J13,'SALES Raw'!$K$6:$K$1634,"Y")*$H$4 -> 2418.9474 | G13: =SUMIFS('SALES Raw'!$F$6:$F$1634,'SALES Raw'!$J$6:$J$1634,$J13,'SALES Raw'!$K$6:$K$1634,"Y")*$H$4 -> 36333.171 | H13: 204 - Sanaflex Anatomic GREECE | I13: 202 - Super-Pharm POLAND | J13: 4415028
A14: =IF(ISNUMBER($J14),$J14,"") -> 4422024 | B14: =IFERROR(INDEX('SALES Raw'!$B$6:$B$1634,MATCH($J14,'SALES Raw'!$J$6:$J$1634,0)),$J14) -> 806CB-B | C14: =IF(ISNUMBER($J14),IFERROR(INDEX('TRANS'!$C:$C,MATCH($J14,'TRANS'!$B:$B,0)),IFERROR(INDEX('Catalog'!$B:$B,MATCH($J14,'Catalog'!$A:$A,0)),$B14)),$B14) -> 806CB-BLACK תחבושת א.נצמ | D14: =SUMIFS('SALES Raw'!$C$6:$C$1634,'SALES Raw'!$J$6:$J$1634,$J14,'SALES Raw'!$K$6:$K$1634,"Y") -> 3124 | E14: =SUMIFS('SALES Raw'!$D$6:$D$1634,'SALES Raw'!$J$6:$J$1634,$J14,'SALES Raw'!$K$6:$K$1634,"Y") -> 23525.18 | F14: =SUMIFS('SALES Raw'!$E$6:$E$1634,'SALES Raw'!$J$6:$J$1634,$J14,'SALES Raw'!$K$6:$K$1634,"Y")*$H$4 -> 2243.3684 | G14: =SUMIFS('SALES Raw'!$F$6:$F$1634,'SALES Raw'!$J$6:$J$1634,$J14,'SALES Raw'!$K$6:$K$1634,"Y")*$H$4 -> 15205.895 | H14: 202 - Super-Pharm POLAND | I14: 207 - Salus HUNGARY | J14: 4422024
A15: =IF(ISNUMBER($J15),$J15,"") -> 4422023 | B15: =IFERROR(INDEX('SALES Raw'!$B$6:$B$1634,MATCH($J15,'SALES Raw'!$J$6:$J$1634,0)),$J15) -> 806CB-C | C15: =IF(ISNUMBER($J15),IFERROR(INDEX('TRANS'!$C:$C,MATCH($J15,'TRANS'!$B:$B,0)),IFERROR(INDEX('Catalog'!$B:$B,MATCH($J15,'Catalog'!$A:$A,0)),$B15)),$B15) -> 806CB-BEIGE תחבושת א.נצמ | D15: =SUMIFS('SALES Raw'!$C$6:$C$1634,'SALES Raw'!$J$6:$J$1634,$J15,'SALES Raw'!$K$6:$K$1634,"Y") -> 2610 | E15: =SUMIFS('SALES Raw'!$D$6:$D$1634,'SALES Raw'!$J$6:$J$1634,$J15,'SALES Raw'!$K$6:$K$1634,"Y") -> 19811.07 | F15: =SUMIFS('SALES Raw'!$E$6:$E$1634,'SALES Raw'!$J$6:$J$1634,$J15,'SALES Raw'!$K$6:$K$1634,"Y")*$H$4 -> 2122.1053 | G15: =SUMIFS('SALES Raw'!$F$6:$F$1634,'SALES Raw'!$J$6:$J$1634,$J15,'SALES Raw'!$K$6:$K$1634,"Y")*$H$4 -> 14397.726 | H15: 202 - Super-Pharm POLAND | I15: 207 - Salus HUNGARY | J15: 4422023
A16: =IF(ISNUMBER($J16),$J16,"") | B16: =IFERROR(INDEX('SALES Raw'!$B$6:$B$1634,MATCH($J16,'SALES Raw'!$J$6:$J$1634,0)),$J16) -> 49PS L | C16: =IF(ISNUMBER($J16),IFERROR(INDEX('TRANS'!$C:$C,MATCH($J16,'TRANS'!$B:$B,0)),IFERROR(INDEX('Catalog'!$B:$B,MATCH($J16,'Catalog'!$A:$A,0)),$B16)),$B16) -> 49PS L | D16: =SUMIFS('SALES Raw'!$C$6:$C$1634,'SALES Raw'!$J$6:$J$1634,$J16,'SALES Raw'!$K$6:$K$1634,"Y") -> 961 | E16: =SUMIFS('SALES Raw'!$D$6:$D$1634,'SALES Raw'!$J$6:$J$1634,$J16,'SALES Raw'!$K$6:$K$1634,"Y") -> 56565.47 | F16: =SUMIFS('SALES Raw'!$E$6:$E$1634,'SALES Raw'!$J$6:$J$1634,$J16,'SALES Raw'!$K$6:$K$1634,"Y")*$H$4 -> 2014.7368 | G16: =SUMIFS('SALES Raw'!$F$6:$F$1634,'SALES Raw'!$J$6:$J$1634,$J16,'SALES Raw'!$K$6:$K$1634,"Y")*$H$4 -> 112001.57 | H16: 203 - Ortho- Partner ag SWITZERLAND | J16: 49PS L
A17: =IF(ISNUMBER($J17),$J17,"") -> 4413328 | B17: =IFERROR(INDEX('SALES Raw'!$B$6:$B$1634,MATCH($J17,'SALES Raw'!$J$6:$J$1634,0)),$J17) -> AC43D 0 | C17: =IF(ISNUMBER($J17),IFERROR(INDEX('TRANS'!$C:$C,MATCH($J17,'TRANS'!$B:$B,0)),IFERROR(INDEX('Catalog'!$B:$B,MATCH($J17,'Catalog'!$A:$A,0)),$B17)),$B17) -> AC43D מגן ברך + צירים | D17: =SUMIFS('SALES Raw'!$C$6:$C$1634,'SALES Raw'!$J$6:$J$1634,$J17,'SALES Raw'!$K$6:$K$1634,"Y") -> 2124 | E17: =SUMIFS('SALES Raw'!$D$6:$D$1634,'SALES Raw'!$J$6:$J$1634,$J17,'SALES Raw'!$K$6:$K$1634,"Y") -> 101797.75 | F17: =SUMIFS('SALES Raw'!$E$6:$E$1634,'SALES Raw'!$J$6:$J$1634,$J17,'SALES Raw'!$K$6:$K$1634,"Y")*$H$4 -> 1777.2632 | G17: =SUMIFS('SALES Raw'!$F$6:$F$1634,'SALES Raw'!$J$6:$J$1634,$J17,'SALES Raw'!$K$6:$K$1634,"Y")*$H$4 -> 78322.004 | H17: 207 - Salus HUNGARY | I17: 204 - Sanaflex Anatomic GREECE | J17: 4413328
A18: =IF(ISNUMBER($J18),$J18,"") | B18: =IFERROR(INDEX('SALES Raw'!$B$6:$B$1634,MATCH($J18,'SALES Raw'!$J$6:$J$1634,0)),$J18) -> 808KTP-C | C18: =IF(ISNUMBER($J18),IFERROR(INDEX('TRANS'!$C:$C,MATCH($J18,'TRANS'!$B:$B,0)),IFERROR(INDEX('Catalog'!$B:$B,MATCH($J18,'Catalog'!$A:$A,0)),$B18)),$B18) -> 808KTP-C | D18: =SUMIFS('SALES Raw'!$C$6:$C$1634,'SALES Raw'!$J$6:$J$1634,$J18,'SALES Raw'!$K$6:$K$1634,"Y") -> 1700 | E18: =SUMIFS('SALES Raw'!$D$6:$D$1634,'SALES Raw'!$J$6:$J$1634,$J18,'SALES Raw'!$K$6:$K$1634,"Y") -> 32023.54 | F18: =SUMIFS('SALES Raw'!$E$6:$E$1634,'SALES Raw'!$J$6:$J$1634,$J18,'SALES Raw'!$K$6:$K$1634,"Y")*$H$4 -> 1768.4211 | G18: =SUMIFS('SALES Raw'!$F$6:$F$1634,'SALES Raw'!$J$6:$J$1634,$J18,'SALES Raw'!$K$6:$K$1634,"Y")*$H$4 -> 29027.608 | H18: 202 - Super-Pharm POLAND | J18: 808KTP-C
A19: =IF(ISNUMBER($J19),$J19,"") -> 4422026 | B19: =IFERROR(INDEX('SALES Raw'!$B$6:$B$1634,MATCH($J19,'SALES Raw'!$J$6:$J$1634,0)),$J19) -> 806CB-P | C19: =IF(ISNUMBER($J19),IFERROR(INDEX('TRANS'!$C:$C,MATCH($J19,'TRANS'!$B:$B,0)),IFERROR(INDEX('Catalog'!$B:$B,MATCH($J19,'Catalog'!$A:$A,0)),$B19)),$B19) -> 806CB-PINK תחבושת א.נצמ | D19: =SUMIFS('SALES Raw'!$C$6:$C$1634,'SALES Raw'!$J$6:$J$1634,$J19,'SALES Raw'!$K$6:$K$1634,"Y") -> 1915 | E19: =SUMIFS('SALES Raw'!$D$6:$D$1634,'SALES Raw'!$J$6:$J$1634,$J19,'SALES Raw'!$K$6:$K$1634,"Y") -> 14493.04 | F19: =SUMIFS('SALES Raw'!$E$6:$E$1634,'SALES Raw'!$J$6:$J$1634,$J19,'SALES Raw'!$K$6:$K$1634,"Y")*$H$4 -> 1695.1579 | G19: =SUMIFS('SALES Raw'!$F$6:$F$1634,'SALES Raw'!$J$6:$J$1634,$J19,'SALES Raw'!$K$6:$K$1634,"Y")*$H$4 -> 11593.149 | H19: 202 - Super-Pharm POLAND | I19: 207 - Salus HUNGARY | J19: 4422026
A20: =IF(ISNUMBER($J20),$J20,"") | B20: =IFERROR(INDEX('SALES Raw'!$B$6:$B$1634,MATCH($J20,'SALES Raw'!$J$6:$J$1634,0)),$J20) -> 808KTP-B | C20: =IF(ISNUMBER($J20),IFERROR(INDEX('TRANS'!$C:$C,MATCH($J20,'TRANS'!$B:$B,0)),IFERROR(INDEX('Catalog'!$B:$B,MATCH($J20,'Catalog'!$A:$A,0)),$B20)),$B20) -> 808KTP-B | D20: =SUMIFS('SALES Raw'!$C$6:$C$1634,'SALES Raw'!$J$6:$J$1634,$J20,'SALES Raw'!$K$6:$K$1634,"Y") -> 1800 | E20: =SUMIFS('SALES Raw'!$D$6:$D$1634,'SALES Raw'!$J$6:$J$1634,$J20,'SALES Raw'!$K$6:$K$1634,"Y") -> 33646.56 | F20: =SUMIFS('SALES Raw'!$E$6:$E$1634,'SALES Raw'!$J$6:$J$1634,$J20,'SALES Raw'!$K$6:$K$1634,"Y")*$H$4 -> 1642.1053 | G20: =SUMIFS('SALES Raw'!$F$6:$F$1634,'SALES Raw'!$J$6:$J$1634,$J20,'SALES Raw'!$K$6:$K$1634,"Y")*$H$4 -> 27227.937 | H20: 202 - Super-Pharm POLAND | J20: 808KTP-B
A21: =IF(ISNUMBER($J21),$J21,"") | B21: =IFERROR(INDEX('SALES Raw'!$B$6:$B$1634,MATCH($J21,'SALES Raw'!$J$6:$J$1634,0)),$J21) -> 808KTP-P | C21: =IF(ISNUMBER($J21),IFERROR(INDEX('TRANS'!$C:$C,MATCH($J21,'TRANS'!$B:$B,0)),IFERROR(INDEX('Catalog'!$B:$B,MATCH($J21,'Catalog'!$A:$A,0)),$B21)),$B21) -> 808KTP-P | D21: =SUMIFS('SALES Raw'!$C$6:$C$1634,'SALES Raw'!$J$6:$J$1634,$J21,'SALES Raw'!$K$6:$K$1634,"Y") -> 1600 | E21: =SUMIFS('SALES Raw'!$D$6:$D$1634,'SALES Raw'!$J$6:$J$1634,$J21,'SALES Raw'!$K$6:$K$1634,"Y") -> 30065.76 | F21: =SUMIFS('SALES Raw'!$E$6:$E$1634,'SALES Raw'!$J$6:$J$1634,$J21,'SALES Raw'!$K$6:$K$1634,"Y")*$H$4 -> 1642.1053 | G21: =SUMIFS('SALES Raw'!$F$6:$F$1634,'SALES Raw'!$J$6:$J$1634,$J21,'SALES Raw'!$K$6:$K$1634,"Y")*$H$4 -> 27227.937 | H21: 202 - Super-Pharm POLAND | J21: 808KTP-P
A22: =IF(ISNUMBER($J22),$J22,"") | B22: =IFERROR(INDEX('SALES Raw'!$B$6:$B$1634,MATCH($J22,'SALES Raw'!$J$6:$J$1634,0)),$J22) -> 808KTP-BL | C22: =IF(ISNUMBER($J22),IFERROR(INDEX('TRANS'!$C:$C,MATCH($J22,'TRANS'!$B:$B,0)),IFERROR(INDEX('Catalog'!$B:$B,MATCH($J22,'Catalog'!$A:$A,0)),$B22)),$B22) -> 808KTP-BL | D22: =SUMIFS('SALES Raw'!$C$6:$C$1634,'SALES Raw'!$J$6:$J$1634,$J22,'SALES Raw'!$K$6:$K$1634,"Y") -> 1450 | E22: =SUMIFS('SALES Raw'!$D$6:$D$1634,'SALES Raw'!$J$6:$J$1634,$J22,'SALES Raw'!$K$6:$K$1634,"Y") -> 27344.66 | F22: =SUMIFS('SALES Raw'!$E$6:$E$1634,'SALES Raw'!$J$6:$J$1634,$J22,'SALES Raw'!$K$6:$K$1634,"Y")*$H$4 -> 1515.7895 | G22: =SUMIFS('SALES Raw'!$F$6:$F$1634,'SALES Raw'!$J$6:$J$1634,$J22,'SALES Raw'!$K$6:$K$1634,"Y")*$H$4 -> 25340.665 | H22: 202 - Super-Pharm POLAND | J22: 808KTP-BL
A23: =IF(ISNUMBER($J23),$J23,"") -> 4415161 | B23: =IFERROR(INDEX('SALES Raw'!$B$6:$B$1634,MATCH($J23,'SALES Raw'!$J$6:$J$1634,0)),$J23) -> 238 M | C23: =IF(ISNUMBER($J23),IFERROR(INDEX('TRANS'!$C:$C,MATCH($J23,'TRANS'!$B:$B,0)),IFERROR(INDEX('Catalog'!$B:$B,MATCH($J23,'Catalog'!$A:$A,0)),$B23)),$B23) -> 238M סד ליישור אצבע | D23: =SUMIFS('SALES Raw'!$C$6:$C$1634,'SALES Raw'!$J$6:$J$1634,$J23,'SALES Raw'!$K$6:$K$1634,"Y") -> 1458 | E23: =SUMIFS('SALES Raw'!$D$6:$D$1634,'SALES Raw'!$J$6:$J$1634,$J23,'SALES Raw'!$K$6:$K$1634,"Y") -> 12345.54 | F23: =SUMIFS('SALES Raw'!$E$6:$E$1634,'SALES Raw'!$J$6:$J$1634,$J23,'SALES Raw'!$K$6:$K$1634,"Y")*$H$4 -> 1514.5263 | G23: =SUMIFS('SALES Raw'!$F$6:$F$1634,'SALES Raw'!$J$6:$J$1634,$J23,'SALES Raw'!$K$6:$K$1634,"Y")*$H$4 -> 12119.836 | H23: 204 - Sanaflex Anatomic GREECE | I23: 207 - Salus HUNGARY | J23: 4415161
A24: =IF(ISNUMBER($J24),$J24,"") -> 4408203 | B24: =IFERROR(INDEX('SALES Raw'!$B$6:$B$1634,MATCH($J24,'SALES Raw'!$J$6:$J$1634,0)),$J24) -> 14 0 | C24: =IF(ISNUMBER($J24),IFERROR(INDEX('TRANS'!$C:$C,MATCH($J24,'TRANS'!$B:$B,0)),IFERROR(INDEX('Catalog'!$B:$B,MATCH($J24,'Catalog'!$A:$A,0)),$B24)),$B24) -> 14 0 חגורה למנותחי בית חזה | D24: =SUMIFS('SALES Raw'!$C$6:$C$1634,'SALES Raw'!$J$6:$J$1634,$J24,'SALES Raw'!$K$6:$K$1634,"Y") -> 1455 | E24: =SUMIFS('SALES Raw'!$D$6:$D$1634,'SALES Raw'!$J$6:$J$1634,$J24,'SALES Raw'!$K$6:$K$1634,"Y") -> 115804.66 | F24: =SUMIFS('SALES Raw'!$E$6:$E$1634,'SALES Raw'!$J$6:$J$1634,$J24,'SALES Raw'!$K$6:$K$1634,"Y")*$H$4 -> 1509.4737 | G24: =SUMIFS('SALES Raw'!$F$6:$F$1634,'SALES Raw'!$J$6:$J$1634,$J24,'SALES Raw'!$K$6:$K$1634,"Y")*$H$4 -> 119013.81 | H24: 209 - Ortoprofil Prod ROMANIA | I24: 207 - Salus HUNGARY | J24: 4408203
A25: =IF(ISNUMBER($J25),$J25,"") -> 4401001 | B25: =IFERROR(INDEX('SALES Raw'!$B$6:$B$1634,MATCH($J25,'SALES Raw'!$J$6:$J$1634,0)),$J25) -> 369-XL | C25: =IF(ISNUMBER($J25),IFERROR(INDEX('TRANS'!$C:$C,MATCH($J25,'TRANS'!$B:$B,0)),IFERROR(INDEX('Catalog'!$B:$B,MATCH($J25,'Catalog'!$A:$A,0)),$B25)),$B25) -> 369 XL אצבעון מסיליקון יחידה | D25: =SUMIFS('SALES Raw'!$C$6:$C$1634,'SALES Raw'!$J$6:$J$1634,$J25,'SALES Raw'!$K$6:$K$1634,"Y") -> 1531 | E25: =SUMIFS('SALES Raw'!$D$6:$D$1634,'SALES Raw'!$J$6:$J$1634,$J25,'SALES Raw'!$K$6:$K$1634,"Y") -> 18553.76 | F25: =SUMIFS('SALES Raw'!$E$6:$E$1634,'SALES Raw'!$J$6:$J$1634,$J25,'SALES Raw'!$K$6:$K$1634,"Y")*$H$4 -> 1505.6842 | G25: =SUMIFS('SALES Raw'!$F$6:$F$1634,'SALES Raw'!$J$6:$J$1634,$J25,'SALES Raw'!$K$6:$K$1634,"Y")*$H$4 -> 16714.32 | H25: 205 - Health Care Prod. Gmbh GERMANY | I25: 202 - Super-Pharm POLAND | J25: 4401001
A26: =IF(ISNUMBER($J26),$J26,"") -> 4420000 | B26: =IFERROR(INDEX('SALES Raw'!$B$6:$B$1634,MATCH($J26,'SALES Raw'!$J$6:$J$1634,0)),$J26) -> 370 0 | C26: =IF(ISNUMBER($J26),IFERROR(INDEX('TRANS'!$C:$C,MATCH($J26,'TRANS'!$B:$B,0)),IFERROR(INDEX('Catalog'!$B:$B,MATCH($J26,'Catalog'!$A:$A,0)),$B26)),$B26) -> 370 רפידת נוחות-זוג | D26: =SUMIFS('SALES Raw'!$C$6:$C$1634,'SALES Raw'!$J$6:$J$1634,$J26,'SALES Raw'!$K$6:$K$1634,"Y") -> 1640 | E26: =SUMIFS('SALES Raw'!$D$6:$D$1634,'SALES Raw'!$J$6:$J$1634,$J26,'SALES Raw'!$K$6:$K$1634,"Y") -> 10748.95 | F26: =SUMIFS('SALES Raw'!$E$6:$E$1634,'SALES Raw'!$J$6:$J$1634,$J26,'SALES Raw'!$K$6:$K$1634,"Y")*$H$4 -> 1429.8947 | G26: =SUMIFS('SALES Raw'!$F$6:$F$1634,'SALES Raw'!$J$6:$J$1634,$J26,'SALES Raw'!$K$6:$K$1634,"Y")*$H$4 -> 8489.2042 | H26: 202 - Super-Pharm POLAND | I26: 204 - Sanaflex Anatomic GREECE | J26: 4420000
A27: =IF(ISNUMBER($J27),$J27,"") -> 4413326 | B27: =IFERROR(INDEX('SALES Raw'!$B$6:$B$1634,MATCH($J27,'SALES Raw'!$J$6:$J$1634,0)),$J27) -> AC37 0 | C27: =IF(ISNUMBER($J27),IFERROR(INDEX('TRANS'!$C:$C,MATCH($J27,'TRANS'!$B:$B,0)),IFERROR(INDEX('Catalog'!$B:$B,MATCH($J27,'Catalog'!$A:$A,0)),$B27)),$B27) -> AC37 מגן קרסול נושם | D27: =SUMIFS('SALES Raw'!$C$6:$C$1634,'SALES Raw'!$J$6:$J$1634,$J27,'SALES Raw'!$K$6:$K$1634,"Y") -> 1655 | E27: =SUMIFS('SALES Raw'!$D$6:$D$1634,'SALES Raw'!$J$6:$J$1634,$J27,'SALES Raw'!$K$6:$K$1634,"Y") -> 34322.38 | F27: =SUMIFS('SALES Raw'!$E$6:$E$1634,'SALES Raw'!$J$6:$J$1634,$J27,'SALES Raw'!$K$6:$K$1634,"Y")*$H$4 -> 1418.5263 | G27: =SUMIFS('SALES Raw'!$F$6:$F$1634,'SALES Raw'!$J$6:$J$1634,$J27,'SALES Raw'!$K$6:$K$1634,"Y")*$H$4 -> 26127.865 | H27: 204 - Sanaflex Anatomic GREECE | I27: 202 - Super-Pharm POLAND | J27: 4413326
A28: =IF(ISNUMBER($J28),$J28,"") -> 4415162 | B28: =IFERROR(INDEX('SALES Raw'!$B$6:$B$1634,MATCH($J28,'SALES Raw'!$J$6:$J$1634,0)),$J28) -> 238 L | C28: =IF(ISNUMBER($J28),IFERROR(INDEX('TRANS'!$C:$C,MATCH($J28,'TRANS'!$B:$B,0)),IFERROR(INDEX('Catalog'!$B:$B,MATCH($J28,'Catalog'!$A:$A,0)),$B28)),$B28) -> 238L סד ליישור אצבע | D28: =SUMIFS('SALES Raw'!$C$6:$C$1634,'SALES Raw'!$J$6:$J$1634,$J28,'SALES Raw'!$K$6:$K$1634,"Y") -> 1361 | E28: =SUMIFS('SALES Raw'!$D$6:$D$1634,'SALES Raw'!$J$6:$J$1634,$J28,'SALES Raw'!$K$6:$K$1634,"Y") -> 11520.84 | F28: =SUMIFS('SALES Raw'!$E$6:$E$1634,'SALES Raw'!$J$6:$J$1634,$J28,'SALES Raw'!$K$6:$K$1634,"Y")*$H$4 -> 1405.8947 | G28: =SUMIFS('SALES Raw'!$F$6:$F$1634,'SALES Raw'!$J$6:$J$1634,$J28,'SALES Raw'!$K$6:$K$1634,"Y")*$H$4 -> 11276.337 | H28: 204 - Sanaflex Anatomic GREECE | I28: 207 - Salus HUNGARY | J28: 4415162
A29: =IF(ISNUMBER($J29),$J29,"") -> 4422025 | B29: =IFERROR(INDEX('SALES Raw'!$B$6:$B$1634,MATCH($J29,'SALES Raw'!$J$6:$J$1634,0)),$J29) -> 806CB-GR | C29: =IF(ISNUMBER($J29),IFERROR(INDEX('TRANS'!$C:$C,MATCH($J29,'TRANS'!$B:$B,0)),IFERROR(INDEX('Catalog'!$B:$B,MATCH($J29,'Catalog'!$A:$A,0)),$B29)),$B29) -> 806CB-GREEN תחבושת א.נצמ | D29: =SUMIFS('SALES Raw'!$C$6:$C$1634,'SALES Raw'!$J$6:$J$1634,$J29,'SALES Raw'!$K$6:$K$1634,"Y") -> 1344 | E29: =SUMIFS('SALES Raw'!$D$6:$D$1634,'SALES Raw'!$J$6:$J$1634,$J29,'SALES Raw'!$K$6:$K$1634,"Y") -> 10054.69 | F29: =SUMIFS('SALES Raw'!$E$6:$E$1634,'SALES Raw'!$J$6:$J$1634,$J29,'SALES Raw'!$K$6:$K$1634,"Y")*$H$4 -> 1268.2105 | G29: =SUMIFS('SALES Raw'!$F$6:$F$1634,'SALES Raw'!$J$6:$J$1634,$J29,'SALES Raw'!$K$6:$K$1634,"Y")*$H$4 -> 8633.4189 | H29: 202 - Super-Pharm POLAND | I29: 207 - Salus HUNGARY | J29: 4422025
A30: =IF(ISNUMBER($J30),$J30,"") -> 4413329 | B30: =IFERROR(INDEX('SALES Raw'!$B$6:$B$1634,MATCH($J30,'SALES Raw'!$J$6:$J$1634,0)),$J30) -> AC45X 0 | C30: =IF(ISNUMBER($J30),IFERROR(INDEX('TRANS'!$C:$C,MATCH($J30,'TRANS'!$B:$B,0)),IFERROR(INDEX('Catalog'!$B:$B,MATCH($J30,'Catalog'!$A:$A,0)),$B30)),$B30) -> AC45X מגן ברך עם תמיכות | D30: =SUMIFS('SALES Raw'!$C$6:$C$1634,'SALES Raw'!$J$6:$J$1634,$J30,'SALES Raw'!$K$6:$K$1634,"Y") -> 2250 | E30: =SUMIFS('SALES Raw'!$D$6:$D$1634,'SALES Raw'!$J$6:$J$1634,$J30,'SALES Raw'!$K$6:$K$1634,"Y") -> 82409.18 | F30: =SUMIFS('SALES Raw'!$E$6:$E$1634,'SALES Raw'!$J$6:$J$1634,$J30,'SALES Raw'!$K$6:$K$1634,"Y")*$H$4 -> 1248 | G30: =SUMIFS('SALES Raw'!$F$6:$F$1634,'SALES Raw'!$J$6:$J$1634,$J30,'SALES Raw'!$K$6:$K$1634,"Y")*$H$4 -> 41549.078 | H30: 204 - Sanaflex Anatomic GREECE | I30: 202 - Super-Pharm POLAND | J30: 4413329
A31: =IF(ISNUMBER($J31),$J31,"") -> 4415158 | B31: =IFERROR(INDEX('SALES Raw'!$B$6:$B$1634,MATCH($J31,'SALES Raw'!$J$6:$J$1634,0)),$J31) -> 266 0 | C31: =IF(ISNUMBER($J31),IFERROR(INDEX('TRANS'!$C:$C,MATCH($J31,'TRANS'!$B:$B,0)),IFERROR(INDEX('Catalog'!$B:$B,MATCH($J31,'Catalog'!$A:$A,0)),$B31)),$B31) -> 266 סד ליד דו צדדי | D31: =SUMIFS('SALES Raw'!$C$6:$C$1634,'SALES Raw'!$J$6:$J$1634,$J31,'SALES Raw'!$K$6:$K$1634,"Y") -> 1124 | E31: =SUMIFS('SALES Raw'!$D$6:$D$1634,'SALES Raw'!$J$6:$J$1634,$J31,'SALES Raw'!$K$6:$K$1634,"Y") -> 25315.91 | F31: =SUMIFS('SALES Raw'!$E$6:$E$1634,'SALES Raw'!$J$6:$J$1634,$J31,'SALES Raw'!$K$6:$K$1634,"Y")*$H$4 -> 1241.6842 | G31: =SUMIFS('SALES Raw'!$F$6:$F$1634,'SALES Raw'!$J$6:$J$1634,$J31,'SALES Raw'!$K$6:$K$1634,"Y")*$H$4 -> 25994.135 | H31: 204 - Sanaflex Anatomic GREECE | I31: 207 - Salus HUNGARY | J31: 4415158
A32: =IF(ISNUMBER($J32),$J32,"") | B32: =IFERROR(INDEX('SALES Raw'!$B$6:$B$1634,MATCH($J32,'SALES Raw'!$J$6:$J$1634,0)),$J32) -> 49PS M | C32: =IF(ISNUMBER($J32),IFERROR(INDEX('TRANS'!$C:$C,MATCH($J32,'TRANS'!$B:$B,0)),IFERROR(INDEX('Catalog'!$B:$B,MATCH($J32,'Catalog'!$A:$A,0)),$B32)),$B32) -> 49PS M | D32: =SUMIFS('SALES Raw'!$C$6:$C$1634,'SALES Raw'!$J$6:$J$1634,$J32,'SALES Raw'!$K$6:$K$1634,"Y") -> 1201 | E32: =SUMIFS('SALES Raw'!$D$6:$D$1634,'SALES Raw'!$J$6:$J$1634,$J32,'SALES Raw'!$K$6:$K$1634,"Y") -> 71527.56 | F32: =SUMIFS('SALES Raw'!$E$6:$E$1634,'SALES Raw'!$J$6:$J$1634,$J32,'SALES Raw'!$K$6:$K$1634,"Y")*$H$4 -> 1182.3158 | G32: =SUMIFS('SALES Raw'!$F$6:$F$1634,'SALES Raw'!$J$6:$J$1634,$J32,'SALES Raw'!$K$6:$K$1634,"Y")*$H$4 -> 64715.785 | H32: 203 - Ortho- Partner ag SWITZERLAND | J32: 49PS M
A33: =IF(ISNUMBER($J33),$J33,"") -> 4408205 | B33: =IFERROR(INDEX('SALES Raw'!$B$6:$B$1634,MATCH($J33,'SALES Raw'!$J$6:$J$1634,0)),$J33) -> AC07 0 | C33: =IF(ISNUMBER($J33),IFERROR(INDEX('TRANS'!$C:$C,MATCH($J33,'TRANS'!$B:$B,0)),IFERROR(INDEX('Catalog'!$B:$B,MATCH($J33,'Catalog'!$A:$A,0)),$B33)),$B33) -> AC-07 חגורת גב עם תמיכות | D33: =SUMIFS('SALES Raw'!$C$6:$C$1634,'SALES Raw'!$J$6:$J$1634,$J33,'SALES Raw'!$K$6:$K$1634,"Y") -> 1548 | E33: =SUMIFS('SALES Raw'!$D$6:$D$1634,'SALES Raw'!$J$6:$J$1634,$J33,'SALES Raw'!$K$6:$K$1634,"Y") -> 66533.35 | F33: =SUMIFS('SALES Raw'!$E$6:$E$1634,'SALES Raw'!$J$6:$J$1634,$J33,'SALES Raw'!$K$6:$K$1634,"Y")*$H$4 -> 1139.3684 | G33: =SUMIFS('SALES Raw'!$F$6:$F$1634,'SALES Raw'!$J$6:$J$1634,$J33,'SALES Raw'!$K$6:$K$1634,"Y")*$H$4 -> 42974.728 | H33: 204 - Sanaflex Anatomic GREECE | I33: 207 - Salus HUNGARY | J33: 4408205
A34: =IF(ISNUMBER($J34),$J34,"") -> 4401000 | B34: =IFERROR(INDEX('SALES Raw'!$B$6:$B$1634,MATCH($J34,'SALES Raw'!$J$6:$J$1634,0)),$J34) -> 369-S-L | C34: =IF(ISNUMBER($J34),IFERROR(INDEX('TRANS'!$C:$C,MATCH($J34,'TRANS'!$B:$B,0)),IFERROR(INDEX('Catalog'!$B:$B,MATCH($J34,'Catalog'!$A:$A,0)),$B34)),$B34) -> 369 S-L אצבעון מסיליקון יחידה | D34: =SUMIFS('SALES Raw'!$C$6:$C$1634,'SALES Raw'!$J$6:$J$1634,$J34,'SALES Raw'!$K$6:$K$1634,"Y") -> 1519 | E34: =SUMIFS('SALES Raw'!$D$6:$D$1634,'SALES Raw'!$J$6:$J$1634,$J34,'SALES Raw'!$K$6:$K$1634,"Y") -> 15947.17 | F34: =SUMIFS('SALES Raw'!$E$6:$E$1634,'SALES Raw'!$J$6:$J$1634,$J34,'SALES Raw'!$K$6:$K$1634,"Y")*$H$4 -> 1128 | G34: =SUMIFS('SALES Raw'!$F$6:$F$1634,'SALES Raw'!$J$6:$J$1634,$J34,'SALES Raw'!$K$6:$K$1634,"Y")*$H$4 -> 10840.029 | H34: 205 - Health Care Prod. Gmbh GERMANY | I34: 209 - Ortoprofil Prod ROMANIA | J34: 4401000
A35: =IF(ISNUMBER($J35),$J35,"") -> 4413060 | B35: =IFERROR(INDEX('SALES Raw'!$B$6:$B$1634,MATCH($J35,'SALES Raw'!$J$6:$J$1634,0)),$J35) -> 364 XL | C35: =IF(ISNUMBER($J35),IFERROR(INDEX('TRANS'!$C:$C,MATCH($J35,'TRANS'!$B:$B,0)),IFERROR(INDEX('Catalog'!$B:$B,MATCH($J35,'Catalog'!$A:$A,0)),$B35)),$B35) -> 364 XLמפריד אצבע סיליקון ליבלת | D35: =SUMIFS('SALES Raw'!$C$6:$C$1634,'SALES Raw'!$J$6:$J$1634,$J35,'SALES Raw'!$K$6:$K$1634,"Y") -> 1592 | E35: =SUMIFS('SALES Raw'!$D$6:$D$1634,'SALES Raw'!$J$6:$J$1634,$J35,'SALES Raw'!$K$6:$K$1634,"Y") -> 8854.48 | F35: =SUMIFS('SALES Raw'!$E$6:$E$1634,'SALES Raw'!$J$6:$J$1634,$J35,'SALES Raw'!$K$6:$K$1634,"Y")*$H$4 -> 1119.1579 | G35: =SUMIFS('SALES Raw'!$F$6:$F$1634,'SALES Raw'!$J$6:$J$1634,$J35,'SALES Raw'!$K$6:$K$1634,"Y")*$H$4 -> 5689.6168 | H35: 209 - Ortoprofil Prod ROMANIA | I35: 202 - Super-Pharm POLAND | J35: 4413060
A36: =IF(ISNUMBER($J36),$J36,"") -> 4415160 | B36: =IFERROR(INDEX('SALES Raw'!$B$6:$B$1634,MATCH($J36,'SALES Raw'!$J$6:$J$1634,0)),$J36) -> 238 S | C36: =IF(ISNUMBER($J36),IFERROR(INDEX('TRANS'!$C:$C,MATCH($J36,'TRANS'!$B:$B,0)),IFERROR(INDEX('Catalog'!$B:$B,MATCH($J36,'Catalog'!$A:$A,0)),$B36)),$B36) -> 238S סד ליישור אצבע | D36: =SUMIFS('SALES Raw'!$C$6:$C$1634,'SALES Raw'!$J$6:$J$1634,$J36,'SALES Raw'!$K$6:$K$1634,"Y") -> 1012 | E36: =SUMIFS('SALES Raw'!$D$6:$D$1634,'SALES Raw'!$J$6:$J$1634,$J36,'SALES Raw'!$K$6:$K$1634,"Y") -> 8535.53 | F36: =SUMIFS('SALES Raw'!$E$6:$E$1634,'SALES Raw'!$J$6:$J$1634,$J36,'SALES Raw'!$K$6:$K$1634,"Y")*$H$4 -> 1091.3684 | G36: =SUMIFS('SALES Raw'!$F$6:$F$1634,'SALES Raw'!$J$6:$J$1634,$J36,'SALES Raw'!$K$6:$K$1634,"Y")*$H$4 -> 8753.8484 | H36: 207 - Salus HUNGARY | I36: 204 - Sanaflex Anatomic GREECE | J36: 4415160
A37: =IF(ISNUMBER($J37),$J37,"") | B37: =IFERROR(INDEX('SALES Raw'!$B$6:$B$1634,MATCH($J37,'SALES Raw'!$J$6:$J$1634,0)),$J37) -> 305-43-44 | C37: =IF(ISNUMBER($J37),IFERROR(INDEX('TRANS'!$C:$C,MATCH($J37,'TRANS'!$B:$B,0)),IFERROR(INDEX('Catalog'!$B:$B,MATCH($J37,'Catalog'!$A:$A,0)),$B37)),$B37) -> 305-43-44 | D37: =SUMIFS('SALES Raw'!$C$6:$C$1634,'SALES Raw'!$J$6:$J$1634,$J37,'SALES Raw'!$K$6:$K$1634,"Y") -> 1060 | E37: =SUMIFS('SALES Raw'!$D$6:$D$1634,'SALES Raw'!$J$6:$J$1634,$J37,'SALES Raw'!$K$6:$K$1634,"Y") -> 36441.37 | F37: =SUMIFS('SALES Raw'!$E$6:$E$1634,'SALES Raw'!$J$6:$J$1634,$J37,'SALES Raw'!$K$6:$K$1634,"Y")*$H$4 -> 1035.7895 | G37: =SUMIFS('SALES Raw'!$F$6:$F$1634,'SALES Raw'!$J$6:$J$1634,$J37,'SALES Raw'!$K$6:$K$1634,"Y")*$H$4 -> 34898.021 | H37: 209 - Ortoprofil Prod ROMANIA | I37: 204 - Sanaflex Anatomic GREECE | J37: 305-43-44
A38: =IF(ISNUMBER($J38),$J38,"") -> 4408208 | B38: =IFERROR(INDEX('SALES Raw'!$B$6:$B$1634,MATCH($J38,'SALES Raw'!$J$6:$J$1634,0)),$J38) -> AC91 0 | C38: =IF(ISNUMBER($J38),IFERROR(INDEX('TRANS'!$C:$C,MATCH($J38,'TRANS'!$B:$B,0)),IFERROR(INDEX('Catalog'!$B:$B,MATCH($J38,'Catalog'!$A:$A,0)),$B38)),$B38) -> AC91 חבק טניס | D38: =SUMIFS('SALES Raw'!$C$6:$C$1634,'SALES Raw'!$J$6:$J$1634,$J38,'SALES Raw'!$K$6:$K$1634,"Y") -> 1266 | E38: =SUMIFS('SALES Raw'!$D$6:$D$1634,'SALES Raw'!$J$6:$J$1634,$J38,'SALES Raw'!$K$6:$K$1634,"Y") -> 20026.99 | F38: =SUMIFS('SALES Raw'!$E$6:$E$1634,'SALES Raw'!$J$6:$J$1634,$J38,'SALES Raw'!$K$6:$K$1634,"Y")*$H$4 -> 1029.4737 | G38: =SUMIFS('SALES Raw'!$F$6:$F$1634,'SALES Raw'!$J$6:$J$1634,$J38,'SALES Raw'!$K$6:$K$1634,"Y")*$H$4 -> 15668.362 | H38: 204 - Sanaflex Anatomic GREECE | I38: 207 - Salus HUNGARY | J38: 4408208
A39: =IF(ISNUMBER($J39),$J39,"") -> 4416000 | B39: =IFERROR(INDEX('SALES Raw'!$B$6:$B$1634,MATCH($J39,'SALES Raw'!$J$6:$J$1634,0)),$J39) -> 307 L | C39: =IF(ISNUMBER($J39),IFERROR(INDEX('TRANS'!$C:$C,MATCH($J39,'TRANS'!$B:$B,0)),IFERROR(INDEX('Catalog'!$B:$B,MATCH($J39,'Catalog'!$A:$A,0)),$B39)),$B39) -> 307 L עקבים לדורבן-זוג כריות | D39: =SUMIFS('SALES Raw'!$C$6:$C$1634,'SALES Raw'!$J$6:$J$1634,$J39,'SALES Raw'!$K$6:$K$1634,"Y") -> 926 | E39: =SUMIFS('SALES Raw'!$D$6:$D$1634,'SALES Raw'!$J$6:$J$1634,$J39,'SALES Raw'!$K$6:$K$1634,"Y") -> 29317.24 | F39: =SUMIFS('SALES Raw'!$E$6:$E$1634,'SALES Raw'!$J$6:$J$1634,$J39,'SALES Raw'!$K$6:$K$1634,"Y")*$H$4 -> 1020.6316 | G39: =SUMIFS('SALES Raw'!$F$6:$F$1634,'SALES Raw'!$J$6:$J$1634,$J39,'SALES Raw'!$K$6:$K$1634,"Y")*$H$4 -> 29800.282 | H39: 209 - Ortoprofil Prod ROMANIA | I39: 202 - Super-Pharm POLAND | J39: 4416000
A40: =IF(ISNUMBER($J40),$J40,"") -> 4408270 | B40: =IFERROR(INDEX('SALES Raw'!$B$6:$B$1634,MATCH($J40,'SALES Raw'!$J$6:$J$1634,0)),$J40) -> ST11 0 | C40: =IF(ISNUMBER($J40),IFERROR(INDEX('TRANS'!$C:$C,MATCH($J40,'TRANS'!$B:$B,0)),IFERROR(INDEX('Catalog'!$B:$B,MATCH($J40,'Catalog'!$A:$A,0)),$B40)),$B40) -> ST11 חגורת בטן | D40: =SUMIFS('SALES Raw'!$C$6:$C$1634,'SALES Raw'!$J$6:$J$1634,$J40,'SALES Raw'!$K$6:$K$1634,"Y") -> 201 | E40: =SUMIFS('SALES Raw'!$D$6:$D$1634,'SALES Raw'!$J$6:$J$1634,$J40,'SALES Raw'!$K$6:$K$1634,"Y") -> 5487.51 | F40: =SUMIFS('SALES Raw'!$E$6:$E$1634,'SALES Raw'!$J$6:$J$1634,$J40,'SALES Raw'!$K$6:$K$1634,"Y")*$H$4 -> 1008 | G40: =SUMIFS('SALES Raw'!$F$6:$F$1634,'SALES Raw'!$J$6:$J$1634,$J40,'SALES Raw'!$K$6:$K$1634,"Y")*$H$4 -> 40878.126 | H40: 207 - Salus HUNGARY | I40: 213 - E.f.m.o. SPAIN | J40: 4408270
A41: =IF(ISNUMBER($J41),$J41,"") -> 4416001 | B41: =IFERROR(INDEX('SALES Raw'!$B$6:$B$1634,MATCH($J41,'SALES Raw'!$J$6:$J$1634,0)),$J41) -> 307 M | C41: =IF(ISNUMBER($J41),IFERROR(INDEX('TRANS'!$C:$C,MATCH($J41,'TRANS'!$B:$B,0)),IFERROR(INDEX('Catalog'!$B:$B,MATCH($J41,'Catalog'!$A:$A,0)),$B41)),$B41) -> 307 M עקבים לדורבן-זוג כריות | D41: =SUMIFS('SALES Raw'!$C$6:$C$1634,'SALES Raw'!$J$6:$J$1634,$J41,'SALES Raw'!$K$6:$K$1634,"Y") -> 1127 | E41: =SUMIFS('SALES Raw'!$D$6:$D$1634,'SALES Raw'!$J$6:$J$1634,$J41,'SALES Raw'!$K$6:$K$1634,"Y") -> 35825.85 | F41: =SUMIFS('SALES Raw'!$E$6:$E$1634,'SALES Raw'!$J$6:$J$1634,$J41,'SALES Raw'!$K$6:$K$1634,"Y")*$H$4 -> 960 | G41: =SUMIFS('SALES Raw'!$F$6:$F$1634,'SALES Raw'!$J$6:$J$1634,$J41,'SALES Raw'!$K$6:$K$1634,"Y")*$H$4 -> 28228.004 | H41: 209 - Ortoprofil Prod ROMANIA | I41: 202 - Super-Pharm POLAND | J41: 4416001
...

Sheet 301 - Amazon
A1: 301 - Amazon
A2: Calculation date: | B2: 46290
A3: 301 - Amazon - Source: kirill/outputs/2026-09-20-salestype-2025-vs-2026.xlsx, "Source" sheet, Sale Type = "301 - Amazon". Kept as its OWN separate sheet per explicit instruction - NOT included in "Main List" or any consolidated total (mirrors the 111/112 pattern in the ITEMISR file). No 0.91 factor (NetSuite-sourced). 2026 normalized to a full year (×12/9.5). Same columns/sort/coloring convention as Main List (DROP/NEW uses the same near-zero tolerance, ROUND(...,2)=0). Cross-validated against this same source file's own native "301 - Amazon" sheet DROP/NEW totals - exact match.
A4: Normalization factor (2026, full year): | G4: Factor (12/9.5): | H4: =12/9.5 -> 1.2631579
A6: CHEMIPAL Code | B6: ITEM NAME | C6: שם מוצר | D6: כמות 2025 | E6: כסף 2025 (₪) | F6: כמות 2026 (מנורמל) | G6: כסף 2026 (מנורמל, ₪) | H6: Source Category
A7: ='SALES Raw'!G551 -> 4414000 | B7: ='SALES Raw'!B551 -> FC342 0 | C7: ='SALES Raw'!H551 -> FC342-נוזל לציפורן חודרנית | D7: ='SALES Raw'!C551 -> 16341 | E7: ='SALES Raw'!D551 -> 1097384.5 | F7: ='SALES Raw'!E551*$H$4 -> 14886.316 | G7: ='SALES Raw'!F551*$H$4 -> 891741.8 | H7: ='SALES Raw'!A551 -> 301 - Amazon
A8: ='SALES Raw'!G543 | B8: ='SALES Raw'!B543 -> EC-59RB M | C8: ='SALES Raw'!H543 -> EC-59RB M | D8: ='SALES Raw'!C543 -> 769 | E8: ='SALES Raw'!D543 -> 135894.77 | F8: ='SALES Raw'!E543*$H$4 -> 1447.5789 | G8: ='SALES Raw'!F543*$H$4 -> 232249 | H8: ='SALES Raw'!A543 -> 301 - Amazon
A9: ='SALES Raw'!G552 | B9: ='SALES Raw'!B552 -> FC3422 0 | C9: ='SALES Raw'!H552 -> FC3422 0 | D9: ='SALES Raw'!C552 -> 1355 | E9: ='SALES Raw'!D552 -> 109768.29 | F9: ='SALES Raw'!E552*$H$4 -> 947.36842 | G9: ='SALES Raw'!F552*$H$4 -> 71485.301 | H9: ='SALES Raw'!A552 -> 301 - Amazon
A10: ='SALES Raw'!G553 | B10: ='SALES Raw'!B553 -> FC342K 0 | C10: ='SALES Raw'!H553 -> FC342K 0 | D10: ='SALES Raw'!C553 -> 1189 | E10: ='SALES Raw'!D553 -> 85731.85 | F10: ='SALES Raw'!E553*$H$4 -> 600 | G10: ='SALES Raw'!F553*$H$4 -> 41214.493 | H10: ='SALES Raw'!A553 -> 301 - Amazon
A11: ='SALES Raw'!G538 | B11: ='SALES Raw'!B538 -> EC-59LB M | C11: ='SALES Raw'!H538 -> EC-59LB M | D11: ='SALES Raw'!C538 -> 324 | E11: ='SALES Raw'!D538 -> 58442.65 | F11: ='SALES Raw'!E538*$H$4 -> 442.10526 | G11: ='SALES Raw'!F538*$H$4 -> 70977.714 | H11: ='SALES Raw'!A538 -> 301 - Amazon
A12: ='SALES Raw'!G528 | B12: ='SALES Raw'!B528 -> EC-59R M | C12: ='SALES Raw'!H528 -> EC-59R M | D12: ='SALES Raw'!C528 -> 1141 | E12: ='SALES Raw'!D528 -> 191075.16 | F12: ='SALES Raw'!E528*$H$4 -> 433.26316 | G12: ='SALES Raw'!F528*$H$4 -> 69735.537 | H12: ='SALES Raw'!A528 -> 301 - Amazon
A13: ='SALES Raw'!G544 | B13: ='SALES Raw'!B544 -> EC-59RB S | C13: ='SALES Raw'!H544 -> EC-59RB S | D13: ='SALES Raw'!C544 -> 384 | E13: ='SALES Raw'!D544 -> 68602.16 | F13: ='SALES Raw'!E544*$H$4 -> 411.78947 | G13: ='SALES Raw'!F544*$H$4 -> 65201.469 | H13: ='SALES Raw'!A544 -> 301 - Amazon
A14: ='SALES Raw'!G524 | B14: ='SALES Raw'!B524 -> EC-59L M | C14: ='SALES Raw'!H524 -> EC-59L M | D14: ='SALES Raw'!C524 -> 670 | E14: ='SALES Raw'!D524 -> 119782.01 | F14: ='SALES Raw'!E524*$H$4 -> 395.36842 | G14: ='SALES Raw'!F524*$H$4 -> 63066.328 | H14: ='SALES Raw'!A524 -> 301 - Amazon
A15: ='SALES Raw'!G542 | B15: ='SALES Raw'!B542 -> EC-59RB L | C15: ='SALES Raw'!H542 -> EC-59RB L | D15: ='SALES Raw'!C542 -> 268 | E15: ='SALES Raw'!D542 -> 47354.81 | F15: ='SALES Raw'!E542*$H$4 -> 256.42105 | G15: ='SALES Raw'!F542*$H$4 -> 41671.099 | H15: ='SALES Raw'!A542 -> 301 - Amazon
A16: ='SALES Raw'!G499 -> 4415029 | B16: ='SALES Raw'!B499 -> 237 0 | C16: ='SALES Raw'!H499 -> סד קיבוע לאצבע הדק | D16: ='SALES Raw'!C499 -> 12 | E16: ='SALES Raw'!D499 -> 705.87 | F16: ='SALES Raw'!E499*$H$4 -> 246.31579 | G16: ='SALES Raw'!F499*$H$4 -> 11803.263 | H16: ='SALES Raw'!A499 -> 301 - Amazon
A17: ='SALES Raw'!G529 | B17: ='SALES Raw'!B529 -> EC-59R S | C17: ='SALES Raw'!H529 -> EC-59R S | D17: ='SALES Raw'!C529 -> 502 | E17: ='SALES Raw'!D529 -> 92438.48 | F17: ='SALES Raw'!E529*$H$4 -> 238.73684 | G17: ='SALES Raw'!F529*$H$4 -> 38432.451 | H17: ='SALES Raw'!A529 -> 301 - Amazon
A18: ='SALES Raw'!G539 | B18: ='SALES Raw'!B539 -> EC-59LB S | C18: ='SALES Raw'!H539 -> EC-59LB S | D18: ='SALES Raw'!C539 -> 243 | E18: ='SALES Raw'!D539 -> 43557.14 | F18: ='SALES Raw'!E539*$H$4 -> 233.68421 | G18: ='SALES Raw'!F539*$H$4 -> 37462.762 | H18: ='SALES Raw'!A539 -> 301 - Amazon
A19: ='SALES Raw'!G494 | B19: ='SALES Raw'!B494 -> EC-11STOB XXL | C19: ='SALES Raw'!H494 -> EC-11STOB XXL | D19: ='SALES Raw'!C494 -> 86 | E19: ='SALES Raw'!D494 -> 10105.03 | F19: ='SALES Raw'!E494*$H$4 -> 190.73684 | G19: ='SALES Raw'!F494*$H$4 -> 23874.24 | H19: ='SALES Raw'!A494 -> 301 - Amazon
A20: ='SALES Raw'!G533 | B20: ='SALES Raw'!B533 -> EC-59DB M | C20: ='SALES Raw'!H533 -> EC-59DB M | D20: ='SALES Raw'!C533 -> 125 | E20: ='SALES Raw'!D533 -> 23137.22 | F20: ='SALES Raw'!E533*$H$4 -> 190.73684 | G20: ='SALES Raw'!F533*$H$4 -> 31900.446 | H20: ='SALES Raw'!A533 -> 301 - Amazon
A21: ='SALES Raw'!G519 | B21: ='SALES Raw'!B519 -> EC-59D M | C21: ='SALES Raw'!H519 -> EC-59D M | D21: ='SALES Raw'!C519 -> 346 | E21: ='SALES Raw'!D519 -> 66008.37 | F21: ='SALES Raw'!E519*$H$4 -> 185.68421 | G21: ='SALES Raw'!F519*$H$4 -> 31333.592 | H21: ='SALES Raw'!A519 -> 301 - Amazon
A22: ='SALES Raw'!G493 | B22: ='SALES Raw'!B493 -> EC-11STOB XL | C22: ='SALES Raw'!H493 -> EC-11STOB XL | D22: ='SALES Raw'!C493 -> 86 | E22: ='SALES Raw'!D493 -> 11577.1 | F22: ='SALES Raw'!E493*$H$4 -> 178.10526 | G22: ='SALES Raw'!F493*$H$4 -> 23441.381 | H22: ='SALES Raw'!A493 -> 301 - Amazon
A23: ='SALES Raw'!G527 | B23: ='SALES Raw'!B527 -> EC-59R L | C23: ='SALES Raw'!H527 -> EC-59R L | D23: ='SALES Raw'!C527 -> 403 | E23: ='SALES Raw'!D527 -> 73333.84 | F23: ='SALES Raw'!E527*$H$4 -> 178.10526 | G23: ='SALES Raw'!F527*$H$4 -> 28441.389 | H23: ='SALES Raw'!A527 -> 301 - Amazon
A24: ='SALES Raw'!G510 -> 4421000 | B24: ='SALES Raw'!B510 -> 3655 0 | C24: ='SALES Raw'!H510 -> 3655 שרוול מסיליקון לאצבע | D24: ='SALES Raw'!C510 -> 28 | E24: ='SALES Raw'!D510 -> 1182.08 | F24: ='SALES Raw'!E510*$H$4 -> 170.52632 | G24: ='SALES Raw'!F510*$H$4 -> 6808.6611 | H24: ='SALES Raw'!A510 -> 301 - Amazon
A25: ='SALES Raw'!G490 | B25: ='SALES Raw'!B490 -> EC-11STOB L | C25: ='SALES Raw'!H490 -> EC-11STOB L | D25: ='SALES Raw'!C490 -> 91 | E25: ='SALES Raw'!D490 -> 12484.46 | F25: ='SALES Raw'!E490*$H$4 -> 159.15789 | G25: ='SALES Raw'!F490*$H$4 -> 20754.922 | H25: ='SALES Raw'!A490 -> 301 - Amazon
A26: ='SALES Raw'!G525 | B26: ='SALES Raw'!B525 -> EC-59L S | C26: ='SALES Raw'!H525 -> EC-59L S | D26: ='SALES Raw'!C525 -> 222 | E26: ='SALES Raw'!D525 -> 40212.55 | F26: ='SALES Raw'!E525*$H$4 -> 151.57895 | G26: ='SALES Raw'!F525*$H$4 -> 24526.787 | H26: ='SALES Raw'!A525 -> 301 - Amazon
A27: ='SALES Raw'!G537 | B27: ='SALES Raw'!B537 -> EC-59LB L | C27: ='SALES Raw'!H537 -> EC-59LB L | D27: ='SALES Raw'!C537 -> 128 | E27: ='SALES Raw'!D537 -> 22838.32 | F27: ='SALES Raw'!E537*$H$4 -> 145.26316 | G27: ='SALES Raw'!F537*$H$4 -> 23300.981 | H27: ='SALES Raw'!A537 -> 301 - Amazon
A28: ='SALES Raw'!G523 | B28: ='SALES Raw'!B523 -> EC-59L L | C28: ='SALES Raw'!H523 -> EC-59L L | D28: ='SALES Raw'!C523 -> 225 | E28: ='SALES Raw'!D523 -> 41045.21 | F28: ='SALES Raw'!E523*$H$4 -> 144 | G28: ='SALES Raw'!F523*$H$4 -> 23521.238 | H28: ='SALES Raw'!A523 -> 301 - Amazon
A29: ='SALES Raw'!G485 | B29: ='SALES Raw'!B485 -> EC-11STO L | C29: ='SALES Raw'!H485 -> EC-11STO L | D29: ='SALES Raw'!C485 -> 177 | E29: ='SALES Raw'!D485 -> 24684.59 | F29: ='SALES Raw'!E485*$H$4 -> 137.68421 | G29: ='SALES Raw'!F485*$H$4 -> 18322.825 | H29: ='SALES Raw'!A485 -> 301 - Amazon
A30: ='SALES Raw'!G520 | B30: ='SALES Raw'!B520 -> EC-59D S | C30: ='SALES Raw'!H520 -> EC-59D S | D30: ='SALES Raw'!C520 -> 175 | E30: ='SALES Raw'!D520 -> 33651.11 | F30: ='SALES Raw'!E520*$H$4 -> 113.68421 | G30: ='SALES Raw'!F520*$H$4 -> 20181.461 | H30: ='SALES Raw'!A520 -> 301 - Amazon
A31: ='SALES Raw'!G534 | B31: ='SALES Raw'!B534 -> EC-59DB S | C31: ='SALES Raw'!H534 -> EC-59DB S | D31: ='SALES Raw'!C534 -> 49 | E31: ='SALES Raw'!D534 -> 9171.45 | F31: ='SALES Raw'!E534*$H$4 -> 106.10526 | G31: ='SALES Raw'!F534*$H$4 -> 17979.158 | H31: ='SALES Raw'!A534 -> 301 - Amazon
A32: ='SALES Raw'!G486 | B32: ='SALES Raw'!B486 -> EC-11STO M | C32: ='SALES Raw'!H486 -> EC-11STO M | D32: ='SALES Raw'!C486 -> 125 | E32: ='SALES Raw'!D486 -> 16991.76 | F32: ='SALES Raw'!E486*$H$4 -> 97.263158 | G32: ='SALES Raw'!F486*$H$4 -> 12988.219 | H32: ='SALES Raw'!A486 -> 301 - Amazon
A33: ='SALES Raw'!G491 | B33: ='SALES Raw'!B491 -> EC-11STOB M | C33: ='SALES Raw'!H491 -> EC-11STOB M | D33: ='SALES Raw'!C491 -> 16 | E33: ='SALES Raw'!D491 -> 2183.52 | F33: ='SALES Raw'!E491*$H$4 -> 97.263158 | G33: ='SALES Raw'!F491*$H$4 -> 11556.379 | H33: ='SALES Raw'!A491 -> 301 - Amazon
A34: ='SALES Raw'!G518 | B34: ='SALES Raw'!B518 -> EC-59D L | C34: ='SALES Raw'!H518 -> EC-59D L | D34: ='SALES Raw'!C518 -> 125 | E34: ='SALES Raw'!D518 -> 23867.72 | F34: ='SALES Raw'!E518*$H$4 -> 96 | G34: ='SALES Raw'!F518*$H$4 -> 16136.135 | H34: ='SALES Raw'!A518 -> 301 - Amazon
A35: ='SALES Raw'!G508 -> 4413059 | B35: ='SALES Raw'!B508 -> 364-S-L | C35: ='SALES Raw'!H508 -> 364S Lמפר.אצבע סיליק. ליבל.זוג | D35: ='SALES Raw'!C508 -> 33 | E35: ='SALES Raw'!D508 -> 1082.62 | F35: ='SALES Raw'!E508*$H$4 -> 92.210526 | G35: ='SALES Raw'!F508*$H$4 -> 2789.0653 | H35: ='SALES Raw'!A508 -> 301 - Amazon
A36: ='SALES Raw'!G483 | B36: ='SALES Raw'!B483 -> EC-11NOR XL | C36: ='SALES Raw'!H483 -> EC-11NOR XL | D36: ='SALES Raw'!C483 -> 191 | E36: ='SALES Raw'!D483 -> 26070.58 | F36: ='SALES Raw'!E483*$H$4 -> 82.105263 | G36: ='SALES Raw'!F483*$H$4 -> 10279.516 | H36: ='SALES Raw'!A483 -> 301 - Amazon
A37: ='SALES Raw'!G489 | B37: ='SALES Raw'!B489 -> EC-11STO XXL | C37: ='SALES Raw'!H489 -> EC-11STO XXL | D37: ='SALES Raw'!C489 -> 224 | E37: ='SALES Raw'!D489 -> 30949.19 | F37: ='SALES Raw'!E489*$H$4 -> 77.052632 | G37: ='SALES Raw'!F489*$H$4 -> 10383.335 | H37: ='SALES Raw'!A489 -> 301 - Amazon
A38: ='SALES Raw'!G532 | B38: ='SALES Raw'!B532 -> EC-59DB L | C38: ='SALES Raw'!H532 -> EC-59DB L | D38: ='SALES Raw'!C532 -> 60 | E38: ='SALES Raw'!D532 -> 11413.11 | F38: ='SALES Raw'!E532*$H$4 -> 73.263158 | G38: ='SALES Raw'!F532*$H$4 -> 12205.023 | H38: ='SALES Raw'!A532 -> 301 - Amazon
A39: ='SALES Raw'!G488 | B39: ='SALES Raw'!B488 -> EC-11STO XL | C39: ='SALES Raw'!H488 -> EC-11STO XL | D39: ='SALES Raw'!C488 -> 195 | E39: ='SALES Raw'!D488 -> 27208.51 | F39: ='SALES Raw'!E488*$H$4 -> 66.947368 | G39: ='SALES Raw'!F488*$H$4 -> 9125.76 | H39: ='SALES Raw'!A488 -> 301 - Amazon
A40: ='SALES Raw'!G514 -> 4413452 | B40: ='SALES Raw'!B514 -> 386 0 | C40: ='SALES Raw'!H514 -> 386 מיישר בוניון-האלוקס ולגוס | D40: ='SALES Raw'!C514 -> 51 | E40: ='SALES Raw'!D514 -> 4500.68 | F40: ='SALES Raw'!E514*$H$4 -> 61.894737 | G40: ='SALES Raw'!F514*$H$4 -> 4031.0021 | H40: ='SALES Raw'!A514 -> 301 - Amazon
A41: ='SALES Raw'!G507 -> 4421007 | B41: ='SALES Raw'!B507 -> 350 0 | C41: ='SALES Raw'!H507 -> שרוול לגבס קצר רגל | D41: ='SALES Raw'!C507 -> 12 | E41: ='SALES Raw'!D507 -> 859.76 | F41: ='SALES Raw'!E507*$H$4 -> 36.631579 | G41: ='SALES Raw'!F507*$H$4 -> 2828.16 | H41: ='SALES Raw'!A507 -> 301 - Amazon
...

Sheet SALES Raw
A1: SALES Raw — item-level data (pre-aggregated per category+item) for all 16 distributor categories | O1: (scope ref list for Main List, col O - the 15 DIRECT categories, excludes 301-Amazon)
A2: Calculation date: | B2: 46290 | O2: 202 - Super-Pharm POLAND
A3: Source: kirill/outputs/2026-09-20-salestype-2025-vs-2026.xlsx, "Source" sheet, filtered per Sale Type (15 categories that feed the Main List + "301 - Amazon" which gets its own separate sheet). No 0.91 factor (NetSuite-sourced). Quantity/Amount 2026 here are RAW ACTUAL (pre-normalization) - normalization happens in the Main List / 301-Amazon sheets' formulas. CHEMIPAL Code matched live: TRANS (primary) then Catalog (fallback), each exact then normalized. | O3: 201- Seven Gear FINLAND oy
O4: 216 - Max Konnaris CYPRUS
A5: Category | B5: Item Name (raw) | C5: Quantity 2025 | D5: Amount 2025 (₪) | E5: Quantity 2026 (raw actual) | F5: Amount 2026 (raw actual, ₪) | G5: CHEMIPAL Code | H5: Product Name | I5: Match Type | J5: Product Key | K5: Main List Scope (15, excl. Amazon) | O5: 200 - ROW : 217 - N3W FOODS USA
A6: 202 - Super-Pharm POLAND | B6: 078 L | C6: 0 | D6: 0 | E6: 40 | F6: 2484.42 | G6: =IFERROR(INDEX('TRANS'!$B:$B,MATCH($B6,'TRANS'!$A:$A,0)),IFERROR(INDEX('TRANS'!$B:$B,MATCH(TRIM(SUBSTITUTE($B6,CHAR(160)," ")),'TRANS'!$D:$D,0)),IFERROR(INDEX('Catalog'!$A:$A,MATCH($B6,'Catalog'!$B:$B,0)),IFERROR(INDEX('Catalog'!$A:$A,MATCH(TRIM(SUBSTITUTE($B6,CHAR(160)," ")),'Catalog'!$C:$C,0)),"")))) -> 4408192 | H6: =IFERROR(INDEX('TRANS'!$C:$C,MATCH($B6,'TRANS'!$A:$A,0)),IFERROR(INDEX('Catalog'!$B:$B,MATCH($G6,'Catalog'!$A:$A,0)),$B6)) -> 078 L חגורת גב +סגירה | I6: =IF($G6="","Unmatched","Matched") -> Matched | J6: =IF($G6<>"",$G6,$B6) -> 4408192 | K6: =IF(COUNTIF($O$2:$O$16,$A6)>0,"Y","N") -> Y | O6: 205 - Health Care Prod. Gmbh GERMANY
A7: 202 - Super-Pharm POLAND | B7: 078 M | C7: 0 | D7: 0 | E7: 50 | F7: 3105.52 | G7: =IFERROR(INDEX('TRANS'!$B:$B,MATCH($B7,'TRANS'!$A:$A,0)),IFERROR(INDEX('TRANS'!$B:$B,MATCH(TRIM(SUBSTITUTE($B7,CHAR(160)," ")),'TRANS'!$D:$D,0)),IFERROR(INDEX('Catalog'!$A:$A,MATCH($B7,'Catalog'!$B:$B,0)),IFERROR(INDEX('Catalog'!$A:$A,MATCH(TRIM(SUBSTITUTE($B7,CHAR(160)," ")),'Catalog'!$C:$C,0)),"")))) -> 4408190 | H7: =IFERROR(INDEX('TRANS'!$C:$C,MATCH($B7,'TRANS'!$A:$A,0)),IFERROR(INDEX('Catalog'!$B:$B,MATCH($G7,'Catalog'!$A:$A,0)),$B7)) -> M078 חגורת גב +סגירה כפולה | I7: =IF($G7="","Unmatched","Matched") -> Matched | J7: =IF($G7<>"",$G7,$B7) -> 4408190 | K7: =IF(COUNTIF($O$2:$O$16,$A7)>0,"Y","N") -> Y | O7: 206 - Orthomed Ltd BULGARIA
A8: 202 - Super-Pharm POLAND | B8: 078 S | C8: 0 | D8: 0 | E8: 30 | F8: 1882.66 | G8: =IFERROR(INDEX('TRANS'!$B:$B,MATCH($B8,'TRANS'!$A:$A,0)),IFERROR(INDEX('TRANS'!$B:$B,MATCH(TRIM(SUBSTITUTE($B8,CHAR(160)," ")),'TRANS'!$D:$D,0)),IFERROR(INDEX('Catalog'!$A:$A,MATCH($B8,'Catalog'!$B:$B,0)),IFERROR(INDEX('Catalog'!$A:$A,MATCH(TRIM(SUBSTITUTE($B8,CHAR(160)," ")),'Catalog'!$C:$C,0)),"")))) -> 4408217 | H8: =IFERROR(INDEX('TRANS'!$C:$C,MATCH($B8,'TRANS'!$A:$A,0)),IFERROR(INDEX('Catalog'!$B:$B,MATCH($G8,'Catalog'!$A:$A,0)),$B8)) -> S078 חגורת גב +סגירה כפולה | I8: =IF($G8="","Unmatched","Matched") -> Matched | J8: =IF($G8<>"",$G8,$B8) -> 4408217 | K8: =IF(COUNTIF($O$2:$O$16,$A8)>0,"Y","N") -> Y | O8: 203 - Ortho- Partner ag SWITZERLAND
A9: 202 - Super-Pharm POLAND | B9: 078 XL | C9: 0 | D9: 0 | E9: 40 | F9: 2484.42 | G9: =IFERROR(INDEX('TRANS'!$B:$B,MATCH($B9,'TRANS'!$A:$A,0)),IFERROR(INDEX('TRANS'!$B:$B,MATCH(TRIM(SUBSTITUTE($B9,CHAR(160)," ")),'TRANS'!$D:$D,0)),IFERROR(INDEX('Catalog'!$A:$A,MATCH($B9,'Catalog'!$B:$B,0)),IFERROR(INDEX('Catalog'!$A:$A,MATCH(TRIM(SUBSTITUTE($B9,CHAR(160)," ")),'Catalog'!$C:$C,0)),"")))) -> 4408218 | H9: =IFERROR(INDEX('TRANS'!$C:$C,MATCH($B9,'TRANS'!$A:$A,0)),IFERROR(INDEX('Catalog'!$B:$B,MATCH($G9,'Catalog'!$A:$A,0)),$B9)) -> 078XL חגורת גב +סגירה כפולה | I9: =IF($G9="","Unmatched","Matched") -> Matched | J9: =IF($G9<>"",$G9,$B9) -> 4408218 | K9: =IF(COUNTIF($O$2:$O$16,$A9)>0,"Y","N") -> Y | O9: 210 - Oy. Ea. Ab. FINLAND
A10: 202 - Super-Pharm POLAND | B10: 078G L | C10: 190 | D10: 13475.39 | E10: 80 | F10: 4998.35 | G10: =IFERROR(INDEX('TRANS'!$B:$B,MATCH($B10,'TRANS'!$A:$A,0)),IFERROR(INDEX('TRANS'!$B:$B,MATCH(TRIM(SUBSTITUTE($B10,CHAR(160)," ")),'TRANS'!$D:$D,0)),IFERROR(INDEX('Catalog'!$A:$A,MATCH($B10,'Catalog'!$B:$B,0)),IFERROR(INDEX('Catalog'!$A:$A,MATCH(TRIM(SUBSTITUTE($B10,CHAR(160)," ")),'Catalog'!$C:$C,0)),"")))) -> 4408221 | H10: =IFERROR(INDEX('TRANS'!$C:$C,MATCH($B10,'TRANS'!$A:$A,0)),IFERROR(INDEX('Catalog'!$B:$B,MATCH($G10,'Catalog'!$A:$A,0)),$B10)) -> 078G-L חגורת גב אפורה | I10: =IF($G10="","Unmatched","Matched") -> Matched | J10: =IF($G10<>"",$G10,$B10) -> 4408221 | K10: =IF(COUNTIF($O$2:$O$16,$A10)>0,"Y","N") -> Y | O10: 204 - Sanaflex Anatomic GREECE
A11: 202 - Super-Pharm POLAND | B11: 078G M | C11: 140 | D11: 9909.22 | E11: 50 | F11: 3127.11 | G11: =IFERROR(INDEX('TRANS'!$B:$B,MATCH($B11,'TRANS'!$A:$A,0)),IFERROR(INDEX('TRANS'!$B:$B,MATCH(TRIM(SUBSTITUTE($B11,CHAR(160)," ")),'TRANS'!$D:$D,0)),IFERROR(INDEX('Catalog'!$A:$A,MATCH($B11,'Catalog'!$B:$B,0)),IFERROR(INDEX('Catalog'!$A:$A,MATCH(TRIM(SUBSTITUTE($B11,CHAR(160)," ")),'Catalog'!$C:$C,0)),"")))) -> 4408220 | H11: =IFERROR(INDEX('TRANS'!$C:$C,MATCH($B11,'TRANS'!$A:$A,0)),IFERROR(INDEX('Catalog'!$B:$B,MATCH($G11,'Catalog'!$A:$A,0)),$B11)) -> 078G-M חגורת גב אפורה | I11: =IF($G11="","Unmatched","Matched") -> Matched | J11: =IF($G11<>"",$G11,$B11) -> 4408220 | K11: =IF(COUNTIF($O$2:$O$16,$A11)>0,"Y","N") -> Y | O11: 214 - Alfred Gera& Sons Ltd. MALTA
A12: 202 - Super-Pharm POLAND | B12: 078G S | C12: 70 | D12: 5033.1 | E12: 12 | F12: 738.48 | G12: =IFERROR(INDEX('TRANS'!$B:$B,MATCH($B12,'TRANS'!$A:$A,0)),IFERROR(INDEX('TRANS'!$B:$B,MATCH(TRIM(SUBSTITUTE($B12,CHAR(160)," ")),'TRANS'!$D:$D,0)),IFERROR(INDEX('Catalog'!$A:$A,MATCH($B12,'Catalog'!$B:$B,0)),IFERROR(INDEX('Catalog'!$A:$A,MATCH(TRIM(SUBSTITUTE($B12,CHAR(160)," ")),'Catalog'!$C:$C,0)),"")))) -> 4408219 | H12: =IFERROR(INDEX('TRANS'!$C:$C,MATCH($B12,'TRANS'!$A:$A,0)),IFERROR(INDEX('Catalog'!$B:$B,MATCH($G12,'Catalog'!$A:$A,0)),$B12)) -> 078G-S חגורת גב אפורה | I12: =IF($G12="","Unmatched","Matched") -> Matched | J12: =IF($G12<>"",$G12,$B12) -> 4408219 | K12: =IF(COUNTIF($O$2:$O$16,$A12)>0,"Y","N") -> Y | O12: 211 - Pharmag Lachmair Ges. Mbh AUSTRIA
A13: 202 - Super-Pharm POLAND | B13: 078G XL | C13: 160 | D13: 11350 | E13: 70 | F13: 4455.67 | G13: =IFERROR(INDEX('TRANS'!$B:$B,MATCH($B13,'TRANS'!$A:$A,0)),IFERROR(INDEX('TRANS'!$B:$B,MATCH(TRIM(SUBSTITUTE($B13,CHAR(160)," ")),'TRANS'!$D:$D,0)),IFERROR(INDEX('Catalog'!$A:$A,MATCH($B13,'Catalog'!$B:$B,0)),IFERROR(INDEX('Catalog'!$A:$A,MATCH(TRIM(SUBSTITUTE($B13,CHAR(160)," ")),'Catalog'!$C:$C,0)),"")))) -> 4408222 | H13: =IFERROR(INDEX('TRANS'!$C:$C,MATCH($B13,'TRANS'!$A:$A,0)),IFERROR(INDEX('Catalog'!$B:$B,MATCH($G13,'Catalog'!$A:$A,0)),$B13)) -> 078G-XLחגורת גב אפורה | I13: =IF($G13="","Unmatched","Matched") -> Matched | J13: =IF($G13<>"",$G13,$B13) -> 4408222 | K13: =IF(COUNTIF($O$2:$O$16,$A13)>0,"Y","N") -> Y | O13: 213 - E.f.m.o. SPAIN
A14: 202 - Super-Pharm POLAND | B14: 078G XXL | C14: 106 | D14: 7580.06 | E14: 30 | F14: 1920.14 | G14: =IFERROR(INDEX('TRANS'!$B:$B,MATCH($B14,'TRANS'!$A:$A,0)),IFERROR(INDEX('TRANS'!$B:$B,MATCH(TRIM(SUBSTITUTE($B14,CHAR(160)," ")),'TRANS'!$D:$D,0)),IFERROR(INDEX('Catalog'!$A:$A,MATCH($B14,'Catalog'!$B:$B,0)),IFERROR(INDEX('Catalog'!$A:$A,MATCH(TRIM(SUBSTITUTE($B14,CHAR(160)," ")),'Catalog'!$C:$C,0)),"")))) -> 4408223 | H14: =IFERROR(INDEX('TRANS'!$C:$C,MATCH($B14,'TRANS'!$A:$A,0)),IFERROR(INDEX('Catalog'!$B:$B,MATCH($G14,'Catalog'!$A:$A,0)),$B14)) -> 078G-XXLחגורת גב אפורה | I14: =IF($G14="","Unmatched","Matched") -> Matched | J14: =IF($G14<>"",$G14,$B14) -> 4408223 | K14: =IF(COUNTIF($O$2:$O$16,$A14)>0,"Y","N") -> Y | O14: 207 - Salus HUNGARY
A15: 202 - Super-Pharm POLAND | B15: 11 L | C15: 86 | D15: 6914.07 | E15: 20 | F15: 1489.16 | G15: =IFERROR(INDEX('TRANS'!$B:$B,MATCH($B15,'TRANS'!$A:$A,0)),IFERROR(INDEX('TRANS'!$B:$B,MATCH(TRIM(SUBSTITUTE($B15,CHAR(160)," ")),'TRANS'!$D:$D,0)),IFERROR(INDEX('Catalog'!$A:$A,MATCH($B15,'Catalog'!$B:$B,0)),IFERROR(INDEX('Catalog'!$A:$A,MATCH(TRIM(SUBSTITUTE($B15,CHAR(160)," ")),'Catalog'!$C:$C,0)),"")))) -> 4408032 | H15: =IFERROR(INDEX('TRANS'!$C:$C,MATCH($B15,'TRANS'!$A:$A,0)),IFERROR(INDEX('Catalog'!$B:$B,MATCH($G15,'Catalog'!$A:$A,0)),$B15)) -> 11 L""""חגורת בטן""""אורירית | I15: =IF($G15="","Unmatched","Matched") -> Matched | J15: =IF($G15<>"",$G15,$B15) -> 4408032 | K15: =IF(COUNTIF($O$2:$O$16,$A15)>0,"Y","N") -> Y | O15: 208 - Medipal Company NABLUS
A16: 202 - Super-Pharm POLAND | B16: 11 M | C16: 92 | D16: 7427.56 | E16: 30 | F16: 2069.36 | G16: =IFERROR(INDEX('TRANS'!$B:$B,MATCH($B16,'TRANS'!$A:$A,0)),IFERROR(INDEX('TRANS'!$B:$B,MATCH(TRIM(SUBSTITUTE($B16,CHAR(160)," ")),'TRANS'!$D:$D,0)),IFERROR(INDEX('Catalog'!$A:$A,MATCH($B16,'Catalog'!$B:$B,0)),IFERROR(INDEX('Catalog'!$A:$A,MATCH(TRIM(SUBSTITUTE($B16,CHAR(160)," ")),'Catalog'!$C:$C,0)),"")))) -> 4408033 | H16: =IFERROR(INDEX('TRANS'!$C:$C,MATCH($B16,'TRANS'!$A:$A,0)),IFERROR(INDEX('Catalog'!$B:$B,MATCH($G16,'Catalog'!$A:$A,0)),$B16)) -> 11 M""""חגורת בטן""""אורירית | I16: =IF($G16="","Unmatched","Matched") -> Matched | J16: =IF($G16<>"",$G16,$B16) -> 4408033 | K16: =IF(COUNTIF($O$2:$O$16,$A16)>0,"Y","N") -> Y | O16: 209 - Ortoprofil Prod ROMANIA
A17: 202 - Super-Pharm POLAND | B17: 11 S | C17: 44 | D17: 3544.17 | E17: 30 | F17: 2125.54 | G17: =IFERROR(INDEX('TRANS'!$B:$B,MATCH($B17,'TRANS'!$A:$A,0)),IFERROR(INDEX('TRANS'!$B:$B,MATCH(TRIM(SUBSTITUTE($B17,CHAR(160)," ")),'TRANS'!$D:$D,0)),IFERROR(INDEX('Catalog'!$A:$A,MATCH($B17,'Catalog'!$B:$B,0)),IFERROR(INDEX('Catalog'!$A:$A,MATCH(TRIM(SUBSTITUTE($B17,CHAR(160)," ")),'Catalog'!$C:$C,0)),"")))) -> 4408031 | H17: =IFERROR(INDEX('TRANS'!$C:$C,MATCH($B17,'TRANS'!$A:$A,0)),IFERROR(INDEX('Catalog'!$B:$B,MATCH($G17,'Catalog'!$A:$A,0)),$B17)) -> 11 S""""חגורת בטן""""אורירית | I17: =IF($G17="","Unmatched","Matched") -> Matched | J17: =IF($G17<>"",$G17,$B17) -> 4408031 | K17: =IF(COUNTIF($O$2:$O$16,$A17)>0,"Y","N") -> Y
A18: 202 - Super-Pharm POLAND | B18: 11 XL | C18: 74 | D18: 5973.41 | E18: 40 | F18: 2815.32 | G18: =IFERROR(INDEX('TRANS'!$B:$B,MATCH($B18,'TRANS'!$A:$A,0)),IFERROR(INDEX('TRANS'!$B:$B,MATCH(TRIM(SUBSTITUTE($B18,CHAR(160)," ")),'TRANS'!$D:$D,0)),IFERROR(INDEX('Catalog'!$A:$A,MATCH($B18,'Catalog'!$B:$B,0)),IFERROR(INDEX('Catalog'!$A:$A,MATCH(TRIM(SUBSTITUTE($B18,CHAR(160)," ")),'Catalog'!$C:$C,0)),"")))) -> 4408034 | H18: =IFERROR(INDEX('TRANS'!$C:$C,MATCH($B18,'TRANS'!$A:$A,0)),IFERROR(INDEX('Catalog'!$B:$B,MATCH($G18,'Catalog'!$A:$A,0)),$B18)) -> 11 XL""""חגורת בטן""""אורירית | I18: =IF($G18="","Unmatched","Matched") -> Matched | J18: =IF($G18<>"",$G18,$B18) -> 4408034 | K18: =IF(COUNTIF($O$2:$O$16,$A18)>0,"Y","N") -> Y
A19: 202 - Super-Pharm POLAND | B19: 16-L-XL | C19: 48 | D19: 3774.69 | E19: 0 | F19: 0 | G19: =IFERROR(INDEX('TRANS'!$B:$B,MATCH($B19,'TRANS'!$A:$A,0)),IFERROR(INDEX('TRANS'!$B:$B,MATCH(TRIM(SUBSTITUTE($B19,CHAR(160)," ")),'TRANS'!$D:$D,0)),IFERROR(INDEX('Catalog'!$A:$A,MATCH($B19,'Catalog'!$B:$B,0)),IFERROR(INDEX('Catalog'!$A:$A,MATCH(TRIM(SUBSTITUTE($B19,CHAR(160)," ")),'Catalog'!$C:$C,0)),"")))) -> 4408230 | H19: =IFERROR(INDEX('TRANS'!$C:$C,MATCH($B19,'TRANS'!$A:$A,0)),IFERROR(INDEX('Catalog'!$B:$B,MATCH($G19,'Catalog'!$A:$A,0)),$B19)) -> 16 L-XL חגורת הריון | I19: =IF($G19="","Unmatched","Matched") -> Matched | J19: =IF($G19<>"",$G19,$B19) -> 4408230 | K19: =IF(COUNTIF($O$2:$O$16,$A19)>0,"Y","N") -> Y
A20: 202 - Super-Pharm POLAND | B20: 16-S-M | C20: 36 | D20: 2831.44 | E20: 6 | F20: 405.76 | G20: =IFERROR(INDEX('TRANS'!$B:$B,MATCH($B20,'TRANS'!$A:$A,0)),IFERROR(INDEX('TRANS'!$B:$B,MATCH(TRIM(SUBSTITUTE($B20,CHAR(160)," ")),'TRANS'!$D:$D,0)),IFERROR(INDEX('Catalog'!$A:$A,MATCH($B20,'Catalog'!$B:$B,0)),IFERROR(INDEX('Catalog'!$A:$A,MATCH(TRIM(SUBSTITUTE($B20,CHAR(160)," ")),'Catalog'!$C:$C,0)),"")))) -> 4408231 | H20: =IFERROR(INDEX('TRANS'!$C:$C,MATCH($B20,'TRANS'!$A:$A,0)),IFERROR(INDEX('Catalog'!$B:$B,MATCH($G20,'Catalog'!$A:$A,0)),$B20)) -> 16 S-M חגורת הריון | I20: =IF($G20="","Unmatched","Matched") -> Matched | J20: =IF($G20<>"",$G20,$B20) -> 4408231 | K20: =IF(COUNTIF($O$2:$O$16,$A20)>0,"Y","N") -> Y
A21: 202 - Super-Pharm POLAND | B21: 20 L | C21: 130 | D21: 2673.97 | E21: 40 | F21: 731.76 | G21: =IFERROR(INDEX('TRANS'!$B:$B,MATCH($B21,'TRANS'!$A:$A,0)),IFERROR(INDEX('TRANS'!$B:$B,MATCH(TRIM(SUBSTITUTE($B21,CHAR(160)," ")),'TRANS'!$D:$D,0)),IFERROR(INDEX('Catalog'!$A:$A,MATCH($B21,'Catalog'!$B:$B,0)),IFERROR(INDEX('Catalog'!$A:$A,MATCH(TRIM(SUBSTITUTE($B21,CHAR(160)," ")),'Catalog'!$C:$C,0)),"")))) -> 4408046 | H21: =IFERROR(INDEX('TRANS'!$C:$C,MATCH($B21,'TRANS'!$A:$A,0)),IFERROR(INDEX('Catalog'!$B:$B,MATCH($G21,'Catalog'!$A:$A,0)),$B21)) -> 20 L חבק יד מתכוון עם צמדן | I21: =IF($G21="","Unmatched","Matched") -> Matched | J21: =IF($G21<>"",$G21,$B21) -> 4408046 | K21: =IF(COUNTIF($O$2:$O$16,$A21)>0,"Y","N") -> Y
