Workbook

Sheet Index
A1: CEMI UPDATED — Sales Comparison 2025 vs 2026 - by Daily-Report Group - with real CHEMIPAL Code (Annualized + DROP/NEW)
A2: Calculation date: | B2: 46290
A3: Builds on kirill/outputs/2026-09-19-CEMI-grouped-2025-vs-2026.xlsx (NOT modified - this is a new, separate file). Every group sheet below now carries a REAL CHEMIPAL Code (matched via the "Catalog" sheet, sourced from the uploaded "חנה_1" PPLAY1 export's columns A/B - a global מק"ט<->item-name catalog, verified against TRANS: e.g. code 4420016 = "40-רצועת פיקה לברך") instead of the old "first token of item name" Product Code. Match rate: 100% by quantity and amount for בתי מרקחת / BE / סופר פארם / מכבי (every raw item name found in the Catalog). 0פארמים is intentionally NOT included in this file (per 25/09/2026 instruction). "מאוחדת" is unchanged from the CEMI file - the CEMI+SALES combined build (see that sheet's own note/comment) - its CHEMIPAL Code already comes from the TRANS crosswalk + 4 manual overrides; cross-checked against this file's Catalog: all 217 matched codes used in מאוחדת are also present in the Catalog, with no discrepancies. "מכבי" (group #20, "ק.חולים מכבי") is NEW - same underlying data as kirill/outputs/2026-09-24-grouped-2025-vs-2026-with-maccabi.xlsx (verified identical: 3 items, 666 ₪ total, 2026-only), but annualized here with the 12/9.5 factor for consistency with the rest of this file (not the 12/8.75 factor used in that other workbook).
A5: Group | B5: Sheet | C5: # Raw categories | D5: # Codes | E5: # Codes 25 | F5: # Codes 26 | G5: # DROP | H5: # NEW | I5: Total Units Drop 25 | J5: Total Amount Drop 25 | K5: NEW — Quantity 2026 | L5: NEW — Amount 2026 (₪) | M5: NEW — Quantity 2026 Annualized | N5: NEW — Amount 2026 Annualized (₪) | O5: Quantity 2025 | P5: Quantity 2026 (Actual) | Q5: Quantity 2026 Annualized | R5: Qty Change % (vs Annualized) | S5: Amount 2025 (₪) | T5: Amount 2026 (Actual) (₪) | U5: Amount 2026 (Annualized) (₪) | V5: Amount Change % (vs Annualized)
A6: בתי מרקחת | B6: בתי מרקחת | C6: 2 | D6: =COUNTA('בתי מרקחת'!$A$9:$A$670) -> 662 | E6: =SUMPRODUCT(--(('בתי מרקחת'!$C$9:$C$670<>0)+('בתי מרקחת'!$H$9:$H$670<>0)>0)) -> 604 | F6: =SUMPRODUCT(--(('בתי מרקחת'!$D$9:$D$670<>0)+('בתי מרקחת'!$I$9:$I$670<>0)>0)) -> 522 | G6: ='בתי מרקחת'!B5 -> 140 | H6: ='בתי מרקחת'!D5 -> 58 | I6: ='בתי מרקחת'!B6 -> 296 | J6: ='בתי מרקחת'!D6 -> 30990.1 | K6: ='בתי מרקחת'!F6 -> 391 | L6: ='בתי מרקחת'!H6 -> 25557.66 | M6: ='בתי מרקחת'!J6 -> 493.89474 | N6: ='בתי מרקחת'!L6 -> 32283.36 | O6: ='בתי מרקחת'!C672 -> 56675 | P6: ='בתי מרקחת'!D672 -> 35110 | Q6: ='בתי מרקחת'!E672 -> 44349.474 | R6: =IF('בתי מרקחת'!C672=0,"N/A",('בתי מרקחת'!E672-'בתי מרקחת'!C672)/'בתי מרקחת'!C672) -> -0.21747731 | S6: ='בתי מרקחת'!H672 -> 2120059.1 | T6: ='בתי מרקחת'!I672 -> 1404694.9 | U6: ='בתי מרקחת'!J672 -> 1774351.4 | V6: =IF('בתי מרקחת'!H672=0,"N/A",('בתי מרקחת'!J672-'בתי מרקחת'!H672)/'בתי מרקחת'!H672) -> -0.1630651
A7: BE | B7: BE | C7: 6 | D7: =COUNTA('BE'!$A$9:$A$354) -> 346 | E7: =SUMPRODUCT(--(('BE'!$C$9:$C$354<>0)+('BE'!$H$9:$H$354<>0)>0)) -> 328 | F7: =SUMPRODUCT(--(('BE'!$D$9:$D$354<>0)+('BE'!$I$9:$I$354<>0)>0)) -> 282 | G7: ='BE'!B5 -> 64 | H7: ='BE'!D5 -> 18 | I7: ='BE'!B6 -> 55 | J7: ='BE'!D6 -> 4567.1 | K7: ='BE'!F6 -> 11 | L7: ='BE'!H6 -> 1501.2 | M7: ='BE'!J6 -> 13.894737 | N7: ='BE'!L6 -> 1896.2526 | O7: ='BE'!C356 -> 27268 | P7: ='BE'!D356 -> 19109 | Q7: ='BE'!E356 -> 24137.684 | R7: =IF('BE'!C356=0,"N/A",('BE'!E356-'BE'!C356)/'BE'!C356) -> -0.11479814 | S7: ='BE'!H356 -> 889501.1 | T7: ='BE'!I356 -> 676265.8 | U7: ='BE'!J356 -> 854230.48 | V7: =IF('BE'!H356=0,"N/A",('BE'!J356-'BE'!H356)/'BE'!H356) -> -0.039652133
A8: סופר פארם | B8: סופר פארם | C8: 1 | D8: =COUNTA('סופר פארם'!$A$9:$A$444) -> 436 | E8: =SUMPRODUCT(--(('סופר פארם'!$C$9:$C$444<>0)+('סופר פארם'!$H$9:$H$444<>0)>0)) -> 384 | F8: =SUMPRODUCT(--(('סופר פארם'!$D$9:$D$444<>0)+('סופר פארם'!$I$9:$I$444<>0)>0)) -> 382 | G8: ='סופר פארם'!B5 -> 54 | H8: ='סופר פארם'!D5 -> 52 | I8: ='סופר פארם'!B6 -> 23 | J8: ='סופר פארם'!D6 -> -2700.3 | K8: ='סופר פארם'!F6 -> 1939 | L8: ='סופר פארם'!H6 -> 146776.3 | M8: ='סופר פארם'!J6 -> 2449.2632 | N8: ='סופר פארם'!L6 -> 185401.64 | O8: ='סופר פארם'!C446 -> 176505 | P8: ='סופר פארם'!D446 -> 118307 | Q8: ='סופר פארם'!E446 -> 149440.42 | R8: =IF('סופר פארם'!C446=0,"N/A",('סופר פארם'!E446-'סופר פארם'!C446)/'סופר פארם'!C446) -> -0.15333605 | S8: ='סופר פארם'!H446 -> 6689220.5 | T8: ='סופר פארם'!I446 -> 4476515.3 | U8: ='סופר פארם'!J446 -> 5654545.6 | V8: =IF('סופר פארם'!H446=0,"N/A",('סופר פארם'!J446-'סופר פארם'!H446)/'סופר פארם'!H446) -> -0.15467794
A9: מאוחדת | B9: מאוחדת | C9: 2 | D9: =COUNTA('מאוחדת'!$A$9:$A$268) -> 260 | E9: =SUMPRODUCT(--(('מאוחדת'!$C$9:$C$268<>0)+('מאוחדת'!$H$9:$H$268<>0)>0)) -> 222 | F9: =SUMPRODUCT(--(('מאוחדת'!$D$9:$D$268<>0)+('מאוחדת'!$I$9:$I$268<>0)>0)) -> 242 | G9: ='מאוחדת'!B5 -> 18 | H9: ='מאוחדת'!D5 -> 38 | I9: ='מאוחדת'!B6 -> 175 | J9: ='מאוחדת'!D6 -> 4498.75 | K9: ='מאוחדת'!F6 -> 569 | L9: ='מאוחדת'!H6 -> 40471.1 | M9: ='מאוחדת'!J6 -> 718.73684 | N9: ='מאוחדת'!L6 -> 51121.389 | O9: ='מאוחדת'!C270 -> 29602 | P9: ='מאוחדת'!D270 -> 17423 | Q9: ='מאוחדת'!E270 -> 22008 | R9: =IF('מאוחדת'!C270=0,"N/A",('מאוחדת'!E270-'מאוחדת'!C270)/'מאוחדת'!C270) -> -0.25653672 | S9: ='מאוחדת'!H270 -> 893547.75 | T9: ='מאוחדת'!I270 -> 529257.42 | U9: ='מאוחדת'!J270 -> 668535.69 | V9: =IF('מאוחדת'!H270=0,"N/A",('מאוחדת'!J270-'מאוחדת'!H270)/'מאוחדת'!H270) -> -0.25181873
A10: מכבי | B10: מכבי | C10: 1 | D10: =COUNTA('מכבי'!$A$9:$A$11) -> 3 | E10: =SUMPRODUCT(--(('מכבי'!$C$9:$C$11<>0)+('מכבי'!$H$9:$H$11<>0)>0)) -> 0 | F10: =SUMPRODUCT(--(('מכבי'!$D$9:$D$11<>0)+('מכבי'!$I$9:$I$11<>0)>0)) -> 3 | G10: ='מכבי'!B5 -> 0 | H10: ='מכבי'!D5 -> 3 | I10: ='מכבי'!B6 -> 0 | J10: ='מכבי'!D6 -> 0 | K10: ='מכבי'!F6 -> 3 | L10: ='מכבי'!H6 -> 666 | M10: ='מכבי'!J6 -> 3.7894737 | N10: ='מכבי'!L6 -> 841.26316 | O10: ='מכבי'!C13 -> 0 | P10: ='מכבי'!D13 -> 3 | Q10: ='מכבי'!E13 -> 3.7894737 | R10: =IF('מכבי'!C13=0,"N/A",('מכבי'!E13-'מכבי'!C13)/'מכבי'!C13) -> N/A | S10: ='מכבי'!H13 -> 0 | T10: ='מכבי'!I13 -> 666 | U10: ='מכבי'!J13 -> 841.26316 | V10: =IF('מכבי'!H13=0,"N/A",('מכבי'!J13-'מכבי'!H13)/'מכבי'!H13) -> N/A

Sheet Group Mapping
A1: Category -> Group mapping (CEMI UPDATED, 25/09/2026)
A2: Calculation date: | B2: 46290
A4: Raw category (PPLAY1 column) | B4: Group # | C4: Group name | D4: Source of mapping
A5: 0בתי טבע | B5: 4 | C5: בתי מרקחת | D5: Confirmed by user 19/09/2026 (same as CEMI file)
A6: 0בתי טבע רשתות | B6: 4 | C6: בתי מרקחת | D6: Confirmed by user 19/09/2026 (same as CEMI file)
A7: 0בתי מרקחת | B7: 4 | C7: בתי מרקחת | D7: Daily report Pplay1 legend
A8: 0כללי | B8: 4 | C8: בתי מרקחת | D8: Confirmed by user 19/09/2026 (same as CEMI file)
A9: 0מפיצי משנה | B9: 4 | C9: בתי מרקחת | D9: Daily report Pplay1 legend
A10: 0צרכנים פרטיים | B10: 4 | C10: בתי מרקחת | D10: Daily report Pplay1 legend
A11: 0שונות | B11: 4 | C11: בתי מרקחת | D11: Daily report Pplay1 legend
A12: גוד פארם | B12: 4 | C12: בתי מרקחת | D12: Daily report Pplay1 legend
A13: גוד פארם מרכז | B13: 4 | C13: בתי מרקחת | D13: Daily report Pplay1 legend
A14: BE | B14: 7 | C14: BE | D14: Confirmed by user 19/09/2026 (same as CEMI file)
A15: אילת BE | B15: 7 | C15: BE | D15: Daily report Pplay1 legend
... A24: 0פארמים | B24: (excluded) | C24: (not included in this file) | D24: Per user instruction 25/09/2026 - not needed in CEMI UPDATED
A26: CHEMIPAL Code methodology (new in this file, 25/09/2026): every group sheet now carries a real CHEMIPAL Code (see "Catalog" sheet - global מק"ט<->item-name table from the uploaded "חנה_1" export) instead of the old first-token-of-name Product Code. Match rate against the Catalog: 100% for בתי מרקחת / BE / סופר פארם / מכבי. "מאוחדת" keeps its own TRANS-based CHEMIPAL Code (cross-checked against this file's Catalog: 100% consistent, 0 discrepancies).

Sheet Catalog
A1: Catalog — global מק"ט (CHEMIPAL Code) <-> Item Name, source: PPLAY1 "חנה_1" export (23/09/2026 17:01, uploaded 25/09/2026)
A2: Calculation date: | B2: 46290
A3: Column A ("מק"ט") is a real numeric CHEMIPAL Code per item - NOT customer/group dependent (same catalog covers every group in this file). Verified against TRANS (kirill/outputs/2026-09-24-meuhedet-comparison-v2.xlsx): e.g. code 4420016 = "40-רצועת פיקה לברך", exact match. Column C is a whitespace-normalized helper column used as a fallback match key by every "<Group> Raw" sheet in this file (exact match first, then normalized).
A5: CHEMIPAL Code | B5: Item Name | C5: Item Name (normalized)
A6: 4402014 | B6: BE CARE תחבושת אלסטית 10ס""מ | C6: =TRIM(SUBSTITUTE($B6,CHAR(160)," ")) -> BE CARE תחבושת אלסטית 10ס""מ
A7: 4402012 | B7: BE CARE תחבושת אלסטית 5 ס""מ | C7: =TRIM(SUBSTITUTE($B7,CHAR(160)," ")) -> BE CARE תחבושת אלסטית 5 ס""מ
A8: 4402013 | B8: BE CARE תחבושת אלסטית 7.5סמ | C8: =TRIM(SUBSTITUTE($B8,CHAR(160)," ")) -> BE CARE תחבושת אלסטית 7.5סמ
A9: 4402015 | B9: BE CARE CB BEIGE | C9: =TRIM(SUBSTITUTE($B9,CHAR(160)," ")) -> BE CARE CB BEIGE
A10: 4402016 | B10: BE CARE CB BLACK | C10: =TRIM(SUBSTITUTE($B10,CHAR(160)," ")) -> BE CARE CB BLACK
A11: 4402017 | B11: BE CARE CB GREEN | C11: =TRIM(SUBSTITUTE($B11,CHAR(160)," ")) -> BE CARE CB GREEN
A12: 4402018 | B12: BE CARE CB PINK | C12: =TRIM(SUBSTITUTE($B12,CHAR(160)," ")) -> BE CARE CB PINK
A13: 4402019 | B13: BE CARE KT BEIGE | C13: =TRIM(SUBSTITUTE($B13,CHAR(160)," ")) -> BE CARE KT BEIGE
A14: 4402020 | B14: BE CARE KT BLACK | C14: =TRIM(SUBSTITUTE($B14,CHAR(160)," ")) -> BE CARE KT BLACK
A15: 4402021 | B15: BE CARE KT BLUE | C15: =TRIM(SUBSTITUTE($B15,CHAR(160)," ")) -> BE CARE KT BLUE
A16: 4402022 | B16: BE CARE KT PINK | C16: =TRIM(SUBSTITUTE($B16,CHAR(160)," ")) -> BE CARE KT PINK
A17: 4420016 | B17: 40-רצועת פיקה לברך | C17: =TRIM(SUBSTITUTE($B17,CHAR(160)," ")) -> 40-רצועת פיקה לברך
... A782: 4422029 | B782: B75 תחבושת אלסטית 7.5ס""מ | C782: =TRIM(SUBSTITUTE($B782,CHAR(160)," ")) -> B75 תחבושת אלסטית 7.5ס""מ

Sheet בתי מרקחת
A1: Sales Comparison 2025 vs 2026 (Annualized) - Group: בתי מרקחת — CEMI (PPLAY1) + SALES (NetSuite "107 - Pharmacies") COMBINED (by CHEMIPAL Code / raw item name) — updated 25/09/2026
A2: Calculation date: | B2: 46290
A3: UPDATED 25/09/2026: this sheet now combines BOTH source systems for בתי מרקחת - CEMI/PPLAY1 (group #4, from kirill/outputs/2026-09-25-CEMI-UPDATED-grouped-2025-vs-2026.xlsx, already 100% CHEMIPAL-Code-matched) AND SALES/NetSuite (Sale Type "107 - Pharmacies") - not CEMI-only as before. For each product (CHEMIPAL Code where matched - via TRANS, automatically or via 3 user-approved manual override rules re-used from מאוחדת: 397/397A "אנטי", 363 "בננה", 394 color family B/W/G - see the "בתי מרקחת Raw" sheet note for full detail; otherwise the raw item name itself, so unmatched items are still fully included), 2025/2026 quantity and amount are a SIMPLE SUM of both sources. "67 0" is intentionally kept as its own product row (no CHEMIPAL Code exists for it in TRANS or the Catalog) per explicit 25/09/2026 instruction - it is an important product, not a non-product adjustment line. First-pass matching/reporting only (without these rules) was done in kirill/outputs/2026-09-25-BETI-comparison.xlsx - see that file for the full match-rate audit trail. Other groups in this file (BE / סופר פארם / מאוחדת / 0פארמים) are unaffected - unchanged.
A4: Annualization note: 2026 actual data covers approximately 9.5 months (1 Jan - 15 Sep 2026) for CEMI, and a similar partial-year window for SALES. Per 25/09/2026 instruction, the SAME factor already used for every other group in this file is reused here for consistency (12 / 9.5 ≈ 1.263158) - straight-line extrapolation, does NOT account for seasonality - treat as an estimate, not an exact forecast. | I4: Months in full year: | J4: 12 | K4: Months covered by 2026 actual (1/1–15/9): | L4: 9.5
A5: # DROP (sold 2025, 0 in 2026): | B5: =SUMPRODUCT(--((($C$9:$C$670<>0)+($H$9:$H$670<>0)>0)*(($D$9:$D$670=0)*($I$9:$I$670=0)))) -> 140 | C5: # NEW (sold 2026, 0 in 2025): | D5: =SUMPRODUCT(--((($D$9:$D$670<>0)+($I$9:$I$670<>0)>0)*(($C$9:$C$670=0)*($H$9:$H$670=0)))) -> 58 | I5: Normalization factor (J4/L4): | J5: =J4/L4 -> 1.2631579
A6: DROP — Quantity 2025: | B6: =SUMPRODUCT(--((($C$9:$C$670<>0)+($H$9:$H$670<>0)>0)*(($D$9:$D$670=0)*($I$9:$I$670=0)))*$C$9:$C$670) -> 296 | C6: DROP — Amount 2025 (₪): | D6: =SUMPRODUCT(--((($C$9:$C$670<>0)+($H$9:$H$670<>0)>0)*(($D$9:$D$670=0)*($I$9:$I$670=0)))*$H$9:$H$670) -> 30990.1 | E6: NEW — Quantity 2026: | F6: =SUMPRODUCT(--((($D$9:$D$670<>0)+($I$9:$I$670<>0)>0)*(($C$9:$C$670=0)*($H$9:$H$670=0)))*$D$9:$D$670) -> 391 | G6: NEW — Amount 2026 (₪): | H6: =SUMPRODUCT(--((($D$9:$D$670<>0)+($I$9:$I$670<>0)>0)*(($C$9:$C$670=0)*($H$9:$H$670=0)))*$I$9:$I$670) -> 25557.66 | I6: NEW — Quantity 2026 Annualized: | J6: =F6*$J$5 -> 493.89474 | K6: NEW — Amount 2026 Annualized (₪): | L6: =H6*$J$5 -> 32283.36
A8: Product Code | B8: Product Name | C8: Quantity 2025 | D8: Quantity 2026 (Actual, partial year) | E8: Quantity 2026 (Annualized) | F8: Quantity Change (Annualized vs 2025) | G8: Quantity Change % (Annualized vs 2025) | H8: Amount 2025 (₪) | I8: Amount 2026 (Actual, partial year) (₪) | J8: Amount 2026 (Annualized) (₪)
A9: 4401000 | B9: =IFERROR(INDEX('בתי מרקחת Raw'!$B:$B,MATCH($A9,'בתי מרקחת Raw'!$F:$F,0)),"") -> 369 S-L אצבעון מסיליקון יחידה | C9: =SUMIFS('בתי מרקחת Raw'!$D$6:$D$1616,'בתי מרקחת Raw'!$F$6:$F$1616,$A9,'בתי מרקחת Raw'!$C$6:$C$1616,2025) -> 337 | D9: =SUMIFS('בתי מרקחת Raw'!$D$6:$D$1616,'בתי מרקחת Raw'!$F$6:$F$1616,$A9,'בתי מרקחת Raw'!$C$6:$C$1616,2026) -> 257 | E9: =D9*$J$5 -> 324.63158 | F9: =E9-C9 -> -12.368421 | G9: =IF(AND(C9=0,E9=0),0,IF(C9=0,"New",(E9-C9)/C9)) -> -0.036701546 | H9: =SUMIFS('בתי מרקחת Raw'!$E$6:$E$1616,'בתי מרקחת Raw'!$F$6:$F$1616,$A9,'בתי מרקחת Raw'!$C$6:$C$1616,2025) -> 7673.02 | I9: =SUMIFS('בתי מרקחת Raw'!$E$6:$E$1616,'בתי מרקחת Raw'!$F$6:$F$1616,$A9,'בתי מרקחת Raw'!$C$6:$C$1616,2026) -> 5915.54 | J9: =I9*$J$5 -> 7472.2611
A10: 4401001 | B10: =IFERROR(INDEX('בתי מרקחת Raw'!$B:$B,MATCH($A10,'בתי מרקחת Raw'!$F:$F,0)),"") -> 369 XL אצבעון מסיליקון יחידה | C10: =SUMIFS('בתי מרקחת Raw'!$D$6:$D$1616,'בתי מרקחת Raw'!$F$6:$F$1616,$A10,'בתי מרקחת Raw'!$C$6:$C$1616,2025) -> 432 | D10: =SUMIFS('בתי מרקחת Raw'!$D$6:$D$1616,'בתי מרקחת Raw'!$F$6:$F$1616,$A10,'בתי מרקחת Raw'!$C$6:$C$1616,2026) -> 292 | E10: =D10*$J$5 -> 368.84211 | F10: =E10-C10 -> -63.157895 | G10: =IF(AND(C10=0,E10=0),0,IF(C10=0,"New",(E10-C10)/C10)) -> -0.14619883 | H10: =SUMIFS('בתי מרקחת Raw'!$E$6:$E$1616,'בתי מרקחת Raw'!$F$6:$F$1616,$A10,'בתי מרקחת Raw'!$C$6:$C$1616,2025) -> 10710.15 | I10: =SUMIFS('בתי מרקחת Raw'!$E$6:$E$1616,'בתי מרקחת Raw'!$F$6:$F$1616,$A10,'בתי מרקחת Raw'!$C$6:$C$1616,2026) -> 7282.89 | J10: =I10*$J$5 -> 9199.44
A11: 4401002 | B11: =IFERROR(INDEX('בתי מרקחת Raw'!$B:$B,MATCH($A11,'בתי מרקחת Raw'!$F:$F,0)),"") -> PD 344-אבן טבעית להסרת עור קשה | C11: =SUMIFS('בתי מרקחת Raw'!$D$6:$D$1616,'בתי מרקחת Raw'!$F$6:$F$1616,$A11,'בתי מרקחת Raw'!$C$6:$C$1616,2025) -> 266 | D11: =SUMIFS('בתי מרקחת Raw'!$D$6:$D$1616,'בתי מרקחת Raw'!$F$6:$F$1616,$A11,'בתי מרקחת Raw'!$C$6:$C$1616,2026) -> 184 | E11: =D11*$J$5 -> 232.42105 | F11: =E11-C11 -> -33.578947 | G11: =IF(AND(C11=0,E11=0),0,IF(C11=0,"New",(E11-C11)/C11)) -> -0.12623664 | H11: =SUMIFS('בתי מרקחת Raw'!$E$6:$E$1616,'בתי מרקחת Raw'!$F$6:$F$1616,$A11,'בתי מרקחת Raw'!$C$6:$C$1616,2025) -> 2275.18 | I11: =SUMIFS('בתי מרקחת Raw'!$E$6:$E$1616,'בתי מרקחת Raw'!$F$6:$F$1616,$A11,'בתי מרקחת Raw'!$C$6:$C$1616,2026) -> 1578.6 | J11: =I11*$J$5 -> 1994.0211
A12: 4401011 | B12: =IFERROR(INDEX('בתי מרקחת Raw'!$B:$B,MATCH($A12,'בתי מרקחת Raw'!$F:$F,0)),"") -> 805AT-Cאתלטיק טייפ בז' 20מ""מ20 | C12: =SUMIFS('בתי מרקחת Raw'!$D$6:$D$1616,'בתי מרקחת Raw'!$F$6:$F$1616,$A12,'בתי מרקחת Raw'!$C$6:$C$1616,2025) -> 72 | D12: =SUMIFS('בתי מרקחת Raw'!$D$6:$D$1616,'בתי מרקחת Raw'!$F$6:$F$1616,$A12,'בתי מרקחת Raw'!$C$6:$C$1616,2026) -> 49 | E12: =D12*$J$5 -> 61.894737 | F12: =E12-C12 -> -10.105263 | G12: =IF(AND(C12=0,E12=0),0,IF(C12=0,"New",(E12-C12)/C12)) -> -0.14035088 | H12: =SUMIFS('בתי מרקחת Raw'!$E$6:$E$1616,'בתי מרקחת Raw'!$F$6:$F$1616,$A12,'בתי מרקחת Raw'!$C$6:$C$1616,2025) -> 1124.09 | I12: =SUMIFS('בתי מרקחת Raw'!$E$6:$E$1616,'בתי מרקחת Raw'!$F$6:$F$1616,$A12,'בתי מרקחת Raw'!$C$6:$C$1616,2026) -> 805.89 | J12: =I12*$J$5 -> 1017.9663
A13: 4401012 | B13: =IFERROR(INDEX('בתי מרקחת Raw'!$B:$B,MATCH($A13,'בתי מרקחת Raw'!$F:$F,0)),"") -> 805AT-B אתלטיק טייפ שחור 20מ""מ | C13: =SUMIFS('בתי מרקחת Raw'!$D$6:$D$1616,'בתי מרקחת Raw'!$F$6:$F$1616,$A13,'בתי מרקחת Raw'!$C$6:$C$1616,2025) -> 20 | D13: =SUMIFS('בתי מרקחת Raw'!$D$6:$D$1616,'בתי מרקחת Raw'!$F$6:$F$1616,$A13,'בתי מרקחת Raw'!$C$6:$C$1616,2026) -> 21 | E13: =D13*$J$5 -> 26.526316 | F13: =E13-C13 -> 6.5263158 | G13: =IF(AND(C13=0,E13=0),0,IF(C13=0,"New",(E13-C13)/C13)) -> 0.32631579 | H13: =SUMIFS('בתי מרקחת Raw'!$E$6:$E$1616,'בתי מרקחת Raw'!$F$6:$F$1616,$A13,'בתי מרקחת Raw'!$C$6:$C$1616,2025) -> 318.7 | I13: =SUMIFS('בתי מרקחת Raw'!$E$6:$E$1616,'בתי מרקחת Raw'!$F$6:$F$1616,$A13,'בתי מרקחת Raw'!$C$6:$C$1616,2026) -> 358.6 | J13: =I13*$J$5 -> 452.96842
A14: 4401013 | B14: =IFERROR(INDEX('בתי מרקחת Raw'!$B:$B,MATCH($A14,'בתי מרקחת Raw'!$F:$F,0)),"") -> 805AT-BLאתלטיק טייפ כחול 20מ""מ | C14: =SUMIFS('בתי מרקחת Raw'!$D$6:$D$1616,'בתי מרקחת Raw'!$F$6:$F$1616,$A14,'בתי מרקחת Raw'!$C$6:$C$1616,2025) -> 19 | D14: =SUMIFS('בתי מרקחת Raw'!$D$6:$D$1616,'בתי מרקחת Raw'!$F$6:$F$1616,$A14,'בתי מרקחת Raw'!$C$6:$C$1616,2026) -> 19 | E14: =D14*$J$5 -> 24 | F14: =E14-C14 -> 5 | G14: =IF(AND(C14=0,E14=0),0,IF(C14=0,"New",(E14-C14)/C14)) -> 0.26315789 | H14: =SUMIFS('בתי מרקחת Raw'!$E$6:$E$1616,'בתי מרקחת Raw'!$F$6:$F$1616,$A14,'בתי מרקחת Raw'!$C$6:$C$1616,2025) -> 301.4 | I14: =SUMIFS('בתי מרקחת Raw'!$E$6:$E$1616,'בתי מרקחת Raw'!$F$6:$F$1616,$A14,'בתי מרקחת Raw'!$C$6:$C$1616,2026) -> 319.4 | J14: =I14*$J$5 -> 403.45263
A15: 4401014 | B15: =IFERROR(INDEX('בתי מרקחת Raw'!$B:$B,MATCH($A15,'בתי מרקחת Raw'!$F:$F,0)),"") -> 805AT-W אתלטיק טייפ לבן 20מ""מ | C15: =SUMIFS('בתי מרקחת Raw'!$D$6:$D$1616,'בתי מרקחת Raw'!$F$6:$F$1616,$A15,'בתי מרקחת Raw'!$C$6:$C$1616,2025) -> 49 | D15: =SUMIFS('בתי מרקחת Raw'!$D$6:$D$1616,'בתי מרקחת Raw'!$F$6:$F$1616,$A15,'בתי מרקחת Raw'!$C$6:$C$1616,2026) -> 41 | E15: =D15*$J$5 -> 51.789474 | F15: =E15-C15 -> 2.7894737 | G15: =IF(AND(C15=0,E15=0),0,IF(C15=0,"New",(E15-C15)/C15)) -> 0.056928034 | H15: =SUMIFS('בתי מרקחת Raw'!$E$6:$E$1616,'בתי מרקחת Raw'!$F$6:$F$1616,$A15,'בתי מרקחת Raw'!$C$6:$C$1616,2025) -> 753.69 | I15: =SUMIFS('בתי מרקחת Raw'!$E$6:$E$1616,'בתי מרקחת Raw'!$F$6:$F$1616,$A15,'בתי מרקחת Raw'!$C$6:$C$1616,2026) -> 665.2 | J15: =I15*$J$5 -> 840.25263
A16: 4402000 | B16: =IFERROR(INDEX('בתי מרקחת Raw'!$B:$B,MATCH($A16,'בתי מרקחת Raw'!$F:$F,0)),"") -> 363 בננה לתמיכת אצבעות ז.כרית | C16: =SUMIFS('בתי מרקחת Raw'!$D$6:$D$1616,'בתי מרקחת Raw'!$F$6:$F$1616,$A16,'בתי מרקחת Raw'!$C$6:$C$1616,2025) -> 132 | D16: =SUMIFS('בתי מרקחת Raw'!$D$6:$D$1616,'בתי מרקחת Raw'!$F$6:$F$1616,$A16,'בתי מרקחת Raw'!$C$6:$C$1616,2026) -> 118 | E16: =D16*$J$5 -> 149.05263 | F16: =E16-C16 -> 17.052632 | G16: =IF(AND(C16=0,E16=0),0,IF(C16=0,"New",(E16-C16)/C16)) -> 0.1291866 | H16: =SUMIFS('בתי מרקחת Raw'!$E$6:$E$1616,'בתי מרקחת Raw'!$F$6:$F$1616,$A16,'בתי מרקחת Raw'!$C$6:$C$1616,2025) -> 3441.28 | I16: =SUMIFS('בתי מרקחת Raw'!$E$6:$E$1616,'בתי מרקחת Raw'!$F$6:$F$1616,$A16,'בתי מרקחת Raw'!$C$6:$C$1616,2026) -> 3114.14 | J16: =I16*$J$5 -> 3933.6505
A17: 4402007 | B17: =IFERROR(INDEX('בתי מרקחת Raw'!$B:$B,MATCH($A17,'בתי מרקחת Raw'!$F:$F,0)),"") -> 320 בליסטר פלסטר | C17: =SUMIFS('בתי מרקחת Raw'!$D$6:$D$1616,'בתי מרקחת Raw'!$F$6:$F$1616,$A17,'בתי מרקחת Raw'!$C$6:$C$1616,2025) -> 356 | D17: =SUMIFS('בתי מרקחת Raw'!$D$6:$D$1616,'בתי מרקחת Raw'!$F$6:$F$1616,$A17,'בתי מרקחת Raw'!$C$6:$C$1616,2026) -> 227 | E17: =D17*$J$5 -> 286.73684 | F17: =E17-C17 -> -69.263158 | G17: =IF(AND(C17=0,E17=0),0,IF(C17=0,"New",(E17-C17)/C17)) -> -0.19455943 | H17: =SUMIFS('בתי מרקחת Raw'!$E$6:$E$1616,'בתי מרקחת Raw'!$F$6:$F$1616,$A17,'בתי מרקחת Raw'!$C$6:$C$1616,2025) -> 6539.26 | I17: =SUMIFS('בתי מרקחת Raw'!$E$6:$E$1616,'בתי מרקחת Raw'!$F$6:$F$1616,$A17,'בתי מרקחת Raw'!$C$6:$C$1616,2026) -> 4172.9 | J17: =I17*$J$5 -> 5271.0316
A18: 4403000 | B18: =IFERROR(INDEX('בתי מרקחת Raw'!$B:$B,MATCH($A18,'בתי מרקחת Raw'!$F:$F,0)),"") -> 390B גרב.כסף לסכרתים שחור35-38 | C18: =SUMIFS('בתי מרקחת Raw'!$D$6:$D$1616,'בתי מרקחת Raw'!$F$6:$F$1616,$A18,'בתי מרקחת Raw'!$C$6:$C$1616,2025) -> 21 | D18: =SUMIFS('בתי מרקחת Raw'!$D$6:$D$1616,'בתי מרקחת Raw'!$F$6:$F$1616,$A18,'בתי מרקחת Raw'!$C$6:$C$1616,2026) -> 11 | E18: =D18*$J$5 -> 13.894737 | F18: =E18-C18 -> -7.1052632 | G18: =IF(AND(C18=0,E18=0),0,IF(C18=0,"New",(E18-C18)/C18)) -> -0.33834586 | H18: =SUMIFS('בתי מרקחת Raw'!$E$6:$E$1616,'בתי מרקחת Raw'!$F$6:$F$1616,$A18,'בתי מרקחת Raw'!$C$6:$C$1616,2025) -> 614.1 | I18: =SUMIFS('בתי מרקחת Raw'!$E$6:$E$1616,'בתי מרקחת Raw'!$F$6:$F$1616,$A18,'בתי מרקחת Raw'!$C$6:$C$1616,2026) -> 360.4 | J18: =I18*$J$5 -> 455.24211
A19: 4403001 | B19: =IFERROR(INDEX('בתי מרקחת Raw'!$B:$B,MATCH($A19,'בתי מרקחת Raw'!$F:$F,0)),"") -> 390B 39-42.גרב.כסף לסכרתיים שח | C19: =SUMIFS('בתי מרקחת Raw'!$D$6:$D$1616,'בתי מרקחת Raw'!$F$6:$F$1616,$A19,'בתי מרקחת Raw'!$C$6:$C$1616,2025) -> 42 | D19: =SUMIFS('בתי מרקחת Raw'!$D$6:$D$1616,'בתי מרקחת Raw'!$F$6:$F$1616,$A19,'בתי מרקחת Raw'!$C$6:$C$1616,2026) -> 15 | E19: =D19*$J$5 -> 18.947368 | F19: =E19-C19 -> -23.052632 | G19: =IF(AND(C19=0,E19=0),0,IF(C19=0,"New",(E19-C19)/C19)) -> -0.54887218 | H19: =SUMIFS('בתי מרקחת Raw'!$E$6:$E$1616,'בתי מרקחת Raw'!$F$6:$F$1616,$A19,'בתי מרקחת Raw'!$C$6:$C$1616,2025) -> 1277.4 | I19: =SUMIFS('בתי מרקחת Raw'!$E$6:$E$1616,'בתי מרקחת Raw'!$F$6:$F$1616,$A19,'בתי מרקחת Raw'!$C$6:$C$1616,2026) -> 507.9 | J19: =I19*$J$5 -> 641.55789
A20: 4403002 | B20: =IFERROR(INDEX('בתי מרקחת Raw'!$B:$B,MATCH($A20,'בתי מרקחת Raw'!$F:$F,0)),"") -> 390B 43-46.גרב.כסף לסכרתיים שח | C20: =SUMIFS('בתי מרקחת Raw'!$D$6:$D$1616,'בתי מרקחת Raw'!$F$6:$F$1616,$A20,'בתי מרקחת Raw'!$C$6:$C$1616,2025) -> 78 | D20: =SUMIFS('בתי מרקחת Raw'!$D$6:$D$1616,'בתי מרקחת Raw'!$F$6:$F$1616,$A20,'בתי מרקחת Raw'!$C$6:$C$1616,2026) -> 23 | E20: =D20*$J$5 -> 29.052632 | F20: =E20-C20 -> -48.947368 | G20: =IF(AND(C20=0,E20=0),0,IF(C20=0,"New",(E20-C20)/C20)) -> -0.62753036 | H20: =SUMIFS('בתי מרקחת Raw'!$E$6:$E$1616,'בתי מרקחת Raw'!$F$6:$F$1616,$A20,'בתי מרקחת Raw'!$C$6:$C$1616,2025) -> 2431 | I20: =SUMIFS('בתי מרקחת Raw'!$E$6:$E$1616,'בתי מרקחת Raw'!$F$6:$F$1616,$A20,'בתי מרקחת Raw'!$C$6:$C$1616,2026) -> 763 | J20: =I20*$J$5 -> 963.78947
... A599: 4422042 | B599: =IFERROR(INDEX('בתי מרקחת Raw'!$B:$B,MATCH($A599,'בתי מרקחת Raw'!$F:$F,0)),"") -> SH422 6 תומך ברך גנושילד | C599: =SUMIFS('בתי מרקחת Raw'!$D$6:$D$1616,'בתי מרקחת Raw'!$F$6:$F$1616,$A599,'בתי מרקחת Raw'!$C$6:$C$1616,2025) -> 1 | D599: =SUMIFS('בתי מרקחת Raw'!$D$6:$D$1616,'בתי מרקחת Raw'!$F$6:$F$1616,$A599,'בתי מרקחת Raw'!$C$6:$C$1616,2026) -> 17 | E599: =D599*$J$5 -> 21.473684 | F599: =E599-C599 -> 20.473684 | G599: =IF(AND(C599=0,E599=0),0,IF(C599=0,"New",(E599-C599)/C599)) -> 20.473684 | H599: =SUMIFS('בתי מרקחת Raw'!$E$6:$E$1616,'בתי מרקחת Raw'!$F$6:$F$1616,$A599,'בתי מרקחת Raw'!$C$6:$C$1616,2025) -> 120 | I599: =SUMIFS('בתי מרקחת Raw'!$E$6:$E$1616,'בתי מרקחת Raw'!$F$6:$F$1616,$A599,'בתי מרקחת Raw'!$C$6:$C$1616,2026) -> 3280.07 | J599: =I599*$J$5 -> 4143.2463
A600: 062 XXL | B600: =IFERROR(INDEX('בתי מרקחת Raw'!$B:$B,MATCH($A600,'בתי מרקחת Raw'!$F:$F,0)),"") -> 062 XXL | C600: =SUMIFS('בתי מרקחת Raw'!$D$6:$D$1616,'בתי מרקחת Raw'!$F$6:$F$1616,$A600,'בתי מרקחת Raw'!$C$6:$C$1616,2025) -> 0 | D600: =SUMIFS('בתי מרקחת Raw'!$D$6:$D$1616,'בתי מרקחת Raw'!$F$6:$F$1616,$A600,'בתי מרקחת Raw'!$C$6:$C$1616,2026) -> 0 | E600: =D600*$J$5 -> 0 | F600: =E600-C600 -> 0 | G600: =IF(AND(C600=0,E600=0),0,IF(C600=0,"New",(E600-C600)/C600)) -> 0 | H600: =SUMIFS('בתי מרקחת Raw'!$E$6:$E$1616,'בתי מרקחת Raw'!$F$6:$F$1616,$A600,'בתי מרקחת Raw'!$C$6:$C$1616,2025) -> 0.01 | I600: =SUMIFS('בתי מרקחת Raw'!$E$6:$E$1616,'בתי מרקחת Raw'!$F$6:$F$1616,$A600,'בתי מרקחת Raw'!$C$6:$C$1616,2026) -> 0 | J600: =I600*$J$5 -> 0
A601: 06U M | B601: =IFERROR(INDEX('בתי מרקחת Raw'!$B:$B,MATCH($A601,'בתי מרקחת Raw'!$F:$F,0)),"") -> 06U M | C601: =SUMIFS('בתי מרקחת Raw'!$D$6:$D$1616,'בתי מרקחת Raw'!$F$6:$F$1616,$A601,'בתי מרקחת Raw'!$C$6:$C$1616,2025) -> 2 | D601: =SUMIFS('בתי מרקחת Raw'!$D$6:$D$1616,'בתי מרקחת Raw'!$F$6:$F$1616,$A601,'בתי מרקחת Raw'!$C$6:$C$1616,2026) -> 0 | E601: =D601*$J$5 -> 0 | F601: =E601-C601 -> -2 | G601: =IF(AND(C601=0,E601=0),0,IF(C601=0,"New",(E601-C601)/C601)) -> -1 | H601: =SUMIFS('בתי מרקחת Raw'!$E$6:$E$1616,'בתי מרקחת Raw'!$F$6:$F$1616,$A601,'בתי מרקחת Raw'!$C$6:$C$1616,2025) -> 281.15 | I601: =SUMIFS('בתי מרקחת Raw'!$E$6:$E$1616,'בתי מרקחת Raw'!$F$6:$F$1616,$A601,'בתי מרקחת Raw'!$C$6:$C$1616,2026) -> 0 | J601: =I601*$J$5 -> 0
A602: 06U XXL | B602: =IFERROR(INDEX('בתי מרקחת Raw'!$B:$B,MATCH($A602,'בתי מרקחת Raw'!$F:$F,0)),"") -> 06U XXL | C602: =SUMIFS('בתי מרקחת Raw'!$D$6:$D$1616,'בתי מרקחת Raw'!$F$6:$F$1616,$A602,'בתי מרקחת Raw'!$C$6:$C$1616,2025) -> 1 | D602: =SUMIFS('בתי מרקחת Raw'!$D$6:$D$1616,'בתי מרקחת Raw'!$F$6:$F$1616,$A602,'בתי מרקחת Raw'!$C$6:$C$1616,2026) -> 0 | E602: =D602*$J$5 -> 0 | F602: =E602-C602 -> -1 | G602: =IF(AND(C602=0,E602=0),0,IF(C602=0,"New",(E602-C602)/C602)) -> -1 | H602: =SUMIFS('בתי מרקחת Raw'!$E$6:$E$1616,'בתי מרקחת Raw'!$F$6:$F$1616,$A602,'בתי מרקחת Raw'!$C$6:$C$1616,2025) -> 140.57 | I602: =SUMIFS('בתי מרקחת Raw'!$E$6:$E$1616,'בתי מרקחת Raw'!$F$6:$F$1616,$A602,'בתי מרקחת Raw'!$C$6:$C$1616,2026) -> 0 | J602: =I602*$J$5 -> 0
A603: 07UB-L-XL | B603: =IFERROR(INDEX('בתי מרקחת Raw'!$B:$B,MATCH($A603,'בתי מרקחת Raw'!$F:$F,0)),"") -> 07UB-L-XL | C603: =SUMIFS('בתי מרקחת Raw'!$D$6:$D$1616,'בתי מרקחת Raw'!$F$6:$F$1616,$A603,'בתי מרקחת Raw'!$C$6:$C$1616,2025) -> 50 | D603: =SUMIFS('בתי מרקחת Raw'!$D$6:$D$1616,'בתי מרקחת Raw'!$F$6:$F$1616,$A603,'בתי מרקחת Raw'!$C$6:$C$1616,2026) -> 1 | E603: =D603*$J$5 -> 1.2631579 | F603: =E603-C603 -> -48.736842 | G603: =IF(AND(C603=0,E603=0),0,IF(C603=0,"New",(E603-C603)/C603)) -> -0.97473684 | H603: =SUMIFS('בתי מרקחת Raw'!$E$6:$E$1616,'בתי מרקחת Raw'!$F$6:$F$1616,$A603,'בתי מרקחת Raw'!$C$6:$C$1616,2025) -> 6250 | I603: =SUMIFS('בתי מרקחת Raw'!$E$6:$E$1616,'בתי מרקחת Raw'!$F$6:$F$1616,$A603,'בתי מרקחת Raw'!$C$6:$C$1616,2026) -> 234.31 | J603: =I603*$J$5 -> 295.97053
A604: 07UB-S-M | B604: =IFERROR(INDEX('בתי מרקחת Raw'!$B:$B,MATCH($A604,'בתי מרקחת Raw'!$F:$F,0)),"") -> 07UB-S-M | C604: =SUMIFS('בתי מרקחת Raw'!$D$6:$D$1616,'בתי מרקחת Raw'!$F$6:$F$1616,$A604,'בתי מרקחת Raw'!$C$6:$C$1616,2025) -> 10 | D604: =SUMIFS('בתי מרקחת Raw'!$D$6:$D$1616,'בתי מרקחת Raw'!$F$6:$F$1616,$A604,'בתי מרקחת Raw'!$C$6:$C$1616,2026) -> 0 | E604: =D604*$J$5 -> 0 | F604: =E604-C604 -> -10 | G604: =IF(AND(C604=0,E604=0),0,IF(C604=0,"New",(E604-C604)/C604)) -> -1 | H604: =SUMIFS('בתי מרקחת Raw'!$E$6:$E$1616,'בתי מרקחת Raw'!$F$6:$F$1616,$A604,'בתי מרקחת Raw'!$C$6:$C$1616,2025) -> 1250 | I604: =SUMIFS('בתי מרקחת Raw'!$E$6:$E$1616,'בתי מרקחת Raw'!$F$6:$F$1616,$A604,'בתי מרקחת Raw'!$C$6:$C$1616,2026) -> 0 | J604: =I604*$J$5 -> 0
A605: 10 XXL | B605: =IFERROR(INDEX('בתי מרקחת Raw'!$B:$B,MATCH($A605,'בתי מרקחת Raw'!$F:$F,0)),"") -> 10 XXL | C605: =SUMIFS('בתי מרקחת Raw'!$D$6:$D$1616,'בתי מרקחת Raw'!$F$6:$F$1616,$A605,'בתי מרקחת Raw'!$C$6:$C$1616,2025) -> 10 | D605: =SUMIFS('בתי מרקחת Raw'!$D$6:$D$1616,'בתי מרקחת Raw'!$F$6:$F$1616,$A605,'בתי מרקחת Raw'!$C$6:$C$1616,2026) -> 0 | E605: =D605*$J$5 -> 0 | F605: =E605-C605 -> -10 | G605: =IF(AND(C605=0,E605=0),0,IF(C605=0,"New",(E605-C605)/C605)) -> -1 | H605: =SUMIFS('בתי מרקחת Raw'!$E$6:$E$1616,'בתי מרקחת Raw'!$F$6:$F$1616,$A605,'בתי מרקחת Raw'!$C$6:$C$1616,2025) -> 1300 | I605: =SUMIFS('בתי מרקחת Raw'!$E$6:$E$1616,'בתי מרקחת Raw'!$F$6:$F$1616,$A605,'בתי מרקחת Raw'!$C$6:$C$1616,2026) -> 0 | J605: =I605*$J$5 -> 0
A606: 11EU S | B606: =IFERROR(INDEX('בתי מרקחת Raw'!$B:$B,MATCH($A606,'בתי מרקחת Raw'!$F:$F,0)),"") -> 11EU S | C606: =SUMIFS('בתי מרקחת Raw'!$D$6:$D$1616,'בתי מרקחת Raw'!$F$6:$F$1616,$A606,'בתי מרקחת Raw'!$C$6:$C$1616,2025) -> 1 | D606: =SUMIFS('בתי מרקחת Raw'!$D$6:$D$1616,'בתי מרקחת Raw'!$F$6:$F$1616,$A606,'בתי מרקחת Raw'!$C$6:$C$1616,2026) -> 1 | E606: =D606*$J$5 -> 1.2631579 | F606: =E606-C606 -> 0.26315789 | G606: =IF(AND(C606=0,E606=0),0,IF(C606=0,"New",(E606-C606)/C606)) -> 0.26315789 | H606: =SUMIFS('בתי מרקחת Raw'!$E$6:$E$1616,'בתי מרקחת Raw'!$F$6:$F$1616,$A606,'בתי מרקחת Raw'!$C$6:$C$1616,2025) -> 69.01 | I606: =SUMIFS('בתי מרקחת Raw'!$E$6:$E$1616,'בתי מרקחת Raw'!$F$6:$F$1616,$A606,'בתי מרקחת Raw'!$C$6:$C$1616,2026) -> 85 | J606: =I606*$J$5 -> 107.36842
A607: 11EU XS | B607: =IFERROR(INDEX('בתי מרקחת Raw'!$B:$B,MATCH($A607,'בתי מרקחת Raw'!$F:$F,0)),"") -> 11EU XS | C607: =SUMIFS('בתי מרקחת Raw'!$D$6:$D$1616,'בתי מרקחת Raw'!$F$6:$F$1616,$A607,'בתי מרקחת Raw'!$C$6:$C$1616,2025) -> 1 | D607: =SUMIFS('בתי מרקחת Raw'!$D$6:$D$1616,'בתי מרקחת Raw'!$F$6:$F$1616,$A607,'בתי מרקחת Raw'!$C$6:$C$1616,2026) -> 0 | E607: =D607*$J$5 -> 0 | F607: =E607-C607 -> -1 | G607: =IF(AND(C607=0,E607=0),0,IF(C607=0,"New",(E607-C607)/C607)) -> -1 | H607: =SUMIFS('בתי מרקחת Raw'!$E$6:$E$1616,'בתי מרקחת Raw'!$F$6:$F$1616,$A607,'בתי מרקחת Raw'!$C$6:$C$1616,2025) -> 69 | I607: =SUMIFS('בתי מרקחת Raw'!$E$6:$E$1616,'בתי מרקחת Raw'!$F$6:$F$1616,$A607,'בתי מרקחת Raw'!$C$6:$C$1616,2026) -> 0 | J607: =I607*$J$5 -> 0
A608: 11PS M | B608: =IFERROR(INDEX('בתי מרקחת Raw'!$B:$B,MATCH($A608,'בתי מרקחת Raw'!$F:$F,0)),"") -> 11PS M | C608: =SUMIFS('בתי מרקחת Raw'!$D$6:$D$1616,'בתי מרקחת Raw'!$F$6:$F$1616,$A608,'בתי מרקחת Raw'!$C$6:$C$1616,2025) -> 1 | D608: =SUMIFS('בתי מרקחת Raw'!$D$6:$D$1616,'בתי מרקחת Raw'!$F$6:$F$1616,$A608,'בתי מרקחת Raw'!$C$6:$C$1616,2026) -> 0 | E608: =D608*$J$5 -> 0 | F608: =E608-C608 -> -1 | G608: =IF(AND(C608=0,E608=0),0,IF(C608=0,"New",(E608-C608)/C608)) -> -1 | H608: =SUMIFS('בתי מרקחת Raw'!$E$6:$E$1616,'בתי מרקחת Raw'!$F$6:$F$1616,$A608,'בתי מרקחת Raw'!$C$6:$C$1616,2025) -> 135.88 | I608: =SUMIFS('בתי מרקחת Raw'!$E$6:$E$1616,'בתי מרקחת Raw'!$F$6:$F$1616,$A608,'בתי מרקחת Raw'!$C$6:$C$1616,2026) -> 0 | J608: =I608*$J$5 -> 0
A609: 13 L | B609: =IFERROR(INDEX('בתי מרקחת Raw'!$B:$B,MATCH($A609,'בתי מרקחת Raw'!$F:$F,0)),"") -> 13 L | C609: =SUMIFS('בתי מרקחת Raw'!$D$6:$D$1616,'בתי מרקחת Raw'!$F$6:$F$1616,$A609,'בתי מרקחת Raw'!$C$6:$C$1616,2025) -> 0 | D609: =SUMIFS('בתי מרקחת Raw'!$D$6:$D$1616,'בתי מרקחת Raw'!$F$6:$F$1616,$A609,'בתי מרקחת Raw'!$C$6:$C$1616,2026) -> 1 | E609: =D609*$J$5 -> 1.2631579 | F609: =E609-C609 -> 1.2631579 | G609: =IF(AND(C609=0,E609=0),0,IF(C609=0,"New",(E609-C609)/C609)) -> New | H609: =SUMIFS('בתי מרקחת Raw'!$E$6:$E$1616,'בתי מרקחת Raw'!$F$6:$F$1616,$A609,'בתי מרקחת Raw'!$C$6:$C$1616,2025) -> 0 | I609: =SUMIFS('בתי מרקחת Raw'!$E$6:$E$1616,'בתי מרקחת Raw'!$F$6:$F$1616,$A609,'בתי מרקחת Raw'!$C$6:$C$1616,2026) -> 156.97 | J609: =I609*$J$5 -> 198.27789
A610: 13 M | B610: =IFERROR(INDEX('בתי מרקחת Raw'!$B:$B,MATCH($A610,'בתי מרקחת Raw'!$F:$F,0)),"") -> 13 M | C610: =SUMIFS('בתי מרקחת Raw'!$D$6:$D$1616,'בתי מרקחת Raw'!$F$6:$F$1616,$A610,'בתי מרקחת Raw'!$C$6:$C$1616,2025) -> 1 | D610: =SUMIFS('בתי מרקחת Raw'!$D$6:$D$1616,'בתי מרקחת Raw'!$F$6:$F$1616,$A610,'בתי מרקחת Raw'!$C$6:$C$1616,2026) -> 0 | E610: =D610*$J$5 -> 0 | F610: =E610-C610 -> -1 | G610: =IF(AND(C610=0,E610=0),0,IF(C610=0,"New",(E610-C610)/C610)) -> -1 | H610: =SUMIFS('בתי מרקחת Raw'!$E$6:$E$1616,'בתי מרקחת Raw'!$F$6:$F$1616,$A610,'בתי מרקחת Raw'!$C$6:$C$1616,2025) -> 156.98 | I610: =SUMIFS('בתי מרקחת Raw'!$E$6:$E$1616,'בתי מרקחת Raw'!$F$6:$F$1616,$A610,'בתי מרקחת Raw'!$C$6:$C$1616,2026) -> 0 | J610: =I610*$J$5 -> 0
A611: 15M L | B611: =IFERROR(INDEX('בתי מרקחת Raw'!$B:$B,MATCH($A611,'בתי מרקחת Raw'!$F:$F,0)),"") -> 15M L | C611: =SUMIFS('בתי מרקחת Raw'!$D$6:$D$1616,'בתי מרקחת Raw'!$F$6:$F$1616,$A611,'בתי מרקחת Raw'!$C$6:$C$1616,2025) -> 1 | D611: =SUMIFS('בתי מרקחת Raw'!$D$6:$D$1616,'בתי מרקחת Raw'!$F$6:$F$1616,$A611,'בתי מרקחת Raw'!$C$6:$C$1616,2026) -> 1 | E611: =D611*$J$5 -> 1.2631579 | F611: =E611-C611 -> 0.26315789 | G611: =IF(AND(C611=0,E611=0),0,IF(C611=0,"New",(E611-C611)/C611)) -> 0.26315789 | H611: =SUMIFS('בתי מרקחת Raw'!$E$6:$E$1616,'בתי מרקחת Raw'!$F$6:$F$1616,$A611,'בתי מרקחת Raw'!$C$6:$C$1616,2025) -> 140.57 | I611: =SUMIFS('בתי מרקחת Raw'!$E$6:$E$1616,'בתי מרקחת Raw'!$F$6:$F$1616,$A611,'בתי מרקחת Raw'!$C$6:$C$1616,2026) -> 140.58 | J611: =I611*$J$5 -> 177.57474
... A670: T45X M | B670: =IFERROR(INDEX('בתי מרקחת Raw'!$B:$B,MATCH($A670,'בתי מרקחת Raw'!$F:$F,0)),"") -> T45X M | C670: =SUMIFS('בתי מרקחת Raw'!$D$6:$D$1616,'בתי מרקחת Raw'!$F$6:$F$1616,$A670,'בתי מרקחת Raw'!$C$6:$C$1616,2025) -> 0 | D670: =SUMIFS('בתי מרקחת Raw'!$D$6:$D$1616,'בתי מרקחת Raw'!$F$6:$F$1616,$A670,'בתי מרקחת Raw'!$C$6:$C$1616,2026) -> 2 | E670: =D670*$J$5 -> 2.5263158 | F670: =E670-C670 -> 2.5263158 | G670: =IF(AND(C670=0,E670=0),0,IF(C670=0,"New",(E670-C670)/C670)) -> New | H670: =SUMIFS('בתי מרקחת Raw'!$E$6:$E$1616,'בתי מרקחת Raw'!$F$6:$F$1616,$A670,'בתי מרקחת Raw'!$C$6:$C$1616,2025) -> 0 | I670: =SUMIFS('בתי מרקחת Raw'!$E$6:$E$1616,'בתי מרקחת Raw'!$F$6:$F$1616,$A670,'בתי מרקחת Raw'!$C$6:$C$1616,2026) -> 236.26 | J670: =I670*$J$5 -> 298.43368
B672: TOTAL | C672: =SUM(C9:C670) -> 56675 | D672: =SUM(D9:D670) -> 35110 | E672: =SUM(E9:E670) -> 44349.474 | F672: =SUM(F9:F670) -> -12325.526 | G672: =IF(C672=0,"N/A",F672/C672) -> -0.21747731 | H672: =SUM(H9:H670) -> 2120059.1 | I672: =SUM(I9:I670) -> 1404694.9 | J672: =SUM(J9:J670) -> 1774351.4

Sheet בתי מרקחת Raw
A1: בתי מרקחת Raw — combined CEMI (PPLAY1, group #4) + SALES (NetSuite "107 - Pharmacies") item-level data
A2: Calculation date: | B2: 46290
A3: Source: kirill/outputs/2026-09-25-CEMI-UPDATED-grouped-2025-vs-2026.xlsx ("בתי מרקחת Raw", already 100% CHEMIPAL-Code-matched via the "חנה_1" Catalog) + kirill/outputs/2026-09-20-salestype-2025-vs-2026.xlsx (Source sheet, Sale Type "107 - Pharmacies"). Product Key = CHEMIPAL Code where matched (via TRANS, automatically or via the 3 user-approved manual override RULES below); otherwise the raw item name itself, so every row from both sources is included - per 25/09/2026 instruction, ALL remaining unmatched SALES items are kept as their own product rows (not dropped), unlike a plain "exclude the unmatched" approach. Manual override RULES applied (same 3 rules already approved for מאוחדת, re-verified here against BOTH TRANS and the fuller 777-row Catalog): (1) "397"/"397A" - items whose description contains "אנטי" are the anti-bacterial variant of the same product: SALES "397-35-38" -> 4403041, "397-43-46" -> 4403043 (TRANS+Catalog agree). (2) "363" - "בננה" variants are the same product: SALES "363 L/R" -> 4402000 (TRANS+Catalog agree). (3) "394" color family (B=שחור/black, W=לבן/white, G=אפור/gray - 3 legitimate variants): unlike at מאוחדת (where TRANS lacked a 394G code and it was left Unmatched), the FULLER 777-row Catalog DOES have 394G codes (4403020/4403021/4403022) - and CEMI's own בתי מרקחת 2025 data already uses them (17/30/37 units respectively) - so SALES "394G-35-38/39-42/43-46" ARE matched here: -> 4403020/4403021/4403022. NOTE for Reuven: this suggests the earlier "no CHEMIPAL Code exists for 394G" conclusion at מאוחדת (based on TRANS alone) may be revisable using this fuller Catalog - flagged, not changed here (out of scope for this task). "67 0" (SALES, unmatched, no CHEMIPAL Code in either TRANS or the Catalog) is KEPT as its own product row in both years per explicit 25/09/2026 instruction ("פריט חשוב, אל תשמיט") - not excluded like a non-product adjustment line.
A5: Source | B5: Item Name (raw) | C5: Year | D5: Quantity | E5: Amount (₪) | F5: Product Key (CHEMIPAL Code or raw name)
A6: CEMI | B6: 369 S-L אצבעון מסיליקון יחידה | C6: 2025 | D6: 328 | E6: 7458.3 | F6: 4401000
A7: CEMI | B7: 369 S-L אצבעון מסיליקון יחידה | C7: 2026 | D7: 246 | E7: 5653.1 | F7: 4401000
A8: CEMI | B8: 369 XL אצבעון מסיליקון יחידה | C8: 2025 | D8: 415 | E8: 10264.8 | F8: 4401001
A9: CEMI | B9: 369 XL אצבעון מסיליקון יחידה | C9: 2026 | D9: 288 | E9: 7178.1 | F9: 4401001
A10: CEMI | B10: PD 344-אבן טבעית להסרת עור קשה | C10: 2025 | D10: 261 | E10: 2230.9 | F10: 4401002
A11: CEMI | B11: PD 344-אבן טבעית להסרת עור קשה | C11: 2026 | D11: 184 | E11: 1578.6 | F11: 4401002
A12: CEMI | B12: 805AT-Cאתלטיק טייפ בז' 20מ""מ20 | C12: 2025 | D12: 70 | E12: 1089.5 | F12: 4401011
A13: CEMI | B13: 805AT-Cאתלטיק טייפ בז' 20מ""מ20 | C13: 2026 | D13: 48 | E13: 788.6 | F13: 4401011
A14: CEMI | B14: 805AT-B אתלטיק טייפ שחור 20מ""מ | C14: 2025 | D14: 20 | E14: 318.7 | F14: 4401012
A15: CEMI | B15: 805AT-B אתלטיק טייפ שחור 20מ""מ | C15: 2026 | D15: 21 | E15: 358.6 | F15: 4401012
A16: CEMI | B16: 805AT-BLאתלטיק טייפ כחול 20מ""מ | C16: 2025 | D16: 19 | E16: 301.4 | F16: 4401013
A17: CEMI | B17: 805AT-BLאתלטיק טייפ כחול 20מ""מ | C17: 2026 | D17: 19 | E17: 319.4 | F17: 4401013
... A1530: SALES | B1530: SH422 6 | C1530: 2026 | D1530: 5 | E1530: 781.77 | F1530: 4422042
A1531: SALES | B1531: 062 XXL | C1531: 2025 | D1531: 0 | E1531: 0.01 | F1531: 062 XXL
A1532: SALES | B1532: 06U M | C1532: 2025 | D1532: 2 | E1532: 281.15 | F1532: 06U M
A1533: SALES | B1533: 06U XXL | C1533: 2025 | D1533: 1 | E1533: 140.57 | F1533: 06U XXL
A1534: SALES | B1534: 07UB-L-XL | C1534: 2025 | D1534: 50 | E1534: 6250 | F1534: 07UB-L-XL
A1535: SALES | B1535: 07UB-L-XL | C1535: 2026 | D1535: 1 | E1535: 234.31 | F1535: 07UB-L-XL
A1536: SALES | B1536: 07UB-S-M | C1536: 2025 | D1536: 10 | E1536: 1250 | F1536: 07UB-S-M
A1537: SALES | B1537: 10 XXL | C1537: 2025 | D1537: 10 | E1537: 1300 | F1537: 10 XXL
A1538: SALES | B1538: 11EU S | C1538: 2025 | D1538: 1 | E1538: 69.01 | F1538: 11EU S
A1539: SALES | B1539: 11EU S | C1539: 2026 | D1539: 1 | E1539: 85 | F1539: 11EU S
A1540: SALES | B1540: 11EU XS | C1540: 2025 | D1540: 1 | E1540: 69 | F1540: 11EU XS
A1541: SALES | B1541: 11PS M | C1541: 2025 | D1541: 1 | E1541: 135.88 | F1541: 11PS M
A1542: SALES | B1542: 13 L | C1542: 2026 | D1542: 1 | E1542: 156.97 | F1542: 13 L
... A1616: SALES | B1616: T45X M | C1616: 2026 | D1616: 2 | E1616: 236.26 | F1616: T45X M

Sheet BE
A1: Sales Comparison 2025 vs 2026 (Annualized) - Group: BE (by CHEMIPAL Code) — CEMI UPDATED 25/09/2026
A2: Calculation date: | B2: 46290
A3: Source: original raw PPLAY1 pivot files, summed across raw customer columns: BE, אילת BE, אילת זיכויי BE, הפרכל הפרפארם, זיכויים BE, שופרסל BE (same 6 categories as 2026-09-19-CEMI-grouped-2025-vs-2026.xlsx). REBUILT 25/09/2026 at true CHEMIPAL Code granularity via the Catalog sheet - match rate: 100% by quantity and amount.
A4: Annualization note: 2026 actual data covers approximately 9.5 months (1 Jan - 15 Sep 2026). Reused for consistency across the whole CEMI UPDATED file (per 25/09/2026 instruction), even for groups sourced from the newer "חנה_1" file whose own snapshot date (23/09/2026) would imply a slightly different factor (12/8.75) - straight-line extrapolation, no seasonality adjustment - treat as an estimate. | I4: Months in full year: | J4: 12 | K4: Months covered by 2026 actual (1/1–15/9): | L4: 9.5
A5: # DROP (sold 2025, 0 in 2026): | B5: =SUMPRODUCT(--((($C$9:$C$354<>0)+($H$9:$H$354<>0)>0)*(($D$9:$D$354=0)*($I$9:$I$354=0)))) -> 64 | C5: # NEW (sold 2026, 0 in 2025): | D5: =SUMPRODUCT(--((($D$9:$D$354<>0)+($I$9:$I$354<>0)>0)*(($C$9:$C$354=0)*($H$9:$H$354=0)))) -> 18 | I5: Normalization factor (J4/L4): | J5: =J4/L4 -> 1.2631579
A6: DROP — Quantity 2025: | B6: =SUMPRODUCT(--((($C$9:$C$354<>0)+($H$9:$H$354<>0)>0)*(($D$9:$D$354=0)*($I$9:$I$354=0)))*$C$9:$C$354) -> 55 | C6: DROP — Amount 2025 (₪): | D6: =SUMPRODUCT(--((($C$9:$C$354<>0)+($H$9:$H$354<>0)>0)*(($D$9:$D$354=0)*($I$9:$I$354=0)))*$H$9:$H$354) -> 4567.1 | E6: NEW — Quantity 2026: | F6: =SUMPRODUCT(--((($D$9:$D$354<>0)+($I$9:$I$354<>0)>0)*(($C$9:$C$354=0)*($H$9:$H$354=0)))*$D$9:$D$354) -> 11 | G6: NEW — Amount 2026 (₪): | H6: =SUMPRODUCT(--((($D$9:$D$354<>0)+($I$9:$I$354<>0)>0)*(($C$9:$C$354=0)*($H$9:$H$354=0)))*$I$9:$I$354) -> 1501.2 | I6: NEW — Quantity 2026 Annualized: | J6: =F6*$J$5 -> 13.894737 | K6: NEW — Amount 2026 Annualized (₪): | L6: =H6*$J$5 -> 1896.2526
A8: CHEMIPAL Code | B8: Product Name | C8: Quantity 2025 | D8: Quantity 2026 (Actual, partial year) | E8: Quantity 2026 (Annualized) | F8: Quantity Change (Annualized vs 2025) | G8: Quantity Change % (Annualized vs 2025) | H8: Amount 2025 (₪) | I8: Amount 2026 (Actual, partial year) (₪) | J8: Amount 2026 (Annualized) (₪)
A9: 4401000 | B9: =IFERROR(INDEX('Catalog'!$B:$B,MATCH($A9,'Catalog'!$A:$A,0)),"") -> 369 S-L אצבעון מסיליקון יחידה | C9: =SUMIFS('BE Raw'!$C$6:$C$615,'BE Raw'!$E$6:$E$615,$A9,'BE Raw'!$B$6:$B$615,2025) -> 134 | D9: =SUMIFS('BE Raw'!$C$6:$C$615,'BE Raw'!$E$6:$E$615,$A9,'BE Raw'!$B$6:$B$615,2026) -> 91 | E9: =D9*$J$5 -> 114.94737 | F9: =E9-C9 -> -19.052632 | G9: =IF(AND(C9=0,E9=0),0,IF(C9=0,"New",(E9-C9)/C9)) -> -0.14218382 | H9: =SUMIFS('BE Raw'!$D$6:$D$615,'BE Raw'!$E$6:$E$615,$A9,'BE Raw'!$B$6:$B$615,2025) -> 2713.5 | I9: =SUMIFS('BE Raw'!$D$6:$D$615,'BE Raw'!$E$6:$E$615,$A9,'BE Raw'!$B$6:$B$615,2026) -> 1849.2 | J9: =I9*$J$5 -> 2335.8316
A10: 4401001 | B10: =IFERROR(INDEX('Catalog'!$B:$B,MATCH($A10,'Catalog'!$A:$A,0)),"") -> 369 XL אצבעון מסיליקון יחידה | C10: =SUMIFS('BE Raw'!$C$6:$C$615,'BE Raw'!$E$6:$E$615,$A10,'BE Raw'!$B$6:$B$615,2025) -> 168 | D10: =SUMIFS('BE Raw'!$C$6:$C$615,'BE Raw'!$E$6:$E$615,$A10,'BE Raw'!$B$6:$B$615,2026) -> 90 | E10: =D10*$J$5 -> 113.68421 | F10: =E10-C10 -> -54.315789 | G10: =IF(AND(C10=0,E10=0),0,IF(C10=0,"New",(E10-C10)/C10)) -> -0.32330827 | H10: =SUMIFS('BE Raw'!$D$6:$D$615,'BE Raw'!$E$6:$E$615,$A10,'BE Raw'!$B$6:$B$615,2025) -> 3675.7 | I10: =SUMIFS('BE Raw'!$D$6:$D$615,'BE Raw'!$E$6:$E$615,$A10,'BE Raw'!$B$6:$B$615,2026) -> 1964.7 | J10: =I10*$J$5 -> 2481.7263
A11: 4401002 | B11: =IFERROR(INDEX('Catalog'!$B:$B,MATCH($A11,'Catalog'!$A:$A,0)),"") -> PD 344-אבן טבעית להסרת עור קשה | C11: =SUMIFS('BE Raw'!$C$6:$C$615,'BE Raw'!$E$6:$E$615,$A11,'BE Raw'!$B$6:$B$615,2025) -> 118 | D11: =SUMIFS('BE Raw'!$C$6:$C$615,'BE Raw'!$E$6:$E$615,$A11,'BE Raw'!$B$6:$B$615,2026) -> 160 | E11: =D11*$J$5 -> 202.10526 | F11: =E11-C11 -> 84.105263 | G11: =IF(AND(C11=0,E11=0),0,IF(C11=0,"New",(E11-C11)/C11)) -> 0.71275647 | H11: =SUMIFS('BE Raw'!$D$6:$D$615,'BE Raw'!$E$6:$E$615,$A11,'BE Raw'!$B$6:$B$615,2025) -> 852 | I11: =SUMIFS('BE Raw'!$D$6:$D$615,'BE Raw'!$E$6:$E$615,$A11,'BE Raw'!$B$6:$B$615,2026) -> 1155.2 | J11: =I11*$J$5 -> 1459.2
A12: 4402000 | B12: =IFERROR(INDEX('Catalog'!$B:$B,MATCH($A12,'Catalog'!$A:$A,0)),"") -> 363 בננה לתמיכת אצבעות ז.כרית | C12: =SUMIFS('BE Raw'!$C$6:$C$615,'BE Raw'!$E$6:$E$615,$A12,'BE Raw'!$B$6:$B$615,2025) -> 53 | D12: =SUMIFS('BE Raw'!$C$6:$C$615,'BE Raw'!$E$6:$E$615,$A12,'BE Raw'!$B$6:$B$615,2026) -> 24 | E12: =D12*$J$5 -> 30.315789 | F12: =E12-C12 -> -22.684211 | G12: =IF(AND(C12=0,E12=0),0,IF(C12=0,"New",(E12-C12)/C12)) -> -0.42800397 | H12: =SUMIFS('BE Raw'!$D$6:$D$615,'BE Raw'!$E$6:$E$615,$A12,'BE Raw'!$B$6:$B$615,2025) -> 1249.8 | I12: =SUMIFS('BE Raw'!$D$6:$D$615,'BE Raw'!$E$6:$E$615,$A12,'BE Raw'!$B$6:$B$615,2026) -> 565.9 | J12: =I12*$J$5 -> 714.82105
A13: 4402007 | B13: =IFERROR(INDEX('Catalog'!$B:$B,MATCH($A13,'Catalog'!$A:$A,0)),"") -> 320 בליסטר פלסטר | C13: =SUMIFS('BE Raw'!$C$6:$C$615,'BE Raw'!$E$6:$E$615,$A13,'BE Raw'!$B$6:$B$615,2025) -> 148 | D13: =SUMIFS('BE Raw'!$C$6:$C$615,'BE Raw'!$E$6:$E$615,$A13,'BE Raw'!$B$6:$B$615,2026) -> 40 | E13: =D13*$J$5 -> 50.526316 | F13: =E13-C13 -> -97.473684 | G13: =IF(AND(C13=0,E13=0),0,IF(C13=0,"New",(E13-C13)/C13)) -> -0.65860597 | H13: =SUMIFS('BE Raw'!$D$6:$D$615,'BE Raw'!$E$6:$E$615,$A13,'BE Raw'!$B$6:$B$615,2025) -> 2837.2 | I13: =SUMIFS('BE Raw'!$D$6:$D$615,'BE Raw'!$E$6:$E$615,$A13,'BE Raw'!$B$6:$B$615,2026) -> 766.8 | J13: =I13*$J$5 -> 968.58947
A14: 4402012 | B14: =IFERROR(INDEX('Catalog'!$B:$B,MATCH($A14,'Catalog'!$A:$A,0)),"") -> BE CARE תחבושת אלסטית 5 ס""מ | C14: =SUMIFS('BE Raw'!$C$6:$C$615,'BE Raw'!$E$6:$E$615,$A14,'BE Raw'!$B$6:$B$615,2025) -> -8 | D14: =SUMIFS('BE Raw'!$C$6:$C$615,'BE Raw'!$E$6:$E$615,$A14,'BE Raw'!$B$6:$B$615,2026) -> 0 | E14: =D14*$J$5 -> 0 | F14: =E14-C14 -> 8 | G14: =IF(AND(C14=0,E14=0),0,IF(C14=0,"New",(E14-C14)/C14)) -> -1 | H14: =SUMIFS('BE Raw'!$D$6:$D$615,'BE Raw'!$E$6:$E$615,$A14,'BE Raw'!$B$6:$B$615,2025) -> -26.4 | I14: =SUMIFS('BE Raw'!$D$6:$D$615,'BE Raw'!$E$6:$E$615,$A14,'BE Raw'!$B$6:$B$615,2026) -> 0 | J14: =I14*$J$5 -> 0
A15: 4402020 | B15: =IFERROR(INDEX('Catalog'!$B:$B,MATCH($A15,'Catalog'!$A:$A,0)),"") -> BE CARE KT BLACK | C15: =SUMIFS('BE Raw'!$C$6:$C$615,'BE Raw'!$E$6:$E$615,$A15,'BE Raw'!$B$6:$B$615,2025) -> -2 | D15: =SUMIFS('BE Raw'!$C$6:$C$615,'BE Raw'!$E$6:$E$615,$A15,'BE Raw'!$B$6:$B$615,2026) -> 0 | E15: =D15*$J$5 -> 0 | F15: =E15-C15 -> 2 | G15: =IF(AND(C15=0,E15=0),0,IF(C15=0,"New",(E15-C15)/C15)) -> -1 | H15: =SUMIFS('BE Raw'!$D$6:$D$615,'BE Raw'!$E$6:$E$615,$A15,'BE Raw'!$B$6:$B$615,2025) -> -48 | I15: =SUMIFS('BE Raw'!$D$6:$D$615,'BE Raw'!$E$6:$E$615,$A15,'BE Raw'!$B$6:$B$615,2026) -> 0 | J15: =I15*$J$5 -> 0
A16: 4402021 | B16: =IFERROR(INDEX('Catalog'!$B:$B,MATCH($A16,'Catalog'!$A:$A,0)),"") -> BE CARE KT BLUE | C16: =SUMIFS('BE Raw'!$C$6:$C$615,'BE Raw'!$E$6:$E$615,$A16,'BE Raw'!$B$6:$B$615,2025) -> -1 | D16: =SUMIFS('BE Raw'!$C$6:$C$615,'BE Raw'!$E$6:$E$615,$A16,'BE Raw'!$B$6:$B$615,2026) -> 0 | E16: =D16*$J$5 -> 0 | F16: =E16-C16 -> 1 | G16: =IF(AND(C16=0,E16=0),0,IF(C16=0,"New",(E16-C16)/C16)) -> -1 | H16: =SUMIFS('BE Raw'!$D$6:$D$615,'BE Raw'!$E$6:$E$615,$A16,'BE Raw'!$B$6:$B$615,2025) -> -24 | I16: =SUMIFS('BE Raw'!$D$6:$D$615,'BE Raw'!$E$6:$E$615,$A16,'BE Raw'!$B$6:$B$615,2026) -> 0 | J16: =I16*$J$5 -> 0
A17: 4403000 | B17: =IFERROR(INDEX('Catalog'!$B:$B,MATCH($A17,'Catalog'!$A:$A,0)),"") -> 390B גרב.כסף לסכרתים שחור35-38 | C17: =SUMIFS('BE Raw'!$C$6:$C$615,'BE Raw'!$E$6:$E$615,$A17,'BE Raw'!$B$6:$B$615,2025) -> 0 | D17: =SUMIFS('BE Raw'!$C$6:$C$615,'BE Raw'!$E$6:$E$615,$A17,'BE Raw'!$B$6:$B$615,2026) -> 4 | E17: =D17*$J$5 -> 5.0526316 | F17: =E17-C17 -> 5.0526316 | G17: =IF(AND(C17=0,E17=0),0,IF(C17=0,"New",(E17-C17)/C17)) -> New | H17: =SUMIFS('BE Raw'!$D$6:$D$615,'BE Raw'!$E$6:$E$615,$A17,'BE Raw'!$B$6:$B$615,2025) -> 0 | I17: =SUMIFS('BE Raw'!$D$6:$D$615,'BE Raw'!$E$6:$E$615,$A17,'BE Raw'!$B$6:$B$615,2026) -> 125.8 | J17: =I17*$J$5 -> 158.90526
A18: 4403001 | B18: =IFERROR(INDEX('Catalog'!$B:$B,MATCH($A18,'Catalog'!$A:$A,0)),"") -> 390B 39-42.גרב.כסף לסכרתיים שח | C18: =SUMIFS('BE Raw'!$C$6:$C$615,'BE Raw'!$E$6:$E$615,$A18,'BE Raw'!$B$6:$B$615,2025) -> 14 | D18: =SUMIFS('BE Raw'!$C$6:$C$615,'BE Raw'!$E$6:$E$615,$A18,'BE Raw'!$B$6:$B$615,2026) -> 2 | E18: =D18*$J$5 -> 2.5263158 | F18: =E18-C18 -> -11.473684 | G18: =IF(AND(C18=0,E18=0),0,IF(C18=0,"New",(E18-C18)/C18)) -> -0.81954887 | H18: =SUMIFS('BE Raw'!$D$6:$D$615,'BE Raw'!$E$6:$E$615,$A18,'BE Raw'!$B$6:$B$615,2025) -> 440.4 | I18: =SUMIFS('BE Raw'!$D$6:$D$615,'BE Raw'!$E$6:$E$615,$A18,'BE Raw'!$B$6:$B$615,2026) -> 62.9 | J18: =I18*$J$5 -> 79.452632
A19: 4403002 | B19: =IFERROR(INDEX('Catalog'!$B:$B,MATCH($A19,'Catalog'!$A:$A,0)),"") -> 390B 43-46.גרב.כסף לסכרתיים שח | C19: =SUMIFS('BE Raw'!$C$6:$C$615,'BE Raw'!$E$6:$E$615,$A19,'BE Raw'!$B$6:$B$615,2025) -> 18 | D19: =SUMIFS('BE Raw'!$C$6:$C$615,'BE Raw'!$E$6:$E$615,$A19,'BE Raw'!$B$6:$B$615,2026) -> 2 | E19: =D19*$J$5 -> 2.5263158 | F19: =E19-C19 -> -15.473684 | G19: =IF(AND(C19=0,E19=0),0,IF(C19=0,"New",(E19-C19)/C19)) -> -0.85964912 | H19: =SUMIFS('BE Raw'!$D$6:$D$615,'BE Raw'!$E$6:$E$615,$A19,'BE Raw'!$B$6:$B$615,2025) -> 566.3 | I19: =SUMIFS('BE Raw'!$D$6:$D$615,'BE Raw'!$E$6:$E$615,$A19,'BE Raw'!$B$6:$B$615,2026) -> 62.9 | J19: =I19*$J$5 -> 79.452632
A20: 4403003 | B20: =IFERROR(INDEX('Catalog'!$B:$B,MATCH($A20,'Catalog'!$A:$A,0)),"") -> 390G ג.כסף לסכרתיים אפור35-38 | C20: =SUMIFS('BE Raw'!$C$6:$C$615,'BE Raw'!$E$6:$E$615,$A20,'BE Raw'!$B$6:$B$615,2025) -> 2 | D20: =SUMIFS('BE Raw'!$C$6:$C$615,'BE Raw'!$E$6:$E$615,$A20,'BE Raw'!$B$6:$B$615,2026) -> 0 | E20: =D20*$J$5 -> 0 | F20: =E20-C20 -> -2 | G20: =IF(AND(C20=0,E20=0),0,IF(C20=0,"New",(E20-C20)/C20)) -> -1 | H20: =SUMIFS('BE Raw'!$D$6:$D$615,'BE Raw'!$E$6:$E$615,$A20,'BE Raw'!$B$6:$B$615,2025) -> 62.9 | I20: =SUMIFS('BE Raw'!$D$6:$D$615,'BE Raw'!$E$6:$E$615,$A20,'BE Raw'!$B$6:$B$615,2026) -> 0 | J20: =I20*$J$5 -> 0
... A354: 4422026 | B354: =IFERROR(INDEX('Catalog'!$B:$B,MATCH($A354,'Catalog'!$A:$A,0)),"") -> 806CB-PINK תחבושת א.נצמ | C354: =SUMIFS('BE Raw'!$C$6:$C$615,'BE Raw'!$E$6:$E$615,$A354,'BE Raw'!$B$6:$B$615,2025) -> 355 | D354: =SUMIFS('BE Raw'!$C$6:$C$615,'BE Raw'!$E$6:$E$615,$A354,'BE Raw'!$B$6:$B$615,2026) -> 277 | E354: =D354*$J$5 -> 349.89474 | F354: =E354-C354 -> -5.1052632 | G354: =IF(AND(C354=0,E354=0),0,IF(C354=0,"New",(E354-C354)/C354)) -> -0.014381023 | H354: =SUMIFS('BE Raw'!$D$6:$D$615,'BE Raw'!$E$6:$E$615,$A354,'BE Raw'!$B$6:$B$615,2025) -> 3897.9 | I354: =SUMIFS('BE Raw'!$D$6:$D$615,'BE Raw'!$E$6:$E$615,$A354,'BE Raw'!$B$6:$B$615,2026) -> 3041.5 | J354: =I354*$J$5 -> 3841.8947
B356: TOTAL | C356: =SUM(C9:C354) -> 27268 | D356: =SUM(D9:D354) -> 19109 | E356: =SUM(E9:E354) -> 24137.684 | F356: =SUM(F9:F354) -> -3130.3158 | G356: =IF(C356=0,"N/A",F356/C356) -> -0.11479814 | H356: =SUM(H9:H354) -> 889501.1 | I356: =SUM(I9:I354) -> 676265.8 | J356: =SUM(J9:J354) -> 854230.48

Sheet BE Raw
A1: BE Raw — item-level data with CHEMIPAL Code (matched via Catalog sheet)
A2: Calculation date: | B2: 46290
A3: Item-level data for group "BE", pre-aggregation, from the original raw PPLAY1 files. CHEMIPAL Code matched live against the Catalog sheet (exact match first, then whitespace-normalized fallback). Match rate for this group: 100% (verified in Python before building this file).
A5: Item Name (raw) | B5: Year | C5: Quantity | D5: Amount (₪) | E5: CHEMIPAL Code | F5: Match Status
A6: 369 S-L אצבעון מסיליקון יחידה | B6: 2025 | C6: 134 | D6: 2713.5 | E6: =IFERROR(INDEX('Catalog'!$A:$A,MATCH($A6,'Catalog'!$B:$B,0)),IFERROR(INDEX('Catalog'!$A:$A,MATCH(TRIM(SUBSTITUTE($A6,CHAR(160)," ")),'Catalog'!$C:$C,0)),"")) -> 4401000 | F6: =IF($E6="","Unmatched","Matched") -> Matched
A7: 369 XL אצבעון מסיליקון יחידה | B7: 2025 | C7: 168 | D7: 3675.7 | E7: =IFERROR(INDEX('Catalog'!$A:$A,MATCH($A7,'Catalog'!$B:$B,0)),IFERROR(INDEX('Catalog'!$A:$A,MATCH(TRIM(SUBSTITUTE($A7,CHAR(160)," ")),'Catalog'!$C:$C,0)),"")) -> 4401001 | F7: =IF($E7="","Unmatched","Matched") -> Matched
A8: PD 344-אבן טבעית להסרת עור קשה | B8: 2025 | C8: 118 | D8: 852 | E8: =IFERROR(INDEX('Catalog'!$A:$A,MATCH($A8,'Catalog'!$B:$B,0)),IFERROR(INDEX('Catalog'!$A:$A,MATCH(TRIM(SUBSTITUTE($A8,CHAR(160)," ")),'Catalog'!$C:$C,0)),"")) -> 4401002 | F8: =IF($E8="","Unmatched","Matched") -> Matched
A9: 363 בננה לתמיכת אצבעות ז.כרית | B9: 2025 | C9: 53 | D9: 1249.8 | E9: =IFERROR(INDEX('Catalog'!$A:$A,MATCH($A9,'Catalog'!$B:$B,0)),IFERROR(INDEX('Catalog'!$A:$A,MATCH(TRIM(SUBSTITUTE($A9,CHAR(160)," ")),'Catalog'!$C:$C,0)),"")) -> 4402000 | F9: =IF($E9="","Unmatched","Matched") -> Matched
A10: 320 בליסטר פלסטר | B10: 2025 | C10: 148 | D10: 2837.2 | E10: =IFERROR(INDEX('Catalog'!$A:$A,MATCH($A10,'Catalog'!$B:$B,0)),IFERROR(INDEX('Catalog'!$A:$A,MATCH(TRIM(SUBSTITUTE($A10,CHAR(160)," ")),'Catalog'!$C:$C,0)),"")) -> 4402007 | F10: =IF($E10="","Unmatched","Matched") -> Matched
A11: 390B 39-42.גרב.כסף לסכרתיים שח | B11: 2025 | C11: 14 | D11: 440.4 | E11: =IFERROR(INDEX('Catalog'!$A:$A,MATCH($A11,'Catalog'!$B:$B,0)),IFERROR(INDEX('Catalog'!$A:$A,MATCH(TRIM(SUBSTITUTE($A11,CHAR(160)," ")),'Catalog'!$C:$C,0)),"")) -> 4403001 | F11: =IF($E11="","Unmatched","Matched") -> Matched
A12: 390B 43-46.גרב.כסף לסכרתיים שח | B12: 2025 | C12: 18 | D12: 566.3 | E12: =IFERROR(INDEX('Catalog'!$A:$A,MATCH($A12,'Catalog'!$B:$B,0)),IFERROR(INDEX('Catalog'!$A:$A,MATCH(TRIM(SUBSTITUTE($A12,CHAR(160)," ")),'Catalog'!$C:$C,0)),"")) -> 4403002 | F12: =IF($E12="","Unmatched","Matched") -> Matched
A13: 390G ג.כסף לסכרתיים אפור35-38 | B13: 2025 | C13: 2 | D13: 62.9 | E13: =IFERROR(INDEX('Catalog'!$A:$A,MATCH($A13,'Catalog'!$B:$B,0)),IFERROR(INDEX('Catalog'!$A:$A,MATCH(TRIM(SUBSTITUTE($A13,CHAR(160)," ")),'Catalog'!$C:$C,0)),"")) -> 4403003 | F13: =IF($E13="","Unmatched","Matched") -> Matched
A14: 390G 39-42.גרב.כסף לסכרתיים אפ | B14: 2025 | C14: 2 | D14: 62.9 | E14: =IFERROR(INDEX('Catalog'!$A:$A,MATCH($A14,'Catalog'!$B:$B,0)),IFERROR(INDEX('Catalog'!$A:$A,MATCH(TRIM(SUBSTITUTE($A14,CHAR(160)," ")),'Catalog'!$C:$C,0)),"")) -> 4403004 | F14: =IF($E14="","Unmatched","Matched") -> Matched
A15: G390.43-46 גרבי כסף לסכרת מידה | B15: 2025 | C15: 3 | D15: 79 | E15: =IFERROR(INDEX('Catalog'!$A:$A,MATCH($A15,'Catalog'!$B:$B,0)),IFERROR(INDEX('Catalog'!$A:$A,MATCH(TRIM(SUBSTITUTE($A15,CHAR(160)," ")),'Catalog'!$C:$C,0)),"")) -> 4403005 | F15: =IF($E15="","Unmatched","Matched") -> Matched
A16: 390W גרב כסף לסכרתיים לבן35-38 | B16: 2025 | C16: 2 | D16: 62.9 | E16: =IFERROR(INDEX('Catalog'!$A:$A,MATCH($A16,'Catalog'!$B:$B,0)),IFERROR(INDEX('Catalog'!$A:$A,MATCH(TRIM(SUBSTITUTE($A16,CHAR(160)," ")),'Catalog'!$C:$C,0)),"")) -> 4403006 | F16: =IF($E16="","Unmatched","Matched") -> Matched
A17: 390W גרב.כסף לסכרתיים לבן39-42 | B17: 2025 | C17: 16 | D17: 499.9 | E17: =IFERROR(INDEX('Catalog'!$A:$A,MATCH($A17,'Catalog'!$B:$B,0)),IFERROR(INDEX('Catalog'!$A:$A,MATCH(TRIM(SUBSTITUTE($A17,CHAR(160)," ")),'Catalog'!$C:$C,0)),"")) -> 4403007 | F17: =IF($E17="","Unmatched","Matched") -> Matched
... A615: סד קיבוע לאצבע הדק | B615: 2026 | C615: 30 | D615: 1216.8 | E615: =IFERROR(INDEX('Catalog'!$A:$A,MATCH($A615,'Catalog'!$B:$B,0)),IFERROR(INDEX('Catalog'!$A:$A,MATCH(TRIM(SUBSTITUTE($A615,CHAR(160)," ")),'Catalog'!$C:$C,0)),"")) -> 4415029 | F615: =IF($E615="","Unmatched","Matched") -> Matched

Sheet סופר פארם
A1: Sales Comparison 2025 vs 2026 (Annualized) - Group: סופר פארם (by CHEMIPAL Code) — CEMI UPDATED 25/09/2026
A2: Calculation date: | B2: 46290
A3: Source: original raw PPLAY1 pivot files, raw customer column: סופרפארם (same as 2026-09-19-CEMI-grouped-2025-vs-2026.xlsx). REBUILT 25/09/2026 at true CHEMIPAL Code granularity via the Catalog sheet - match rate: 100% by quantity and amount.
A4: Annualization note: 2026 actual data covers approximately 9.5 months (1 Jan - 15 Sep 2026). Reused for consistency across the whole CEMI UPDATED file (per 25/09/2026 instruction), even for groups sourced from the newer "חנה_1" file whose own snapshot date (23/09/2026) would imply a slightly different factor (12/8.75) - straight-line extrapolation, no seasonality adjustment - treat as an estimate. | I4: Months in full year: | J4: 12 | K4: Months covered by 2026 actual (1/1–15/9): | L4: 9.5
A5: # DROP (sold 2025, 0 in 2026): | B5: =SUMPRODUCT(--((($C$9:$C$444<>0)+($H$9:$H$444<>0)>0)*(($D$9:$D$444=0)*($I$9:$I$444=0)))) -> 54 | C5: # NEW (sold 2026, 0 in 2025): | D5: =SUMPRODUCT(--((($D$9:$D$444<>0)+($I$9:$I$444<>0)>0)*(($C$9:$C$444=0)*($H$9:$H$444=0)))) -> 52 | I5: Normalization factor (J4/L4): | J5: =J4/L4 -> 1.2631579
A6: DROP — Quantity 2025: | B6: =SUMPRODUCT(--((($C$9:$C$444<>0)+($H$9:$H$444<>0)>0)*(($D$9:$D$444=0)*($I$9:$I$444=0)))*$C$9:$C$444) -> 23 | C6: DROP — Amount 2025 (₪): | D6: =SUMPRODUCT(--((($C$9:$C$444<>0)+($H$9:$H$444<>0)>0)*(($D$9:$D$444=0)*($I$9:$I$444=0)))*$H$9:$H$444) -> -2700.3 | E6: NEW — Quantity 2026: | F6: =SUMPRODUCT(--((($D$9:$D$444<>0)+($I$9:$I$444<>0)>0)*(($C$9:$C$444=0)*($H$9:$H$444=0)))*$D$9:$D$444) -> 1939 | G6: NEW — Amount 2026 (₪): | H6: =SUMPRODUCT(--((($D$9:$D$444<>0)+($I$9:$I$444<>0)>0)*(($C$9:$C$444=0)*($H$9:$H$444=0)))*$I$9:$I$444) -> 146776.3 | I6: NEW — Quantity 2026 Annualized: | J6: =F6*$J$5 -> 2449.2632 | K6: NEW — Amount 2026 Annualized (₪): | L6: =H6*$J$5 -> 185401.64
A8: CHEMIPAL Code | B8: Product Name | C8: Quantity 2025 | D8: Quantity 2026 (Actual, partial year) | E8: Quantity 2026 (Annualized) | F8: Quantity Change (Annualized vs 2025) | G8: Quantity Change % (Annualized vs 2025) | H8: Amount 2025 (₪) | I8: Amount 2026 (Actual, partial year) (₪) | J8: Amount 2026 (Annualized) (₪)
A9: 4401000 | B9: =IFERROR(INDEX('Catalog'!$B:$B,MATCH($A9,'Catalog'!$A:$A,0)),"") -> 369 S-L אצבעון מסיליקון יחידה | C9: =SUMIFS('סופר פארם Raw'!$C$6:$C$771,'סופר פארם Raw'!$E$6:$E$771,$A9,'סופר פארם Raw'!$B$6:$B$771,2025) -> 1030 | D9: =SUMIFS('סופר פארם Raw'!$C$6:$C$771,'סופר פארם Raw'!$E$6:$E$771,$A9,'סופר פארם Raw'!$B$6:$B$771,2026) -> 742 | E9: =D9*$J$5 -> 937.26316 | F9: =E9-C9 -> -92.736842 | G9: =IF(AND(C9=0,E9=0),0,IF(C9=0,"New",(E9-C9)/C9)) -> -0.090035769 | H9: =SUMIFS('סופר פארם Raw'!$D$6:$D$771,'סופר פארם Raw'!$E$6:$E$771,$A9,'סופר פארם Raw'!$B$6:$B$771,2025) -> 22376.6 | I9: =SUMIFS('סופר פארם Raw'!$D$6:$D$771,'סופר פארם Raw'!$E$6:$E$771,$A9,'סופר פארם Raw'!$B$6:$B$771,2026) -> 16354.5 | J9: =I9*$J$5 -> 20658.316
A10: 4401001 | B10: =IFERROR(INDEX('Catalog'!$B:$B,MATCH($A10,'Catalog'!$A:$A,0)),"") -> 369 XL אצבעון מסיליקון יחידה | C10: =SUMIFS('סופר פארם Raw'!$C$6:$C$771,'סופר פארם Raw'!$E$6:$E$771,$A10,'סופר פארם Raw'!$B$6:$B$771,2025) -> 1142 | D10: =SUMIFS('סופר פארם Raw'!$C$6:$C$771,'סופר פארם Raw'!$E$6:$E$771,$A10,'סופר פארם Raw'!$B$6:$B$771,2026) -> 807 | E10: =D10*$J$5 -> 1019.3684 | F10: =E10-C10 -> -122.63158 | G10: =IF(AND(C10=0,E10=0),0,IF(C10=0,"New",(E10-C10)/C10)) -> -0.10738317 | H10: =SUMIFS('סופר פארם Raw'!$D$6:$D$771,'סופר פארם Raw'!$E$6:$E$771,$A10,'סופר פארם Raw'!$B$6:$B$771,2025) -> 25972.9 | I10: =SUMIFS('סופר פארם Raw'!$D$6:$D$771,'סופר פארם Raw'!$E$6:$E$771,$A10,'סופר פארם Raw'!$B$6:$B$771,2026) -> 18338.8 | J10: =I10*$J$5 -> 23164.8
A11: 4402000 | B11: =IFERROR(INDEX('Catalog'!$B:$B,MATCH($A11,'Catalog'!$A:$A,0)),"") -> 363 בננה לתמיכת אצבעות ז.כרית | C11: =SUMIFS('סופר פארם Raw'!$C$6:$C$771,'סופר פארם Raw'!$E$6:$E$771,$A11,'סופר פארם Raw'!$B$6:$B$771,2025) -> 199 | D11: =SUMIFS('סופר פארם Raw'!$C$6:$C$771,'סופר פארם Raw'!$E$6:$E$771,$A11,'סופר פארם Raw'!$B$6:$B$771,2026) -> 101 | E11: =D11*$J$5 -> 127.57895 | F11: =E11-C11 -> -71.421053 | G11: =IF(AND(C11=0,E11=0),0,IF(C11=0,"New",(E11-C11)/C11)) -> -0.35889976 | H11: =SUMIFS('סופר פארם Raw'!$D$6:$D$771,'סופר פארם Raw'!$E$6:$E$771,$A11,'סופר פארם Raw'!$B$6:$B$771,2025) -> 4320.4 | I11: =SUMIFS('סופר פארם Raw'!$D$6:$D$771,'סופר פארם Raw'!$E$6:$E$771,$A11,'סופר פארם Raw'!$B$6:$B$771,2026) -> 2224.3 | J11: =I11*$J$5 -> 2809.6421
A12: 4402007 | B12: =IFERROR(INDEX('Catalog'!$B:$B,MATCH($A12,'Catalog'!$A:$A,0)),"") -> 320 בליסטר פלסטר | C12: =SUMIFS('סופר פארם Raw'!$C$6:$C$771,'סופר פארם Raw'!$E$6:$E$771,$A12,'סופר פארם Raw'!$B$6:$B$771,2025) -> 1909 | D12: =SUMIFS('סופר פארם Raw'!$C$6:$C$771,'סופר פארם Raw'!$E$6:$E$771,$A12,'סופר פארם Raw'!$B$6:$B$771,2026) -> 1332 | E12: =D12*$J$5 -> 1682.5263 | F12: =E12-C12 -> -226.47368 | G12: =IF(AND(C12=0,E12=0),0,IF(C12=0,"New",(E12-C12)/C12)) -> -0.11863472 | H12: =SUMIFS('סופר פארם Raw'!$D$6:$D$771,'סופר פארם Raw'!$E$6:$E$771,$A12,'סופר פארם Raw'!$B$6:$B$771,2025) -> 33927.9 | I12: =SUMIFS('סופר פארם Raw'!$D$6:$D$771,'סופר פארם Raw'!$E$6:$E$771,$A12,'סופר פארם Raw'!$B$6:$B$771,2026) -> 23901.8 | J12: =I12*$J$5 -> 30191.747
A13: 4403000 | B13: =IFERROR(INDEX('Catalog'!$B:$B,MATCH($A13,'Catalog'!$A:$A,0)),"") -> 390B גרב.כסף לסכרתים שחור35-38 | C13: =SUMIFS('סופר פארם Raw'!$C$6:$C$771,'סופר פארם Raw'!$E$6:$E$771,$A13,'סופר פארם Raw'!$B$6:$B$771,2025) -> 30 | D13: =SUMIFS('סופר פארם Raw'!$C$6:$C$771,'סופר פארם Raw'!$E$6:$E$771,$A13,'סופר פארם Raw'!$B$6:$B$771,2026) -> 7 | E13: =D13*$J$5 -> 8.8421053 | F13: =E13-C13 -> -21.157895 | G13: =IF(AND(C13=0,E13=0),0,IF(C13=0,"New",(E13-C13)/C13)) -> -0.70526316 | H13: =SUMIFS('סופר פארם Raw'!$D$6:$D$771,'סופר פארם Raw'!$E$6:$E$771,$A13,'סופר פארם Raw'!$B$6:$B$771,2025) -> 882.1 | I13: =SUMIFS('סופר פארם Raw'!$D$6:$D$771,'סופר פארם Raw'!$E$6:$E$771,$A13,'סופר פארם Raw'!$B$6:$B$771,2026) -> 211.3 | J13: =I13*$J$5 -> 266.90526
