Workbook

Sheet CHMI קבוצות לקוחות
A1: קבוצות לקוחות — ספירת לקוחות (שורות) לפי קבוצה, מתוך דוח PPlay1 of uriel (Reporter)
A3: קבוצת לקוחות | B3: מספר לקוחות (שורות) | C3: סכום 2025 (מקור) | D3: סכום 2026 (מקור)
A4: 0בתי טבע | B4: =COUNTIF('קבוצות לקוחות - מקור'!$A$2:$A$945,$A4) | C4: =SUMIF('קבוצות לקוחות - מקור'!$A$2:$A$945,$A4,'קבוצות לקוחות - מקור'!$C$2:$C$945) | D4: =SUMIF('קבוצות לקוחות - מקור'!$A$2:$A$945,$A4,'קבוצות לקוחות - מקור'!$D$2:$D$945)
A5: 0בתי טבע רשתות | B5: =COUNTIF('קבוצות לקוחות - מקור'!$A$2:$A$945,$A5) | C5: =SUMIF('קבוצות לקוחות - מקור'!$A$2:$A$945,$A5,'קבוצות לקוחות - מקור'!$C$2:$C$945) | D5: =SUMIF('קבוצות לקוחות - מקור'!$A$2:$A$945,$A5,'קבוצות לקוחות - מקור'!$D$2:$D$945)
A6: 0בתי מרקחת | B6: =COUNTIF('קבוצות לקוחות - מקור'!$A$2:$A$945,$A6) | C6: =SUMIF('קבוצות לקוחות - מקור'!$A$2:$A$945,$A6,'קבוצות לקוחות - מקור'!$C$2:$C$945) | D6: =SUMIF('קבוצות לקוחות - מקור'!$A$2:$A$945,$A6,'קבוצות לקוחות - מקור'!$D$2:$D$945)
A7: מגזר ערבי | B7: =COUNTIF('קבוצות לקוחות - מקור'!$A$2:$A$945,$A7) | C7: =SUMIF('קבוצות לקוחות - מקור'!$A$2:$A$945,$A7,'קבוצות לקוחות - מקור'!$C$2:$C$945) | D7: =SUMIF('קבוצות לקוחות - מקור'!$A$2:$A$945,$A7,'קבוצות לקוחות - מקור'!$D$2:$D$945)
A8: רוקחים עתיד | B8: =COUNTIF('קבוצות לקוחות - מקור'!$A$2:$A$945,$A8) | C8: =SUMIF('קבוצות לקוחות - מקור'!$A$2:$A$945,$A8,'קבוצות לקוחות - מקור'!$C$2:$C$945) | D8: =SUMIF('קבוצות לקוחות - מקור'!$A$2:$A$945,$A8,'קבוצות לקוחות - מקור'!$D$2:$D$945)
A9: רשת י-ם | B9: =COUNTIF('קבוצות לקוחות - מקור'!$A$2:$A$945,$A9) | C9: =SUMIF('קבוצות לקוחות - מקור'!$A$2:$A$945,$A9,'קבוצות לקוחות - מקור'!$C$2:$C$945) | D9: =SUMIF('קבוצות לקוחות - מקור'!$A$2:$A$945,$A9,'קבוצות לקוחות - מקור'!$D$2:$D$945)
A10: שור טבצניק | B10: =COUNTIF('קבוצות לקוחות - מקור'!$A$2:$A$945,$A10) | C10: =SUMIF('קבוצות לקוחות - מקור'!$A$2:$A$945,$A10,'קבוצות לקוחות - מקור'!$C$2:$C$945) | D10: =SUMIF('קבוצות לקוחות - מקור'!$A$2:$A$945,$A10,'קבוצות לקוחות - מקור'!$D$2:$D$945)
A11: שרם | B11: =COUNTIF('קבוצות לקוחות - מקור'!$A$2:$A$945,$A11) | C11: =SUMIF('קבוצות לקוחות - מקור'!$A$2:$A$945,$A11,'קבוצות לקוחות - מקור'!$C$2:$C$945) | D11: =SUMIF('קבוצות לקוחות - מקור'!$A$2:$A$945,$A11,'קבוצות לקוחות - מקור'!$D$2:$D$945)
A12: 0כללי | B12: =COUNTIF('קבוצות לקוחות - מקור'!$A$2:$A$945,$A12) | C12: =SUMIF('קבוצות לקוחות - מקור'!$A$2:$A$945,$A12,'קבוצות לקוחות - מקור'!$C$2:$C$945) | D12: =SUMIF('קבוצות לקוחות - מקור'!$A$2:$A$945,$A12,'קבוצות לקוחות - מקור'!$D$2:$D$945)
A13: 0מפיצי משנה | B13: =COUNTIF('קבוצות לקוחות - מקור'!$A$2:$A$945,$A13) | C13: =SUMIF('קבוצות לקוחות - מקור'!$A$2:$A$945,$A13,'קבוצות לקוחות - מקור'!$C$2:$C$945) | D13: =SUMIF('קבוצות לקוחות - מקור'!$A$2:$A$945,$A13,'קבוצות לקוחות - מקור'!$D$2:$D$945)
A14: ס. פארם | B14: =COUNTIF('קבוצות לקוחות - מקור'!$A$2:$A$945,$A14) | C14: =SUMIF('קבוצות לקוחות - מקור'!$A$2:$A$945,$A14,'קבוצות לקוחות - מקור'!$C$2:$C$945) | D14: =SUMIF('קבוצות לקוחות - מקור'!$A$2:$A$945,$A14,'קבוצות לקוחות - מקור'!$D$2:$D$945)
A15: BE | B15: =COUNTIF('קבוצות לקוחות - מקור'!$A$2:$A$945,$A15) | C15: =SUMIF('קבוצות לקוחות - מקור'!$A$2:$A$945,$A15,'קבוצות לקוחות - מקור'!$C$2:$C$945) | D15: =SUMIF('קבוצות לקוחות - מקור'!$A$2:$A$945,$A15,'קבוצות לקוחות - מקור'!$D$2:$D$945)
... A20: 0שונות | B20: =COUNTIF('קבוצות לקוחות - מקור'!$A$2:$A$945,$A20) | C20: =SUMIF('קבוצות לקוחות - מקור'!$A$2:$A$945,$A20,'קבוצות לקוחות - מקור'!$C$2:$C$945) | D20: =SUMIF('קבוצות לקוחות - מקור'!$A$2:$A$945,$A20,'קבוצות לקוחות - מקור'!$D$2:$D$945)
A21: סה"כ 17 קבוצות | B21: =SUM(B4:B20) | C21: =SUM(C4:C20) | D21: =SUM(D4:D20)

Sheet נקודות לפי סוכן 2026
A1: נקודות לכל סוכן בכל קבוצת לקוחות — מתוך דוח PPlay1 of uriel (Reporter), "2026_נקודות_של_סוכן_1"
A3: קבוצת לקוחות | B3: חיים וייצמ | C3: חאזם תלחמי | D3: סטאס נסאר | E3: עיסא | F3: .דוד א | G3: לא מטופל | H3: סה"כ נקודות (קבוצה)
A4: 0בתי מרקחת | B4: =COUNTIFS('נקודות - מקור'!$A$2:$A$564,$A4,'נקודות - מקור'!$C$2:$C$564,"<>0") | C4: =COUNTIFS('נקודות - מקור'!$A$2:$A$564,$A4,'נקודות - מקור'!$D$2:$D$564,"<>0") | D4: =COUNTIFS('נקודות - מקור'!$A$2:$A$564,$A4,'נקודות - מקור'!$E$2:$E$564,"<>0") | E4: =COUNTIFS('נקודות - מקור'!$A$2:$A$564,$A4,'נקודות - מקור'!$F$2:$F$564,"<>0") | F4: =COUNTIFS('נקודות - מקור'!$A$2:$A$564,$A4,'נקודות - מקור'!$G$2:$G$564,"<>0") | G4: =COUNTIFS('נקודות - מקור'!$A$2:$A$564,$A4,'נקודות - מקור'!$H$2:$H$564,0) | H4: =COUNTIFS('נקודות - מקור'!$A$2:$A$564,$A4)
A5: מגזר ערבי | B5: =COUNTIFS('נקודות - מקור'!$A$2:$A$564,$A5,'נקודות - מקור'!$C$2:$C$564,"<>0") | C5: =COUNTIFS('נקודות - מקור'!$A$2:$A$564,$A5,'נקודות - מקור'!$D$2:$D$564,"<>0") | D5: =COUNTIFS('נקודות - מקור'!$A$2:$A$564,$A5,'נקודות - מקור'!$E$2:$E$564,"<>0") | E5: =COUNTIFS('נקודות - מקור'!$A$2:$A$564,$A5,'נקודות - מקור'!$F$2:$F$564,"<>0") | F5: =COUNTIFS('נקודות - מקור'!$A$2:$A$564,$A5,'נקודות - מקור'!$G$2:$G$564,"<>0") | G5: =COUNTIFS('נקודות - מקור'!$A$2:$A$564,$A5,'נקודות - מקור'!$H$2:$H$564,0) | H5: =COUNTIFS('נקודות - מקור'!$A$2:$A$564,$A5)
A6: רוקחים עתיד | B6: =COUNTIFS('נקודות - מקור'!$A$2:$A$564,$A6,'נקודות - מקור'!$C$2:$C$564,"<>0") | C6: =COUNTIFS('נקודות - מקור'!$A$2:$A$564,$A6,'נקודות - מקור'!$D$2:$D$564,"<>0") | D6: =COUNTIFS('נקודות - מקור'!$A$2:$A$564,$A6,'נקודות - מקור'!$E$2:$E$564,"<>0") | E6: =COUNTIFS('נקודות - מקור'!$A$2:$A$564,$A6,'נקודות - מקור'!$F$2:$F$564,"<>0") | F6: =COUNTIFS('נקודות - מקור'!$A$2:$A$564,$A6,'נקודות - מקור'!$G$2:$G$564,"<>0") | G6: =COUNTIFS('נקודות - מקור'!$A$2:$A$564,$A6,'נקודות - מקור'!$H$2:$H$564,0) | H6: =COUNTIFS('נקודות - מקור'!$A$2:$A$564,$A6)
A7: רשת י-ם | B7: =COUNTIFS('נקודות - מקור'!$A$2:$A$564,$A7,'נקודות - מקור'!$C$2:$C$564,"<>0") | C7: =COUNTIFS('נקודות - מקור'!$A$2:$A$564,$A7,'נקודות - מקור'!$D$2:$D$564,"<>0") | D7: =COUNTIFS('נקודות - מקור'!$A$2:$A$564,$A7,'נקודות - מקור'!$E$2:$E$564,"<>0") | E7: =COUNTIFS('נקודות - מקור'!$A$2:$A$564,$A7,'נקודות - מקור'!$F$2:$F$564,"<>0") | F7: =COUNTIFS('נקודות - מקור'!$A$2:$A$564,$A7,'נקודות - מקור'!$G$2:$G$564,"<>0") | G7: =COUNTIFS('נקודות - מקור'!$A$2:$A$564,$A7,'נקודות - מקור'!$H$2:$H$564,0) | H7: =COUNTIFS('נקודות - מקור'!$A$2:$A$564,$A7)
A8: שור טבצניק | B8: =COUNTIFS('נקודות - מקור'!$A$2:$A$564,$A8,'נקודות - מקור'!$C$2:$C$564,"<>0") | C8: =COUNTIFS('נקודות - מקור'!$A$2:$A$564,$A8,'נקודות - מקור'!$D$2:$D$564,"<>0") | D8: =COUNTIFS('נקודות - מקור'!$A$2:$A$564,$A8,'נקודות - מקור'!$E$2:$E$564,"<>0") | E8: =COUNTIFS('נקודות - מקור'!$A$2:$A$564,$A8,'נקודות - מקור'!$F$2:$F$564,"<>0") | F8: =COUNTIFS('נקודות - מקור'!$A$2:$A$564,$A8,'נקודות - מקור'!$G$2:$G$564,"<>0") | G8: =COUNTIFS('נקודות - מקור'!$A$2:$A$564,$A8,'נקודות - מקור'!$H$2:$H$564,0) | H8: =COUNTIFS('נקודות - מקור'!$A$2:$A$564,$A8)
A9: שרם | B9: =COUNTIFS('נקודות - מקור'!$A$2:$A$564,$A9,'נקודות - מקור'!$C$2:$C$564,"<>0") | C9: =COUNTIFS('נקודות - מקור'!$A$2:$A$564,$A9,'נקודות - מקור'!$D$2:$D$564,"<>0") | D9: =COUNTIFS('נקודות - מקור'!$A$2:$A$564,$A9,'נקודות - מקור'!$E$2:$E$564,"<>0") | E9: =COUNTIFS('נקודות - מקור'!$A$2:$A$564,$A9,'נקודות - מקור'!$F$2:$F$564,"<>0") | F9: =COUNTIFS('נקודות - מקור'!$A$2:$A$564,$A9,'נקודות - מקור'!$G$2:$G$564,"<>0") | G9: =COUNTIFS('נקודות - מקור'!$A$2:$A$564,$A9,'נקודות - מקור'!$H$2:$H$564,0) | H9: =COUNTIFS('נקודות - מקור'!$A$2:$A$564,$A9)
A10: 0מפיצי משנה | B10: =COUNTIFS('נקודות - מקור'!$A$2:$A$564,$A10,'נקודות - מקור'!$C$2:$C$564,"<>0") | C10: =COUNTIFS('נקודות - מקור'!$A$2:$A$564,$A10,'נקודות - מקור'!$D$2:$D$564,"<>0") | D10: =COUNTIFS('נקודות - מקור'!$A$2:$A$564,$A10,'נקודות - מקור'!$E$2:$E$564,"<>0") | E10: =COUNTIFS('נקודות - מקור'!$A$2:$A$564,$A10,'נקודות - מקור'!$F$2:$F$564,"<>0") | F10: =COUNTIFS('נקודות - מקור'!$A$2:$A$564,$A10,'נקודות - מקור'!$G$2:$G$564,"<>0") | G10: =COUNTIFS('נקודות - מקור'!$A$2:$A$564,$A10,'נקודות - מקור'!$H$2:$H$564,0) | H10: =COUNTIFS('נקודות - מקור'!$A$2:$A$564,$A10)
A11: ס. פארם | B11: =COUNTIFS('נקודות - מקור'!$A$2:$A$564,$A11,'נקודות - מקור'!$C$2:$C$564,"<>0") | C11: =COUNTIFS('נקודות - מקור'!$A$2:$A$564,$A11,'נקודות - מקור'!$D$2:$D$564,"<>0") | D11: =COUNTIFS('נקודות - מקור'!$A$2:$A$564,$A11,'נקודות - מקור'!$E$2:$E$564,"<>0") | E11: =COUNTIFS('נקודות - מקור'!$A$2:$A$564,$A11,'נקודות - מקור'!$F$2:$F$564,"<>0") | F11: =COUNTIFS('נקודות - מקור'!$A$2:$A$564,$A11,'נקודות - מקור'!$G$2:$G$564,"<>0") | G11: =COUNTIFS('נקודות - מקור'!$A$2:$A$564,$A11,'נקודות - מקור'!$H$2:$H$564,0) | H11: =COUNTIFS('נקודות - מקור'!$A$2:$A$564,$A11)
A12: שופרסל BE | B12: =COUNTIFS('נקודות - מקור'!$A$2:$A$564,$A12,'נקודות - מקור'!$C$2:$C$564,"<>0") | C12: =COUNTIFS('נקודות - מקור'!$A$2:$A$564,$A12,'נקודות - מקור'!$D$2:$D$564,"<>0") | D12: =COUNTIFS('נקודות - מקור'!$A$2:$A$564,$A12,'נקודות - מקור'!$E$2:$E$564,"<>0") | E12: =COUNTIFS('נקודות - מקור'!$A$2:$A$564,$A12,'נקודות - מקור'!$F$2:$F$564,"<>0") | F12: =COUNTIFS('נקודות - מקור'!$A$2:$A$564,$A12,'נקודות - מקור'!$G$2:$G$564,"<>0") | G12: =COUNTIFS('נקודות - מקור'!$A$2:$A$564,$A12,'נקודות - מקור'!$H$2:$H$564,0) | H12: =COUNTIFS('נקודות - מקור'!$A$2:$A$564,$A12)
A13: 0קופות חולים | B13: =COUNTIFS('נקודות - מקור'!$A$2:$A$564,$A13,'נקודות - מקור'!$C$2:$C$564,"<>0") | C13: =COUNTIFS('נקודות - מקור'!$A$2:$A$564,$A13,'נקודות - מקור'!$D$2:$D$564,"<>0") | D13: =COUNTIFS('נקודות - מקור'!$A$2:$A$564,$A13,'נקודות - מקור'!$E$2:$E$564,"<>0") | E13: =COUNTIFS('נקודות - מקור'!$A$2:$A$564,$A13,'נקודות - מקור'!$F$2:$F$564,"<>0") | F13: =COUNTIFS('נקודות - מקור'!$A$2:$A$564,$A13,'נקודות - מקור'!$G$2:$G$564,"<>0") | G13: =COUNTIFS('נקודות - מקור'!$A$2:$A$564,$A13,'נקודות - מקור'!$H$2:$H$564,0) | H13: =COUNTIFS('נקודות - מקור'!$A$2:$A$564,$A13)
A14: סה"כ | B14: =SUM(B4:B13) | C14: =SUM(C4:C13) | D14: =SUM(D4:D13) | E14: =SUM(E4:E13) | F14: =SUM(F4:F13) | G14: =SUM(G4:G13) | H14: =SUM(H4:H13)
A16: בדיקת הצלבה — מספר שורות-לקוח במקור (COUNTA): | B16: =COUNTA('נקודות - מקור'!$A$2:$A$564)
A17: הפרש מול "סה"כ נקודות" הכללי (צריך להיות 0): | B17: =H14-B16
A20: נקודות עם יותר מסוכן אחד (לשקיפות — לא נזרקות, נספרות בכל הסוכנים הרלוונטיים):
A21: קבוצה | B21: שם לקוח (מקור) | C21: סוכנים עם סכום≠0
A22: שרם | B22: ב.מ שרה פארם צור יצחק שרמפארם | C22: חאזם תלחמי, סטאס נסאר

Sheet נקודות לפי סוכן 2025
A1: נקודות לכל סוכן בכל קבוצת לקוחות — מתוך דוח PPlay1 of uriel (Reporter), "2025_נקודות_של_סוכן_1" (2025, שנה מלאה)
A3: קבוצת לקוחות | B3: חיים וייצמ | C3: חאזם תלחמי | D3: סטאס נסאר | E3: עיסא | F3: .דוד א | G3: לא מטופל | H3: סה"כ נקודות (קבוצה)
A4: 0בתי מרקחת | B4: =COUNTIFS('נקודות - מקור 2025'!$A$2:$A$583,$A4,'נקודות - מקור 2025'!$C$2:$C$583,"<>0") | C4: =COUNTIFS('נקודות - מקור 2025'!$A$2:$A$583,$A4,'נקודות - מקור 2025'!$D$2:$D$583,"<>0") | D4: =COUNTIFS('נקודות - מקור 2025'!$A$2:$A$583,$A4,'נקודות - מקור 2025'!$E$2:$E$583,"<>0") | E4: =COUNTIFS('נקודות - מקור 2025'!$A$2:$A$583,$A4,'נקודות - מקור 2025'!$F$2:$F$583,"<>0") | F4: =COUNTIFS('נקודות - מקור 2025'!$A$2:$A$583,$A4,'נקודות - מקור 2025'!$G$2:$G$583,"<>0") | G4: =COUNTIFS('נקודות - מקור 2025'!$A$2:$A$583,$A4,'נקודות - מקור 2025'!$H$2:$H$583,0) | H4: =COUNTIFS('נקודות - מקור 2025'!$A$2:$A$583,$A4)
A5: מגזר ערבי | B5: =COUNTIFS('נקודות - מקור 2025'!$A$2:$A$583,$A5,'נקודות - מקור 2025'!$C$2:$C$583,"<>0") | C5: =COUNTIFS('נקודות - מקור 2025'!$A$2:$A$583,$A5,'נקודות - מקור 2025'!$D$2:$D$583,"<>0") | D5: =COUNTIFS('נקודות - מקור 2025'!$A$2:$A$583,$A5,'נקודות - מקור 2025'!$E$2:$E$583,"<>0") | E5: =COUNTIFS('נקודות - מקור 2025'!$A$2:$A$583,$A5,'נקודות - מקור 2025'!$F$2:$F$583,"<>0") | F5: =COUNTIFS('נקודות - מקור 2025'!$A$2:$A$583,$A5,'נקודות - מקור 2025'!$G$2:$G$583,"<>0") | G5: =COUNTIFS('נקודות - מקור 2025'!$A$2:$A$583,$A5,'נקודות - מקור 2025'!$H$2:$H$583,0) | H5: =COUNTIFS('נקודות - מקור 2025'!$A$2:$A$583,$A5)
A6: רוקחים עתיד | B6: =COUNTIFS('נקודות - מקור 2025'!$A$2:$A$583,$A6,'נקודות - מקור 2025'!$C$2:$C$583,"<>0") | C6: =COUNTIFS('נקודות - מקור 2025'!$A$2:$A$583,$A6,'נקודות - מקור 2025'!$D$2:$D$583,"<>0") | D6: =COUNTIFS('נקודות - מקור 2025'!$A$2:$A$583,$A6,'נקודות - מקור 2025'!$E$2:$E$583,"<>0") | E6: =COUNTIFS('נקודות - מקור 2025'!$A$2:$A$583,$A6,'נקודות - מקור 2025'!$F$2:$F$583,"<>0") | F6: =COUNTIFS('נקודות - מקור 2025'!$A$2:$A$583,$A6,'נקודות - מקור 2025'!$G$2:$G$583,"<>0") | G6: =COUNTIFS('נקודות - מקור 2025'!$A$2:$A$583,$A6,'נקודות - מקור 2025'!$H$2:$H$583,0) | H6: =COUNTIFS('נקודות - מקור 2025'!$A$2:$A$583,$A6)
A7: רשת י-ם | B7: =COUNTIFS('נקודות - מקור 2025'!$A$2:$A$583,$A7,'נקודות - מקור 2025'!$C$2:$C$583,"<>0") | C7: =COUNTIFS('נקודות - מקור 2025'!$A$2:$A$583,$A7,'נקודות - מקור 2025'!$D$2:$D$583,"<>0") | D7: =COUNTIFS('נקודות - מקור 2025'!$A$2:$A$583,$A7,'נקודות - מקור 2025'!$E$2:$E$583,"<>0") | E7: =COUNTIFS('נקודות - מקור 2025'!$A$2:$A$583,$A7,'נקודות - מקור 2025'!$F$2:$F$583,"<>0") | F7: =COUNTIFS('נקודות - מקור 2025'!$A$2:$A$583,$A7,'נקודות - מקור 2025'!$G$2:$G$583,"<>0") | G7: =COUNTIFS('נקודות - מקור 2025'!$A$2:$A$583,$A7,'נקודות - מקור 2025'!$H$2:$H$583,0) | H7: =COUNTIFS('נקודות - מקור 2025'!$A$2:$A$583,$A7)
A8: שור טבצניק | B8: =COUNTIFS('נקודות - מקור 2025'!$A$2:$A$583,$A8,'נקודות - מקור 2025'!$C$2:$C$583,"<>0") | C8: =COUNTIFS('נקודות - מקור 2025'!$A$2:$A$583,$A8,'נקודות - מקור 2025'!$D$2:$D$583,"<>0") | D8: =COUNTIFS('נקודות - מקור 2025'!$A$2:$A$583,$A8,'נקודות - מקור 2025'!$E$2:$E$583,"<>0") | E8: =COUNTIFS('נקודות - מקור 2025'!$A$2:$A$583,$A8,'נקודות - מקור 2025'!$F$2:$F$583,"<>0") | F8: =COUNTIFS('נקודות - מקור 2025'!$A$2:$A$583,$A8,'נקודות - מקור 2025'!$G$2:$G$583,"<>0") | G8: =COUNTIFS('נקודות - מקור 2025'!$A$2:$A$583,$A8,'נקודות - מקור 2025'!$H$2:$H$583,0) | H8: =COUNTIFS('נקודות - מקור 2025'!$A$2:$A$583,$A8)
A9: שרם | B9: =COUNTIFS('נקודות - מקור 2025'!$A$2:$A$583,$A9,'נקודות - מקור 2025'!$C$2:$C$583,"<>0") | C9: =COUNTIFS('נקודות - מקור 2025'!$A$2:$A$583,$A9,'נקודות - מקור 2025'!$D$2:$D$583,"<>0") | D9: =COUNTIFS('נקודות - מקור 2025'!$A$2:$A$583,$A9,'נקודות - מקור 2025'!$E$2:$E$583,"<>0") | E9: =COUNTIFS('נקודות - מקור 2025'!$A$2:$A$583,$A9,'נקודות - מקור 2025'!$F$2:$F$583,"<>0") | F9: =COUNTIFS('נקודות - מקור 2025'!$A$2:$A$583,$A9,'נקודות - מקור 2025'!$G$2:$G$583,"<>0") | G9: =COUNTIFS('נקודות - מקור 2025'!$A$2:$A$583,$A9,'נקודות - מקור 2025'!$H$2:$H$583,0) | H9: =COUNTIFS('נקודות - מקור 2025'!$A$2:$A$583,$A9)
A10: 0מפיצי משנה | B10: =COUNTIFS('נקודות - מקור 2025'!$A$2:$A$583,$A10,'נקודות - מקור 2025'!$C$2:$C$583,"<>0") | C10: =COUNTIFS('נקודות - מקור 2025'!$A$2:$A$583,$A10,'נקודות - מקור 2025'!$D$2:$D$583,"<>0") | D10: =COUNTIFS('נקודות - מקור 2025'!$A$2:$A$583,$A10,'נקודות - מקור 2025'!$E$2:$E$583,"<>0") | E10: =COUNTIFS('נקודות - מקור 2025'!$A$2:$A$583,$A10,'נקודות - מקור 2025'!$F$2:$F$583,"<>0") | F10: =COUNTIFS('נקודות - מקור 2025'!$A$2:$A$583,$A10,'נקודות - מקור 2025'!$G$2:$G$583,"<>0") | G10: =COUNTIFS('נקודות - מקור 2025'!$A$2:$A$583,$A10,'נקודות - מקור 2025'!$H$2:$H$583,0) | H10: =COUNTIFS('נקודות - מקור 2025'!$A$2:$A$583,$A10)
A11: ס. פארם | B11: =COUNTIFS('נקודות - מקור 2025'!$A$2:$A$583,$A11,'נקודות - מקור 2025'!$C$2:$C$583,"<>0") | C11: =COUNTIFS('נקודות - מקור 2025'!$A$2:$A$583,$A11,'נקודות - מקור 2025'!$D$2:$D$583,"<>0") | D11: =COUNTIFS('נקודות - מקור 2025'!$A$2:$A$583,$A11,'נקודות - מקור 2025'!$E$2:$E$583,"<>0") | E11: =COUNTIFS('נקודות - מקור 2025'!$A$2:$A$583,$A11,'נקודות - מקור 2025'!$F$2:$F$583,"<>0") | F11: =COUNTIFS('נקודות - מקור 2025'!$A$2:$A$583,$A11,'נקודות - מקור 2025'!$G$2:$G$583,"<>0") | G11: =COUNTIFS('נקודות - מקור 2025'!$A$2:$A$583,$A11,'נקודות - מקור 2025'!$H$2:$H$583,0) | H11: =COUNTIFS('נקודות - מקור 2025'!$A$2:$A$583,$A11)
A12: שופרסל BE | B12: =COUNTIFS('נקודות - מקור 2025'!$A$2:$A$583,$A12,'נקודות - מקור 2025'!$C$2:$C$583,"<>0") | C12: =COUNTIFS('נקודות - מקור 2025'!$A$2:$A$583,$A12,'נקודות - מקור 2025'!$D$2:$D$583,"<>0") | D12: =COUNTIFS('נקודות - מקור 2025'!$A$2:$A$583,$A12,'נקודות - מקור 2025'!$E$2:$E$583,"<>0") | E12: =COUNTIFS('נקודות - מקור 2025'!$A$2:$A$583,$A12,'נקודות - מקור 2025'!$F$2:$F$583,"<>0") | F12: =COUNTIFS('נקודות - מקור 2025'!$A$2:$A$583,$A12,'נקודות - מקור 2025'!$G$2:$G$583,"<>0") | G12: =COUNTIFS('נקודות - מקור 2025'!$A$2:$A$583,$A12,'נקודות - מקור 2025'!$H$2:$H$583,0) | H12: =COUNTIFS('נקודות - מקור 2025'!$A$2:$A$583,$A12)
A13: סה"כ | B13: =SUM(B4:B12) | C13: =SUM(C4:C12) | D13: =SUM(D4:D12) | E13: =SUM(E4:E12) | F13: =SUM(F4:F12) | G13: =SUM(G4:G12) | H13: =SUM(H4:H12)
A15: בדיקת הצלבה — מספר שורות-לקוח במקור (COUNTA): | B15: =COUNTA('נקודות - מקור 2025'!$A$2:$A$583)
A16: הפרש מול "סה"כ נקודות" הכללי (צריך להיות 0): | B16: =H13-B15
A19: נקודות עם יותר מסוכן אחד (לשקיפות — לא נזרקות, נספרות בכל הסוכנים הרלוונטיים):
A20: קבוצה | B20: שם לקוח (מקור) | C20: סוכנים עם סכום≠0
A21: 0בתי מרקחת | B21: בתי מרקחת פרטי | C21: חיים וייצמ, חאזם תלחמי, סטאס נסאר, .דוד א

Sheet RawData
A1: ערוץ (קוד+שם) | B1: לקוח | C1: מספר מסמך | D1: סוג מסמך | E1: מכירות 2025 | F1: כמות 2025 | G1: מכירות 2026 | H1: כמות 2026
A2: 102 - Orthopedic institutes | B2: 150002 אילן המרכז לאורטופדיה | C2: INV60424 | D2: INV | E2: 1498.64 | F2: 29 | G2: 0 | H2: 0
A3: 102 - Orthopedic institutes | B3: 150002 אילן המרכז לאורטופדיה | C3: INV68487 | D3: INV | E3: 0 | F3: 0 | G3: 1222.81 | H3: 9
A4: 102 - Orthopedic institutes | B4: 150002 אילן המרכז לאורטופדיה | C4: INV68397 | D4: INV | E4: 0 | F4: 0 | G4: 855.88 | H4: 16
A5: 102 - Orthopedic institutes | B5: 150002 אילן המרכז לאורטופדיה | C5: INV67820 | D5: INV | E5: 0 | F5: 0 | G5: 819.94 | H5: 7
A6: 102 - Orthopedic institutes | B6: 150002 אילן המרכז לאורטופדיה | C6: INV52159 | D6: INV | E6: 790.57 | F6: 9 | G6: 0 | H6: 0
A7: 102 - Orthopedic institutes | B7: 150002 אילן המרכז לאורטופדיה | C7: INV68852 | D7: INV | E7: 0 | F7: 0 | G7: 718.99 | H7: 12
A8: 102 - Orthopedic institutes | B8: 150002 אילן המרכז לאורטופדיה | C8: INV68593 | D8: INV | E8: 0 | F8: 0 | G8: 709.15 | H8: 17
A9: 102 - Orthopedic institutes | B9: 150002 אילן המרכז לאורטופדיה | C9: INV65991 | D9: INV | E9: 657.45 | F9: 20 | G9: 0 | H9: 0
A10: 102 - Orthopedic institutes | B10: 150002 אילן המרכז לאורטופדיה | C10: INV66251 | D10: INV | E10: 638.53 | F10: 6 | G10: 0 | H10: 0
A11: 102 - Orthopedic institutes | B11: 150002 אילן המרכז לאורטופדיה | C11: INV68791 | D11: INV | E11: 0 | F11: 0 | G11: 630 | H11: 7
A12: 102 - Orthopedic institutes | B12: 150002 אילן המרכז לאורטופדיה | C12: INV66952 | D12: INV | E12: 629.99 | F12: 7 | G12: 0 | H12: 0
A13: 102 - Orthopedic institutes | B13: 150002 אילן המרכז לאורטופדיה | C13: INV69189 | D13: INV | E13: 0 | F13: 0 | G13: 562.36 | H13: 13
... A2208: 108 - Shoe Stores | B2208: C02283 אדור למסחר כללי ואופנה בע"מ | C2208: INV45213 | D2208: INV | E2208: 0.01 | F2208: 1 | G2208: 0 | H2208: 0

Sheet הערות שיטה
A1: הערות שיטה — איך נבנה הניתוח, ואיזו הגדרה נבחרה ל"חשבונית"
A3: 1. מבנה המקור: הדוח הגולמי (56,263 שורות, גיליון יחיד) בנוי בהיררכיה של 3 רמות: (א) שורת Sale Type (ערוץ, עמודה A, למשל "102 - Orthopedic institutes") שמסתיימת בשורת "Total - <ערוץ>"; (ב) בתוכה שורת לקוח (עמודה A, בלי Document Number) שמסתיימת ב"Total - <לקוח>"; (ג) בתוכה שורות מסמך/חשבונית (עמודה C = Document Number).
A4: 2. מקרה קצה שזוהה ותוקן: כשללקוח יש מסמך יחיד בלבד בכל הטווח, NetSuite לא פותח שורת-לקוח נפרדת ושורת-Total נפרדת — השם וה-Document Number מופיעים על אותה שורה (למשל "150064 מיקס שופ" ו-"INV66238" יחד). הניתוח מזהה זאת נכון: לקוח נספר כל עוד יש ערך בעמודה A (גם אם יש גם מספר מסמך באותה שורה).
A5: 3. אימות שלמות: לכל אחד מ-7 הערוצים הושווה סכום כל שורות המסמך (2025 Sales / 2026 Sales) לעומת הערך העצמי של שורת הכותרת של אותו ערוץ (שמכילה את הסכום הכולל) — בכל 7 הערוצים ההתאמה הייתה מדויקת לסנט (ראו קוד האימות). זה מוכיח שלא נשמטו שורות ושלא נכנסו שורות כפולות.
A6: 4. לא נמצא אף לקוח (מתוך 172 הלקוחות הייחודיים ב-7 הערוצים) בלי אף שורת מסמך — לכן "מספר לקוחות" ו"יש להם לפחות מסמך אחד" חופפים במקרה הזה.
A8: 5. סוגי מסמך שנמצאו (עמודת Document Number) בתוך 7 הערוצים הרלוונטיים: INV (Invoice), CM (Credit Memo), CS (Cash Sale). לא נמצאו Journal Entry ("JE...") או סוגים אחרים בתוך הערוצים האלה — JE הופיע רק בשורות "- Unassigned -" / "- No Customer/Project -" בתחילת הדוח, מחוץ ל-7 הערוצים.
A9: 6. ההחלטה הסופית (אושרה במפורש ע"י המשתמש): "חשבונית" = מסמכים שמספרם מתחיל ב-"INV" בלבד. CM (Credit Memo) ו-CS (Cash Sale) לא נספרים כחשבונית, גם אם היו מועמדים סבירים.
A10: נימוק רקע (לשקיפות): נבדקו כל 142 שורות ה-CM בתוך 7 הערוצים (וכל 25,119 שורות ה-CM/ה-CS בקובץ כולו) — 100% מערכי ה-CM שליליים (זיכוי/החזר על חשבונית קודמת), ו-100% מערכי ה-CS חיוביים (מכירה במזומן). ההחלטה הסופית של המשתמש הייתה לספור רק prefix "INV" במדויק — ראו טבלת הפירוט למטה לכל שאר ה-prefixes שנמצאו (לשם שקיפות בלבד, לא נספרים).
A11: 7. "חשבונית נספרה" לשנה מסוימת = יש ערך שונה מאפס ולא ריק בעמודת ה-Sales של אותה שנה (2025 Sales / 2026 Sales) באותה שורת מסמך, בדיוק כנדרש.
A13: 8. טבלת שקיפות — פירוט לפי סוג מסמך ושנה, לכל ערוץ (לצורך ביקורת/שינוי הגדרה אם תרצה):
A15: ערוץ | B15: INV 2025 | C15: CM 2025 | D15: CS 2025 | E15: INV 2026 | F15: CM 2026 | G15: CS 2026
A16: 102 - Orthopedic institutes | B16: =COUNTIFS(RawData!$A$2:$A$2208,$A16,RawData!$D$2:$D$2208,"INV",RawData!$E$2:$E$2208,"<>0") | C16: =COUNTIFS(RawData!$A$2:$A$2208,$A16,RawData!$D$2:$D$2208,"CM",RawData!$E$2:$E$2208,"<>0") | D16: =COUNTIFS(RawData!$A$2:$A$2208,$A16,RawData!$D$2:$D$2208,"CS",RawData!$E$2:$E$2208,"<>0") | E16: =COUNTIFS(RawData!$A$2:$A$2208,$A16,RawData!$D$2:$D$2208,"INV",RawData!$G$2:$G$2208,"<>0") | F16: =COUNTIFS(RawData!$A$2:$A$2208,$A16,RawData!$D$2:$D$2208,"CM",RawData!$G$2:$G$2208,"<>0") | G16: =COUNTIFS(RawData!$A$2:$A$2208,$A16,RawData!$D$2:$D$2208,"CS",RawData!$G$2:$G$2208,"<>0")
A17: 103 - Physiotherapy institutes | B17: =COUNTIFS(RawData!$A$2:$A$2208,$A17,RawData!$D$2:$D$2208,"INV",RawData!$E$2:$E$2208,"<>0") | C17: =COUNTIFS(RawData!$A$2:$A$2208,$A17,RawData!$D$2:$D$2208,"CM",RawData!$E$2:$E$2208,"<>0") | D17: =COUNTIFS(RawData!$A$2:$A$2208,$A17,RawData!$D$2:$D$2208,"CS",RawData!$E$2:$E$2208,"<>0") | E17: =COUNTIFS(RawData!$A$2:$A$2208,$A17,RawData!$D$2:$D$2208,"INV",RawData!$G$2:$G$2208,"<>0") | F17: =COUNTIFS(RawData!$A$2:$A$2208,$A17,RawData!$D$2:$D$2208,"CM",RawData!$G$2:$G$2208,"<>0") | G17: =COUNTIFS(RawData!$A$2:$A$2208,$A17,RawData!$D$2:$D$2208,"CS",RawData!$G$2:$G$2208,"<>0")
A18: 104 - Sports Shop | B18: =COUNTIFS(RawData!$A$2:$A$2208,$A18,RawData!$D$2:$D$2208,"INV",RawData!$E$2:$E$2208,"<>0") | C18: =COUNTIFS(RawData!$A$2:$A$2208,$A18,RawData!$D$2:$D$2208,"CM",RawData!$E$2:$E$2208,"<>0") | D18: =COUNTIFS(RawData!$A$2:$A$2208,$A18,RawData!$D$2:$D$2208,"CS",RawData!$E$2:$E$2208,"<>0") | E18: =COUNTIFS(RawData!$A$2:$A$2208,$A18,RawData!$D$2:$D$2208,"INV",RawData!$G$2:$G$2208,"<>0") | F18: =COUNTIFS(RawData!$A$2:$A$2208,$A18,RawData!$D$2:$D$2208,"CM",RawData!$G$2:$G$2208,"<>0") | G18: =COUNTIFS(RawData!$A$2:$A$2208,$A18,RawData!$D$2:$D$2208,"CS",RawData!$G$2:$G$2208,"<>0")
A19: 105 - Pedicure Salons | B19: =COUNTIFS(RawData!$A$2:$A$2208,$A19,RawData!$D$2:$D$2208,"INV",RawData!$E$2:$E$2208,"<>0") | C19: =COUNTIFS(RawData!$A$2:$A$2208,$A19,RawData!$D$2:$D$2208,"CM",RawData!$E$2:$E$2208,"<>0") | D19: =COUNTIFS(RawData!$A$2:$A$2208,$A19,RawData!$D$2:$D$2208,"CS",RawData!$E$2:$E$2208,"<>0") | E19: =COUNTIFS(RawData!$A$2:$A$2208,$A19,RawData!$D$2:$D$2208,"INV",RawData!$G$2:$G$2208,"<>0") | F19: =COUNTIFS(RawData!$A$2:$A$2208,$A19,RawData!$D$2:$D$2208,"CM",RawData!$G$2:$G$2208,"<>0") | G19: =COUNTIFS(RawData!$A$2:$A$2208,$A19,RawData!$D$2:$D$2208,"CS",RawData!$G$2:$G$2208,"<>0")
A20: 107 - Pharmacies | B20: =COUNTIFS(RawData!$A$2:$A$2208,$A20,RawData!$D$2:$D$2208,"INV",RawData!$E$2:$E$2208,"<>0") | C20: =COUNTIFS(RawData!$A$2:$A$2208,$A20,RawData!$D$2:$D$2208,"CM",RawData!$E$2:$E$2208,"<>0") | D20: =COUNTIFS(RawData!$A$2:$A$2208,$A20,RawData!$D$2:$D$2208,"CS",RawData!$E$2:$E$2208,"<>0") | E20: =COUNTIFS(RawData!$A$2:$A$2208,$A20,RawData!$D$2:$D$2208,"INV",RawData!$G$2:$G$2208,"<>0") | F20: =COUNTIFS(RawData!$A$2:$A$2208,$A20,RawData!$D$2:$D$2208,"CM",RawData!$G$2:$G$2208,"<>0") | G20: =COUNTIFS(RawData!$A$2:$A$2208,$A20,RawData!$D$2:$D$2208,"CS",RawData!$G$2:$G$2208,"<>0")
A21: 108 - Shoe Stores | B21: =COUNTIFS(RawData!$A$2:$A$2208,$A21,RawData!$D$2:$D$2208,"INV",RawData!$E$2:$E$2208,"<>0") | C21: =COUNTIFS(RawData!$A$2:$A$2208,$A21,RawData!$D$2:$D$2208,"CM",RawData!$E$2:$E$2208,"<>0") | D21: =COUNTIFS(RawData!$A$2:$A$2208,$A21,RawData!$D$2:$D$2208,"CS",RawData!$E$2:$E$2208,"<>0") | E21: =COUNTIFS(RawData!$A$2:$A$2208,$A21,RawData!$D$2:$D$2208,"INV",RawData!$G$2:$G$2208,"<>0") | F21: =COUNTIFS(RawData!$A$2:$A$2208,$A21,RawData!$D$2:$D$2208,"CM",RawData!$G$2:$G$2208,"<>0") | G21: =COUNTIFS(RawData!$A$2:$A$2208,$A21,RawData!$D$2:$D$2208,"CS",RawData!$G$2:$G$2208,"<>0")
A22: 109 - Private Shops | B22: =COUNTIFS(RawData!$A$2:$A$2208,$A22,RawData!$D$2:$D$2208,"INV",RawData!$E$2:$E$2208,"<>0") | C22: =COUNTIFS(RawData!$A$2:$A$2208,$A22,RawData!$D$2:$D$2208,"CM",RawData!$E$2:$E$2208,"<>0") | D22: =COUNTIFS(RawData!$A$2:$A$2208,$A22,RawData!$D$2:$D$2208,"CS",RawData!$E$2:$E$2208,"<>0") | E22: =COUNTIFS(RawData!$A$2:$A$2208,$A22,RawData!$D$2:$D$2208,"INV",RawData!$G$2:$G$2208,"<>0") | F22: =COUNTIFS(RawData!$A$2:$A$2208,$A22,RawData!$D$2:$D$2208,"CM",RawData!$G$2:$G$2208,"<>0") | G22: =COUNTIFS(RawData!$A$2:$A$2208,$A22,RawData!$D$2:$D$2208,"CS",RawData!$G$2:$G$2208,"<>0")
A23: סה"כ | B23: =SUM(B16:B22) | C23: =SUM(C16:C22) | D23: =SUM(D16:D22) | E23: =SUM(E16:E22) | F23: =SUM(F16:F22) | G23: =SUM(G16:G22)
A25: הטבלה למעלה מציגה את כל 3 סוגי המסמך (INV/CM/CS) לשם שקיפות מלאה. ההגדרה הסופית שנבחרה לטבלת הסיכום (גיליון "סיכום") היא עמודות ה-INV בלבד — CM ו-CS אינם נספרים.

Sheet קבוצות לקוחות - מקור
A1: קבוצה | B1: שם לקוח/שורה (מהמקור) | C1: סכום 2025 | D1: סכום 2026
A2: 0בתי מרקחת | B2: בימק מחוז צפון | C2: 87507.8 | D2: 48827.1
A3: 0בתי מרקחת | B3: המרכז אעבלין ב.מ | C3: 10975.3 | D3: 2875.2
A4: 0בתי מרקחת | B4: (מדיקל הצפון מעיליה )חורי בע""מ | C4: 5349.7 | D4: 3742.5
A5: 0בתי מרקחת | B5: נובו פארם דיר אל אסד ב.מ | C5: 21464.5 | D5: 15273.8
A6: 0בתי מרקחת | B6: עמית נהריה ב.מ | C6: 271.9 | D6: 0
A7: 0בתי מרקחת | B7: שביט בע""מ ק.אתא ב.מ | C7: 612.5 | D7: 429.8
A8: 0בתי מרקחת | B8: חידאר פארם ב.מ | C8: 3557.4 | D8: 2601
A9: 0בתי מרקחת | B9: -סמי בית שאן בע""מ ב.מ | C9: 647.8 | D9: 560.9
A10: 0בתי מרקחת | B10: רסקו טבריה ב.מ | C10: 5421 | D10: 3837.2
A11: 0בתי מרקחת | B11: פרמה טבריה ב.מ | C11: 211.6 | D11: 278
A12: 0בתי מרקחת | B12: צפת דרום ב.מ | C12: 0 | D12: 20.1
A13: 0בתי מרקחת | B13: בימר""ק אלעין פארם כפר שעב | C13: 0 | D13: 0
... A945: 0צרכנים פרטיים | B945: עובדי כמיפל | C945: 1619.8 | D945: 454.6

Sheet נקודות - מקור
A1: קבוצה | B1: שם לקוח/שורה (מהמקור) | C1: חיים וייצמ | D1: חאזם תלחמי | E1: סטאס נסאר | F1: עיסא | G1: .דוד א | H1: מספר סוכנים (סכום≠0) | I1: סטטוס
A2: 0בתי מרקחת | B2: המרכז אעבלין ב.מ | C2: 0 | D2: 2875.2 | E2: 0 | F2: 0 | G2: 0 | H2: =COUNTIF(C2:G2,"<>0") | I2: =IF(H2=0,"לא מטופל",IF(H2=1,"מטופל - סוכן אחד","מטופל - יותר מסוכן אחד"))
A3: 0בתי מרקחת | B3: (מדיקל הצפון מעיליה )חורי בע""מ | C3: 0 | D3: 3742.5 | E3: 0 | F3: 0 | G3: 0 | H3: =COUNTIF(C3:G3,"<>0") | I3: =IF(H3=0,"לא מטופל",IF(H3=1,"מטופל - סוכן אחד","מטופל - יותר מסוכן אחד"))
A4: 0בתי מרקחת | B4: נובו פארם דיר אל אסד ב.מ | C4: 0 | D4: 14900.4 | E4: 0 | F4: 0 | G4: 0 | H4: =COUNTIF(C4:G4,"<>0") | I4: =IF(H4=0,"לא מטופל",IF(H4=1,"מטופל - סוכן אחד","מטופל - יותר מסוכן אחד"))
A5: 0בתי מרקחת | B5: שביט בע""מ ק.אתא ב.מ | C5: 0 | D5: 429.8 | E5: 0 | F5: 0 | G5: 0 | H5: =COUNTIF(C5:G5,"<>0") | I5: =IF(H5=0,"לא מטופל",IF(H5=1,"מטופל - סוכן אחד","מטופל - יותר מסוכן אחד"))
A6: 0בתי מרקחת | B6: חידאר פארם ב.מ | C6: 0 | D6: 2601 | E6: 0 | F6: 0 | G6: 0 | H6: =COUNTIF(C6:G6,"<>0") | I6: =IF(H6=0,"לא מטופל",IF(H6=1,"מטופל - סוכן אחד","מטופל - יותר מסוכן אחד"))
A7: 0בתי מרקחת | B7: -סמי בית שאן בע""מ ב.מ | C7: 0 | D7: 560.9 | E7: 0 | F7: 0 | G7: 0 | H7: =COUNTIF(C7:G7,"<>0") | I7: =IF(H7=0,"לא מטופל",IF(H7=1,"מטופל - סוכן אחד","מטופל - יותר מסוכן אחד"))
A8: 0בתי מרקחת | B8: רסקו טבריה ב.מ | C8: 0 | D8: 3837.2 | E8: 0 | F8: 0 | G8: 0 | H8: =COUNTIF(C8:G8,"<>0") | I8: =IF(H8=0,"לא מטופל",IF(H8=1,"מטופל - סוכן אחד","מטופל - יותר מסוכן אחד"))
A9: 0בתי מרקחת | B9: פרמה טבריה ב.מ | C9: 0 | D9: 278 | E9: 0 | F9: 0 | G9: 0 | H9: =COUNTIF(C9:G9,"<>0") | I9: =IF(H9=0,"לא מטופל",IF(H9=1,"מטופל - סוכן אחד","מטופל - יותר מסוכן אחד"))
A10: 0בתי מרקחת | B10: צפת דרום ב.מ | C10: 0 | D10: 20.1 | E10: 0 | F10: 0 | G10: 0 | H10: =COUNTIF(C10:G10,"<>0") | I10: =IF(H10=0,"לא מטופל",IF(H10=1,"מטופל - סוכן אחד","מטופל - יותר מסוכן אחד"))
A11: 0בתי מרקחת | B11: .נובו פארם בית שאן ב.מ | C11: 0 | D11: 6926 | E11: 0 | F11: 0 | G11: 0 | H11: =COUNTIF(C11:G11,"<>0") | I11: =IF(H11=0,"לא מטופל",IF(H11=1,"מטופל - סוכן אחד","מטופל - יותר מסוכן אחד"))
A12: 0בתי מרקחת | B12: גרין ב.מ -גבעת עדה | C12: 0 | D12: 2061.6 | E12: 0 | F12: 0 | G12: 0 | H12: =COUNTIF(C12:G12,"<>0") | I12: =IF(H12=0,"לא מטופל",IF(H12=1,"מטופל - סוכן אחד","מטופל - יותר מסוכן אחד"))
A13: 0בתי מרקחת | B13: מוראד פארם ב.מ אבו סנאן | C13: 0 | D13: 2578 | E13: 0 | F13: 0 | G13: 0 | H13: =COUNTIF(C13:G13,"<>0") | I13: =IF(H13=0,"לא מטופל",IF(H13=1,"מטופל - סוכן אחד","מטופל - יותר מסוכן אחד"))
... A564: 0קופות חולים | B564: ק.חולים מכבי | C564: 0 | D564: 0 | E564: 0 | F564: 586.8 | G564: 0 | H564: =COUNTIF(C564:G564,"<>0") | I564: =IF(H564=0,"לא מטופל",IF(H564=1,"מטופל - סוכן אחד","מטופל - יותר מסוכן אחד"))

Sheet נקודות - מקור 2025
A1: קבוצה | B1: שם לקוח/שורה (מהמקור) | C1: חיים וייצמ | D1: חאזם תלחמי | E1: סטאס נסאר | F1: עיסא | G1: .דוד א | H1: מספר סוכנים (סכום≠0) | I1: סטטוס
A2: 0בתי מרקחת | B2: המרכז אעבלין ב.מ | C2: 0 | D2: 10975.3 | E2: 0 | F2: 0 | G2: 0 | H2: =COUNTIF(C2:G2,"<>0") | I2: =IF(H2=0,"לא מטופל",IF(H2=1,"מטופל - סוכן אחד","מטופל - יותר מסוכן אחד"))
A3: 0בתי מרקחת | B3: (מדיקל הצפון מעיליה )חורי בע""מ | C3: 0 | D3: 5349.7 | E3: 0 | F3: 0 | G3: 0 | H3: =COUNTIF(C3:G3,"<>0") | I3: =IF(H3=0,"לא מטופל",IF(H3=1,"מטופל - סוכן אחד","מטופל - יותר מסוכן אחד"))
A4: 0בתי מרקחת | B4: נובו פארם דיר אל אסד ב.מ | C4: 0 | D4: 21464.5 | E4: 0 | F4: 0 | G4: 0 | H4: =COUNTIF(C4:G4,"<>0") | I4: =IF(H4=0,"לא מטופל",IF(H4=1,"מטופל - סוכן אחד","מטופל - יותר מסוכן אחד"))
A5: 0בתי מרקחת | B5: עמית נהריה ב.מ | C5: 0 | D5: 0 | E5: 271.9 | F5: 0 | G5: 0 | H5: =COUNTIF(C5:G5,"<>0") | I5: =IF(H5=0,"לא מטופל",IF(H5=1,"מטופל - סוכן אחד","מטופל - יותר מסוכן אחד"))
A6: 0בתי מרקחת | B6: שביט בע""מ ק.אתא ב.מ | C6: 0 | D6: 612.5 | E6: 0 | F6: 0 | G6: 0 | H6: =COUNTIF(C6:G6,"<>0") | I6: =IF(H6=0,"לא מטופל",IF(H6=1,"מטופל - סוכן אחד","מטופל - יותר מסוכן אחד"))
A7: 0בתי מרקחת | B7: חידאר פארם ב.מ | C7: 0 | D7: 3557.4 | E7: 0 | F7: 0 | G7: 0 | H7: =COUNTIF(C7:G7,"<>0") | I7: =IF(H7=0,"לא מטופל",IF(H7=1,"מטופל - סוכן אחד","מטופל - יותר מסוכן אחד"))
A8: 0בתי מרקחת | B8: -סמי בית שאן בע""מ ב.מ | C8: 0 | D8: 647.8 | E8: 0 | F8: 0 | G8: 0 | H8: =COUNTIF(C8:G8,"<>0") | I8: =IF(H8=0,"לא מטופל",IF(H8=1,"מטופל - סוכן אחד","מטופל - יותר מסוכן אחד"))
A9: 0בתי מרקחת | B9: רסקו טבריה ב.מ | C9: 0 | D9: 5421 | E9: 0 | F9: 0 | G9: 0 | H9: =COUNTIF(C9:G9,"<>0") | I9: =IF(H9=0,"לא מטופל",IF(H9=1,"מטופל - סוכן אחד","מטופל - יותר מסוכן אחד"))
A10: 0בתי מרקחת | B10: פרמה טבריה ב.מ | C10: 0 | D10: 211.6 | E10: 0 | F10: 0 | G10: 0 | H10: =COUNTIF(C10:G10,"<>0") | I10: =IF(H10=0,"לא מטופל",IF(H10=1,"מטופל - סוכן אחד","מטופל - יותר מסוכן אחד"))
A11: 0בתי מרקחת | B11: .נובו פארם בית שאן ב.מ | C11: 0 | D11: 15653.4 | E11: 0 | F11: 0 | G11: 0 | H11: =COUNTIF(C11:G11,"<>0") | I11: =IF(H11=0,"לא מטופל",IF(H11=1,"מטופל - סוכן אחד","מטופל - יותר מסוכן אחד"))
A12: 0בתי מרקחת | B12: גרין ב.מ -גבעת עדה | C12: 0 | D12: 3161.8 | E12: 0 | F12: 0 | G12: 0 | H12: =COUNTIF(C12:G12,"<>0") | I12: =IF(H12=0,"לא מטופל",IF(H12=1,"מטופל - סוכן אחד","מטופל - יותר מסוכן אחד"))
A13: 0בתי מרקחת | B13: מוראד פארם ב.מ אבו סנאן | C13: 0 | D13: 6271.6 | E13: 0 | F13: 0 | G13: 0 | H13: =COUNTIF(C13:G13,"<>0") | I13: =IF(H13=0,"לא מטופל",IF(H13=1,"מטופל - סוכן אחד","מטופל - יותר מסוכן אחד"))
... A583: שופרסל BE | B583: 518 כפר קרע BE | C583: 0 | D583: 2759.6 | E583: 0 | F583: 0 | G583: 0 | H583: =COUNTIF(C583:G583,"<>0") | I583: =IF(H583=0,"לא מטופל",IF(H583=1,"מטופל - סוכן אחד","מטופל - יותר מסוכן אחד"))

Sheet סיכום NET
A1: Doors by channel 25&26 — מספר לקוחות (דלתות) וחשבוניות לפי ערוץ, 2025 מול 2026
A2: מקור: | B2: CustomSalesbyCustomerSummary965.xlsx (NetSuite, Custom Sales by Customer Summary)
A3: טווח תאריכים במקור: | B3: 01 January 2025 - 31 October 2026
A4: תאריך חישוב: | B4: 46297
A5: הגדרת "חשבונית": | B5: מסמכים שמספרם (Document Number) מתחיל ב-"INV" בלבד. CM (Credit Memo) ו-CS (Cash Sale) אינם נספרים — ראו גיליון "הערות שיטה".
A7: ערוץ (קוד+שם) | B7: מספר לקוחות (דלתות) | C7: חשבוניות 2025 | D7: חשבוניות 2026
A8: 102 - Orthopedic institutes | B8: =SUMPRODUCT((RawData!$A$2:$A$2208=$A8)/COUNTIFS(RawData!$A$2:$A$2208,RawData!$A$2:$A$2208,RawData!$B$2:$B$2208,RawData!$B$2:$B$2208)) | C8: =COUNTIFS(RawData!$A$2:$A$2208,$A8,RawData!$D$2:$D$2208,"INV",RawData!$E$2:$E$2208,"<>0") | D8: =COUNTIFS(RawData!$A$2:$A$2208,$A8,RawData!$D$2:$D$2208,"INV",RawData!$G$2:$G$2208,"<>0")
A9: 103 - Physiotherapy institutes | B9: =SUMPRODUCT((RawData!$A$2:$A$2208=$A9)/COUNTIFS(RawData!$A$2:$A$2208,RawData!$A$2:$A$2208,RawData!$B$2:$B$2208,RawData!$B$2:$B$2208)) | C9: =COUNTIFS(RawData!$A$2:$A$2208,$A9,RawData!$D$2:$D$2208,"INV",RawData!$E$2:$E$2208,"<>0") | D9: =COUNTIFS(RawData!$A$2:$A$2208,$A9,RawData!$D$2:$D$2208,"INV",RawData!$G$2:$G$2208,"<>0")
A10: 104 - Sports Shop | B10: =SUMPRODUCT((RawData!$A$2:$A$2208=$A10)/COUNTIFS(RawData!$A$2:$A$2208,RawData!$A$2:$A$2208,RawData!$B$2:$B$2208,RawData!$B$2:$B$2208)) | C10: =COUNTIFS(RawData!$A$2:$A$2208,$A10,RawData!$D$2:$D$2208,"INV",RawData!$E$2:$E$2208,"<>0") | D10: =COUNTIFS(RawData!$A$2:$A$2208,$A10,RawData!$D$2:$D$2208,"INV",RawData!$G$2:$G$2208,"<>0")
A11: 105 - Pedicure Salons | B11: =SUMPRODUCT((RawData!$A$2:$A$2208=$A11)/COUNTIFS(RawData!$A$2:$A$2208,RawData!$A$2:$A$2208,RawData!$B$2:$B$2208,RawData!$B$2:$B$2208)) | C11: =COUNTIFS(RawData!$A$2:$A$2208,$A11,RawData!$D$2:$D$2208,"INV",RawData!$E$2:$E$2208,"<>0") | D11: =COUNTIFS(RawData!$A$2:$A$2208,$A11,RawData!$D$2:$D$2208,"INV",RawData!$G$2:$G$2208,"<>0")
A12: 107 - Pharmacies | B12: =SUMPRODUCT((RawData!$A$2:$A$2208=$A12)/COUNTIFS(RawData!$A$2:$A$2208,RawData!$A$2:$A$2208,RawData!$B$2:$B$2208,RawData!$B$2:$B$2208)) | C12: =COUNTIFS(RawData!$A$2:$A$2208,$A12,RawData!$D$2:$D$2208,"INV",RawData!$E$2:$E$2208,"<>0") | D12: =COUNTIFS(RawData!$A$2:$A$2208,$A12,RawData!$D$2:$D$2208,"INV",RawData!$G$2:$G$2208,"<>0")
A13: 108 - Shoe Stores | B13: =SUMPRODUCT((RawData!$A$2:$A$2208=$A13)/COUNTIFS(RawData!$A$2:$A$2208,RawData!$A$2:$A$2208,RawData!$B$2:$B$2208,RawData!$B$2:$B$2208)) | C13: =COUNTIFS(RawData!$A$2:$A$2208,$A13,RawData!$D$2:$D$2208,"INV",RawData!$E$2:$E$2208,"<>0") | D13: =COUNTIFS(RawData!$A$2:$A$2208,$A13,RawData!$D$2:$D$2208,"INV",RawData!$G$2:$G$2208,"<>0")
A14: 109 - Private Shops | B14: =SUMPRODUCT((RawData!$A$2:$A$2208=$A14)/COUNTIFS(RawData!$A$2:$A$2208,RawData!$A$2:$A$2208,RawData!$B$2:$B$2208,RawData!$B$2:$B$2208)) | C14: =COUNTIFS(RawData!$A$2:$A$2208,$A14,RawData!$D$2:$D$2208,"INV",RawData!$E$2:$E$2208,"<>0") | D14: =COUNTIFS(RawData!$A$2:$A$2208,$A14,RawData!$D$2:$D$2208,"INV",RawData!$G$2:$G$2208,"<>0")
A15: סה"כ 7 הערוצים | B15: =SUM(B8:B14) | C15: =SUM(C8:C14) | D15: =SUM(D8:D14)

Sheet השוואת מכר לפי סוכן
A1: השוואת מכר (₪) לפי סוכן — 2025 מול 2026
A3: סוכן | B3: מכר 2025 (₪, 12 ח׳) | C3: מכר 2026 גולמי (₪, 9 ח׳) | D3: מכר 2026 מנורמל (₪, ×12/9) | E3: % שינוי (מנורמל מול 2025) | F3: ₪ שינוי (מנורמל מול 2025)
A4: חיים וייצמ | B4: =SUM('נקודות - מקור 2025'!$C$2:$C$583) | C4: =SUM('נקודות - מקור'!$C$2:$C$564) | D4: =C4*12/9 | E4: =IF(B4=0,"",(D4-B4)/B4) | F4: =D4-B4
A5: חאזם תלחמי | B5: =SUM('נקודות - מקור 2025'!$D$2:$D$583) | C5: =SUM('נקודות - מקור'!$D$2:$D$564) | D5: =C5*12/9 | E5: =IF(B5=0,"",(D5-B5)/B5) | F5: =D5-B5
A6: סטאס נסאר | B6: =SUM('נקודות - מקור 2025'!$E$2:$E$583) | C6: =SUM('נקודות - מקור'!$E$2:$E$564) | D6: =C6*12/9 | E6: =IF(B6=0,"",(D6-B6)/B6) | F6: =D6-B6
A7: עיסא | B7: =SUM('נקודות - מקור 2025'!$F$2:$F$583) | C7: =SUM('נקודות - מקור'!$F$2:$F$564) | D7: =C7*12/9 | E7: =IF(B7=0,"",(D7-B7)/B7) | F7: =D7-B7
A8: .דוד א | B8: =SUM('נקודות - מקור 2025'!$G$2:$G$583) | C8: =SUM('נקודות - מקור'!$G$2:$G$564) | D8: =C8*12/9 | E8: =IF(B8=0,"",(D8-B8)/B8) | F8: =D8-B8
A9: סה"כ | B9: =SUM(B4:B8) | C9: =SUM(C4:C8) | D9: =SUM(D4:D8) | E9: =IF(B9=0,"",(D9-B9)/B9) | F9: =SUM(F4:F8)

Sheet סוכנים-ערוצים - מקור
A1: סוכן | B1: ערוץ (קוד+שם) | C1: שנה | D1: מספר לקוחות (דלתות) | E1: סה"כ מכר (₪)
A2: אמזלג × מירב שירה | B2: 102 - Orthopedic institutes | C2: 2025 | D2: 3 | E2: 25159.06
A3: אמזלג × מירב שירה | B3: 103 - Physiotherapy institutes | C3: 2025 | D3: 3 | E3: 19548.06
A4: אמזלג × מירב שירה | B4: 104 - Sports Shop | C4: 2025 | D4: 0 | E4: 0
A5: אמזלג × מירב שירה | B5: 105 - Pedicure Salons | C5: 2025 | D5: 0 | E5: 0
A6: אמזלג × מירב שירה | B6: 107 - Pharmacies | C6: 2025 | D6: 0 | E6: 0
A7: אמזלג × מירב שירה | B7: 108 - Shoe Stores | C7: 2025 | D7: 1 | E7: 19065.38
A8: אמזלג × מירב שירה | B8: 109 - Private Shops | C8: 2025 | D8: 3 | E8: 4676.89
A9: אזולאי דוד | B9: 102 - Orthopedic institutes | C9: 2025 | D9: 27 | E9: 257530.14
A10: אזולאי דוד | B10: 103 - Physiotherapy institutes | C10: 2025 | D10: 0 | E10: 0
A11: אזולאי דוד | B11: 104 - Sports Shop | C11: 2025 | D11: 0 | E11: 0
A12: אזולאי דוד | B12: 105 - Pedicure Salons | C12: 2025 | D12: 1 | E12: 2013.25
A13: אזולאי דוד | B13: 107 - Pharmacies | C13: 2025 | D13: 0 | E13: 0
... A85: - Unassigned - | B85: 109 - Private Shops | C85: 2026 | D85: 0 | E85: 0

Sheet סוכנים-ערוצים 2025
A1: סוכנים לפי ערוץ 2025 — מספר לקוחות (דלתות) וסה"כ מכר (₪)
A2: טבלה א׳: מספר לקוחות (דלתות)
A3: סוכן | B3: 102 - Orthopedic institutes | C3: 103 - Physiotherapy institutes | D3: 104 - Sports Shop | E3: 105 - Pedicure Salons | F3: 107 - Pharmacies | G3: 108 - Shoe Stores | H3: 109 - Private Shops | I3: סה"כ 7 הערוצים
A4: אמזלג × מירב שירה | B4: =SUMIFS('סוכנים-ערוצים - מקור'!$D$2:$D$85,'סוכנים-ערוצים - מקור'!$A$2:$A$85,$A4,'סוכנים-ערוצים - מקור'!$B$2:$B$85,B$3,'סוכנים-ערוצים - מקור'!$C$2:$C$85,2025) | C4: =SUMIFS('סוכנים-ערוצים - מקור'!$D$2:$D$85,'סוכנים-ערוצים - מקור'!$A$2:$A$85,$A4,'סוכנים-ערוצים - מקור'!$B$2:$B$85,C$3,'סוכנים-ערוצים - מקור'!$C$2:$C$85,2025) | D4: =SUMIFS('סוכנים-ערוצים - מקור'!$D$2:$D$85,'סוכנים-ערוצים - מקור'!$A$2:$A$85,$A4,'סוכנים-ערוצים - מקור'!$B$2:$B$85,D$3,'סוכנים-ערוצים - מקור'!$C$2:$C$85,2025) | E4: =SUMIFS('סוכנים-ערוצים - מקור'!$D$2:$D$85,'סוכנים-ערוצים - מקור'!$A$2:$A$85,$A4,'סוכנים-ערוצים - מקור'!$B$2:$B$85,E$3,'סוכנים-ערוצים - מקור'!$C$2:$C$85,2025) | F4: =SUMIFS('סוכנים-ערוצים - מקור'!$D$2:$D$85,'סוכנים-ערוצים - מקור'!$A$2:$A$85,$A4,'סוכנים-ערוצים - מקור'!$B$2:$B$85,F$3,'סוכנים-ערוצים - מקור'!$C$2:$C$85,2025) | G4: =SUMIFS('סוכנים-ערוצים - מקור'!$D$2:$D$85,'סוכנים-ערוצים - מקור'!$A$2:$A$85,$A4,'סוכנים-ערוצים - מקור'!$B$2:$B$85,G$3,'סוכנים-ערוצים - מקור'!$C$2:$C$85,2025) | H4: =SUMIFS('סוכנים-ערוצים - מקור'!$D$2:$D$85,'סוכנים-ערוצים - מקור'!$A$2:$A$85,$A4,'סוכנים-ערוצים - מקור'!$B$2:$B$85,H$3,'סוכנים-ערוצים - מקור'!$C$2:$C$85,2025) | I4: =SUM(B4:H4)
A5: אזולאי דוד | B5: =SUMIFS('סוכנים-ערוצים - מקור'!$D$2:$D$85,'סוכנים-ערוצים - מקור'!$A$2:$A$85,$A5,'סוכנים-ערוצים - מקור'!$B$2:$B$85,B$3,'סוכנים-ערוצים - מקור'!$C$2:$C$85,2025) | C5: =SUMIFS('סוכנים-ערוצים - מקור'!$D$2:$D$85,'סוכנים-ערוצים - מקור'!$A$2:$A$85,$A5,'סוכנים-ערוצים - מקור'!$B$2:$B$85,C$3,'סוכנים-ערוצים - מקור'!$C$2:$C$85,2025) | D5: =SUMIFS('סוכנים-ערוצים - מקור'!$D$2:$D$85,'סוכנים-ערוצים - מקור'!$A$2:$A$85,$A5,'סוכנים-ערוצים - מקור'!$B$2:$B$85,D$3,'סוכנים-ערוצים - מקור'!$C$2:$C$85,2025) | E5: =SUMIFS('סוכנים-ערוצים - מקור'!$D$2:$D$85,'סוכנים-ערוצים - מקור'!$A$2:$A$85,$A5,'סוכנים-ערוצים - מקור'!$B$2:$B$85,E$3,'סוכנים-ערוצים - מקור'!$C$2:$C$85,2025) | F5: =SUMIFS('סוכנים-ערוצים - מקור'!$D$2:$D$85,'סוכנים-ערוצים - מקור'!$A$2:$A$85,$A5,'סוכנים-ערוצים - מקור'!$B$2:$B$85,F$3,'סוכנים-ערוצים - מקור'!$C$2:$C$85,2025) | G5: =SUMIFS('סוכנים-ערוצים - מקור'!$D$2:$D$85,'סוכנים-ערוצים - מקור'!$A$2:$A$85,$A5,'סוכנים-ערוצים - מקור'!$B$2:$B$85,G$3,'סוכנים-ערוצים - מקור'!$C$2:$C$85,2025) | H5: =SUMIFS('סוכנים-ערוצים - מקור'!$D$2:$D$85,'סוכנים-ערוצים - מקור'!$A$2:$A$85,$A5,'סוכנים-ערוצים - מקור'!$B$2:$B$85,H$3,'סוכנים-ערוצים - מקור'!$C$2:$C$85,2025) | I5: =SUM(B5:H5)
A6: סטניסלב נסאר | B6: =SUMIFS('סוכנים-ערוצים - מקור'!$D$2:$D$85,'סוכנים-ערוצים - מקור'!$A$2:$A$85,$A6,'סוכנים-ערוצים - מקור'!$B$2:$B$85,B$3,'סוכנים-ערוצים - מקור'!$C$2:$C$85,2025) | C6: =SUMIFS('סוכנים-ערוצים - מקור'!$D$2:$D$85,'סוכנים-ערוצים - מקור'!$A$2:$A$85,$A6,'סוכנים-ערוצים - מקור'!$B$2:$B$85,C$3,'סוכנים-ערוצים - מקור'!$C$2:$C$85,2025) | D6: =SUMIFS('סוכנים-ערוצים - מקור'!$D$2:$D$85,'סוכנים-ערוצים - מקור'!$A$2:$A$85,$A6,'סוכנים-ערוצים - מקור'!$B$2:$B$85,D$3,'סוכנים-ערוצים - מקור'!$C$2:$C$85,2025) | E6: =SUMIFS('סוכנים-ערוצים - מקור'!$D$2:$D$85,'סוכנים-ערוצים - מקור'!$A$2:$A$85,$A6,'סוכנים-ערוצים - מקור'!$B$2:$B$85,E$3,'סוכנים-ערוצים - מקור'!$C$2:$C$85,2025) | F6: =SUMIFS('סוכנים-ערוצים - מקור'!$D$2:$D$85,'סוכנים-ערוצים - מקור'!$A$2:$A$85,$A6,'סוכנים-ערוצים - מקור'!$B$2:$B$85,F$3,'סוכנים-ערוצים - מקור'!$C$2:$C$85,2025) | G6: =SUMIFS('סוכנים-ערוצים - מקור'!$D$2:$D$85,'סוכנים-ערוצים - מקור'!$A$2:$A$85,$A6,'סוכנים-ערוצים - מקור'!$B$2:$B$85,G$3,'סוכנים-ערוצים - מקור'!$C$2:$C$85,2025) | H6: =SUMIFS('סוכנים-ערוצים - מקור'!$D$2:$D$85,'סוכנים-ערוצים - מקור'!$A$2:$A$85,$A6,'סוכנים-ערוצים - מקור'!$B$2:$B$85,H$3,'סוכנים-ערוצים - מקור'!$C$2:$C$85,2025) | I6: =SUM(B6:H6)
A7: חאזם תלחמי | B7: =SUMIFS('סוכנים-ערוצים - מקור'!$D$2:$D$85,'סוכנים-ערוצים - מקור'!$A$2:$A$85,$A7,'סוכנים-ערוצים - מקור'!$B$2:$B$85,B$3,'סוכנים-ערוצים - מקור'!$C$2:$C$85,2025) | C7: =SUMIFS('סוכנים-ערוצים - מקור'!$D$2:$D$85,'סוכנים-ערוצים - מקור'!$A$2:$A$85,$A7,'סוכנים-ערוצים - מקור'!$B$2:$B$85,C$3,'סוכנים-ערוצים - מקור'!$C$2:$C$85,2025) | D7: =SUMIFS('סוכנים-ערוצים - מקור'!$D$2:$D$85,'סוכנים-ערוצים - מקור'!$A$2:$A$85,$A7,'סוכנים-ערוצים - מקור'!$B$2:$B$85,D$3,'סוכנים-ערוצים - מקור'!$C$2:$C$85,2025) | E7: =SUMIFS('סוכנים-ערוצים - מקור'!$D$2:$D$85,'סוכנים-ערוצים - מקור'!$A$2:$A$85,$A7,'סוכנים-ערוצים - מקור'!$B$2:$B$85,E$3,'סוכנים-ערוצים - מקור'!$C$2:$C$85,2025) | F7: =SUMIFS('סוכנים-ערוצים - מקור'!$D$2:$D$85,'סוכנים-ערוצים - מקור'!$A$2:$A$85,$A7,'סוכנים-ערוצים - מקור'!$B$2:$B$85,F$3,'סוכנים-ערוצים - מקור'!$C$2:$C$85,2025) | G7: =SUMIFS('סוכנים-ערוצים - מקור'!$D$2:$D$85,'סוכנים-ערוצים - מקור'!$A$2:$A$85,$A7,'סוכנים-ערוצים - מקור'!$B$2:$B$85,G$3,'סוכנים-ערוצים - מקור'!$C$2:$C$85,2025) | H7: =SUMIFS('סוכנים-ערוצים - מקור'!$D$2:$D$85,'סוכנים-ערוצים - מקור'!$A$2:$A$85,$A7,'סוכנים-ערוצים - מקור'!$B$2:$B$85,H$3,'סוכנים-ערוצים - מקור'!$C$2:$C$85,2025) | I7: =SUM(B7:H7)
A8: חיים ויצמן | B8: =SUMIFS('סוכנים-ערוצים - מקור'!$D$2:$D$85,'סוכנים-ערוצים - מקור'!$A$2:$A$85,$A8,'סוכנים-ערוצים - מקור'!$B$2:$B$85,B$3,'סוכנים-ערוצים - מקור'!$C$2:$C$85,2025) | C8: =SUMIFS('סוכנים-ערוצים - מקור'!$D$2:$D$85,'סוכנים-ערוצים - מקור'!$A$2:$A$85,$A8,'סוכנים-ערוצים - מקור'!$B$2:$B$85,C$3,'סוכנים-ערוצים - מקור'!$C$2:$C$85,2025) | D8: =SUMIFS('סוכנים-ערוצים - מקור'!$D$2:$D$85,'סוכנים-ערוצים - מקור'!$A$2:$A$85,$A8,'סוכנים-ערוצים - מקור'!$B$2:$B$85,D$3,'סוכנים-ערוצים - מקור'!$C$2:$C$85,2025) | E8: =SUMIFS('סוכנים-ערוצים - מקור'!$D$2:$D$85,'סוכנים-ערוצים - מקור'!$A$2:$A$85,$A8,'סוכנים-ערוצים - מקור'!$B$2:$B$85,E$3,'סוכנים-ערוצים - מקור'!$C$2:$C$85,2025) | F8: =SUMIFS('סוכנים-ערוצים - מקור'!$D$2:$D$85,'סוכנים-ערוצים - מקור'!$A$2:$A$85,$A8,'סוכנים-ערוצים - מקור'!$B$2:$B$85,F$3,'סוכנים-ערוצים - מקור'!$C$2:$C$85,2025) | G8: =SUMIFS('סוכנים-ערוצים - מקור'!$D$2:$D$85,'סוכנים-ערוצים - מקור'!$A$2:$A$85,$A8,'סוכנים-ערוצים - מקור'!$B$2:$B$85,G$3,'סוכנים-ערוצים - מקור'!$C$2:$C$85,2025) | H8: =SUMIFS('סוכנים-ערוצים - מקור'!$D$2:$D$85,'סוכנים-ערוצים - מקור'!$A$2:$A$85,$A8,'סוכנים-ערוצים - מקור'!$B$2:$B$85,H$3,'סוכנים-ערוצים - מקור'!$C$2:$C$85,2025) | I8: =SUM(B8:H8)
A9: - Unassigned - | B9: =SUMIFS('סוכנים-ערוצים - מקור'!$D$2:$D$85,'סוכנים-ערוצים - מקור'!$A$2:$A$85,$A9,'סוכנים-ערוצים - מקור'!$B$2:$B$85,B$3,'סוכנים-ערוצים - מקור'!$C$2:$C$85,2025) | C9: =SUMIFS('סוכנים-ערוצים - מקור'!$D$2:$D$85,'סוכנים-ערוצים - מקור'!$A$2:$A$85,$A9,'סוכנים-ערוצים - מקור'!$B$2:$B$85,C$3,'סוכנים-ערוצים - מקור'!$C$2:$C$85,2025) | D9: =SUMIFS('סוכנים-ערוצים - מקור'!$D$2:$D$85,'סוכנים-ערוצים - מקור'!$A$2:$A$85,$A9,'סוכנים-ערוצים - מקור'!$B$2:$B$85,D$3,'סוכנים-ערוצים - מקור'!$C$2:$C$85,2025) | E9: =SUMIFS('סוכנים-ערוצים - מקור'!$D$2:$D$85,'סוכנים-ערוצים - מקור'!$A$2:$A$85,$A9,'סוכנים-ערוצים - מקור'!$B$2:$B$85,E$3,'סוכנים-ערוצים - מקור'!$C$2:$C$85,2025) | F9: =SUMIFS('סוכנים-ערוצים - מקור'!$D$2:$D$85,'סוכנים-ערוצים - מקור'!$A$2:$A$85,$A9,'סוכנים-ערוצים - מקור'!$B$2:$B$85,F$3,'סוכנים-ערוצים - מקור'!$C$2:$C$85,2025) | G9: =SUMIFS('סוכנים-ערוצים - מקור'!$D$2:$D$85,'סוכנים-ערוצים - מקור'!$A$2:$A$85,$A9,'סוכנים-ערוצים - מקור'!$B$2:$B$85,G$3,'סוכנים-ערוצים - מקור'!$C$2:$C$85,2025) | H9: =SUMIFS('סוכנים-ערוצים - מקור'!$D$2:$D$85,'סוכנים-ערוצים - מקור'!$A$2:$A$85,$A9,'סוכנים-ערוצים - מקור'!$B$2:$B$85,H$3,'סוכנים-ערוצים - מקור'!$C$2:$C$85,2025) | I9: =SUM(B9:H9)
A10: סה"כ | B10: =SUM(B4:B9) | C10: =SUM(C4:C9) | D10: =SUM(D4:D9) | E10: =SUM(E4:E9) | F10: =SUM(F4:F9) | G10: =SUM(G4:G9) | H10: =SUM(H4:H9) | I10: =SUM(I4:I9)
A12: טבלה ב׳: סה"כ מכר (₪)
A13: סוכן | B13: 102 - Orthopedic institutes | C13: 103 - Physiotherapy institutes | D13: 104 - Sports Shop | E13: 105 - Pedicure Salons | F13: 107 - Pharmacies | G13: 108 - Shoe Stores | H13: 109 - Private Shops | I13: סה"כ 7 הערוצים (₪)
A14: אמזלג × מירב שירה | B14: =SUMIFS('סוכנים-ערוצים - מקור'!$E$2:$E$85,'סוכנים-ערוצים - מקור'!$A$2:$A$85,$A14,'סוכנים-ערוצים - מקור'!$B$2:$B$85,B$13,'סוכנים-ערוצים - מקור'!$C$2:$C$85,2025) | C14: =SUMIFS('סוכנים-ערוצים - מקור'!$E$2:$E$85,'סוכנים-ערוצים - מקור'!$A$2:$A$85,$A14,'סוכנים-ערוצים - מקור'!$B$2:$B$85,C$13,'סוכנים-ערוצים - מקור'!$C$2:$C$85,2025) | D14: =SUMIFS('סוכנים-ערוצים - מקור'!$E$2:$E$85,'סוכנים-ערוצים - מקור'!$A$2:$A$85,$A14,'סוכנים-ערוצים - מקור'!$B$2:$B$85,D$13,'סוכנים-ערוצים - מקור'!$C$2:$C$85,2025) | E14: =SUMIFS('סוכנים-ערוצים - מקור'!$E$2:$E$85,'סוכנים-ערוצים - מקור'!$A$2:$A$85,$A14,'סוכנים-ערוצים - מקור'!$B$2:$B$85,E$13,'סוכנים-ערוצים - מקור'!$C$2:$C$85,2025) | F14: =SUMIFS('סוכנים-ערוצים - מקור'!$E$2:$E$85,'סוכנים-ערוצים - מקור'!$A$2:$A$85,$A14,'סוכנים-ערוצים - מקור'!$B$2:$B$85,F$13,'סוכנים-ערוצים - מקור'!$C$2:$C$85,2025) | G14: =SUMIFS('סוכנים-ערוצים - מקור'!$E$2:$E$85,'סוכנים-ערוצים - מקור'!$A$2:$A$85,$A14,'סוכנים-ערוצים - מקור'!$B$2:$B$85,G$13,'סוכנים-ערוצים - מקור'!$C$2:$C$85,2025) | H14: =SUMIFS('סוכנים-ערוצים - מקור'!$E$2:$E$85,'סוכנים-ערוצים - מקור'!$A$2:$A$85,$A14,'סוכנים-ערוצים - מקור'!$B$2:$B$85,H$13,'סוכנים-ערוצים - מקור'!$C$2:$C$85,2025) | I14: =SUM(B14:H14)
A15: אזולאי דוד | B15: =SUMIFS('סוכנים-ערוצים - מקור'!$E$2:$E$85,'סוכנים-ערוצים - מקור'!$A$2:$A$85,$A15,'סוכנים-ערוצים - מקור'!$B$2:$B$85,B$13,'סוכנים-ערוצים - מקור'!$C$2:$C$85,2025) | C15: =SUMIFS('סוכנים-ערוצים - מקור'!$E$2:$E$85,'סוכנים-ערוצים - מקור'!$A$2:$A$85,$A15,'סוכנים-ערוצים - מקור'!$B$2:$B$85,C$13,'סוכנים-ערוצים - מקור'!$C$2:$C$85,2025) | D15: =SUMIFS('סוכנים-ערוצים - מקור'!$E$2:$E$85,'סוכנים-ערוצים - מקור'!$A$2:$A$85,$A15,'סוכנים-ערוצים - מקור'!$B$2:$B$85,D$13,'סוכנים-ערוצים - מקור'!$C$2:$C$85,2025) | E15: =SUMIFS('סוכנים-ערוצים - מקור'!$E$2:$E$85,'סוכנים-ערוצים - מקור'!$A$2:$A$85,$A15,'סוכנים-ערוצים - מקור'!$B$2:$B$85,E$13,'סוכנים-ערוצים - מקור'!$C$2:$C$85,2025) | F15: =SUMIFS('סוכנים-ערוצים - מקור'!$E$2:$E$85,'סוכנים-ערוצים - מקור'!$A$2:$A$85,$A15,'סוכנים-ערוצים - מקור'!$B$2:$B$85,F$13,'סוכנים-ערוצים - מקור'!$C$2:$C$85,2025) | G15: =SUMIFS('סוכנים-ערוצים - מקור'!$E$2:$E$85,'סוכנים-ערוצים - מקור'!$A$2:$A$85,$A15,'סוכנים-ערוצים - מקור'!$B$2:$B$85,G$13,'סוכנים-ערוצים - מקור'!$C$2:$C$85,2025) | H15: =SUMIFS('סוכנים-ערוצים - מקור'!$E$2:$E$85,'סוכנים-ערוצים - מקור'!$A$2:$A$85,$A15,'סוכנים-ערוצים - מקור'!$B$2:$B$85,H$13,'סוכנים-ערוצים - מקור'!$C$2:$C$85,2025) | I15: =SUM(B15:H15)
A16: סטניסלב נסאר | B16: =SUMIFS('סוכנים-ערוצים - מקור'!$E$2:$E$85,'סוכנים-ערוצים - מקור'!$A$2:$A$85,$A16,'סוכנים-ערוצים - מקור'!$B$2:$B$85,B$13,'סוכנים-ערוצים - מקור'!$C$2:$C$85,2025) | C16: =SUMIFS('סוכנים-ערוצים - מקור'!$E$2:$E$85,'סוכנים-ערוצים - מקור'!$A$2:$A$85,$A16,'סוכנים-ערוצים - מקור'!$B$2:$B$85,C$13,'סוכנים-ערוצים - מקור'!$C$2:$C$85,2025) | D16: =SUMIFS('סוכנים-ערוצים - מקור'!$E$2:$E$85,'סוכנים-ערוצים - מקור'!$A$2:$A$85,$A16,'סוכנים-ערוצים - מקור'!$B$2:$B$85,D$13,'סוכנים-ערוצים - מקור'!$C$2:$C$85,2025) | E16: =SUMIFS('סוכנים-ערוצים - מקור'!$E$2:$E$85,'סוכנים-ערוצים - מקור'!$A$2:$A$85,$A16,'סוכנים-ערוצים - מקור'!$B$2:$B$85,E$13,'סוכנים-ערוצים - מקור'!$C$2:$C$85,2025) | F16: =SUMIFS('סוכנים-ערוצים - מקור'!$E$2:$E$85,'סוכנים-ערוצים - מקור'!$A$2:$A$85,$A16,'סוכנים-ערוצים - מקור'!$B$2:$B$85,F$13,'סוכנים-ערוצים - מקור'!$C$2:$C$85,2025) | G16: =SUMIFS('סוכנים-ערוצים - מקור'!$E$2:$E$85,'סוכנים-ערוצים - מקור'!$A$2:$A$85,$A16,'סוכנים-ערוצים - מקור'!$B$2:$B$85,G$13,'סוכנים-ערוצים - מקור'!$C$2:$C$85,2025) | H16: =SUMIFS('סוכנים-ערוצים - מקור'!$E$2:$E$85,'סוכנים-ערוצים - מקור'!$A$2:$A$85,$A16,'סוכנים-ערוצים - מקור'!$B$2:$B$85,H$13,'סוכנים-ערוצים - מקור'!$C$2:$C$85,2025) | I16: =SUM(B16:H16)
A17: חאזם תלחמי | B17: =SUMIFS('סוכנים-ערוצים - מקור'!$E$2:$E$85,'סוכנים-ערוצים - מקור'!$A$2:$A$85,$A17,'סוכנים-ערוצים - מקור'!$B$2:$B$85,B$13,'סוכנים-ערוצים - מקור'!$C$2:$C$85,2025) | C17: =SUMIFS('סוכנים-ערוצים - מקור'!$E$2:$E$85,'סוכנים-ערוצים - מקור'!$A$2:$A$85,$A17,'סוכנים-ערוצים - מקור'!$B$2:$B$85,C$13,'סוכנים-ערוצים - מקור'!$C$2:$C$85,2025) | D17: =SUMIFS('סוכנים-ערוצים - מקור'!$E$2:$E$85,'סוכנים-ערוצים - מקור'!$A$2:$A$85,$A17,'סוכנים-ערוצים - מקור'!$B$2:$B$85,D$13,'סוכנים-ערוצים - מקור'!$C$2:$C$85,2025) | E17: =SUMIFS('סוכנים-ערוצים - מקור'!$E$2:$E$85,'סוכנים-ערוצים - מקור'!$A$2:$A$85,$A17,'סוכנים-ערוצים - מקור'!$B$2:$B$85,E$13,'סוכנים-ערוצים - מקור'!$C$2:$C$85,2025) | F17: =SUMIFS('סוכנים-ערוצים - מקור'!$E$2:$E$85,'סוכנים-ערוצים - מקור'!$A$2:$A$85,$A17,'סוכנים-ערוצים - מקור'!$B$2:$B$85,F$13,'סוכנים-ערוצים - מקור'!$C$2:$C$85,2025) | G17: =SUMIFS('סוכנים-ערוצים - מקור'!$E$2:$E$85,'סוכנים-ערוצים - מקור'!$A$2:$A$85,$A17,'סוכנים-ערוצים - מקור'!$B$2:$B$85,G$13,'סוכנים-ערוצים - מקור'!$C$2:$C$85,2025) | H17: =SUMIFS('סוכנים-ערוצים - מקור'!$E$2:$E$85,'סוכנים-ערוצים - מקור'!$A$2:$A$85,$A17,'סוכנים-ערוצים - מקור'!$B$2:$B$85,H$13,'סוכנים-ערוצים - מקור'!$C$2:$C$85,2025) | I17: =SUM(B17:H17)
A18: חיים ויצמן | B18: =SUMIFS('סוכנים-ערוצים - מקור'!$E$2:$E$85,'סוכנים-ערוצים - מקור'!$A$2:$A$85,$A18,'סוכנים-ערוצים - מקור'!$B$2:$B$85,B$13,'סוכנים-ערוצים - מקור'!$C$2:$C$85,2025) | C18: =SUMIFS('סוכנים-ערוצים - מקור'!$E$2:$E$85,'סוכנים-ערוצים - מקור'!$A$2:$A$85,$A18,'סוכנים-ערוצים - מקור'!$B$2:$B$85,C$13,'סוכנים-ערוצים - מקור'!$C$2:$C$85,2025) | D18: =SUMIFS('סוכנים-ערוצים - מקור'!$E$2:$E$85,'סוכנים-ערוצים - מקור'!$A$2:$A$85,$A18,'סוכנים-ערוצים - מקור'!$B$2:$B$85,D$13,'סוכנים-ערוצים - מקור'!$C$2:$C$85,2025) | E18: =SUMIFS('סוכנים-ערוצים - מקור'!$E$2:$E$85,'סוכנים-ערוצים - מקור'!$A$2:$A$85,$A18,'סוכנים-ערוצים - מקור'!$B$2:$B$85,E$13,'סוכנים-ערוצים - מקור'!$C$2:$C$85,2025) | F18: =SUMIFS('סוכנים-ערוצים - מקור'!$E$2:$E$85,'סוכנים-ערוצים - מקור'!$A$2:$A$85,$A18,'סוכנים-ערוצים - מקור'!$B$2:$B$85,F$13,'סוכנים-ערוצים - מקור'!$C$2:$C$85,2025) | G18: =SUMIFS('סוכנים-ערוצים - מקור'!$E$2:$E$85,'סוכנים-ערוצים - מקור'!$A$2:$A$85,$A18,'סוכנים-ערוצים - מקור'!$B$2:$B$85,G$13,'סוכנים-ערוצים - מקור'!$C$2:$C$85,2025) | H18: =SUMIFS('סוכנים-ערוצים - מקור'!$E$2:$E$85,'סוכנים-ערוצים - מקור'!$A$2:$A$85,$A18,'סוכנים-ערוצים - מקור'!$B$2:$B$85,H$13,'סוכנים-ערוצים - מקור'!$C$2:$C$85,2025) | I18: =SUM(B18:H18)
A19: - Unassigned - | B19: =SUMIFS('סוכנים-ערוצים - מקור'!$E$2:$E$85,'סוכנים-ערוצים - מקור'!$A$2:$A$85,$A19,'סוכנים-ערוצים - מקור'!$B$2:$B$85,B$13,'סוכנים-ערוצים - מקור'!$C$2:$C$85,2025) | C19: =SUMIFS('סוכנים-ערוצים - מקור'!$E$2:$E$85,'סוכנים-ערוצים - מקור'!$A$2:$A$85,$A19,'סוכנים-ערוצים - מקור'!$B$2:$B$85,C$13,'סוכנים-ערוצים - מקור'!$C$2:$C$85,2025) | D19: =SUMIFS('סוכנים-ערוצים - מקור'!$E$2:$E$85,'סוכנים-ערוצים - מקור'!$A$2:$A$85,$A19,'סוכנים-ערוצים - מקור'!$B$2:$B$85,D$13,'סוכנים-ערוצים - מקור'!$C$2:$C$85,2025) | E19: =SUMIFS('סוכנים-ערוצים - מקור'!$E$2:$E$85,'סוכנים-ערוצים - מקור'!$A$2:$A$85,$A19,'סוכנים-ערוצים - מקור'!$B$2:$B$85,E$13,'סוכנים-ערוצים - מקור'!$C$2:$C$85,2025) | F19: =SUMIFS('סוכנים-ערוצים - מקור'!$E$2:$E$85,'סוכנים-ערוצים - מקור'!$A$2:$A$85,$A19,'סוכנים-ערוצים - מקור'!$B$2:$B$85,F$13,'סוכנים-ערוצים - מקור'!$C$2:$C$85,2025) | G19: =SUMIFS('סוכנים-ערוצים - מקור'!$E$2:$E$85,'סוכנים-ערוצים - מקור'!$A$2:$A$85,$A19,'סוכנים-ערוצים - מקור'!$B$2:$B$85,G$13,'סוכנים-ערוצים - מקור'!$C$2:$C$85,2025) | H19: =SUMIFS('סוכנים-ערוצים - מקור'!$E$2:$E$85,'סוכנים-ערוצים - מקור'!$A$2:$A$85,$A19,'סוכנים-ערוצים - מקור'!$B$2:$B$85,H$13,'סוכנים-ערוצים - מקור'!$C$2:$C$85,2025) | I19: =SUM(B19:H19)
A20: סה"כ | B20: =SUM(B14:B19) | C20: =SUM(C14:C19) | D20: =SUM(D14:D19) | E20: =SUM(E14:E19) | F20: =SUM(F14:F19) | G20: =SUM(G14:G19) | H20: =SUM(H14:H19) | I20: =SUM(I14:I19)

Sheet סוכנים-ערוצים 2026
A1: סוכנים לפי ערוץ 2026 — מספר לקוחות (דלתות) וסה"כ מכר (₪)
A2: טבלה א׳: מספר לקוחות (דלתות)
A3: סוכן | B3: 102 - Orthopedic institutes | C3: 103 - Physiotherapy institutes | D3: 104 - Sports Shop | E3: 105 - Pedicure Salons | F3: 107 - Pharmacies | G3: 108 - Shoe Stores | H3: 109 - Private Shops | I3: סה"כ 7 הערוצים
A4: אמזלג × מירב שירה | B4: =SUMIFS('סוכנים-ערוצים - מקור'!$D$2:$D$85,'סוכנים-ערוצים - מקור'!$A$2:$A$85,$A4,'סוכנים-ערוצים - מקור'!$B$2:$B$85,B$3,'סוכנים-ערוצים - מקור'!$C$2:$C$85,2026) | C4: =SUMIFS('סוכנים-ערוצים - מקור'!$D$2:$D$85,'סוכנים-ערוצים - מקור'!$A$2:$A$85,$A4,'סוכנים-ערוצים - מקור'!$B$2:$B$85,C$3,'סוכנים-ערוצים - מקור'!$C$2:$C$85,2026) | D4: =SUMIFS('סוכנים-ערוצים - מקור'!$D$2:$D$85,'סוכנים-ערוצים - מקור'!$A$2:$A$85,$A4,'סוכנים-ערוצים - מקור'!$B$2:$B$85,D$3,'סוכנים-ערוצים - מקור'!$C$2:$C$85,2026) | E4: =SUMIFS('סוכנים-ערוצים - מקור'!$D$2:$D$85,'סוכנים-ערוצים - מקור'!$A$2:$A$85,$A4,'סוכנים-ערוצים - מקור'!$B$2:$B$85,E$3,'סוכנים-ערוצים - מקור'!$C$2:$C$85,2026) | F4: =SUMIFS('סוכנים-ערוצים - מקור'!$D$2:$D$85,'סוכנים-ערוצים - מקור'!$A$2:$A$85,$A4,'סוכנים-ערוצים - מקור'!$B$2:$B$85,F$3,'סוכנים-ערוצים - מקור'!$C$2:$C$85,2026) | G4: =SUMIFS('סוכנים-ערוצים - מקור'!$D$2:$D$85,'סוכנים-ערוצים - מקור'!$A$2:$A$85,$A4,'סוכנים-ערוצים - מקור'!$B$2:$B$85,G$3,'סוכנים-ערוצים - מקור'!$C$2:$C$85,2026) | H4: =SUMIFS('סוכנים-ערוצים - מקור'!$D$2:$D$85,'סוכנים-ערוצים - מקור'!$A$2:$A$85,$A4,'סוכנים-ערוצים - מקור'!$B$2:$B$85,H$3,'סוכנים-ערוצים - מקור'!$C$2:$C$85,2026) | I4: =SUM(B4:H4)
A5: אזולאי דוד | B5: =SUMIFS('סוכנים-ערוצים - מקור'!$D$2:$D$85,'סוכנים-ערוצים - מקור'!$A$2:$A$85,$A5,'סוכנים-ערוצים - מקור'!$B$2:$B$85,B$3,'סוכנים-ערוצים - מקור'!$C$2:$C$85,2026) | C5: =SUMIFS('סוכנים-ערוצים - מקור'!$D$2:$D$85,'סוכנים-ערוצים - מקור'!$A$2:$A$85,$A5,'סוכנים-ערוצים - מקור'!$B$2:$B$85,C$3,'סוכנים-ערוצים - מקור'!$C$2:$C$85,2026) | D5: =SUMIFS('סוכנים-ערוצים - מקור'!$D$2:$D$85,'סוכנים-ערוצים - מקור'!$A$2:$A$85,$A5,'סוכנים-ערוצים - מקור'!$B$2:$B$85,D$3,'סוכנים-ערוצים - מקור'!$C$2:$C$85,2026) | E5: =SUMIFS('סוכנים-ערוצים - מקור'!$D$2:$D$85,'סוכנים-ערוצים - מקור'!$A$2:$A$85,$A5,'סוכנים-ערוצים - מקור'!$B$2:$B$85,E$3,'סוכנים-ערוצים - מקור'!$C$2:$C$85,2026) | F5: =SUMIFS('סוכנים-ערוצים - מקור'!$D$2:$D$85,'סוכנים-ערוצים - מקור'!$A$2:$A$85,$A5,'סוכנים-ערוצים - מקור'!$B$2:$B$85,F$3,'סוכנים-ערוצים - מקור'!$C$2:$C$85,2026) | G5: =SUMIFS('סוכנים-ערוצים - מקור'!$D$2:$D$85,'סוכנים-ערוצים - מקור'!$A$2:$A$85,$A5,'סוכנים-ערוצים - מקור'!$B$2:$B$85,G$3,'סוכנים-ערוצים - מקור'!$C$2:$C$85,2026) | H5: =SUMIFS('סוכנים-ערוצים - מקור'!$D$2:$D$85,'סוכנים-ערוצים - מקור'!$A$2:$A$85,$A5,'סוכנים-ערוצים - מקור'!$B$2:$B$85,H$3,'סוכנים-ערוצים - מקור'!$C$2:$C$85,2026) | I5: =SUM(B5:H5)
A6: סטניסלב נסאר | B6: =SUMIFS('סוכנים-ערוצים - מקור'!$D$2:$D$85,'סוכנים-ערוצים - מקור'!$A$2:$A$85,$A6,'סוכנים-ערוצים - מקור'!$B$2:$B$85,B$3,'סוכנים-ערוצים - מקור'!$C$2:$C$85,2026) | C6: =SUMIFS('סוכנים-ערוצים - מקור'!$D$2:$D$85,'סוכנים-ערוצים - מקור'!$A$2:$A$85,$A6,'סוכנים-ערוצים - מקור'!$B$2:$B$85,C$3,'סוכנים-ערוצים - מקור'!$C$2:$C$85,2026) | D6: =SUMIFS('סוכנים-ערוצים - מקור'!$D$2:$D$85,'סוכנים-ערוצים - מקור'!$A$2:$A$85,$A6,'סוכנים-ערוצים - מקור'!$B$2:$B$85,D$3,'סוכנים-ערוצים - מקור'!$C$2:$C$85,2026) | E6: =SUMIFS('סוכנים-ערוצים - מקור'!$D$2:$D$85,'סוכנים-ערוצים - מקור'!$A$2:$A$85,$A6,'סוכנים-ערוצים - מקור'!$B$2:$B$85,E$3,'סוכנים-ערוצים - מקור'!$C$2:$C$85,2026) | F6: =SUMIFS('סוכנים-ערוצים - מקור'!$D$2:$D$85,'סוכנים-ערוצים - מקור'!$A$2:$A$85,$A6,'סוכנים-ערוצים - מקור'!$B$2:$B$85,F$3,'סוכנים-ערוצים - מקור'!$C$2:$C$85,2026) | G6: =SUMIFS('סוכנים-ערוצים - מקור'!$D$2:$D$85,'סוכנים-ערוצים - מקור'!$A$2:$A$85,$A6,'סוכנים-ערוצים - מקור'!$B$2:$B$85,G$3,'סוכנים-ערוצים - מקור'!$C$2:$C$85,2026) | H6: =SUMIFS('סוכנים-ערוצים - מקור'!$D$2:$D$85,'סוכנים-ערוצים - מקור'!$A$2:$A$85,$A6,'סוכנים-ערוצים - מקור'!$B$2:$B$85,H$3,'סוכנים-ערוצים - מקור'!$C$2:$C$85,2026) | I6: =SUM(B6:H6)
A7: חאזם תלחמי | B7: =SUMIFS('סוכנים-ערוצים - מקור'!$D$2:$D$85,'סוכנים-ערוצים - מקור'!$A$2:$A$85,$A7,'סוכנים-ערוצים - מקור'!$B$2:$B$85,B$3,'סוכנים-ערוצים - מקור'!$C$2:$C$85,2026) | C7: =SUMIFS('סוכנים-ערוצים - מקור'!$D$2:$D$85,'סוכנים-ערוצים - מקור'!$A$2:$A$85,$A7,'סוכנים-ערוצים - מקור'!$B$2:$B$85,C$3,'סוכנים-ערוצים - מקור'!$C$2:$C$85,2026) | D7: =SUMIFS('סוכנים-ערוצים - מקור'!$D$2:$D$85,'סוכנים-ערוצים - מקור'!$A$2:$A$85,$A7,'סוכנים-ערוצים - מקור'!$B$2:$B$85,D$3,'סוכנים-ערוצים - מקור'!$C$2:$C$85,2026) | E7: =SUMIFS('סוכנים-ערוצים - מקור'!$D$2:$D$85,'סוכנים-ערוצים - מקור'!$A$2:$A$85,$A7,'סוכנים-ערוצים - מקור'!$B$2:$B$85,E$3,'סוכנים-ערוצים - מקור'!$C$2:$C$85,2026) | F7: =SUMIFS('סוכנים-ערוצים - מקור'!$D$2:$D$85,'סוכנים-ערוצים - מקור'!$A$2:$A$85,$A7,'סוכנים-ערוצים - מקור'!$B$2:$B$85,F$3,'סוכנים-ערוצים - מקור'!$C$2:$C$85,2026) | G7: =SUMIFS('סוכנים-ערוצים - מקור'!$D$2:$D$85,'סוכנים-ערוצים - מקור'!$A$2:$A$85,$A7,'סוכנים-ערוצים - מקור'!$B$2:$B$85,G$3,'סוכנים-ערוצים - מקור'!$C$2:$C$85,2026) | H7: =SUMIFS('סוכנים-ערוצים - מקור'!$D$2:$D$85,'סוכנים-ערוצים - מקור'!$A$2:$A$85,$A7,'סוכנים-ערוצים - מקור'!$B$2:$B$85,H$3,'סוכנים-ערוצים - מקור'!$C$2:$C$85,2026) | I7: =SUM(B7:H7)
A8: חיים ויצמן | B8: =SUMIFS('סוכנים-ערוצים - מקור'!$D$2:$D$85,'סוכנים-ערוצים - מקור'!$A$2:$A$85,$A8,'סוכנים-ערוצים - מקור'!$B$2:$B$85,B$3,'סוכנים-ערוצים - מקור'!$C$2:$C$85,2026) | C8: =SUMIFS('סוכנים-ערוצים - מקור'!$D$2:$D$85,'סוכנים-ערוצים - מקור'!$A$2:$A$85,$A8,'סוכנים-ערוצים - מקור'!$B$2:$B$85,C$3,'סוכנים-ערוצים - מקור'!$C$2:$C$85,2026) | D8: =SUMIFS('סוכנים-ערוצים - מקור'!$D$2:$D$85,'סוכנים-ערוצים - מקור'!$A$2:$A$85,$A8,'סוכנים-ערוצים - מקור'!$B$2:$B$85,D$3,'סוכנים-ערוצים - מקור'!$C$2:$C$85,2026) | E8: =SUMIFS('סוכנים-ערוצים - מקור'!$D$2:$D$85,'סוכנים-ערוצים - מקור'!$A$2:$A$85,$A8,'סוכנים-ערוצים - מקור'!$B$2:$B$85,E$3,'סוכנים-ערוצים - מקור'!$C$2:$C$85,2026) | F8: =SUMIFS('סוכנים-ערוצים - מקור'!$D$2:$D$85,'סוכנים-ערוצים - מקור'!$A$2:$A$85,$A8,'סוכנים-ערוצים - מקור'!$B$2:$B$85,F$3,'סוכנים-ערוצים - מקור'!$C$2:$C$85,2026) | G8: =SUMIFS('סוכנים-ערוצים - מקור'!$D$2:$D$85,'סוכנים-ערוצים - מקור'!$A$2:$A$85,$A8,'סוכנים-ערוצים - מקור'!$B$2:$B$85,G$3,'סוכנים-ערוצים - מקור'!$C$2:$C$85,2026) | H8: =SUMIFS('סוכנים-ערוצים - מקור'!$D$2:$D$85,'סוכנים-ערוצים - מקור'!$A$2:$A$85,$A8,'סוכנים-ערוצים - מקור'!$B$2:$B$85,H$3,'סוכנים-ערוצים - מקור'!$C$2:$C$85,2026) | I8: =SUM(B8:H8)
A9: - Unassigned - | B9: =SUMIFS('סוכנים-ערוצים - מקור'!$D$2:$D$85,'סוכנים-ערוצים - מקור'!$A$2:$A$85,$A9,'סוכנים-ערוצים - מקור'!$B$2:$B$85,B$3,'סוכנים-ערוצים - מקור'!$C$2:$C$85,2026) | C9: =SUMIFS('סוכנים-ערוצים - מקור'!$D$2:$D$85,'סוכנים-ערוצים - מקור'!$A$2:$A$85,$A9,'סוכנים-ערוצים - מקור'!$B$2:$B$85,C$3,'סוכנים-ערוצים - מקור'!$C$2:$C$85,2026) | D9: =SUMIFS('סוכנים-ערוצים - מקור'!$D$2:$D$85,'סוכנים-ערוצים - מקור'!$A$2:$A$85,$A9,'סוכנים-ערוצים - מקור'!$B$2:$B$85,D$3,'סוכנים-ערוצים - מקור'!$C$2:$C$85,2026) | E9: =SUMIFS('סוכנים-ערוצים - מקור'!$D$2:$D$85,'סוכנים-ערוצים - מקור'!$A$2:$A$85,$A9,'סוכנים-ערוצים - מקור'!$B$2:$B$85,E$3,'סוכנים-ערוצים - מקור'!$C$2:$C$85,2026) | F9: =SUMIFS('סוכנים-ערוצים - מקור'!$D$2:$D$85,'סוכנים-ערוצים - מקור'!$A$2:$A$85,$A9,'סוכנים-ערוצים - מקור'!$B$2:$B$85,F$3,'סוכנים-ערוצים - מקור'!$C$2:$C$85,2026) | G9: =SUMIFS('סוכנים-ערוצים - מקור'!$D$2:$D$85,'סוכנים-ערוצים - מקור'!$A$2:$A$85,$A9,'סוכנים-ערוצים - מקור'!$B$2:$B$85,G$3,'סוכנים-ערוצים - מקור'!$C$2:$C$85,2026) | H9: =SUMIFS('סוכנים-ערוצים - מקור'!$D$2:$D$85,'סוכנים-ערוצים - מקור'!$A$2:$A$85,$A9,'סוכנים-ערוצים - מקור'!$B$2:$B$85,H$3,'סוכנים-ערוצים - מקור'!$C$2:$C$85,2026) | I9: =SUM(B9:H9)
A10: סה"כ | B10: =SUM(B4:B9) | C10: =SUM(C4:C9) | D10: =SUM(D4:D9) | E10: =SUM(E4:E9) | F10: =SUM(F4:F9) | G10: =SUM(G4:G9) | H10: =SUM(H4:H9) | I10: =SUM(I4:I9)
A12: טבלה ב׳: סה"כ מכר (₪)
