Workbook

Sheet ניו
A1: לקוח | B1: פריט אב | C1: סך עלות | D1: Euro | E1: mu
A2: NZ | B2: 078 | C2: 24.780153 | D2: 16.5 | E2: 2.6101534
A3: NZ | B3: 078G | C3: 28.763394 | D3: 16.5 | E3: 2.2486915
A4: NZ | B4: 07AU | C4: 80.020931 | D4: 38.75 | E4: 1.8982534
A5: NZ | B5: 11STO | C5: 27.751475 | D5: 22.5 | E5: 3.1782094
A6: NZ | B6: 11TO | C6: 39.612447 | D6: 21.85 | E6: 2.1622497
A7: NZ | B7: 13 | C7: 41.645439 | D7: 21.8 | E7: 2.0519894
A8: NZ | B8: 14 | C8: 62.103423 | D8: 29.95 | E8: 1.8904594
A9: NZ | B9: 15M | C9: 41.142264 | D9: 19.95 | E9: 1.9008191
A10: NZ | B10: 15W | C10: 36.494703 | D10: 18.9 | E10: 2.0301028
A11: NZ | B11: 16 | C11: 32.401747 | D11: 16.8 | E11: 2.032483
A12: NZ | B12: 21 | C12: 10.742199 | D12: 5.5 | E12: 2.0070379
A13: NZ | B13: 211 | C13: 9.7558581 | D13: 5.65 | E13: 2.2702257
A14: NZ | B14: 212 | C14: 10.064243 | D14: 5.85 | E14: 2.2785618
A15: NZ | B15: 237 | C15: 7.9041891 | D15: 4.65 | E15: 2.3061189
A16: NZ | B16: 238 | C16: 5.1708301 | D16: 2.8 | E16: 2.1226766
A17: NZ | B17: 239 | C17: 5.3603825 | D17: 3.25 | E17: 2.3766961
A18: NZ | B18: 250 | C18: 14.074193 | D18: 6.6 | E18: 1.8382582
A19: NZ | B19: 251 | C19: 13.981992 | D19: 7.5 | E19: 2.1027046
A20: NZ | B20: 26 | C20: 32.879937 | D20: 16.5 | E20: 1.9671571
A21: NZ | B21: 266 | C21: 12.43339 | D21: 6.3 | E21: 1.9862643
A22: NZ | B22: 268 | C22: 19.771523 | D22: 9.75 | E22: 1.9330832
A23: NZ | B23: 302M | C23: 16.673415 | D23: 9.1 | E23: 2.1394537
... A35: NZ | B35: 351 | C35: 17.432062 | D35: 9.15 | E35: 2.0575879
A36: NZ | B36: 35 | C36: 6.6482388 | D36: 3.55 | E36: 2.0931859
A37: NZ | B37: 35B | C37: 6.8426828 | D37: 3.55 | E37: 2.0337053
A38: NZ | B38: 35C | C38: 6.8426828 | D38: 3.55 | E38: 2.0337053
A39: NZ | B39: 3611 | C39: 17.795447 | D39: 9.1 | E39: 2.0045577
A40: NZ | B40: 362 | C40: 8.7565615 | D40: 4.9 | E40: 2.1935551
A41: NZ | B41: 3622S | C41: 9.4336352 | D41: 5.45 | E41: 2.2646625
A42: NZ | B42: 3623 | C42: 8.8779872 | D42: 5.1 | E42: 2.2518618
A43: NZ | B43: 363 | C43: 6.5625268 | D43: 3.65 | E43: 2.1802578
A44: NZ | B44: 364 S-L | C44: 2.9456457 | D44: 1.8 | E44: 2.3954001
A45: NZ | B45: 364 XL | C45: 3.4747457 | D45: 1.8 | E45: 2.0306522
A46: NZ | B46: 365 S-L | C46: 4.2153864 | D46: 2.15 | E46: 1.9993422
A47: NZ | B47: 365 XL | C47: 3.8495957 | D47: 2 | E47: 2.0365775
A48: NZ | B48: 3655 | C48: 4.6550457 | D48: 2.4 | E48: 2.0210328
A49: NZ | B49: 3666 | C49: 10.671621 | D49: 6.2 | E49: 2.2774423
A50: NZ | B50: 366S | C50: 4.4730941 | D50: 2.6 | E50: 2.2785123
A51: NZ | B51: 3672 | C51: 10.108953 | D51: 6.45 | E51: 2.5011492
...

Sheet מדי 
A1: לקוח | B1: פריט אב | C1: סך עלות | D1: $ | E1: מחיר לאחר 10%בסחורה + 5% כספי | F1: 160951
A2: מדי | B2: 06U | C2: 42.668603 | D2: 20.8 | E2: 17.963636 | F2: 1.4103621
A3: מדי | B3: 077A | C3: 36.852078 | D3: 22.4 | E3: 14 | F3: 1.2726555
A4: מדי | B4: 078 | C4: 24.780153 | D4: 12.5 | E4: 10.795455 | F4: 1.4594249
A5: מדי | B5: K078 | C5: 22.876816 | D5: 12.5 | E5: 10.795455 | F5: 1.5808482
A6: מדי | B6: 07AU | C6: 80.020931 | D6: 40.7 | E6: 35.15 | F6: 1.4715213
A7: מדי | B7: 099 | C7: 35.87145 | D7: 22.3 | E7: 15 | F7: 1.4008355
A8: מדי | B8: 10 | C8: 44.864122 | D8: 25.79 | E8: 22.273182 | F8: 1.6631365
A9: מדי | B9: 11 | C9: 28.087776 | D9: 17.8 | E9: 15.372727 | F9: 1.8334893
A10: מדי | B10: 12 | C10: 63.750814 | D10: 32.2 | E10: 27.809091 | F10: 1.4613218
A11: מדי | B11: 15M | C11: 41.142264 | D11: 17.1 | E11: 14.768182 | F11: 1.202496
A12: מדי | B12: 15W | C12: 36.494703 | D12: 15.75 | E12: 13.602273 | F12: 1.248609
A13: מדי | B13: 20 | C13: 11.241719 | D13: 4.5 | E13: 3.8863636 | F13: 1.1581252
... A41: מדי | B41: 34+ | C41: 19.231895 | D41: 10.45 | E41: 9.025 | F41: 1.5720629
A42: מדי | B42: 35 | C42: 6.6482388 | D42: 3.85 | E42: 3.325 | F42: 1.6754437
A43: מדי | B43: K35 | C43: 6.8383573 | D43: 3.85 | E43: 3.325 | F43: 1.6288634
A44: מדי | B44: 35G | C44: 7.3456572 | D44: 2.9 | E44: 2.5045455 | F44: 1.1422024
A45: מדי | B45: 3611 | C45: 17.795447 | D45: 9.36 | E45: 8.0836364 | F45: 1.5217478
A46: מדי | B46: 362 | C46: 8.7565615 | D46: 4.35 | E46: 3.7568182 | F46: 1.4372469
A47: מדי | B47: 3623 | C47: 8.8779872 | D47: 4.4 | E47: 3.8 | F47: 1.4338836
A48: מדי | B48: 363 | C48: 6.5625268 | D48: 3.89 | E48: 3.3595455 | F48: 1.714961
A49: מדי | B49: 364 S-L | C49: 2.9456457 | D49: 3.28 | E49: 2.8327273 | F49: 3.221581
A50: מדי | B50: 364 XL | C50: 3.4747457 | D50: 1.91 | E50: 1.6495455 | F50: 1.5903256
A51: מדי | B51: 3641 | C51: 4.1400547 | D51: 1.6 | E51: 1.3818182 | F51: 1.1181231
A52: מדי | B52: 365 S-L | C52: 4.2153864 | D52: 2.28 | E52: 1.9690909 | F52: 1.5648517
A53: מדי | B53: 365 XL | C53: 3.8495957 | D53: 1.86 | E53: 1.6063636 | F53: 1.3978918
A54: מדי | B54: 3655 | C54: 4.6550457 | D54: 2.6 | E54: 2.2454545 | F54: 1.6159396
A55: מדי | B55: 3672 | C55: 10.108953 | D55: 5.15 | E55: 4.4477273 | F55: 1.4739297
A56: מדי | B56: 3674 | C56: 5.8353457 | D56: 5.2 | E56: 4.4909091 | F56: 2.5781755
A57: מדי | B57: 3675 | C57: 7.9502588 | D57: 4.1 | E57: 3.5409091 | F57: 1.4920326
A58: מדי | B58: 3677S | C58: 6.3278734 | D58: 3.52 | E58: 3.04 | F58: 1.6093875
A59: מדי | B59: 369 S-L | C59: 5.5410018 | D59: 2.9 | E59: 2.5045455 | F59: 1.5142076
A60: מדי | B60: 369 XL | C60: 6.0035791 | D60: 3.2 | E60: 2.7636364 | F60: 1.5421104
... A68: מדי | B68: 422 | C68: 66.126622 | D68: 25.6 | E68: 22.109091 | F68: 1.120055
A69: מדי | B69: 44 | C69: 125.03101 | D69: 59 | E69: 50.954545 | F69: 1.3652431
A70: מדי | B70: 45E | C70: 7.2093459 | D70: 4.37 | E70: 3.7740909 | F70: 1.7537242
A71: מדי | B71: 45 | C71: 6.7649052 | D71: 3.85 | E71: 3.325 | F71: 1.6465493
A72: מדי | B72: K45 | C72: 6.9550236 | D72: 3.85 | E72: 3.325 | F72: 1.6015402
A73: מדי | B73: 45G | C73: 7.4234347 | D73: 2.9 | E73: 2.5045455 | F73: 1.1302352
A74: מדי | B74: 55 | C74: 24.846822 | D74: 11.8 | E74: 10.190909 | F74: 1.3740005
...

Sheet OUT
A1: לקוח | B1: מספר אייטם | C1: מק''ט מחסן | D1: ONE SIZE | E1: מידה XS | F1: מידה S | G1: מידה M | H1: מידה L | I1: מידה XL | J1: מידה XXL | K1: מידה XXXL | L1: מידה XXXXL | M1: מבצע
A2: עיסא | B2: 99 | C2: 76606B29 | F2: 178
A3: עיסא | B3: 99 | C3: 76606B39 | H3: 510
A4: עיסא | B4: 077A | C4: 78100002 | F4: 200
A5: עיסא | B5: 077A | C5: 78100032 | H5: 300
A6: עיסא | B6: 267C L | C6: 77626722 | F6: 88
A7: עיסא | B7: 267C L | C7: 77626732 | H7: 58
A8: עיסא | B8: 267C L | C8: 77626752 | J8: 22
A9: עיסא | B9: 267B L | C9: 77626729 | F9: 123
A10: עיסא | B10: 267B L | C10: 77626739 | H10: 133
A11: עיסא | B11: 267B L | C11: 77626759 | J11: 71
A12: עיסא | B12: 267C R | C12: 77726722 | F12: 93
A13: עיסא | B13: 267C R | C13: 77726732 | H13: 49
A14: עיסא | B14: 267C R | C14: 77726752 | J14: 108
A15: עיסא | B15: 267B R | C15: 77726729 | F15: 110
A16: עיסא | B16: 267B R | C16: 77726739 | H16: 110
A17: עיסא | B17: 267B R | C17: 77726759 | J17: 75
A18: עיסא | B18: 78AB | C18: 78700069 | K18: 16
A19: עיסא | B19: 78AB | C19: 78700079 | L19: 12
A20: עיסא | B20: 78A | C20: 78700068 | K20: 114
A21: עיסא | B21: 78A | C21: 78700078 | L21: 104
A22: עיסא | B22: 922B | C22: 32900019 | F22: 11
A23: עיסא | B23: 922B | C23: 32900029 | G23: 18
A24: עיסא | B24: 922B | C24: 32900039 | H24: 13
A25: עיסא | B25: 922B | C25: 32900049 | I25: 15
A26: עיסא | B26: 922B | C26: 32900059 | J26: 10
A27: עיסא | B27: 922 | C27: 32900018 | F27: 57
A28: עיסא | B28: 922 | C28: 32900028 | G28: 120
A29: עיסא | B29: 922 | C29: 32900038 | H29: 50
A30: עיסא | B30: 922 | C30: 32900048 | I30: 0
A31: עיסא | B31: 922 | C31: 32900058 | J31: 50
A32: עיסא | B32: 95G | C32: 33000018 | F32: 400
A33: עיסא | B33: 95G | C33: 33000028 | G33: 620
A34: עיסא | B34: 95G | C34: 33000038 | H34: 640
A35: עיסא | B35: 95G | C35: 33000048 | I35: 320
A36: עיסא | B36: 95G | C36: 33000058 | J36: 220
A37: עיסא | B37: 422EB | C37: 31900019 | F37: 18
A38: עיסא | B38: 422EB | C38: 31900029 | G38: 150
A39: עיסא | B39: 422EB | C39: 31900039 | H39: 130
A40: עיסא | B40: 422EB | C40: 31900049 | I40: 90
...

Sheet סיכום מוצרים
A1: סיכום מוצרים - ניו + מדי (כל המוצרים משני הגיליונות, ללא OUT)
A2: תאריך חישוב: | B2: 46313
A3: מקור: גיליונות 'ניו' ו'מדי ' בלבד מתוך מוצרים-מדי-ניו.xlsx (גיליון OUT לא נכלל). התאמה בין המקורות לפי 'פריט אב', התאמה מדויקת.
A5: פריט אב | B5: שייך ל | C5: סך עלות | D5: Euro (ניו) | E5: mu (ניו) | F5: $ (מדי) | G5: מחיר לאחר 10% בסחורה + 5% כספי (מדי) | H5: 160951 (מדי)
A6: 078 | B6: =IF(AND(COUNTIF(ניו!$B:$B,$A6)>0,COUNTIF('מדי '!$B:$B,$A6)>0),"NZ + מדי",IF(COUNTIF(ניו!$B:$B,$A6)>0,"NZ","מדי")) -> NZ + מדי | C6: =IFERROR(INDEX(ניו!$C:$C,MATCH($A6,ניו!$B:$B,0)),IFERROR(INDEX('מדי '!$C:$C,MATCH($A6,'מדי '!$B:$B,0)),"")) -> 24.780153 | D6: =IFERROR(INDEX(ניו!$D:$D,MATCH($A6,ניו!$B:$B,0)),"") -> 16.5 | E6: =IFERROR(INDEX(ניו!$E:$E,MATCH($A6,ניו!$B:$B,0)),"") -> 2.6101534 | F6: =IFERROR(INDEX('מדי '!$D:$D,MATCH($A6,'מדי '!$B:$B,0)),"") -> 12.5 | G6: =IFERROR(INDEX('מדי '!$E:$E,MATCH($A6,'מדי '!$B:$B,0)),"") -> 10.795455 | H6: =IFERROR(INDEX('מדי '!$F:$F,MATCH($A6,'מדי '!$B:$B,0)),"") -> 1.4594249
A7: 078G | B7: =IF(AND(COUNTIF(ניו!$B:$B,$A7)>0,COUNTIF('מדי '!$B:$B,$A7)>0),"NZ + מדי",IF(COUNTIF(ניו!$B:$B,$A7)>0,"NZ","מדי")) -> NZ | C7: =IFERROR(INDEX(ניו!$C:$C,MATCH($A7,ניו!$B:$B,0)),IFERROR(INDEX('מדי '!$C:$C,MATCH($A7,'מדי '!$B:$B,0)),"")) -> 28.763394 | D7: =IFERROR(INDEX(ניו!$D:$D,MATCH($A7,ניו!$B:$B,0)),"") -> 16.5 | E7: =IFERROR(INDEX(ניו!$E:$E,MATCH($A7,ניו!$B:$B,0)),"") -> 2.2486915 | F7: =IFERROR(INDEX('מדי '!$D:$D,MATCH($A7,'מדי '!$B:$B,0)),"") | G7: =IFERROR(INDEX('מדי '!$E:$E,MATCH($A7,'מדי '!$B:$B,0)),"") | H7: =IFERROR(INDEX('מדי '!$F:$F,MATCH($A7,'מדי '!$B:$B,0)),"")
A8: 07AU | B8: =IF(AND(COUNTIF(ניו!$B:$B,$A8)>0,COUNTIF('מדי '!$B:$B,$A8)>0),"NZ + מדי",IF(COUNTIF(ניו!$B:$B,$A8)>0,"NZ","מדי")) -> NZ + מדי | C8: =IFERROR(INDEX(ניו!$C:$C,MATCH($A8,ניו!$B:$B,0)),IFERROR(INDEX('מדי '!$C:$C,MATCH($A8,'מדי '!$B:$B,0)),"")) -> 80.020931 | D8: =IFERROR(INDEX(ניו!$D:$D,MATCH($A8,ניו!$B:$B,0)),"") -> 38.75 | E8: =IFERROR(INDEX(ניו!$E:$E,MATCH($A8,ניו!$B:$B,0)),"") -> 1.8982534 | F8: =IFERROR(INDEX('מדי '!$D:$D,MATCH($A8,'מדי '!$B:$B,0)),"") -> 40.7 | G8: =IFERROR(INDEX('מדי '!$E:$E,MATCH($A8,'מדי '!$B:$B,0)),"") -> 35.15 | H8: =IFERROR(INDEX('מדי '!$F:$F,MATCH($A8,'מדי '!$B:$B,0)),"") -> 1.4715213
A9: 11STO | B9: =IF(AND(COUNTIF(ניו!$B:$B,$A9)>0,COUNTIF('מדי '!$B:$B,$A9)>0),"NZ + מדי",IF(COUNTIF(ניו!$B:$B,$A9)>0,"NZ","מדי")) -> NZ | C9: =IFERROR(INDEX(ניו!$C:$C,MATCH($A9,ניו!$B:$B,0)),IFERROR(INDEX('מדי '!$C:$C,MATCH($A9,'מדי '!$B:$B,0)),"")) -> 27.751475 | D9: =IFERROR(INDEX(ניו!$D:$D,MATCH($A9,ניו!$B:$B,0)),"") -> 22.5 | E9: =IFERROR(INDEX(ניו!$E:$E,MATCH($A9,ניו!$B:$B,0)),"") -> 3.1782094 | F9: =IFERROR(INDEX('מדי '!$D:$D,MATCH($A9,'מדי '!$B:$B,0)),"") | G9: =IFERROR(INDEX('מדי '!$E:$E,MATCH($A9,'מדי '!$B:$B,0)),"") | H9: =IFERROR(INDEX('מדי '!$F:$F,MATCH($A9,'מדי '!$B:$B,0)),"")
A10: 11TO | B10: =IF(AND(COUNTIF(ניו!$B:$B,$A10)>0,COUNTIF('מדי '!$B:$B,$A10)>0),"NZ + מדי",IF(COUNTIF(ניו!$B:$B,$A10)>0,"NZ","מדי")) -> NZ | C10: =IFERROR(INDEX(ניו!$C:$C,MATCH($A10,ניו!$B:$B,0)),IFERROR(INDEX('מדי '!$C:$C,MATCH($A10,'מדי '!$B:$B,0)),"")) -> 39.612447 | D10: =IFERROR(INDEX(ניו!$D:$D,MATCH($A10,ניו!$B:$B,0)),"") -> 21.85 | E10: =IFERROR(INDEX(ניו!$E:$E,MATCH($A10,ניו!$B:$B,0)),"") -> 2.1622497 | F10: =IFERROR(INDEX('מדי '!$D:$D,MATCH($A10,'מדי '!$B:$B,0)),"") | G10: =IFERROR(INDEX('מדי '!$E:$E,MATCH($A10,'מדי '!$B:$B,0)),"") | H10: =IFERROR(INDEX('מדי '!$F:$F,MATCH($A10,'מדי '!$B:$B,0)),"")
A11: 13 | B11: =IF(AND(COUNTIF(ניו!$B:$B,$A11)>0,COUNTIF('מדי '!$B:$B,$A11)>0),"NZ + מדי",IF(COUNTIF(ניו!$B:$B,$A11)>0,"NZ","מדי")) -> NZ | C11: =IFERROR(INDEX(ניו!$C:$C,MATCH($A11,ניו!$B:$B,0)),IFERROR(INDEX('מדי '!$C:$C,MATCH($A11,'מדי '!$B:$B,0)),"")) -> 41.645439 | D11: =IFERROR(INDEX(ניו!$D:$D,MATCH($A11,ניו!$B:$B,0)),"") -> 21.8 | E11: =IFERROR(INDEX(ניו!$E:$E,MATCH($A11,ניו!$B:$B,0)),"") -> 2.0519894 | F11: =IFERROR(INDEX('מדי '!$D:$D,MATCH($A11,'מדי '!$B:$B,0)),"") | G11: =IFERROR(INDEX('מדי '!$E:$E,MATCH($A11,'מדי '!$B:$B,0)),"") | H11: =IFERROR(INDEX('מדי '!$F:$F,MATCH($A11,'מדי '!$B:$B,0)),"")
A12: 14 | B12: =IF(AND(COUNTIF(ניו!$B:$B,$A12)>0,COUNTIF('מדי '!$B:$B,$A12)>0),"NZ + מדי",IF(COUNTIF(ניו!$B:$B,$A12)>0,"NZ","מדי")) -> NZ | C12: =IFERROR(INDEX(ניו!$C:$C,MATCH($A12,ניו!$B:$B,0)),IFERROR(INDEX('מדי '!$C:$C,MATCH($A12,'מדי '!$B:$B,0)),"")) -> 62.103423 | D12: =IFERROR(INDEX(ניו!$D:$D,MATCH($A12,ניו!$B:$B,0)),"") -> 29.95 | E12: =IFERROR(INDEX(ניו!$E:$E,MATCH($A12,ניו!$B:$B,0)),"") -> 1.8904594 | F12: =IFERROR(INDEX('מדי '!$D:$D,MATCH($A12,'מדי '!$B:$B,0)),"") | G12: =IFERROR(INDEX('מדי '!$E:$E,MATCH($A12,'מדי '!$B:$B,0)),"") | H12: =IFERROR(INDEX('מדי '!$F:$F,MATCH($A12,'מדי '!$B:$B,0)),"")
A13: 15M | B13: =IF(AND(COUNTIF(ניו!$B:$B,$A13)>0,COUNTIF('מדי '!$B:$B,$A13)>0),"NZ + מדי",IF(COUNTIF(ניו!$B:$B,$A13)>0,"NZ","מדי")) -> NZ + מדי | C13: =IFERROR(INDEX(ניו!$C:$C,MATCH($A13,ניו!$B:$B,0)),IFERROR(INDEX('מדי '!$C:$C,MATCH($A13,'מדי '!$B:$B,0)),"")) -> 41.142264 | D13: =IFERROR(INDEX(ניו!$D:$D,MATCH($A13,ניו!$B:$B,0)),"") -> 19.95 | E13: =IFERROR(INDEX(ניו!$E:$E,MATCH($A13,ניו!$B:$B,0)),"") -> 1.9008191 | F13: =IFERROR(INDEX('מדי '!$D:$D,MATCH($A13,'מדי '!$B:$B,0)),"") -> 17.1 | G13: =IFERROR(INDEX('מדי '!$E:$E,MATCH($A13,'מדי '!$B:$B,0)),"") -> 14.768182 | H13: =IFERROR(INDEX('מדי '!$F:$F,MATCH($A13,'מדי '!$B:$B,0)),"") -> 1.202496
A14: 15W | B14: =IF(AND(COUNTIF(ניו!$B:$B,$A14)>0,COUNTIF('מדי '!$B:$B,$A14)>0),"NZ + מדי",IF(COUNTIF(ניו!$B:$B,$A14)>0,"NZ","מדי")) -> NZ + מדי | C14: =IFERROR(INDEX(ניו!$C:$C,MATCH($A14,ניו!$B:$B,0)),IFERROR(INDEX('מדי '!$C:$C,MATCH($A14,'מדי '!$B:$B,0)),"")) -> 36.494703 | D14: =IFERROR(INDEX(ניו!$D:$D,MATCH($A14,ניו!$B:$B,0)),"") -> 18.9 | E14: =IFERROR(INDEX(ניו!$E:$E,MATCH($A14,ניו!$B:$B,0)),"") -> 2.0301028 | F14: =IFERROR(INDEX('מדי '!$D:$D,MATCH($A14,'מדי '!$B:$B,0)),"") -> 15.75 | G14: =IFERROR(INDEX('מדי '!$E:$E,MATCH($A14,'מדי '!$B:$B,0)),"") -> 13.602273 | H14: =IFERROR(INDEX('מדי '!$F:$F,MATCH($A14,'מדי '!$B:$B,0)),"") -> 1.248609
A15: 16 | B15: =IF(AND(COUNTIF(ניו!$B:$B,$A15)>0,COUNTIF('מדי '!$B:$B,$A15)>0),"NZ + מדי",IF(COUNTIF(ניו!$B:$B,$A15)>0,"NZ","מדי")) -> NZ | C15: =IFERROR(INDEX(ניו!$C:$C,MATCH($A15,ניו!$B:$B,0)),IFERROR(INDEX('מדי '!$C:$C,MATCH($A15,'מדי '!$B:$B,0)),"")) -> 32.401747 | D15: =IFERROR(INDEX(ניו!$D:$D,MATCH($A15,ניו!$B:$B,0)),"") -> 16.8 | E15: =IFERROR(INDEX(ניו!$E:$E,MATCH($A15,ניו!$B:$B,0)),"") -> 2.032483 | F15: =IFERROR(INDEX('מדי '!$D:$D,MATCH($A15,'מדי '!$B:$B,0)),"") | G15: =IFERROR(INDEX('מדי '!$E:$E,MATCH($A15,'מדי '!$B:$B,0)),"") | H15: =IFERROR(INDEX('מדי '!$F:$F,MATCH($A15,'מדי '!$B:$B,0)),"")
A16: 21 | B16: =IF(AND(COUNTIF(ניו!$B:$B,$A16)>0,COUNTIF('מדי '!$B:$B,$A16)>0),"NZ + מדי",IF(COUNTIF(ניו!$B:$B,$A16)>0,"NZ","מדי")) -> NZ + מדי | C16: =IFERROR(INDEX(ניו!$C:$C,MATCH($A16,ניו!$B:$B,0)),IFERROR(INDEX('מדי '!$C:$C,MATCH($A16,'מדי '!$B:$B,0)),"")) -> 10.742199 | D16: =IFERROR(INDEX(ניו!$D:$D,MATCH($A16,ניו!$B:$B,0)),"") -> 5.5 | E16: =IFERROR(INDEX(ניו!$E:$E,MATCH($A16,ניו!$B:$B,0)),"") -> 2.0070379 | F16: =IFERROR(INDEX('מדי '!$D:$D,MATCH($A16,'מדי '!$B:$B,0)),"") -> 5.73 | G16: =IFERROR(INDEX('מדי '!$E:$E,MATCH($A16,'מדי '!$B:$B,0)),"") -> 4.9486364 | H16: =IFERROR(INDEX('מדי '!$F:$F,MATCH($A16,'מדי '!$B:$B,0)),"") -> 1.5432532
A17: 211 | B17: =IF(AND(COUNTIF(ניו!$B:$B,$A17)>0,COUNTIF('מדי '!$B:$B,$A17)>0),"NZ + מדי",IF(COUNTIF(ניו!$B:$B,$A17)>0,"NZ","מדי")) -> NZ | C17: =IFERROR(INDEX(ניו!$C:$C,MATCH($A17,ניו!$B:$B,0)),IFERROR(INDEX('מדי '!$C:$C,MATCH($A17,'מדי '!$B:$B,0)),"")) -> 9.7558581 | D17: =IFERROR(INDEX(ניו!$D:$D,MATCH($A17,ניו!$B:$B,0)),"") -> 5.65 | E17: =IFERROR(INDEX(ניו!$E:$E,MATCH($A17,ניו!$B:$B,0)),"") -> 2.2702257 | F17: =IFERROR(INDEX('מדי '!$D:$D,MATCH($A17,'מדי '!$B:$B,0)),"") | G17: =IFERROR(INDEX('מדי '!$E:$E,MATCH($A17,'מדי '!$B:$B,0)),"") | H17: =IFERROR(INDEX('מדי '!$F:$F,MATCH($A17,'מדי '!$B:$B,0)),"")
A18: 212 | B18: =IF(AND(COUNTIF(ניו!$B:$B,$A18)>0,COUNTIF('מדי '!$B:$B,$A18)>0),"NZ + מדי",IF(COUNTIF(ניו!$B:$B,$A18)>0,"NZ","מדי")) -> NZ | C18: =IFERROR(INDEX(ניו!$C:$C,MATCH($A18,ניו!$B:$B,0)),IFERROR(INDEX('מדי '!$C:$C,MATCH($A18,'מדי '!$B:$B,0)),"")) -> 10.064243 | D18: =IFERROR(INDEX(ניו!$D:$D,MATCH($A18,ניו!$B:$B,0)),"") -> 5.85 | E18: =IFERROR(INDEX(ניו!$E:$E,MATCH($A18,ניו!$B:$B,0)),"") -> 2.2785618 | F18: =IFERROR(INDEX('מדי '!$D:$D,MATCH($A18,'מדי '!$B:$B,0)),"") | G18: =IFERROR(INDEX('מדי '!$E:$E,MATCH($A18,'מדי '!$B:$B,0)),"") | H18: =IFERROR(INDEX('מדי '!$F:$F,MATCH($A18,'מדי '!$B:$B,0)),"")
A19: 237 | B19: =IF(AND(COUNTIF(ניו!$B:$B,$A19)>0,COUNTIF('מדי '!$B:$B,$A19)>0),"NZ + מדי",IF(COUNTIF(ניו!$B:$B,$A19)>0,"NZ","מדי")) -> NZ | C19: =IFERROR(INDEX(ניו!$C:$C,MATCH($A19,ניו!$B:$B,0)),IFERROR(INDEX('מדי '!$C:$C,MATCH($A19,'מדי '!$B:$B,0)),"")) -> 7.9041891 | D19: =IFERROR(INDEX(ניו!$D:$D,MATCH($A19,ניו!$B:$B,0)),"") -> 4.65 | E19: =IFERROR(INDEX(ניו!$E:$E,MATCH($A19,ניו!$B:$B,0)),"") -> 2.3061189 | F19: =IFERROR(INDEX('מדי '!$D:$D,MATCH($A19,'מדי '!$B:$B,0)),"") | G19: =IFERROR(INDEX('מדי '!$E:$E,MATCH($A19,'מדי '!$B:$B,0)),"") | H19: =IFERROR(INDEX('מדי '!$F:$F,MATCH($A19,'מדי '!$B:$B,0)),"")
A20: 238 | B20: =IF(AND(COUNTIF(ניו!$B:$B,$A20)>0,COUNTIF('מדי '!$B:$B,$A20)>0),"NZ + מדי",IF(COUNTIF(ניו!$B:$B,$A20)>0,"NZ","מדי")) -> NZ + מדי | C20: =IFERROR(INDEX(ניו!$C:$C,MATCH($A20,ניו!$B:$B,0)),IFERROR(INDEX('מדי '!$C:$C,MATCH($A20,'מדי '!$B:$B,0)),"")) -> 5.1708301 | D20: =IFERROR(INDEX(ניו!$D:$D,MATCH($A20,ניו!$B:$B,0)),"") -> 2.8 | E20: =IFERROR(INDEX(ניו!$E:$E,MATCH($A20,ניו!$B:$B,0)),"") -> 2.1226766 | F20: =IFERROR(INDEX('מדי '!$D:$D,MATCH($A20,'מדי '!$B:$B,0)),"") -> 2.6 | G20: =IFERROR(INDEX('מדי '!$E:$E,MATCH($A20,'מדי '!$B:$B,0)),"") -> 2.2454545 | H20: =IFERROR(INDEX('מדי '!$F:$F,MATCH($A20,'מדי '!$B:$B,0)),"") -> 1.4547515
A21: 239 | B21: =IF(AND(COUNTIF(ניו!$B:$B,$A21)>0,COUNTIF('מדי '!$B:$B,$A21)>0),"NZ + מדי",IF(COUNTIF(ניו!$B:$B,$A21)>0,"NZ","מדי")) -> NZ | C21: =IFERROR(INDEX(ניו!$C:$C,MATCH($A21,ניו!$B:$B,0)),IFERROR(INDEX('מדי '!$C:$C,MATCH($A21,'מדי '!$B:$B,0)),"")) -> 5.3603825 | D21: =IFERROR(INDEX(ניו!$D:$D,MATCH($A21,ניו!$B:$B,0)),"") -> 3.25 | E21: =IFERROR(INDEX(ניו!$E:$E,MATCH($A21,ניו!$B:$B,0)),"") -> 2.3766961 | F21: =IFERROR(INDEX('מדי '!$D:$D,MATCH($A21,'מדי '!$B:$B,0)),"") | G21: =IFERROR(INDEX('מדי '!$E:$E,MATCH($A21,'מדי '!$B:$B,0)),"") | H21: =IFERROR(INDEX('מדי '!$F:$F,MATCH($A21,'מדי '!$B:$B,0)),"")
A22: 250 | B22: =IF(AND(COUNTIF(ניו!$B:$B,$A22)>0,COUNTIF('מדי '!$B:$B,$A22)>0),"NZ + מדי",IF(COUNTIF(ניו!$B:$B,$A22)>0,"NZ","מדי")) -> NZ | C22: =IFERROR(INDEX(ניו!$C:$C,MATCH($A22,ניו!$B:$B,0)),IFERROR(INDEX('מדי '!$C:$C,MATCH($A22,'מדי '!$B:$B,0)),"")) -> 14.074193 | D22: =IFERROR(INDEX(ניו!$D:$D,MATCH($A22,ניו!$B:$B,0)),"") -> 6.6 | E22: =IFERROR(INDEX(ניו!$E:$E,MATCH($A22,ניו!$B:$B,0)),"") -> 1.8382582 | F22: =IFERROR(INDEX('מדי '!$D:$D,MATCH($A22,'מדי '!$B:$B,0)),"") | G22: =IFERROR(INDEX('מדי '!$E:$E,MATCH($A22,'מדי '!$B:$B,0)),"") | H22: =IFERROR(INDEX('מדי '!$F:$F,MATCH($A22,'מדי '!$B:$B,0)),"")
A23: 251 | B23: =IF(AND(COUNTIF(ניו!$B:$B,$A23)>0,COUNTIF('מדי '!$B:$B,$A23)>0),"NZ + מדי",IF(COUNTIF(ניו!$B:$B,$A23)>0,"NZ","מדי")) -> NZ | C23: =IFERROR(INDEX(ניו!$C:$C,MATCH($A23,ניו!$B:$B,0)),IFERROR(INDEX('מדי '!$C:$C,MATCH($A23,'מדי '!$B:$B,0)),"")) -> 13.981992 | D23: =IFERROR(INDEX(ניו!$D:$D,MATCH($A23,ניו!$B:$B,0)),"") -> 7.5 | E23: =IFERROR(INDEX(ניו!$E:$E,MATCH($A23,ניו!$B:$B,0)),"") -> 2.1027046 | F23: =IFERROR(INDEX('מדי '!$D:$D,MATCH($A23,'מדי '!$B:$B,0)),"") | G23: =IFERROR(INDEX('מדי '!$E:$E,MATCH($A23,'מדי '!$B:$B,0)),"") | H23: =IFERROR(INDEX('מדי '!$F:$F,MATCH($A23,'מדי '!$B:$B,0)),"")
A24: 26 | B24: =IF(AND(COUNTIF(ניו!$B:$B,$A24)>0,COUNTIF('מדי '!$B:$B,$A24)>0),"NZ + מדי",IF(COUNTIF(ניו!$B:$B,$A24)>0,"NZ","מדי")) -> NZ + מדי | C24: =IFERROR(INDEX(ניו!$C:$C,MATCH($A24,ניו!$B:$B,0)),IFERROR(INDEX('מדי '!$C:$C,MATCH($A24,'מדי '!$B:$B,0)),"")) -> 32.879937 | D24: =IFERROR(INDEX(ניו!$D:$D,MATCH($A24,ניו!$B:$B,0)),"") -> 16.5 | E24: =IFERROR(INDEX(ניו!$E:$E,MATCH($A24,ניו!$B:$B,0)),"") -> 1.9671571 | F24: =IFERROR(INDEX('מדי '!$D:$D,MATCH($A24,'מדי '!$B:$B,0)),"") -> 15.55 | G24: =IFERROR(INDEX('מדי '!$E:$E,MATCH($A24,'מדי '!$B:$B,0)),"") -> 13.429545 | H24: =IFERROR(INDEX('מדי '!$F:$F,MATCH($A24,'מדי '!$B:$B,0)),"") -> 1.3682805
A25: 266 | B25: =IF(AND(COUNTIF(ניו!$B:$B,$A25)>0,COUNTIF('מדי '!$B:$B,$A25)>0),"NZ + מדי",IF(COUNTIF(ניו!$B:$B,$A25)>0,"NZ","מדי")) -> NZ + מדי | C25: =IFERROR(INDEX(ניו!$C:$C,MATCH($A25,ניו!$B:$B,0)),IFERROR(INDEX('מדי '!$C:$C,MATCH($A25,'מדי '!$B:$B,0)),"")) -> 12.43339 | D25: =IFERROR(INDEX(ניו!$D:$D,MATCH($A25,ניו!$B:$B,0)),"") -> 6.3 | E25: =IFERROR(INDEX(ניו!$E:$E,MATCH($A25,ניו!$B:$B,0)),"") -> 1.9862643 | F25: =IFERROR(INDEX('מדי '!$D:$D,MATCH($A25,'מדי '!$B:$B,0)),"") -> 8.2 | G25: =IFERROR(INDEX('מדי '!$E:$E,MATCH($A25,'מדי '!$B:$B,0)),"") -> 7.0818182 | H25: =IFERROR(INDEX('מדי '!$F:$F,MATCH($A25,'מדי '!$B:$B,0)),"") -> 1.9080951
A26: 268 | B26: =IF(AND(COUNTIF(ניו!$B:$B,$A26)>0,COUNTIF('מדי '!$B:$B,$A26)>0),"NZ + מדי",IF(COUNTIF(ניו!$B:$B,$A26)>0,"NZ","מדי")) -> NZ + מדי | C26: =IFERROR(INDEX(ניו!$C:$C,MATCH($A26,ניו!$B:$B,0)),IFERROR(INDEX('מדי '!$C:$C,MATCH($A26,'מדי '!$B:$B,0)),"")) -> 19.771523 | D26: =IFERROR(INDEX(ניו!$D:$D,MATCH($A26,ניו!$B:$B,0)),"") -> 9.75 | E26: =IFERROR(INDEX(ניו!$E:$E,MATCH($A26,ניו!$B:$B,0)),"") -> 1.9330832 | F26: =IFERROR(INDEX('מדי '!$D:$D,MATCH($A26,'מדי '!$B:$B,0)),"") -> 11.7 | G26: =IFERROR(INDEX('מדי '!$E:$E,MATCH($A26,'מדי '!$B:$B,0)),"") -> 10.104545 | H26: =IFERROR(INDEX('מדי '!$F:$F,MATCH($A26,'מדי '!$B:$B,0)),"") -> 1.7120698
A27: 302M | B27: =IF(AND(COUNTIF(ניו!$B:$B,$A27)>0,COUNTIF('מדי '!$B:$B,$A27)>0),"NZ + מדי",IF(COUNTIF(ניו!$B:$B,$A27)>0,"NZ","מדי")) -> NZ + מדי | C27: =IFERROR(INDEX(ניו!$C:$C,MATCH($A27,ניו!$B:$B,0)),IFERROR(INDEX('מדי '!$C:$C,MATCH($A27,'מדי '!$B:$B,0)),"")) -> 16.673415 | D27: =IFERROR(INDEX(ניו!$D:$D,MATCH($A27,ניו!$B:$B,0)),"") -> 9.1 | E27: =IFERROR(INDEX(ניו!$E:$E,MATCH($A27,ניו!$B:$B,0)),"") -> 2.1394537 | F27: =IFERROR(INDEX('מדי '!$D:$D,MATCH($A27,'מדי '!$B:$B,0)),"") -> 8.5 | G27: =IFERROR(INDEX('מדי '!$E:$E,MATCH($A27,'מדי '!$B:$B,0)),"") -> 7.3409091 | H27: =IFERROR(INDEX('מדי '!$F:$F,MATCH($A27,'מדי '!$B:$B,0)),"") -> 1.4749255
... A39: 351 | B39: =IF(AND(COUNTIF(ניו!$B:$B,$A39)>0,COUNTIF('מדי '!$B:$B,$A39)>0),"NZ + מדי",IF(COUNTIF(ניו!$B:$B,$A39)>0,"NZ","מדי")) -> NZ | C39: =IFERROR(INDEX(ניו!$C:$C,MATCH($A39,ניו!$B:$B,0)),IFERROR(INDEX('מדי '!$C:$C,MATCH($A39,'מדי '!$B:$B,0)),"")) -> 17.432062 | D39: =IFERROR(INDEX(ניו!$D:$D,MATCH($A39,ניו!$B:$B,0)),"") -> 9.15 | E39: =IFERROR(INDEX(ניו!$E:$E,MATCH($A39,ניו!$B:$B,0)),"") -> 2.0575879 | F39: =IFERROR(INDEX('מדי '!$D:$D,MATCH($A39,'מדי '!$B:$B,0)),"") | G39: =IFERROR(INDEX('מדי '!$E:$E,MATCH($A39,'מדי '!$B:$B,0)),"") | H39: =IFERROR(INDEX('מדי '!$F:$F,MATCH($A39,'מדי '!$B:$B,0)),"")
A40: 35 | B40: =IF(AND(COUNTIF(ניו!$B:$B,$A40)>0,COUNTIF('מדי '!$B:$B,$A40)>0),"NZ + מדי",IF(COUNTIF(ניו!$B:$B,$A40)>0,"NZ","מדי")) -> NZ + מדי | C40: =IFERROR(INDEX(ניו!$C:$C,MATCH($A40,ניו!$B:$B,0)),IFERROR(INDEX('מדי '!$C:$C,MATCH($A40,'מדי '!$B:$B,0)),"")) -> 6.6482388 | D40: =IFERROR(INDEX(ניו!$D:$D,MATCH($A40,ניו!$B:$B,0)),"") -> 3.55 | E40: =IFERROR(INDEX(ניו!$E:$E,MATCH($A40,ניו!$B:$B,0)),"") -> 2.0931859 | F40: =IFERROR(INDEX('מדי '!$D:$D,MATCH($A40,'מדי '!$B:$B,0)),"") -> 3.85 | G40: =IFERROR(INDEX('מדי '!$E:$E,MATCH($A40,'מדי '!$B:$B,0)),"") -> 3.325 | H40: =IFERROR(INDEX('מדי '!$F:$F,MATCH($A40,'מדי '!$B:$B,0)),"") -> 1.6754437
A41: 35B | B41: =IF(AND(COUNTIF(ניו!$B:$B,$A41)>0,COUNTIF('מדי '!$B:$B,$A41)>0),"NZ + מדי",IF(COUNTIF(ניו!$B:$B,$A41)>0,"NZ","מדי")) -> NZ | C41: =IFERROR(INDEX(ניו!$C:$C,MATCH($A41,ניו!$B:$B,0)),IFERROR(INDEX('מדי '!$C:$C,MATCH($A41,'מדי '!$B:$B,0)),"")) -> 6.8426828 | D41: =IFERROR(INDEX(ניו!$D:$D,MATCH($A41,ניו!$B:$B,0)),"") -> 3.55 | E41: =IFERROR(INDEX(ניו!$E:$E,MATCH($A41,ניו!$B:$B,0)),"") -> 2.0337053 | F41: =IFERROR(INDEX('מדי '!$D:$D,MATCH($A41,'מדי '!$B:$B,0)),"") | G41: =IFERROR(INDEX('מדי '!$E:$E,MATCH($A41,'מדי '!$B:$B,0)),"") | H41: =IFERROR(INDEX('מדי '!$F:$F,MATCH($A41,'מדי '!$B:$B,0)),"")
A42: 35C | B42: =IF(AND(COUNTIF(ניו!$B:$B,$A42)>0,COUNTIF('מדי '!$B:$B,$A42)>0),"NZ + מדי",IF(COUNTIF(ניו!$B:$B,$A42)>0,"NZ","מדי")) -> NZ | C42: =IFERROR(INDEX(ניו!$C:$C,MATCH($A42,ניו!$B:$B,0)),IFERROR(INDEX('מדי '!$C:$C,MATCH($A42,'מדי '!$B:$B,0)),"")) -> 6.8426828 | D42: =IFERROR(INDEX(ניו!$D:$D,MATCH($A42,ניו!$B:$B,0)),"") -> 3.55 | E42: =IFERROR(INDEX(ניו!$E:$E,MATCH($A42,ניו!$B:$B,0)),"") -> 2.0337053 | F42: =IFERROR(INDEX('מדי '!$D:$D,MATCH($A42,'מדי '!$B:$B,0)),"") | G42: =IFERROR(INDEX('מדי '!$E:$E,MATCH($A42,'מדי '!$B:$B,0)),"") | H42: =IFERROR(INDEX('מדי '!$F:$F,MATCH($A42,'מדי '!$B:$B,0)),"")
A43: 3611 | B43: =IF(AND(COUNTIF(ניו!$B:$B,$A43)>0,COUNTIF('מדי '!$B:$B,$A43)>0),"NZ + מדי",IF(COUNTIF(ניו!$B:$B,$A43)>0,"NZ","מדי")) -> NZ + מדי | C43: =IFERROR(INDEX(ניו!$C:$C,MATCH($A43,ניו!$B:$B,0)),IFERROR(INDEX('מדי '!$C:$C,MATCH($A43,'מדי '!$B:$B,0)),"")) -> 17.795447 | D43: =IFERROR(INDEX(ניו!$D:$D,MATCH($A43,ניו!$B:$B,0)),"") -> 9.1 | E43: =IFERROR(INDEX(ניו!$E:$E,MATCH($A43,ניו!$B:$B,0)),"") -> 2.0045577 | F43: =IFERROR(INDEX('מדי '!$D:$D,MATCH($A43,'מדי '!$B:$B,0)),"") -> 9.36 | G43: =IFERROR(INDEX('מדי '!$E:$E,MATCH($A43,'מדי '!$B:$B,0)),"") -> 8.0836364 | H43: =IFERROR(INDEX('מדי '!$F:$F,MATCH($A43,'מדי '!$B:$B,0)),"") -> 1.5217478
A44: 362 | B44: =IF(AND(COUNTIF(ניו!$B:$B,$A44)>0,COUNTIF('מדי '!$B:$B,$A44)>0),"NZ + מדי",IF(COUNTIF(ניו!$B:$B,$A44)>0,"NZ","מדי")) -> NZ + מדי | C44: =IFERROR(INDEX(ניו!$C:$C,MATCH($A44,ניו!$B:$B,0)),IFERROR(INDEX('מדי '!$C:$C,MATCH($A44,'מדי '!$B:$B,0)),"")) -> 8.7565615 | D44: =IFERROR(INDEX(ניו!$D:$D,MATCH($A44,ניו!$B:$B,0)),"") -> 4.9 | E44: =IFERROR(INDEX(ניו!$E:$E,MATCH($A44,ניו!$B:$B,0)),"") -> 2.1935551 | F44: =IFERROR(INDEX('מדי '!$D:$D,MATCH($A44,'מדי '!$B:$B,0)),"") -> 4.35 | G44: =IFERROR(INDEX('מדי '!$E:$E,MATCH($A44,'מדי '!$B:$B,0)),"") -> 3.7568182 | H44: =IFERROR(INDEX('מדי '!$F:$F,MATCH($A44,'מדי '!$B:$B,0)),"") -> 1.4372469
A45: 3622S | B45: =IF(AND(COUNTIF(ניו!$B:$B,$A45)>0,COUNTIF('מדי '!$B:$B,$A45)>0),"NZ + מדי",IF(COUNTIF(ניו!$B:$B,$A45)>0,"NZ","מדי")) -> NZ | C45: =IFERROR(INDEX(ניו!$C:$C,MATCH($A45,ניו!$B:$B,0)),IFERROR(INDEX('מדי '!$C:$C,MATCH($A45,'מדי '!$B:$B,0)),"")) -> 9.4336352 | D45: =IFERROR(INDEX(ניו!$D:$D,MATCH($A45,ניו!$B:$B,0)),"") -> 5.45 | E45: =IFERROR(INDEX(ניו!$E:$E,MATCH($A45,ניו!$B:$B,0)),"") -> 2.2646625 | F45: =IFERROR(INDEX('מדי '!$D:$D,MATCH($A45,'מדי '!$B:$B,0)),"") | G45: =IFERROR(INDEX('מדי '!$E:$E,MATCH($A45,'מדי '!$B:$B,0)),"") | H45: =IFERROR(INDEX('מדי '!$F:$F,MATCH($A45,'מדי '!$B:$B,0)),"")
A46: 3623 | B46: =IF(AND(COUNTIF(ניו!$B:$B,$A46)>0,COUNTIF('מדי '!$B:$B,$A46)>0),"NZ + מדי",IF(COUNTIF(ניו!$B:$B,$A46)>0,"NZ","מדי")) -> NZ + מדי | C46: =IFERROR(INDEX(ניו!$C:$C,MATCH($A46,ניו!$B:$B,0)),IFERROR(INDEX('מדי '!$C:$C,MATCH($A46,'מדי '!$B:$B,0)),"")) -> 8.8779872 | D46: =IFERROR(INDEX(ניו!$D:$D,MATCH($A46,ניו!$B:$B,0)),"") -> 5.1 | E46: =IFERROR(INDEX(ניו!$E:$E,MATCH($A46,ניו!$B:$B,0)),"") -> 2.2518618 | F46: =IFERROR(INDEX('מדי '!$D:$D,MATCH($A46,'מדי '!$B:$B,0)),"") -> 4.4 | G46: =IFERROR(INDEX('מדי '!$E:$E,MATCH($A46,'מדי '!$B:$B,0)),"") -> 3.8 | H46: =IFERROR(INDEX('מדי '!$F:$F,MATCH($A46,'מדי '!$B:$B,0)),"") -> 1.4338836
A47: 363 | B47: =IF(AND(COUNTIF(ניו!$B:$B,$A47)>0,COUNTIF('מדי '!$B:$B,$A47)>0),"NZ + מדי",IF(COUNTIF(ניו!$B:$B,$A47)>0,"NZ","מדי")) -> NZ + מדי | C47: =IFERROR(INDEX(ניו!$C:$C,MATCH($A47,ניו!$B:$B,0)),IFERROR(INDEX('מדי '!$C:$C,MATCH($A47,'מדי '!$B:$B,0)),"")) -> 6.5625268 | D47: =IFERROR(INDEX(ניו!$D:$D,MATCH($A47,ניו!$B:$B,0)),"") -> 3.65 | E47: =IFERROR(INDEX(ניו!$E:$E,MATCH($A47,ניו!$B:$B,0)),"") -> 2.1802578 | F47: =IFERROR(INDEX('מדי '!$D:$D,MATCH($A47,'מדי '!$B:$B,0)),"") -> 3.89 | G47: =IFERROR(INDEX('מדי '!$E:$E,MATCH($A47,'מדי '!$B:$B,0)),"") -> 3.3595455 | H47: =IFERROR(INDEX('מדי '!$F:$F,MATCH($A47,'מדי '!$B:$B,0)),"") -> 1.714961
A48: 364 S-L | B48: =IF(AND(COUNTIF(ניו!$B:$B,$A48)>0,COUNTIF('מדי '!$B:$B,$A48)>0),"NZ + מדי",IF(COUNTIF(ניו!$B:$B,$A48)>0,"NZ","מדי")) -> NZ + מדי | C48: =IFERROR(INDEX(ניו!$C:$C,MATCH($A48,ניו!$B:$B,0)),IFERROR(INDEX('מדי '!$C:$C,MATCH($A48,'מדי '!$B:$B,0)),"")) -> 2.9456457 | D48: =IFERROR(INDEX(ניו!$D:$D,MATCH($A48,ניו!$B:$B,0)),"") -> 1.8 | E48: =IFERROR(INDEX(ניו!$E:$E,MATCH($A48,ניו!$B:$B,0)),"") -> 2.3954001 | F48: =IFERROR(INDEX('מדי '!$D:$D,MATCH($A48,'מדי '!$B:$B,0)),"") -> 3.28 | G48: =IFERROR(INDEX('מדי '!$E:$E,MATCH($A48,'מדי '!$B:$B,0)),"") -> 2.8327273 | H48: =IFERROR(INDEX('מדי '!$F:$F,MATCH($A48,'מדי '!$B:$B,0)),"") -> 3.221581
A49: 364 XL | B49: =IF(AND(COUNTIF(ניו!$B:$B,$A49)>0,COUNTIF('מדי '!$B:$B,$A49)>0),"NZ + מדי",IF(COUNTIF(ניו!$B:$B,$A49)>0,"NZ","מדי")) -> NZ + מדי | C49: =IFERROR(INDEX(ניו!$C:$C,MATCH($A49,ניו!$B:$B,0)),IFERROR(INDEX('מדי '!$C:$C,MATCH($A49,'מדי '!$B:$B,0)),"")) -> 3.4747457 | D49: =IFERROR(INDEX(ניו!$D:$D,MATCH($A49,ניו!$B:$B,0)),"") -> 1.8 | E49: =IFERROR(INDEX(ניו!$E:$E,MATCH($A49,ניו!$B:$B,0)),"") -> 2.0306522 | F49: =IFERROR(INDEX('מדי '!$D:$D,MATCH($A49,'מדי '!$B:$B,0)),"") -> 1.91 | G49: =IFERROR(INDEX('מדי '!$E:$E,MATCH($A49,'מדי '!$B:$B,0)),"") -> 1.6495455 | H49: =IFERROR(INDEX('מדי '!$F:$F,MATCH($A49,'מדי '!$B:$B,0)),"") -> 1.5903256
A50: 365 S-L | B50: =IF(AND(COUNTIF(ניו!$B:$B,$A50)>0,COUNTIF('מדי '!$B:$B,$A50)>0),"NZ + מדי",IF(COUNTIF(ניו!$B:$B,$A50)>0,"NZ","מדי")) -> NZ + מדי | C50: =IFERROR(INDEX(ניו!$C:$C,MATCH($A50,ניו!$B:$B,0)),IFERROR(INDEX('מדי '!$C:$C,MATCH($A50,'מדי '!$B:$B,0)),"")) -> 4.2153864 | D50: =IFERROR(INDEX(ניו!$D:$D,MATCH($A50,ניו!$B:$B,0)),"") -> 2.15 | E50: =IFERROR(INDEX(ניו!$E:$E,MATCH($A50,ניו!$B:$B,0)),"") -> 1.9993422 | F50: =IFERROR(INDEX('מדי '!$D:$D,MATCH($A50,'מדי '!$B:$B,0)),"") -> 2.28 | G50: =IFERROR(INDEX('מדי '!$E:$E,MATCH($A50,'מדי '!$B:$B,0)),"") -> 1.9690909 | H50: =IFERROR(INDEX('מדי '!$F:$F,MATCH($A50,'מדי '!$B:$B,0)),"") -> 1.5648517
A51: 365 XL | B51: =IF(AND(COUNTIF(ניו!$B:$B,$A51)>0,COUNTIF('מדי '!$B:$B,$A51)>0),"NZ + מדי",IF(COUNTIF(ניו!$B:$B,$A51)>0,"NZ","מדי")) -> NZ + מדי | C51: =IFERROR(INDEX(ניו!$C:$C,MATCH($A51,ניו!$B:$B,0)),IFERROR(INDEX('מדי '!$C:$C,MATCH($A51,'מדי '!$B:$B,0)),"")) -> 3.8495957 | D51: =IFERROR(INDEX(ניו!$D:$D,MATCH($A51,ניו!$B:$B,0)),"") -> 2 | E51: =IFERROR(INDEX(ניו!$E:$E,MATCH($A51,ניו!$B:$B,0)),"") -> 2.0365775 | F51: =IFERROR(INDEX('מדי '!$D:$D,MATCH($A51,'מדי '!$B:$B,0)),"") -> 1.86 | G51: =IFERROR(INDEX('מדי '!$E:$E,MATCH($A51,'מדי '!$B:$B,0)),"") -> 1.6063636 | H51: =IFERROR(INDEX('מדי '!$F:$F,MATCH($A51,'מדי '!$B:$B,0)),"") -> 1.3978918
A52: 3655 | B52: =IF(AND(COUNTIF(ניו!$B:$B,$A52)>0,COUNTIF('מדי '!$B:$B,$A52)>0),"NZ + מדי",IF(COUNTIF(ניו!$B:$B,$A52)>0,"NZ","מדי")) -> NZ + מדי | C52: =IFERROR(INDEX(ניו!$C:$C,MATCH($A52,ניו!$B:$B,0)),IFERROR(INDEX('מדי '!$C:$C,MATCH($A52,'מדי '!$B:$B,0)),"")) -> 4.6550457 | D52: =IFERROR(INDEX(ניו!$D:$D,MATCH($A52,ניו!$B:$B,0)),"") -> 2.4 | E52: =IFERROR(INDEX(ניו!$E:$E,MATCH($A52,ניו!$B:$B,0)),"") -> 2.0210328 | F52: =IFERROR(INDEX('מדי '!$D:$D,MATCH($A52,'מדי '!$B:$B,0)),"") -> 2.6 | G52: =IFERROR(INDEX('מדי '!$E:$E,MATCH($A52,'מדי '!$B:$B,0)),"") -> 2.2454545 | H52: =IFERROR(INDEX('מדי '!$F:$F,MATCH($A52,'מדי '!$B:$B,0)),"") -> 1.6159396
...
