Workbook

Sheet השוואה כוללת
A1: השוואה כוללת - מכירות ינואר-יולי, 2025 מול 2026
A2: תאריך חישוב: | B2: 46243
A3: מקורות: month-01.xlsx עד month-07.xlsx (ינואר-יולי 2026 מול אותם חודשים ב-2025), kirill/reference/2026-sales-comparison/
A5: קוד SKU | B5: שם מוצר | C5: יחידות ינואר-יולי 2025 | D5: יחידות ינואר-יולי 2026 | E5: הפרש (יחידות) | F5: שינוי %
A6: 8616 | B6: URI 3623 1 כרית ליישור אצבע | C6: =SUMIF('מקור-01'!$A:$A,$A6,'מקור-01'!$C:$C)+SUMIF('מקור-02'!$A:$A,$A6,'מקור-02'!$C:$C)+SUMIF('מקור-03'!$A:$A,$A6,'מקור-03'!$C:$C)+SUMIF('מקור-04'!$A:$A,$A6,'מקור-04'!$C:$C)+SUMIF('מקור-05'!$A:$A,$A6,'מקור-05'!$C:$C)+SUMIF('מקור-06'!$A:$A,$A6,'מקור-06'!$C:$C)+SUMIF('מקור-07'!$A:$A,$A6,'מקור-07'!$C:$C) -> 88 | D6: =SUMIF('מקור-01'!$A:$A,$A6,'מקור-01'!$D:$D)+SUMIF('מקור-02'!$A:$A,$A6,'מקור-02'!$D:$D)+SUMIF('מקור-03'!$A:$A,$A6,'מקור-03'!$D:$D)+SUMIF('מקור-04'!$A:$A,$A6,'מקור-04'!$D:$D)+SUMIF('מקור-05'!$A:$A,$A6,'מקור-05'!$D:$D)+SUMIF('מקור-06'!$A:$A,$A6,'מקור-06'!$D:$D)+SUMIF('מקור-07'!$A:$A,$A6,'מקור-07'!$D:$D) -> 97 | E6: =D6-C6 -> 9 | F6: =IF(C6=0,"מוצר חדש",(D6-C6)/C6) -> 0.10227273
A7: 8618 | B7: URI 311 1 מדבקת ג'ל | C7: =SUMIF('מקור-01'!$A:$A,$A7,'מקור-01'!$C:$C)+SUMIF('מקור-02'!$A:$A,$A7,'מקור-02'!$C:$C)+SUMIF('מקור-03'!$A:$A,$A7,'מקור-03'!$C:$C)+SUMIF('מקור-04'!$A:$A,$A7,'מקור-04'!$C:$C)+SUMIF('מקור-05'!$A:$A,$A7,'מקור-05'!$C:$C)+SUMIF('מקור-06'!$A:$A,$A7,'מקור-06'!$C:$C)+SUMIF('מקור-07'!$A:$A,$A7,'מקור-07'!$C:$C) -> 133 | D7: =SUMIF('מקור-01'!$A:$A,$A7,'מקור-01'!$D:$D)+SUMIF('מקור-02'!$A:$A,$A7,'מקור-02'!$D:$D)+SUMIF('מקור-03'!$A:$A,$A7,'מקור-03'!$D:$D)+SUMIF('מקור-04'!$A:$A,$A7,'מקור-04'!$D:$D)+SUMIF('מקור-05'!$A:$A,$A7,'מקור-05'!$D:$D)+SUMIF('מקור-06'!$A:$A,$A7,'מקור-06'!$D:$D)+SUMIF('מקור-07'!$A:$A,$A7,'מקור-07'!$D:$D) -> 122 | E7: =D7-C7 -> -11 | F7: =IF(C7=0,"מוצר חדש",(D7-C7)/C7) -> -0.082706767
A8: 9771 | B8: URI 307 M 1 זוג עקב סיל+נ כ | C8: =SUMIF('מקור-01'!$A:$A,$A8,'מקור-01'!$C:$C)+SUMIF('מקור-02'!$A:$A,$A8,'מקור-02'!$C:$C)+SUMIF('מקור-03'!$A:$A,$A8,'מקור-03'!$C:$C)+SUMIF('מקור-04'!$A:$A,$A8,'מקור-04'!$C:$C)+SUMIF('מקור-05'!$A:$A,$A8,'מקור-05'!$C:$C)+SUMIF('מקור-06'!$A:$A,$A8,'מקור-06'!$C:$C)+SUMIF('מקור-07'!$A:$A,$A8,'מקור-07'!$C:$C) -> 143 | D8: =SUMIF('מקור-01'!$A:$A,$A8,'מקור-01'!$D:$D)+SUMIF('מקור-02'!$A:$A,$A8,'מקור-02'!$D:$D)+SUMIF('מקור-03'!$A:$A,$A8,'מקור-03'!$D:$D)+SUMIF('מקור-04'!$A:$A,$A8,'מקור-04'!$D:$D)+SUMIF('מקור-05'!$A:$A,$A8,'מקור-05'!$D:$D)+SUMIF('מקור-06'!$A:$A,$A8,'מקור-06'!$D:$D)+SUMIF('מקור-07'!$A:$A,$A8,'מקור-07'!$D:$D) -> 132 | E8: =D8-C8 -> -11 | F8: =IF(C8=0,"מוצר חדש",(D8-C8)/C8) -> -0.076923077
A9: 9772 | B9: URI 307 L 1 זוג עקב סיל+נ כ | C9: =SUMIF('מקור-01'!$A:$A,$A9,'מקור-01'!$C:$C)+SUMIF('מקור-02'!$A:$A,$A9,'מקור-02'!$C:$C)+SUMIF('מקור-03'!$A:$A,$A9,'מקור-03'!$C:$C)+SUMIF('מקור-04'!$A:$A,$A9,'מקור-04'!$C:$C)+SUMIF('מקור-05'!$A:$A,$A9,'מקור-05'!$C:$C)+SUMIF('מקור-06'!$A:$A,$A9,'מקור-06'!$C:$C)+SUMIF('מקור-07'!$A:$A,$A9,'מקור-07'!$C:$C) -> 141 | D9: =SUMIF('מקור-01'!$A:$A,$A9,'מקור-01'!$D:$D)+SUMIF('מקור-02'!$A:$A,$A9,'מקור-02'!$D:$D)+SUMIF('מקור-03'!$A:$A,$A9,'מקור-03'!$D:$D)+SUMIF('מקור-04'!$A:$A,$A9,'מקור-04'!$D:$D)+SUMIF('מקור-05'!$A:$A,$A9,'מקור-05'!$D:$D)+SUMIF('מקור-06'!$A:$A,$A9,'מקור-06'!$D:$D)+SUMIF('מקור-07'!$A:$A,$A9,'מקור-07'!$D:$D) -> 141 | E9: =D9-C9 -> 0 | F9: =IF(C9=0,"מוצר חדש",(D9-C9)/C9) -> 0
A10: 16211 | B10: 394B-35-381 גרבי קיץ לסוכרת | C10: =SUMIF('מקור-01'!$A:$A,$A10,'מקור-01'!$C:$C)+SUMIF('מקור-02'!$A:$A,$A10,'מקור-02'!$C:$C)+SUMIF('מקור-03'!$A:$A,$A10,'מקור-03'!$C:$C)+SUMIF('מקור-04'!$A:$A,$A10,'מקור-04'!$C:$C)+SUMIF('מקור-05'!$A:$A,$A10,'מקור-05'!$C:$C)+SUMIF('מקור-06'!$A:$A,$A10,'מקור-06'!$C:$C)+SUMIF('מקור-07'!$A:$A,$A10,'מקור-07'!$C:$C) -> 41 | D10: =SUMIF('מקור-01'!$A:$A,$A10,'מקור-01'!$D:$D)+SUMIF('מקור-02'!$A:$A,$A10,'מקור-02'!$D:$D)+SUMIF('מקור-03'!$A:$A,$A10,'מקור-03'!$D:$D)+SUMIF('מקור-04'!$A:$A,$A10,'מקור-04'!$D:$D)+SUMIF('מקור-05'!$A:$A,$A10,'מקור-05'!$D:$D)+SUMIF('מקור-06'!$A:$A,$A10,'מקור-06'!$D:$D)+SUMIF('מקור-07'!$A:$A,$A10,'מקור-07'!$D:$D) -> 30 | E10: =D10-C10 -> -11 | F10: =IF(C10=0,"מוצר חדש",(D10-C10)/C10) -> -0.26829268
A11: 16212 | B11: 394B-39-421 גרבי קיץ לסוכרת | C11: =SUMIF('מקור-01'!$A:$A,$A11,'מקור-01'!$C:$C)+SUMIF('מקור-02'!$A:$A,$A11,'מקור-02'!$C:$C)+SUMIF('מקור-03'!$A:$A,$A11,'מקור-03'!$C:$C)+SUMIF('מקור-04'!$A:$A,$A11,'מקור-04'!$C:$C)+SUMIF('מקור-05'!$A:$A,$A11,'מקור-05'!$C:$C)+SUMIF('מקור-06'!$A:$A,$A11,'מקור-06'!$C:$C)+SUMIF('מקור-07'!$A:$A,$A11,'מקור-07'!$C:$C) -> 107 | D11: =SUMIF('מקור-01'!$A:$A,$A11,'מקור-01'!$D:$D)+SUMIF('מקור-02'!$A:$A,$A11,'מקור-02'!$D:$D)+SUMIF('מקור-03'!$A:$A,$A11,'מקור-03'!$D:$D)+SUMIF('מקור-04'!$A:$A,$A11,'מקור-04'!$D:$D)+SUMIF('מקור-05'!$A:$A,$A11,'מקור-05'!$D:$D)+SUMIF('מקור-06'!$A:$A,$A11,'מקור-06'!$D:$D)+SUMIF('מקור-07'!$A:$A,$A11,'מקור-07'!$D:$D) -> 55 | E11: =D11-C11 -> -52 | F11: =IF(C11=0,"מוצר חדש",(D11-C11)/C11) -> -0.48598131
A12: 16213 | B12: 394B-43-461 גרבי קיץ לסוכרת | C12: =SUMIF('מקור-01'!$A:$A,$A12,'מקור-01'!$C:$C)+SUMIF('מקור-02'!$A:$A,$A12,'מקור-02'!$C:$C)+SUMIF('מקור-03'!$A:$A,$A12,'מקור-03'!$C:$C)+SUMIF('מקור-04'!$A:$A,$A12,'מקור-04'!$C:$C)+SUMIF('מקור-05'!$A:$A,$A12,'מקור-05'!$C:$C)+SUMIF('מקור-06'!$A:$A,$A12,'מקור-06'!$C:$C)+SUMIF('מקור-07'!$A:$A,$A12,'מקור-07'!$C:$C) -> 131 | D12: =SUMIF('מקור-01'!$A:$A,$A12,'מקור-01'!$D:$D)+SUMIF('מקור-02'!$A:$A,$A12,'מקור-02'!$D:$D)+SUMIF('מקור-03'!$A:$A,$A12,'מקור-03'!$D:$D)+SUMIF('מקור-04'!$A:$A,$A12,'מקור-04'!$D:$D)+SUMIF('מקור-05'!$A:$A,$A12,'מקור-05'!$D:$D)+SUMIF('מקור-06'!$A:$A,$A12,'מקור-06'!$D:$D)+SUMIF('מקור-07'!$A:$A,$A12,'מקור-07'!$D:$D) -> 87 | E12: =D12-C12 -> -44 | F12: =IF(C12=0,"מוצר חדש",(D12-C12)/C12) -> -0.33587786
A13: 16214 | B13: 394-G-35-31 גרבי קיץ לסוכרת | C13: =SUMIF('מקור-01'!$A:$A,$A13,'מקור-01'!$C:$C)+SUMIF('מקור-02'!$A:$A,$A13,'מקור-02'!$C:$C)+SUMIF('מקור-03'!$A:$A,$A13,'מקור-03'!$C:$C)+SUMIF('מקור-04'!$A:$A,$A13,'מקור-04'!$C:$C)+SUMIF('מקור-05'!$A:$A,$A13,'מקור-05'!$C:$C)+SUMIF('מקור-06'!$A:$A,$A13,'מקור-06'!$C:$C)+SUMIF('מקור-07'!$A:$A,$A13,'מקור-07'!$C:$C) -> 20 | D13: =SUMIF('מקור-01'!$A:$A,$A13,'מקור-01'!$D:$D)+SUMIF('מקור-02'!$A:$A,$A13,'מקור-02'!$D:$D)+SUMIF('מקור-03'!$A:$A,$A13,'מקור-03'!$D:$D)+SUMIF('מקור-04'!$A:$A,$A13,'מקור-04'!$D:$D)+SUMIF('מקור-05'!$A:$A,$A13,'מקור-05'!$D:$D)+SUMIF('מקור-06'!$A:$A,$A13,'מקור-06'!$D:$D)+SUMIF('מקור-07'!$A:$A,$A13,'מקור-07'!$D:$D) -> 19 | E13: =D13-C13 -> -1 | F13: =IF(C13=0,"מוצר חדש",(D13-C13)/C13) -> -0.05
A14: 16217 | B14: 394G-39-421 גרבי קיץ לסוכרת | C14: =SUMIF('מקור-01'!$A:$A,$A14,'מקור-01'!$C:$C)+SUMIF('מקור-02'!$A:$A,$A14,'מקור-02'!$C:$C)+SUMIF('מקור-03'!$A:$A,$A14,'מקור-03'!$C:$C)+SUMIF('מקור-04'!$A:$A,$A14,'מקור-04'!$C:$C)+SUMIF('מקור-05'!$A:$A,$A14,'מקור-05'!$C:$C)+SUMIF('מקור-06'!$A:$A,$A14,'מקור-06'!$C:$C)+SUMIF('מקור-07'!$A:$A,$A14,'מקור-07'!$C:$C) -> 33 | D14: =SUMIF('מקור-01'!$A:$A,$A14,'מקור-01'!$D:$D)+SUMIF('מקור-02'!$A:$A,$A14,'מקור-02'!$D:$D)+SUMIF('מקור-03'!$A:$A,$A14,'מקור-03'!$D:$D)+SUMIF('מקור-04'!$A:$A,$A14,'מקור-04'!$D:$D)+SUMIF('מקור-05'!$A:$A,$A14,'מקור-05'!$D:$D)+SUMIF('מקור-06'!$A:$A,$A14,'מקור-06'!$D:$D)+SUMIF('מקור-07'!$A:$A,$A14,'מקור-07'!$D:$D) -> 18 | E14: =D14-C14 -> -15 | F14: =IF(C14=0,"מוצר חדש",(D14-C14)/C14) -> -0.45454545
A15: 16237 | B15: 394G-43-461 גרבי קיץ לסוכרת | C15: =SUMIF('מקור-01'!$A:$A,$A15,'מקור-01'!$C:$C)+SUMIF('מקור-02'!$A:$A,$A15,'מקור-02'!$C:$C)+SUMIF('מקור-03'!$A:$A,$A15,'מקור-03'!$C:$C)+SUMIF('מקור-04'!$A:$A,$A15,'מקור-04'!$C:$C)+SUMIF('מקור-05'!$A:$A,$A15,'מקור-05'!$C:$C)+SUMIF('מקור-06'!$A:$A,$A15,'מקור-06'!$C:$C)+SUMIF('מקור-07'!$A:$A,$A15,'מקור-07'!$C:$C) -> 36 | D15: =SUMIF('מקור-01'!$A:$A,$A15,'מקור-01'!$D:$D)+SUMIF('מקור-02'!$A:$A,$A15,'מקור-02'!$D:$D)+SUMIF('מקור-03'!$A:$A,$A15,'מקור-03'!$D:$D)+SUMIF('מקור-04'!$A:$A,$A15,'מקור-04'!$D:$D)+SUMIF('מקור-05'!$A:$A,$A15,'מקור-05'!$D:$D)+SUMIF('מקור-06'!$A:$A,$A15,'מקור-06'!$D:$D)+SUMIF('מקור-07'!$A:$A,$A15,'מקור-07'!$D:$D) -> 10 | E15: =D15-C15 -> -26 | F15: =IF(C15=0,"מוצר חדש",(D15-C15)/C15) -> -0.72222222
A16: 16239 | B16: 394W-35-381 גרבי קיץ לסוכרת | C16: =SUMIF('מקור-01'!$A:$A,$A16,'מקור-01'!$C:$C)+SUMIF('מקור-02'!$A:$A,$A16,'מקור-02'!$C:$C)+SUMIF('מקור-03'!$A:$A,$A16,'מקור-03'!$C:$C)+SUMIF('מקור-04'!$A:$A,$A16,'מקור-04'!$C:$C)+SUMIF('מקור-05'!$A:$A,$A16,'מקור-05'!$C:$C)+SUMIF('מקור-06'!$A:$A,$A16,'מקור-06'!$C:$C)+SUMIF('מקור-07'!$A:$A,$A16,'מקור-07'!$C:$C) -> 27 | D16: =SUMIF('מקור-01'!$A:$A,$A16,'מקור-01'!$D:$D)+SUMIF('מקור-02'!$A:$A,$A16,'מקור-02'!$D:$D)+SUMIF('מקור-03'!$A:$A,$A16,'מקור-03'!$D:$D)+SUMIF('מקור-04'!$A:$A,$A16,'מקור-04'!$D:$D)+SUMIF('מקור-05'!$A:$A,$A16,'מקור-05'!$D:$D)+SUMIF('מקור-06'!$A:$A,$A16,'מקור-06'!$D:$D)+SUMIF('מקור-07'!$A:$A,$A16,'מקור-07'!$D:$D) -> 17 | E16: =D16-C16 -> -10 | F16: =IF(C16=0,"מוצר חדש",(D16-C16)/C16) -> -0.37037037
A17: 16244 | B17: 394W-39-421 גרבי קיץ לסוכרת | C17: =SUMIF('מקור-01'!$A:$A,$A17,'מקור-01'!$C:$C)+SUMIF('מקור-02'!$A:$A,$A17,'מקור-02'!$C:$C)+SUMIF('מקור-03'!$A:$A,$A17,'מקור-03'!$C:$C)+SUMIF('מקור-04'!$A:$A,$A17,'מקור-04'!$C:$C)+SUMIF('מקור-05'!$A:$A,$A17,'מקור-05'!$C:$C)+SUMIF('מקור-06'!$A:$A,$A17,'מקור-06'!$C:$C)+SUMIF('מקור-07'!$A:$A,$A17,'מקור-07'!$C:$C) -> 27 | D17: =SUMIF('מקור-01'!$A:$A,$A17,'מקור-01'!$D:$D)+SUMIF('מקור-02'!$A:$A,$A17,'מקור-02'!$D:$D)+SUMIF('מקור-03'!$A:$A,$A17,'מקור-03'!$D:$D)+SUMIF('מקור-04'!$A:$A,$A17,'מקור-04'!$D:$D)+SUMIF('מקור-05'!$A:$A,$A17,'מקור-05'!$D:$D)+SUMIF('מקור-06'!$A:$A,$A17,'מקור-06'!$D:$D)+SUMIF('מקור-07'!$A:$A,$A17,'מקור-07'!$D:$D) -> 24 | E17: =D17-C17 -> -3 | F17: =IF(C17=0,"מוצר חדש",(D17-C17)/C17) -> -0.11111111
... A233: 88478 | B233: URI LF377 L 1 מדרס סיליקון | C233: =SUMIF('מקור-01'!$A:$A,$A233,'מקור-01'!$C:$C)+SUMIF('מקור-02'!$A:$A,$A233,'מקור-02'!$C:$C)+SUMIF('מקור-03'!$A:$A,$A233,'מקור-03'!$C:$C)+SUMIF('מקור-04'!$A:$A,$A233,'מקור-04'!$C:$C)+SUMIF('מקור-05'!$A:$A,$A233,'מקור-05'!$C:$C)+SUMIF('מקור-06'!$A:$A,$A233,'מקור-06'!$C:$C)+SUMIF('מקור-07'!$A:$A,$A233,'מקור-07'!$C:$C) -> 2 | D233: =SUMIF('מקור-01'!$A:$A,$A233,'מקור-01'!$D:$D)+SUMIF('מקור-02'!$A:$A,$A233,'מקור-02'!$D:$D)+SUMIF('מקור-03'!$A:$A,$A233,'מקור-03'!$D:$D)+SUMIF('מקור-04'!$A:$A,$A233,'מקור-04'!$D:$D)+SUMIF('מקור-05'!$A:$A,$A233,'מקור-05'!$D:$D)+SUMIF('מקור-06'!$A:$A,$A233,'מקור-06'!$D:$D)+SUMIF('מקור-07'!$A:$A,$A233,'מקור-07'!$D:$D) -> 0 | E233: =D233-C233 -> -2 | F233: =IF(C233=0,"מוצר חדש",(D233-C233)/C233) -> -1
A234: סה"כ כללי | C234: =SUM(C6:C233) -> 14701 | D234: =SUM(D6:D233) -> 15115 | E234: =D234-C234 -> 414 | F234: =IF(C234=0,"",(D234-C234)/C234) -> 0.02816135

Sheet הכי נמכרים 2025
A1: הכי נמכרים 2025 - Top 20 לפי יחידות ינואר-יולי 2025 (עם השוואה ל-2026)
A3: # | B3: קוד SKU | C3: שם מוצר | D3: יחידות ינואר-יולי 2025 | E3: יחידות ינואר-יולי 2026
A4: 1 | B4: ='השוואה כוללת'!A65 -> 51567 | C4: ='השוואה כוללת'!B65 -> 1 סד יד דו צדדי | D4: ='השוואה כוללת'!C65 -> 972 | E4: ='השוואה כוללת'!D65 -> 953
A5: 2 | B5: ='השוואה כוללת'!A213 -> 83668 | C5: ='השוואה כוללת'!B213 -> URI FC335 1 טלק לכף הרגל | D5: ='השוואה כוללת'!C213 -> 773 | E5: ='השוואה כוללת'!D213 -> 462
A6: 3 | B6: ='השוואה כוללת'!A150 -> 71204 | C6: ='השוואה כוללת'!B150 -> URI 3655 1 שרוול מסיליקון | D6: ='השוואה כוללת'!C150 -> 654 | E6: ='השוואה כוללת'!D150 -> 561
A7: 4 | B7: ='השוואה כוללת'!A84 -> 59679 | C7: ='השוואה כוללת'!B84 -> URI 364 S M 1 | D7: ='השוואה כוללת'!C84 -> 397 | E7: ='השוואה כוללת'!D84 -> 329
A8: 5 | B8: ='השוואה כוללת'!A98 -> 63360 | C8: ='השוואה כוללת'!B98 -> URI 45 L 1 מגן ברךBOX | D8: ='השוואה כוללת'!C98 -> 338 | E8: ='השוואה כוללת'!D98 -> 318
A9: 6 | B9: ='השוואה כוללת'!A30 -> 24612 | C9: ='השוואה כוללת'!B30 -> URI AC28 1 סד לאגודל | D9: ='השוואה כוללת'!C30 -> 328 | E9: ='השוואה כוללת'!D30 -> 255
A10: 7 | B10: ='השוואה כוללת'!A45 -> 31188 | C10: ='השוואה כוללת'!B45 -> URI 372 1 רפידת אנטי ריח | D10: ='השוואה כוללת'!C45 -> 326 | E10: ='השוואה כוללת'!D45 -> 311
A11: 8 | B11: ='השוואה כוללת'!A66 -> 51568 | C11: ='השוואה כוללת'!B66 -> 1 סד לאגודל | D11: ='השוואה כוללת'!C66 -> 316 | E11: ='השוואה כוללת'!D66 -> 415
A12: 9 | B12: ='השוואה כוללת'!A97 -> 63359 | C12: ='השוואה כוללת'!B97 -> URI 45 M 1 מגן ברך | D12: ='השוואה כוללת'!C97 -> 276 | E12: ='השוואה כוללת'!D97 -> 262
A13: 10 | B13: ='השוואה כוללת'!A162 -> 74709 | C13: ='השוואה כוללת'!B162 -> URI 21 M 1 חבק יד ארוך | D13: ='השוואה כוללת'!C162 -> 250 | E13: ='השוואה כוללת'!D162 -> 233
A14: 11 | B14: ='השוואה כוללת'!A87 -> 60472 | C14: ='השוואה כוללת'!B87 -> URI PD340 1 קוצץ ציפורניים | D14: ='השוואה כוללת'!C87 -> 237 | E14: ='השוואה כוללת'!D87 -> 275
A15: 12 | B15: ='השוואה כוללת'!A135 -> 67385 | C15: ='השוואה כוללת'!B135 -> URI 302M 0 1 מדרס ג'ל לגבר | D15: ='השוואה כוללת'!C135 -> 231 | E15: ='השוואה כוללת'!D135 -> 105
A16: 13 | B16: ='השוואה כוללת'!A85 -> 59694 | C16: ='השוואה כוללת'!B85 -> URI 365 S-L 1 טבעת אלסטית | D16: ='השוואה כוללת'!C85 -> 228 | E16: ='השוואה כוללת'!D85 -> 209
A17: 14 | B17: ='השוואה כוללת'!A167 -> 74799 | C17: ='השוואה כוללת'!B167 -> URI 45E L1 מגן ברך ארוך לבן | D17: ='השוואה כוללת'!C167 -> 227 | E17: ='השוואה כוללת'!D167 -> 210
A18: 15 | B18: ='השוואה כוללת'!A99 -> 63361 | C18: ='השוואה כוללת'!B99 -> URI 45 XL 1 מגן ברך | D18: ='השוואה כוללת'!C99 -> 202 | E18: ='השוואה כוללת'!D99 -> 191
A19: 16 | B19: ='השוואה כוללת'!A168 -> 74800 | C19: ='השוואה כוללת'!B168 -> URI 45E M 1 מגן ברך ארוך | D19: ='השוואה כוללת'!C168 -> 200 | E19: ='השוואה כוללת'!D168 -> 166
A20: 17 | B20: ='השוואה כוללת'!A44 -> 31183 | C20: ='השוואה כוללת'!B44 -> URI 370 1 רפידת נוחות | D20: ='השוואה כוללת'!C44 -> 197 | E20: ='השוואה כוללת'!D44 -> 201
A21: 18 | B21: ='השוואה כוללת'!A101 -> 63367 | C21: ='השוואה כוללת'!B101 -> URI 34 L 1 מגן קרסול ס.בעקב | D21: ='השוואה כוללת'!C101 -> 189 | E21: ='השוואה כוללת'!D101 -> 168
A22: 19 | B22: ='השוואה כוללת'!A68 -> 52323 | C22: ='השוואה כוללת'!B68 -> URI 078G L 1 חגורת גב אפורה | D22: ='השוואה כוללת'!C68 -> 188 | E22: ='השוואה כוללת'!D68 -> 183
A23: 20 | B23: ='השוואה כוללת'!A108 -> 63415 | C23: ='השוואה כוללת'!B108 -> URI 85 L 1 מתלה ליד | D23: ='השוואה כוללת'!C108 -> 187 | E23: ='השוואה כוללת'!D108 -> 209

Sheet הכי נמכרים 2026
A1: הכי נמכרים 2026 - Top 20 לפי יחידות ינואר-יולי 2026 (עם השוואה ל-2025)
A3: # | B3: קוד SKU | C3: שם מוצר | D3: יחידות ינואר-יולי 2025 | E3: יחידות ינואר-יולי 2026
A4: 1 | B4: ='השוואה כוללת'!A65 -> 51567 | C4: ='השוואה כוללת'!B65 -> 1 סד יד דו צדדי | D4: ='השוואה כוללת'!C65 -> 972 | E4: ='השוואה כוללת'!D65 -> 953
A5: 2 | B5: ='השוואה כוללת'!A150 -> 71204 | C5: ='השוואה כוללת'!B150 -> URI 3655 1 שרוול מסיליקון | D5: ='השוואה כוללת'!C150 -> 654 | E5: ='השוואה כוללת'!D150 -> 561
A6: 3 | B6: ='השוואה כוללת'!A213 -> 83668 | C6: ='השוואה כוללת'!B213 -> URI FC335 1 טלק לכף הרגל | D6: ='השוואה כוללת'!C213 -> 773 | E6: ='השוואה כוללת'!D213 -> 462
A7: 4 | B7: ='השוואה כוללת'!A207 -> 82206 | C7: ='השוואה כוללת'!B207 -> ST25 1 חבק לשורש כף היד | D7: ='השוואה כוללת'!C207 -> 93 | E7: ='השוואה כוללת'!D207 -> 438
A8: 5 | B8: ='השוואה כוללת'!A66 -> 51568 | C8: ='השוואה כוללת'!B66 -> 1 סד לאגודל | D8: ='השוואה כוללת'!C66 -> 316 | E8: ='השוואה כוללת'!D66 -> 415
A9: 6 | B9: ='השוואה כוללת'!A84 -> 59679 | C9: ='השוואה כוללת'!B84 -> URI 364 S M 1 | D9: ='השוואה כוללת'!C84 -> 397 | E9: ='השוואה כוללת'!D84 -> 329
A10: 7 | B10: ='השוואה כוללת'!A98 -> 63360 | C10: ='השוואה כוללת'!B98 -> URI 45 L 1 מגן ברךBOX | D10: ='השוואה כוללת'!C98 -> 338 | E10: ='השוואה כוללת'!D98 -> 318
A11: 8 | B11: ='השוואה כוללת'!A45 -> 31188 | C11: ='השוואה כוללת'!B45 -> URI 372 1 רפידת אנטי ריח | D11: ='השוואה כוללת'!C45 -> 326 | E11: ='השוואה כוללת'!D45 -> 311
A12: 9 | B12: ='השוואה כוללת'!A131 -> 66745 | C12: ='השוואה כוללת'!B131 -> 1 תרסיס דיאו.אנטי בקטר.לנעל | D12: ='השוואה כוללת'!C131 -> 165 | E12: ='השוואה כוללת'!D131 -> 291
A13: 10 | B13: ='השוואה כוללת'!A87 -> 60472 | C13: ='השוואה כוללת'!B87 -> URI PD340 1 קוצץ ציפורניים | D13: ='השוואה כוללת'!C87 -> 237 | E13: ='השוואה כוללת'!D87 -> 275
A14: 11 | B14: ='השוואה כוללת'!A97 -> 63359 | C14: ='השוואה כוללת'!B97 -> URI 45 M 1 מגן ברך | D14: ='השוואה כוללת'!C97 -> 276 | E14: ='השוואה כוללת'!D97 -> 262
A15: 12 | B15: ='השוואה כוללת'!A30 -> 24612 | C15: ='השוואה כוללת'!B30 -> URI AC28 1 סד לאגודל | D15: ='השוואה כוללת'!C30 -> 328 | E15: ='השוואה כוללת'!D30 -> 255
A16: 13 | B16: ='השוואה כוללת'!A162 -> 74709 | C16: ='השוואה כוללת'!B162 -> URI 21 M 1 חבק יד ארוך | D16: ='השוואה כוללת'!C162 -> 250 | E16: ='השוואה כוללת'!D162 -> 233
A17: 14 | B17: ='השוואה כוללת'!A29 -> 23008 | C17: ='השוואה כוללת'!B29 -> URI 364 XL 1 | D17: ='השוואה כוללת'!C29 -> 183 | E17: ='השוואה כוללת'!D29 -> 218
A18: 15 | B18: ='השוואה כוללת'!A167 -> 74799 | C18: ='השוואה כוללת'!B167 -> URI 45E L1 מגן ברך ארוך לבן | D18: ='השוואה כוללת'!C167 -> 227 | E18: ='השוואה כוללת'!D167 -> 210
A19: 16 | B19: ='השוואה כוללת'!A85 -> 59694 | C19: ='השוואה כוללת'!B85 -> URI 365 S-L 1 טבעת אלסטית | D19: ='השוואה כוללת'!C85 -> 228 | E19: ='השוואה כוללת'!D85 -> 209
A20: 17 | B20: ='השוואה כוללת'!A108 -> 63415 | C20: ='השוואה כוללת'!B108 -> URI 85 L 1 מתלה ליד | D20: ='השוואה כוללת'!C108 -> 187 | E20: ='השוואה כוללת'!D108 -> 209
A21: 18 | B21: ='השוואה כוללת'!A44 -> 31183 | C21: ='השוואה כוללת'!B44 -> URI 370 1 רפידת נוחות | D21: ='השוואה כוללת'!C44 -> 197 | E21: ='השוואה כוללת'!D44 -> 201
A22: 19 | B22: ='השוואה כוללת'!A99 -> 63361 | C22: ='השוואה כוללת'!B99 -> URI 45 XL 1 מגן ברך | D22: ='השוואה כוללת'!C99 -> 202 | E22: ='השוואה כוללת'!D99 -> 191
A23: 20 | B23: ='השוואה כוללת'!A68 -> 52323 | C23: ='השוואה כוללת'!B68 -> URI 078G L 1 חגורת גב אפורה | D23: ='השוואה כוללת'!C68 -> 188 | E23: ='השוואה כוללת'!D68 -> 183

Sheet עליות הכי גדולות
A1: עליות הכי גדולות - Top 20 לפי אחוז עלייה מ-2025 ל-2026
A2: סף מינימלי: רק מוצרים עם לפחות 5 יחידות שנמכרו בינואר-יולי 2025 (מוצאים מוצרים חדשים/שוליים עם בסיס נמוך שמעוותים אחוזים).
A4: # | B4: קוד SKU | C4: שם מוצר | D4: יחידות ינואר-יולי 2025 | E4: יחידות ינואר-יולי 2026 | F4: שינוי %
A5: 1 | B5: ='השוואה כוללת'!A208 -> 82207 | C5: ='השוואה כוללת'!B208 -> ST20 1 חבק יד | D5: ='השוואה כוללת'!C208 -> 17 | E5: ='השוואה כוללת'!D208 -> 101 | F5: ='השוואה כוללת'!F208 -> 4.9411765
A6: 2 | B6: ='השוואה כוללת'!A212 -> 83420 | C6: ='השוואה כוללת'!B212 -> URI ST4221 מגן ברך +כ סיליק | D6: ='השוואה כוללת'!C212 -> 18 | E6: ='השוואה כוללת'!D212 -> 92 | F6: ='השוואה כוללת'!F212 -> 4.1111111
A7: 3 | B7: ='השוואה כוללת'!A77 -> 57662 | C7: ='השוואה כוללת'!B77 -> 808KT-P 1 טייפ קינזיולוגי | D7: ='השוואה כוללת'!C77 -> 10 | E7: ='השוואה כוללת'!D77 -> 50 | F7: ='השוואה כוללת'!F77 -> 4
A8: 4 | B8: ='השוואה כוללת'!A80 -> 57696 | C8: ='השוואה כוללת'!B80 -> 808KT-B 1 טייפ קינזיולוגי | D8: ='השוואה כוללת'!C80 -> 13 | E8: ='השוואה כוללת'!D80 -> 65 | F8: ='השוואה כוללת'!F80 -> 4
A9: 5 | B9: ='השוואה כוללת'!A207 -> 82206 | C9: ='השוואה כוללת'!B207 -> ST25 1 חבק לשורש כף היד | D9: ='השוואה כוללת'!C207 -> 93 | E9: ='השוואה כוללת'!D207 -> 438 | F9: ='השוואה כוללת'!F207 -> 3.7096774
A10: 6 | B10: ='השוואה כוללת'!A209 -> 82208 | C10: ='השוואה כוללת'!B209 -> URI ST37 1 חבק לקרסול | D10: ='השוואה כוללת'!C209 -> 35 | E10: ='השוואה כוללת'!D209 -> 145 | F10: ='השוואה כוללת'!F209 -> 3.1428571
A11: 7 | B11: ='השוואה כוללת'!A79 -> 57690 | C11: ='השוואה כוללת'!B79 -> 808KT-C 1 טייפ קינזיולוגי | D11: ='השוואה כוללת'!C79 -> 18 | E11: ='השוואה כוללת'!D79 -> 74 | F11: ='השוואה כוללת'!F79 -> 3.1111111
A12: 8 | B12: ='השוואה כוללת'!A206 -> 82202 | C12: ='השוואה כוללת'!B206 -> ST91 1 מגן מרפק לטניס | D12: ='השוואה כוללת'!C206 -> 40 | E12: ='השוואה כוללת'!D206 -> 146 | F12: ='השוואה כוללת'!F206 -> 2.65
A13: 9 | B13: ='השוואה כוללת'!A78 -> 57664 | C13: ='השוואה כוללת'!B78 -> 808KT-BL 1 טייפ קינזיולוגי | D13: ='השוואה כוללת'!C78 -> 22 | E13: ='השוואה כוללת'!D78 -> 69 | F13: ='השוואה כוללת'!F78 -> 2.1363636
A14: 10 | B14: ='השוואה כוללת'!A210 -> 82213 | C14: ='השוואה כוללת'!B210 -> ST28 1 סט אגודלי+מוט תמיכה | D14: ='השוואה כוללת'!C210 -> 50 | E14: ='השוואה כוללת'!D210 -> 155 | F14: ='השוואה כוללת'!F210 -> 2.1
A15: 11 | B15: ='השוואה כוללת'!A217 -> 87819 | C15: ='השוואה כוללת'!B217 -> ST433 H 1 מגן ברך עם ציר | D15: ='השוואה כוללת'!C217 -> 9 | E15: ='השוואה כוללת'!D217 -> 24 | F15: ='השוואה כוללת'!F217 -> 1.6666667
A16: 12 | B16: ='השוואה כוללת'!A122 -> 64635 | C16: ='השוואה כוללת'!B122 -> URI 390B 43-46 1 גרבי כסף | D16: ='השוואה כוללת'!C122 -> 25 | E16: ='השוואה כוללת'!D122 -> 58 | F16: ='השוואה כוללת'!F122 -> 1.32
A17: 13 | B17: ='השוואה כוללת'!A67 -> 52147 | C17: ='השוואה כוללת'!B67 -> URI FC321 1 מלח אמבט לכף ר | D17: ='השוואה כוללת'!C67 -> 70 | E17: ='השוואה כוללת'!D67 -> 134 | F17: ='השוואה כוללת'!F67 -> 0.91428571
A18: 14 | B18: ='השוואה כוללת'!A147 -> 71086 | C18: ='השוואה כוללת'!B147 -> URI 078M 1 | D18: ='השוואה כוללת'!C147 -> 21 | E18: ='השוואה כוללת'!D147 -> 39 | F18: ='השוואה כוללת'!F147 -> 0.85714286
A19: 15 | B19: ='השוואה כוללת'!A185 -> 74848 | C19: ='השוואה כוללת'!B185 -> URI 76 XL 1 מיישר כתף | D19: ='השוואה כוללת'!C185 -> 6 | E19: ='השוואה כוללת'!D185 -> 11 | F19: ='השוואה כוללת'!F185 -> 0.83333333
A20: 16 | B20: ='השוואה כוללת'!A131 -> 66745 | C20: ='השוואה כוללת'!B131 -> 1 תרסיס דיאו.אנטי בקטר.לנעל | D20: ='השוואה כוללת'!C131 -> 165 | E20: ='השוואה כוללת'!D131 -> 291 | F20: ='השוואה כוללת'!F131 -> 0.76363636
A21: 17 | B21: ='השוואה כוללת'!A211 -> 82551 | C21: ='השוואה כוללת'!B211 -> URI ST11 1 חגורת בטן | D21: ='השוואה כוללת'!C211 -> 8 | E21: ='השוואה כוללת'!D211 -> 14 | F21: ='השוואה כוללת'!F211 -> 0.75
A22: 18 | B22: ='השוואה כוללת'!A197 -> 75764 | C22: ='השוואה כוללת'!B197 -> URI 16 XXL 1 חגורת הריון | D22: ='השוואה כוללת'!C197 -> 13 | E22: ='השוואה כוללת'!D197 -> 21 | F22: ='השוואה כוללת'!F197 -> 0.61538462
A23: 19 | B23: ='השוואה כוללת'!A183 -> 74846 | C23: ='השוואה כוללת'!B183 -> URI 76 L 1 מיישר כתף | D23: ='השוואה כוללת'!C183 -> 12 | E23: ='השוואה כוללת'!D183 -> 19 | F23: ='השוואה כוללת'!F183 -> 0.58333333
A24: 20 | B24: ='השוואה כוללת'!A112 -> 63419 | C24: ='השוואה כוללת'!B112 -> URI 87 XL1 חגו.קיבוע תמ.אמה | D24: ='השוואה כוללת'!C112 -> 21 | E24: ='השוואה כוללת'!D112 -> 32 | F24: ='השוואה כוללת'!F112 -> 0.52380952

Sheet ירידות הכי גדולות
A1: ירידות הכי גדולות - Top 20 לפי אחוז ירידה מ-2025 ל-2026
A2: סף מינימלי: רק מוצרים עם לפחות 5 יחידות שנמכרו בינואר-יולי 2025 (מוצאים מוצרים חדשים/שוליים עם בסיס נמוך שמעוותים אחוזים).
A4: # | B4: קוד SKU | C4: שם מוצר | D4: יחידות ינואר-יולי 2025 | E4: יחידות ינואר-יולי 2026 | F4: שינוי %
A5: 1 | B5: ='השוואה כוללת'!A28 -> 21897 | C5: ='השוואה כוללת'!B28 -> URI 388R 1 סד לילה לבוהן | D5: ='השוואה כוללת'!C28 -> 9 | E5: ='השוואה כוללת'!D28 -> 1 | F5: ='השוואה כוללת'!F28 -> -0.88888889
A6: 2 | B6: ='השוואה כוללת'!A43 -> 29984 | C6: ='השוואה כוללת'!B43 -> URI 95 XS 1 מגן מרפק | D6: ='השוואה כוללת'!C43 -> 24 | E6: ='השוואה כוללת'!D43 -> 6 | F6: ='השוואה כוללת'!F43 -> -0.75
A7: 3 | B7: ='השוואה כוללת'!A15 -> 16237 | C7: ='השוואה כוללת'!B15 -> 394G-43-461 גרבי קיץ לסוכרת | D7: ='השוואה כוללת'!C15 -> 36 | E7: ='השוואה כוללת'!D15 -> 10 | F7: ='השוואה כוללת'!F15 -> -0.72222222
A8: 4 | B8: ='השוואה כוללת'!A63 -> 50057 | C8: ='השוואה כוללת'!B63 -> URI 76 1 מיישר כתף | D8: ='השוואה כוללת'!C63 -> 9 | E8: ='השוואה כוללת'!D63 -> 3 | F8: ='השוואה כוללת'!F63 -> -0.66666667
A9: 5 | B9: ='השוואה כוללת'!A136 -> 67895 | C9: ='השוואה כוללת'!B136 -> URI 11 1 ח בטן אורירית | D9: ='השוואה כוללת'!C136 -> 15 | E9: ='השוואה כוללת'!D136 -> 5 | F9: ='השוואה כוללת'!F136 -> -0.66666667
A10: 6 | B10: ='השוואה כוללת'!A27 -> 21896 | C10: ='השוואה כוללת'!B27 -> URI 388L 1 סד לילה לבוהן | D10: ='השוואה כוללת'!C27 -> 8 | E10: ='השוואה כוללת'!D27 -> 3 | F10: ='השוואה כוללת'!F27 -> -0.625
A11: 7 | B11: ='השוואה כוללת'!A124 -> 64637 | C11: ='השוואה כוללת'!B124 -> URI 390G 39-42 1 גרבי כסף | D11: ='השוואה כוללת'!C124 -> 20 | E11: ='השוואה כוללת'!D124 -> 8 | F11: ='השוואה כוללת'!F124 -> -0.6
A12: 8 | B12: ='השוואה כוללת'!A135 -> 67385 | C12: ='השוואה כוללת'!B135 -> URI 302M 0 1 מדרס ג'ל לגבר | D12: ='השוואה כוללת'!C135 -> 231 | E12: ='השוואה כוללת'!D135 -> 105 | F12: ='השוואה כוללת'!F135 -> -0.54545455
A13: 9 | B13: ='השוואה כוללת'!A33 -> 28302 | C13: ='השוואה כוללת'!B33 -> URI 34+XXL1 מ קרסול+עכב סגו | D13: ='השוואה כוללת'!C33 -> 13 | E13: ='השוואה כוללת'!D33 -> 6 | F13: ='השוואה כוללת'!F33 -> -0.53846154
A14: 10 | B14: ='השוואה כוללת'!A105 -> 63406 | C14: ='השוואה כוללת'!B105 -> URI 11U L 1 ח בטן אחר ניתוח | D14: ='השוואה כוללת'!C105 -> 8 | E14: ='השוואה כוללת'!D105 -> 4 | F14: ='השוואה כוללת'!F105 -> -0.5
A15: 11 | B15: ='השוואה כוללת'!A74 -> 53791 | C15: ='השוואה כוללת'!B74 -> URI 397-43-46 1 גרבי טיסה | D15: ='השוואה כוללת'!C74 -> 53 | E15: ='השוואה כוללת'!D74 -> 27 | F15: ='השוואה כוללת'!F74 -> -0.49056604
A16: 12 | B16: ='השוואה כוללת'!A11 -> 16212 | C16: ='השוואה כוללת'!B11 -> 394B-39-421 גרבי קיץ לסוכרת | D16: ='השוואה כוללת'!C11 -> 107 | E16: ='השוואה כוללת'!D11 -> 55 | F16: ='השוואה כוללת'!F11 -> -0.48598131
A17: 13 | B17: ='השוואה כוללת'!A14 -> 16217 | C17: ='השוואה כוללת'!B14 -> 394G-39-421 גרבי קיץ לסוכרת | D17: ='השוואה כוללת'!C14 -> 33 | E17: ='השוואה כוללת'!D14 -> 18 | F17: ='השוואה כוללת'!F14 -> -0.45454545
A18: 14 | B18: ='השוואה כוללת'!A42 -> 29981 | C18: ='השוואה כוללת'!B42 -> URI 35 XXL 1 מגן קרסול לבן | D18: ='השוואה כוללת'!C42 -> 42 | E18: ='השוואה כוללת'!D42 -> 24 | F18: ='השוואה כוללת'!F42 -> -0.42857143
A19: 15 | B19: ='השוואה כוללת'!A152 -> 74670 | C19: ='השוואה כוללת'!B152 -> URI 07AU L 1 ח.גב איטלקית | D19: ='השוואה כוללת'!C152 -> 35 | E19: ='השוואה כוללת'!D152 -> 20 | F19: ='השוואה כוללת'!F152 -> -0.42857143
A20: 16 | B20: ='השוואה כוללת'!A177 -> 74824 | C20: ='השוואה כוללת'!B177 -> URI 59 L M 1 חגורת שבר צד ש | D20: ='השוואה כוללת'!C177 -> 7 | E20: ='השוואה כוללת'!D177 -> 4 | F20: ='השוואה כוללת'!F177 -> -0.42857143
A21: 17 | B21: ='השוואה כוללת'!A213 -> 83668 | C21: ='השוואה כוללת'!B213 -> URI FC335 1 טלק לכף הרגל | D21: ='השוואה כוללת'!C213 -> 773 | E21: ='השוואה כוללת'!D213 -> 462 | F21: ='השוואה כוללת'!F213 -> -0.40232859
A22: 18 | B22: ='השוואה כוללת'!A47 -> 34874 | C22: ='השוואה כוללת'!B47 -> URI 333 1 סד לקרסול | D22: ='השוואה כוללת'!C47 -> 16 | E22: ='השוואה כוללת'!D47 -> 10 | F22: ='השוואה כוללת'!F47 -> -0.375
A23: 19 | B23: ='השוואה כוללת'!A16 -> 16239 | C23: ='השוואה כוללת'!B16 -> 394W-35-381 גרבי קיץ לסוכרת | D23: ='השוואה כוללת'!C16 -> 27 | E23: ='השוואה כוללת'!D16 -> 17 | F23: ='השוואה כוללת'!F16 -> -0.37037037
A24: 20 | B24: ='השוואה כוללת'!A118 -> 64631 | C24: ='השוואה כוללת'!B118 -> URI 390W 39-42 1 גרבי כסף | D24: ='השוואה כוללת'!C118 -> 14 | E24: ='השוואה כוללת'!D118 -> 9 | F24: ='השוואה כוללת'!F118 -> -0.35714286

Sheet סיכום ומסקנות
A1: סיכום ומסקנות - השוואת מכירות ינואר-יולי 2025 מול 2026
A2: תאריך חישוב: | B2: ='השוואה כוללת'!B2 -> 46243
A4: נתונים כלליים:
A5: - סה"כ יחידות שנמכרו בינואר-יולי 2025: 14,701 (נוסחה: ='השוואה כוללת'!C234)
A6: - סה"כ יחידות שנמכרו בינואר-יולי 2026: 15,115 (נוסחה: ='השוואה כוללת'!D234)
A7: - שינוי כולל: +414 יחידות, +2.8%
A9: המגמה הכללית: המכירות עברו למגמה חיובית - עלייה של כ-2.8% בסך היחידות על פני שבעת החודשים הראשונים של 2026 לעומת אותה תקופה ב-2025. זה שינוי מהותי לעומת התמונה שעלתה מינואר-מאי בלבד (שם נראתה ירידה קלה של כ-0.9%): חודש יוני היה חזק במיוחד ל-2026 (1,924 יחידות ב-2025 מול 2,374 ב-2026, כ-+23.4%), ויולי הראה עלייה מתונה יותר (2,261 מול 2,315, כ-+2.4%). שני החודשים הנוספים הפכו את המגמה המצטברת מירידה קלה לעלייה נטו.
A11: סה"כ נבדקו 228 SKU-ים ייחודיים על פני 7 החודשים (219 מתוך ינואר-מאי, ועוד 9 SKU-ים חדשים שהופיעו לראשונה ביוני/יולי). מתוכם 163 עומדים בסף המינימלי של 5 יחידות ב-2025 (ינואר-יולי) ונכללים בטבלאות העליות/ירידות למטה - זה מסנן מוצרים שוליים עם בסיס נמוך שמעוותים אחוזי שינוי.
A13: העליות הבולטות ביותר:
A14: 1. ST20 1 חבק יד (SKU 82207): 17 -> 101 יחידות (+494%)
A15: 2. URI ST4221 מגן ברך +כ סיליק (SKU 83420): 18 -> 92 יחידות (+411%)
A16: 3. 808KT-P 1 טייפ קינזיולוגי (SKU 57662): 10 -> 50 יחידות (+400%)
A17: 4. 808KT-B 1 טייפ קינזיולוגי (SKU 57696): 13 -> 65 יחידות (+400%)
A18: 5. ST25 1 חבק לשורש כף היד (SKU 82206): 93 -> 438 יחידות (+371%)
... A36: - מוצרים עם 0 יחידות ב-2025 וסכום חיובי ב-2026 מסומנים בגיליון "השוואה כוללת" כ-"מוצר חדש" (במקום חלוקה באפס). 9 SKU-ים חדשים שלא הופיעו כלל בינואר-מאי נוספו לטבלת ה"השוואה כוללת" (שורות 225-233) עם נתוני יוני/יולי בלבד.

Sheet מקור-01
A1: נתוני מקור - ינואר (2025 מול 2026) - מקור: month-01.xlsx
A2: קוד SKU | B2: שם מוצר | C2: יחידות ינואר 2025 | D2: יחידות ינואר 2026
A3: 71086 | B3: URI 078M 1 | C3: 1 | D3: 5
A4: 29981 | B4: URI 35 XXL 1 מגן קרסול לבן | C4: 2 | D4: 8
A5: 16239 | B5: 394W-35-381 גרבי קיץ לסוכרת | C5: 2 | D5: 6
A6: 74672 | B6: URI 07AU XL 1 ח.גב איטלקית | C6: 1 | D6: 3
A7: 74683 | B7: URI 11 M 1 ח.בטן אורירית | C7: 3 | D7: 8
A8: 59659 | B8: URI 369 S-L 1 | C8: 10 | D8: 25
A9: 63416 | B9: URI 85 XL 1 מתלה ליד | C9: 5 | D9: 11
A10: 67935 | B10: URI 45 S 1 מגן ברך | C10: 6 | D10: 13
A11: 52147 | B11: URI FC321 1 מלח אמבט לכף ר | C11: 8 | D11: 17
A12: 64632 | B12: URI 390W 43-46 1 גרבי כסף | C12: 1 | D12: 2
A13: 74824 | B13: URI 59 L M 1 חגורת שבר צד ש | C13: 1 | D13: 2
A14: 20948 | B14: URI 35 XST 1 מגן קרסול פתוח | C14: 1 | D14: 2
... A191: 74825 | B191: URI 59L XL 1 חגורת שבר צד ש | C191: 0 | D191: -1

Sheet מקור-02
A1: נתוני מקור - פברואר (2025 מול 2026) - מקור: month-02.xlsx
A2: קוד SKU | B2: שם מוצר | C2: יחידות פברואר 2025 | D2: יחידות פברואר 2026
A3: 75762 | B3: URI 16 L-XL 1 חגורת הריון | C3: 2 | D3: 14
A4: 60478 | B4: URI PD3461 10 סכינים למקצוע | C4: 1 | D4: 5
A5: 8616 | B5: URI 3623 1 כרית ליישור אצבע | C5: 5 | D5: 20
A6: 25386 | B6: URI 3666 1 מפריד הלקס+כרית | C6: 2 | D6: 7
A7: 67960 | B7: URI 85 S 1 מיתלה ליד | C7: 3 | D7: 10
A8: 63421 | B8: URI 95 L 1 מגן מרפק | C8: 5 | D8: 15
A9: 71683 | B9: URI S 3622 1 מדבקה לשחרור ל | C9: 3 | D9: 9
A10: 71088 | B10: URI 078XL 1 | C10: 4 | D10: 10
A11: 75764 | B11: URI 16 XXL 1 חגורת הריון | C11: 2 | D11: 5
A12: 64632 | B12: URI 390W 43-46 1 גרבי כסף | C12: 2 | D12: 5
A13: 63418 | B13: URI 87 L1 חגו.לקיבוע תמ.אמה | C13: 5 | D13: 12
A14: 61962 | B14: URI 3677 1 מדבקה לשחרור לחץ | C14: 3 | D14: 7
... A185: 29790 | B185: URI 11STO L1 חגורה אחר ניתו | C185: 0 | D185: 1

Sheet מקור-03
A1: נתוני מקור - מרץ (2025 מול 2026) - מקור: month-03.xlsx
A2: קוד SKU | B2: שם מוצר | C2: יחידות מרץ 2025 | D2: יחידות מרץ 2026
A3: 45264 | B3: URI 34+ 1 מגן לקרסול | C3: 1 | D3: 6
A4: 86583 | B4: URI 87 XXL 1 מקבע כתף ויד | C4: 1 | D4: 5
A5: 29881 | B5: URI 34 XXL 1 מגן קרסול סגור | C5: 1 | D5: 4
A6: 60473 | B6: URI PD341 1 מקצוע להסרת עור | C6: 1 | D6: 4
A7: 64634 | B7: URI 390B 39-42 1 גרבי כסף | C7: 1 | D7: 4
A8: 71086 | B8: URI 078M 1 | C8: 2 | D8: 6
A9: 64631 | B9: URI 390W 39-42 1 גרבי כסף | C9: 1 | D9: 3
A10: 63419 | B10: URI 87 XL1 חגו.קיבוע תמ.אמה | C10: 2 | D10: 5
A11: 63421 | B11: URI 95 L 1 מגן מרפק | C11: 6 | D11: 14
A12: 60478 | B12: URI PD3461 10 סכינים למקצוע | C12: 2 | D12: 4
A13: 29977 | B13: URI 11TO XXL 1 חגורת בטן | C13: 1 | D13: 2
A14: 63407 | B14: URI 11U XL1 ח בטן אחר ניתוח | C14: 1 | D14: 2
... A191: 50061 | B191: URI 87 S 1 חגו.קיבוע תמ.אמה | C191: 0 | D191: 0

Sheet מקור-04
A1: נתוני מקור - אפריל (2025 מול 2026) - מקור: month-04.xlsx
A2: קוד SKU | B2: שם מוצר | C2: יחידות אפריל 2025 | D2: יחידות אפריל 2026
A3: 25386 | B3: URI 3666 1 מפריד הלקס+כרית | C3: 1 | D3: 6
A4: 64635 | B4: URI 390B 43-46 1 גרבי כסף | C4: 2 | D4: 11
A5: 16217 | B5: 394G-39-421 גרבי קיץ לסוכרת | C5: 1 | D5: 5
A6: 67925 | B6: URI 35 S 1 מגן קרסול לבן | C6: 3 | D6: 10
A7: 74846 | B7: URI 76 L 1 מיישר כתף | C7: 2 | D7: 6
A8: 74806 | B8: URI 49 M 1 מגן ירך | C8: 1 | D8: 3
A9: 21004 | B9: URI 45E XXL 1 מגן ברך ארוך | C9: 4 | D9: 10
A10: 52324 | B10: URI 078G M 1 חגורת גב אפורה | C10: 4 | D10: 10
A11: 20998 | B11: URI 11 XXL 1 ח.בטן אורירית | C11: 2 | D11: 5
A12: 71086 | B12: URI 078M 1 | C12: 2 | D12: 5
A13: 74684 | B13: URI 11 XL 1 ח.בטן אורירית | C13: 4 | D13: 9
A14: 52147 | B14: URI FC321 1 מלח אמבט לכף ר | C14: 5 | D14: 11
... A181: 82551 | B181: URI ST11 1 חגורת בטן | C181: 0 | D181: 1

Sheet מקור-05
A1: נתוני מקור - מאי (2025 מול 2026) - מקור: month-05.xlsx
A2: קוד SKU | B2: שם מוצר | C2: יחידות מאי 2025 | D2: יחידות מאי 2026
A3: 82208 | B3: URI ST37 1 חבק לקרסול | C3: 2 | D3: 23
A4: 83420 | B4: URI ST4221 מגן ברך +כ סיליק | C4: 2 | D4: 17
A5: 57696 | B5: 808KT-B 1 טייפ קינזיולוגי | C5: 2 | D5: 14
A6: 82202 | B6: ST91 1 מגן מרפק לטניס | C6: 4 | D6: 25
A7: 82206 | B7: ST25 1 חבק לשורש כף היד | C7: 10 | D7: 61
A8: 82207 | B8: ST20 1 חבק יד | C8: 4 | D8: 24
A9: 57662 | B9: 808KT-P 1 טייפ קינזיולוגי | C9: 2 | D9: 10
A10: 75764 | B10: URI 16 XXL 1 חגורת הריון | C10: 1 | D10: 5
A11: 63417 | B11: URI 87 M1 חגו.לקיבוע תמ.אמה | C11: 2 | D11: 9
A12: 19083 | B12: URI 40 1 רצועת פיקה לברך | C12: 1 | D12: 4
A13: 68750 | B13: 388B L 1 סד לילה שחור לבוהן | C13: 1 | D13: 4
A14: 57664 | B14: 808KT-BL 1 טייפ קינזיולוגי | C14: 4 | D14: 14
... A192: 88479 | B192: URI LF377 M 1 מדרס סיליקון | C192: 0 | D192: 1

Sheet מקור-06
A1: נתוני מקור - יוני (2025 מול 2026) - מקור: month-06.xlsx
A2: קוד SKU | B2: שם מוצר | C2: יחידות יוני 2025 | D2: יחידות יוני 2026
A3: 19083 | B3: URI 40 1 רצועת פיקה לברך | C3: 1 | D3: 7
A4: 57662 | B4: 808KT-P 1 טייפ קינזיולוגי | C4: 1 | D4: 7
A5: 35339 | B5: URI 307 S 1 זוג עקב סיל+נ כ | C5: 1 | D5: 6
A6: 80182 | B6: URI 3667 1 מגן בונין | C6: 4 | D6: 22
A7: 76453 | B7: URI 3675 1 מגן זרת מסיליקון | C7: 2 | D7: 8
A8: 60471 | B8: URI 365 XL 1 טבעת אלסטית | C8: 4 | D8: 14
A9: 63449 | B9: URI 40221 רצועה לפיקה +כרית | C9: 2 | D9: 7
A10: 52147 | B10: URI FC321 1 מלח אמבט לכף ר | C10: 12 | D10: 36
A11: 74684 | B11: URI 11 XL 1 ח.בטן אורירית | C11: 5 | D11: 15
A12: 71086 | B12: URI 078M 1 | C12: 2 | D12: 6
A13: 68750 | B13: 388B L 1 סד לילה שחור לבוהן | C13: 1 | D13: 3
A14: 82207 | B14: ST20 1 חבק יד | C14: 6 | D14: 16
... A141: 86583 | B141: URI 87 XXL 1 מקבע כתף ויד | C141: 1 | D141: 0
A142: 16214 | B142: 394-G-35-31 גרבי קיץ לסוכרת | C142: 2
A143: 28302 | B143: URI 34+XXL1 מ קרסול+עכב סגו | C143: 1
A144: 28323 | B144: URI T33 XXL 1 סד לקרסול | C144: 1
A145: 34874 | B145: URI 333 1 סד לקרסול | C145: 3
A146: 44007 | B146: URI 07AU 1 חגור.גב איטלקית | C146: 2
A147: 46309 | B147: STRAP4U 239B L-XL 1 | C147: 1
A148: 50055 | B148: URI 74 1 רצועה לשבר בעצם | C148: 1
A149: 50057 | B149: URI 76 1 מיישר כתף | C149: 2
A150: 64631 | B150: URI 390W 39-42 1 גרבי כסף | C150: 2
A151: 67053 | B151: URI 34 XS 1 מגן קרסול סגור | C151: 3
A152: 74806 | B152: URI 49 M 1 מגן ירך | C152: 1
A153: 74822 | B153: URI 59R XL1 חגורת שבר צד י | C153: 1
... A158: 88480 | B158: URI LF377 S 1 מדרס סיליקון | C158: 1
A159: 43277 | B159: 397A-39-42 1 גרבי טיסה | D159: 20
A160: 43283 | B160: 397A-43-46 1 גרבי טיסה | D160: 10
A161: 43248 | B161: 397A-35-38 1 גרבי טיסה | D161: 7
A162: 64635 | B162: URI 390B 43-46 1 גרבי כסף | D162: 7
A163: 68751 | B163: 388B R 1 סד לילה שחור לבוהן | D163: 6
A164: 74687 | B164: URI 11 TO L 1 ח בטן | D164: 4
A165: 74827 | B165: URI 59D M 1 חגורת שבר דו צד | D165: 3
A166: 74807 | B166: URI 49 XL 1 מגן ירך | D166: 2
A167: 74846 | B167: URI 76 L 1 מיישר כתף | D167: 2
A168: 74848 | B168: URI 76 XL 1 מיישר כתף | D168: 2
A169: 87828 | B169: ST49 1 מגן ירך | D169: 2
A170: 20996 | B170: URI 07AU XXL 1 | D170: 1
...

Sheet מקור-07
A1: נתוני מקור - יולי (2025 מול 2026) - מקור: month-07.xlsx
A2: קוד SKU | B2: שם מוצר | C2: יחידות יולי 2025 | D2: יחידות יולי 2026
A3: 18559 | B3: URI 8200 1 כרית חום וקור | C3: 1 | D3: 12
A4: 74683 | B4: URI 11 M 1 ח.בטן אורירית | C4: 1 | D4: 7
A5: 64635 | B5: URI 390B 43-46 1 גרבי כסף | C5: 1 | D5: 5
A6: 75762 | B6: URI 16 L-XL 1 חגורת הריון | C6: 2 | D6: 8
A7: 65743 | B7: URI LF 360 1 מדרס מטטרזלי | C7: 2 | D7: 7
A8: 75763 | B8: URI 16 S-M 1 חגורת הריון | C8: 2 | D8: 7
A9: 16244 | B9: 394W-39-421 גרבי קיץ לסוכרת | C9: 2 | D9: 6
A10: 74821 | B10: URI 59R M.1 חגורת שבר צד י | C10: 1 | D10: 3
A11: 71087 | B11: URI 078L 1 | C11: 6 | D11: 15
A12: 16214 | B12: 394-G-35-31 גרבי קיץ לסוכרת | C12: 2 | D12: 5
A13: 74846 | B13: URI 76 L 1 מיישר כתף | C13: 2 | D13: 5
A14: 74710 | B14: URI 21 XL 1 חבק יד ארוך | C14: 7 | D14: 17
... A151: 29984 | B151: URI 95 XS 1 מגן מרפק | C151: 8 | D151: 1
A152: 28297 | B152: URI 13 XL1 חגורה ללשבר טבור | C152: 1
A153: 28331 | B153: URI T78 XXL 1 תומך זרוע כתף | C153: 1
A154: 29794 | B154: URI 11STO XXL1 חגורה א ניתו | C154: 1
A155: 29977 | B155: URI 11TO XXL 1 חגורת בטן | C155: 2
A156: 37229 | B156: URI 59R 1 חגורת שבר לצד י | C156: 1
A157: 44007 | B157: URI 07AU 1 חגור.גב איטלקית | C157: 1
A158: 46306 | B158: STRAP4U 239B S-M 1 | C158: 2
A159: 50022 | B159: URI 38 1 חבישת הלוקס ולגוס | C159: 1
A160: 64637 | B160: URI 390G 39-42 1 גרבי כסף | C160: 1
A161: 74671 | B161: URI 07AU M 1 ח גב איטלקית | C161: 1
A162: 74672 | B162: URI 07AU XL 1 ח.גב איטלקית | C162: 6
A163: 74824 | B163: URI 59 L M 1 חגורת שבר צד ש | C163: 3
... A174: 88479 | B174: URI LF377 M 1 מדרס סיליקון | C174: 1
A175: 43277 | B175: 397A-39-42 1 גרבי טיסה | D175: 29
A176: 43283 | B176: 397A-43-46 1 גרבי טיסה | D176: 25
A177: 43248 | B177: 397A-35-38 1 גרבי טיסה | D177: 12
A178: 64638 | B178: URI 390G 43-46 1 גרבי כסף | D178: 4
A179: 68750 | B179: 388B L 1 סד לילה שחור לבוהן | C179: 0 | D179: 2
A180: 75764 | B180: URI 16 XXL 1 חגורת הריון | D180: 2
A181: 88480 | B181: URI LF377 S 1 מדרס סיליקון | D181: 2
A182: 28937 | B182: URI 70N XS 1 חגורת פאבליק | D182: 1
A183: 37498 | B183: URI SH333 1 מקבע קרסול | D183: 1
A184: 43454 | B184: SH422 5 1 תומך ברך גנושילד | D184: 1
A185: 50055 | B185: URI 74 1 רצועה לשבר בעצם | D185: 1
A186: 63404 | B186: URI 11U S 1 ח בטן אחר ניתוח | D186: 1
...
