Workbook

Sheet Index
A1: Sales Comparison 2025 vs 2026 - by Customer (PPlay1 of uriel report)
A2: Calculation date: | B2: 46284
A3: Each sheet below is a live comparison table (formulas, not hardcoded values) for one customer, built from the "Source 2025"/"Source 2026" raw-data sheets. "Super Pharm" is on the sheet named "Comparison" (kept from the previous build). Click a customer name to jump to its sheet.
A5: Customer | B5: Sheet | C5: # Product Codes | D5: Quantity 2025 | E5: Quantity 2026 | F5: Qty Change % | G5: Amount 2025 (₪) | H5: Amount 2026 (₪) | I5: Amount Change %
A6: 0בתי טבע | B6: 0בתי טבע | C6: 1 | D6: ='0בתי טבע'!C8 -> 0 | E6: ='0בתי טבע'!D8 -> 2 | F6: ='0בתי טבע'!F8 -> N/A | G6: ='0בתי טבע'!G8 -> 0 | H6: ='0בתי טבע'!H8 -> 120 | I6: ='0בתי טבע'!J8 -> N/A
A7: 0בתי טבע רשתות | B7: 0בתי טבע רשתות | C7: 0 | D7: ='0בתי טבע רשתות'!C7 -> 0 | E7: ='0בתי טבע רשתות'!D7 -> 0 | F7: ='0בתי טבע רשתות'!F7 -> 0 | G7: ='0בתי טבע רשתות'!G7 -> 0 | H7: ='0בתי טבע רשתות'!H7 -> 0 | I7: ='0בתי טבע רשתות'!J7 -> 0
A8: 0בתי מרקחת | B8: 0בתי מרקחת | C8: 278 | D8: ='0בתי מרקחת'!C285 -> 53153 | E8: ='0בתי מרקחת'!D285 -> 32995 | F8: ='0בתי מרקחת'!F285 -> -0.37924482 | G8: ='0בתי מרקחת'!G285 -> 1940731.5 | H8: ='0בתי מרקחת'!H285 -> 1283059.8 | I8: ='0בתי מרקחת'!J285 -> -0.33887825
A9: 0כללי | B9: 0כללי | C9: 0 | D9: =0כללי!C7 -> 0 | E9: =0כללי!D7 -> 0 | F9: =0כללי!F7 -> 0 | G9: =0כללי!G7 -> 0 | H9: =0כללי!H7 -> 0 | I9: =0כללי!J7 -> 0
A10: 0מפיצי משנה | B10: 0מפיצי משנה | C10: 43 | D10: ='0מפיצי משנה'!C50 -> 374 | E10: ='0מפיצי משנה'!D50 -> 175 | F10: ='0מפיצי משנה'!F50 -> -0.53208556 | G10: ='0מפיצי משנה'!G50 -> 9812.1 | H10: ='0מפיצי משנה'!H50 -> 4549.9 | I10: ='0מפיצי משנה'!J50 -> -0.53629702
A11: 0פארמים | B11: 0פארמים | C11: 255 | D11: =0פארמים!C262 -> 204428 | E11: =0פארמים!D262 -> 137851 | F11: =0פארמים!F262 -> -0.32567457 | G11: =0פארמים!G262 -> 7597886.3 | H11: =0פארמים!H262 -> 5165969.3 | I11: =0פארמים!J262 -> -0.3200781
A12: BE | B12: BE | C12: 0 | D12: =BE!C7 -> 0 | E12: =BE!D7 -> 0 | F12: =BE!F7 -> 0 | G12: =BE!G7 -> 0 | H12: =BE!H7 -> 0 | I12: =BE!J7 -> 0
A13: אילת BE | B13: אילת BE | C13: 116 | D13: ='אילת BE'!C123 -> 2393 | E13: ='אילת BE'!D123 -> 1501 | F13: ='אילת BE'!F123 -> -0.37275387 | G13: ='אילת BE'!G123 -> 65581.4 | H13: ='אילת BE'!H123 -> 49349.3 | I13: ='אילת BE'!J123 -> -0.24751073
A14: אילת זיכויי BE | B14: אילת זיכויי BE | C14: 23 | D14: ='אילת זיכויי BE'!C30 -> -47 | E14: ='אילת זיכויי BE'!D30 -> -5 | F14: ='אילת זיכויי BE'!F30 -> -0.89361702 | G14: ='אילת זיכויי BE'!G30 -> -2050 | H14: ='אילת זיכויי BE'!H30 -> -517.8 | I14: ='אילת זיכויי BE'!J30 -> -0.74741463
A15: גוד פארם | B15: גוד פארם | C15: 42 | D15: ='גוד פארם'!C49 -> 211 | E15: ='גוד פארם'!D49 -> 125 | F15: ='גוד פארם'!F49 -> -0.40758294 | G15: ='גוד פארם'!G49 -> 7329.5 | H15: ='גוד פארם'!H49 -> 4352.2 | I15: ='גוד פארם'!J49 -> -0.40620779
A16: גוד פארם מרכז | B16: גוד פארם מרכז | C16: 99 | D16: ='גוד פארם מרכז'!C106 -> 444 | E16: ='גוד פארם מרכז'!D106 -> 310 | F16: ='גוד פארם מרכז'!F106 -> -0.3018018 | G16: ='גוד פארם מרכז'!G106 -> 11837 | H16: ='גוד פארם מרכז'!H106 -> 8839.1 | I16: ='גוד פארם מרכז'!J106 -> -0.25326519
A17: הפרכל הפרפארם | B17: הפרכל הפרפארם | C17: 52 | D17: ='הפרכל הפרפארם'!C59 -> 316 | E17: ='הפרכל הפרפארם'!D59 -> 233 | F17: ='הפרכל הפרפארם'!F59 -> -0.26265823 | G17: ='הפרכל הפרפארם'!G59 -> 9222.1 | H17: ='הפרכל הפרפארם'!H59 -> 7173.6 | I17: ='הפרכל הפרפארם'!J59 -> -0.22212945
A18: זיכויים BE | B18: זיכויים BE | C18: 150 | D18: ='זיכויים BE'!C157 -> -1274 | E18: ='זיכויים BE'!D157 -> -660 | F18: ='זיכויים BE'!F157 -> -0.48194662 | G18: ='זיכויים BE'!G157 -> -78358.9 | H18: ='זיכויים BE'!H157 -> -35015.9 | I18: ='זיכויים BE'!J157 -> -0.55313436
A19: סופרפארם | B19: Comparison | C19: 219 | D19: =Comparison!C226 -> 176505 | E19: =Comparison!D226 -> 118307 | F19: =Comparison!F226 -> -0.32972437 | G19: =Comparison!G226 -> 6689220.5 | H19: =Comparison!H226 -> 4476515.3 | I19: =Comparison!J226 -> -0.3307867
A20: שופרסל BE | B20: שופרסל BE | C20: 149 | D20: ='שופרסל BE'!C156 -> 25880 | E20: ='שופרסל BE'!D156 -> 18040 | F20: ='שופרסל BE'!F156 -> -0.30293663 | G20: ='שופרסל BE'!G156 -> 895106.5 | H20: ='שופרסל BE'!H156 -> 655276.6 | I20: ='שופרסל BE'!J156 -> -0.26793449
A21: 0צרכנים פרטיים | B21: 0צרכנים פרטיים | C21: 23 | D21: ='0צרכנים פרטיים'!C30 -> 34 | E21: ='0צרכנים פרטיים'!D30 -> 8 | F21: ='0צרכנים פרטיים'!F30 -> -0.76470588 | G21: ='0צרכנים פרטיים'!G30 -> 1620.1 | H21: ='0צרכנים פרטיים'!H30 -> 454.5 | I21: ='0צרכנים פרטיים'!J30 -> -0.71946176
A22: 0קופות חולים | B22: 0קופות חולים | C22: 107 | D22: ='0קופות חולים'!C114 -> 0 | E22: ='0קופות חולים'!D114 -> 10037 | F22: ='0קופות חולים'!F114 -> N/A | G22: ='0קופות חולים'!G114 -> 0 | H22: ='0קופות חולים'!H114 -> 307514.4 | I22: ='0קופות חולים'!J114 -> N/A
A23: 0שונות | B23: 0שונות | C23: 39 | D23: =0שונות!C46 -> -39 | E23: =0שונות!D46 -> -128 | F23: =0שונות!F46 -> 2.2820513 | G23: =0שונות!G46 -> -3696.5 | H23: =0שונות!H46 -> -7567.7 | I23: =0שונות!J46 -> 1.0472609

Sheet Comparison
A1: Sales Comparison 2025 vs 2026 - Customer: סופרפארם (by Product CODE)
A2: Calculation date: | B2: 46284
A3: Source: PPlay1 of uriel (Reporter) product x customer pivot reports for 2025 and 2026, customer column "סופרפארם" only (raw values in 'Source 2025'!$Q:$Q / 'Source 2026'!$Q:$Q). Each file has two data blocks: "נטו" (Net Amount, NIS) and "סהכ יחידות" (Total Units). Product CODE parsed as the first token of column B in the original file (before the first space); size/color variants sharing the same base CODE are summed together via SUMIFS. Rows below only include product codes with non-zero quantity or amount for this customer in at least one of the two years; codes that are 0 for this customer in both years (sold only to other customers) were excluded as not relevant to this comparison.
A5: Product Code | B5: Product Name | C5: Quantity 2025 | D5: Quantity 2026 | E5: Quantity Change | F5: Quantity Change % | G5: Amount 2025 (₪) | H5: Amount 2026 (₪) | I5: Amount Change (₪) | J5: Amount Change %
A6: מדרסי | B6: =IFERROR(INDEX('Source 2026'!$C:$C,MATCH($A6,'Source 2026'!$B:$B,0)),IFERROR(INDEX('Source 2025'!$C:$C,MATCH($A6,'Source 2025'!$B:$B,0)),"")) -> אפיק ג'ל מולט.ספורט35-38 | C6: =SUMIFS('Source 2025'!$Q:$Q,'Source 2025'!$B:$B,$A6,'Source 2025'!$A:$A,"Quantity (units)") -> 2855 | D6: =SUMIFS('Source 2026'!$Q:$Q,'Source 2026'!$B:$B,$A6,'Source 2026'!$A:$A,"Quantity (units)") -> 481 | E6: =D6-C6 -> -2374 | F6: =IF(AND(C6=0,D6=0),0,IF(C6=0,"New",(D6-C6)/C6)) -> -0.83152364 | G6: =SUMIFS('Source 2025'!$Q:$Q,'Source 2025'!$B:$B,$A6,'Source 2025'!$A:$A,"Amount (NIS)") -> 265726.2 | H6: =SUMIFS('Source 2026'!$Q:$Q,'Source 2026'!$B:$B,$A6,'Source 2026'!$A:$A,"Amount (NIS)") -> 47626.6 | I6: =H6-G6 -> -218099.6 | J6: =IF(AND(G6=0,H6=0),0,IF(G6=0,"New",(H6-G6)/G6)) -> -0.82076814
A7: 35-38 | B7: =IFERROR(INDEX('Source 2026'!$C:$C,MATCH($A7,'Source 2026'!$B:$B,0)),IFERROR(INDEX('Source 2025'!$C:$C,MATCH($A7,'Source 2025'!$B:$B,0)),"")) -> מדרסי אפיק ג'ל נוחות | C7: =SUMIFS('Source 2025'!$Q:$Q,'Source 2025'!$B:$B,$A7,'Source 2025'!$A:$A,"Quantity (units)") -> 1776 | D7: =SUMIFS('Source 2026'!$Q:$Q,'Source 2026'!$B:$B,$A7,'Source 2026'!$A:$A,"Quantity (units)") -> 112 | E7: =D7-C7 -> -1664 | F7: =IF(AND(C7=0,D7=0),0,IF(C7=0,"New",(D7-C7)/C7)) -> -0.93693694 | G7: =SUMIFS('Source 2025'!$Q:$Q,'Source 2025'!$B:$B,$A7,'Source 2025'!$A:$A,"Amount (NIS)") -> 164431.7 | H7: =SUMIFS('Source 2026'!$Q:$Q,'Source 2026'!$B:$B,$A7,'Source 2026'!$A:$A,"Amount (NIS)") -> 11519.9 | I7: =H7-G7 -> -152911.8 | J7: =IF(AND(G7=0,H7=0),0,IF(G7=0,"New",(H7-G7)/G7)) -> -0.92994112
A8: 39-42 | B8: =IFERROR(INDEX('Source 2026'!$C:$C,MATCH($A8,'Source 2026'!$B:$B,0)),IFERROR(INDEX('Source 2025'!$C:$C,MATCH($A8,'Source 2025'!$B:$B,0)),"")) -> מדרסי אפיק ג'ל נוחות | C8: =SUMIFS('Source 2025'!$Q:$Q,'Source 2025'!$B:$B,$A8,'Source 2025'!$A:$A,"Quantity (units)") -> 2025 | D8: =SUMIFS('Source 2026'!$Q:$Q,'Source 2026'!$B:$B,$A8,'Source 2026'!$A:$A,"Quantity (units)") -> 522 | E8: =D8-C8 -> -1503 | F8: =IF(AND(C8=0,D8=0),0,IF(C8=0,"New",(D8-C8)/C8)) -> -0.74222222 | G8: =SUMIFS('Source 2025'!$Q:$Q,'Source 2025'!$B:$B,$A8,'Source 2025'!$A:$A,"Amount (NIS)") -> 188767.1 | H8: =SUMIFS('Source 2026'!$Q:$Q,'Source 2026'!$B:$B,$A8,'Source 2026'!$A:$A,"Amount (NIS)") -> 52314 | I8: =H8-G8 -> -136453.1 | J8: =IF(AND(G8=0,H8=0),0,IF(G8=0,"New",(H8-G8)/G8)) -> -0.72286484
A9: 43-47 | B9: =IFERROR(INDEX('Source 2026'!$C:$C,MATCH($A9,'Source 2026'!$B:$B,0)),IFERROR(INDEX('Source 2025'!$C:$C,MATCH($A9,'Source 2025'!$B:$B,0)),"")) -> מדרסי אפיק ג'ל נוחות | C9: =SUMIFS('Source 2025'!$Q:$Q,'Source 2025'!$B:$B,$A9,'Source 2025'!$A:$A,"Quantity (units)") -> 2122 | D9: =SUMIFS('Source 2026'!$Q:$Q,'Source 2026'!$B:$B,$A9,'Source 2026'!$A:$A,"Quantity (units)") -> 789 | E9: =D9-C9 -> -1333 | F9: =IF(AND(C9=0,D9=0),0,IF(C9=0,"New",(D9-C9)/C9)) -> -0.62818096 | G9: =SUMIFS('Source 2025'!$Q:$Q,'Source 2025'!$B:$B,$A9,'Source 2025'!$A:$A,"Amount (NIS)") -> 197774.9 | H9: =SUMIFS('Source 2026'!$Q:$Q,'Source 2026'!$B:$B,$A9,'Source 2026'!$A:$A,"Amount (NIS)") -> 78734.4 | I9: =H9-G9 -> -119040.5 | J9: =IF(AND(G9=0,H9=0),0,IF(G9=0,"New",(H9-G9)/G9)) -> -0.60189893
A10: 26 | B10: =IFERROR(INDEX('Source 2026'!$C:$C,MATCH($A10,'Source 2026'!$B:$B,0)),IFERROR(INDEX('Source 2025'!$C:$C,MATCH($A10,'Source 2025'!$B:$B,0)),"")) -> L סד ליד דו צדדי לאחר שבר | C10: =SUMIFS('Source 2025'!$Q:$Q,'Source 2025'!$B:$B,$A10,'Source 2025'!$A:$A,"Quantity (units)") -> 2550 | D10: =SUMIFS('Source 2026'!$Q:$Q,'Source 2026'!$B:$B,$A10,'Source 2026'!$A:$A,"Quantity (units)") -> 1172 | E10: =D10-C10 -> -1378 | F10: =IF(AND(C10=0,D10=0),0,IF(C10=0,"New",(D10-C10)/C10)) -> -0.54039216 | G10: =SUMIFS('Source 2025'!$Q:$Q,'Source 2025'!$B:$B,$A10,'Source 2025'!$A:$A,"Amount (NIS)") -> 208574.2 | H10: =SUMIFS('Source 2026'!$Q:$Q,'Source 2026'!$B:$B,$A10,'Source 2026'!$A:$A,"Amount (NIS)") -> 97035.9 | I10: =H10-G10 -> -111538.3 | J10: =IF(AND(G10=0,H10=0),0,IF(G10=0,"New",(H10-G10)/G10)) -> -0.53476557
A11: 35C | B11: =IFERROR(INDEX('Source 2026'!$C:$C,MATCH($A11,'Source 2026'!$B:$B,0)),IFERROR(INDEX('Source 2025'!$C:$C,MATCH($A11,'Source 2025'!$B:$B,0)),"")) -> S מגן קרסול חום | C11: =SUMIFS('Source 2025'!$Q:$Q,'Source 2025'!$B:$B,$A11,'Source 2025'!$A:$A,"Quantity (units)") -> 10751 | D11: =SUMIFS('Source 2026'!$Q:$Q,'Source 2026'!$B:$B,$A11,'Source 2026'!$A:$A,"Quantity (units)") -> 7007 | E11: =D11-C11 -> -3744 | F11: =IF(AND(C11=0,D11=0),0,IF(C11=0,"New",(D11-C11)/C11)) -> -0.34824667 | G11: =SUMIFS('Source 2025'!$Q:$Q,'Source 2025'!$B:$B,$A11,'Source 2025'!$A:$A,"Amount (NIS)") -> 276617 | H11: =SUMIFS('Source 2026'!$Q:$Q,'Source 2026'!$B:$B,$A11,'Source 2026'!$A:$A,"Amount (NIS)") -> 183180 | I11: =H11-G11 -> -93437 | J11: =IF(AND(G11=0,H11=0),0,IF(G11=0,"New",(H11-G11)/G11)) -> -0.33778473
A12: 21 | B12: =IFERROR(INDEX('Source 2026'!$C:$C,MATCH($A12,'Source 2026'!$B:$B,0)),IFERROR(INDEX('Source 2025'!$C:$C,MATCH($A12,'Source 2025'!$B:$B,0)),"")) -> S חבק יד ארוך | C12: =SUMIFS('Source 2025'!$Q:$Q,'Source 2025'!$B:$B,$A12,'Source 2025'!$A:$A,"Quantity (units)") -> 8258 | D12: =SUMIFS('Source 2026'!$Q:$Q,'Source 2026'!$B:$B,$A12,'Source 2026'!$A:$A,"Quantity (units)") -> 5458 | E12: =D12-C12 -> -2800 | F12: =IF(AND(C12=0,D12=0),0,IF(C12=0,"New",(D12-C12)/C12)) -> -0.33906515 | G12: =SUMIFS('Source 2025'!$Q:$Q,'Source 2025'!$B:$B,$A12,'Source 2025'!$A:$A,"Amount (NIS)") -> 269862.5 | H12: =SUMIFS('Source 2026'!$Q:$Q,'Source 2026'!$B:$B,$A12,'Source 2026'!$A:$A,"Amount (NIS)") -> 179838.7 | I12: =H12-G12 -> -90023.8 | J12: =IF(AND(G12=0,H12=0),0,IF(G12=0,"New",(H12-G12)/G12)) -> -0.33359137
A13: 397A-גרבי | B13: =IFERROR(INDEX('Source 2026'!$C:$C,MATCH($A13,'Source 2026'!$B:$B,0)),IFERROR(INDEX('Source 2025'!$C:$C,MATCH($A13,'Source 2025'!$B:$B,0)),"")) -> טיסה אנטי בקטרי35-38 | C13: =SUMIFS('Source 2025'!$Q:$Q,'Source 2025'!$B:$B,$A13,'Source 2025'!$A:$A,"Quantity (units)") -> 0 | D13: =SUMIFS('Source 2026'!$Q:$Q,'Source 2026'!$B:$B,$A13,'Source 2026'!$A:$A,"Quantity (units)") -> 1552 | E13: =D13-C13 -> 1552 | F13: =IF(AND(C13=0,D13=0),0,IF(C13=0,"New",(D13-C13)/C13)) -> New | G13: =SUMIFS('Source 2025'!$Q:$Q,'Source 2025'!$B:$B,$A13,'Source 2025'!$A:$A,"Amount (NIS)") -> 0 | H13: =SUMIFS('Source 2026'!$Q:$Q,'Source 2026'!$B:$B,$A13,'Source 2026'!$A:$A,"Amount (NIS)") -> 84761 | I13: =H13-G13 -> 84761 | J13: =IF(AND(G13=0,H13=0),0,IF(G13=0,"New",(H13-G13)/G13)) -> New
A14: 397 | B14: =IFERROR(INDEX('Source 2026'!$C:$C,MATCH($A14,'Source 2026'!$B:$B,0)),IFERROR(INDEX('Source 2025'!$C:$C,MATCH($A14,'Source 2025'!$B:$B,0)),"")) -> 35-38 גרבי טיסה מידה | C14: =SUMIFS('Source 2025'!$Q:$Q,'Source 2025'!$B:$B,$A14,'Source 2025'!$A:$A,"Quantity (units)") -> 1506 | D14: =SUMIFS('Source 2026'!$Q:$Q,'Source 2026'!$B:$B,$A14,'Source 2026'!$A:$A,"Quantity (units)") -> -10 | E14: =D14-C14 -> -1516 | F14: =IF(AND(C14=0,D14=0),0,IF(C14=0,"New",(D14-C14)/C14)) -> -1.0066401 | G14: =SUMIFS('Source 2025'!$Q:$Q,'Source 2025'!$B:$B,$A14,'Source 2025'!$A:$A,"Amount (NIS)") -> 79204.9 | H14: =SUMIFS('Source 2026'!$Q:$Q,'Source 2026'!$B:$B,$A14,'Source 2026'!$A:$A,"Amount (NIS)") -> -514.5 | I14: =H14-G14 -> -79719.4 | J14: =IF(AND(G14=0,H14=0),0,IF(G14=0,"New",(H14-G14)/G14)) -> -1.0064958
A15: 34 | B15: =IFERROR(INDEX('Source 2026'!$C:$C,MATCH($A15,'Source 2026'!$B:$B,0)),IFERROR(INDEX('Source 2025'!$C:$C,MATCH($A15,'Source 2025'!$B:$B,0)),"")) -> M מגן קרסול עקב סגור | C15: =SUMIFS('Source 2025'!$Q:$Q,'Source 2025'!$B:$B,$A15,'Source 2025'!$A:$A,"Quantity (units)") -> 6177 | D15: =SUMIFS('Source 2026'!$Q:$Q,'Source 2026'!$B:$B,$A15,'Source 2026'!$A:$A,"Quantity (units)") -> 4200 | E15: =D15-C15 -> -1977 | F15: =IF(AND(C15=0,D15=0),0,IF(C15=0,"New",(D15-C15)/C15)) -> -0.32005828 | G15: =SUMIFS('Source 2025'!$Q:$Q,'Source 2025'!$B:$B,$A15,'Source 2025'!$A:$A,"Amount (NIS)") -> 231846.4 | H15: =SUMIFS('Source 2026'!$Q:$Q,'Source 2026'!$B:$B,$A15,'Source 2026'!$A:$A,"Amount (NIS)") -> 159810.8 | I15: =H15-G15 -> -72035.6 | J15: =IF(AND(G15=0,H15=0),0,IF(G15=0,"New",(H15-G15)/G15)) -> -0.31070398
A16: AC75 | B16: =IFERROR(INDEX('Source 2026'!$C:$C,MATCH($A16,'Source 2026'!$B:$B,0)),IFERROR(INDEX('Source 2025'!$C:$C,MATCH($A16,'Source 2025'!$B:$B,0)),"")) -> מישר כתפיים אקטיב | C16: =SUMIFS('Source 2025'!$Q:$Q,'Source 2025'!$B:$B,$A16,'Source 2025'!$A:$A,"Quantity (units)") -> 659 | D16: =SUMIFS('Source 2026'!$Q:$Q,'Source 2026'!$B:$B,$A16,'Source 2026'!$A:$A,"Quantity (units)") -> 1707 | E16: =D16-C16 -> 1048 | F16: =IF(AND(C16=0,D16=0),0,IF(C16=0,"New",(D16-C16)/C16)) -> 1.5902883 | G16: =SUMIFS('Source 2025'!$Q:$Q,'Source 2025'!$B:$B,$A16,'Source 2025'!$A:$A,"Amount (NIS)") -> 40255.2 | H16: =SUMIFS('Source 2026'!$Q:$Q,'Source 2026'!$B:$B,$A16,'Source 2026'!$A:$A,"Amount (NIS)") -> 109715.2 | I16: =H16-G16 -> 69460 | J16: =IF(AND(G16=0,H16=0),0,IF(G16=0,"New",(H16-G16)/G16)) -> 1.7254914
A17: 45C | B17: =IFERROR(INDEX('Source 2026'!$C:$C,MATCH($A17,'Source 2026'!$B:$B,0)),IFERROR(INDEX('Source 2025'!$C:$C,MATCH($A17,'Source 2025'!$B:$B,0)),"")) -> S מגן ברך חום | C17: =SUMIFS('Source 2025'!$Q:$Q,'Source 2025'!$B:$B,$A17,'Source 2025'!$A:$A,"Quantity (units)") -> 10069 | D17: =SUMIFS('Source 2026'!$Q:$Q,'Source 2026'!$B:$B,$A17,'Source 2026'!$A:$A,"Quantity (units)") -> 7331 | E17: =D17-C17 -> -2738 | F17: =IF(AND(C17=0,D17=0),0,IF(C17=0,"New",(D17-C17)/C17)) -> -0.27192373 | G17: =SUMIFS('Source 2025'!$Q:$Q,'Source 2025'!$B:$B,$A17,'Source 2025'!$A:$A,"Amount (NIS)") -> 259116.9 | H17: =SUMIFS('Source 2026'!$Q:$Q,'Source 2026'!$B:$B,$A17,'Source 2026'!$A:$A,"Amount (NIS)") -> 190767.7 | I17: =H17-G17 -> -68349.2 | J17: =IF(AND(G17=0,H17=0),0,IF(G17=0,"New",(H17-G17)/G17)) -> -0.26377747
... A224: 12 | B224: =IFERROR(INDEX('Source 2026'!$C:$C,MATCH($A224,'Source 2026'!$B:$B,0)),IFERROR(INDEX('Source 2025'!$C:$C,MATCH($A224,'Source 2025'!$B:$B,0)),"")) -> XL ח.גב מגנטית+מוטות תמיכה | C224: =SUMIFS('Source 2025'!$Q:$Q,'Source 2025'!$B:$B,$A224,'Source 2025'!$A:$A,"Quantity (units)") -> -1 | D224: =SUMIFS('Source 2026'!$Q:$Q,'Source 2026'!$B:$B,$A224,'Source 2026'!$A:$A,"Quantity (units)") -> -1 | E224: =D224-C224 -> 0 | F224: =IF(AND(C224=0,D224=0),0,IF(C224=0,"New",(D224-C224)/C224)) -> 0 | G224: =SUMIFS('Source 2025'!$Q:$Q,'Source 2025'!$B:$B,$A224,'Source 2025'!$A:$A,"Amount (NIS)") -> -178.6 | H224: =SUMIFS('Source 2026'!$Q:$Q,'Source 2026'!$B:$B,$A224,'Source 2026'!$A:$A,"Amount (NIS)") -> -178.6 | I224: =H224-G224 -> 0 | J224: =IF(AND(G224=0,H224=0),0,IF(G224=0,"New",(H224-G224)/G224)) -> 0
B226: TOTAL | C226: =SUM(C6:C224) -> 176505 | D226: =SUM(D6:D224) -> 118307 | E226: =SUM(E6:E224) -> -58198 | F226: =IF(C226=0,"N/A",E226/C226) -> -0.32972437 | G226: =SUM(G6:G224) -> 6689220.5 | H226: =SUM(H6:H224) -> 4476515.3 | I226: =SUM(I6:I224) -> -2212705.2 | J226: =IF(G226=0,"N/A",I226/G226) -> -0.3307867

Sheet 0בתי טבע
A1: Sales Comparison 2025 vs 2026 - Customer: 0בתי טבע (by Product CODE)
A2: Calculation date: | B2: 46284
A3: Source: PPlay1 of uriel (Reporter) product x customer pivot reports for 2025 and 2026, customer column "0בתי טבע" only (raw values in 'Source 2025'!$D:$D / 'Source 2026'!$D:$D). Each file has two data blocks: "נטו" (Net Amount, NIS) and "סהכ יחידות" (Total Units). Product CODE parsed as the first token of column B in the original file (before the first space); size/color variants sharing the same base CODE are summed together via SUMIFS. Rows below only include product codes with non-zero quantity or amount for this customer in at least one of the two years; codes that are 0 for this customer in both years (sold only to other customers) were excluded as not relevant to this comparison.
A5: Product Code | B5: Product Name | C5: Quantity 2025 | D5: Quantity 2026 | E5: Quantity Change | F5: Quantity Change % | G5: Amount 2025 (₪) | H5: Amount 2026 (₪) | I5: Amount Change (₪) | J5: Amount Change %
A6: 333 | B6: =IFERROR(INDEX('Source 2026'!$C:$C,MATCH($A6,'Source 2026'!$B:$B,0)),IFERROR(INDEX('Source 2025'!$C:$C,MATCH($A6,'Source 2025'!$B:$B,0)),"")) -> סד לקרסול עם כריות אויר | C6: =SUMIFS('Source 2025'!$D:$D,'Source 2025'!$B:$B,$A6,'Source 2025'!$A:$A,"Quantity (units)") -> 0 | D6: =SUMIFS('Source 2026'!$D:$D,'Source 2026'!$B:$B,$A6,'Source 2026'!$A:$A,"Quantity (units)") -> 2 | E6: =D6-C6 -> 2 | F6: =IF(AND(C6=0,D6=0),0,IF(C6=0,"New",(D6-C6)/C6)) -> New | G6: =SUMIFS('Source 2025'!$D:$D,'Source 2025'!$B:$B,$A6,'Source 2025'!$A:$A,"Amount (NIS)") -> 0 | H6: =SUMIFS('Source 2026'!$D:$D,'Source 2026'!$B:$B,$A6,'Source 2026'!$A:$A,"Amount (NIS)") -> 120 | I6: =H6-G6 -> 120 | J6: =IF(AND(G6=0,H6=0),0,IF(G6=0,"New",(H6-G6)/G6)) -> New
B8: TOTAL | C8: =SUM(C6:C6) -> 0 | D8: =SUM(D6:D6) -> 2 | E8: =SUM(E6:E6) -> 2 | F8: =IF(C8=0,"N/A",E8/C8) -> N/A | G8: =SUM(G6:G6) -> 0 | H8: =SUM(H6:H6) -> 120 | I8: =SUM(I6:I6) -> 120 | J8: =IF(G8=0,"N/A",I8/G8) -> N/A

Sheet 0בתי טבע רשתות
A1: Sales Comparison 2025 vs 2026 - Customer: 0בתי טבע רשתות (by Product CODE)
A2: Calculation date: | B2: 46284
A3: Source: PPlay1 of uriel (Reporter) product x customer pivot reports for 2025 and 2026, customer column "0בתי טבע רשתות" only (raw values in 'Source 2025'!$E:$E / 'Source 2026'!$E:$E). Each file has two data blocks: "נטו" (Net Amount, NIS) and "סהכ יחידות" (Total Units). Product CODE parsed as the first token of column B in the original file (before the first space); size/color variants sharing the same base CODE are summed together via SUMIFS. Rows below only include product codes with non-zero quantity or amount for this customer in at least one of the two years; codes that are 0 for this customer in both years (sold only to other customers) were excluded as not relevant to this comparison.
A5: Product Code | B5: Product Name | C5: Quantity 2025 | D5: Quantity 2026 | E5: Quantity Change | F5: Quantity Change % | G5: Amount 2025 (₪) | H5: Amount 2026 (₪) | I5: Amount Change (₪) | J5: Amount Change %
A6: (No product codes with activity for this customer in either 2025 or 2026)
B7: TOTAL | C7: 0 | D7: 0 | E7: 0 | F7: 0 | G7: 0 | H7: 0 | I7: 0 | J7: 0

Sheet 0בתי מרקחת
A1: Sales Comparison 2025 vs 2026 - Customer: 0בתי מרקחת (by Product CODE)
A2: Calculation date: | B2: 46284
A3: Source: PPlay1 of uriel (Reporter) product x customer pivot reports for 2025 and 2026, customer column "0בתי מרקחת" only (raw values in 'Source 2025'!$F:$F / 'Source 2026'!$F:$F). Each file has two data blocks: "נטו" (Net Amount, NIS) and "סהכ יחידות" (Total Units). Product CODE parsed as the first token of column B in the original file (before the first space); size/color variants sharing the same base CODE are summed together via SUMIFS. Rows below only include product codes with non-zero quantity or amount for this customer in at least one of the two years; codes that are 0 for this customer in both years (sold only to other customers) were excluded as not relevant to this comparison.
A5: Product Code | B5: Product Name | C5: Quantity 2025 | D5: Quantity 2026 | E5: Quantity Change | F5: Quantity Change % | G5: Amount 2025 (₪) | H5: Amount 2026 (₪) | I5: Amount Change (₪) | J5: Amount Change %
A6: 21 | B6: =IFERROR(INDEX('Source 2026'!$C:$C,MATCH($A6,'Source 2026'!$B:$B,0)),IFERROR(INDEX('Source 2025'!$C:$C,MATCH($A6,'Source 2025'!$B:$B,0)),"")) -> S חבק יד ארוך | C6: =SUMIFS('Source 2025'!$F:$F,'Source 2025'!$B:$B,$A6,'Source 2025'!$A:$A,"Quantity (units)") -> 1860 | D6: =SUMIFS('Source 2026'!$F:$F,'Source 2026'!$B:$B,$A6,'Source 2026'!$A:$A,"Quantity (units)") -> 943 | E6: =D6-C6 -> -917 | F6: =IF(AND(C6=0,D6=0),0,IF(C6=0,"New",(D6-C6)/C6)) -> -0.49301075 | G6: =SUMIFS('Source 2025'!$F:$F,'Source 2025'!$B:$B,$A6,'Source 2025'!$A:$A,"Amount (NIS)") -> 72114.1 | H6: =SUMIFS('Source 2026'!$F:$F,'Source 2026'!$B:$B,$A6,'Source 2026'!$A:$A,"Amount (NIS)") -> 36879 | I6: =H6-G6 -> -35235.1 | J6: =IF(AND(G6=0,H6=0),0,IF(G6=0,"New",(H6-G6)/G6)) -> -0.48860209
A7: 397 | B7: =IFERROR(INDEX('Source 2026'!$C:$C,MATCH($A7,'Source 2026'!$B:$B,0)),IFERROR(INDEX('Source 2025'!$C:$C,MATCH($A7,'Source 2025'!$B:$B,0)),"")) -> 35-38 גרבי טיסה מידה | C7: =SUMIFS('Source 2025'!$F:$F,'Source 2025'!$B:$B,$A7,'Source 2025'!$A:$A,"Quantity (units)") -> 518 | D7: =SUMIFS('Source 2026'!$F:$F,'Source 2026'!$B:$B,$A7,'Source 2026'!$A:$A,"Quantity (units)") -> -2 | E7: =D7-C7 -> -520 | F7: =IF(AND(C7=0,D7=0),0,IF(C7=0,"New",(D7-C7)/C7)) -> -1.003861 | G7: =SUMIFS('Source 2025'!$F:$F,'Source 2025'!$B:$B,$A7,'Source 2025'!$A:$A,"Amount (NIS)") -> 30622.4 | H7: =SUMIFS('Source 2026'!$F:$F,'Source 2026'!$B:$B,$A7,'Source 2026'!$A:$A,"Amount (NIS)") -> -82.3 | I7: =H7-G7 -> -30704.7 | J7: =IF(AND(G7=0,H7=0),0,IF(G7=0,"New",(H7-G7)/G7)) -> -1.0026876
A8: 397A-גרבי | B8: =IFERROR(INDEX('Source 2026'!$C:$C,MATCH($A8,'Source 2026'!$B:$B,0)),IFERROR(INDEX('Source 2025'!$C:$C,MATCH($A8,'Source 2025'!$B:$B,0)),"")) -> טיסה אנטי בקטרי35-38 | C8: =SUMIFS('Source 2025'!$F:$F,'Source 2025'!$B:$B,$A8,'Source 2025'!$A:$A,"Quantity (units)") -> 0 | D8: =SUMIFS('Source 2026'!$F:$F,'Source 2026'!$B:$B,$A8,'Source 2026'!$A:$A,"Quantity (units)") -> 456 | E8: =D8-C8 -> 456 | F8: =IF(AND(C8=0,D8=0),0,IF(C8=0,"New",(D8-C8)/C8)) -> New | G8: =SUMIFS('Source 2025'!$F:$F,'Source 2025'!$B:$B,$A8,'Source 2025'!$A:$A,"Amount (NIS)") -> 0 | H8: =SUMIFS('Source 2026'!$F:$F,'Source 2026'!$B:$B,$A8,'Source 2026'!$A:$A,"Amount (NIS)") -> 27020.5 | I8: =H8-G8 -> 27020.5 | J8: =IF(AND(G8=0,H8=0),0,IF(G8=0,"New",(H8-G8)/G8)) -> New
A9: 302 | B9: =IFERROR(INDEX('Source 2026'!$C:$C,MATCH($A9,'Source 2026'!$B:$B,0)),IFERROR(INDEX('Source 2025'!$C:$C,MATCH($A9,'Source 2025'!$B:$B,0)),"")) -> מדרס ג'ל לגבר | C9: =SUMIFS('Source 2025'!$F:$F,'Source 2025'!$B:$B,$A9,'Source 2025'!$A:$A,"Quantity (units)") -> 837 | D9: =SUMIFS('Source 2026'!$F:$F,'Source 2026'!$B:$B,$A9,'Source 2026'!$A:$A,"Quantity (units)") -> 383 | E9: =D9-C9 -> -454 | F9: =IF(AND(C9=0,D9=0),0,IF(C9=0,"New",(D9-C9)/C9)) -> -0.54241338 | G9: =SUMIFS('Source 2025'!$F:$F,'Source 2025'!$B:$B,$A9,'Source 2025'!$A:$A,"Amount (NIS)") -> 49868.9 | H9: =SUMIFS('Source 2026'!$F:$F,'Source 2026'!$B:$B,$A9,'Source 2026'!$A:$A,"Amount (NIS)") -> 24597.7 | I9: =H9-G9 -> -25271.2 | J9: =IF(AND(G9=0,H9=0),0,IF(G9=0,"New",(H9-G9)/G9)) -> -0.50675271
A10: AC-07 | B10: =IFERROR(INDEX('Source 2026'!$C:$C,MATCH($A10,'Source 2026'!$B:$B,0)),IFERROR(INDEX('Source 2025'!$C:$C,MATCH($A10,'Source 2025'!$B:$B,0)),"")) -> חגורת גב עם תמיכות | C10: =SUMIFS('Source 2025'!$F:$F,'Source 2025'!$B:$B,$A10,'Source 2025'!$A:$A,"Quantity (units)") -> 1098 | D10: =SUMIFS('Source 2026'!$F:$F,'Source 2026'!$B:$B,$A10,'Source 2026'!$A:$A,"Quantity (units)") -> 797 | E10: =D10-C10 -> -301 | F10: =IF(AND(C10=0,D10=0),0,IF(C10=0,"New",(D10-C10)/C10)) -> -0.27413479 | G10: =SUMIFS('Source 2025'!$F:$F,'Source 2025'!$B:$B,$A10,'Source 2025'!$A:$A,"Amount (NIS)") -> 93491.9 | H10: =SUMIFS('Source 2026'!$F:$F,'Source 2026'!$B:$B,$A10,'Source 2026'!$A:$A,"Amount (NIS)") -> 68622.4 | I10: =H10-G10 -> -24869.5 | J10: =IF(AND(G10=0,H10=0),0,IF(G10=0,"New",(H10-G10)/G10)) -> -0.266007
A11: SH422 | B11: =IFERROR(INDEX('Source 2026'!$C:$C,MATCH($A11,'Source 2026'!$B:$B,0)),IFERROR(INDEX('Source 2025'!$C:$C,MATCH($A11,'Source 2025'!$B:$B,0)),"")) -> 1 תומך ברך גנושילד | C11: =SUMIFS('Source 2025'!$F:$F,'Source 2025'!$B:$B,$A11,'Source 2025'!$A:$A,"Quantity (units)") -> 19 | D11: =SUMIFS('Source 2026'!$F:$F,'Source 2026'!$B:$B,$A11,'Source 2026'!$A:$A,"Quantity (units)") -> 114 | E11: =D11-C11 -> 95 | F11: =IF(AND(C11=0,D11=0),0,IF(C11=0,"New",(D11-C11)/C11)) -> 5 | G11: =SUMIFS('Source 2025'!$F:$F,'Source 2025'!$B:$B,$A11,'Source 2025'!$A:$A,"Amount (NIS)") -> 4034.6 | H11: =SUMIFS('Source 2026'!$F:$F,'Source 2026'!$B:$B,$A11,'Source 2026'!$A:$A,"Amount (NIS)") -> 23279.6 | I11: =H11-G11 -> 19245 | J11: =IF(AND(G11=0,H11=0),0,IF(G11=0,"New",(H11-G11)/G11)) -> 4.7699896
A12: 307 | B12: =IFERROR(INDEX('Source 2026'!$C:$C,MATCH($A12,'Source 2026'!$B:$B,0)),IFERROR(INDEX('Source 2025'!$C:$C,MATCH($A12,'Source 2025'!$B:$B,0)),"")) -> L עקבים לדורבן-זוג כריות | C12: =SUMIFS('Source 2025'!$F:$F,'Source 2025'!$B:$B,$A12,'Source 2025'!$A:$A,"Quantity (units)") -> 445 | D12: =SUMIFS('Source 2026'!$F:$F,'Source 2026'!$B:$B,$A12,'Source 2026'!$A:$A,"Quantity (units)") -> 230 | E12: =D12-C12 -> -215 | F12: =IF(AND(C12=0,D12=0),0,IF(C12=0,"New",(D12-C12)/C12)) -> -0.48314607 | G12: =SUMIFS('Source 2025'!$F:$F,'Source 2025'!$B:$B,$A12,'Source 2025'!$A:$A,"Amount (NIS)") -> 35993.7 | H12: =SUMIFS('Source 2026'!$F:$F,'Source 2026'!$B:$B,$A12,'Source 2026'!$A:$A,"Amount (NIS)") -> 19504.3 | I12: =H12-G12 -> -16489.4 | J12: =IF(AND(G12=0,H12=0),0,IF(G12=0,"New",(H12-G12)/G12)) -> -0.45811906
A13: 26 | B13: =IFERROR(INDEX('Source 2026'!$C:$C,MATCH($A13,'Source 2026'!$B:$B,0)),IFERROR(INDEX('Source 2025'!$C:$C,MATCH($A13,'Source 2025'!$B:$B,0)),"")) -> L סד ליד דו צדדי לאחר שבר | C13: =SUMIFS('Source 2025'!$F:$F,'Source 2025'!$B:$B,$A13,'Source 2025'!$A:$A,"Quantity (units)") -> 322 | D13: =SUMIFS('Source 2026'!$F:$F,'Source 2026'!$B:$B,$A13,'Source 2026'!$A:$A,"Quantity (units)") -> 161 | E13: =D13-C13 -> -161 | F13: =IF(AND(C13=0,D13=0),0,IF(C13=0,"New",(D13-C13)/C13)) -> -0.5 | G13: =SUMIFS('Source 2025'!$F:$F,'Source 2025'!$B:$B,$A13,'Source 2025'!$A:$A,"Amount (NIS)") -> 31583.1 | H13: =SUMIFS('Source 2026'!$F:$F,'Source 2026'!$B:$B,$A13,'Source 2026'!$A:$A,"Amount (NIS)") -> 16060.1 | I13: =H13-G13 -> -15523 | J13: =IF(AND(G13=0,H13=0),0,IF(G13=0,"New",(H13-G13)/G13)) -> -0.49149703
A14: 60 | B14: =IFERROR(INDEX('Source 2026'!$C:$C,MATCH($A14,'Source 2026'!$B:$B,0)),IFERROR(INDEX('Source 2025'!$C:$C,MATCH($A14,'Source 2025'!$B:$B,0)),"")) -> L צוארון ספוגי | C14: =SUMIFS('Source 2025'!$F:$F,'Source 2025'!$B:$B,$A14,'Source 2025'!$A:$A,"Quantity (units)") -> 532 | D14: =SUMIFS('Source 2026'!$F:$F,'Source 2026'!$B:$B,$A14,'Source 2026'!$A:$A,"Quantity (units)") -> 227 | E14: =D14-C14 -> -305 | F14: =IF(AND(C14=0,D14=0),0,IF(C14=0,"New",(D14-C14)/C14)) -> -0.57330827 | G14: =SUMIFS('Source 2025'!$F:$F,'Source 2025'!$B:$B,$A14,'Source 2025'!$A:$A,"Amount (NIS)") -> 25724 | H14: =SUMIFS('Source 2026'!$F:$F,'Source 2026'!$B:$B,$A14,'Source 2026'!$A:$A,"Amount (NIS)") -> 11000.8 | I14: =H14-G14 -> -14723.2 | J14: =IF(AND(G14=0,H14=0),0,IF(G14=0,"New",(H14-G14)/G14)) -> -0.57235267
A15: 45C | B15: =IFERROR(INDEX('Source 2026'!$C:$C,MATCH($A15,'Source 2026'!$B:$B,0)),IFERROR(INDEX('Source 2025'!$C:$C,MATCH($A15,'Source 2025'!$B:$B,0)),"")) -> S מגן ברך חום | C15: =SUMIFS('Source 2025'!$F:$F,'Source 2025'!$B:$B,$A15,'Source 2025'!$A:$A,"Quantity (units)") -> 1320 | D15: =SUMIFS('Source 2026'!$F:$F,'Source 2026'!$B:$B,$A15,'Source 2026'!$A:$A,"Quantity (units)") -> 876 | E15: =D15-C15 -> -444 | F15: =IF(AND(C15=0,D15=0),0,IF(C15=0,"New",(D15-C15)/C15)) -> -0.33636364 | G15: =SUMIFS('Source 2025'!$F:$F,'Source 2025'!$B:$B,$A15,'Source 2025'!$A:$A,"Amount (NIS)") -> 39604.4 | H15: =SUMIFS('Source 2026'!$F:$F,'Source 2026'!$B:$B,$A15,'Source 2026'!$A:$A,"Amount (NIS)") -> 26476.8 | I15: =H15-G15 -> -13127.6 | J15: =IF(AND(G15=0,H15=0),0,IF(G15=0,"New",(H15-G15)/G15)) -> -0.33146822
A16: 45B | B16: =IFERROR(INDEX('Source 2026'!$C:$C,MATCH($A16,'Source 2026'!$B:$B,0)),IFERROR(INDEX('Source 2025'!$C:$C,MATCH($A16,'Source 2025'!$B:$B,0)),"")) -> L מגן ברך שחור | C16: =SUMIFS('Source 2025'!$F:$F,'Source 2025'!$B:$B,$A16,'Source 2025'!$A:$A,"Quantity (units)") -> 1144 | D16: =SUMIFS('Source 2026'!$F:$F,'Source 2026'!$B:$B,$A16,'Source 2026'!$A:$A,"Quantity (units)") -> 685 | E16: =D16-C16 -> -459 | F16: =IF(AND(C16=0,D16=0),0,IF(C16=0,"New",(D16-C16)/C16)) -> -0.40122378 | G16: =SUMIFS('Source 2025'!$F:$F,'Source 2025'!$B:$B,$A16,'Source 2025'!$A:$A,"Amount (NIS)") -> 33625.5 | H16: =SUMIFS('Source 2026'!$F:$F,'Source 2026'!$B:$B,$A16,'Source 2026'!$A:$A,"Amount (NIS)") -> 20801.5 | I16: =H16-G16 -> -12824 | J16: =IF(AND(G16=0,H16=0),0,IF(G16=0,"New",(H16-G16)/G16)) -> -0.38137723
A17: 28 | B17: =IFERROR(INDEX('Source 2026'!$C:$C,MATCH($A17,'Source 2026'!$B:$B,0)),IFERROR(INDEX('Source 2025'!$C:$C,MATCH($A17,'Source 2025'!$B:$B,0)),"")) -> L סד לאגודל לאחר שבר | C17: =SUMIFS('Source 2025'!$F:$F,'Source 2025'!$B:$B,$A17,'Source 2025'!$A:$A,"Quantity (units)") -> 237 | D17: =SUMIFS('Source 2026'!$F:$F,'Source 2026'!$B:$B,$A17,'Source 2026'!$A:$A,"Quantity (units)") -> 108 | E17: =D17-C17 -> -129 | F17: =IF(AND(C17=0,D17=0),0,IF(C17=0,"New",(D17-C17)/C17)) -> -0.5443038 | G17: =SUMIFS('Source 2025'!$F:$F,'Source 2025'!$B:$B,$A17,'Source 2025'!$A:$A,"Amount (NIS)") -> 23347.4 | H17: =SUMIFS('Source 2026'!$F:$F,'Source 2026'!$B:$B,$A17,'Source 2026'!$A:$A,"Amount (NIS)") -> 10645.5 | I17: =H17-G17 -> -12701.9 | J17: =IF(AND(G17=0,H17=0),0,IF(G17=0,"New",(H17-G17)/G17)) -> -0.54403916
... A283: 63 | B283: =IFERROR(INDEX('Source 2026'!$C:$C,MATCH($A283,'Source 2026'!$B:$B,0)),IFERROR(INDEX('Source 2025'!$C:$C,MATCH($A283,'Source 2025'!$B:$B,0)),"")) -> M צוארון פלסטי מתכוון | C283: =SUMIFS('Source 2025'!$F:$F,'Source 2025'!$B:$B,$A283,'Source 2025'!$A:$A,"Quantity (units)") -> 1 | D283: =SUMIFS('Source 2026'!$F:$F,'Source 2026'!$B:$B,$A283,'Source 2026'!$A:$A,"Quantity (units)") -> 1 | E283: =D283-C283 -> 0 | F283: =IF(AND(C283=0,D283=0),0,IF(C283=0,"New",(D283-C283)/C283)) -> 0 | G283: =SUMIFS('Source 2025'!$F:$F,'Source 2025'!$B:$B,$A283,'Source 2025'!$A:$A,"Amount (NIS)") -> 66.5 | H283: =SUMIFS('Source 2026'!$F:$F,'Source 2026'!$B:$B,$A283,'Source 2026'!$A:$A,"Amount (NIS)") -> 66.5 | I283: =H283-G283 -> 0 | J283: =IF(AND(G283=0,H283=0),0,IF(G283=0,"New",(H283-G283)/G283)) -> 0
B285: TOTAL | C285: =SUM(C6:C283) -> 53153 | D285: =SUM(D6:D283) -> 32995 | E285: =SUM(E6:E283) -> -20158 | F285: =IF(C285=0,"N/A",E285/C285) -> -0.37924482 | G285: =SUM(G6:G283) -> 1940731.5 | H285: =SUM(H6:H283) -> 1283059.8 | I285: =SUM(I6:I283) -> -657671.7 | J285: =IF(G285=0,"N/A",I285/G285) -> -0.33887825

Sheet 0כללי
A1: Sales Comparison 2025 vs 2026 - Customer: 0כללי (by Product CODE)
A2: Calculation date: | B2: 46284
A3: Source: PPlay1 of uriel (Reporter) product x customer pivot reports for 2025 and 2026, customer column "0כללי" only (raw values in 'Source 2025'!$G:$G / 'Source 2026'!$G:$G). Each file has two data blocks: "נטו" (Net Amount, NIS) and "סהכ יחידות" (Total Units). Product CODE parsed as the first token of column B in the original file (before the first space); size/color variants sharing the same base CODE are summed together via SUMIFS. Rows below only include product codes with non-zero quantity or amount for this customer in at least one of the two years; codes that are 0 for this customer in both years (sold only to other customers) were excluded as not relevant to this comparison.
A5: Product Code | B5: Product Name | C5: Quantity 2025 | D5: Quantity 2026 | E5: Quantity Change | F5: Quantity Change % | G5: Amount 2025 (₪) | H5: Amount 2026 (₪) | I5: Amount Change (₪) | J5: Amount Change %
A6: (No product codes with activity for this customer in either 2025 or 2026)
B7: TOTAL | C7: 0 | D7: 0 | E7: 0 | F7: 0 | G7: 0 | H7: 0 | I7: 0 | J7: 0

Sheet 0מפיצי משנה
A1: Sales Comparison 2025 vs 2026 - Customer: 0מפיצי משנה (by Product CODE)
A2: Calculation date: | B2: 46284
A3: Source: PPlay1 of uriel (Reporter) product x customer pivot reports for 2025 and 2026, customer column "0מפיצי משנה" only (raw values in 'Source 2025'!$H:$H / 'Source 2026'!$H:$H). Each file has two data blocks: "נטו" (Net Amount, NIS) and "סהכ יחידות" (Total Units). Product CODE parsed as the first token of column B in the original file (before the first space); size/color variants sharing the same base CODE are summed together via SUMIFS. Rows below only include product codes with non-zero quantity or amount for this customer in at least one of the two years; codes that are 0 for this customer in both years (sold only to other customers) were excluded as not relevant to this comparison.
A5: Product Code | B5: Product Name | C5: Quantity 2025 | D5: Quantity 2026 | E5: Quantity Change | F5: Quantity Change % | G5: Amount 2025 (₪) | H5: Amount 2026 (₪) | I5: Amount Change (₪) | J5: Amount Change %
A6: 397 | B6: =IFERROR(INDEX('Source 2026'!$C:$C,MATCH($A6,'Source 2026'!$B:$B,0)),IFERROR(INDEX('Source 2025'!$C:$C,MATCH($A6,'Source 2025'!$B:$B,0)),"")) -> 35-38 גרבי טיסה מידה | C6: =SUMIFS('Source 2025'!$H:$H,'Source 2025'!$B:$B,$A6,'Source 2025'!$A:$A,"Quantity (units)") -> 14 | D6: =SUMIFS('Source 2026'!$H:$H,'Source 2026'!$B:$B,$A6,'Source 2026'!$A:$A,"Quantity (units)") -> 0 | E6: =D6-C6 -> -14 | F6: =IF(AND(C6=0,D6=0),0,IF(C6=0,"New",(D6-C6)/C6)) -> -1 | G6: =SUMIFS('Source 2025'!$H:$H,'Source 2025'!$B:$B,$A6,'Source 2025'!$A:$A,"Amount (NIS)") -> 745.3 | H6: =SUMIFS('Source 2026'!$H:$H,'Source 2026'!$B:$B,$A6,'Source 2026'!$A:$A,"Amount (NIS)") -> 0 | I6: =H6-G6 -> -745.3 | J6: =IF(AND(G6=0,H6=0),0,IF(G6=0,"New",(H6-G6)/G6)) -> -1
A7: 372 | B7: =IFERROR(INDEX('Source 2026'!$C:$C,MATCH($A7,'Source 2026'!$B:$B,0)),IFERROR(INDEX('Source 2025'!$C:$C,MATCH($A7,'Source 2025'!$B:$B,0)),"")) -> רפידת אנטי ריח -זוג | C7: =SUMIFS('Source 2025'!$H:$H,'Source 2025'!$B:$B,$A7,'Source 2025'!$A:$A,"Quantity (units)") -> 70 | D7: =SUMIFS('Source 2026'!$H:$H,'Source 2026'!$B:$B,$A7,'Source 2026'!$A:$A,"Quantity (units)") -> 20 | E7: =D7-C7 -> -50 | F7: =IF(AND(C7=0,D7=0),0,IF(C7=0,"New",(D7-C7)/C7)) -> -0.71428571 | G7: =SUMIFS('Source 2025'!$H:$H,'Source 2025'!$B:$B,$A7,'Source 2025'!$A:$A,"Amount (NIS)") -> 935.5 | H7: =SUMIFS('Source 2026'!$H:$H,'Source 2026'!$B:$B,$A7,'Source 2026'!$A:$A,"Amount (NIS)") -> 267.3 | I7: =H7-G7 -> -668.2 | J7: =IF(AND(G7=0,H7=0),0,IF(G7=0,"New",(H7-G7)/G7)) -> -0.71427044
A8: 320 | B8: =IFERROR(INDEX('Source 2026'!$C:$C,MATCH($A8,'Source 2026'!$B:$B,0)),IFERROR(INDEX('Source 2025'!$C:$C,MATCH($A8,'Source 2025'!$B:$B,0)),"")) -> בליסטר פלסטר | C8: =SUMIFS('Source 2025'!$H:$H,'Source 2025'!$B:$B,$A8,'Source 2025'!$A:$A,"Quantity (units)") -> 42 | D8: =SUMIFS('Source 2026'!$H:$H,'Source 2026'!$B:$B,$A8,'Source 2026'!$A:$A,"Quantity (units)") -> 3 | E8: =D8-C8 -> -39 | F8: =IF(AND(C8=0,D8=0),0,IF(C8=0,"New",(D8-C8)/C8)) -> -0.92857143 | G8: =SUMIFS('Source 2025'!$H:$H,'Source 2025'!$B:$B,$A8,'Source 2025'!$A:$A,"Amount (NIS)") -> 708.9 | H8: =SUMIFS('Source 2026'!$H:$H,'Source 2026'!$B:$B,$A8,'Source 2026'!$A:$A,"Amount (NIS)") -> 51.1 | I8: =H8-G8 -> -657.8 | J8: =IF(AND(G8=0,H8=0),0,IF(G8=0,"New",(H8-G8)/G8)) -> -0.92791649
A9: 34 | B9: =IFERROR(INDEX('Source 2026'!$C:$C,MATCH($A9,'Source 2026'!$B:$B,0)),IFERROR(INDEX('Source 2025'!$C:$C,MATCH($A9,'Source 2025'!$B:$B,0)),"")) -> M מגן קרסול עקב סגור | C9: =SUMIFS('Source 2025'!$H:$H,'Source 2025'!$B:$B,$A9,'Source 2025'!$A:$A,"Quantity (units)") -> 13 | D9: =SUMIFS('Source 2026'!$H:$H,'Source 2026'!$B:$B,$A9,'Source 2026'!$A:$A,"Quantity (units)") -> 0 | E9: =D9-C9 -> -13 | F9: =IF(AND(C9=0,D9=0),0,IF(C9=0,"New",(D9-C9)/C9)) -> -1 | G9: =SUMIFS('Source 2025'!$H:$H,'Source 2025'!$B:$B,$A9,'Source 2025'!$A:$A,"Amount (NIS)") -> 527.5 | H9: =SUMIFS('Source 2026'!$H:$H,'Source 2026'!$B:$B,$A9,'Source 2026'!$A:$A,"Amount (NIS)") -> 0 | I9: =H9-G9 -> -527.5 | J9: =IF(AND(G9=0,H9=0),0,IF(G9=0,"New",(H9-G9)/G9)) -> -1
A10: 394G | B10: =IFERROR(INDEX('Source 2026'!$C:$C,MATCH($A10,'Source 2026'!$B:$B,0)),IFERROR(INDEX('Source 2025'!$C:$C,MATCH($A10,'Source 2025'!$B:$B,0)),"")) -> גרב.כסף לסכרתים אפור35-38 | C10: =SUMIFS('Source 2025'!$H:$H,'Source 2025'!$B:$B,$A10,'Source 2025'!$A:$A,"Quantity (units)") -> 22 | D10: =SUMIFS('Source 2026'!$H:$H,'Source 2026'!$B:$B,$A10,'Source 2026'!$A:$A,"Quantity (units)") -> 0 | E10: =D10-C10 -> -22 | F10: =IF(AND(C10=0,D10=0),0,IF(C10=0,"New",(D10-C10)/C10)) -> -1 | G10: =SUMIFS('Source 2025'!$H:$H,'Source 2025'!$B:$B,$A10,'Source 2025'!$A:$A,"Amount (NIS)") -> 506.8 | H10: =SUMIFS('Source 2026'!$H:$H,'Source 2026'!$B:$B,$A10,'Source 2026'!$A:$A,"Amount (NIS)") -> 0 | I10: =H10-G10 -> -506.8 | J10: =IF(AND(G10=0,H10=0),0,IF(G10=0,"New",(H10-G10)/G10)) -> -1
A11: 394W | B11: =IFERROR(INDEX('Source 2026'!$C:$C,MATCH($A11,'Source 2026'!$B:$B,0)),IFERROR(INDEX('Source 2025'!$C:$C,MATCH($A11,'Source 2025'!$B:$B,0)),"")) -> 35-38 גרב.כסף לסכרתים לבן | C11: =SUMIFS('Source 2025'!$H:$H,'Source 2025'!$B:$B,$A11,'Source 2025'!$A:$A,"Quantity (units)") -> 30 | D11: =SUMIFS('Source 2026'!$H:$H,'Source 2026'!$B:$B,$A11,'Source 2026'!$A:$A,"Quantity (units)") -> 11 | E11: =D11-C11 -> -19 | F11: =IF(AND(C11=0,D11=0),0,IF(C11=0,"New",(D11-C11)/C11)) -> -0.63333333 | G11: =SUMIFS('Source 2025'!$H:$H,'Source 2025'!$B:$B,$A11,'Source 2025'!$A:$A,"Amount (NIS)") -> 711.7 | H11: =SUMIFS('Source 2026'!$H:$H,'Source 2026'!$B:$B,$A11,'Source 2026'!$A:$A,"Amount (NIS)") -> 267.7 | I11: =H11-G11 -> -444 | J11: =IF(AND(G11=0,H11=0),0,IF(G11=0,"New",(H11-G11)/G11)) -> -0.62385837
A12: 3655 | B12: =IFERROR(INDEX('Source 2026'!$C:$C,MATCH($A12,'Source 2026'!$B:$B,0)),IFERROR(INDEX('Source 2025'!$C:$C,MATCH($A12,'Source 2025'!$B:$B,0)),"")) -> שרוול מסיליקון לאצבע | C12: =SUMIFS('Source 2025'!$H:$H,'Source 2025'!$B:$B,$A12,'Source 2025'!$A:$A,"Quantity (units)") -> 25 | D12: =SUMIFS('Source 2026'!$H:$H,'Source 2026'!$B:$B,$A12,'Source 2026'!$A:$A,"Quantity (units)") -> 0 | E12: =D12-C12 -> -25 | F12: =IF(AND(C12=0,D12=0),0,IF(C12=0,"New",(D12-C12)/C12)) -> -1 | G12: =SUMIFS('Source 2025'!$H:$H,'Source 2025'!$B:$B,$A12,'Source 2025'!$A:$A,"Amount (NIS)") -> 413.3 | H12: =SUMIFS('Source 2026'!$H:$H,'Source 2026'!$B:$B,$A12,'Source 2026'!$A:$A,"Amount (NIS)") -> 0 | I12: =H12-G12 -> -413.3 | J12: =IF(AND(G12=0,H12=0),0,IF(G12=0,"New",(H12-G12)/G12)) -> -1
A13: 45E | B13: =IFERROR(INDEX('Source 2026'!$C:$C,MATCH($A13,'Source 2026'!$B:$B,0)),IFERROR(INDEX('Source 2025'!$C:$C,MATCH($A13,'Source 2025'!$B:$B,0)),"")) -> Sמגן ברך ארוך לבן | C13: =SUMIFS('Source 2025'!$H:$H,'Source 2025'!$B:$B,$A13,'Source 2025'!$A:$A,"Quantity (units)") -> 22 | D13: =SUMIFS('Source 2026'!$H:$H,'Source 2026'!$B:$B,$A13,'Source 2026'!$A:$A,"Quantity (units)") -> 10 | E13: =D13-C13 -> -12 | F13: =IF(AND(C13=0,D13=0),0,IF(C13=0,"New",(D13-C13)/C13)) -> -0.54545455 | G13: =SUMIFS('Source 2025'!$H:$H,'Source 2025'!$B:$B,$A13,'Source 2025'!$A:$A,"Amount (NIS)") -> 712.8 | H13: =SUMIFS('Source 2026'!$H:$H,'Source 2026'!$B:$B,$A13,'Source 2026'!$A:$A,"Amount (NIS)") -> 324.6 | I13: =H13-G13 -> -388.2 | J13: =IF(AND(G13=0,H13=0),0,IF(G13=0,"New",(H13-G13)/G13)) -> -0.54461279
A14: 394B | B14: =IFERROR(INDEX('Source 2026'!$C:$C,MATCH($A14,'Source 2026'!$B:$B,0)),IFERROR(INDEX('Source 2025'!$C:$C,MATCH($A14,'Source 2025'!$B:$B,0)),"")) -> גרב.כסף לסכרתים שחור35-38 | C14: =SUMIFS('Source 2025'!$H:$H,'Source 2025'!$B:$B,$A14,'Source 2025'!$A:$A,"Quantity (units)") -> 63 | D14: =SUMIFS('Source 2026'!$H:$H,'Source 2026'!$B:$B,$A14,'Source 2026'!$A:$A,"Quantity (units)") -> 49 | E14: =D14-C14 -> -14 | F14: =IF(AND(C14=0,D14=0),0,IF(C14=0,"New",(D14-C14)/C14)) -> -0.22222222 | G14: =SUMIFS('Source 2025'!$H:$H,'Source 2025'!$B:$B,$A14,'Source 2025'!$A:$A,"Amount (NIS)") -> 1545.6 | H14: =SUMIFS('Source 2026'!$H:$H,'Source 2026'!$B:$B,$A14,'Source 2026'!$A:$A,"Amount (NIS)") -> 1192.4 | I14: =H14-G14 -> -353.2 | J14: =IF(AND(G14=0,H14=0),0,IF(G14=0,"New",(H14-G14)/G14)) -> -0.22851967
A15: T78 | B15: =IFERROR(INDEX('Source 2026'!$C:$C,MATCH($A15,'Source 2026'!$B:$B,0)),IFERROR(INDEX('Source 2025'!$C:$C,MATCH($A15,'Source 2025'!$B:$B,0)),"")) -> S תומך זרוע וכתף | C15: =SUMIFS('Source 2025'!$H:$H,'Source 2025'!$B:$B,$A15,'Source 2025'!$A:$A,"Quantity (units)") -> 2 | D15: =SUMIFS('Source 2026'!$H:$H,'Source 2026'!$B:$B,$A15,'Source 2026'!$A:$A,"Quantity (units)") -> 0 | E15: =D15-C15 -> -2 | F15: =IF(AND(C15=0,D15=0),0,IF(C15=0,"New",(D15-C15)/C15)) -> -1 | G15: =SUMIFS('Source 2025'!$H:$H,'Source 2025'!$B:$B,$A15,'Source 2025'!$A:$A,"Amount (NIS)") -> 328.1 | H15: =SUMIFS('Source 2026'!$H:$H,'Source 2026'!$B:$B,$A15,'Source 2026'!$A:$A,"Amount (NIS)") -> 0 | I15: =H15-G15 -> -328.1 | J15: =IF(AND(G15=0,H15=0),0,IF(G15=0,"New",(H15-G15)/G15)) -> -1
A16: 302 | B16: =IFERROR(INDEX('Source 2026'!$C:$C,MATCH($A16,'Source 2026'!$B:$B,0)),IFERROR(INDEX('Source 2025'!$C:$C,MATCH($A16,'Source 2025'!$B:$B,0)),"")) -> מדרס ג'ל לגבר | C16: =SUMIFS('Source 2025'!$H:$H,'Source 2025'!$B:$B,$A16,'Source 2025'!$A:$A,"Quantity (units)") -> 5 | D16: =SUMIFS('Source 2026'!$H:$H,'Source 2026'!$B:$B,$A16,'Source 2026'!$A:$A,"Quantity (units)") -> 0 | E16: =D16-C16 -> -5 | F16: =IF(AND(C16=0,D16=0),0,IF(C16=0,"New",(D16-C16)/C16)) -> -1 | G16: =SUMIFS('Source 2025'!$H:$H,'Source 2025'!$B:$B,$A16,'Source 2025'!$A:$A,"Amount (NIS)") -> 307.6 | H16: =SUMIFS('Source 2026'!$H:$H,'Source 2026'!$B:$B,$A16,'Source 2026'!$A:$A,"Amount (NIS)") -> 0 | I16: =H16-G16 -> -307.6 | J16: =IF(AND(G16=0,H16=0),0,IF(G16=0,"New",(H16-G16)/G16)) -> -1
A17: 10 | B17: =IFERROR(INDEX('Source 2026'!$C:$C,MATCH($A17,'Source 2026'!$B:$B,0)),IFERROR(INDEX('Source 2025'!$C:$C,MATCH($A17,'Source 2025'!$B:$B,0)),"")) -> S ""חגורת גב ""לומבו | C17: =SUMIFS('Source 2025'!$H:$H,'Source 2025'!$B:$B,$A17,'Source 2025'!$A:$A,"Quantity (units)") -> 1 | D17: =SUMIFS('Source 2026'!$H:$H,'Source 2026'!$B:$B,$A17,'Source 2026'!$A:$A,"Quantity (units)") -> 3 | E17: =D17-C17 -> 2 | F17: =IF(AND(C17=0,D17=0),0,IF(C17=0,"New",(D17-C17)/C17)) -> 2 | G17: =SUMIFS('Source 2025'!$H:$H,'Source 2025'!$B:$B,$A17,'Source 2025'!$A:$A,"Amount (NIS)") -> 134 | H17: =SUMIFS('Source 2026'!$H:$H,'Source 2026'!$B:$B,$A17,'Source 2026'!$A:$A,"Amount (NIS)") -> 402 | I17: =H17-G17 -> 268 | J17: =IF(AND(G17=0,H17=0),0,IF(G17=0,"New",(H17-G17)/G17)) -> 2
... A48: FC335 | B48: =IFERROR(INDEX('Source 2026'!$C:$C,MATCH($A48,'Source 2026'!$B:$B,0)),IFERROR(INDEX('Source 2025'!$C:$C,MATCH($A48,'Source 2025'!$B:$B,0)),"")) -> טלק מעושר באלוורה | C48: =SUMIFS('Source 2025'!$H:$H,'Source 2025'!$B:$B,$A48,'Source 2025'!$A:$A,"Quantity (units)") -> 11 | D48: =SUMIFS('Source 2026'!$H:$H,'Source 2026'!$B:$B,$A48,'Source 2026'!$A:$A,"Quantity (units)") -> 11 | E48: =D48-C48 -> 0 | F48: =IF(AND(C48=0,D48=0),0,IF(C48=0,"New",(D48-C48)/C48)) -> 0 | G48: =SUMIFS('Source 2025'!$H:$H,'Source 2025'!$B:$B,$A48,'Source 2025'!$A:$A,"Amount (NIS)") -> 223 | H48: =SUMIFS('Source 2026'!$H:$H,'Source 2026'!$B:$B,$A48,'Source 2026'!$A:$A,"Amount (NIS)") -> 223 | I48: =H48-G48 -> 0 | J48: =IF(AND(G48=0,H48=0),0,IF(G48=0,"New",(H48-G48)/G48)) -> 0
B50: TOTAL | C50: =SUM(C6:C48) -> 374 | D50: =SUM(D6:D48) -> 175 | E50: =SUM(E6:E48) -> -199 | F50: =IF(C50=0,"N/A",E50/C50) -> -0.53208556 | G50: =SUM(G6:G48) -> 9812.1 | H50: =SUM(H6:H48) -> 4549.9 | I50: =SUM(I6:I48) -> -5262.2 | J50: =IF(G50=0,"N/A",I50/G50) -> -0.53629702

Sheet 0פארמים
A1: Sales Comparison 2025 vs 2026 - Customer: 0פארמים (by Product CODE)
A2: Calculation date: | B2: 46284
A3: Source: PPlay1 of uriel (Reporter) product x customer pivot reports for 2025 and 2026, customer column "0פארמים" only (raw values in 'Source 2025'!$I:$I / 'Source 2026'!$I:$I). Each file has two data blocks: "נטו" (Net Amount, NIS) and "סהכ יחידות" (Total Units). Product CODE parsed as the first token of column B in the original file (before the first space); size/color variants sharing the same base CODE are summed together via SUMIFS. Rows below only include product codes with non-zero quantity or amount for this customer in at least one of the two years; codes that are 0 for this customer in both years (sold only to other customers) were excluded as not relevant to this comparison.
A5: Product Code | B5: Product Name | C5: Quantity 2025 | D5: Quantity 2026 | E5: Quantity Change | F5: Quantity Change % | G5: Amount 2025 (₪) | H5: Amount 2026 (₪) | I5: Amount Change (₪) | J5: Amount Change %
A6: מדרסי | B6: =IFERROR(INDEX('Source 2026'!$C:$C,MATCH($A6,'Source 2026'!$B:$B,0)),IFERROR(INDEX('Source 2025'!$C:$C,MATCH($A6,'Source 2025'!$B:$B,0)),"")) -> אפיק ג'ל מולט.ספורט35-38 | C6: =SUMIFS('Source 2025'!$I:$I,'Source 2025'!$B:$B,$A6,'Source 2025'!$A:$A,"Quantity (units)") -> 2855 | D6: =SUMIFS('Source 2026'!$I:$I,'Source 2026'!$B:$B,$A6,'Source 2026'!$A:$A,"Quantity (units)") -> 481 | E6: =D6-C6 -> -2374 | F6: =IF(AND(C6=0,D6=0),0,IF(C6=0,"New",(D6-C6)/C6)) -> -0.83152364 | G6: =SUMIFS('Source 2025'!$I:$I,'Source 2025'!$B:$B,$A6,'Source 2025'!$A:$A,"Amount (NIS)") -> 265726.2 | H6: =SUMIFS('Source 2026'!$I:$I,'Source 2026'!$B:$B,$A6,'Source 2026'!$A:$A,"Amount (NIS)") -> 47626.6 | I6: =H6-G6 -> -218099.6 | J6: =IF(AND(G6=0,H6=0),0,IF(G6=0,"New",(H6-G6)/G6)) -> -0.82076814
A7: 35-38 | B7: =IFERROR(INDEX('Source 2026'!$C:$C,MATCH($A7,'Source 2026'!$B:$B,0)),IFERROR(INDEX('Source 2025'!$C:$C,MATCH($A7,'Source 2025'!$B:$B,0)),"")) -> מדרסי אפיק ג'ל נוחות | C7: =SUMIFS('Source 2025'!$I:$I,'Source 2025'!$B:$B,$A7,'Source 2025'!$A:$A,"Quantity (units)") -> 1776 | D7: =SUMIFS('Source 2026'!$I:$I,'Source 2026'!$B:$B,$A7,'Source 2026'!$A:$A,"Quantity (units)") -> 112 | E7: =D7-C7 -> -1664 | F7: =IF(AND(C7=0,D7=0),0,IF(C7=0,"New",(D7-C7)/C7)) -> -0.93693694 | G7: =SUMIFS('Source 2025'!$I:$I,'Source 2025'!$B:$B,$A7,'Source 2025'!$A:$A,"Amount (NIS)") -> 164431.7 | H7: =SUMIFS('Source 2026'!$I:$I,'Source 2026'!$B:$B,$A7,'Source 2026'!$A:$A,"Amount (NIS)") -> 11519.9 | I7: =H7-G7 -> -152911.8 | J7: =IF(AND(G7=0,H7=0),0,IF(G7=0,"New",(H7-G7)/G7)) -> -0.92994112
A8: 39-42 | B8: =IFERROR(INDEX('Source 2026'!$C:$C,MATCH($A8,'Source 2026'!$B:$B,0)),IFERROR(INDEX('Source 2025'!$C:$C,MATCH($A8,'Source 2025'!$B:$B,0)),"")) -> מדרסי אפיק ג'ל נוחות | C8: =SUMIFS('Source 2025'!$I:$I,'Source 2025'!$B:$B,$A8,'Source 2025'!$A:$A,"Quantity (units)") -> 2025 | D8: =SUMIFS('Source 2026'!$I:$I,'Source 2026'!$B:$B,$A8,'Source 2026'!$A:$A,"Quantity (units)") -> 522 | E8: =D8-C8 -> -1503 | F8: =IF(AND(C8=0,D8=0),0,IF(C8=0,"New",(D8-C8)/C8)) -> -0.74222222 | G8: =SUMIFS('Source 2025'!$I:$I,'Source 2025'!$B:$B,$A8,'Source 2025'!$A:$A,"Amount (NIS)") -> 188767.1 | H8: =SUMIFS('Source 2026'!$I:$I,'Source 2026'!$B:$B,$A8,'Source 2026'!$A:$A,"Amount (NIS)") -> 52314 | I8: =H8-G8 -> -136453.1 | J8: =IF(AND(G8=0,H8=0),0,IF(G8=0,"New",(H8-G8)/G8)) -> -0.72286484
A9: 43-47 | B9: =IFERROR(INDEX('Source 2026'!$C:$C,MATCH($A9,'Source 2026'!$B:$B,0)),IFERROR(INDEX('Source 2025'!$C:$C,MATCH($A9,'Source 2025'!$B:$B,0)),"")) -> מדרסי אפיק ג'ל נוחות | C9: =SUMIFS('Source 2025'!$I:$I,'Source 2025'!$B:$B,$A9,'Source 2025'!$A:$A,"Quantity (units)") -> 2122 | D9: =SUMIFS('Source 2026'!$I:$I,'Source 2026'!$B:$B,$A9,'Source 2026'!$A:$A,"Quantity (units)") -> 789 | E9: =D9-C9 -> -1333 | F9: =IF(AND(C9=0,D9=0),0,IF(C9=0,"New",(D9-C9)/C9)) -> -0.62818096 | G9: =SUMIFS('Source 2025'!$I:$I,'Source 2025'!$B:$B,$A9,'Source 2025'!$A:$A,"Amount (NIS)") -> 197774.9 | H9: =SUMIFS('Source 2026'!$I:$I,'Source 2026'!$B:$B,$A9,'Source 2026'!$A:$A,"Amount (NIS)") -> 78734.4 | I9: =H9-G9 -> -119040.5 | J9: =IF(AND(G9=0,H9=0),0,IF(G9=0,"New",(H9-G9)/G9)) -> -0.60189893
A10: 26 | B10: =IFERROR(INDEX('Source 2026'!$C:$C,MATCH($A10,'Source 2026'!$B:$B,0)),IFERROR(INDEX('Source 2025'!$C:$C,MATCH($A10,'Source 2025'!$B:$B,0)),"")) -> L סד ליד דו צדדי לאחר שבר | C10: =SUMIFS('Source 2025'!$I:$I,'Source 2025'!$B:$B,$A10,'Source 2025'!$A:$A,"Quantity (units)") -> 2734 | D10: =SUMIFS('Source 2026'!$I:$I,'Source 2026'!$B:$B,$A10,'Source 2026'!$A:$A,"Quantity (units)") -> 1361 | E10: =D10-C10 -> -1373 | F10: =IF(AND(C10=0,D10=0),0,IF(C10=0,"New",(D10-C10)/C10)) -> -0.50219459 | G10: =SUMIFS('Source 2025'!$I:$I,'Source 2025'!$B:$B,$A10,'Source 2025'!$A:$A,"Amount (NIS)") -> 224663.9 | H10: =SUMIFS('Source 2026'!$I:$I,'Source 2026'!$B:$B,$A10,'Source 2026'!$A:$A,"Amount (NIS)") -> 113662.8 | I10: =H10-G10 -> -111001.1 | J10: =IF(AND(G10=0,H10=0),0,IF(G10=0,"New",(H10-G10)/G10)) -> -0.49407626
A11: 397 | B11: =IFERROR(INDEX('Source 2026'!$C:$C,MATCH($A11,'Source 2026'!$B:$B,0)),IFERROR(INDEX('Source 2025'!$C:$C,MATCH($A11,'Source 2025'!$B:$B,0)),"")) -> 35-38 גרבי טיסה מידה | C11: =SUMIFS('Source 2025'!$I:$I,'Source 2025'!$B:$B,$A11,'Source 2025'!$A:$A,"Quantity (units)") -> 2048 | D11: =SUMIFS('Source 2026'!$I:$I,'Source 2026'!$B:$B,$A11,'Source 2026'!$A:$A,"Quantity (units)") -> -9 | E11: =D11-C11 -> -2057 | F11: =IF(AND(C11=0,D11=0),0,IF(C11=0,"New",(D11-C11)/C11)) -> -1.0043945 | G11: =SUMIFS('Source 2025'!$I:$I,'Source 2025'!$B:$B,$A11,'Source 2025'!$A:$A,"Amount (NIS)") -> 110040.8 | H11: =SUMIFS('Source 2026'!$I:$I,'Source 2026'!$B:$B,$A11,'Source 2026'!$A:$A,"Amount (NIS)") -> -457.7 | I11: =H11-G11 -> -110498.5 | J11: =IF(AND(G11=0,H11=0),0,IF(G11=0,"New",(H11-G11)/G11)) -> -1.0041594
A12: 35C | B12: =IFERROR(INDEX('Source 2026'!$C:$C,MATCH($A12,'Source 2026'!$B:$B,0)),IFERROR(INDEX('Source 2025'!$C:$C,MATCH($A12,'Source 2025'!$B:$B,0)),"")) -> S מגן קרסול חום | C12: =SUMIFS('Source 2025'!$I:$I,'Source 2025'!$B:$B,$A12,'Source 2025'!$A:$A,"Quantity (units)") -> 11682 | D12: =SUMIFS('Source 2026'!$I:$I,'Source 2026'!$B:$B,$A12,'Source 2026'!$A:$A,"Quantity (units)") -> 7746 | E12: =D12-C12 -> -3936 | F12: =IF(AND(C12=0,D12=0),0,IF(C12=0,"New",(D12-C12)/C12)) -> -0.33692861 | G12: =SUMIFS('Source 2025'!$I:$I,'Source 2025'!$B:$B,$A12,'Source 2025'!$A:$A,"Amount (NIS)") -> 302519 | H12: =SUMIFS('Source 2026'!$I:$I,'Source 2026'!$B:$B,$A12,'Source 2026'!$A:$A,"Amount (NIS)") -> 203753.2 | I12: =H12-G12 -> -98765.8 | J12: =IF(AND(G12=0,H12=0),0,IF(G12=0,"New",(H12-G12)/G12)) -> -0.32647801
A13: 21 | B13: =IFERROR(INDEX('Source 2026'!$C:$C,MATCH($A13,'Source 2026'!$B:$B,0)),IFERROR(INDEX('Source 2025'!$C:$C,MATCH($A13,'Source 2025'!$B:$B,0)),"")) -> S חבק יד ארוך | C13: =SUMIFS('Source 2025'!$I:$I,'Source 2025'!$B:$B,$A13,'Source 2025'!$A:$A,"Quantity (units)") -> 9023 | D13: =SUMIFS('Source 2026'!$I:$I,'Source 2026'!$B:$B,$A13,'Source 2026'!$A:$A,"Quantity (units)") -> 6005 | E13: =D13-C13 -> -3018 | F13: =IF(AND(C13=0,D13=0),0,IF(C13=0,"New",(D13-C13)/C13)) -> -0.33447855 | G13: =SUMIFS('Source 2025'!$I:$I,'Source 2025'!$B:$B,$A13,'Source 2025'!$A:$A,"Amount (NIS)") -> 296880.7 | H13: =SUMIFS('Source 2026'!$I:$I,'Source 2026'!$B:$B,$A13,'Source 2026'!$A:$A,"Amount (NIS)") -> 199190.1 | I13: =H13-G13 -> -97690.6 | J13: =IF(AND(G13=0,H13=0),0,IF(G13=0,"New",(H13-G13)/G13)) -> -0.32905676
A14: 397A-גרבי | B14: =IFERROR(INDEX('Source 2026'!$C:$C,MATCH($A14,'Source 2026'!$B:$B,0)),IFERROR(INDEX('Source 2025'!$C:$C,MATCH($A14,'Source 2025'!$B:$B,0)),"")) -> טיסה אנטי בקטרי35-38 | C14: =SUMIFS('Source 2025'!$I:$I,'Source 2025'!$B:$B,$A14,'Source 2025'!$A:$A,"Quantity (units)") -> 0 | D14: =SUMIFS('Source 2026'!$I:$I,'Source 2026'!$B:$B,$A14,'Source 2026'!$A:$A,"Quantity (units)") -> 1552 | E14: =D14-C14 -> 1552 | F14: =IF(AND(C14=0,D14=0),0,IF(C14=0,"New",(D14-C14)/C14)) -> New | G14: =SUMIFS('Source 2025'!$I:$I,'Source 2025'!$B:$B,$A14,'Source 2025'!$A:$A,"Amount (NIS)") -> 0 | H14: =SUMIFS('Source 2026'!$I:$I,'Source 2026'!$B:$B,$A14,'Source 2026'!$A:$A,"Amount (NIS)") -> 84761 | I14: =H14-G14 -> 84761 | J14: =IF(AND(G14=0,H14=0),0,IF(G14=0,"New",(H14-G14)/G14)) -> New
A15: 34 | B15: =IFERROR(INDEX('Source 2026'!$C:$C,MATCH($A15,'Source 2026'!$B:$B,0)),IFERROR(INDEX('Source 2025'!$C:$C,MATCH($A15,'Source 2025'!$B:$B,0)),"")) -> M מגן קרסול עקב סגור | C15: =SUMIFS('Source 2025'!$I:$I,'Source 2025'!$B:$B,$A15,'Source 2025'!$A:$A,"Quantity (units)") -> 6872 | D15: =SUMIFS('Source 2026'!$I:$I,'Source 2026'!$B:$B,$A15,'Source 2026'!$A:$A,"Quantity (units)") -> 4609 | E15: =D15-C15 -> -2263 | F15: =IF(AND(C15=0,D15=0),0,IF(C15=0,"New",(D15-C15)/C15)) -> -0.32930733 | G15: =SUMIFS('Source 2025'!$I:$I,'Source 2025'!$B:$B,$A15,'Source 2025'!$A:$A,"Amount (NIS)") -> 260017.5 | H15: =SUMIFS('Source 2026'!$I:$I,'Source 2026'!$B:$B,$A15,'Source 2026'!$A:$A,"Amount (NIS)") -> 176444.8 | I15: =H15-G15 -> -83572.7 | J15: =IF(AND(G15=0,H15=0),0,IF(G15=0,"New",(H15-G15)/G15)) -> -0.32141183
A16: 45C | B16: =IFERROR(INDEX('Source 2026'!$C:$C,MATCH($A16,'Source 2026'!$B:$B,0)),IFERROR(INDEX('Source 2025'!$C:$C,MATCH($A16,'Source 2025'!$B:$B,0)),"")) -> S מגן ברך חום | C16: =SUMIFS('Source 2025'!$I:$I,'Source 2025'!$B:$B,$A16,'Source 2025'!$A:$A,"Quantity (units)") -> 11105 | D16: =SUMIFS('Source 2026'!$I:$I,'Source 2026'!$B:$B,$A16,'Source 2026'!$A:$A,"Quantity (units)") -> 8013 | E16: =D16-C16 -> -3092 | F16: =IF(AND(C16=0,D16=0),0,IF(C16=0,"New",(D16-C16)/C16)) -> -0.27843314 | G16: =SUMIFS('Source 2025'!$I:$I,'Source 2025'!$B:$B,$A16,'Source 2025'!$A:$A,"Amount (NIS)") -> 287948.7 | H16: =SUMIFS('Source 2026'!$I:$I,'Source 2026'!$B:$B,$A16,'Source 2026'!$A:$A,"Amount (NIS)") -> 209745.6 | I16: =H16-G16 -> -78203.1 | J16: =IF(AND(G16=0,H16=0),0,IF(G16=0,"New",(H16-G16)/G16)) -> -0.27158692
A17: AC75 | B17: =IFERROR(INDEX('Source 2026'!$C:$C,MATCH($A17,'Source 2026'!$B:$B,0)),IFERROR(INDEX('Source 2025'!$C:$C,MATCH($A17,'Source 2025'!$B:$B,0)),"")) -> מישר כתפיים אקטיב | C17: =SUMIFS('Source 2025'!$I:$I,'Source 2025'!$B:$B,$A17,'Source 2025'!$A:$A,"Quantity (units)") -> 738 | D17: =SUMIFS('Source 2026'!$I:$I,'Source 2026'!$B:$B,$A17,'Source 2026'!$A:$A,"Quantity (units)") -> 1790 | E17: =D17-C17 -> 1052 | F17: =IF(AND(C17=0,D17=0),0,IF(C17=0,"New",(D17-C17)/C17)) -> 1.4254743 | G17: =SUMIFS('Source 2025'!$I:$I,'Source 2025'!$B:$B,$A17,'Source 2025'!$A:$A,"Amount (NIS)") -> 46423.4 | H17: =SUMIFS('Source 2026'!$I:$I,'Source 2026'!$B:$B,$A17,'Source 2026'!$A:$A,"Amount (NIS)") -> 116307.2 | I17: =H17-G17 -> 69883.8 | J17: =IF(AND(G17=0,H17=0),0,IF(G17=0,"New",(H17-G17)/G17)) -> 1.5053572
... A260: 12 | B260: =IFERROR(INDEX('Source 2026'!$C:$C,MATCH($A260,'Source 2026'!$B:$B,0)),IFERROR(INDEX('Source 2025'!$C:$C,MATCH($A260,'Source 2025'!$B:$B,0)),"")) -> XL ח.גב מגנטית+מוטות תמיכה | C260: =SUMIFS('Source 2025'!$I:$I,'Source 2025'!$B:$B,$A260,'Source 2025'!$A:$A,"Quantity (units)") -> -1 | D260: =SUMIFS('Source 2026'!$I:$I,'Source 2026'!$B:$B,$A260,'Source 2026'!$A:$A,"Quantity (units)") -> -1 | E260: =D260-C260 -> 0 | F260: =IF(AND(C260=0,D260=0),0,IF(C260=0,"New",(D260-C260)/C260)) -> 0 | G260: =SUMIFS('Source 2025'!$I:$I,'Source 2025'!$B:$B,$A260,'Source 2025'!$A:$A,"Amount (NIS)") -> -178.6 | H260: =SUMIFS('Source 2026'!$I:$I,'Source 2026'!$B:$B,$A260,'Source 2026'!$A:$A,"Amount (NIS)") -> -178.6 | I260: =H260-G260 -> 0 | J260: =IF(AND(G260=0,H260=0),0,IF(G260=0,"New",(H260-G260)/G260)) -> 0
B262: TOTAL | C262: =SUM(C6:C260) -> 204428 | D262: =SUM(D6:D260) -> 137851 | E262: =SUM(E6:E260) -> -66577 | F262: =IF(C262=0,"N/A",E262/C262) -> -0.32567457 | G262: =SUM(G6:G260) -> 7597886.3 | H262: =SUM(H6:H260) -> 5165969.3 | I262: =SUM(I6:I260) -> -2431917 | J262: =IF(G262=0,"N/A",I262/G262) -> -0.3200781

Sheet BE
A1: Sales Comparison 2025 vs 2026 - Customer: BE (by Product CODE)
A2: Calculation date: | B2: 46284
A3: Source: PPlay1 of uriel (Reporter) product x customer pivot reports for 2025 and 2026, customer column "BE" only (raw values in 'Source 2025'!$J:$J / 'Source 2026'!$J:$J). Each file has two data blocks: "נטו" (Net Amount, NIS) and "סהכ יחידות" (Total Units). Product CODE parsed as the first token of column B in the original file (before the first space); size/color variants sharing the same base CODE are summed together via SUMIFS. Rows below only include product codes with non-zero quantity or amount for this customer in at least one of the two years; codes that are 0 for this customer in both years (sold only to other customers) were excluded as not relevant to this comparison.
A5: Product Code | B5: Product Name | C5: Quantity 2025 | D5: Quantity 2026 | E5: Quantity Change | F5: Quantity Change % | G5: Amount 2025 (₪) | H5: Amount 2026 (₪) | I5: Amount Change (₪) | J5: Amount Change %
A6: (No product codes with activity for this customer in either 2025 or 2026)
B7: TOTAL | C7: 0 | D7: 0 | E7: 0 | F7: 0 | G7: 0 | H7: 0 | I7: 0 | J7: 0

Sheet אילת BE
A1: Sales Comparison 2025 vs 2026 - Customer: אילת BE (by Product CODE)
A2: Calculation date: | B2: 46284
A3: Source: PPlay1 of uriel (Reporter) product x customer pivot reports for 2025 and 2026, customer column "אילת BE" only (raw values in 'Source 2025'!$K:$K / 'Source 2026'!$K:$K). Each file has two data blocks: "נטו" (Net Amount, NIS) and "סהכ יחידות" (Total Units). Product CODE parsed as the first token of column B in the original file (before the first space); size/color variants sharing the same base CODE are summed together via SUMIFS. Rows below only include product codes with non-zero quantity or amount for this customer in at least one of the two years; codes that are 0 for this customer in both years (sold only to other customers) were excluded as not relevant to this comparison.
A5: Product Code | B5: Product Name | C5: Quantity 2025 | D5: Quantity 2026 | E5: Quantity Change | F5: Quantity Change % | G5: Amount 2025 (₪) | H5: Amount 2026 (₪) | I5: Amount Change (₪) | J5: Amount Change %
A6: PD340-קוצץ | B6: =IFERROR(INDEX('Source 2026'!$C:$C,MATCH($A6,'Source 2026'!$B:$B,0)),IFERROR(INDEX('Source 2025'!$C:$C,MATCH($A6,'Source 2025'!$B:$B,0)),"")) -> ציפורניים | C6: =SUMIFS('Source 2025'!$K:$K,'Source 2025'!$B:$B,$A6,'Source 2025'!$A:$A,"Quantity (units)") -> 372 | D6: =SUMIFS('Source 2026'!$K:$K,'Source 2026'!$B:$B,$A6,'Source 2026'!$A:$A,"Quantity (units)") -> 137 | E6: =D6-C6 -> -235 | F6: =IF(AND(C6=0,D6=0),0,IF(C6=0,"New",(D6-C6)/C6)) -> -0.63172043 | G6: =SUMIFS('Source 2025'!$K:$K,'Source 2025'!$B:$B,$A6,'Source 2025'!$A:$A,"Amount (NIS)") -> 4892.8 | H6: =SUMIFS('Source 2026'!$K:$K,'Source 2026'!$B:$B,$A6,'Source 2026'!$A:$A,"Amount (NIS)") -> 1801.9 | I6: =H6-G6 -> -3090.9 | J6: =IF(AND(G6=0,H6=0),0,IF(G6=0,"New",(H6-G6)/G6)) -> -0.63172417
