Workbook

Sheet דודו
A1: ביצועי סניפים לפי סוכן — דודו (Top 20 לפי מכירות 2026)
A2: תאריך חישוב: | B2: 46235
A4: # | B4: שם הסניף | C4: שם הסוכן | D4: מכירות 2026 | E4: מכירות 2025 | F4: קצב 2025 | G4: 2026 מול קצב 2025 (%) | H4: מיקום אורתופדיה | I4: מיקום כללי
A5: 1 | B5: =IFERROR(INDEX(מקור!$A$2:$A$309,MATCH("דודו|"&A5,מקור!$K$2:$K$309,0)),"") -> הדסה עין כרם~138 | C5: דודו | D5: =IFERROR(INDEX(מקור!$I$2:$I$309,MATCH("דודו|"&A5,מקור!$K$2:$K$309,0)),"") -> 40303.1 | E5: =IFERROR(INDEX(מקור!$J$2:$J$309,MATCH("דודו|"&A5,מקור!$K$2:$K$309,0)),"") -> 70289.5 | F5: =IFERROR(E5/12*6,"") -> 35144.75 | G5: =IFERROR(D5/F5-1,"") -> 0.14677441 | H5: =IFERROR(INDEX(מקור!$B$2:$B$309,MATCH("דודו|"&A5,מקור!$K$2:$K$309,0)),"") -> 3 | I5: =IFERROR(INDEX(מקור!$C$2:$C$309,MATCH("דודו|"&A5,מקור!$K$2:$K$309,0)),"") -> 133
A6: 2 | B6: =IFERROR(INDEX(מקור!$A$2:$A$309,MATCH("דודו|"&A6,מקור!$K$2:$K$309,0)),"") -> גאלרי כיכר-ציון~219 | C6: דודו | D6: =IFERROR(INDEX(מקור!$I$2:$I$309,MATCH("דודו|"&A6,מקור!$K$2:$K$309,0)),"") -> 34207.6 | E6: =IFERROR(INDEX(מקור!$J$2:$J$309,MATCH("דודו|"&A6,מקור!$K$2:$K$309,0)),"") -> 46442.7 | F6: =IFERROR(E6/12*6,"") -> 23221.35 | G6: =IFERROR(D6/F6-1,"") -> 0.47310988 | H6: =IFERROR(INDEX(מקור!$B$2:$B$309,MATCH("דודו|"&A6,מקור!$K$2:$K$309,0)),"") -> 11 | I6: =IFERROR(INDEX(מקור!$C$2:$C$309,MATCH("דודו|"&A6,מקור!$K$2:$K$309,0)),"") -> 55
A7: 3 | B7: =IFERROR(INDEX(מקור!$A$2:$A$309,MATCH("דודו|"&A7,מקור!$K$2:$K$309,0)),"") -> אשדוד סטאר-סנטר~117 | C7: דודו | D7: =IFERROR(INDEX(מקור!$I$2:$I$309,MATCH("דודו|"&A7,מקור!$K$2:$K$309,0)),"") -> 34181.8 | E7: =IFERROR(INDEX(מקור!$J$2:$J$309,MATCH("דודו|"&A7,מקור!$K$2:$K$309,0)),"") -> 63211.5 | F7: =IFERROR(E7/12*6,"") -> 31605.75 | G7: =IFERROR(D7/F7-1,"") -> 0.081505739 | H7: =IFERROR(INDEX(מקור!$B$2:$B$309,MATCH("דודו|"&A7,מקור!$K$2:$K$309,0)),"") -> 5 | I7: =IFERROR(INDEX(מקור!$C$2:$C$309,MATCH("דודו|"&A7,מקור!$K$2:$K$309,0)),"") -> 31
A8: 4 | B8: =IFERROR(INDEX(מקור!$A$2:$A$309,MATCH("דודו|"&A8,מקור!$K$2:$K$309,0)),"") -> רמות ירושלים~184 | C8: דודו | D8: =IFERROR(INDEX(מקור!$I$2:$I$309,MATCH("דודו|"&A8,מקור!$K$2:$K$309,0)),"") -> 33328.8 | E8: =IFERROR(INDEX(מקור!$J$2:$J$309,MATCH("דודו|"&A8,מקור!$K$2:$K$309,0)),"") -> 58295.4 | F8: =IFERROR(E8/12*6,"") -> 29147.7 | G8: =IFERROR(D8/F8-1,"") -> 0.14344528 | H8: =IFERROR(INDEX(מקור!$B$2:$B$309,MATCH("דודו|"&A8,מקור!$K$2:$K$309,0)),"") -> 24 | I8: =IFERROR(INDEX(מקור!$C$2:$C$309,MATCH("דודו|"&A8,מקור!$K$2:$K$309,0)),"") -> 63
A9: 5 | B9: =IFERROR(INDEX(מקור!$A$2:$A$309,MATCH("דודו|"&A9,מקור!$K$2:$K$309,0)),"") -> מודיעין ישפרו~125 | C9: דודו | D9: =IFERROR(INDEX(מקור!$I$2:$I$309,MATCH("דודו|"&A9,מקור!$K$2:$K$309,0)),"") -> 31106.1 | E9: =IFERROR(INDEX(מקור!$J$2:$J$309,MATCH("דודו|"&A9,מקור!$K$2:$K$309,0)),"") -> 51666.7 | F9: =IFERROR(E9/12*6,"") -> 25833.35 | G9: =IFERROR(D9/F9-1,"") -> 0.20410632 | H9: =IFERROR(INDEX(מקור!$B$2:$B$309,MATCH("דודו|"&A9,מקור!$K$2:$K$309,0)),"") -> 14 | I9: =IFERROR(INDEX(מקור!$C$2:$C$309,MATCH("דודו|"&A9,מקור!$K$2:$K$309,0)),"") -> 39
A10: 6 | B10: =IFERROR(INDEX(מקור!$A$2:$A$309,MATCH("דודו|"&A10,מקור!$K$2:$K$309,0)),"") -> קניון-מודיעין~153 | C10: דודו | D10: =IFERROR(INDEX(מקור!$I$2:$I$309,MATCH("דודו|"&A10,מקור!$K$2:$K$309,0)),"") -> 30919.3 | E10: =IFERROR(INDEX(מקור!$J$2:$J$309,MATCH("דודו|"&A10,מקור!$K$2:$K$309,0)),"") -> 52742 | F10: =IFERROR(E10/12*6,"") -> 26371 | G10: =IFERROR(D10/F10-1,"") -> 0.17247355 | H10: =IFERROR(INDEX(מקור!$B$2:$B$309,MATCH("דודו|"&A10,מקור!$K$2:$K$309,0)),"") -> 4 | I10: =IFERROR(INDEX(מקור!$C$2:$C$309,MATCH("דודו|"&A10,מקור!$K$2:$K$309,0)),"") -> 26
A11: 7 | B11: =IFERROR(INDEX(מקור!$A$2:$A$309,MATCH("דודו|"&A11,מקור!$K$2:$K$309,0)),"") -> אשקלון גירון~28 | C11: דודו | D11: =IFERROR(INDEX(מקור!$I$2:$I$309,MATCH("דודו|"&A11,מקור!$K$2:$K$309,0)),"") -> 29916.7 | E11: =IFERROR(INDEX(מקור!$J$2:$J$309,MATCH("דודו|"&A11,מקור!$K$2:$K$309,0)),"") -> 56802.8 | F11: =IFERROR(E11/12*6,"") -> 28401.4 | G11: =IFERROR(D11/F11-1,"") -> 0.053353004 | H11: =IFERROR(INDEX(מקור!$B$2:$B$309,MATCH("דודו|"&A11,מקור!$K$2:$K$309,0)),"") -> 17 | I11: =IFERROR(INDEX(מקור!$C$2:$C$309,MATCH("דודו|"&A11,מקור!$K$2:$K$309,0)),"") -> 44
A12: 8 | B12: =IFERROR(INDEX(מקור!$A$2:$A$309,MATCH("דודו|"&A12,מקור!$K$2:$K$309,0)),"") -> גאלרי מלחה~30 | C12: דודו | D12: =IFERROR(INDEX(מקור!$I$2:$I$309,MATCH("דודו|"&A12,מקור!$K$2:$K$309,0)),"") -> 25566.1 | E12: =IFERROR(INDEX(מקור!$J$2:$J$309,MATCH("דודו|"&A12,מקור!$K$2:$K$309,0)),"") -> 52586.4 | F12: =IFERROR(E12/12*6,"") -> 26293.2 | G12: =IFERROR(D12/F12-1,"") -> -0.027653538 | H12: =IFERROR(INDEX(מקור!$B$2:$B$309,MATCH("דודו|"&A12,מקור!$K$2:$K$309,0)),"") -> 16 | I12: =IFERROR(INDEX(מקור!$C$2:$C$309,MATCH("דודו|"&A12,מקור!$K$2:$K$309,0)),"") -> 13
A13: 9 | B13: =IFERROR(INDEX(מקור!$A$2:$A$309,MATCH("דודו|"&A13,מקור!$K$2:$K$309,0)),"") -> קניון רחובות~45 | C13: דודו | D13: =IFERROR(INDEX(מקור!$I$2:$I$309,MATCH("דודו|"&A13,מקור!$K$2:$K$309,0)),"") -> 24091.9 | E13: =IFERROR(INDEX(מקור!$J$2:$J$309,MATCH("דודו|"&A13,מקור!$K$2:$K$309,0)),"") -> 50792.3 | F13: =IFERROR(E13/12*6,"") -> 25396.15 | G13: =IFERROR(D13/F13-1,"") -> -0.05135621 | H13: =IFERROR(INDEX(מקור!$B$2:$B$309,MATCH("דודו|"&A13,מקור!$K$2:$K$309,0)),"") -> 13 | I13: =IFERROR(INDEX(מקור!$C$2:$C$309,MATCH("דודו|"&A13,מקור!$K$2:$K$309,0)),"") -> 16
A14: 10 | B14: =IFERROR(INDEX(מקור!$A$2:$A$309,MATCH("דודו|"&A14,מקור!$K$2:$K$309,0)),"") -> תלפיות~95 | C14: דודו | D14: =IFERROR(INDEX(מקור!$I$2:$I$309,MATCH("דודו|"&A14,מקור!$K$2:$K$309,0)),"") -> 22454.5 | E14: =IFERROR(INDEX(מקור!$J$2:$J$309,MATCH("דודו|"&A14,מקור!$K$2:$K$309,0)),"") -> 46557.9 | F14: =IFERROR(E14/12*6,"") -> 23278.95 | G14: =IFERROR(D14/F14-1,"") -> -0.035416116 | H14: =IFERROR(INDEX(מקור!$B$2:$B$309,MATCH("דודו|"&A14,מקור!$K$2:$K$309,0)),"") -> 25 | I14: =IFERROR(INDEX(מקור!$C$2:$C$309,MATCH("דודו|"&A14,מקור!$K$2:$K$309,0)),"") -> 64
A15: 11 | B15: =IFERROR(INDEX(מקור!$A$2:$A$309,MATCH("דודו|"&A15,מקור!$K$2:$K$309,0)),"") -> ניות~2 | C15: דודו | D15: =IFERROR(INDEX(מקור!$I$2:$I$309,MATCH("דודו|"&A15,מקור!$K$2:$K$309,0)),"") -> 22141.7 | E15: =IFERROR(INDEX(מקור!$J$2:$J$309,MATCH("דודו|"&A15,מקור!$K$2:$K$309,0)),"") -> 42012.2 | F15: =IFERROR(E15/12*6,"") -> 21006.1 | G15: =IFERROR(D15/F15-1,"") -> 0.054060487 | H15: =IFERROR(INDEX(מקור!$B$2:$B$309,MATCH("דודו|"&A15,מקור!$K$2:$K$309,0)),"") -> 43 | I15: =IFERROR(INDEX(מקור!$C$2:$C$309,MATCH("דודו|"&A15,מקור!$K$2:$K$309,0)),"") -> 69
A16: 12 | B16: =IFERROR(INDEX(מקור!$A$2:$A$309,MATCH("דודו|"&A16,מקור!$K$2:$K$309,0)),"") -> בילו סנטר~52 | C16: דודו | D16: =IFERROR(INDEX(מקור!$I$2:$I$309,MATCH("דודו|"&A16,מקור!$K$2:$K$309,0)),"") -> 21969.8 | E16: =IFERROR(INDEX(מקור!$J$2:$J$309,MATCH("דודו|"&A16,מקור!$K$2:$K$309,0)),"") -> 39005.8 | F16: =IFERROR(E16/12*6,"") -> 19502.9 | G16: =IFERROR(D16/F16-1,"") -> 0.12648888 | H16: =IFERROR(INDEX(מקור!$B$2:$B$309,MATCH("דודו|"&A16,מקור!$K$2:$K$309,0)),"") -> 15 | I16: =IFERROR(INDEX(מקור!$C$2:$C$309,MATCH("דודו|"&A16,מקור!$K$2:$K$309,0)),"") -> 36
... A24: 20 | B24: =IFERROR(INDEX(מקור!$A$2:$A$309,MATCH("דודו|"&A24,מקור!$K$2:$K$309,0)),"") -> אשדוד סיטי~40 | C24: דודו | D24: =IFERROR(INDEX(מקור!$I$2:$I$309,MATCH("דודו|"&A24,מקור!$K$2:$K$309,0)),"") -> 18434.6 | E24: =IFERROR(INDEX(מקור!$J$2:$J$309,MATCH("דודו|"&A24,מקור!$K$2:$K$309,0)),"") -> 36774.5 | F24: =IFERROR(E24/12*6,"") -> 18387.25 | G24: =IFERROR(D24/F24-1,"") -> 0.002575154 | H24: =IFERROR(INDEX(מקור!$B$2:$B$309,MATCH("דודו|"&A24,מקור!$K$2:$K$309,0)),"") -> 26 | I24: =IFERROR(INDEX(מקור!$C$2:$C$309,MATCH("דודו|"&A24,מקור!$K$2:$K$309,0)),"") -> 18
A26: הערה: "20 הסניפים הכי חזקים" מדורגים לפי מכירות 2026 בפועל (לא לפי אחוז שינוי מול 2025). קצב 2025 = מכירות 2025 (שנה מלאה) חלקי 12 כפול 6, כדי להשוות לחצי-שנה של 2026.

Sheet דודו - אורתופדיה
A1: דודו — כל הסניפים מדורגים לפי מיקום באורתופדיה (פער מול דירוג מכירות)
A2: תאריך חישוב: | B2: 46235
A4: דירוג אורתופדיה (בין סניפי דודו) | B4: שם הסניף | C4: מיקום באורתופדיה (ברשת כולה) | D4: מכירות 2026 | E4: דירוג מכירות (בין סניפי דודו) | F4: פער (מכירות מול אורתופדיה)
A5: 1 | B5: =IFERROR(INDEX(מקור!$A$2:$A$309,MATCH("דודו|"&A5,מקור!$L$2:$L$309,0)),"") -> הדסה עין כרם~138 | C5: =IFERROR(INDEX(מקור!$B$2:$B$309,MATCH("דודו|"&A5,מקור!$L$2:$L$309,0)),"") -> 3 | D5: =IFERROR(INDEX(מקור!$I$2:$I$309,MATCH("דודו|"&A5,מקור!$L$2:$L$309,0)),"") -> 40303.1 | E5: =IFERROR(INDEX(מקור!$M$2:$M$309,MATCH("דודו|"&A5,מקור!$L$2:$L$309,0)),"") -> 1 | F5: =IFERROR(E5-A5,"") -> 0
A6: 2 | B6: =IFERROR(INDEX(מקור!$A$2:$A$309,MATCH("דודו|"&A6,מקור!$L$2:$L$309,0)),"") -> קניון-מודיעין~153 | C6: =IFERROR(INDEX(מקור!$B$2:$B$309,MATCH("דודו|"&A6,מקור!$L$2:$L$309,0)),"") -> 4 | D6: =IFERROR(INDEX(מקור!$I$2:$I$309,MATCH("דודו|"&A6,מקור!$L$2:$L$309,0)),"") -> 30919.3 | E6: =IFERROR(INDEX(מקור!$M$2:$M$309,MATCH("דודו|"&A6,מקור!$L$2:$L$309,0)),"") -> 6 | F6: =IFERROR(E6-A6,"") -> 4
A7: 3 | B7: =IFERROR(INDEX(מקור!$A$2:$A$309,MATCH("דודו|"&A7,מקור!$L$2:$L$309,0)),"") -> אשדוד סטאר-סנטר~117 | C7: =IFERROR(INDEX(מקור!$B$2:$B$309,MATCH("דודו|"&A7,מקור!$L$2:$L$309,0)),"") -> 5 | D7: =IFERROR(INDEX(מקור!$I$2:$I$309,MATCH("דודו|"&A7,מקור!$L$2:$L$309,0)),"") -> 34181.8 | E7: =IFERROR(INDEX(מקור!$M$2:$M$309,MATCH("דודו|"&A7,מקור!$L$2:$L$309,0)),"") -> 3 | F7: =IFERROR(E7-A7,"") -> 0
A8: 4 | B8: =IFERROR(INDEX(מקור!$A$2:$A$309,MATCH("דודו|"&A8,מקור!$L$2:$L$309,0)),"") -> גאלרי כיכר-ציון~219 | C8: =IFERROR(INDEX(מקור!$B$2:$B$309,MATCH("דודו|"&A8,מקור!$L$2:$L$309,0)),"") -> 11 | D8: =IFERROR(INDEX(מקור!$I$2:$I$309,MATCH("דודו|"&A8,מקור!$L$2:$L$309,0)),"") -> 34207.6 | E8: =IFERROR(INDEX(מקור!$M$2:$M$309,MATCH("דודו|"&A8,מקור!$L$2:$L$309,0)),"") -> 2 | F8: =IFERROR(E8-A8,"") -> -2
A9: 5 | B9: =IFERROR(INDEX(מקור!$A$2:$A$309,MATCH("דודו|"&A9,מקור!$L$2:$L$309,0)),"") -> קניון רחובות~45 | C9: =IFERROR(INDEX(מקור!$B$2:$B$309,MATCH("דודו|"&A9,מקור!$L$2:$L$309,0)),"") -> 13 | D9: =IFERROR(INDEX(מקור!$I$2:$I$309,MATCH("דודו|"&A9,מקור!$L$2:$L$309,0)),"") -> 24091.9 | E9: =IFERROR(INDEX(מקור!$M$2:$M$309,MATCH("דודו|"&A9,מקור!$L$2:$L$309,0)),"") -> 9 | F9: =IFERROR(E9-A9,"") -> 4
A10: 6 | B10: =IFERROR(INDEX(מקור!$A$2:$A$309,MATCH("דודו|"&A10,מקור!$L$2:$L$309,0)),"") -> מודיעין ישפרו~125 | C10: =IFERROR(INDEX(מקור!$B$2:$B$309,MATCH("דודו|"&A10,מקור!$L$2:$L$309,0)),"") -> 14 | D10: =IFERROR(INDEX(מקור!$I$2:$I$309,MATCH("דודו|"&A10,מקור!$L$2:$L$309,0)),"") -> 31106.1 | E10: =IFERROR(INDEX(מקור!$M$2:$M$309,MATCH("דודו|"&A10,מקור!$L$2:$L$309,0)),"") -> 5 | F10: =IFERROR(E10-A10,"") -> -1
A11: 7 | B11: =IFERROR(INDEX(מקור!$A$2:$A$309,MATCH("דודו|"&A11,מקור!$L$2:$L$309,0)),"") -> בילו סנטר~52 | C11: =IFERROR(INDEX(מקור!$B$2:$B$309,MATCH("דודו|"&A11,מקור!$L$2:$L$309,0)),"") -> 15 | D11: =IFERROR(INDEX(מקור!$I$2:$I$309,MATCH("דודו|"&A11,מקור!$L$2:$L$309,0)),"") -> 21969.8 | E11: =IFERROR(INDEX(מקור!$M$2:$M$309,MATCH("דודו|"&A11,מקור!$L$2:$L$309,0)),"") -> 12 | F11: =IFERROR(E11-A11,"") -> 5
A12: 8 | B12: =IFERROR(INDEX(מקור!$A$2:$A$309,MATCH("דודו|"&A12,מקור!$L$2:$L$309,0)),"") -> גאלרי מלחה~30 | C12: =IFERROR(INDEX(מקור!$B$2:$B$309,MATCH("דודו|"&A12,מקור!$L$2:$L$309,0)),"") -> 16 | D12: =IFERROR(INDEX(מקור!$I$2:$I$309,MATCH("דודו|"&A12,מקור!$L$2:$L$309,0)),"") -> 25566.1 | E12: =IFERROR(INDEX(מקור!$M$2:$M$309,MATCH("דודו|"&A12,מקור!$L$2:$L$309,0)),"") -> 8 | F12: =IFERROR(E12-A12,"") -> 0
A13: 9 | B13: =IFERROR(INDEX(מקור!$A$2:$A$309,MATCH("דודו|"&A13,מקור!$L$2:$L$309,0)),"") -> אשקלון גירון~28 | C13: =IFERROR(INDEX(מקור!$B$2:$B$309,MATCH("דודו|"&A13,מקור!$L$2:$L$309,0)),"") -> 17 | D13: =IFERROR(INDEX(מקור!$I$2:$I$309,MATCH("דודו|"&A13,מקור!$L$2:$L$309,0)),"") -> 29916.7 | E13: =IFERROR(INDEX(מקור!$M$2:$M$309,MATCH("דודו|"&A13,מקור!$L$2:$L$309,0)),"") -> 7 | F13: =IFERROR(E13-A13,"") -> -2
A14: 10 | B14: =IFERROR(INDEX(מקור!$A$2:$A$309,MATCH("דודו|"&A14,מקור!$L$2:$L$309,0)),"") -> רמות ירושלים~184 | C14: =IFERROR(INDEX(מקור!$B$2:$B$309,MATCH("דודו|"&A14,מקור!$L$2:$L$309,0)),"") -> 24 | D14: =IFERROR(INDEX(מקור!$I$2:$I$309,MATCH("דודו|"&A14,מקור!$L$2:$L$309,0)),"") -> 33328.8 | E14: =IFERROR(INDEX(מקור!$M$2:$M$309,MATCH("דודו|"&A14,מקור!$L$2:$L$309,0)),"") -> 4 | F14: =IFERROR(E14-A14,"") -> -6
A15: 11 | B15: =IFERROR(INDEX(מקור!$A$2:$A$309,MATCH("דודו|"&A15,מקור!$L$2:$L$309,0)),"") -> תלפיות~95 | C15: =IFERROR(INDEX(מקור!$B$2:$B$309,MATCH("דודו|"&A15,מקור!$L$2:$L$309,0)),"") -> 25 | D15: =IFERROR(INDEX(מקור!$I$2:$I$309,MATCH("דודו|"&A15,מקור!$L$2:$L$309,0)),"") -> 22454.5 | E15: =IFERROR(INDEX(מקור!$M$2:$M$309,MATCH("דודו|"&A15,מקור!$L$2:$L$309,0)),"") -> 10 | F15: =IFERROR(E15-A15,"") -> -1
A16: 12 | B16: =IFERROR(INDEX(מקור!$A$2:$A$309,MATCH("דודו|"&A16,מקור!$L$2:$L$309,0)),"") -> אשדוד סיטי~40 | C16: =IFERROR(INDEX(מקור!$B$2:$B$309,MATCH("דודו|"&A16,מקור!$L$2:$L$309,0)),"") -> 26 | D16: =IFERROR(INDEX(מקור!$I$2:$I$309,MATCH("דודו|"&A16,מקור!$L$2:$L$309,0)),"") -> 18434.6 | E16: =IFERROR(INDEX(מקור!$M$2:$M$309,MATCH("דודו|"&A16,מקור!$L$2:$L$309,0)),"") -> 20 | F16: =IFERROR(E16-A16,"") -> 8
... A72: 68 | B72: =IFERROR(INDEX(מקור!$A$2:$A$309,MATCH("דודו|"&A72,מקור!$L$2:$L$309,0)),"") -> אשדוד ט"ז~345 | C72: =IFERROR(INDEX(מקור!$B$2:$B$309,MATCH("דודו|"&A72,מקור!$L$2:$L$309,0)),"") -> 301 | D72: =IFERROR(INDEX(מקור!$I$2:$I$309,MATCH("דודו|"&A72,מקור!$L$2:$L$309,0)),"") -> 2594.7 | E72: =IFERROR(INDEX(מקור!$M$2:$M$309,MATCH("דודו|"&A72,מקור!$L$2:$L$309,0)),"") -> 67 | F72: =IFERROR(E72-A72,"") -> -1
A74: הערה: הדירוג בעמודה A ובעמודה E הוא דירוג יחסי בין 68 סניפי דודו בלבד (לא הדירוג הכללי ברשת). פער = דירוג מכירות פחות דירוג אורתופדיה; פער חיובי וגדול = הסניף חזק באורתופדיה יחסית לסניפי דודו האחרים אך מוכר פחות טוב יחסית אליהם (פוטנציאל לא ממומש). שורות עם פער >= 10 מודגשות (הסף נבחר לפי התפלגות בפועל: פערים בין -14 ל-16, ממוצע 0, סטיית תקן כ-5).

Sheet מקור
A1: חנויות | B1: מיקום באורתופדיה | C1: מיקום בסך מכירות הרשת | D1: עיר | E1: אזור | F1: סוכן | G1: מיקום פר סוכן | H1: הערות | I1: מכירות שלנו לכל סניף 2026 | J1: מכירות שלנו לכל סניף 2025 | K1: מפתח מורכב (סוכן|דירוג מכירות) | L1: מפתח מורכב אורתופדיה (סוכן|דירוג אורתופדיה) | M1: דירוג מכירות (בין הסוכן) | O1: תאריך חישוב: | P1: 46235
A2: אבן-יהודה~268 | B2: 253 | C2: 223 | D2: אבן יהודה | E2: השרון | F2: חיים | I2: 3445 | J2: 5811.6 | K2: =IF(F2="","",TRIM(F2)&"|"&(SUMPRODUCT((TRIM($F$2:$F$309)=TRIM(F2))*($I$2:$I$309>I2))+1)) -> חיים|77 | L2: =IF(F2="","",TRIM(F2)&"|"&(SUMPRODUCT((TRIM($F$2:$F$309)=TRIM(F2))*($B$2:$B$309<B2))+1)) -> חיים|73 | M2: =IF(F2="","",SUMPRODUCT((TRIM($F$2:$F$309)=TRIM(F2))*($I$2:$I$309>I2))+1) -> 77
A3: אבן גבירול~109 | B3: 80 | C3: 145 | D3: ת"א | E3: ת"א | F3: חיים | I3: 20526 | J3: 24134.5 | K3: =IF(F3="","",TRIM(F3)&"|"&(SUMPRODUCT((TRIM($F$2:$F$309)=TRIM(F3))*($I$2:$I$309>I3))+1)) -> חיים|9 | L3: =IF(F3="","",TRIM(F3)&"|"&(SUMPRODUCT((TRIM($F$2:$F$309)=TRIM(F3))*($B$2:$B$309<B3))+1)) -> חיים|26 | M3: =IF(F3="","",SUMPRODUCT((TRIM($F$2:$F$309)=TRIM(F3))*($I$2:$I$309>I3))+1) -> 9
A4: אגמים אשקלון~318 | B4: 229 | C4: 227 | D4: אשקלון | E4: דרום | F4: דודו | I4: 5259.1 | J4: 17310.2 | K4: =IF(F4="","",TRIM(F4)&"|"&(SUMPRODUCT((TRIM($F$2:$F$309)=TRIM(F4))*($I$2:$I$309>I4))+1)) -> דודו|58 | L4: =IF(F4="","",TRIM(F4)&"|"&(SUMPRODUCT((TRIM($F$2:$F$309)=TRIM(F4))*($B$2:$B$309<B4))+1)) -> דודו|57 | M4: =IF(F4="","",SUMPRODUCT((TRIM($F$2:$F$309)=TRIM(F4))*($I$2:$I$309>I4))+1) -> 58
A5: אגמים נתניה~233 | B5: 213 | C5: 179 | D5: נתניה | E5: השרון | F5: חיים | I5: 8559.2 | J5: 19823.2 | K5: =IF(F5="","",TRIM(F5)&"|"&(SUMPRODUCT((TRIM($F$2:$F$309)=TRIM(F5))*($I$2:$I$309>I5))+1)) -> חיים|49 | L5: =IF(F5="","",TRIM(F5)&"|"&(SUMPRODUCT((TRIM($F$2:$F$309)=TRIM(F5))*($B$2:$B$309<B5))+1)) -> חיים|65 | M5: =IF(F5="","",SUMPRODUCT((TRIM($F$2:$F$309)=TRIM(F5))*($I$2:$I$309>I5))+1) -> 49
A6: אודיטוריום~111 | B6: 112 | C6: 93 | D6: חיפה והקריות | E6: חיפה | F6: חדש | G6: 12 | I6: 10897.3 | J6: 18916.7 | K6: =IF(F6="","",TRIM(F6)&"|"&(SUMPRODUCT((TRIM($F$2:$F$309)=TRIM(F6))*($I$2:$I$309>I6))+1)) -> חדש|16 | L6: =IF(F6="","",TRIM(F6)&"|"&(SUMPRODUCT((TRIM($F$2:$F$309)=TRIM(F6))*($B$2:$B$309<B6))+1)) -> חדש|17 | M6: =IF(F6="","",SUMPRODUCT((TRIM($F$2:$F$309)=TRIM(F6))*($I$2:$I$309>I6))+1) -> 16
A7: אום-אל-פאחם~129 | B7: 198 | C7: 167 | D7: אום אל פאחם | E7: צפון | F7: חדש | I7: 8203.8 | J7: 14488.6 | K7: =IF(F7="","",TRIM(F7)&"|"&(SUMPRODUCT((TRIM($F$2:$F$309)=TRIM(F7))*($I$2:$I$309>I7))+1)) -> חדש|27 | L7: =IF(F7="","",TRIM(F7)&"|"&(SUMPRODUCT((TRIM($F$2:$F$309)=TRIM(F7))*($B$2:$B$309<B7))+1)) -> חדש|44 | M7: =IF(F7="","",SUMPRODUCT((TRIM($F$2:$F$309)=TRIM(F7))*($I$2:$I$309>I7))+1) -> 27
A8: אונו פארק~327 | B8: 269 | C8: 235 | D8: קרית אונו | E8: צפון | F8: חדש | I8: 4982.2 | J8: 9100.3 | K8: =IF(F8="","",TRIM(F8)&"|"&(SUMPRODUCT((TRIM($F$2:$F$309)=TRIM(F8))*($I$2:$I$309>I8))+1)) -> חדש|49 | L8: =IF(F8="","",TRIM(F8)&"|"&(SUMPRODUCT((TRIM($F$2:$F$309)=TRIM(F8))*($B$2:$B$309<B8))+1)) -> חדש|69 | M8: =IF(F8="","",SUMPRODUCT((TRIM($F$2:$F$309)=TRIM(F8))*($I$2:$I$309>I8))+1) -> 49
A9: אוסישקין רמה"ש~127 | B9: 105 | C9: 59 | D9: רמת השרון | E9: מרכז | F9: חיים | G9: 19 | I9: 12679.3 | J9: 25328.7 | K9: =IF(F9="","",TRIM(F9)&"|"&(SUMPRODUCT((TRIM($F$2:$F$309)=TRIM(F9))*($I$2:$I$309>I9))+1)) -> חיים|26 | L9: =IF(F9="","",TRIM(F9)&"|"&(SUMPRODUCT((TRIM($F$2:$F$309)=TRIM(F9))*($B$2:$B$309<B9))+1)) -> חיים|35 | M9: =IF(F9="","",SUMPRODUCT((TRIM($F$2:$F$309)=TRIM(F9))*($I$2:$I$309>I9))+1) -> 26
A10: אופקים~128 | B10: 96 | C10: 94 | D10: אופקים | E10: דרום | F10: דודו | I10: 12889.3 | J10: 13546.6 | K10: =IF(F10="","",TRIM(F10)&"|"&(SUMPRODUCT((TRIM($F$2:$F$309)=TRIM(F10))*($I$2:$I$309>I10))+1)) -> דודו|32 | L10: =IF(F10="","",TRIM(F10)&"|"&(SUMPRODUCT((TRIM($F$2:$F$309)=TRIM(F10))*($B$2:$B$309<B10))+1)) -> דודו|34 | M10: =IF(F10="","",SUMPRODUCT((TRIM($F$2:$F$309)=TRIM(F10))*($I$2:$I$309>I10))+1) -> 32
A11: אור יהודה~126 | B11: 191 | C11: 229 | D11: אור יהודה | E11: מרכז | F11: סטאס | I11: 6807.5 | J11: 14974.2 | K11: =IF(F11="","",TRIM(F11)&"|"&(SUMPRODUCT((TRIM($F$2:$F$309)=TRIM(F11))*($I$2:$I$309>I11))+1)) -> סטאס|38 | L11: =IF(F11="","",TRIM(F11)&"|"&(SUMPRODUCT((TRIM($F$2:$F$309)=TRIM(F11))*($B$2:$B$309<B11))+1)) -> סטאס|39 | M11: =IF(F11="","",SUMPRODUCT((TRIM($F$2:$F$309)=TRIM(F11))*($I$2:$I$309>I11))+1) -> 38
A12: אורדע~50 | B12: 232 | C12: 178 | D12: רמת גן | E12: מרכז | F12: סטאס | I12: 5956.5 | J12: 12140.5 | K12: =IF(F12="","",TRIM(F12)&"|"&(SUMPRODUCT((TRIM($F$2:$F$309)=TRIM(F12))*($I$2:$I$309>I12))+1)) -> סטאס|45 | L12: =IF(F12="","",TRIM(F12)&"|"&(SUMPRODUCT((TRIM($F$2:$F$309)=TRIM(F12))*($B$2:$B$309<B12))+1)) -> סטאס|48 | M12: =IF(F12="","",SUMPRODUCT((TRIM($F$2:$F$309)=TRIM(F12))*($I$2:$I$309>I12))+1) -> 45
A13: אורון~6 | B13: 199 | C13: 166 | D13: פתח תקווה | E13: מרכז | F13: סטאס | I13: 6751.9 | J13: 11659.4 | K13: =IF(F13="","",TRIM(F13)&"|"&(SUMPRODUCT((TRIM($F$2:$F$309)=TRIM(F13))*($I$2:$I$309>I13))+1)) -> סטאס|40 | L13: =IF(F13="","",TRIM(F13)&"|"&(SUMPRODUCT((TRIM($F$2:$F$309)=TRIM(F13))*($B$2:$B$309<B13))+1)) -> סטאס|40 | M13: =IF(F13="","",SUMPRODUCT((TRIM($F$2:$F$309)=TRIM(F13))*($I$2:$I$309>I13))+1) -> 40
A14: אזור התעשיה חולון~185 | B14: 150 | C14: 210 | D14: חולון | E14: מרכז | F14: סטאס | I14: 10505.1 | J14: 20001.1 | K14: =IF(F14="","",TRIM(F14)&"|"&(SUMPRODUCT((TRIM($F$2:$F$309)=TRIM(F14))*($I$2:$I$309>I14))+1)) -> סטאס|20 | L14: =IF(F14="","",TRIM(F14)&"|"&(SUMPRODUCT((TRIM($F$2:$F$309)=TRIM(F14))*($B$2:$B$309<B14))+1)) -> סטאס|31 | M14: =IF(F14="","",SUMPRODUCT((TRIM($F$2:$F$309)=TRIM(F14))*($I$2:$I$309>I14))+1) -> 20
A15: איינשטיין חיפה~263 | B15: 233 | C15: 202 | D15: חיפה והקריות | E15: חיפה | F15: חדש | I15: 7027.7 | J15: 9894.1 | K15: =IF(F15="","",TRIM(F15)&"|"&(SUMPRODUCT((TRIM($F$2:$F$309)=TRIM(F15))*($I$2:$I$309>I15))+1)) -> חדש|32 | L15: =IF(F15="","",TRIM(F15)&"|"&(SUMPRODUCT((TRIM($F$2:$F$309)=TRIM(F15))*($B$2:$B$309<B15))+1)) -> חדש|57 | M15: =IF(F15="","",SUMPRODUCT((TRIM($F$2:$F$309)=TRIM(F15))*($I$2:$I$309>I15))+1) -> 32
A16: איירפורט סיטי~160 | B16: 275 | C16: 291 | D16: לוד | E16: מרכז | F16: סטאס | I16: 4561.3 | J16: 8864.9 | K16: =IF(F16="","",TRIM(F16)&"|"&(SUMPRODUCT((TRIM($F$2:$F$309)=TRIM(F16))*($I$2:$I$309>I16))+1)) -> סטאס|51 | L16: =IF(F16="","",TRIM(F16)&"|"&(SUMPRODUCT((TRIM($F$2:$F$309)=TRIM(F16))*($B$2:$B$309<B16))+1)) -> סטאס|59 | M16: =IF(F16="","",SUMPRODUCT((TRIM($F$2:$F$309)=TRIM(F16))*($I$2:$I$309>I16))+1) -> 51
A17: איכילוב~107 | B17: 12 | C17: 25 | D17: ת"א | E17: ת"א | F17: חיים | G17: 10 | I17: 23252.2 | J17: 52869.2 | K17: =IF(F17="","",TRIM(F17)&"|"&(SUMPRODUCT((TRIM($F$2:$F$309)=TRIM(F17))*($I$2:$I$309>I17))+1)) -> חיים|4 | L17: =IF(F17="","",TRIM(F17)&"|"&(SUMPRODUCT((TRIM($F$2:$F$309)=TRIM(F17))*($B$2:$B$309<B17))+1)) -> חיים|4 | M17: =IF(F17="","",SUMPRODUCT((TRIM($F$2:$F$309)=TRIM(F17))*($I$2:$I$309>I17))+1) -> 4
A18: אליהו קורן י-ם~240 | B18: 223 | C18: 231 | D18: ירושלים | E18: ירושלים | F18: דודו | I18: 10094.1 | J18: 17473.5 | K18: =IF(F18="","",TRIM(F18)&"|"&(SUMPRODUCT((TRIM($F$2:$F$309)=TRIM(F18))*($I$2:$I$309>I18))+1)) -> דודו|41 | L18: =IF(F18="","",TRIM(F18)&"|"&(SUMPRODUCT((TRIM($F$2:$F$309)=TRIM(F18))*($B$2:$B$309<B18))+1)) -> דודו|55 | M18: =IF(F18="","",SUMPRODUCT((TRIM($F$2:$F$309)=TRIM(F18))*($I$2:$I$309>I18))+1) -> 41
A19: אלנבי~114 | B19: 114 | C19: 96 | D19: ת"א | E19: ת"א | F19: חיים | I19: 10650.5 | J19: 23531.3 | K19: =IF(F19="","",TRIM(F19)&"|"&(SUMPRODUCT((TRIM($F$2:$F$309)=TRIM(F19))*($I$2:$I$309>I19))+1)) -> חיים|34 | L19: =IF(F19="","",TRIM(F19)&"|"&(SUMPRODUCT((TRIM($F$2:$F$309)=TRIM(F19))*($B$2:$B$309<B19))+1)) -> חיים|38 | M19: =IF(F19="","",SUMPRODUCT((TRIM($F$2:$F$309)=TRIM(F19))*($I$2:$I$309>I19))+1) -> 34
A20: אם-המושבות פ"ת~199 | B20: 44 | C20: 46 | D20: פתח תקוה | E20: מרכז | F20: סטאס | G20: 10 | I20: 13498 | J20: 30392 | K20: =IF(F20="","",TRIM(F20)&"|"&(SUMPRODUCT((TRIM($F$2:$F$309)=TRIM(F20))*($I$2:$I$309>I20))+1)) -> סטאס|12 | L20: =IF(F20="","",TRIM(F20)&"|"&(SUMPRODUCT((TRIM($F$2:$F$309)=TRIM(F20))*($B$2:$B$309<B20))+1)) -> סטאס|7 | M20: =IF(F20="","",SUMPRODUCT((TRIM($F$2:$F$309)=TRIM(F20))*($I$2:$I$309>I20))+1) -> 12
A21: אסף הרופא~264 | B21: 239 | C21: 293 | D21: רחובות | E21: מרכז | F21: דודו | I21: 4994.4 | J21: 10880.1 | K21: =IF(F21="","",TRIM(F21)&"|"&(SUMPRODUCT((TRIM($F$2:$F$309)=TRIM(F21))*($I$2:$I$309>I21))+1)) -> דודו|59 | L21: =IF(F21="","",TRIM(F21)&"|"&(SUMPRODUCT((TRIM($F$2:$F$309)=TRIM(F21))*($B$2:$B$309<B21))+1)) -> דודו|61 | M21: =IF(F21="","",SUMPRODUCT((TRIM($F$2:$F$309)=TRIM(F21))*($I$2:$I$309>I21))+1) -> 59
A22: אעבלין~332 | B22: 303 | C22: 304 | D22: אעבלין | E22: צפון | F22: חדש | I22: 1602.1 | J22: 3939.3 | K22: =IF(F22="","",TRIM(F22)&"|"&(SUMPRODUCT((TRIM($F$2:$F$309)=TRIM(F22))*($I$2:$I$309>I22))+1)) -> חדש|84 | L22: =IF(F22="","",TRIM(F22)&"|"&(SUMPRODUCT((TRIM($F$2:$F$309)=TRIM(F22))*($B$2:$B$309<B22))+1)) -> חדש|85 | M22: =IF(F22="","",SUMPRODUCT((TRIM($F$2:$F$309)=TRIM(F22))*($I$2:$I$309>I22))+1) -> 84
A23: אפקה קרית-ביאליק~341 | B23: 307 | C23: 298 | D23: חיפה והקריות | E23: חיפה | F23: חדש | I23: 1123.1 | J23: 4158.2 | K23: =IF(F23="","",TRIM(F23)&"|"&(SUMPRODUCT((TRIM($F$2:$F$309)=TRIM(F23))*($I$2:$I$309>I23))+1)) -> חדש|85 | L23: =IF(F23="","",TRIM(F23)&"|"&(SUMPRODUCT((TRIM($F$2:$F$309)=TRIM(F23))*($B$2:$B$309<B23))+1)) -> חדש|88 | M23: =IF(F23="","",SUMPRODUCT((TRIM($F$2:$F$309)=TRIM(F23))*($I$2:$I$309>I23))+1) -> 85
A24: ארלוזורוב~220 | B24: 194 | C24: 157 | D24: ת"א | E24: ת"א | F24: חיים | I24: 6255.2 | J24: 20297.6 | K24: =IF(F24="","",TRIM(F24)&"|"&(SUMPRODUCT((TRIM($F$2:$F$309)=TRIM(F24))*($I$2:$I$309>I24))+1)) -> חיים|67 | L24: =IF(F24="","",TRIM(F24)&"|"&(SUMPRODUCT((TRIM($F$2:$F$309)=TRIM(F24))*($B$2:$B$309<B24))+1)) -> חיים|60 | M24: =IF(F24="","",SUMPRODUCT((TRIM($F$2:$F$309)=TRIM(F24))*($I$2:$I$309>I24))+1) -> 67
A25: ארמון חיפה~82 | B25: 129 | C25: 106 | D25: חיפה והקריות | E25: חיפה | F25: חדש | G25: 16 | I25: 59.1 | J25: 20460.6 | K25: =IF(F25="","",TRIM(F25)&"|"&(SUMPRODUCT((TRIM($F$2:$F$309)=TRIM(F25))*($I$2:$I$309>I25))+1)) -> חדש|87 | L25: =IF(F25="","",TRIM(F25)&"|"&(SUMPRODUCT((TRIM($F$2:$F$309)=TRIM(F25))*($B$2:$B$309<B25))+1)) -> חדש|22 | M25: =IF(F25="","",SUMPRODUCT((TRIM($F$2:$F$309)=TRIM(F25))*($I$2:$I$309>I25))+1) -> 87
A26: אשדוד ט"ז~345 | B26: 301 | C26: 303 | D26: אשדוד | E26: דרום | F26: דודו | I26: 2594.7 | J26: 0 | K26: =IF(F26="","",TRIM(F26)&"|"&(SUMPRODUCT((TRIM($F$2:$F$309)=TRIM(F26))*($I$2:$I$309>I26))+1)) -> דודו|67 | L26: =IF(F26="","",TRIM(F26)&"|"&(SUMPRODUCT((TRIM($F$2:$F$309)=TRIM(F26))*($B$2:$B$309<B26))+1)) -> דודו|68 | M26: =IF(F26="","",SUMPRODUCT((TRIM($F$2:$F$309)=TRIM(F26))*($I$2:$I$309>I26))+1) -> 67
A27: אשדוד סטאר-סנטר~117 | B27: 5 | C27: 31 | D27: אשדוד | E27: דרום | F27: דודו | G27: 9 | I27: 34181.8 | J27: 63211.5 | K27: =IF(F27="","",TRIM(F27)&"|"&(SUMPRODUCT((TRIM($F$2:$F$309)=TRIM(F27))*($I$2:$I$309>I27))+1)) -> דודו|3 | L27: =IF(F27="","",TRIM(F27)&"|"&(SUMPRODUCT((TRIM($F$2:$F$309)=TRIM(F27))*($B$2:$B$309<B27))+1)) -> דודו|3 | M27: =IF(F27="","",SUMPRODUCT((TRIM($F$2:$F$309)=TRIM(F27))*($I$2:$I$309>I27))+1) -> 3
A28: אשדוד סיטי~40 | B28: 26 | C28: 18 | D28: אשדוד | E28: דרום | F28: דודו | G28: 6 | I28: 18434.6 | J28: 36774.5 | K28: =IF(F28="","",TRIM(F28)&"|"&(SUMPRODUCT((TRIM($F$2:$F$309)=TRIM(F28))*($I$2:$I$309>I28))+1)) -> דודו|20 | L28: =IF(F28="","",TRIM(F28)&"|"&(SUMPRODUCT((TRIM($F$2:$F$309)=TRIM(F28))*($B$2:$B$309<B28))+1)) -> דודו|12 | M28: =IF(F28="","",SUMPRODUCT((TRIM($F$2:$F$309)=TRIM(F28))*($I$2:$I$309>I28))+1) -> 20
A29: אשקלון גירון~28 | B29: 17 | C29: 44 | D29: אשקלון | E29: דרום | F29: דודו | G29: 14 | I29: 29916.7 | J29: 56802.8 | K29: =IF(F29="","",TRIM(F29)&"|"&(SUMPRODUCT((TRIM($F$2:$F$309)=TRIM(F29))*($I$2:$I$309>I29))+1)) -> דודו|7 | L29: =IF(F29="","",TRIM(F29)&"|"&(SUMPRODUCT((TRIM($F$2:$F$309)=TRIM(F29))*($B$2:$B$309<B29))+1)) -> דודו|9 | M29: =IF(F29="","",SUMPRODUCT((TRIM($F$2:$F$309)=TRIM(F29))*($I$2:$I$309>I29))+1) -> 7
A30: אתר סחר~667 | B30: 7 | K30: =IF(F30="","",TRIM(F30)&"|"&(SUMPRODUCT((TRIM($F$2:$F$309)=TRIM(F30))*($I$2:$I$309>I30))+1)) | L30: =IF(F30="","",TRIM(F30)&"|"&(SUMPRODUCT((TRIM($F$2:$F$309)=TRIM(F30))*($B$2:$B$309<B30))+1)) | M30: =IF(F30="","",SUMPRODUCT((TRIM($F$2:$F$309)=TRIM(F30))*($I$2:$I$309>I30))+1)
A31: באקה סנטר~290 | B31: 267 | C31: 212 | D31: באקה | E31: צפון | F31: חדש | I31: 2644 | J31: 9221.4 | K31: =IF(F31="","",TRIM(F31)&"|"&(SUMPRODUCT((TRIM($F$2:$F$309)=TRIM(F31))*($I$2:$I$309>I31))+1)) -> חדש|76 | L31: =IF(F31="","",TRIM(F31)&"|"&(SUMPRODUCT((TRIM($F$2:$F$309)=TRIM(F31))*($B$2:$B$309<B31))+1)) -> חדש|68 | M31: =IF(F31="","",SUMPRODUCT((TRIM($F$2:$F$309)=TRIM(F31))*($I$2:$I$309>I31))+1) -> 76
A32: בורוכוב גבעתיים~279 | B32: 218 | C32: 155 | D32: גבעתיים | E32: מרכז | F32: סטאס | I32: 5224.1 | J32: 12498.9 | K32: =IF(F32="","",TRIM(F32)&"|"&(SUMPRODUCT((TRIM($F$2:$F$309)=TRIM(F32))*($I$2:$I$309>I32))+1)) -> סטאס|48 | L32: =IF(F32="","",TRIM(F32)&"|"&(SUMPRODUCT((TRIM($F$2:$F$309)=TRIM(F32))*($B$2:$B$309<B32))+1)) -> סטאס|45 | M32: =IF(F32="","",SUMPRODUCT((TRIM($F$2:$F$309)=TRIM(F32))*($I$2:$I$309>I32))+1) -> 48
A33: ביג-יקנעם~151 | B33: 90 | C33: 103 | D33: יוקנעם | E33: צפון | F33: חדש | G33: 15 | I33: 12858.5 | J33: 25510.2 | K33: =IF(F33="","",TRIM(F33)&"|"&(SUMPRODUCT((TRIM($F$2:$F$309)=TRIM(F33))*($I$2:$I$309>I33))+1)) -> חדש|8 | L33: =IF(F33="","",TRIM(F33)&"|"&(SUMPRODUCT((TRIM($F$2:$F$309)=TRIM(F33))*($B$2:$B$309<B33))+1)) -> חדש|12 | M33: =IF(F33="","",SUMPRODUCT((TRIM($F$2:$F$309)=TRIM(F33))*($I$2:$I$309>I33))+1) -> 8
A34: ביג-נצרת~159 | B34: 221 | C34: 172 | D34: נצרת | E34: צפון | F34: חדש | I34: 4315.3 | J34: 11638.9 | K34: =IF(F34="","",TRIM(F34)&"|"&(SUMPRODUCT((TRIM($F$2:$F$309)=TRIM(F34))*($I$2:$I$309>I34))+1)) -> חדש|57 | L34: =IF(F34="","",TRIM(F34)&"|"&(SUMPRODUCT((TRIM($F$2:$F$309)=TRIM(F34))*($B$2:$B$309<B34))+1)) -> חדש|51 | M34: =IF(F34="","",SUMPRODUCT((TRIM($F$2:$F$309)=TRIM(F34))*($I$2:$I$309>I34))+1) -> 57
A35: ביג-עפולה~201 | B35: 227 | C35: 233 | D35: עפולה | E35: צפון | F35: חדש | I35: 4806.5 | J35: 12817.1 | K35: =IF(F35="","",TRIM(F35)&"|"&(SUMPRODUCT((TRIM($F$2:$F$309)=TRIM(F35))*($I$2:$I$309>I35))+1)) -> חדש|50 | L35: =IF(F35="","",TRIM(F35)&"|"&(SUMPRODUCT((TRIM($F$2:$F$309)=TRIM(F35))*($B$2:$B$309<B35))+1)) -> חדש|54 | M35: =IF(F35="","",SUMPRODUCT((TRIM($F$2:$F$309)=TRIM(F35))*($I$2:$I$309>I35))+1) -> 50
A36: ביג-פאשן אשדוד~230 | B36: 53 | C36: 40 | D36: אשדוד | E36: דרום | F36: דודו | G36: 13 | I36: 17795.5 | J36: 33328.1 | K36: =IF(F36="","",TRIM(F36)&"|"&(SUMPRODUCT((TRIM($F$2:$F$309)=TRIM(F36))*($I$2:$I$309>I36))+1)) -> דודו|21 | L36: =IF(F36="","",TRIM(F36)&"|"&(SUMPRODUCT((TRIM($F$2:$F$309)=TRIM(F36))*($B$2:$B$309<B36))+1)) -> דודו|21 | M36: =IF(F36="","",SUMPRODUCT((TRIM($F$2:$F$309)=TRIM(F36))*($I$2:$I$309>I36))+1) -> 21
A37: ביג-פוריה~158 | B37: 174 | C37: 138 | D37: טבריה | E37: צפון | F37: חדש | I37: 5705.4 | J37: 11722.6 | K37: =IF(F37="","",TRIM(F37)&"|"&(SUMPRODUCT((TRIM($F$2:$F$309)=TRIM(F37))*($I$2:$I$309>I37))+1)) -> חדש|45 | L37: =IF(F37="","",TRIM(F37)&"|"&(SUMPRODUCT((TRIM($F$2:$F$309)=TRIM(F37))*($B$2:$B$309<B37))+1)) -> חדש|35 | M37: =IF(F37="","",SUMPRODUCT((TRIM($F$2:$F$309)=TRIM(F37))*($I$2:$I$309>I37))+1) -> 45
A38: ביג אור-יהודה~193 | B38: 284 | C38: 265 | D38: אור יהודה | E38: מרכז | F38: סטאס | I38: 2316 | J38: 9819.2 | K38: =IF(F38="","",TRIM(F38)&"|"&(SUMPRODUCT((TRIM($F$2:$F$309)=TRIM(F38))*($I$2:$I$309>I38))+1)) -> סטאס|61 | L38: =IF(F38="","",TRIM(F38)&"|"&(SUMPRODUCT((TRIM($F$2:$F$309)=TRIM(F38))*($B$2:$B$309<B38))+1)) -> סטאס|60 | M38: =IF(F38="","",SUMPRODUCT((TRIM($F$2:$F$309)=TRIM(F38))*($I$2:$I$309>I38))+1) -> 61
A39: ביג אור-עקיבא~236 | B39: 214 | C39: 208 | D39: אור עקיבא | E39: צפון | F39: חדש | I39: 7577.7 | J39: 12491.1 | K39: =IF(F39="","",TRIM(F39)&"|"&(SUMPRODUCT((TRIM($F$2:$F$309)=TRIM(F39))*($I$2:$I$309>I39))+1)) -> חדש|29 | L39: =IF(F39="","",TRIM(F39)&"|"&(SUMPRODUCT((TRIM($F$2:$F$309)=TRIM(F39))*($B$2:$B$309<B39))+1)) -> חדש|49 | M39: =IF(F39="","",SUMPRODUCT((TRIM($F$2:$F$309)=TRIM(F39))*($I$2:$I$309>I39))+1) -> 29
A40: ביג אילת~112 | B40: 36 | C40: 6 | D40: אילת | E40: אילת | F40: דודו | G40: 1 | I40: 17265.6 | J40: 29529.4 | K40: =IF(F40="","",TRIM(F40)&"|"&(SUMPRODUCT((TRIM($F$2:$F$309)=TRIM(F40))*($I$2:$I$309>I40))+1)) -> דודו|23 | L40: =IF(F40="","",TRIM(F40)&"|"&(SUMPRODUCT((TRIM($F$2:$F$309)=TRIM(F40))*($B$2:$B$309<B40))+1)) -> דודו|16 | M40: =IF(F40="","",SUMPRODUCT((TRIM($F$2:$F$309)=TRIM(F40))*($I$2:$I$309>I40))+1) -> 23
...
