Workbook

Sheet מצטבר - בחירה
A1: ביצוע מצטבר לפי חודשים (ללא תקציב/מטרה - עדיין לא הוגדר תקציב 2027)
B2: בחר חודש (מצטבר מינואר עד החודש שנבחר, כולל): | D2: דצמבר | E2: (מספר חודש נבחר:) | F2: =MATCH($D$2,נתונים_שטוחים!$BB$2:$BB$13,0) -> 12 | G2: תאריך חישוב: | H2: 02/10/26
A4: # | B4: לקוח | C4: קבוצה | D4: 2024 מצטבר | E4: 2025 מצטבר | F4: 2026 מצטבר | G4: 2027 מצטבר | H4: % מול 2026 | I4: ₪ מול 2026
A5: =נתונים_שטוחים!A5 -> 111 | B5: =נתונים_שטוחים!B5 -> סופר פארם לייף | C5: =נתונים_שטוחים!C5 -> ISR | D5: =SUMIFS(נתונים_שטוחים!D5:O5,נתונים_שטוחים!$D$3:$O$3,"<="&$F$2) -> 2052731.8 | E5: =SUMIFS(נתונים_שטוחים!P5:AA5,נתונים_שטוחים!$P$3:$AA$3,"<="&$F$2) -> 1708656.9 | F5: =SUMIFS(נתונים_שטוחים!AB5:AM5,נתונים_שטוחים!$AB$3:$AM$3,"<="&$F$2) -> 1328770.6 | G5: =SUMIFS(נתונים_שטוחים!AN5:AY5,נתונים_שטוחים!$AN$3:$AY$3,"<="&$F$2) -> 0 | H5: =IFERROR(G5/F5-1,"-") -> -1 | I5: =G5-F5 -> -1328770.6
A6: =נתונים_שטוחים!A6 -> 1 | B6: =נתונים_שטוחים!B6 -> סופרפארם | C6: =נתונים_שטוחים!C6 -> ISR | D6: =SUMIFS(נתונים_שטוחים!D6:O6,נתונים_שטוחים!$D$3:$O$3,"<="&$F$2) -> 5482291.2 | E6: =SUMIFS(נתונים_שטוחים!P6:AA6,נתונים_שטוחים!$P$3:$AA$3,"<="&$F$2) -> 6071777.6 | F6: =SUMIFS(נתונים_שטוחים!AB6:AM6,נתונים_שטוחים!$AB$3:$AM$3,"<="&$F$2) -> 4231396.3 | G6: =SUMIFS(נתונים_שטוחים!AN6:AY6,נתונים_שטוחים!$AN$3:$AY$3,"<="&$F$2) -> 0 | H6: =IFERROR(G6/F6-1,"-") -> -1 | I6: =G6-F6 -> -4231396.3
A7: =נתונים_שטוחים!A7 -> 2 | B7: =נתונים_שטוחים!B7 -> BE | C7: =נתונים_שטוחים!C7 -> ISR | D7: =SUMIFS(נתונים_שטוחים!D7:O7,נתונים_שטוחים!$D$3:$O$3,"<="&$F$2) -> 1089803.8 | E7: =SUMIFS(נתונים_שטוחים!P7:AA7,נתונים_שטוחים!$P$3:$AA$3,"<="&$F$2) -> 828689.86 | F7: =SUMIFS(נתונים_שטוחים!AB7:AM7,נתונים_שטוחים!$AB$3:$AM$3,"<="&$F$2) -> 651059.05 | G7: =SUMIFS(נתונים_שטוחים!AN7:AY7,נתונים_שטוחים!$AN$3:$AY$3,"<="&$F$2) -> 0 | H7: =IFERROR(G7/F7-1,"-") -> -1 | I7: =G7-F7 -> -651059.05
A8: =נתונים_שטוחים!A8 -> 3 | B8: =נתונים_שטוחים!B8 -> בתי מרקחת | C8: =נתונים_שטוחים!C8 -> ISR | D8: =SUMIFS(נתונים_שטוחים!D8:O8,נתונים_שטוחים!$D$3:$O$3,"<="&$F$2) -> 1835959.5 | E8: =SUMIFS(נתונים_שטוחים!P8:AA8,נתונים_שטוחים!$P$3:$AA$3,"<="&$F$2) -> 1941001.6 | F8: =SUMIFS(נתונים_שטוחים!AB8:AM8,נתונים_שטוחים!$AB$3:$AM$3,"<="&$F$2) -> 1409547.8 | G8: =SUMIFS(נתונים_שטוחים!AN8:AY8,נתונים_שטוחים!$AN$3:$AY$3,"<="&$F$2) -> 0 | H8: =IFERROR(G8/F8-1,"-") -> -1 | I8: =G8-F8 -> -1409547.8
A9: =נתונים_שטוחים!A9 -> 112 | B9: =נתונים_שטוחים!B9 -> כללית | C9: =נתונים_שטוחים!C9 -> ISR | D9: =SUMIFS(נתונים_שטוחים!D9:O9,נתונים_שטוחים!$D$3:$O$3,"<="&$F$2) -> 4118466.1 | E9: =SUMIFS(נתונים_שטוחים!P9:AA9,נתונים_שטוחים!$P$3:$AA$3,"<="&$F$2) -> 3809616.4 | F9: =SUMIFS(נתונים_שטוחים!AB9:AM9,נתונים_שטוחים!$AB$3:$AM$3,"<="&$F$2) -> 2727663.2 | G9: =SUMIFS(נתונים_שטוחים!AN9:AY9,נתונים_שטוחים!$AN$3:$AY$3,"<="&$F$2) -> 0 | H9: =IFERROR(G9/F9-1,"-") -> -1 | I9: =G9-F9 -> -2727663.2
A10: =נתונים_שטוחים!A10 -> 113 | B10: =נתונים_שטוחים!B10 -> מאוחדת | C10: =נתונים_שטוחים!C10 -> ISR | D10: =SUMIFS(נתונים_שטוחים!D10:O10,נתונים_שטוחים!$D$3:$O$3,"<="&$F$2) -> 797978.25 | E10: =SUMIFS(נתונים_שטוחים!P10:AA10,נתונים_שטוחים!$P$3:$AA$3,"<="&$F$2) -> 892626.19 | F10: =SUMIFS(נתונים_שטוחים!AB10:AM10,נתונים_שטוחים!$AB$3:$AM$3,"<="&$F$2) -> 520254.74 | G10: =SUMIFS(נתונים_שטוחים!AN10:AY10,נתונים_שטוחים!$AN$3:$AY$3,"<="&$F$2) -> 0 | H10: =IFERROR(G10/F10-1,"-") -> -1 | I10: =G10-F10 -> -520254.74
A11: =נתונים_שטוחים!A11 -> 4 | B11: =נתונים_שטוחים!B11 -> מכבי | C11: =נתונים_שטוחים!C11 -> ISR | D11: =SUMIFS(נתונים_שטוחים!D11:O11,נתונים_שטוחים!$D$3:$O$3,"<="&$F$2) -> 0 | E11: =SUMIFS(נתונים_שטוחים!P11:AA11,נתונים_שטוחים!$P$3:$AA$3,"<="&$F$2) -> 0 | F11: =SUMIFS(נתונים_שטוחים!AB11:AM11,נתונים_שטוחים!$AB$3:$AM$3,"<="&$F$2) -> 0 | G11: =SUMIFS(נתונים_שטוחים!AN11:AY11,נתונים_שטוחים!$AN$3:$AY$3,"<="&$F$2) -> 0 | H11: =IFERROR(G11/F11-1,"-") -> - | I11: =G11-F11 -> 0
A12: =נתונים_שטוחים!A12 -> 102 | B12: =נתונים_שטוחים!B12 -> מכוני אורטופדיה | C12: =נתונים_שטוחים!C12 -> ISR | D12: =SUMIFS(נתונים_שטוחים!D12:O12,נתונים_שטוחים!$D$3:$O$3,"<="&$F$2) -> 901019.25 | E12: =SUMIFS(נתונים_שטוחים!P12:AA12,נתונים_שטוחים!$P$3:$AA$3,"<="&$F$2) -> 854818.94 | F12: =SUMIFS(נתונים_שטוחים!AB12:AM12,נתונים_שטוחים!$AB$3:$AM$3,"<="&$F$2) -> 678114.16 | G12: =SUMIFS(נתונים_שטוחים!AN12:AY12,נתונים_שטוחים!$AN$3:$AY$3,"<="&$F$2) -> 0 | H12: =IFERROR(G12/F12-1,"-") -> -1 | I12: =G12-F12 -> -678114.16
A13: =נתונים_שטוחים!A13 -> 101 | B13: =נתונים_שטוחים!B13 -> לקוחות מפעל | C13: =נתונים_שטוחים!C13 -> ISR | D13: =SUMIFS(נתונים_שטוחים!D13:O13,נתונים_שטוחים!$D$3:$O$3,"<="&$F$2) -> 187203.67 | E13: =SUMIFS(נתונים_שטוחים!P13:AA13,נתונים_שטוחים!$P$3:$AA$3,"<="&$F$2) -> 185250.51 | F13: =SUMIFS(נתונים_שטוחים!AB13:AM13,נתונים_שטוחים!$AB$3:$AM$3,"<="&$F$2) -> 79418.59 | G13: =SUMIFS(נתונים_שטוחים!AN13:AY13,נתונים_שטוחים!$AN$3:$AY$3,"<="&$F$2) -> 0 | H13: =IFERROR(G13/F13-1,"-") -> -1 | I13: =G13-F13 -> -79418.59
A14: =נתונים_שטוחים!A14 -> 109 | B14: =נתונים_שטוחים!B14 -> חנויות פרטיות | C14: =נתונים_שטוחים!C14 -> ISR | D14: =SUMIFS(נתונים_שטוחים!D14:O14,נתונים_שטוחים!$D$3:$O$3,"<="&$F$2) -> 92204.35 | E14: =SUMIFS(נתונים_שטוחים!P14:AA14,נתונים_שטוחים!$P$3:$AA$3,"<="&$F$2) -> 57359.72 | F14: =SUMIFS(נתונים_שטוחים!AB14:AM14,נתונים_שטוחים!$AB$3:$AM$3,"<="&$F$2) -> 45013.96 | G14: =SUMIFS(נתונים_שטוחים!AN14:AY14,נתונים_שטוחים!$AN$3:$AY$3,"<="&$F$2) -> 0 | H14: =IFERROR(G14/F14-1,"-") -> -1 | I14: =G14-F14 -> -45013.96
A15: =נתונים_שטוחים!A15 -> 105 | B15: =נתונים_שטוחים!B15 -> מכוני פדיקור | C15: =נתונים_שטוחים!C15 -> ISR | D15: =SUMIFS(נתונים_שטוחים!D15:O15,נתונים_שטוחים!$D$3:$O$3,"<="&$F$2) -> 3230.5 | E15: =SUMIFS(נתונים_שטוחים!P15:AA15,נתונים_שטוחים!$P$3:$AA$3,"<="&$F$2) -> 4145.68 | F15: =SUMIFS(נתונים_שטוחים!AB15:AM15,נתונים_שטוחים!$AB$3:$AM$3,"<="&$F$2) -> 4305.02 | G15: =SUMIFS(נתונים_שטוחים!AN15:AY15,נתונים_שטוחים!$AN$3:$AY$3,"<="&$F$2) -> 0 | H15: =IFERROR(G15/F15-1,"-") -> -1 | I15: =G15-F15 -> -4305.02
A16: =נתונים_שטוחים!A16 -> 104 | B16: =נתונים_שטוחים!B16 -> חנויות נעליים | C16: =נתונים_שטוחים!C16 -> ISR | D16: =SUMIFS(נתונים_שטוחים!D16:O16,נתונים_שטוחים!$D$3:$O$3,"<="&$F$2) -> 1583.18 | E16: =SUMIFS(נתונים_שטוחים!P16:AA16,נתונים_שטוחים!$P$3:$AA$3,"<="&$F$2) -> 514.2 | F16: =SUMIFS(נתונים_שטוחים!AB16:AM16,נתונים_שטוחים!$AB$3:$AM$3,"<="&$F$2) -> 1896.82 | G16: =SUMIFS(נתונים_שטוחים!AN16:AY16,נתונים_שטוחים!$AN$3:$AY$3,"<="&$F$2) -> 0 | H16: =IFERROR(G16/F16-1,"-") -> -1 | I16: =G16-F16 -> -1896.82
... A18: =נתונים_שטוחים!A18 -> 103 | B18: =נתונים_שטוחים!B18 -> מכוני פיזיותרפיה | C18: =נתונים_שטוחים!C18 -> ISR | D18: =SUMIFS(נתונים_שטוחים!D18:O18,נתונים_שטוחים!$D$3:$O$3,"<="&$F$2) -> 72915.81 | E18: =SUMIFS(נתונים_שטוחים!P18:AA18,נתונים_שטוחים!$P$3:$AA$3,"<="&$F$2) -> 94701.6 | F18: =SUMIFS(נתונים_שטוחים!AB18:AM18,נתונים_שטוחים!$AB$3:$AM$3,"<="&$F$2) -> 118677.26 | G18: =SUMIFS(נתונים_שטוחים!AN18:AY18,נתונים_שטוחים!$AN$3:$AY$3,"<="&$F$2) -> 0 | H18: =IFERROR(G18/F18-1,"-") -> -1 | I18: =G18-F18 -> -118677.26
B19: ='1'!B17 -> סה"כ ישראל ללא אונליין | D19: =SUM(D5:D18) -> 16644965 | E19: =SUM(E5:E18) -> 16462691 | F19: =SUM(F5:F18) -> 11811071 | G19: =SUM(G5:G18) -> 0 | H19: =IFERROR(G19/F19-1,"-") -> -1 | I19: =G19-F19 -> -11811071
A20: =נתונים_שטוחים!A19 -> 114 | B20: =נתונים_שטוחים!B19 -> לקוחות אינטרנט | C20: =נתונים_שטוחים!C19 -> ISR | D20: =SUMIFS(נתונים_שטוחים!D19:O19,נתונים_שטוחים!$D$3:$O$3,"<="&$F$2) -> 683558.5 | E20: =SUMIFS(נתונים_שטוחים!P19:AA19,נתונים_שטוחים!$P$3:$AA$3,"<="&$F$2) -> 1656258.3 | F20: =SUMIFS(נתונים_שטוחים!AB19:AM19,נתונים_שטוחים!$AB$3:$AM$3,"<="&$F$2) -> 3368003.3 | G20: =SUMIFS(נתונים_שטוחים!AN19:AY19,נתונים_שטוחים!$AN$3:$AY$3,"<="&$F$2) -> 0 | H20: =IFERROR(G20/F20-1,"-") -> -1 | I20: =G20-F20 -> -3368003.3
A21: =נתונים_שטוחים!A20 -> 115 | B21: =נתונים_שטוחים!B20 -> סופר פארם מרקט פלייס | C21: =נתונים_שטוחים!C20 -> ISR | D21: =SUMIFS(נתונים_שטוחים!D20:O20,נתונים_שטוחים!$D$3:$O$3,"<="&$F$2) -> 35758.89 | E21: =SUMIFS(נתונים_שטוחים!P20:AA20,נתונים_שטוחים!$P$3:$AA$3,"<="&$F$2) -> 27325.74 | F21: =SUMIFS(נתונים_שטוחים!AB20:AM20,נתונים_שטוחים!$AB$3:$AM$3,"<="&$F$2) -> 13580.48 | G21: =SUMIFS(נתונים_שטוחים!AN20:AY20,נתונים_שטוחים!$AN$3:$AY$3,"<="&$F$2) -> 0 | H21: =IFERROR(G21/F21-1,"-") -> -1 | I21: =G21-F21 -> -13580.48
B22: ='1'!B20 -> סה"כ ישראל | D22: =D19+D20+D21 -> 17364282 | E22: =E19+E20+E21 -> 18146275 | F22: =F19+F20+F21 -> 15192655 | G22: =G19+G20+G21 -> 0 | H22: =IFERROR(G22/F22-1,"-") -> -1 | I22: =G22-F22 -> -15192655
A23: =נתונים_שטוחים!A21 -> 301 | B23: =נתונים_שטוחים!B21 -> AMAZON | C23: =נתונים_שטוחים!C21 -> USA | D23: =SUMIFS(נתונים_שטוחים!D21:O21,נתונים_שטוחים!$D$3:$O$3,"<="&$F$2) -> 3501494.5 | E23: =SUMIFS(נתונים_שטוחים!P21:AA21,נתונים_שטוחים!$P$3:$AA$3,"<="&$F$2) -> 2705391.2 | F23: =SUMIFS(נתונים_שטוחים!AB21:AM21,נתונים_שטוחים!$AB$3:$AM$3,"<="&$F$2) -> 1879662.7 | G23: =SUMIFS(נתונים_שטוחים!AN21:AY21,נתונים_שטוחים!$AN$3:$AY$3,"<="&$F$2) -> 0 | H23: =IFERROR(G23/F23-1,"-") -> -1 | I23: =G23-F23 -> -1879662.7
A24: =נתונים_שטוחים!A22 -> 202 | B24: =נתונים_שטוחים!B22 -> SUPER PHARM POLAND | C24: =נתונים_שטוחים!C22 -> POLAND | D24: =SUMIFS(נתונים_שטוחים!D22:O22,נתונים_שטוחים!$D$3:$O$3,"<="&$F$2) -> 879383.45 | E24: =SUMIFS(נתונים_שטוחים!P22:AA22,נתונים_שטוחים!$P$3:$AA$3,"<="&$F$2) -> 902537.64 | F24: =SUMIFS(נתונים_שטוחים!AB22:AM22,נתונים_שטוחים!$AB$3:$AM$3,"<="&$F$2) -> 474182.59 | G24: =SUMIFS(נתונים_שטוחים!AN22:AY22,נתונים_שטוחים!$AN$3:$AY$3,"<="&$F$2) -> 0 | H24: =IFERROR(G24/F24-1,"-") -> -1 | I24: =G24-F24 -> -474182.59
A25: =נתונים_שטוחים!A23 -> 203 | B25: =נתונים_שטוחים!B23 -> ORTHO- PARTNER AG. | C25: =נתונים_שטוחים!C23 -> SWITZERLAND | D25: =SUMIFS(נתונים_שטוחים!D23:O23,נתונים_שטוחים!$D$3:$O$3,"<="&$F$2) -> 633752.75 | E25: =SUMIFS(נתונים_שטוחים!P23:AA23,נתונים_שטוחים!$P$3:$AA$3,"<="&$F$2) -> 405920.85 | F25: =SUMIFS(נתונים_שטוחים!AB23:AM23,נתונים_שטוחים!$AB$3:$AM$3,"<="&$F$2) -> 344263.09 | G25: =SUMIFS(נתונים_שטוחים!AN23:AY23,נתונים_שטוחים!$AN$3:$AY$3,"<="&$F$2) -> 0 | H25: =IFERROR(G25/F25-1,"-") -> -1 | I25: =G25-F25 -> -344263.09
A26: =נתונים_שטוחים!A24 -> 204 | B26: =נתונים_שטוחים!B24 -> SANAFLEX ANATOMIC | C26: =נתונים_שטוחים!C24 -> GREECE | D26: =SUMIFS(נתונים_שטוחים!D24:O24,נתונים_שטוחים!$D$3:$O$3,"<="&$F$2) -> 489809 | E26: =SUMIFS(נתונים_שטוחים!P24:AA24,נתונים_שטוחים!$P$3:$AA$3,"<="&$F$2) -> 414072.64 | F26: =SUMIFS(נתונים_שטוחים!AB24:AM24,נתונים_שטוחים!$AB$3:$AM$3,"<="&$F$2) -> 358276.36 | G26: =SUMIFS(נתונים_שטוחים!AN24:AY24,נתונים_שטוחים!$AN$3:$AY$3,"<="&$F$2) -> 0 | H26: =IFERROR(G26/F26-1,"-") -> -1 | I26: =G26-F26 -> -358276.36
A27: =נתונים_שטוחים!A25 -> 205 | B27: =נתונים_שטוחים!B25 -> HEALTH CARE PROD. GMBH | C27: =נתונים_שטוחים!C25 -> GERMANY | D27: =SUMIFS(נתונים_שטוחים!D25:O25,נתונים_שטוחים!$D$3:$O$3,"<="&$F$2) -> 128758.9 | E27: =SUMIFS(נתונים_שטוחים!P25:AA25,נתונים_שטוחים!$P$3:$AA$3,"<="&$F$2) -> 122339 | F27: =SUMIFS(נתונים_שטוחים!AB25:AM25,נתונים_שטוחים!$AB$3:$AM$3,"<="&$F$2) -> 111290.53 | G27: =SUMIFS(נתונים_שטוחים!AN25:AY25,נתונים_שטוחים!$AN$3:$AY$3,"<="&$F$2) -> 0 | H27: =IFERROR(G27/F27-1,"-") -> -1 | I27: =G27-F27 -> -111290.53
A28: =נתונים_שטוחים!A26 -> 206 | B28: =נתונים_שטוחים!B26 -> ORTHOMED LTD | C28: =נתונים_שטוחים!C26 -> BULGARIA | D28: =SUMIFS(נתונים_שטוחים!D26:O26,נתונים_שטוחים!$D$3:$O$3,"<="&$F$2) -> 160712.5 | E28: =SUMIFS(נתונים_שטוחים!P26:AA26,נתונים_שטוחים!$P$3:$AA$3,"<="&$F$2) -> 52899.82 | F28: =SUMIFS(נתונים_שטוחים!AB26:AM26,נתונים_שטוחים!$AB$3:$AM$3,"<="&$F$2) -> 0 | G28: =SUMIFS(נתונים_שטוחים!AN26:AY26,נתונים_שטוחים!$AN$3:$AY$3,"<="&$F$2) -> 0 | H28: =IFERROR(G28/F28-1,"-") -> - | I28: =G28-F28 -> 0
A29: =נתונים_שטוחים!A27 -> 207 | B29: =נתונים_שטוחים!B27 -> SALUS | C29: =נתונים_שטוחים!C27 -> HUNGARY | D29: =SUMIFS(נתונים_שטוחים!D27:O27,נתונים_שטוחים!$D$3:$O$3,"<="&$F$2) -> 471280.16 | E29: =SUMIFS(נתונים_שטוחים!P27:AA27,נתונים_שטוחים!$P$3:$AA$3,"<="&$F$2) -> 319558.55 | F29: =SUMIFS(נתונים_שטוחים!AB27:AM27,נתונים_שטוחים!$AB$3:$AM$3,"<="&$F$2) -> 365555.25 | G29: =SUMIFS(נתונים_שטוחים!AN27:AY27,נתונים_שטוחים!$AN$3:$AY$3,"<="&$F$2) -> 0 | H29: =IFERROR(G29/F29-1,"-") -> -1 | I29: =G29-F29 -> -365555.25
A30: =נתונים_שטוחים!A28 -> 216 | B30: =נתונים_שטוחים!B28 -> MAX KONNARIS LTD | C30: =נתונים_שטוחים!C28 -> CYPRUS | D30: =SUMIFS(נתונים_שטוחים!D28:O28,נתונים_שטוחים!$D$3:$O$3,"<="&$F$2) -> 162967.91 | E30: =SUMIFS(נתונים_שטוחים!P28:AA28,נתונים_שטוחים!$P$3:$AA$3,"<="&$F$2) -> 86855.65 | F30: =SUMIFS(נתונים_שטוחים!AB28:AM28,נתונים_שטוחים!$AB$3:$AM$3,"<="&$F$2) -> 60694.01 | G30: =SUMIFS(נתונים_שטוחים!AN28:AY28,נתונים_שטוחים!$AN$3:$AY$3,"<="&$F$2) -> 0 | H30: =IFERROR(G30/F30-1,"-") -> -1 | I30: =G30-F30 -> -60694.01
A31: =נתונים_שטוחים!A29 -> 208 | B31: =נתונים_שטוחים!B29 -> MEDIPAL COMPANY | C31: =נתונים_שטוחים!C29 -> NABLUS | D31: =SUMIFS(נתונים_שטוחים!D29:O29,נתונים_שטוחים!$D$3:$O$3,"<="&$F$2) -> 370614.64 | E31: =SUMIFS(נתונים_שטוחים!P29:AA29,נתונים_שטוחים!$P$3:$AA$3,"<="&$F$2) -> 256772.1 | F31: =SUMIFS(נתונים_שטוחים!AB29:AM29,נתונים_שטוחים!$AB$3:$AM$3,"<="&$F$2) -> 0 | G31: =SUMIFS(נתונים_שטוחים!AN29:AY29,נתונים_שטוחים!$AN$3:$AY$3,"<="&$F$2) -> 0 | H31: =IFERROR(G31/F31-1,"-") -> - | I31: =G31-F31 -> 0
A32: =נתונים_שטוחים!A30 -> 209 | B32: =נתונים_שטוחים!B30 -> ORTOPROFIL PROD | C32: =נתונים_שטוחים!C30 -> ROMANIA | D32: =SUMIFS(נתונים_שטוחים!D30:O30,נתונים_שטוחים!$D$3:$O$3,"<="&$F$2) -> 348874.04 | E32: =SUMIFS(נתונים_שטוחים!P30:AA30,נתונים_שטוחים!$P$3:$AA$3,"<="&$F$2) -> 405953.63 | F32: =SUMIFS(נתונים_שטוחים!AB30:AM30,נתונים_שטוחים!$AB$3:$AM$3,"<="&$F$2) -> 300835.11 | G32: =SUMIFS(נתונים_שטוחים!AN30:AY30,נתונים_שטוחים!$AN$3:$AY$3,"<="&$F$2) -> 0 | H32: =IFERROR(G32/F32-1,"-") -> -1 | I32: =G32-F32 -> -300835.11
A33: =נתונים_שטוחים!A31 -> 210 | B33: =נתונים_שטוחים!B31 -> OY. EA. AB. | C33: =נתונים_שטוחים!C31 -> FINLAND | D33: =SUMIFS(נתונים_שטוחים!D31:O31,נתונים_שטוחים!$D$3:$O$3,"<="&$F$2) -> 107690.85 | E33: =SUMIFS(נתונים_שטוחים!P31:AA31,נתונים_שטוחים!$P$3:$AA$3,"<="&$F$2) -> 64554.59 | F33: =SUMIFS(נתונים_שטוחים!AB31:AM31,נתונים_שטוחים!$AB$3:$AM$3,"<="&$F$2) -> 43116.44 | G33: =SUMIFS(נתונים_שטוחים!AN31:AY31,נתונים_שטוחים!$AN$3:$AY$3,"<="&$F$2) -> 0 | H33: =IFERROR(G33/F33-1,"-") -> -1 | I33: =G33-F33 -> -43116.44
A34: =נתונים_שטוחים!A32 -> 201 | B34: =נתונים_שטוחים!B32 -> SEVEN GEAR | C34: =נתונים_שטוחים!C32 -> FINLAND | D34: =SUMIFS(נתונים_שטוחים!D32:O32,נתונים_שטוחים!$D$3:$O$3,"<="&$F$2) -> 41028.36 | E34: =SUMIFS(נתונים_שטוחים!P32:AA32,נתונים_שטוחים!$P$3:$AA$3,"<="&$F$2) -> 60908.2 | F34: =SUMIFS(נתונים_שטוחים!AB32:AM32,נתונים_שטוחים!$AB$3:$AM$3,"<="&$F$2) -> 39400.13 | G34: =SUMIFS(נתונים_שטוחים!AN32:AY32,נתונים_שטוחים!$AN$3:$AY$3,"<="&$F$2) -> 0 | H34: =IFERROR(G34/F34-1,"-") -> -1 | I34: =G34-F34 -> -39400.13
... A44: =נתונים_שטוחים!A42 -> 302 | B44: =נתונים_שטוחים!B42 -> MEXICO | C44: =נתונים_שטוחים!C42 -> MEXICO | D44: =SUMIFS(נתונים_שטוחים!D42:O42,נתונים_שטוחים!$D$3:$O$3,"<="&$F$2) -> 0 | E44: =SUMIFS(נתונים_שטוחים!P42:AA42,נתונים_שטוחים!$P$3:$AA$3,"<="&$F$2) -> 0 | F44: =SUMIFS(נתונים_שטוחים!AB42:AM42,נתונים_שטוחים!$AB$3:$AM$3,"<="&$F$2) -> 0 | G44: =SUMIFS(נתונים_שטוחים!AN42:AY42,נתונים_שטוחים!$AN$3:$AY$3,"<="&$F$2) -> 0 | H44: =IFERROR(G44/F44-1,"-") -> - | I44: =G44-F44 -> 0
B45: ='1'!B43 -> סה"כ חו"ל | D45: =SUM(D23:D44) -> 7648509.6 | E45: =SUM(E23:E44) -> 5973375.8 | F45: =SUM(F23:F44) -> 4050561.8 | G45: =SUM(G23:G44) -> 0 | H45: =IFERROR(G45/F45-1,"-") -> -1 | I45: =G45-F45 -> -4050561.8
B46: ='1'!B44 -> סה"כ מכירות | D46: =D45+D22 -> 25012792 | E46: =E45+E22 -> 24119651 | F46: =F45+F22 -> 19243217 | G46: =G45+G22 -> 0 | H46: =IFERROR(G46/F46-1,"-") -> -1 | I46: =G46-F46 -> -19243217

Sheet רבעונים
A1: ביצוע לפי רבעונים (ללא תקציב/מטרה - עדיין לא הוגדר תקציב 2027)
B2: בחר רבעון: | D2: Q4 | E2: (מספר רבעון נבחר:) | F2: =VALUE(MID($D$2,2,1)) -> 4 | G2: תאריך חישוב: | H2: 02/10/26
A4: # | B4: לקוח | C4: קבוצה | D4: 2024 (רבעון) | E4: 2025 (רבעון) | F4: 2026 (רבעון) | G4: 2027 (רבעון) | H4: % מול 2026 | I4: ₪ מול 2026
A5: =נתונים_שטוחים!A5 -> 111 | B5: =נתונים_שטוחים!B5 -> סופר פארם לייף | C5: =נתונים_שטוחים!C5 -> ISR | D5: =SUMIFS(נתונים_שטוחים!D5:O5,נתונים_שטוחים!$D$4:$O$4,$F$2) -> 501891.94 | E5: =SUMIFS(נתונים_שטוחים!P5:AA5,נתונים_שטוחים!$P$4:$AA$4,$F$2) -> 397235.16 | F5: =SUMIFS(נתונים_שטוחים!AB5:AM5,נתונים_שטוחים!$AB$4:$AM$4,$F$2) -> 20995.2 | G5: =SUMIFS(נתונים_שטוחים!AN5:AY5,נתונים_שטוחים!$AN$4:$AY$4,$F$2) -> 0 | H5: =IFERROR(G5/F5-1,"-") -> -1 | I5: =G5-F5 -> -20995.2
A6: =נתונים_שטוחים!A6 -> 1 | B6: =נתונים_שטוחים!B6 -> סופרפארם | C6: =נתונים_שטוחים!C6 -> ISR | D6: =SUMIFS(נתונים_שטוחים!D6:O6,נתונים_שטוחים!$D$4:$O$4,$F$2) -> 1256467.8 | E6: =SUMIFS(נתונים_שטוחים!P6:AA6,נתונים_שטוחים!$P$4:$AA$4,$F$2) -> 1377947.5 | F6: =SUMIFS(נתונים_שטוחים!AB6:AM6,נתונים_שטוחים!$AB$4:$AM$4,$F$2) -> 0 | G6: =SUMIFS(נתונים_שטוחים!AN6:AY6,נתונים_שטוחים!$AN$4:$AY$4,$F$2) -> 0 | H6: =IFERROR(G6/F6-1,"-") -> - | I6: =G6-F6 -> 0
A7: =נתונים_שטוחים!A7 -> 2 | B7: =נתונים_שטוחים!B7 -> BE | C7: =נתונים_שטוחים!C7 -> ISR | D7: =SUMIFS(נתונים_שטוחים!D7:O7,נתונים_שטוחים!$D$4:$O$4,$F$2) -> 249549.94 | E7: =SUMIFS(נתונים_שטוחים!P7:AA7,נתונים_שטוחים!$P$4:$AA$4,$F$2) -> 208571.09 | F7: =SUMIFS(נתונים_שטוחים!AB7:AM7,נתונים_שטוחים!$AB$4:$AM$4,$F$2) -> 0 | G7: =SUMIFS(נתונים_שטוחים!AN7:AY7,נתונים_שטוחים!$AN$4:$AY$4,$F$2) -> 0 | H7: =IFERROR(G7/F7-1,"-") -> - | I7: =G7-F7 -> 0
A8: =נתונים_שטוחים!A8 -> 3 | B8: =נתונים_שטוחים!B8 -> בתי מרקחת | C8: =נתונים_שטוחים!C8 -> ISR | D8: =SUMIFS(נתונים_שטוחים!D8:O8,נתונים_שטוחים!$D$4:$O$4,$F$2) -> 423029.49 | E8: =SUMIFS(נתונים_שטוחים!P8:AA8,נתונים_שטוחים!$P$4:$AA$4,$F$2) -> 462437.99 | F8: =SUMIFS(נתונים_שטוחים!AB8:AM8,נתונים_שטוחים!$AB$4:$AM$4,$F$2) -> 0 | G8: =SUMIFS(נתונים_שטוחים!AN8:AY8,נתונים_שטוחים!$AN$4:$AY$4,$F$2) -> 0 | H8: =IFERROR(G8/F8-1,"-") -> - | I8: =G8-F8 -> 0
A9: =נתונים_שטוחים!A9 -> 112 | B9: =נתונים_שטוחים!B9 -> כללית | C9: =נתונים_שטוחים!C9 -> ISR | D9: =SUMIFS(נתונים_שטוחים!D9:O9,נתונים_שטוחים!$D$4:$O$4,$F$2) -> 988830.3 | E9: =SUMIFS(נתונים_שטוחים!P9:AA9,נתונים_שטוחים!$P$4:$AA$4,$F$2) -> 860724.67 | F9: =SUMIFS(נתונים_שטוחים!AB9:AM9,נתונים_שטוחים!$AB$4:$AM$4,$F$2) -> 0 | G9: =SUMIFS(נתונים_שטוחים!AN9:AY9,נתונים_שטוחים!$AN$4:$AY$4,$F$2) -> 0 | H9: =IFERROR(G9/F9-1,"-") -> - | I9: =G9-F9 -> 0
A10: =נתונים_שטוחים!A10 -> 113 | B10: =נתונים_שטוחים!B10 -> מאוחדת | C10: =נתונים_שטוחים!C10 -> ISR | D10: =SUMIFS(נתונים_שטוחים!D10:O10,נתונים_שטוחים!$D$4:$O$4,$F$2) -> 175743.18 | E10: =SUMIFS(נתונים_שטוחים!P10:AA10,נתונים_שטוחים!$P$4:$AA$4,$F$2) -> 198828.06 | F10: =SUMIFS(נתונים_שטוחים!AB10:AM10,נתונים_שטוחים!$AB$4:$AM$4,$F$2) -> 0 | G10: =SUMIFS(נתונים_שטוחים!AN10:AY10,נתונים_שטוחים!$AN$4:$AY$4,$F$2) -> 0 | H10: =IFERROR(G10/F10-1,"-") -> - | I10: =G10-F10 -> 0
A11: =נתונים_שטוחים!A11 -> 4 | B11: =נתונים_שטוחים!B11 -> מכבי | C11: =נתונים_שטוחים!C11 -> ISR | D11: =SUMIFS(נתונים_שטוחים!D11:O11,נתונים_שטוחים!$D$4:$O$4,$F$2) -> 0 | E11: =SUMIFS(נתונים_שטוחים!P11:AA11,נתונים_שטוחים!$P$4:$AA$4,$F$2) -> 0 | F11: =SUMIFS(נתונים_שטוחים!AB11:AM11,נתונים_שטוחים!$AB$4:$AM$4,$F$2) -> 0 | G11: =SUMIFS(נתונים_שטוחים!AN11:AY11,נתונים_שטוחים!$AN$4:$AY$4,$F$2) -> 0 | H11: =IFERROR(G11/F11-1,"-") -> - | I11: =G11-F11 -> 0
A12: =נתונים_שטוחים!A12 -> 102 | B12: =נתונים_שטוחים!B12 -> מכוני אורטופדיה | C12: =נתונים_שטוחים!C12 -> ISR | D12: =SUMIFS(נתונים_שטוחים!D12:O12,נתונים_שטוחים!$D$4:$O$4,$F$2) -> 184800.08 | E12: =SUMIFS(נתונים_שטוחים!P12:AA12,נתונים_שטוחים!$P$4:$AA$4,$F$2) -> 223581.68 | F12: =SUMIFS(נתונים_שטוחים!AB12:AM12,נתונים_שטוחים!$AB$4:$AM$4,$F$2) -> 0 | G12: =SUMIFS(נתונים_שטוחים!AN12:AY12,נתונים_שטוחים!$AN$4:$AY$4,$F$2) -> 0 | H12: =IFERROR(G12/F12-1,"-") -> - | I12: =G12-F12 -> 0
A13: =נתונים_שטוחים!A13 -> 101 | B13: =נתונים_שטוחים!B13 -> לקוחות מפעל | C13: =נתונים_שטוחים!C13 -> ISR | D13: =SUMIFS(נתונים_שטוחים!D13:O13,נתונים_שטוחים!$D$4:$O$4,$F$2) -> 38609.45 | E13: =SUMIFS(נתונים_שטוחים!P13:AA13,נתונים_שטוחים!$P$4:$AA$4,$F$2) -> 48810.03 | F13: =SUMIFS(נתונים_שטוחים!AB13:AM13,נתונים_שטוחים!$AB$4:$AM$4,$F$2) -> 0 | G13: =SUMIFS(נתונים_שטוחים!AN13:AY13,נתונים_שטוחים!$AN$4:$AY$4,$F$2) -> 0 | H13: =IFERROR(G13/F13-1,"-") -> - | I13: =G13-F13 -> 0
A14: =נתונים_שטוחים!A14 -> 109 | B14: =נתונים_שטוחים!B14 -> חנויות פרטיות | C14: =נתונים_שטוחים!C14 -> ISR | D14: =SUMIFS(נתונים_שטוחים!D14:O14,נתונים_שטוחים!$D$4:$O$4,$F$2) -> 39179.29 | E14: =SUMIFS(נתונים_שטוחים!P14:AA14,נתונים_שטוחים!$P$4:$AA$4,$F$2) -> 11043.34 | F14: =SUMIFS(נתונים_שטוחים!AB14:AM14,נתונים_שטוחים!$AB$4:$AM$4,$F$2) -> 0 | G14: =SUMIFS(נתונים_שטוחים!AN14:AY14,נתונים_שטוחים!$AN$4:$AY$4,$F$2) -> 0 | H14: =IFERROR(G14/F14-1,"-") -> - | I14: =G14-F14 -> 0
A15: =נתונים_שטוחים!A15 -> 105 | B15: =נתונים_שטוחים!B15 -> מכוני פדיקור | C15: =נתונים_שטוחים!C15 -> ISR | D15: =SUMIFS(נתונים_שטוחים!D15:O15,נתונים_שטוחים!$D$4:$O$4,$F$2) -> 850.4 | E15: =SUMIFS(נתונים_שטוחים!P15:AA15,נתונים_שטוחים!$P$4:$AA$4,$F$2) -> 1168.54 | F15: =SUMIFS(נתונים_שטוחים!AB15:AM15,נתונים_שטוחים!$AB$4:$AM$4,$F$2) -> 0 | G15: =SUMIFS(נתונים_שטוחים!AN15:AY15,נתונים_שטוחים!$AN$4:$AY$4,$F$2) -> 0 | H15: =IFERROR(G15/F15-1,"-") -> - | I15: =G15-F15 -> 0
A16: =נתונים_שטוחים!A16 -> 104 | B16: =נתונים_שטוחים!B16 -> חנויות נעליים | C16: =נתונים_שטוחים!C16 -> ISR | D16: =SUMIFS(נתונים_שטוחים!D16:O16,נתונים_שטוחים!$D$4:$O$4,$F$2) -> -14.28 | E16: =SUMIFS(נתונים_שטוחים!P16:AA16,נתונים_שטוחים!$P$4:$AA$4,$F$2) -> 514.2 | F16: =SUMIFS(נתונים_שטוחים!AB16:AM16,נתונים_שטוחים!$AB$4:$AM$4,$F$2) -> 0 | G16: =SUMIFS(נתונים_שטוחים!AN16:AY16,נתונים_שטוחים!$AN$4:$AY$4,$F$2) -> 0 | H16: =IFERROR(G16/F16-1,"-") -> - | I16: =G16-F16 -> 0
... A18: =נתונים_שטוחים!A18 -> 103 | B18: =נתונים_שטוחים!B18 -> מכוני פיזיותרפיה | C18: =נתונים_שטוחים!C18 -> ISR | D18: =SUMIFS(נתונים_שטוחים!D18:O18,נתונים_שטוחים!$D$4:$O$4,$F$2) -> 11626.65 | E18: =SUMIFS(נתונים_שטוחים!P18:AA18,נתונים_שטוחים!$P$4:$AA$4,$F$2) -> 17330.93 | F18: =SUMIFS(נתונים_שטוחים!AB18:AM18,נתונים_שטוחים!$AB$4:$AM$4,$F$2) -> 0 | G18: =SUMIFS(נתונים_שטוחים!AN18:AY18,נתונים_שטוחים!$AN$4:$AY$4,$F$2) -> 0 | H18: =IFERROR(G18/F18-1,"-") -> - | I18: =G18-F18 -> 0
B19: ='1'!B17 -> סה"כ ישראל ללא אונליין | D19: =SUM(D5:D18) -> 3874286.9 | E19: =SUM(E5:E18) -> 3810006.7 | F19: =SUM(F5:F18) -> 20995.2 | G19: =SUM(G5:G18) -> 0 | H19: =IFERROR(G19/F19-1,"-") -> -1 | I19: =G19-F19 -> -20995.2
A20: =נתונים_שטוחים!A19 -> 114 | B20: =נתונים_שטוחים!B19 -> לקוחות אינטרנט | C20: =נתונים_שטוחים!C19 -> ISR | D20: =SUMIFS(נתונים_שטוחים!D19:O19,נתונים_שטוחים!$D$4:$O$4,$F$2) -> 253937.59 | E20: =SUMIFS(נתונים_שטוחים!P19:AA19,נתונים_שטוחים!$P$4:$AA$4,$F$2) -> 599115.08 | F20: =SUMIFS(נתונים_שטוחים!AB19:AM19,נתונים_שטוחים!$AB$4:$AM$4,$F$2) -> 0 | G20: =SUMIFS(נתונים_שטוחים!AN19:AY19,נתונים_שטוחים!$AN$4:$AY$4,$F$2) -> 0 | H20: =IFERROR(G20/F20-1,"-") -> - | I20: =G20-F20 -> 0
A21: =נתונים_שטוחים!A20 -> 115 | B21: =נתונים_שטוחים!B20 -> סופר פארם מרקט פלייס | C21: =נתונים_שטוחים!C20 -> ISR | D21: =SUMIFS(נתונים_שטוחים!D20:O20,נתונים_שטוחים!$D$4:$O$4,$F$2) -> 10454.96 | E21: =SUMIFS(נתונים_שטוחים!P20:AA20,נתונים_שטוחים!$P$4:$AA$4,$F$2) -> 4382.6 | F21: =SUMIFS(נתונים_שטוחים!AB20:AM20,נתונים_שטוחים!$AB$4:$AM$4,$F$2) -> 0 | G21: =SUMIFS(נתונים_שטוחים!AN20:AY20,נתונים_שטוחים!$AN$4:$AY$4,$F$2) -> 0 | H21: =IFERROR(G21/F21-1,"-") -> - | I21: =G21-F21 -> 0
B22: ='1'!B20 -> סה"כ ישראל | D22: =D19+D20+D21 -> 4138679.5 | E22: =E19+E20+E21 -> 4413504.4 | F22: =F19+F20+F21 -> 20995.2 | G22: =G19+G20+G21 -> 0 | H22: =IFERROR(G22/F22-1,"-") -> -1 | I22: =G22-F22 -> -20995.2
A23: =נתונים_שטוחים!A21 -> 301 | B23: =נתונים_שטוחים!B21 -> AMAZON | C23: =נתונים_שטוחים!C21 -> USA | D23: =SUMIFS(נתונים_שטוחים!D21:O21,נתונים_שטוחים!$D$4:$O$4,$F$2) -> 594913.85 | E23: =SUMIFS(נתונים_שטוחים!P21:AA21,נתונים_שטוחים!$P$4:$AA$4,$F$2) -> 676973.71 | F23: =SUMIFS(נתונים_שטוחים!AB21:AM21,נתונים_שטוחים!$AB$4:$AM$4,$F$2) -> 0 | G23: =SUMIFS(נתונים_שטוחים!AN21:AY21,נתונים_שטוחים!$AN$4:$AY$4,$F$2) -> 0 | H23: =IFERROR(G23/F23-1,"-") -> - | I23: =G23-F23 -> 0
A24: =נתונים_שטוחים!A22 -> 202 | B24: =נתונים_שטוחים!B22 -> SUPER PHARM POLAND | C24: =נתונים_שטוחים!C22 -> POLAND | D24: =SUMIFS(נתונים_שטוחים!D22:O22,נתונים_שטוחים!$D$4:$O$4,$F$2) -> 137974.18 | E24: =SUMIFS(נתונים_שטוחים!P22:AA22,נתונים_שטוחים!$P$4:$AA$4,$F$2) -> 284867.18 | F24: =SUMIFS(נתונים_שטוחים!AB22:AM22,נתונים_שטוחים!$AB$4:$AM$4,$F$2) -> 0 | G24: =SUMIFS(נתונים_שטוחים!AN22:AY22,נתונים_שטוחים!$AN$4:$AY$4,$F$2) -> 0 | H24: =IFERROR(G24/F24-1,"-") -> - | I24: =G24-F24 -> 0
A25: =נתונים_שטוחים!A23 -> 203 | B25: =נתונים_שטוחים!B23 -> ORTHO- PARTNER AG. | C25: =נתונים_שטוחים!C23 -> SWITZERLAND | D25: =SUMIFS(נתונים_שטוחים!D23:O23,נתונים_שטוחים!$D$4:$O$4,$F$2) -> 220830.5 | E25: =SUMIFS(נתונים_שטוחים!P23:AA23,נתונים_שטוחים!$P$4:$AA$4,$F$2) -> 54650.07 | F25: =SUMIFS(נתונים_שטוחים!AB23:AM23,נתונים_שטוחים!$AB$4:$AM$4,$F$2) -> 0 | G25: =SUMIFS(נתונים_שטוחים!AN23:AY23,נתונים_שטוחים!$AN$4:$AY$4,$F$2) -> 0 | H25: =IFERROR(G25/F25-1,"-") -> - | I25: =G25-F25 -> 0
A26: =נתונים_שטוחים!A24 -> 204 | B26: =נתונים_שטוחים!B24 -> SANAFLEX ANATOMIC | C26: =נתונים_שטוחים!C24 -> GREECE | D26: =SUMIFS(נתונים_שטוחים!D24:O24,נתונים_שטוחים!$D$4:$O$4,$F$2) -> 167224.53 | E26: =SUMIFS(נתונים_שטוחים!P24:AA24,נתונים_שטוחים!$P$4:$AA$4,$F$2) -> 83397.79 | F26: =SUMIFS(נתונים_שטוחים!AB24:AM24,נתונים_שטוחים!$AB$4:$AM$4,$F$2) -> 0 | G26: =SUMIFS(נתונים_שטוחים!AN24:AY24,נתונים_שטוחים!$AN$4:$AY$4,$F$2) -> 0 | H26: =IFERROR(G26/F26-1,"-") -> - | I26: =G26-F26 -> 0
A27: =נתונים_שטוחים!A25 -> 205 | B27: =נתונים_שטוחים!B25 -> HEALTH CARE PROD. GMBH | C27: =נתונים_שטוחים!C25 -> GERMANY | D27: =SUMIFS(נתונים_שטוחים!D25:O25,נתונים_שטוחים!$D$4:$O$4,$F$2) -> 17813.97 | E27: =SUMIFS(נתונים_שטוחים!P25:AA25,נתונים_שטוחים!$P$4:$AA$4,$F$2) -> 31158.35 | F27: =SUMIFS(נתונים_שטוחים!AB25:AM25,נתונים_שטוחים!$AB$4:$AM$4,$F$2) -> 0 | G27: =SUMIFS(נתונים_שטוחים!AN25:AY25,נתונים_שטוחים!$AN$4:$AY$4,$F$2) -> 0 | H27: =IFERROR(G27/F27-1,"-") -> - | I27: =G27-F27 -> 0
A28: =נתונים_שטוחים!A26 -> 206 | B28: =נתונים_שטוחים!B26 -> ORTHOMED LTD | C28: =נתונים_שטוחים!C26 -> BULGARIA | D28: =SUMIFS(נתונים_שטוחים!D26:O26,נתונים_שטוחים!$D$4:$O$4,$F$2) -> 44572.45 | E28: =SUMIFS(נתונים_שטוחים!P26:AA26,נתונים_שטוחים!$P$4:$AA$4,$F$2) -> 0 | F28: =SUMIFS(נתונים_שטוחים!AB26:AM26,נתונים_שטוחים!$AB$4:$AM$4,$F$2) -> 0 | G28: =SUMIFS(נתונים_שטוחים!AN26:AY26,נתונים_שטוחים!$AN$4:$AY$4,$F$2) -> 0 | H28: =IFERROR(G28/F28-1,"-") -> - | I28: =G28-F28 -> 0
A29: =נתונים_שטוחים!A27 -> 207 | B29: =נתונים_שטוחים!B27 -> SALUS | C29: =נתונים_שטוחים!C27 -> HUNGARY | D29: =SUMIFS(נתונים_שטוחים!D27:O27,נתונים_שטוחים!$D$4:$O$4,$F$2) -> 222074.04 | E29: =SUMIFS(נתונים_שטוחים!P27:AA27,נתונים_שטוחים!$P$4:$AA$4,$F$2) -> 146752.62 | F29: =SUMIFS(נתונים_שטוחים!AB27:AM27,נתונים_שטוחים!$AB$4:$AM$4,$F$2) -> 0 | G29: =SUMIFS(נתונים_שטוחים!AN27:AY27,נתונים_שטוחים!$AN$4:$AY$4,$F$2) -> 0 | H29: =IFERROR(G29/F29-1,"-") -> - | I29: =G29-F29 -> 0
A30: =נתונים_שטוחים!A28 -> 216 | B30: =נתונים_שטוחים!B28 -> MAX KONNARIS LTD | C30: =נתונים_שטוחים!C28 -> CYPRUS | D30: =SUMIFS(נתונים_שטוחים!D28:O28,נתונים_שטוחים!$D$4:$O$4,$F$2) -> 20724.08 | E30: =SUMIFS(נתונים_שטוחים!P28:AA28,נתונים_שטוחים!$P$4:$AA$4,$F$2) -> 20604.23 | F30: =SUMIFS(נתונים_שטוחים!AB28:AM28,נתונים_שטוחים!$AB$4:$AM$4,$F$2) -> 0 | G30: =SUMIFS(נתונים_שטוחים!AN28:AY28,נתונים_שטוחים!$AN$4:$AY$4,$F$2) -> 0 | H30: =IFERROR(G30/F30-1,"-") -> - | I30: =G30-F30 -> 0
A31: =נתונים_שטוחים!A29 -> 208 | B31: =נתונים_שטוחים!B29 -> MEDIPAL COMPANY | C31: =נתונים_שטוחים!C29 -> NABLUS | D31: =SUMIFS(נתונים_שטוחים!D29:O29,נתונים_שטוחים!$D$4:$O$4,$F$2) -> 198800.83 | E31: =SUMIFS(נתונים_שטוחים!P29:AA29,נתונים_שטוחים!$P$4:$AA$4,$F$2) -> 256771.88 | F31: =SUMIFS(נתונים_שטוחים!AB29:AM29,נתונים_שטוחים!$AB$4:$AM$4,$F$2) -> 0 | G31: =SUMIFS(נתונים_שטוחים!AN29:AY29,נתונים_שטוחים!$AN$4:$AY$4,$F$2) -> 0 | H31: =IFERROR(G31/F31-1,"-") -> - | I31: =G31-F31 -> 0
A32: =נתונים_שטוחים!A30 -> 209 | B32: =נתונים_שטוחים!B30 -> ORTOPROFIL PROD | C32: =נתונים_שטוחים!C30 -> ROMANIA | D32: =SUMIFS(נתונים_שטוחים!D30:O30,נתונים_שטוחים!$D$4:$O$4,$F$2) -> 62633.86 | E32: =SUMIFS(נתונים_שטוחים!P30:AA30,נתונים_שטוחים!$P$4:$AA$4,$F$2) -> 106882.54 | F32: =SUMIFS(נתונים_שטוחים!AB30:AM30,נתונים_שטוחים!$AB$4:$AM$4,$F$2) -> 0 | G32: =SUMIFS(נתונים_שטוחים!AN30:AY30,נתונים_שטוחים!$AN$4:$AY$4,$F$2) -> 0 | H32: =IFERROR(G32/F32-1,"-") -> - | I32: =G32-F32 -> 0
A33: =נתונים_שטוחים!A31 -> 210 | B33: =נתונים_שטוחים!B31 -> OY. EA. AB. | C33: =נתונים_שטוחים!C31 -> FINLAND | D33: =SUMIFS(נתונים_שטוחים!D31:O31,נתונים_שטוחים!$D$4:$O$4,$F$2) -> 3920.16 | E33: =SUMIFS(נתונים_שטוחים!P31:AA31,נתונים_שטוחים!$P$4:$AA$4,$F$2) -> 32544.41 | F33: =SUMIFS(נתונים_שטוחים!AB31:AM31,נתונים_שטוחים!$AB$4:$AM$4,$F$2) -> 0 | G33: =SUMIFS(נתונים_שטוחים!AN31:AY31,נתונים_שטוחים!$AN$4:$AY$4,$F$2) -> 0 | H33: =IFERROR(G33/F33-1,"-") -> - | I33: =G33-F33 -> 0
A34: =נתונים_שטוחים!A32 -> 201 | B34: =נתונים_שטוחים!B32 -> SEVEN GEAR | C34: =נתונים_שטוחים!C32 -> FINLAND | D34: =SUMIFS(נתונים_שטוחים!D32:O32,נתונים_שטוחים!$D$4:$O$4,$F$2) -> 0 | E34: =SUMIFS(נתונים_שטוחים!P32:AA32,נתונים_שטוחים!$P$4:$AA$4,$F$2) -> 22174.9 | F34: =SUMIFS(נתונים_שטוחים!AB32:AM32,נתונים_שטוחים!$AB$4:$AM$4,$F$2) -> 0 | G34: =SUMIFS(נתונים_שטוחים!AN32:AY32,נתונים_שטוחים!$AN$4:$AY$4,$F$2) -> 0 | H34: =IFERROR(G34/F34-1,"-") -> - | I34: =G34-F34 -> 0
... A44: =נתונים_שטוחים!A42 -> 302 | B44: =נתונים_שטוחים!B42 -> MEXICO | C44: =נתונים_שטוחים!C42 -> MEXICO | D44: =SUMIFS(נתונים_שטוחים!D42:O42,נתונים_שטוחים!$D$4:$O$4,$F$2) -> 0 | E44: =SUMIFS(נתונים_שטוחים!P42:AA42,נתונים_שטוחים!$P$4:$AA$4,$F$2) -> 0 | F44: =SUMIFS(נתונים_שטוחים!AB42:AM42,נתונים_שטוחים!$AB$4:$AM$4,$F$2) -> 0 | G44: =SUMIFS(נתונים_שטוחים!AN42:AY42,נתונים_שטוחים!$AN$4:$AY$4,$F$2) -> 0 | H44: =IFERROR(G44/F44-1,"-") -> - | I44: =G44-F44 -> 0
B45: ='1'!B43 -> סה"כ חו"ל | D45: =SUM(D23:D44) -> 1853058.6 | E45: =SUM(E23:E44) -> 1740109.3 | F45: =SUM(F23:F44) -> 0 | G45: =SUM(G23:G44) -> 0 | H45: =IFERROR(G45/F45-1,"-") -> - | I45: =G45-F45 -> 0
B46: ='1'!B44 -> סה"כ מכירות | D46: =D45+D22 -> 5991738.1 | E46: =E45+E22 -> 6153613.8 | F46: =F45+F22 -> 20995.2 | G46: =G45+G22 -> 0 | H46: =IFERROR(G46/F46-1,"-") -> -1 | I46: =G46-F46 -> -20995.2

Sheet 1
B1: דוח מכירות ינואר 2027 | K1: תאריך הכנת התשתית: 02/10/26
A2: # | B2: לקוח | C2: קבוצה | D2: 2024 | E2: 2025 | F2: 2026 | G2: 2027 | H2: אחוז מול 2026 | I2: כספי מול 2026
A3: 111 | B3: סופר פארם לייף | C3: ISR | D3: -594.08 | E3: 58427.8 | F3: 63104 | H3: =IF(G3="","-",IFERROR(G3/F3-1,"-")) -> - | I3: =IF(G3="","-",G3-F3) -> -
A4: 1 | B4: סופרפארם | C4: ISR | D4: 452441.08 | E4: 670882.2 | F4: 423956.26 | H4: =IF(G4="","-",IFERROR(G4/F4-1,"-")) -> - | I4: =IF(G4="","-",G4-F4) -> -
A5: 2 | B5: BE | C5: ISR | D5: 63301.42 | E5: 54489.89 | F5: 67635.75 | H5: =IF(G5="","-",IFERROR(G5/F5-1,"-")) -> - | I5: =IF(G5="","-",G5-F5) -> -
A6: 3 | B6: בתי מרקחת | C6: ISR | D6: 164714.58 | E6: 136160.38 | F6: 192169.79 | H6: =IF(G6="","-",IFERROR(G6/F6-1,"-")) -> - | I6: =IF(G6="","-",G6-F6) -> -
A7: 112 | B7: כללית | C7: ISR | D7: 414961 | E7: 326467.5 | F7: 320186.2 | H7: =IF(G7="","-",IFERROR(G7/F7-1,"-")) -> - | I7: =IF(G7="","-",G7-F7) -> -
A8: 113 | B8: מאוחדת | C8: ISR | D8: 74817.97 | E8: 57834.64 | F8: 60425.14 | H8: =IF(G8="","-",IFERROR(G8/F8-1,"-")) -> - | I8: =IF(G8="","-",G8-F8) -> -
A9: 4 | B9: מכבי | C9: ISR | F9: 0 | H9: =IF(G9="","-",IFERROR(G9/F9-1,"-")) -> - | I9: =IF(G9="","-",G9-F9) -> -
A10: 102 | B10: מכוני אורטופדיה | C10: ISR | D10: 91890.1 | E10: 72633.3 | F10: 86618.03 | H10: =IF(G10="","-",IFERROR(G10/F10-1,"-")) -> - | I10: =IF(G10="","-",G10-F10) -> -
A11: 101 | B11: לקוחות מפעל | C11: ISR | D11: 15878.93 | E11: 16402.68 | F11: 18073.66 | H11: =IF(G11="","-",IFERROR(G11/F11-1,"-")) -> - | I11: =IF(G11="","-",G11-F11) -> -
A12: 109 | B12: חנויות פרטיות | C12: ISR | D12: 5667.68 | E12: 6025.5 | F12: 5894.68 | H12: =IF(G12="","-",IFERROR(G12/F12-1,"-")) -> - | I12: =IF(G12="","-",G12-F12) -> -
A13: 105 | B13: מכוני פדיקור | C13: ISR | D13: 0 | E13: 1162.85 | F13: 810.6 | H13: =IF(G13="","-",IFERROR(G13/F13-1,"-")) -> - | I13: =IF(G13="","-",G13-F13) -> -
A14: 104 | B14: חנויות נעליים | C14: ISR | D14: 0 | E14: 0 | H14: =IF(G14="","-",IFERROR(G14/F14-1,"-")) -> - | I14: =IF(G14="","-",G14-F14) -> -
A15: 106 | B15: בתי חולים ושרות | C15: ISR | D15: 0 | E15: 0 | F15: 2523.6 | H15: =IF(G15="","-",IFERROR(G15/F15-1,"-")) -> - | I15: =IF(G15="","-",G15-F15) -> -
A16: 103 | B16: מכוני פיזיותרפיה | C16: ISR | D16: 4135.49 | E16: 15213.91 | F16: 11467.92 | H16: =IF(G16="","-",IFERROR(G16/F16-1,"-")) -> - | I16: =IF(G16="","-",G16-F16) -> -
B17: סה"כ ישראל ללא אונליין | D17: =SUM(D3:D16) -> 1287214.2 | E17: =SUM(E3:E16) -> 1415700.6 | F17: =SUM(F3:F16) -> 1252865.6 | G17: =SUM(G3:G16) -> 0 | H17: =IF(G17="","-",IFERROR(G17/F17-1,"-")) -> -1 | I17: =IF(G17="","-",G17-F17) -> -1252865.6
A18: 114 | B18: לקוחות אינטרנט | C18: ISR | D18: 42663.04 | E18: 92988.17 | F18: 212354.12 | H18: =IF(G18="","-",IFERROR(G18/F18-1,"-")) -> - | I18: =IF(G18="","-",G18-F18) -> -
A19: 115 | B19: סופר פארם מרקט פלייס | C19: ISR | D19: 1654.88 | E19: 2032.3 | F19: 1274.4 | H19: =IF(G19="","-",IFERROR(G19/F19-1,"-")) -> - | I19: =IF(G19="","-",G19-F19) -> -
B20: סה"כ ישראל | D20: =D17+D18+D19 -> 1331532.1 | E20: =E17+E18+E19 -> 1510721.1 | F20: =F17+F18+F19 -> 1466494.1 | G20: =G17+G18+G19 -> 0 | H20: =IF(G20="","-",IFERROR(G20/F20-1,"-")) -> -1 | I20: =IF(G20="","-",G20-F20) -> -1466494.1
A21: 301 | B21: AMAZON | C21: USA | D21: 391520.95 | E21: 187395.64 | F21: 178026.69 | H21: =IF(G21="","-",IFERROR(G21/F21-1,"-")) -> - | I21: =IF(G21="","-",G21-F21) -> -
A22: 202 | B22: SUPER PHARM POLAND | C22: POLAND | D22: 203.73 | E22: 0 | H22: =IF(G22="","-",IFERROR(G22/F22-1,"-")) -> - | I22: =IF(G22="","-",G22-F22) -> -
A23: 203 | B23: ORTHO- PARTNER AG. | C23: SWITZERLAND | D23: 49158.59 | E23: 18517.61 | F23: 124895.37 | H23: =IF(G23="","-",IFERROR(G23/F23-1,"-")) -> - | I23: =IF(G23="","-",G23-F23) -> -
A24: 204 | B24: SANAFLEX ANATOMIC | C24: GREECE | D24: 68604.55 | E24: 0 | F24: 67158.97 | H24: =IF(G24="","-",IFERROR(G24/F24-1,"-")) -> - | I24: =IF(G24="","-",G24-F24) -> -
A25: 205 | B25: HEALTH CARE PROD. GMBH | C25: GERMANY | D25: 15923.68 | E25: 0 | F25: 15774.92 | H25: =IF(G25="","-",IFERROR(G25/F25-1,"-")) -> - | I25: =IF(G25="","-",G25-F25) -> -
A26: 206 | B26: ORTHOMED LTD | C26: BULGARIA | D26: 50777.76 | E26: 0 | H26: =IF(G26="","-",IFERROR(G26/F26-1,"-")) -> - | I26: =IF(G26="","-",G26-F26) -> -
A27: 207 | B27: SALUS | C27: HUNGARY | D27: 249206.12 | E27: 0 | F27: -1269.06 | H27: =IF(G27="","-",IFERROR(G27/F27-1,"-")) -> - | I27: =IF(G27="","-",G27-F27) -> -
A28: 216 | B28: MAX KONNARIS LTD | C28: CYPRUS | D28: 0 | E28: 0 | H28: =IF(G28="","-",IFERROR(G28/F28-1,"-")) -> - | I28: =IF(G28="","-",G28-F28) -> -
A29: 208 | B29: MEDIPAL COMPANY | C29: NABLUS | D29: 0 | E29: 0 | H29: =IF(G29="","-",IFERROR(G29/F29-1,"-")) -> - | I29: =IF(G29="","-",G29-F29) -> -
A30: 209 | B30: ORTOPROFIL PROD | C30: ROMANIA | D30: 0 | E30: 0 | F30: 27429.74 | H30: =IF(G30="","-",IFERROR(G30/F30-1,"-")) -> - | I30: =IF(G30="","-",G30-F30) -> -
A31: 210 | B31: OY. EA. AB. | C31: FINLAND | D31: 0 | E31: 0 | H31: =IF(G31="","-",IFERROR(G31/F31-1,"-")) -> - | I31: =IF(G31="","-",G31-F31) -> -
A32: 201 | B32: SEVEN GEAR | C32: FINLAND | D32: 0 | E32: 19897.57 | H32: =IF(G32="","-",IFERROR(G32/F32-1,"-")) -> - | I32: =IF(G32="","-",G32-F32) -> -
A33: 211 | B33: PHARMAG LACHMAIR GES. MBH | C33: AUSTRIA | D33: 0 | E33: 0 | H33: =IF(G33="","-",IFERROR(G33/F33-1,"-")) -> - | I33: =IF(G33="","-",G33-F33) -> -
A34: 304 | B34: REMEDICARE B.V. | C34: HOLLAND | H34: =IF(G34="","-",IFERROR(G34/F34-1,"-")) -> - | I34: =IF(G34="","-",G34-F34) -> -
A35: 213 | B35: E.F.M.O. | C35: SPAIN | D35: 20732.48 | E35: 19111.37 | F35: 18792.66 | H35: =IF(G35="","-",IFERROR(G35/F35-1,"-")) -> - | I35: =IF(G35="","-",G35-F35) -> -
A36: 214 | B36: ALFRED GERA | C36: MALTA | D36: 0 | E36: 0 | H36: =IF(G36="","-",IFERROR(G36/F36-1,"-")) -> - | I36: =IF(G36="","-",G36-F36) -> -
A37: 212 | B37: QUADRIFOGLIO MEDICAL | C37: ROMANIA | D37: 0 | E37: 0 | H37: =IF(G37="","-",IFERROR(G37/F37-1,"-")) -> - | I37: =IF(G37="","-",G37-F37) -> -
A38: 215 | B38: YOUNG IN HEALTHCARE CO., | C38: KOREA | D38: 0 | E38: 0 | H38: =IF(G38="","-",IFERROR(G38/F38-1,"-")) -> - | I38: =IF(G38="","-",G38-F38) -> -
A39: 217 | B39: HANS | C39: USA | D39: 0 | E39: 0 | H39: =IF(G39="","-",IFERROR(G39/F39-1,"-")) -> - | I39: =IF(G39="","-",G39-F39) -> -
A40: 303 | B40: NEW DISTRIBUTORS | C40: Other | H40: =IF(G40="","-",IFERROR(G40/F40-1,"-")) -> - | I40: =IF(G40="","-",G40-F40) -> -
...

Sheet 2
B1: דוח מכירות פברואר 2027 | K1: תאריך הכנת התשתית: 02/10/26
A2: # | B2: לקוח | C2: קבוצה | D2: 2024 | E2: 2025 | F2: 2026 | G2: 2027 | H2: אחוז מול 2026 | I2: כספי מול 2026
A3: 111 | B3: סופר פארם לייף | C3: ISR | D3: 347582.74 | E3: 233209.9 | F3: 364352.2 | H3: =IF(G3="","-",IFERROR(G3/F3-1,"-")) -> - | I3: =IF(G3="","-",G3-F3) -> -
A4: 1 | B4: סופרפארם | C4: ISR | D4: 422279.31 | E4: 406825.35 | F4: 469684.03 | H4: =IF(G4="","-",IFERROR(G4/F4-1,"-")) -> - | I4: =IF(G4="","-",G4-F4) -> -
A5: 2 | B5: BE | C5: ISR | D5: 82457.193 | E5: 65962.26 | F5: 68397.329 | H5: =IF(G5="","-",IFERROR(G5/F5-1,"-")) -> - | I5: =IF(G5="","-",G5-F5) -> -
A6: 3 | B6: בתי מרקחת | C6: ISR | D6: 163451.95 | E6: 133409.82 | F6: 140722.24 | H6: =IF(G6="","-",IFERROR(G6/F6-1,"-")) -> - | I6: =IF(G6="","-",G6-F6) -> -
A7: 112 | B7: כללית | C7: ISR | D7: 385135 | E7: 371734.5 | F7: 299047.35 | H7: =IF(G7="","-",IFERROR(G7/F7-1,"-")) -> - | I7: =IF(G7="","-",G7-F7) -> -
A8: 113 | B8: מאוחדת | C8: ISR | D8: 91523.03 | E8: 82146.14 | F8: 59215.28 | H8: =IF(G8="","-",IFERROR(G8/F8-1,"-")) -> - | I8: =IF(G8="","-",G8-F8) -> -
A9: 4 | B9: מכבי | C9: ISR | F9: 0 | H9: =IF(G9="","-",IFERROR(G9/F9-1,"-")) -> - | I9: =IF(G9="","-",G9-F9) -> -
A10: 102 | B10: מכוני אורטופדיה | C10: ISR | D10: 85829.2 | E10: 46378.11 | F10: 81282.23 | H10: =IF(G10="","-",IFERROR(G10/F10-1,"-")) -> - | I10: =IF(G10="","-",G10-F10) -> -
A11: 101 | B11: לקוחות מפעל | C11: ISR | D11: 11131.68 | E11: 17589.94 | F11: 11368.09 | H11: =IF(G11="","-",IFERROR(G11/F11-1,"-")) -> - | I11: =IF(G11="","-",G11-F11) -> -
A12: 109 | B12: חנויות פרטיות | C12: ISR | D12: 0 | E12: 4045.81 | F12: 3319.04 | H12: =IF(G12="","-",IFERROR(G12/F12-1,"-")) -> - | I12: =IF(G12="","-",G12-F12) -> -
A13: 105 | B13: מכוני פדיקור | C13: ISR | D13: 0 | E13: 569.45 | H13: =IF(G13="","-",IFERROR(G13/F13-1,"-")) -> - | I13: =IF(G13="","-",G13-F13) -> -
A14: 104 | B14: חנויות נעליים | C14: ISR | D14: 0 | E14: 0 | H14: =IF(G14="","-",IFERROR(G14/F14-1,"-")) -> - | I14: =IF(G14="","-",G14-F14) -> -
A15: 106 | B15: בתי חולים ושרות | C15: ISR | D15: 0 | E15: 11067.51 | F15: 947.38 | H15: =IF(G15="","-",IFERROR(G15/F15-1,"-")) -> - | I15: =IF(G15="","-",G15-F15) -> -
A16: 103 | B16: מכוני פיזיותרפיה | C16: ISR | D16: 8592.99 | E16: 12501.56 | F16: 15269.72 | H16: =IF(G16="","-",IFERROR(G16/F16-1,"-")) -> - | I16: =IF(G16="","-",G16-F16) -> -
B17: סה"כ ישראל ללא אונליין | D17: =SUM(D3:D16) -> 1597983.1 | E17: =SUM(E3:E16) -> 1385440.4 | F17: =SUM(F3:F16) -> 1513604.9 | G17: =SUM(G3:G16) -> 0 | H17: =IF(G17="","-",IFERROR(G17/F17-1,"-")) -> -1 | I17: =IF(G17="","-",G17-F17) -> -1513604.9
A18: 114 | B18: לקוחות אינטרנט | C18: ISR | D18: 40630.42 | E18: 97231.18 | F18: 236431.2 | H18: =IF(G18="","-",IFERROR(G18/F18-1,"-")) -> - | I18: =IF(G18="","-",G18-F18) -> -
A19: 115 | B19: סופר פארם מרקט פלייס | C19: ISR | D19: 2455.66 | E19: 3188.82 | F19: 1747 | H19: =IF(G19="","-",IFERROR(G19/F19-1,"-")) -> - | I19: =IF(G19="","-",G19-F19) -> -
B20: סה"כ ישראל | D20: =D17+D18+D19 -> 1641069.2 | E20: =E17+E18+E19 -> 1485860.4 | F20: =F17+F18+F19 -> 1751783.1 | G20: =G17+G18+G19 -> 0 | H20: =IF(G20="","-",IFERROR(G20/F20-1,"-")) -> -1 | I20: =IF(G20="","-",G20-F20) -> -1751783.1
A21: 301 | B21: AMAZON | C21: USA | D21: 377981.61 | E21: 188313.47 | F21: 194189.2 | H21: =IF(G21="","-",IFERROR(G21/F21-1,"-")) -> - | I21: =IF(G21="","-",G21-F21) -> -
A22: 202 | B22: SUPER PHARM POLAND | C22: POLAND | D22: 255841.44 | E22: 213082.56 | F22: 137198.2 | H22: =IF(G22="","-",IFERROR(G22/F22-1,"-")) -> - | I22: =IF(G22="","-",G22-F22) -> -
A23: 203 | B23: ORTHO- PARTNER AG. | C23: SWITZERLAND | D23: 73976.74 | E23: 35605.91 | F23: 17835.42 | H23: =IF(G23="","-",IFERROR(G23/F23-1,"-")) -> - | I23: =IF(G23="","-",G23-F23) -> -
A24: 204 | B24: SANAFLEX ANATOMIC | C24: GREECE | D24: 0 | E24: 85563.25 | H24: =IF(G24="","-",IFERROR(G24/F24-1,"-")) -> - | I24: =IF(G24="","-",G24-F24) -> -
A25: 205 | B25: HEALTH CARE PROD. GMBH | C25: GERMANY | D25: 0 | E25: 16335.18 | H25: =IF(G25="","-",IFERROR(G25/F25-1,"-")) -> - | I25: =IF(G25="","-",G25-F25) -> -
A26: 206 | B26: ORTHOMED LTD | C26: BULGARIA | D26: 0 | E26: 0 | H26: =IF(G26="","-",IFERROR(G26/F26-1,"-")) -> - | I26: =IF(G26="","-",G26-F26) -> -
A27: 207 | B27: SALUS | C27: HUNGARY | D27: 0 | E27: 0 | H27: =IF(G27="","-",IFERROR(G27/F27-1,"-")) -> - | I27: =IF(G27="","-",G27-F27) -> -
A28: 216 | B28: MAX KONNARIS LTD | C28: CYPRUS | D28: 23907.35 | E28: 0 | F28: 42152.31 | H28: =IF(G28="","-",IFERROR(G28/F28-1,"-")) -> - | I28: =IF(G28="","-",G28-F28) -> -
A29: 208 | B29: MEDIPAL COMPANY | C29: NABLUS | D29: 0 | E29: 0 | H29: =IF(G29="","-",IFERROR(G29/F29-1,"-")) -> - | I29: =IF(G29="","-",G29-F29) -> -
A30: 209 | B30: ORTOPROFIL PROD | C30: ROMANIA | D30: 49906.61 | E30: 49474.45 | F30: 24695.01 | H30: =IF(G30="","-",IFERROR(G30/F30-1,"-")) -> - | I30: =IF(G30="","-",G30-F30) -> -
A31: 210 | B31: OY. EA. AB. | C31: FINLAND | D31: 0 | E31: 0 | H31: =IF(G31="","-",IFERROR(G31/F31-1,"-")) -> - | I31: =IF(G31="","-",G31-F31) -> -
A32: 201 | B32: SEVEN GEAR | C32: FINLAND | D32: 0 | E32: 0 | H32: =IF(G32="","-",IFERROR(G32/F32-1,"-")) -> - | I32: =IF(G32="","-",G32-F32) -> -
A33: 211 | B33: PHARMAG LACHMAIR GES. MBH | C33: AUSTRIA | D33: 0 | E33: 0 | H33: =IF(G33="","-",IFERROR(G33/F33-1,"-")) -> - | I33: =IF(G33="","-",G33-F33) -> -
A34: 304 | B34: REMEDICARE B.V. | C34: HOLLAND | H34: =IF(G34="","-",IFERROR(G34/F34-1,"-")) -> - | I34: =IF(G34="","-",G34-F34) -> -
A35: 213 | B35: E.F.M.O. | C35: SPAIN | D35: 19941.82 | E35: 1584.32 | H35: =IF(G35="","-",IFERROR(G35/F35-1,"-")) -> - | I35: =IF(G35="","-",G35-F35) -> -
A36: 214 | B36: ALFRED GERA | C36: MALTA | D36: 34034.18 | E36: 0 | H36: =IF(G36="","-",IFERROR(G36/F36-1,"-")) -> - | I36: =IF(G36="","-",G36-F36) -> -
A37: 212 | B37: QUADRIFOGLIO MEDICAL | C37: ROMANIA | D37: 0 | E37: 0 | H37: =IF(G37="","-",IFERROR(G37/F37-1,"-")) -> - | I37: =IF(G37="","-",G37-F37) -> -
A38: 215 | B38: YOUNG IN HEALTHCARE CO., | C38: KOREA | D38: 0 | E38: 0 | H38: =IF(G38="","-",IFERROR(G38/F38-1,"-")) -> - | I38: =IF(G38="","-",G38-F38) -> -
A39: 217 | B39: HANS | C39: USA | D39: 0 | E39: 0 | H39: =IF(G39="","-",IFERROR(G39/F39-1,"-")) -> - | I39: =IF(G39="","-",G39-F39) -> -
A40: 303 | B40: NEW DISTRIBUTORS | C40: Other | H40: =IF(G40="","-",IFERROR(G40/F40-1,"-")) -> - | I40: =IF(G40="","-",G40-F40) -> -
...

Sheet 3
B1: דוח מכירות מרץ 2027 | K1: תאריך הכנת התשתית: 02/10/26
A2: # | B2: לקוח | C2: קבוצה | D2: 2024 | E2: 2025 | F2: 2026 | G2: 2027 | H2: אחוז מול 2026 | I2: כספי מול 2026
A3: 111 | B3: סופר פארם לייף | C3: ISR | D3: 0 | E3: 66608.1 | F3: 123280.14 | H3: =IF(G3="","-",IFERROR(G3/F3-1,"-")) -> - | I3: =IF(G3="","-",G3-F3) -> -
A4: 1 | B4: סופרפארם | C4: ISR | D4: 442108.94 | E4: 437918.57 | F4: 418342.47 | H4: =IF(G4="","-",IFERROR(G4/F4-1,"-")) -> - | I4: =IF(G4="","-",G4-F4) -> -
A5: 2 | B5: BE | C5: ISR | D5: 98496.489 | E5: 58257.29 | F5: 59847.151 | H5: =IF(G5="","-",IFERROR(G5/F5-1,"-")) -> - | I5: =IF(G5="","-",G5-F5) -> -
A6: 3 | B6: בתי מרקחת | C6: ISR | D6: 155174.62 | E6: 153012.03 | F6: 122676.56 | H6: =IF(G6="","-",IFERROR(G6/F6-1,"-")) -> - | I6: =IF(G6="","-",G6-F6) -> -
A7: 112 | B7: כללית | C7: ISR | D7: 389673.5 | E7: 376182 | F7: 244180.55 | H7: =IF(G7="","-",IFERROR(G7/F7-1,"-")) -> - | I7: =IF(G7="","-",G7-F7) -> -
A8: 113 | B8: מאוחדת | C8: ISR | D8: 77394.37 | E8: 74502.3 | F8: 55389.04 | H8: =IF(G8="","-",IFERROR(G8/F8-1,"-")) -> - | I8: =IF(G8="","-",G8-F8) -> -
A9: 4 | B9: מכבי | C9: ISR | F9: 0 | H9: =IF(G9="","-",IFERROR(G9/F9-1,"-")) -> - | I9: =IF(G9="","-",G9-F9) -> -
A10: 102 | B10: מכוני אורטופדיה | C10: ISR | D10: 87247.96 | E10: 65531.82 | F10: 48951.14 | H10: =IF(G10="","-",IFERROR(G10/F10-1,"-")) -> - | I10: =IF(G10="","-",G10-F10) -> -
A11: 101 | B11: לקוחות מפעל | C11: ISR | D11: 21528.06 | E11: 21300.79 | F11: 6765.24 | H11: =IF(G11="","-",IFERROR(G11/F11-1,"-")) -> - | I11: =IF(G11="","-",G11-F11) -> -
A12: 109 | B12: חנויות פרטיות | C12: ISR | D12: 3573.08 | E12: 11352.51 | F12: 3196.2 | H12: =IF(G12="","-",IFERROR(G12/F12-1,"-")) -> - | I12: =IF(G12="","-",G12-F12) -> -
A13: 105 | B13: מכוני פדיקור | C13: ISR | D13: 0 | E13: 0 | F13: 1106.56 | H13: =IF(G13="","-",IFERROR(G13/F13-1,"-")) -> - | I13: =IF(G13="","-",G13-F13) -> -
A14: 104 | B14: חנויות נעליים | C14: ISR | D14: 0 | E14: 0 | H14: =IF(G14="","-",IFERROR(G14/F14-1,"-")) -> - | I14: =IF(G14="","-",G14-F14) -> -
A15: 106 | B15: בתי חולים ושרות | C15: ISR | D15: 1275.21 | E15: 0 | H15: =IF(G15="","-",IFERROR(G15/F15-1,"-")) -> - | I15: =IF(G15="","-",G15-F15) -> -
A16: 103 | B16: מכוני פיזיותרפיה | C16: ISR | D16: 7451.5 | E16: 2138.43 | F16: 6672.87 | H16: =IF(G16="","-",IFERROR(G16/F16-1,"-")) -> - | I16: =IF(G16="","-",G16-F16) -> -
B17: סה"כ ישראל ללא אונליין | D17: =SUM(D3:D16) -> 1283923.7 | E17: =SUM(E3:E16) -> 1266803.8 | F17: =SUM(F3:F16) -> 1090407.9 | G17: =SUM(G3:G16) -> 0 | H17: =IF(G17="","-",IFERROR(G17/F17-1,"-")) -> -1 | I17: =IF(G17="","-",G17-F17) -> -1090407.9
A18: 114 | B18: לקוחות אינטרנט | C18: ISR | D18: 45122.89 | E18: 98819.24 | F18: 409497.07 | H18: =IF(G18="","-",IFERROR(G18/F18-1,"-")) -> - | I18: =IF(G18="","-",G18-F18) -> -
A19: 115 | B19: סופר פארם מרקט פלייס | C19: ISR | D19: 2233.52 | E19: 3577.56 | F19: 2065.63 | H19: =IF(G19="","-",IFERROR(G19/F19-1,"-")) -> - | I19: =IF(G19="","-",G19-F19) -> -
B20: סה"כ ישראל | D20: =D17+D18+D19 -> 1331280.1 | E20: =E17+E18+E19 -> 1369200.6 | F20: =F17+F18+F19 -> 1501970.6 | G20: =G17+G18+G19 -> 0 | H20: =IF(G20="","-",IFERROR(G20/F20-1,"-")) -> -1 | I20: =IF(G20="","-",G20-F20) -> -1501970.6
A21: 301 | B21: AMAZON | C21: USA | D21: 334336.04 | E21: 239973.2 | F21: 213959.66 | H21: =IF(G21="","-",IFERROR(G21/F21-1,"-")) -> - | I21: =IF(G21="","-",G21-F21) -> -
A22: 202 | B22: SUPER PHARM POLAND | C22: POLAND | D22: 0 | E22: 0 | H22: =IF(G22="","-",IFERROR(G22/F22-1,"-")) -> - | I22: =IF(G22="","-",G22-F22) -> -
A23: 203 | B23: ORTHO- PARTNER AG. | C23: SWITZERLAND | D23: 11470.17 | E23: 26449.51 | F23: 6418.64 | H23: =IF(G23="","-",IFERROR(G23/F23-1,"-")) -> - | I23: =IF(G23="","-",G23-F23) -> -
A24: 204 | B24: SANAFLEX ANATOMIC | C24: GREECE | D24: 84607.51 | E24: 0 | H24: =IF(G24="","-",IFERROR(G24/F24-1,"-")) -> - | I24: =IF(G24="","-",G24-F24) -> -
A25: 205 | B25: HEALTH CARE PROD. GMBH | C25: GERMANY | D25: 16377.13 | E25: 13664.6 | F25: 29021.19 | H25: =IF(G25="","-",IFERROR(G25/F25-1,"-")) -> - | I25: =IF(G25="","-",G25-F25) -> -
A26: 206 | B26: ORTHOMED LTD | C26: BULGARIA | D26: 0 | E26: 42132.93 | H26: =IF(G26="","-",IFERROR(G26/F26-1,"-")) -> - | I26: =IF(G26="","-",G26-F26) -> -
A27: 207 | B27: SALUS | C27: HUNGARY | D27: 0 | E27: 0 | H27: =IF(G27="","-",IFERROR(G27/F27-1,"-")) -> - | I27: =IF(G27="","-",G27-F27) -> -
A28: 216 | B28: MAX KONNARIS LTD | C28: CYPRUS | D28: 38588.13 | E28: 0 | H28: =IF(G28="","-",IFERROR(G28/F28-1,"-")) -> - | I28: =IF(G28="","-",G28-F28) -> -
A29: 208 | B29: MEDIPAL COMPANY | C29: NABLUS | D29: 171813.81 | E29: 0.22 | H29: =IF(G29="","-",IFERROR(G29/F29-1,"-")) -> - | I29: =IF(G29="","-",G29-F29) -> -
A30: 209 | B30: ORTOPROFIL PROD | C30: ROMANIA | D30: 25514.68 | E30: 43871.72 | H30: =IF(G30="","-",IFERROR(G30/F30-1,"-")) -> - | I30: =IF(G30="","-",G30-F30) -> -
A31: 210 | B31: OY. EA. AB. | C31: FINLAND | D31: 0 | E31: 32010.18 | H31: =IF(G31="","-",IFERROR(G31/F31-1,"-")) -> - | I31: =IF(G31="","-",G31-F31) -> -
A32: 201 | B32: SEVEN GEAR | C32: FINLAND | D32: 0 | E32: 0 | H32: =IF(G32="","-",IFERROR(G32/F32-1,"-")) -> - | I32: =IF(G32="","-",G32-F32) -> -
A33: 211 | B33: PHARMAG LACHMAIR GES. MBH | C33: AUSTRIA | D33: 0 | E33: 16024.5 | H33: =IF(G33="","-",IFERROR(G33/F33-1,"-")) -> - | I33: =IF(G33="","-",G33-F33) -> -
A34: 304 | B34: REMEDICARE B.V. | C34: HOLLAND | H34: =IF(G34="","-",IFERROR(G34/F34-1,"-")) -> - | I34: =IF(G34="","-",G34-F34) -> -
A35: 213 | B35: E.F.M.O. | C35: SPAIN | D35: -20732.48 | E35: 0 | H35: =IF(G35="","-",IFERROR(G35/F35-1,"-")) -> - | I35: =IF(G35="","-",G35-F35) -> -
A36: 214 | B36: ALFRED GERA | C36: MALTA | D36: 0 | E36: 0 | H36: =IF(G36="","-",IFERROR(G36/F36-1,"-")) -> - | I36: =IF(G36="","-",G36-F36) -> -
A37: 212 | B37: QUADRIFOGLIO MEDICAL | C37: ROMANIA | D37: 0 | E37: 0 | H37: =IF(G37="","-",IFERROR(G37/F37-1,"-")) -> - | I37: =IF(G37="","-",G37-F37) -> -
A38: 215 | B38: YOUNG IN HEALTHCARE CO., | C38: KOREA | D38: 0 | E38: 0 | H38: =IF(G38="","-",IFERROR(G38/F38-1,"-")) -> - | I38: =IF(G38="","-",G38-F38) -> -
A39: 217 | B39: HANS | C39: USA | D39: 0 | E39: 0 | H39: =IF(G39="","-",IFERROR(G39/F39-1,"-")) -> - | I39: =IF(G39="","-",G39-F39) -> -
A40: 303 | B40: NEW DISTRIBUTORS | C40: Other | H40: =IF(G40="","-",IFERROR(G40/F40-1,"-")) -> - | I40: =IF(G40="","-",G40-F40) -> -
...

Sheet 4
B1: דוח מכירות אפריל 2027 | K1: תאריך הכנת התשתית: 02/10/26
A2: # | B2: לקוח | C2: קבוצה | D2: 2024 | E2: 2025 | F2: 2026 | G2: 2027 | H2: אחוז מול 2026 | I2: כספי מול 2026
A3: 111 | B3: סופר פארם לייף | C3: ISR | D3: 263037.5 | E3: 336937.6 | F3: 124575.26 | H3: =IF(G3="","-",IFERROR(G3/F3-1,"-")) -> - | I3: =IF(G3="","-",G3-F3) -> -
A4: 1 | B4: סופרפארם | C4: ISR | D4: 473814.8 | E4: 549545.83 | F4: 429718.2 | H4: =IF(G4="","-",IFERROR(G4/F4-1,"-")) -> - | I4: =IF(G4="","-",G4-F4) -> -
A5: 2 | B5: BE | C5: ISR | D5: 100846.29 | E5: 75168 | F5: 83501.964 | H5: =IF(G5="","-",IFERROR(G5/F5-1,"-")) -> - | I5: =IF(G5="","-",G5-F5) -> -
A6: 3 | B6: בתי מרקחת | C6: ISR | D6: 132554.79 | E6: 173213.55 | F6: 125615.73 | H6: =IF(G6="","-",IFERROR(G6/F6-1,"-")) -> - | I6: =IF(G6="","-",G6-F6) -> -
A7: 112 | B7: כללית | C7: ISR | D7: 244648 | E7: 263457 | F7: 220778.2 | H7: =IF(G7="","-",IFERROR(G7/F7-1,"-")) -> - | I7: =IF(G7="","-",G7-F7) -> -
A8: 113 | B8: מאוחדת | C8: ISR | D8: 59971.53 | E8: 62433.13 | F8: 50971.08 | H8: =IF(G8="","-",IFERROR(G8/F8-1,"-")) -> - | I8: =IF(G8="","-",G8-F8) -> -
A9: 4 | B9: מכבי | C9: ISR | F9: 0 | H9: =IF(G9="","-",IFERROR(G9/F9-1,"-")) -> - | I9: =IF(G9="","-",G9-F9) -> -
A10: 102 | B10: מכוני אורטופדיה | C10: ISR | D10: 69580.43 | E10: 74555.12 | F10: 88526.04 | H10: =IF(G10="","-",IFERROR(G10/F10-1,"-")) -> - | I10: =IF(G10="","-",G10-F10) -> -
A11: 101 | B11: לקוחות מפעל | C11: ISR | D11: 14571.76 | E11: 15201.7 | F11: 11923.54 | H11: =IF(G11="","-",IFERROR(G11/F11-1,"-")) -> - | I11: =IF(G11="","-",G11-F11) -> -
A12: 109 | B12: חנויות פרטיות | C12: ISR | D12: 11309.68 | E12: 4054.42 | F12: 4956.22 | H12: =IF(G12="","-",IFERROR(G12/F12-1,"-")) -> - | I12: =IF(G12="","-",G12-F12) -> -
A13: 105 | B13: מכוני פדיקור | C13: ISR | D13: 850.4 | E13: 0 | H13: =IF(G13="","-",IFERROR(G13/F13-1,"-")) -> - | I13: =IF(G13="","-",G13-F13) -> -
A14: 104 | B14: חנויות נעליים | C14: ISR | D14: 0 | E14: 0 | H14: =IF(G14="","-",IFERROR(G14/F14-1,"-")) -> - | I14: =IF(G14="","-",G14-F14) -> -
A15: 106 | B15: בתי חולים ושרות | C15: ISR | D15: 0 | E15: 0 | F15: 847.74 | H15: =IF(G15="","-",IFERROR(G15/F15-1,"-")) -> - | I15: =IF(G15="","-",G15-F15) -> -
A16: 103 | B16: מכוני פיזיותרפיה | C16: ISR | D16: 3314.43 | E16: 5898.37 | F16: 33906.96 | H16: =IF(G16="","-",IFERROR(G16/F16-1,"-")) -> - | I16: =IF(G16="","-",G16-F16) -> -
B17: סה"כ ישראל ללא אונליין | D17: =SUM(D3:D16) -> 1374499.6 | E17: =SUM(E3:E16) -> 1560464.7 | F17: =SUM(F3:F16) -> 1175320.9 | G17: =SUM(G3:G16) -> 0 | H17: =IF(G17="","-",IFERROR(G17/F17-1,"-")) -> -1 | I17: =IF(G17="","-",G17-F17) -> -1175320.9
A18: 114 | B18: לקוחות אינטרנט | C18: ISR | D18: 43476.43 | E18: 96447.31 | F18: 544858.41 | H18: =IF(G18="","-",IFERROR(G18/F18-1,"-")) -> - | I18: =IF(G18="","-",G18-F18) -> -
A19: 115 | B19: סופר פארם מרקט פלייס | C19: ISR | D19: 2046.43 | E19: 2606.4 | F19: 1302.94 | H19: =IF(G19="","-",IFERROR(G19/F19-1,"-")) -> - | I19: =IF(G19="","-",G19-F19) -> -
B20: סה"כ ישראל | D20: =D17+D18+D19 -> 1420022.5 | E20: =E17+E18+E19 -> 1659518.4 | F20: =F17+F18+F19 -> 1721482.3 | G20: =G17+G18+G19 -> 0 | H20: =IF(G20="","-",IFERROR(G20/F20-1,"-")) -> -1 | I20: =IF(G20="","-",G20-F20) -> -1721482.3
A21: 301 | B21: AMAZON | C21: USA | D21: 264520.55 | E21: 238431.78 | F21: 214988.69 | H21: =IF(G21="","-",IFERROR(G21/F21-1,"-")) -> - | I21: =IF(G21="","-",G21-F21) -> -
A22: 202 | B22: SUPER PHARM POLAND | C22: POLAND | D22: 184350.47 | E22: 217182.24 | H22: =IF(G22="","-",IFERROR(G22/F22-1,"-")) -> - | I22: =IF(G22="","-",G22-F22) -> -
A23: 203 | B23: ORTHO- PARTNER AG. | C23: SWITZERLAND | D23: 0 | E23: 0 | F23: 123835.02 | H23: =IF(G23="","-",IFERROR(G23/F23-1,"-")) -> - | I23: =IF(G23="","-",G23-F23) -> -
A24: 204 | B24: SANAFLEX ANATOMIC | C24: GREECE | D24: 0 | E24: 88706.82 | F24: 92404.96 | H24: =IF(G24="","-",IFERROR(G24/F24-1,"-")) -> - | I24: =IF(G24="","-",G24-F24) -> -
A25: 205 | B25: HEALTH CARE PROD. GMBH | C25: GERMANY | D25: 17556.44 | E25: 11888.32 | H25: =IF(G25="","-",IFERROR(G25/F25-1,"-")) -> - | I25: =IF(G25="","-",G25-F25) -> -
A26: 206 | B26: ORTHOMED LTD | C26: BULGARIA | D26: 0 | E26: 0 | H26: =IF(G26="","-",IFERROR(G26/F26-1,"-")) -> - | I26: =IF(G26="","-",G26-F26) -> -
A27: 207 | B27: SALUS | C27: HUNGARY | D27: 0 | E27: 0 | F27: 165356.86 | H27: =IF(G27="","-",IFERROR(G27/F27-1,"-")) -> - | I27: =IF(G27="","-",G27-F27) -> -
A28: 216 | B28: MAX KONNARIS LTD | C28: CYPRUS | D28: 0 | E28: 35240.62 | H28: =IF(G28="","-",IFERROR(G28/F28-1,"-")) -> - | I28: =IF(G28="","-",G28-F28) -> -
A29: 208 | B29: MEDIPAL COMPANY | C29: NABLUS | D29: 0 | E29: 0 | H29: =IF(G29="","-",IFERROR(G29/F29-1,"-")) -> - | I29: =IF(G29="","-",G29-F29) -> -
A30: 209 | B30: ORTOPROFIL PROD | C30: ROMANIA | D30: 27828.48 | E30: 38170.88 | F30: 60931.15 | H30: =IF(G30="","-",IFERROR(G30/F30-1,"-")) -> - | I30: =IF(G30="","-",G30-F30) -> -
A31: 210 | B31: OY. EA. AB. | C31: FINLAND | D31: 49617.59 | E31: 0 | H31: =IF(G31="","-",IFERROR(G31/F31-1,"-")) -> - | I31: =IF(G31="","-",G31-F31) -> -
A32: 201 | B32: SEVEN GEAR | C32: FINLAND | D32: 20354.79 | E32: 0 | F32: 17809.5 | H32: =IF(G32="","-",IFERROR(G32/F32-1,"-")) -> - | I32: =IF(G32="","-",G32-F32) -> -
A33: 211 | B33: PHARMAG LACHMAIR GES. MBH | C33: AUSTRIA | D33: 0 | E33: 0 | H33: =IF(G33="","-",IFERROR(G33/F33-1,"-")) -> - | I33: =IF(G33="","-",G33-F33) -> -
A34: 304 | B34: REMEDICARE B.V. | C34: HOLLAND | H34: =IF(G34="","-",IFERROR(G34/F34-1,"-")) -> - | I34: =IF(G34="","-",G34-F34) -> -
A35: 213 | B35: E.F.M.O. | C35: SPAIN | D35: 0 | E35: 0 | H35: =IF(G35="","-",IFERROR(G35/F35-1,"-")) -> - | I35: =IF(G35="","-",G35-F35) -> -
A36: 214 | B36: ALFRED GERA | C36: MALTA | D36: 0 | E36: 0 | H36: =IF(G36="","-",IFERROR(G36/F36-1,"-")) -> - | I36: =IF(G36="","-",G36-F36) -> -
A37: 212 | B37: QUADRIFOGLIO MEDICAL | C37: ROMANIA | D37: 41531.96 | E37: 0 | H37: =IF(G37="","-",IFERROR(G37/F37-1,"-")) -> - | I37: =IF(G37="","-",G37-F37) -> -
A38: 215 | B38: YOUNG IN HEALTHCARE CO., | C38: KOREA | D38: 0 | E38: 0 | H38: =IF(G38="","-",IFERROR(G38/F38-1,"-")) -> - | I38: =IF(G38="","-",G38-F38) -> -
A39: 217 | B39: HANS | C39: USA | D39: 0 | E39: 0 | H39: =IF(G39="","-",IFERROR(G39/F39-1,"-")) -> - | I39: =IF(G39="","-",G39-F39) -> -
A40: 303 | B40: NEW DISTRIBUTORS | C40: Other | H40: =IF(G40="","-",IFERROR(G40/F40-1,"-")) -> - | I40: =IF(G40="","-",G40-F40) -> -
...

Sheet 5
B1: דוח מכירות מאי 2027 | K1: תאריך הכנת התשתית: 02/10/26
A2: # | B2: לקוח | C2: קבוצה | D2: 2024 | E2: 2025 | F2: 2026 | G2: 2027 | H2: אחוז מול 2026 | I2: כספי מול 2026
A3: 111 | B3: סופר פארם לייף | C3: ISR | D3: 155618.13 | E3: 131634 | H3: =IF(G3="","-",IFERROR(G3/F3-1,"-")) -> - | I3: =IF(G3="","-",G3-F3) -> -
A4: 1 | B4: סופרפארם | C4: ISR | D4: 560199.91 | E4: 729180.69 | F4: 498482.53 | H4: =IF(G4="","-",IFERROR(G4/F4-1,"-")) -> - | I4: =IF(G4="","-",G4-F4) -> -
A5: 2 | B5: BE | C5: ISR | D5: 104005.54 | E5: 80577.77 | F5: 81328.338 | H5: =IF(G5="","-",IFERROR(G5/F5-1,"-")) -> - | I5: =IF(G5="","-",G5-F5) -> -
A6: 3 | B6: בתי מרקחת | C6: ISR | D6: 211638.8 | E6: 186515.16 | F6: 148972.08 | H6: =IF(G6="","-",IFERROR(G6/F6-1,"-")) -> - | I6: =IF(G6="","-",G6-F6) -> -
A7: 112 | B7: כללית | C7: ISR | D7: 327442 | E7: 307503 | F7: 318846.8 | H7: =IF(G7="","-",IFERROR(G7/F7-1,"-")) -> - | I7: =IF(G7="","-",G7-F7) -> -
A8: 113 | B8: מאוחדת | C8: ISR | D8: 65998.04 | E8: 88130.8 | F8: 47091.772 | H8: =IF(G8="","-",IFERROR(G8/F8-1,"-")) -> - | I8: =IF(G8="","-",G8-F8) -> -
A9: 4 | B9: מכבי | C9: ISR | F9: 0 | H9: =IF(G9="","-",IFERROR(G9/F9-1,"-")) -> - | I9: =IF(G9="","-",G9-F9) -> -
A10: 102 | B10: מכוני אורטופדיה | C10: ISR | D10: 99310.41 | E10: 94846.85 | F10: 102176.91 | H10: =IF(G10="","-",IFERROR(G10/F10-1,"-")) -> - | I10: =IF(G10="","-",G10-F10) -> -
A11: 101 | B11: לקוחות מפעל | C11: ISR | D11: 16034.44 | E11: 15870.65 | F11: 6343.11 | H11: =IF(G11="","-",IFERROR(G11/F11-1,"-")) -> - | I11: =IF(G11="","-",G11-F11) -> -
A12: 109 | B12: חנויות פרטיות | C12: ISR | D12: 1188.66 | E12: 5871.12 | F12: 7664.69 | H12: =IF(G12="","-",IFERROR(G12/F12-1,"-")) -> - | I12: =IF(G12="","-",G12-F12) -> -
A13: 105 | B13: מכוני פדיקור | C13: ISR | D13: 0 | E13: 0 | H13: =IF(G13="","-",IFERROR(G13/F13-1,"-")) -> - | I13: =IF(G13="","-",G13-F13) -> -
A14: 104 | B14: חנויות נעליים | C14: ISR | D14: 1597.46 | E14: 0 | F14: 1896.82 | H14: =IF(G14="","-",IFERROR(G14/F14-1,"-")) -> - | I14: =IF(G14="","-",G14-F14) -> -
A15: 106 | B15: בתי חולים ושרות | C15: ISR | D15: 0 | E15: 0 | F15: 3430 | H15: =IF(G15="","-",IFERROR(G15/F15-1,"-")) -> - | I15: =IF(G15="","-",G15-F15) -> -
A16: 103 | B16: מכוני פיזיותרפיה | C16: ISR | D16: 3187.34 | E16: 707.66 | F16: 6150.22 | H16: =IF(G16="","-",IFERROR(G16/F16-1,"-")) -> - | I16: =IF(G16="","-",G16-F16) -> -
B17: סה"כ ישראל ללא אונליין | D17: =SUM(D3:D16) -> 1546220.7 | E17: =SUM(E3:E16) -> 1640837.7 | F17: =SUM(F3:F16) -> 1222383.3 | G17: =SUM(G3:G16) -> 0 | H17: =IF(G17="","-",IFERROR(G17/F17-1,"-")) -> -1 | I17: =IF(G17="","-",G17-F17) -> -1222383.3
A18: 114 | B18: לקוחות אינטרנט | C18: ISR | D18: 49304.7 | E18: 99302.95 | F18: 404699.34 | H18: =IF(G18="","-",IFERROR(G18/F18-1,"-")) -> - | I18: =IF(G18="","-",G18-F18) -> -
A19: 115 | B19: סופר פארם מרקט פלייס | C19: ISR | D19: 2364.29 | E19: 1491.14 | F19: 2347.76 | H19: =IF(G19="","-",IFERROR(G19/F19-1,"-")) -> - | I19: =IF(G19="","-",G19-F19) -> -
B20: סה"כ ישראל | D20: =D17+D18+D19 -> 1597889.7 | E20: =E17+E18+E19 -> 1741631.8 | F20: =F17+F18+F19 -> 1629430.4 | G20: =G17+G18+G19 -> 0 | H20: =IF(G20="","-",IFERROR(G20/F20-1,"-")) -> -1 | I20: =IF(G20="","-",G20-F20) -> -1629430.4
A21: 301 | B21: AMAZON | C21: USA | D21: 318316.8 | E21: 252540.02 | F21: 224163.96 | H21: =IF(G21="","-",IFERROR(G21/F21-1,"-")) -> - | I21: =IF(G21="","-",G21-F21) -> -
A22: 202 | B22: SUPER PHARM POLAND | C22: POLAND | D22: 0 | E22: 0 | F22: 204882.82 | H22: =IF(G22="","-",IFERROR(G22/F22-1,"-")) -> - | I22: =IF(G22="","-",G22-F22) -> -
A23: 203 | B23: ORTHO- PARTNER AG. | C23: SWITZERLAND | D23: 169505.88 | E23: 1513.3 | F23: 5036.8 | H23: =IF(G23="","-",IFERROR(G23/F23-1,"-")) -> - | I23: =IF(G23="","-",G23-F23) -> -
A24: 204 | B24: SANAFLEX ANATOMIC | C24: GREECE | D24: 0 | E24: 0 | H24: =IF(G24="","-",IFERROR(G24/F24-1,"-")) -> - | I24: =IF(G24="","-",G24-F24) -> -
A25: 205 | B25: HEALTH CARE PROD. GMBH | C25: GERMANY | D25: 0 | E25: 0 | F25: 16087.48 | H25: =IF(G25="","-",IFERROR(G25/F25-1,"-")) -> - | I25: =IF(G25="","-",G25-F25) -> -
A26: 206 | B26: ORTHOMED LTD | C26: BULGARIA | D26: 0 | E26: 10766.89 | H26: =IF(G26="","-",IFERROR(G26/F26-1,"-")) -> - | I26: =IF(G26="","-",G26-F26) -> -
A27: 207 | B27: SALUS | C27: HUNGARY | D27: 0 | E27: 172805.6 | F27: -19940.33 | H27: =IF(G27="","-",IFERROR(G27/F27-1,"-")) -> - | I27: =IF(G27="","-",G27-F27) -> -
